Workbook

Sheet 數值累積總表(月)
B1: 項目 | D1: 1月 | E1: 2月 | F1: 3月 | G1: 4月 | H1: 5月 | I1: 6月 | J1: 7月 | K1: 8月 | L1: 9月 | M1: 10月 | N1: 11月 | O1: 12月 | P1: 合計/平均
B2: （１）收支狀況 | C2: 業績金額(千元) | D2: 146299.94 | E2: 116569.43 | F2: 148838 | P2: =SUM(D2:O2) -> 411707.36
C3: 訂單數量 | D3: 4768701 | E3: 3787002 | F3: 5045753 | P3: =SUM(D3:O3) -> 13601456
C4: 材料費(千元) | D4: 93253 | E4: 74777 | F4: 93614 | P4: =SUM(D4:O4) -> 261644
C5: 材料費率(%) | D5: 0.655 | E5: 0.653 | F5: 0.648 | G5: =IFERROR(G4/G2, "") | H5: =IFERROR(H4/H2, "") | I5: =IFERROR(I4/I2, "") | J5: =IFERROR(J4/J2, "") | K5: =IFERROR(K4/K2, "") | L5: =IFERROR(L4/L2, "") | M5: =IFERROR(M4/M2, "") | N5: =IFERROR(N4/N2, "") | O5: =IFERROR(O4/O2, "") | P5: =AVERAGEIF(D5:O5, ">0") -> 0.652
C6: 勞務成本(千元) | D6: 22378 | E6: 22860 | F6: 22710 | P6: =SUM(D6:O6) -> 67948
C7: 勞務費率(%) | D7: 0.157 | E7: 0.2 | F7: 0.157 | G7: =IFERROR(G6/G2, "") | H7: =IFERROR(H6/H2, "") | I7: =IFERROR(I6/I2, "") | J7: =IFERROR(J6/J2, "") | K7: =IFERROR(K6/K2, "") | L7: =IFERROR(L6/L2, "") | M7: =IFERROR(M6/M2, "") | N7: =IFERROR(N6/N2, "") | O7: =IFERROR(O6/O2, "") | P7: =AVERAGEIF(D7:O7, ">0") -> 0.17133333
B9: （２）ＫＰＩ達成進度 | C9: 人時性KPI | D9: 497.6 | E9: 497.6 | F9: 497.6 | P9: =AVERAGEIF(D9:O9, ">0") -> 497.6
C10: 人時性(個/月均) | D10: 458.38414 | E10: 476.04172 | F10: 409.81563 | P10: =AVERAGEIF(D10:O10, ">0") -> 448.0805
C11: 人時達成率(%/月均) | D11: =IFERROR(D10/D9, "") -> 0.92118999 | E11: =IFERROR(E10/E9, "") -> 0.95667547 | F11: =IFERROR(F10/F9, "") -> 0.82358447 | G11: =IFERROR(G10/G9, "") | H11: =IFERROR(H10/H9, "") | I11: =IFERROR(I10/I9, "") | J11: =IFERROR(J10/J9, "") | K11: =IFERROR(K10/K9, "") | ... O11: =IFERROR(O10/O9, "") | P11: =AVERAGEIF(D11:O11, ">0") -> 0.90048331
C12: 半成品-報廢(%) | D12: 0.0024135432 | E12: 0.0023657636 | F12: 0.0020222248 | P12: =AVERAGEIF(D12:O12, ">0") -> 0.0022671772
C13: 半成品-超用(%) | D13: 0.0055994433 | E13: 0.0052393001 | F13: 0.0048799138 | P13: =AVERAGEIF(D13:O13, ">0") -> 0.0052395524
C14: 固定產線-導入率(%) | D14: 0.9 | E14: 0.9 | F14: 0.9 | P14: =AVERAGEIF(D14:O14, ">0") -> 0.9
C15: 教育訓練-實施率(%) | D15: 0.057692308 | E15: 0.13873626 | F15: 0.21960298 | P15: 0.2196
B17: （３）業績構成比 | C17: 18℃-飯糰(061,063) | D17: 0.36139567 | E17: 0.34737657 | F17: 0.36414345 | P17: =AVERAGEIF(D17:O17, ">0") -> 0.35763856
C18: 18℃-壽司手卷(071,072,075,076) | D18: 0.069633574 | E18: 0.077793665 | F18: 0.084480826 | P18: =AVERAGEIF(D18:O18, ">0") -> 0.077302689
C19: 4℃-飯糰(065) | D19: 0.022453222 | E19: 0.02167645 | F19: 0.02436516 | P19: =AVERAGEIF(D19:O19, ">0") -> 0.022831611
C20: 4℃-壽司手卷(077) | D20: 0.008585039 | E20: 0.0099523222 | F20: 0.014684918 | P20: =AVERAGEIF(D20:O20, ">0") -> 0.011074093
C21: 主食(091,092,093,094,095) | D21: 0.16215294 | E21: 0.18214708 | F21: 0.20289324 | P21: =AVERAGEIF(D21:O21, ">0") -> 0.18239775
C22: 便當(083) | D22: 0.27057088 | E22: 0.27529226 | F22: 0.29293399 | P22: =AVERAGEIF(D22:O22, ">0") -> 0.27959904
C23: 熱食義麵(122,123,124,126) | D23: 0.029234371 | E23: 0.0089796819 | F23: 0 | P23: =AVERAGEIF(D23:O23, ">0") -> 0.019107026
C24: 季節調理麵(111,112) | D24: 0.040564166 | E24: 0.040109499 | F24: 0.0016541185 | P24: =AVERAGEIF(D24:O24, ">0") -> 0.027442594
C25: 微波小吃(153,154,155) | D25: 0.035410133 | E25: 0.036672477 | F25: 0.01484429 | P25: =AVERAGEIF(D25:O25, ">0") -> 0.028975633
B27: （４）訂單數量構成比 | C27: 18℃-飯糰(061,063) | D27: 0.58577126 | E27: 0.57025346 | F27: 0.57640852 | P27: =AVERAGEIF(D27:O27, ">0") -> 0.57747775
C28: 18℃-壽司手卷(071,072,075,076) | D28: 0.081693946 | E28: 0.091615478 | F28: 0.10179987 | P28: =AVERAGEIF(D28:O28, ">0") -> 0.091703098
C29: 4℃-飯糰(065) | D29: 0.024966128 | E29: 0.023825971 | F29: 0.026809081 | P29: =AVERAGEIF(D29:O29, ">0") -> 0.025200393
C30: 4℃-壽司手卷(077) | D30: 0.0097963785 | E30: 0.011706622 | F30: 0.016401516 | P30: =AVERAGEIF(D30:O30, ">0") -> 0.012634839
C31: 主食(091,092,093,094,095) | D31: 0.089953008 | E31: 0.10114835 | F31: 0.11343936 | P31: =AVERAGEIF(D31:O31, ">0") -> 0.10151357
C32: 便當(083) | D32: 0.13708178 | E32: 0.14060779 | F32: 0.14223546 | P32: =AVERAGEIF(D32:O32, ">0") -> 0.13997501
C33: 熱食義麵(122,123,124,126) | D33: 0.015652481 | E33: 0.0048238686 | F33: 0 | P33: =AVERAGEIF(D33:O33, ">0") -> 0.010238175
C34: 季節調理麵(111,112) | D34: 0.022004735 | E34: 0.020902022 | F34: 0.00067918505 | P34: =AVERAGEIF(D34:O34, ">0") -> 0.014528647
C35: 微波小吃(153,154,155) | D35: 0.033080287 | E35: 0.035116432 | F35: 0.02222701 | P35: =AVERAGEIF(D35:O35, ">0") -> 0.030141243
B37: （５）品群別人時生產性 | C37: 18℃-飯糰(061,063) | D37: 768.96509 | E37: 774.12086 | F37: 757.59042 | P37: =AVERAGEIF(D37:O37, ">0") -> 766.89213
C38: 18℃-壽司手卷(071,072,075,076) | D38: 280.52358 | E38: 304.46478 | F38: 311.70582 | P38: =AVERAGEIF(D38:O38, ">0") -> 298.89806
C39: 4℃-飯糰(065) | D39: 258.56167 | E39: 203.24374 | F39: 331.13667 | P39: =AVERAGEIF(D39:O39, ">0") -> 264.31403
C40: 4℃-壽司手卷(077) | D40: 486.07171 | E40: 490.19814 | F40: 493.97618 | P40: =AVERAGEIF(D40:O40, ">0") -> 490.08201
C41: 主食(091,092,093,094,095) | D41: 82.669482 | E41: 81.452412 | F41: 79.949999 | P41: =AVERAGEIF(D41:O41, ">0") -> 81.357298
C42: 便當(083) | D42: 78.306367 | E42: 77.971323 | F42: 77.906797 | P42: =AVERAGEIF(D42:O42, ">0") -> 78.061495
C43: 熱食義麵(122,123,124,126) | D43: 76.250133 | E43: 72.949976 | F43: 0 | P43: =AVERAGEIF(D43:O43, ">0") -> 74.600054
C44: 季節調理麵(111,112) | D44: 110.8083 | E44: 97.157501 | F44: 84.601424 | P44: =AVERAGEIF(D44:O44, ">0") -> 97.52241
...

Sheet 生產管理報表(月)
A1: 大溪廠生產管理報表
A3: 月別 | B3: 4 | C3: 工廠 | D3: 大溪廠
A4: （１）收支狀況 | E4: ※單位：千元 | G4: （２）ＫＰＩ達成進度
A5: 項目 | B5: 當月 | C5: 前月 | D5: 差異 | E5: 累計 | G5: 項目 | H5: KPI | I5: 當月 | J5: 前月 | K5: 累計 | L5: ※補充
A6: 業績金額 | B6: ='（１）收支狀況'!#REF!/1000 -> #REF! | C6: ='數值累積總表(月)'!F2 -> 148838 | D6: =B6-C6 -> #REF! | E6: ='數值累積總表(月)'!P2 -> 411707.36 | G6: 人時性(個/月均) | H6: 497.6 | I6: ='（２）ＫＰＩ達成進度'!#REF! -> #REF! | J6: ='數值累積總表(月)'!F10 -> 409.81563 | K6: ='數值累積總表(月)'!P10 -> 448.0805 | L6: 個／MH
A7: 訂單數量 | B7: ='（１）收支狀況'!#REF! -> #REF! | C7: ='數值累積總表(月)'!F3 -> 5045753 | D7: =B7-C7 -> #REF! | E7: ='數值累積總表(月)'!P3 -> 13601456 | G7: 人時達成率(%/月均) | H7: 0.8 | I7: ='[1]（２）ＫＰＩ達成進度'!K10 -> 0.82360963 | J7: ='數值累積總表(月)'!F11 -> 0.82358447 | K7: ='數值累積總表(月)'!P11 -> 0.90048331 | L7: 達成率
A8: 材料費 | B8: 93614 | C8: ='數值累積總表(月)'!F4 -> 93614 | D8: =B8-C8 -> 0 | E8: ='數值累積總表(月)'!P4 -> 261644 | G8: 半成品-報廢(%) | H8: 0.0025 | I8: ='（２）ＫＰＩ達成進度'!#REF! -> #REF! | J8: ='數值累積總表(月)'!F12 -> 0.0020222248 | K8: ='數值累積總表(月)'!P12 -> 0.0022671772 | L8: 報廢率
A9: 材料費率 | B9: 0.648 | C9: ='數值累積總表(月)'!F5 -> 0.648 | D9: =B9-C9 -> 0 | E9: ='數值累積總表(月)'!P5 -> 0.652 | G9: 半成品-超用(%) | H9: 0.004 | I9: ='（２）ＫＰＩ達成進度'!#REF! -> #REF! | J9: ='數值累積總表(月)'!F13 -> 0.0048799138 | K9: ='數值累積總表(月)'!P13 -> 0.0052395524 | L9: 超用率
A10: 勞務成本 | B10: 22710 | C10: ='數值累積總表(月)'!F6 -> 22710 | D10: =B10-C10 -> 0 | E10: ='[1]數值累積總表(月)'!P6 -> 67948 | G10: 固定產線-導入率(%) | H10: 0.8 | I10: ='（２）ＫＰＩ達成進度'!#REF! -> #REF! | J10: ='數值累積總表(月)'!F14 -> 0.9 | K10: ='數值累積總表(月)'!P14 -> 0.9 | L10: 導入率
A11: 勞務費率 | B11: 0.157 | C11: ='數值累積總表(月)'!F7 -> 0.157 | D11: =B11-C11 -> 0 | E11: ='數值累積總表(月)'!P7 -> 0.17133333 | G11: 教育訓練-實施率(%) | H11: 1 | I11: ='（２）ＫＰＩ達成進度'!#REF! -> #REF! | J11: ='數值累積總表(月)'!F15 -> 0.21960298 | K11: ='數值累積總表(月)'!P15 -> 0.2196 | L11: 實施率
A13: （３）業績構成比 | E13: ※單位：千元 | G13: （４）訂單數量構成比 | K13: ※單位：個
B14: 當月 | C14: 比例 | D14: 前月 | E14: 差異 | H14: 當月 | I14: 比例 | J14: 前月 | K14: 差異
A15: 18℃-飯糰(061,063) | B15: =SUM('（３）業績構成比'!M7:M9)/1000 -> 6378.1459 | C15: =IFERROR(B15/$B$6,"") | D15: ='數值累積總表(月)'!F17 -> 0.36414345 | E15: =IFERROR(C15-D15,"") | G15: 18℃-飯糰(061,063) | H15: =SUM('（４）訂單數量構成比'!M7:M9) -> 321465 | I15: =IFERROR(H15/$B$7,"") | J15: ='數值累積總表(月)'!F27 -> 0.57640852 | K15: =IFERROR(I15-J15,"")
A16: 18℃-壽司手卷(071,072,075,076) | B16: =SUM('（３）業績構成比'!S7:S9)/1000 -> 761.65179 | C16: =IFERROR(B16/$B$6,"") | D16: ='數值累積總表(月)'!F18 -> 0.084480826 | E16: =IFERROR(C16-D16,"") | G16: 18℃-壽司手卷(071,072,075,076) | H16: =SUM('（４）訂單數量構成比'!S7:S9) -> 28968 | I16: =IFERROR(H16/$B$7,"") | J16: ='數值累積總表(月)'!F28 -> 0.10179987 | K16: =IFERROR(I16-J16,"")
A17: 4℃-飯糰(065) | B17: =SUM('（３）業績構成比'!U7:U9)/1000 -> 287.38825 | C17: =IFERROR(B17/$B$6,"") | D17: ='數值累積總表(月)'!F19 -> 0.02436516 | E17: =IFERROR(C17-D17,"") | G17: 4℃-飯糰(065) | H17: =SUM('（４）訂單數量構成比'!U7:U9) -> 10265 | I17: =IFERROR(H17/$B$7,"") | J17: ='數值累積總表(月)'!F29 -> 0.026809081 | K17: =IFERROR(I17-J17,"")
A18: 4℃-壽司手卷(077) | B18: =SUM('（３）業績構成比'!W7:W9)/1000 -> 372.33153 | C18: =IFERROR(B18/$B$6,"") | D18: ='數值累積總表(月)'!F20 -> 0.014684918 | E18: =IFERROR(C18-D18,"") | G18: 4℃-壽司手卷(077) | H18: =SUM('（４）訂單數量構成比'!W7:W9) -> 14490 | I18: =IFERROR(H18/$B$7,"") | J18: ='數值累積總表(月)'!F30 -> 0.016401516 | K18: =IFERROR(I18-J18,"")
A19: 主食(091,092,093,094,095) | B19: =SUM('（３）業績構成比'!AC7:AC9)/1000 -> 2169.0539 | C19: =IFERROR(B19/$B$6,"") | D19: ='數值累積總表(月)'!F21 -> 0.20289324 | E19: =IFERROR(C19-D19,"") | G19: 主食(091,092,093,094,095) | H19: =SUM('（４）訂單數量構成比'!AC7:AC9) -> 43187 | I19: =IFERROR(H19/$B$7,"") | J19: ='數值累積總表(月)'!F31 -> 0.11343936 | K19: =IFERROR(I19-J19,"")
A20: 便當(083) | B20: =SUM('（３）業績構成比'!AE7:AE9)/1000 -> 4154.9154 | C20: =IFERROR(B20/$B$6,"") | D20: ='數值累積總表(月)'!F22 -> 0.29293399 | E20: =IFERROR(C20-D20,"") | G20: 便當(083) | H20: =SUM('（４）訂單數量構成比'!AE7:AE9) -> 66980 | I20: =IFERROR(H20/$B$7,"") | J20: ='數值累積總表(月)'!F32 -> 0.14223546 | K20: =IFERROR(I20-J20,"")
A21: 熱食義麵(122,123,124,126) | B21: =SUM('（３）業績構成比'!AG7:AG9)/1000 -> 0 | C21: =IFERROR(B21/$B$6,"") | D21: ='數值累積總表(月)'!F23 -> 0 | E21: =IFERROR(C21-D21,"") | G21: 熱食義麵(122,123,124,126) | H21: =SUM('（４）訂單數量構成比'!AG7:AG9) -> 0 | I21: =IFERROR(H21/$B$7,"") | J21: ='數值累積總表(月)'!F33 -> 0 | K21: =IFERROR(I21-J21,"")
A22: 季節調理麵(111,112) | B22: =SUM('（３）業績構成比'!AI7:AI9)/1000 -> 2140.6655 | C22: =IFERROR(B22/$B$6,"") | D22: ='數值累積總表(月)'!F24 -> 0.0016541185 | E22: =IFERROR(C22-D22,"") | G22: 季節調理麵(111,112) | H22: =SUM('（４）訂單數量構成比'!AI7:AI9) -> 59298 | I22: =IFERROR(H22/$B$7,"") | J22: ='數值累積總表(月)'!F34 -> 0.00067918505 | K22: =IFERROR(I22-J22,"")
A23: 微波小吃(153,154,155) | B23: =SUM('（３）業績構成比'!AK7:AK9)/1000 -> 204.1314 | C23: =IFERROR(B23/$B$6,"") | D23: ='數值累積總表(月)'!F25 -> 0.01484429 | E23: =IFERROR(C23-D23,"") | G23: 微波小吃(153,154,155) | H23: =SUM('（４）訂單數量構成比'!AK7:AK9) -> 10362 | I23: =IFERROR(H23/$B$7,"") | J23: ='數值累積總表(月)'!F35 -> 0.02222701 | K23: =IFERROR(I23-J23,"")
C24: =SUM(C15:C23) -> 0 | D24: =SUM(D15:D23) -> 1 | I24: =SUM(I15:I23) -> 0 | J24: =SUM(J15:J23) -> 1
A26: （５）品群別人時生產性
A27: 品群 | B27: 當月 | C27: 前月 | D27: 差異 | E27: 累計
A28: 18℃-飯A15:A23糰(061,063) | B28: ='（５-1）品群別人時生產性(18℃-飯糰)'!C1 -> 754.59166 | C28: ='數值累積總表(月)'!F37 -> 757.59042 | D28: =B28-C28 -> -2.998764 | E28: ='數值累積總表(月)'!P37 -> 766.89213
A29: 18℃-壽司手卷(071,072,075,076) | B29: ='（５-2）品群別人時生產性(18℃-壽司手卷)'!C1 -> 323.81927 | C29: ='數值累積總表(月)'!F38 -> 311.70582 | D29: =B29-C29 -> 12.113446 | E29: ='數值累積總表(月)'!P38 -> 298.89806
A30: 4℃-飯糰(065) | B30: ='（５-3）品群別人時生產性(4℃-飯糰)'!C1 -> 346.03759 | C30: ='數值累積總表(月)'!F39 -> 331.13667 | D30: =B30-C30 -> 14.900923 | E30: ='數值累積總表(月)'!P39 -> 264.31403
A31: 4℃-壽司手卷(077) | B31: ='（５-4）品群別人時生產性(4℃-壽司手卷)'!C1 -> 353.15448 | C31: ='數值累積總表(月)'!F40 -> 493.97618 | D31: =B31-C31 -> -140.82171 | E31: ='數值累積總表(月)'!P40 -> 490.08201
A32: 主食(091,092,093,094,095) | B32: ='（５-5）品群別人時生產性(微波主食) '!C1 -> 85.277751 | C32: ='數值累積總表(月)'!F41 -> 79.949999 | D32: =B32-C32 -> 5.3277522 | E32: ='數值累積總表(月)'!P41 -> 81.357298
A33: 便當(083) | B33: ='（５-6）品群別人時生產性(便當)'!C1 -> 78.576002 | C33: ='數值累積總表(月)'!F42 -> 77.906797 | D33: =B33-C33 -> 0.66920481 | E33: ='數值累積總表(月)'!P42 -> 78.061495
A34: 熱食義麵(122,123,124,126) | B34: ='（５-7）品群別人時生產性(熱食義麵) '!C1 -> 0 | C34: ='數值累積總表(月)'!F43 -> 0 | D34: =B34-C34 -> 0 | E34: ='數值累積總表(月)'!P43 -> 74.600054
A35: 季節調理麵(111,112) | B35: ='（５-8）品群別人時生產性(季節調理麵) '!C1 -> 163.41538 | C35: ='數值累積總表(月)'!F44 -> 84.601424 | D35: =B35-C35 -> 78.813957 | E35: ='數值累積總表(月)'!P44 -> 97.52241
A36: 微波小吃(153,154,155) | B36: ='（５-9）品群別人時生產性(微波小吃)'!C1 -> 83.085237 | C36: ='數值累積總表(月)'!F45 -> 83.044479 | D36: =B36-C36 -> 0.040758728 | E36: ='數值累積總表(月)'!P45 -> 78.920094

Sheet 生產管理報表(週) 
A1: 大溪廠生產管理報表
A3: 月別 | B3: 5 | C3: 週別 | D3: W2 | E3: 工廠 | F3: 大溪廠
A4: （１）收支狀況 | E4: ※單位：千元 | G4: （２）ＫＰＩ達成進度
A5: 項目 | B5: 當週 | C5: 前週 | D5: 差異 | E5: 累計 | G5: 項目 | H5: KPI | I5: 當週 | J5: 前週 | K5: 累計 | L5: ※補充
A6: 業績金額 | B6: ='（１）收支狀況'!G12/1000 -> 38419.573 | C6: 37624.281 | D6: =B6-C6 -> 795.2914 | E6: ='（１）收支狀況'!H8:H8/1000 -> 59575.57 | G6: 人時性(個/月均) | H6: 442.4 | I6: ='（２）ＫＰＩ達成進度'!G12 -> 410.70345 | J6: 409.72046 | K6: ='（２）ＫＰＩ達成進度'!H8 -> 411.48779 | L6: 個／MH
A7: 訂單數量 | B7: ='（１）收支狀況'!J12 -> 1283685 | C7: 1262288 | D7: =B7-C7 -> 21397 | E7: ='（１）收支狀況'!K8:K8 -> 1990958 | G7: 人時達成率(%/月均) | H7: 0.8 | I7: ='（２）ＫＰＩ達成進度'!J12 -> 0.92835318 | J7: 0.92613124 | K7: ='（２）ＫＰＩ達成進度'!K8 -> 0.9301261 | L7: 達成率
A8: 材料費 | B8: ='（１）收支狀況'!M12/1000 -> 25686.053 | C8: 25299.965 | D8: =B8-C8 -> 386.08845 | E8: ='（１）收支狀況'!N8:N8/1000 -> 39856.822 | G8: 半成品-報廢(%) | H8: 0.0025 | I8: ='（２）ＫＰＩ達成進度'!M12 -> 0.0020046816 | J8: 0.0020023819 | K8: ='（２）ＫＰＩ達成進度'!N8 -> 0.0020045261 | L8: 報廢率
A9: 材料費率 | B9: ='（１）收支狀況'!P12 -> 0.66856686 | C9: 0.67243715 | D9: =B9-C9 -> -0.0038702939 | E9: ='（１）收支狀況'!Q8 -> 0.66901285 | G9: 半成品-超用(%) | H9: 0.004 | I9: ='（２）ＫＰＩ達成進度'!P12 -> 0.0061073691 | J9: 0.0053888197 | K9: ='（２）ＫＰＩ達成進度'!Q8 -> 0.0061668044 | L9: 超用率
A10: 勞務成本 | B10: ='（１）收支狀況'!S12/1000 -> 5512.6754 | C10: 5540.8399 | D10: =B10-C10 -> -28.164474 | E10: ='（１）收支狀況'!T8/1000 -> 8636.2906 | G10: 固定產線-導入率(%) | H10: 0.8 | I10: ='（２）ＫＰＩ達成進度'!S12 -> 0.9 | J10: 0.9 | K10: ='（２）ＫＰＩ達成進度'!T8 -> 0.9 | L10: 導入率
A11: 勞務費率 | B11: ='（１）收支狀況'!V12 -> 0.14348612 | C11: 0.14726766 | D11: =B11-C11 -> -0.0037815407 | E11: ='（１）收支狀況'!W8 -> 0.14496363 | G11: 教育訓練-實施率(%) | H11: 1 | I11: =19/52*100% -> 0.36538462 | J11: 0.34615385 | K11: ='（２）ＫＰＩ達成進度'!W8 -> 0.35839161 | L11: 實施率
A13: （３）業績構成比 | E13: ※單位：千元 | G13: （４）訂單數量構成比 | K13: ※單位：個
B14: 當週 | C14: 比例 | D14: 前週 | E14: 差異 | H14: 當週 | I14: 比例 | J14: 前週 | K14: 差異
A15: 18℃-飯糰(061,063) | B15: =SUM('（３）業績構成比'!M14:M20)/1000 -> 14747.475 | C15: =IFERROR(B15/$B$6,"") -> 0.38385318 | D15: 0.3882246 | E15: =IFERROR(C15-D15,"") -> -0.0043714178 | G15: 18℃-飯糰(061,063) | H15: =SUM('（４）訂單數量構成比'!M14:M20) -> 754370 | I15: =IFERROR(H15/$B$7,"") -> 0.58765975 | J15: 0.58526739 | K15: =IFERROR(I15-J15,"") -> 0.0023923577
A16: 18℃-壽司手卷(071,072,075,076) | B16: =SUM('（３）業績構成比'!S14:S20)/1000 -> 1887.4768 | C16: =IFERROR(B16/$B$6,"") -> 0.049128002 | D16: 0.045390189 | E16: =IFERROR(C16-D16,"") -> 0.0037378126 | G16: 18℃-壽司手卷(071,072,075,076) | H16: =SUM('（４）訂單數量構成比'!S14:S20) -> 71264 | I16: =IFERROR(H16/$B$7,"") -> 0.055515177 | J16: 0.051363873 | K16: =IFERROR(I16-J16,"") -> 0.0041513044
A17: 4℃-飯糰(065) | B17: =SUM('（３）業績構成比'!U14:U20)/1000 -> 665.12295 | C17: =IFERROR(B17/$B$6,"") -> 0.017312086 | D17: 0.017530048 | E17: =IFERROR(C17-D17,"") -> -0.00021796146 | G17: 4℃-飯糰(065) | H17: =SUM('（４）訂單數量構成比'!U14:U20) -> 23670 | I17: =IFERROR(H17/$B$7,"") -> 0.018439103 | J17: 0.018630455 | K17: =IFERROR(I17-J17,"") -> -0.00019135212
A18: 4℃-壽司手卷(077) | B18: =SUM('（３）業績構成比'!W14:W20)/1000 -> 318.23523 | C18: =IFERROR(B18/$B$6,"") -> 0.0082831538 | D18: 0.015801359 | E18: =IFERROR(C18-D18,"") -> -0.0075182051 | G18: 4℃-壽司手卷(077) | H18: =SUM('（４）訂單數量構成比'!W14:W20) -> 13593 | I18: =IFERROR(H18/$B$7,"") -> 0.010589046 | J18: 0.019002003 | K18: =IFERROR(I18-J18,"") -> -0.0084129563
A19: 主食(091,092,093,094,095) | B19: =SUM('（３）業績構成比'!AC14:AC20)/1000 -> 5644.4875 | C19: =IFERROR(B19/$B$6,"") -> 0.14691698 | D19: 0.1452857 | E19: =IFERROR(C19-D19,"") -> 0.0016312724 | G19: 主食(091,092,093,094,095) | H19: =SUM('（４）訂單數量構成比'!AC14:AC20) -> 108812 | I19: =IFERROR(H19/$B$7,"") -> 0.084765344 | J19: 0.085932846 | K19: =IFERROR(I19-J19,"") -> -0.0011675022
A20: 便當(083) | B20: =SUM('（３）業績構成比'!AE14:AE20)/1000 -> 10384.797 | C20: =IFERROR(B20/$B$6,"") -> 0.27029964 | D20: 0.2590831 | E20: =IFERROR(C20-D20,"") -> 0.011216541 | G20: 便當(083) | H20: =SUM('（４）訂單數量構成比'!AE14:AE20) -> 167336 | I20: =IFERROR(H20/$B$7,"") -> 0.13035597 | J20: 0.12460706 | K20: =IFERROR(I20-J20,"") -> 0.0057489047
A21: 熱食義麵(122,123,124,126) | B21: =SUM('（３）業績構成比'!AG14:AG20)/1000 -> 0 | C21: =IFERROR(B21/$B$6,"") -> 0 | D21: 0 | E21: =IFERROR(C21-D21,"") -> 0 | G21: 熱食義麵(122,123,124,126) | H21: =SUM('（４）訂單數量構成比'!AG14:AG20) -> 0 | I21: =IFERROR(H21/$B$7,"") -> 0 | J21: 0 | K21: =IFERROR(I21-J21,"") -> 0
A22: 季節調理麵(111,112) | B22: =SUM('（３）業績構成比'!AI14:AI20)/1000 -> 4268.1508 | C22: =IFERROR(B22/$B$6,"") -> 0.11109314 | D22: 0.11630871 | E22: =IFERROR(C22-D22,"") -> -0.0052155783 | G22: 季節調理麵(111,112) | H22: =SUM('（４）訂單數量構成比'!AI14:AI20) -> 119065 | I22: =IFERROR(H22/$B$7,"") -> 0.092752505 | J22: 0.096470853 | K22: =IFERROR(I22-J22,"") -> -0.0037183474
A23: 微波小吃(153,154,155) | B23: =SUM('（３）業績構成比'!AK14:AK20)/1000 -> 503.8275 | C23: =IFERROR(B23/$B$6,"") -> 0.013113824 | D23: 0.012376287 | E23: =IFERROR(C23-D23,"") -> 0.00073753672 | G23: 微波小吃(153,154,155) | H23: =SUM('（４）訂單數量構成比'!AK14:AK20) -> 25575 | I23: =IFERROR(H23/$B$7,"") -> 0.019923112 | J23: 0.018725521 | K23: =IFERROR(I23-J23,"") -> 0.0011975913
C24: =SUM(C15:C23) -> 1 | D24: =SUM(D15:D23) -> 1 | I24: =SUM(I15:I23) -> 1 | J24: =SUM(J15:J23) -> 1
A26: （５）品群別人時生產性
A27: 品群 | B27: 當週 | C27: 前週 | D27: 差異 | E27: 累計
A28: 18℃-飯糰(061,063) | B28: ='（５-1）品群別人時生產性(18℃-飯糰)'!L47 -> 754.59199 | C28: 754.59133 | D28: =B28-C28 -> 0.00065879724 | E28: ='（５-1）品群別人時生產性(18℃-飯糰)'!C1 -> 754.59166
A29: 18℃-壽司手卷(071,072,075,076) | B29: ='（５-2）品群別人時生產性(18℃-壽司手卷)'!L27 -> 328.28594 | C29: 319.35259 | D29: =B29-C29 -> 8.9333431 | E29: ='（５-2）品群別人時生產性(18℃-壽司手卷)'!C1 -> 323.81927
A30: 4℃-飯糰(065) | B30: ='（５-3）品群別人時生產性(4℃-飯糰)'!L27 -> 361.14748 | C30: 330.92771 | D30: =B30-C30 -> 30.219772 | E30: ='（５-3）品群別人時生產性(4℃-飯糰)'!C1 -> 346.03759
A31: 4℃-壽司手卷(077) | B31: ='（５-4）品群別人時生產性(4℃-壽司手卷)'!L27 -> 375.84262 | C31: 330.46633 | D31: =B31-C31 -> 45.376292 | E31: ='（５-4）品群別人時生產性(4℃-壽司手卷)'!C1 -> 353.15448
A32: 主食(091,092,093,094,095) | B32: ='（５-5）品群別人時生產性(微波主食) '!L27 -> 85.681574 | C32: 84.873929 | D32: =B32-C32 -> 0.80764537 | E32: ='（５-5）品群別人時生產性(微波主食) '!C1 -> 85.277751
A33: 便當(083) | B33: ='（５-6）品群別人時生產性(便當)'!L27 -> 78.595015 | C33: 78.556988 | D33: =B33-C33 -> 0.038026524 | E33: ='（５-6）品群別人時生產性(便當)'!C1 -> 78.576002
A34: 熱食義麵(122,123,124,126) | B34: ='（５-7）品群別人時生產性(熱食義麵) '!L27 -> 0 | C34: 0 | D34: =B34-C34 -> 0 | E34: ='（５-7）品群別人時生產性(熱食義麵) '!C1 -> 0
A35: 季節調理麵(111,112) | B35: ='（５-8）品群別人時生產性(季節調理麵) '!L27 -> 163.7605 | C35: 163.07027 | D35: =B35-C35 -> 0.69022972 | E35: ='（５-8）品群別人時生產性(季節調理麵) '!C1 -> 163.41538
A36: 微波小吃(153,154,155) | B36: ='（５-9）品群別人時生產性(微波小吃)'!L27 -> 83.069668 | C36: 83.100806 | D36: =B36-C36 -> -0.031137924 | E36: ='（５-9）品群別人時生產性(微波小吃)'!C1 -> 83.085237

Sheet （１）收支狀況
B2: （１）收支狀況
B3: 資料繳交日 | C3: 月份 | D3: 日期 | F3: 營業額(元) | I3: 訂單數量(個) | L3: 材料費(元) | O3: 材料費率（材料費／營業額） | R3: 勞務成本（全廠人事成本） | U3: 勞務費率（勞務成本／營業額）
F4: 日 | G4: 週累積 | H4: 月累積 | I4: 日 | J4: 週累積 | K4: 月累積 | L4: 日 | M4: 週累積 | N4: 月累積 | O4: 日 | P4: 週累積 | Q4: 月累積 | R4: 日 | S4: 週累積 | T4: 月累積 | U4: 日 | V4: 週累積 | W4: 月累積
B5: 46148 | D5: 46140 | E5: 二 | F5: 6434818.3 | G5: =SUM(F5:F11) -> 37624281 | I5: 214895 | J5: =SUM(I5:I11) -> 1262288 | L5: 4415081.4 | M5: =SUM(L5:L11) -> 25299965 | O5: =L5/F5 -> 0.68612371 | P5: =M5/G5 -> 0.67243715 | R5: 888285.35 | S5: =SUM(R5:R11) -> 5540839.9 | U5: =R5/F5 -> 0.13804358 | V5: =S5/G5 -> 0.14726766
D6: =D5+1 -> 46141 | E6: 三 | F6: 5586966.6 | I6: 189446 | L6: 3741194.1 | O6: =L6/F6 -> 0.66962887 | R6: 808748.23 | U6: =R6/F6 -> 0.14475623
D7: =D6+1 -> 46142 | E7: 四 | F7: 4446498.9 | I7: 150674 | L7: 2972920 | O7: =L7/F7 -> 0.66859794 | R7: 720191.12 | U7: =R7/F7 -> 0.16196813
C8: 五 | D8: =D7+1 -> 46143 | E8: 五 | F8: 4128529.6 | H8: =SUM(F8:F38) -> 59575570 | I8: 140738 | K8: =SUM(I8:I38) -> 1990958 | L8: 2836938.3 | N8: =SUM(L8:L38) -> 39856822 | O8: =L8/F8 -> 0.68715464 | Q8: =N8/H8 -> 0.66901285 | R8: 715052.78 | T8: =SUM(R8:R38) -> 8636290.6 | U8: =R8/F8 -> 0.17319793 | W8: =T8/H8 -> 0.14496363
D9: =D8+1 -> 46144 | E9: 六 | F9: 4422738.3 | I9: 150228 | L9: 2943355.2 | O9: =L9/F9 -> 0.66550515 | R9: 720724.18 | U9: =R9/F9 -> 0.16295881
D10: =D9+1 -> 46145 | E10: 日 | F10: 6472238.9 | I10: 212432 | L10: 4332663.5 | O10: =L10/F10 -> 0.66942268 | R10: 865468.5 | U10: =R10/F10 -> 0.13372011
D11: =D10+1 -> 46146 | E11: 一 | F11: 6132490.7 | I11: 203875 | L11: 4057812.2 | O11: =L11/F11 -> 0.66169072 | R11: 822369.74 | U11: =R11/F11 -> 0.13410045
B12: =B5+7 -> 46155 | D12: =D11+1 -> 46147 | E12: 二 | F12: 5984383.9 | G12: =SUM(F12:F18) -> 38419573 | I12: 198337 | J12: =SUM(I12:I18) -> 1283685 | L12: 4026441.6 | M12: =SUM(L12:L18) -> 25686053 | O12: =L12/F12 -> 0.67282474 | P12: =M12/G12 -> 0.66856686 | R12: 817348.36 | S12: =SUM(R12:R18) -> 5512675.4 | U12: =R12/F12 -> 0.1365802 | V12: =S12/G12 -> 0.14348612
D13: =D12+1 -> 46148 | E13: 三 | F13: 5601506.9 | I13: 188660 | L13: 3714549.8 | O13: =L13/F13 -> 0.66313402 | R13: 791562.49 | U13: =R13/F13 -> 0.14131242
D14: =D13+1 -> 46149 | E14: 四 | F14: 5146313.4 | I14: 175320 | L14: 3443997.8 | O14: =L14/F14 -> 0.66921649 | R14: 743044.16 | U14: =R14/F14 -> 0.14438378
D15: =D14+1 -> 46150 | E15: 五 | F15: 4462931.7 | I15: 151315 | L15: 3016113.7 | O15: =L15/F15 -> 0.67581443 | R15: 721133.71 | U15: =R15/F15 -> 0.16158296
D16: =D15+1 -> 46151 | E16: 六 | F16: 4779377.8 | I16: 161184 | L16: 3162469.9 | O16: =L16/F16 -> 0.66169072 | R16: 747478.39 | U16: =R16/F16 -> 0.15639659
D17: =D16+1 -> 46152 | E17: 日 | F17: 6245830.3 | I17: 206176 | L17: 4152125 | O17: =L17/F17 -> 0.66478351 | R17: 848777.17 | U17: =R17/F17 -> 0.13589501
D18: =D17+1 -> 46153 | E18: 一 | F18: 6199228.5 | I18: 202693 | L18: 4170355.2 | O18: =L18/F18 -> 0.67272165 | R18: 843331.15 | U18: =R18/F18 -> 0.13603808
B19: =B12+7 -> 46162 | D19: =D18+1 -> 46154 | E19: 二 | G19: =SUM(F19:F25) -> 0 | J19: =SUM(I19:I25) -> 0 | M19: =SUM(L19:L25) -> 0 | O19: =L19/F19 -> #DIV/0! | P19: =M19/G19 -> #DIV/0! | S19: =SUM(R19:R25) -> 0 | U19: =R19/F19 -> #DIV/0! | V19: =S19/G19 -> #DIV/0!
D20: =D19+1 -> 46155 | E20: 三 | O20: =L20/F20 -> #DIV/0! | U20: =R20/F20 -> #DIV/0!
D21: =D20+1 -> 46156 | E21: 四 | O21: =L21/F21 -> #DIV/0! | U21: =R21/F21 -> #DIV/0!
D22: =D21+1 -> 46157 | E22: 五 | O22: =L22/F22 -> #DIV/0! | U22: =R22/F22 -> #DIV/0!
D23: =D22+1 -> 46158 | E23: 六 | O23: =L23/F23 -> #DIV/0! | U23: =R23/F23 -> #DIV/0!
D24: =D23+1 -> 46159 | E24: 日 | O24: =L24/F24 -> #DIV/0! | U24: =R24/F24 -> #DIV/0!
D25: =D24+1 -> 46160 | E25: 一 | O25: =L25/F25 -> #DIV/0! | U25: =R25/F25 -> #DIV/0!
B26: =B19+7 -> 46169 | D26: =D25+1 -> 46161 | E26: 二 | G26: =SUM(F26:F32) -> 0 | J26: =SUM(I26:I32) -> 0 | M26: =SUM(L26:L32) -> 0 | O26: =L26/F26 -> #DIV/0! | P26: =M26/G26 -> #DIV/0! | S26: =SUM(R26:R32) -> 0 | U26: =R26/F26 -> #DIV/0! | V26: =S26/G26 -> #DIV/0!
D27: =D26+1 -> 46162 | E27: 三 | O27: =L27/F27 -> #DIV/0! | U27: =R27/F27 -> #DIV/0!
D28: =D27+1 -> 46163 | E28: 四 | O28: =L28/F28 -> #DIV/0! | U28: =R28/F28 -> #DIV/0!
D29: =D28+1 -> 46164 | E29: 五 | O29: =L29/F29 -> #DIV/0! | U29: =R29/F29 -> #DIV/0!
D30: =D29+1 -> 46165 | E30: 六 | O30: =L30/F30 -> #DIV/0! | U30: =R30/F30 -> #DIV/0!
D31: =D30+1 -> 46166 | E31: 日 | O31: =L31/F31 -> #DIV/0! | U31: =R31/F31 -> #DIV/0!
D32: =D31+1 -> 46167 | E32: 一 | O32: =L32/F32 -> #DIV/0! | U32: =R32/F32 -> #DIV/0!
B33: =B26+7 -> 46176 | D33: =D32+1 -> 46168 | E33: 二 | G33: =SUM(F33:F39) -> 0 | J33: =SUM(I33:I39) -> 0 | M33: =SUM(L33:L39) -> 0 | O33: =L33/F33 -> #DIV/0! | P33: =M33/G33 -> #DIV/0! | S33: =SUM(R33:R39) -> 0 | U33: =R33/F33 -> #DIV/0! | V33: =S33/G33 -> #DIV/0!
D34: =D33+1 -> 46169 | E34: 三 | O34: =L34/F34 -> #DIV/0! | U34: =R34/F34 -> #DIV/0!
D35: =D34+1 -> 46170 | E35: 四 | O35: =L35/F35 -> #DIV/0! | U35: =R35/F35 -> #DIV/0!
D36: =D35+1 -> 46171 | E36: 五 | O36: =L36/F36 -> #DIV/0! | U36: =R36/F36 -> #DIV/0!
D37: =D36+1 -> 46172 | E37: 六 | O37: =L37/F37 -> #DIV/0! | U37: =R37/F37 -> #DIV/0!
D38: =D37+1 -> 46173 | E38: 日 | O38: =L38/F38 -> #DIV/0! | U38: =R38/F38 -> #DIV/0!
C39: 六 | D39: =D38+1 -> 46174 | E39: 一 | O39: =L39/F39 -> #DIV/0! | U39: =R39/F39 -> #DIV/0!
B40: =B33+7 -> 46183 | D40: =D39+1 -> 46175 | E40: 二 | G40: =SUM(F40:F46) -> 0 | J40: =SUM(I40:I46) -> 0 | M40: =SUM(L40:L46) -> 0 | O40: =L40/F40 -> #DIV/0! | P40: =M40/G40 -> #DIV/0! | S40: =SUM(R40:R46) -> 0 | U40: =R40/F40 -> #DIV/0! | V40: =S40/G40 -> #DIV/0!
D41: =D40+1 -> 46176 | E41: 三 | O41: =L41/F41 -> #DIV/0! | U41: =R41/F41 -> #DIV/0!
...

Sheet （２）ＫＰＩ達成進度
B1: 人時生產性基準值 | C1: 442.4
B2: （２）ＫＰＩ達成進度
B3: 資料繳交日 | C3: 月份 | D3: 日期 | F3: 人時生產性(個/人) | I3: 人時生產性達成率(%) | L3: 半成品報廢(%) | O3: 半成品超用(%) | R3: 固定產線-導入率(固定產線數/總產線數) | U3: 教育訓練-實施率(進度/計畫)
F4: 日 | G4: 週平均 | H4: 月平均 | I4: 日 | J4: 週平均 | K4: 月平均 | L4: 日 | M4: 週平均 | N4: 月平均 | O4: 日 | P4: 週平均 | Q4: 月平均 | R4: 日 | S4: 週平均 | T4: 月平均 | U4: 日 | V4: 週平均 | W4: 月平均
B5: 46148 | D5: 46140 | E5: 二 | F5: 399.7543 | G5: =AVERAGE(F5:F11) -> 409.72046 | I5: =F5/$C$1 -> 0.90360376 | J5: =AVERAGE(I5:I11) -> 0.92613124 | L5: 0.0019999699 | M5: =AVERAGE(L5:L11) -> 0.0020023819 | O5: 0.0042745687 | P5: =AVERAGE(O5:O11) -> 0.0053888197 | R5: 0.9 | S5: =AVERAGE(R5:R11) -> 0.9 | U5: =18/52*100% -> 0.34615385 | V5: =AVERAGE(U5:U11) -> 0.34615385
D6: =D5+1 -> 46141 | E6: 三 | F6: 399.78289 | I6: =F6/$C$1 -> 0.90366837 | L6: 0.0020001055 | O6: 0.0041835264 | R6: 0.9 | U6: =18/52*100% -> 0.34615385
D7: =D6+1 -> 46142 | E7: 四 | F7: 417.06453 | I7: =F7/$C$1 -> 0.94273176 | L7: 0.001999582 | O7: 0.0041803774 | R7: 0.9 | U7: =18/52*100% -> 0.34615385
C8: 五 | D8: =D7+1 -> 46143 | E8: 五 | F8: 421.58555 | H8: =AVERAGEIF(F8:F38,"<>0") -> 411.48779 | I8: =F8/$C$1 -> 0.95295107 | K8: =AVERAGEIF(I8:I38,"<>0") -> 0.9301261 | L8: 0.0019983887 | N8: =AVERAGEIF(L8:L38,"<>0") -> 0.0020045261 | O8: 0.0064823776 | Q8: =AVERAGEIF(O8:O38,"<>0") -> 0.0061668044 | R8: 0.9 | T8: =AVERAGEIF(R8:R38,"<>0") -> 0.9 | U8: =18/52*100% -> 0.34615385 | W8: =AVERAGEIF(U8:U38,"<>0") -> 0.35839161
D9: =D8+1 -> 46144 | E9: 六 | F9: 423.28012 | I9: =F9/$C$1 -> 0.95678145 | L9: 0.00200407 | O9: 0.0063600143 | R9: 0.9 | U9: =18/52*100% -> 0.34615385
D10: =D9+1 -> 46145 | E10: 日 | F10: 403.2986 | I10: =F10/$C$1 -> 0.91161527 | L10: 0.002008357 | O10: 0.0061243973 | R10: 0.9 | U10: =18/52*100% -> 0.34615385
D11: =D10+1 -> 46146 | E11: 一 | F11: 403.27725 | I11: =F11/$C$1 -> 0.91156702 | L11: 0.0020062 | O11: 0.0061164763 | R11: 0.9 | U11: =18/52*100% -> 0.34615385
B12: =B5+7 -> 46155 | D12: =D11+1 -> 46147 | E12: 二 | F12: 403.07321 | G12: =AVERAGE(F12:F18) -> 410.70345 | I12: =F12/$C$1 -> 0.91110581 | J12: =AVERAGE(I12:I18) -> 0.92835318 | L12: 0.0020043146 | M12: =AVERAGE(L12:L18) -> 0.0020046816 | O12: 0.0060261623 | P12: =AVERAGE(O12:O18) -> 0.0061073691 | R12: 0.9 | S12: =AVERAGE(R12:R18) -> 0.9 | U12: =19/52*100% -> 0.36538462 | V12: =AVERAGE(U12:U18) -> 0.36538462
D13: =D12+1 -> 46148 | E13: 三 | F13: 403.85733 | I13: =F13/$C$1 -> 0.91287823 | L13: 0.0020041882 | O13: 0.0060278412 | R13: 0.9 | U13: =19/52*100% -> 0.36538462
D14: =D13+1 -> 46149 | E14: 四 | F14: 403.86519 | I14: =F14/$C$1 -> 0.91289599 | L14: 0.0020039731 | O14: 0.0062019901 | R14: 0.9 | U14: =19/52*100% -> 0.36538462
D15: =D14+1 -> 46150 | E15: 五 | F15: 405.06555 | I15: =F15/$C$1 -> 0.91560928 | L15: 0.0020003209 | O15: 0.0060802079 | R15: 0.9 | U15: =19/52*100% -> 0.36538462
D16: =D15+1 -> 46151 | E16: 六 | F16: 425.49494 | I16: =F16/$C$1 -> 0.96178784 | L16: 0.0019998526 | O16: 0.0061100532 | R16: 0.9 | U16: =19/52*100% -> 0.36538462
D17: =D16+1 -> 46152 | E17: 日 | F17: 426.57471 | I17: =F17/$C$1 -> 0.96422854 | L17: 0.0020079386 | O17: 0.0061516535 | R17: 0.9 | U17: =19/52*100% -> 0.36538462
D18: =D17+1 -> 46153 | E18: 一 | F18: 406.99321 | I18: =F18/$C$1 -> 0.91996656 | L18: 0.0020121832 | O18: 0.0061536753 | R18: 0.9 | U18: =19/52*100% -> 0.36538462
B19: =B12+7 -> 46162 | D19: =D18+1 -> 46154 | E19: 二 | G19: =AVERAGE(F19:F25) -> #DIV/0! | I19: =F19/$C$1 -> 0 | J19: =AVERAGE(I19:I25) -> 0 | M19: =AVERAGE(L19:L25) -> #DIV/0! | P19: =AVERAGE(O19:O25) -> #DIV/0! | S19: =AVERAGE(R19:R25) -> #DIV/0! | V19: =AVERAGE(U19:U25) -> #DIV/0!
D20: =D19+1 -> 46155 | E20: 三 | I20: =F20/$C$1 -> 0
D21: =D20+1 -> 46156 | E21: 四 | I21: =F21/$C$1 -> 0
D22: =D21+1 -> 46157 | E22: 五 | I22: =F22/$C$1 -> 0
D23: =D22+1 -> 46158 | E23: 六 | I23: =F23/$C$1 -> 0
D24: =D23+1 -> 46159 | E24: 日 | I24: =F24/$C$1 -> 0
D25: =D24+1 -> 46160 | E25: 一 | I25: =F25/$C$1 -> 0
B26: =B19+7 -> 46169 | D26: =D25+1 -> 46161 | E26: 二 | G26: =AVERAGE(F26:F32) -> #DIV/0! | I26: =F26/$C$1 -> 0 | J26: =AVERAGE(I26:I32) -> 0 | M26: =AVERAGE(L26:L32) -> #DIV/0! | P26: =AVERAGE(O26:O32) -> #DIV/0! | S26: =AVERAGE(R26:R32) -> #DIV/0! | V26: =AVERAGE(U26:U32) -> #DIV/0!
D27: =D26+1 -> 46162 | E27: 三 | I27: =F27/$C$1 -> 0
D28: =D27+1 -> 46163 | E28: 四 | I28: =F28/$C$1 -> 0
D29: =D28+1 -> 46164 | E29: 五 | I29: =F29/$C$1 -> 0
D30: =D29+1 -> 46165 | E30: 六 | I30: =F30/$C$1 -> 0
D31: =D30+1 -> 46166 | E31: 日 | I31: =F31/$C$1 -> 0
D32: =D31+1 -> 46167 | E32: 一 | I32: =F32/$C$1 -> 0
B33: =B26+7 -> 46176 | D33: =D32+1 -> 46168 | E33: 二 | G33: =AVERAGE(F33:F39) -> #DIV/0! | I33: =F33/$C$1 -> 0 | J33: =AVERAGE(I33:I39) -> 0 | M33: =AVERAGE(L33:L39) -> #DIV/0! | P33: =AVERAGE(O33:O39) -> #DIV/0! | S33: =AVERAGE(R33:R39) -> #DIV/0! | V33: =AVERAGE(U33:U39) -> #DIV/0!
D34: =D33+1 -> 46169 | E34: 三 | I34: =F34/$C$1 -> 0
D35: =D34+1 -> 46170 | E35: 四 | I35: =F35/$C$1 -> 0
D36: =D35+1 -> 46171 | E36: 五 | I36: =F36/$C$1 -> 0
D37: =D36+1 -> 46172 | E37: 六 | I37: =F37/$C$1 -> 0
D38: =D37+1 -> 46173 | E38: 日 | I38: =F38/$C$1 -> 0
D39: =D38+1 -> 46174 | E39: 一 | I39: =F39/$C$1 -> 0
B40: =B33+7 -> 46183 | D40: =D39+1 -> 46175 | E40: 二 | G40: =AVERAGE(F40:F46) -> #DIV/0! | I40: =F40/$C$1 -> 0 | J40: =AVERAGE(I40:I46) -> 0 | M40: =AVERAGE(L40:L46) -> #DIV/0! | P40: =AVERAGE(O40:O46) -> #DIV/0! | S40: =AVERAGE(R40:R46) -> #DIV/0! | V40: =AVERAGE(U40:U46) -> #DIV/0!
...

Sheet （３）業績構成比
B2: （3）業績構成比
B3: 資料繳交日 | C3: 月份 | D3: 日期 | F3: 營業額 | I3: 品類業績
I4: 18℃-飯糰 | O4: 18℃-壽司手卷 | U4: 4℃-飯糰 | W4: 4℃-壽司手卷 | Y4: 主食 | AE4: 便當 | AG4: 熱食義麵 | AI4: 季節調理麵 | AK4: 微波小吃
F5: 日 | G5: 週累積 | H5: 月累積 | I5: 一配 | K5: 二配 | M5: 合計 | O5: 一配 | Q5: 二配 | S5: 合計 | U5: 一配 | W5: 一配 | Y5: 一配 | AA5: 二配 | AC5: 合計 | AE5: 一配 | AG5: 一配 | AI5: 一配 | AK5: 一配
I6: 業績(元) | J6: 比例(%) | K6: 業績(元) | L6: 比例(%) | M6: 業績(元) | N6: 比例(%) | O6: 業績(元) | P6: 比例(%) | Q6: 業績(元) | R6: 比例(%) | S6: 業績(元) | T6: 比例(%) | U6: 業績(元) | V6: 比例(%) | W6: 業績(元) | X6: 比例(%) | Y6: 業績(元) | Z6: 比例(%) | AA6: 業績(元) | AB6: 比例(%) | AC6: 業績(元) | AD6: 比例(%) | AE6: 業績(元) | AF6: 比例(%) | AG6: 業績(元) | AH6: 比例(%) | AI6: 業績(元) | AJ6: 比例(%) | AK6: 業績(元) | AL6: 比例(%)
B7: =D8+7 -> 46148 | D7: 46140 | E7: 二 | F7: =SUM(M7,S7,U7,W7,AC7,AE7,AG7,AI7,AK7) -> 6434818.3 | G7: =SUM(F7:F13) -> 37624281 | I7: 1196648 | J7: =I7/$F7 -> 0.18596453 | K7: 1283344.1 | L7: =K7/$F7 -> 0.19943751 | M7: =I7+K7 -> 2479992.1 | N7: =M7/$F7 -> 0.38540204 | O7: 293690.21 | P7: =O7/$F7 -> 0.045640793 | Q7: 0 | R7: =Q7/$F7 -> 0 | S7: =O7+Q7 -> 293690.21 | T7: =S7/$F7 -> 0.045640793 | U7: 106373.61 | V7: =U7/$F7 -> 0.016530942 | W7: 124844.22 | X7: =W7/$F7 -> 0.019401359 | Y7: 224979.51 | Z7: =Y7/$F7 -> 0.034962838 | AA7: 654753.21 | AB7: =AA7/$F7 -> 0.10175162 | AC7: =Y7+AA7 -> 879732.72 | AD7: =AC7/$F7 -> 0.13671446 | AE7: 1635891.8 | AF7: =AE7/F7 -> 0.25422501 | AG7: 0 | AH7: =AG7/$F7 -> 0 | AI7: 840773.25 | AJ7: =AI7/$F7 -> 0.13065998 | AK7: 73520.4 | AL7: =AK7/$F7 -> 0.011425404
D8: 46141 | E8: 三 | F8: =SUM(M8,S8,U8,W8,AC8,AE8,AG8,AI8,AK8) -> 5586966.6 | I8: 1152282.1 | J8: =I8/$F8 -> 0.20624468 | K8: 1052758.5 | L8: =K8/$F8 -> 0.18843114 | M8: =I8+K8 -> 2205040.6 | N8: =M8/F8 -> 0.39467583 | O8: 273819.69 | P8: =O8/$F8 -> 0.04901044 | Q8: 0 | R8: =Q8/$F8 -> 0 | S8: =O8+Q8 -> 273819.69 | T8: =S8/F8 -> 0.04901044 | U8: 96518.21 | V8: =U8/F8 -> 0.017275602 | W8: 143424.39 | X8: =W8/$F8 -> 0.025671245 | Y8: 174567.75 | Z8: =Y8/$F8 -> 0.031245533 | AA8: 510976.59 | AB8: =AA8/$F8 -> 0.091458681 | AC8: =Y8+AA8 -> 685544.34 | AD8: =AC8/$F8 -> 0.12270421 | AE8: 1433507.4 | AF8: =AE8/F8 -> 0.25658062 | AG8: 0 | AH8: =AG8/$F8 -> 0 | AI8: 685934.02 | AJ8: =AI8/$F8 -> 0.12277396 | AK8: 63177.9 | AL8: =AK8/$F8 -> 0.011308086
D9: 46142 | E9: 四 | F9: =SUM(M9,S9,U9,W9,AC9,AE9,AG9,AI9,AK9) -> 4446498.9 | I9: 762684.46 | J9: =I9/$F9 -> 0.17152472 | K9: 930428.7 | L9: =K9/$F9 -> 0.20924973 | M9: =I9+K9 -> 1693113.2 | N9: =M9/$F9 -> 0.38077445 | O9: 194141.89 | P9: =O9/$F9 -> 0.043661743 | Q9: 0 | R9: =Q9/$F9 -> 0 | S9: =O9+Q9 -> 194141.89 | T9: =S9/$F9 -> 0.043661743 | U9: 84496.43 | V9: =U9/$F9 -> 0.019002913 | W9: 104062.92 | X9: =W9/$F9 -> 0.023403339 | Y9: 149475.41 | Z9: =Y9/$F9 -> 0.033616428 | AA9: 454301.42 | AB9: =AA9/$F9 -> 0.10217059 | AC9: =Y9+AA9 -> 603776.83 | AD9: =AC9/$F9 -> 0.13578702 | AE9: 1085516.3 | AF9: =AE9/F9 -> 0.24412831 | AG9: 0 | AH9: =AG9/$F9 -> 0 | AI9: 613958.28 | AJ9: =AI9/$F9 -> 0.13807679 | AK9: 67433.1 | AL9: =AK9/$F9 -> 0.015165437
C10: 五 | D10: 46143 | E10: 五 | F10: =SUM(M10,S10,U10,W10,AC10,AE10,AG10,AI10,AK10) -> 4128529.6 | H10: =SUM(F10:F20) -> 59575570 | I10: 735223.63 | J10: =I10/$F10 -> 0.17808365 | K10: 904301.05 | L10: =K10/$F10 -> 0.21903708 | M10: =I10+K10 -> 1639524.7 | N10: =M10/F10 -> 0.39712073 | O10: 189738.31 | P10: =O10/$F10 -> 0.045957842 | Q10: 0 | R10: =Q10/$F10 -> 0 | S10: =O10+Q10 -> 189738.31 | T10: =S10/F10 -> 0.045957842 | U10: 74886.61 | V10: =U10/F10 -> 0.018138809 | W10: 51528.84 | X10: =W10/$F10 -> 0.01248116 | Y10: 153506.08 | Z10: =Y10/$F10 -> 0.03718178 | AA10: 528791.28 | AB10: =AA10/$F10 -> 0.12808223 | AC10: =Y10+AA10 -> 682297.36 | AD10: =AC10/$F10 -> 0.16526401 | AE10: 951820.67 | AF10: =AE10/F10 -> 0.23054714 | AG10: 0 | AH10: =AG10/$F10 -> 0 | AI10: 473191.21 | AJ10: =AI10/$F10 -> 0.11461495 | AK10: 65541.9 | AL10: =AK10/$F10 -> 0.015875362
D11: 46144 | E11: 六 | F11: =SUM(M11,S11,U11,W11,AC11,AE11,AG11,AI11,AK11) -> 4422738.3 | I11: 696928.85 | J11: =I11/$F11 -> 0.15757859 | K11: 1077661 | L11: =K11/$F11 -> 0.24366374 | M11: =I11+K11 -> 1774589.8 | N11: =M11/$F11 -> 0.40124233 | O11: 185451.79 | P11: =O11/$F11 -> 0.041931441 | Q11: 0 | R11: =Q11/$F11 -> 0 | S11: =O11+Q11 -> 185451.79 | T11: =S11/$F11 -> 0.041931441 | U11: 77677.25 | V11: =U11/$F11 -> 0.017563158 | W11: 43769.16 | X11: =W11/$F11 -> 0.0098963938 | Y11: 182174.93 | Z11: =Y11/$F11 -> 0.041190529 | AA11: 591196.37 | AB11: =AA11/$F11 -> 0.13367202 | AC11: =Y11+AA11 -> 773371.3 | AD11: =AC11/$F11 -> 0.17486255 | AE11: 1049970.1 | AF11: =AE11/F11 -> 0.23740271 | AG11: 0 | AH11: =AG11/$F11 -> 0 | AI11: 455262.94 | AJ11: =AI11/$F11 -> 0.10293689 | AK11: 62646 | AL11: =AK11/$F11 -> 0.014164528
D12: 46145 | E12: 日 | F12: =SUM(M12,S12,U12,W12,AC12,AE12,AG12,AI12,AK12) -> 6472238.9 | I12: 1156742.1 | J12: =I12/$F12 -> 0.17872364 | K12: 1287660.1 | L12: =K12/$F12 -> 0.19895127 | M12: =I12+K12 -> 2444402.2 | N12: =M12/F12 -> 0.37767491 | O12: 295800.71 | P12: =O12/$F12 -> 0.045702997 | Q12: 0 | R12: =Q12/$F12 -> 0 | S12: =O12+Q12 -> 295800.71 | T12: =S12/F12 -> 0.045702997 | U12: 113189.96 | V12: =U12/F12 -> 0.017488533 | W12: 63000.24 | X12: =W12/$F12 -> 0.0097339176 | Y12: 232813.77 | Z12: =Y12/$F12 -> 0.035971134 | AA12: 696145.05 | AB12: =AA12/$F12 -> 0.10755862 | AC12: =Y12+AA12 -> 928958.82 | AD12: =AC12/$F12 -> 0.14352975 | AE12: 1880462.7 | AF12: =AE12/F12 -> 0.29054285 | AG12: 0 | AH12: =AG12/$F12 -> 0 | AI12: 683482.69 | AJ12: =AI12/$F12 -> 0.1056022 | AK12: 62941.5 | AL12: =AK12/$F12 -> 0.009724842
D13: 46146 | E13: 一 | F13: =SUM(M13,S13,U13,W13,AC13,AE13,AG13,AI13,AK13) -> 6132490.7 | I13: 1117910.6 | J13: =I13/$F13 -> 0.18229309 | K13: 1252098.1 | L13: =K13/$F13 -> 0.20417448 | M13: =I13+K13 -> 2370008.7 | N13: =M13/$F13 -> 0.38646756 | O13: 275130.65 | P13: =O13/$F13 -> 0.044864422 | Q13: 0 | R13: =Q13/$F13 -> 0 | S13: =O13+Q13 -> 275130.65 | T13: =S13/$F13 -> 0.044864422 | U13: 106413.37 | V13: =U13/$F13 -> 0.01735239 | W13: 63885 | X13: =W13/$F13 -> 0.010417464 | Y13: 228328.94 | Z13: =Y13/$F13 -> 0.03723266 | AA13: 684259.9 | AB13: =AA13/$F13 -> 0.11157944 | AC13: =Y13+AA13 -> 912588.84 | AD13: =AC13/$F13 -> 0.1488121 | AE13: 1710646.6 | AF13: =AE13/F13 -> 0.2789481 | AG13: 0 | AH13: =AG13/$F13 -> 0 | AI13: 623429.36 | AJ13: =AI13/$F13 -> 0.10166006 | AK13: 70388.1 | AL13: =AK13/$F13 -> 0.011477898
B14: =D15+7 -> 46155 | D14: 46147 | E14: 二 | F14: =SUM(M14,S14,U14,W14,AC14,AE14,AG14,AI14,AK14) -> 5984383.9 | G14: =SUM(F14:F20) -> 38419573 | I14: 1056722.8 | J14: =I14/$F14 -> 0.17658004 | K14: 1211356.8 | L14: =K14/$F14 -> 0.20241962 | M14: =I14+K14 -> 2268079.5 | N14: =M14/$F14 -> 0.37899967 | O14: 289161.94 | P14: =O14/$F14 -> 0.048319416 | Q14: 0 | R14: =Q14/$F14 -> 0 | S14: =O14+Q14 -> 289161.94 | T14: =S14/$F14 -> 0.048319416 | U14: 96983.86 | V14: =U14/$F14 -> 0.016206156 | W14: 51599.28 | X14: =W14/$F14 -> 0.0086223211 | Y14: 223730.57 | Z14: =Y14/$F14 -> 0.037385731 | AA14: 660245.14 | AB14: =AA14/$F14 -> 0.110328 | AC14: =Y14+AA14 -> 883975.71 | AD14: =AC14/$F14 -> 0.14771374 | AE14: 1692750.4 | AF14: =AE14/F14 -> 0.28286126 | AG14: 0 | AH14: =AG14/$F14 -> 0 | AI14: 630913.25 | AJ14: =AI14/$F14 -> 0.1054266 | AK14: 70920 | AL14: =AK14/$F14 -> 0.011850844
D15: 46148 | E15: 三 | F15: =SUM(M15,S15,U15,W15,AC15,AE15,AG15,AI15,AK15) -> 5601506.9 | I15: 1042367.5 | J15: =I15/$F15 -> 0.18608698 | K15: 1158816.9 | L15: =K15/$F15 -> 0.20687592 | M15: =I15+K15 -> 2201184.4 | N15: =M15/F15 -> 0.3929629 | O15: 283443.26 | P15: =O15/$F15 -> 0.050601252 | Q15: 0 | R15: =Q15/$F15 -> 0 | S15: =O15+Q15 -> 283443.26 | T15: =S15/F15 -> 0.050601252 | U15: 94909.73 | V15: =U15/F15 -> 0.016943607 | W15: 58081.08 | X15: =W15/$F15 -> 0.010368831 | Y15: 195118.49 | Z15: =Y15/$F15 -> 0.034833214 | AA15: 608668.34 | AB15: =AA15/$F15 -> 0.10866154 | AC15: =Y15+AA15 -> 803786.83 | AD15: =AC15/$F15 -> 0.14349475 | AE15: 1525813.4 | AF15: =AE15/F15 -> 0.27239339 | AG15: 0 | AH15: =AG15/$F15 -> 0 | AI15: 556867.15 | AJ15: =AI15/$F15 -> 0.099413812 | AK15: 77421 | AL15: =AK15/$F15 -> 0.013821459
D16: 46149 | E16: 四 | F16: =SUM(M16,S16,U16,W16,AC16,AE16,AG16,AI16,AK16) -> 5146313.4 | I16: 1025270.3 | J16: =I16/$F16 -> 0.19922422 | K16: 1038831.9 | L16: =K16/$F16 -> 0.20185943 | M16: =I16+K16 -> 2064102.2 | N16: =M16/$F16 -> 0.40108365 | O16: 290629.81 | P16: =O16/$F16 -> 0.056473399 | Q16: 0 | R16: =Q16/$F16 -> 0 | S16: =O16+Q16 -> 290629.81 | T16: =S16/$F16 -> 0.056473399 | U16: 90950.97 | V16: =U16/$F16 -> 0.017673034 | W16: 54794.67 | X16: =W16/$F16 -> 0.010647364 | Y16: 184729.58 | Z16: =Y16/$F16 -> 0.035895517 | AA16: 503106.35 | AB16: =AA16/$F16 -> 0.097760535 | AC16: =Y16+AA16 -> 687835.93 | AD16: =AC16/$F16 -> 0.13365605 | AE16: 1344665.1 | AF16: =AE16/F16 -> 0.26128706 | AG16: 0 | AH16: =AG16/$F16 -> 0 | AI16: 540819.06 | AJ16: =AI16/$F16 -> 0.10508864 | AK16: 72515.7 | AL16: =AK16/$F16 -> 0.014090805
D17: 46150 | E17: 五 | F17: =SUM(M17,S17,U17,W17,AC17,AE17,AG17,AI17,AK17) -> 4462931.7 | I17: 777175.74 | J17: =I17/$F17 -> 0.17414018 | K17: 961676.78 | L17: =K17/$F17 -> 0.21548095 | M17: =I17+K17 -> 1738852.5 | N17: =M17/F17 -> 0.38962113 | O17: 226043.27 | P17: =O17/$F17 -> 0.050649054 | Q17: 0 | R17: =Q17/$F17 -> 0 | S17: =O17+Q17 -> 226043.27 | T17: =S17/F17 -> 0.050649054 | U17: 79333.32 | V17: =U17/F17 -> 0.017776055 | W17: 34375.92 | X17: =W17/$F17 -> 0.0077025422 | Y17: 173545.89 | Z17: =Y17/$F17 -> 0.038886073 | AA17: 503735.33 | AB17: =AA17/$F17 -> 0.11287095 | AC17: =Y17+AA17 -> 677281.22 | AD17: =AC17/$F17 -> 0.15175702 | AE17: 1077397.9 | AF17: =AE17/F17 -> 0.24141036 | AG17: 0 | AH17: =AG17/$F17 -> 0 | AI17: 559614.05 | AJ17: =AI17/$F17 -> 0.12539158 | AK17: 70033.5 | AL17: =AK17/$F17 -> 0.015692263
D18: 46151 | E18: 六 | F18: =SUM(M18,S18,U18,W18,AC18,AE18,AG18,AI18,AK18) -> 4779377.8 | I18: 749797.69 | J18: =I18/$F18 -> 0.15688186 | K18: 1107396.2 | L18: =K18/$F18 -> 0.23170301 | M18: =I18+K18 -> 1857193.9 | N18: =M18/$F18 -> 0.38858487 | O18: 219797.09 | P18: =O18/$F18 -> 0.045988642 | Q18: 0 | R18: =Q18/$F18 -> 0 | S18: =O18+Q18 -> 219797.09 | T18: =S18/$F18 -> 0.045988642 | U18: 85618.32 | V18: =U18/$F18 -> 0.017914114 | W18: 35587.35 | X18: =W18/$F18 -> 0.0074460216 | Y18: 199660.09 | Z18: =Y18/$F18 -> 0.041775332 | AA18: 505230.49 | AB18: =AA18/$F18 -> 0.10571052 | AC18: =Y18+AA18 -> 704890.58 | AD18: =AC18/$F18 -> 0.14748585 | AE18: 1227699.5 | AF18: =AE18/F18 -> 0.25687434 | AG18: 0 | AH18: =AG18/$F18 -> 0 | AI18: 581926.2 | AJ18: =AI18/$F18 -> 0.12175773 | AK18: 66664.8 | AL18: =AK18/$F18 -> 0.013948427
D19: 46152 | E19: 日 | F19: =SUM(M19,S19,U19,W19,AC19,AE19,AG19,AI19,AK19) -> 6245830.3 | I19: 1083630 | J19: =I19/$F19 -> 0.17349655 | K19: 1255020.9 | L19: =K19/$F19 -> 0.20093739 | M19: =I19+K19 -> 2338650.9 | N19: =M19/F19 -> 0.37443394 | O19: 295487.26 | P19: =O19/$F19 -> 0.047309524 | Q19: 0 | R19: =Q19/$F19 -> 0 | S19: =O19+Q19 -> 295487.26 | T19: =S19/F19 -> 0.047309524 | U19: 112838.37 | V19: =U19/F19 -> 0.018066192 | W19: 39317.61 | X19: =W19/$F19 -> 0.0062950173 | Y19: 228612.79 | Z19: =Y19/$F19 -> 0.036602466 | AA19: 562910.98 | AB19: =AA19/$F19 -> 0.090125884 | AC19: =Y19+AA19 -> 791523.77 | AD19: =AC19/$F19 -> 0.12672835 | AE19: 1848588.9 | AF19: =AE19/F19 -> 0.29597168 | AG19: 0 | AH19: =AG19/$F19 -> 0 | AI19: 752049.55 | AJ19: =AI19/$F19 -> 0.12040826 | AK19: 67374 | AL19: =AK19/$F19 -> 0.010787037
D20: 46153 | E20: 一 | F20: =SUM(M20,S20,U20,W20,AC20,AE20,AG20,AI20,AK20) -> 6199228.5 | I20: 1050325.2 | J20: =I20/$F20 -> 0.16942837 | K20: 1229086.5 | L20: =K20/$F20 -> 0.19826443 | M20: =I20+K20 -> 2279411.7 | N20: =M20/$F20 -> 0.3676928 | O20: 282914.21 | P20: =O20/$F20 -> 0.045637003 | Q20: 0 | R20: =Q20/$F20 -> 0 | S20: =O20+Q20 -> 282914.21 | T20: =S20/$F20 -> 0.045637003 | U20: 104488.38 | V20: =U20/$F20 -> 0.016855062 | W20: 44479.32 | X20: =W20/$F20 -> 0.0071749767 | Y20: 233551.78 | Z20: =Y20/$F20 -> 0.03767433 | AA20: 861641.65 | AB20: =AA20/$F20 -> 0.13899175 | AC20: =Y20+AA20 -> 1095193.4 | AD20: =AC20/$F20 -> 0.17666608 | AE20: 1667881.5 | AF20: =AE20/F20 -> 0.26904662 | AG20: 0 | AH20: =AG20/$F20 -> 0 | AI20: 645961.52 | AJ20: =AI20/$F20 -> 0.10420031 | AK20: 78898.5 | AL20: =AK20/$F20 -> 0.012727148

Sheet （４）訂單數量構成比
B2: （4）訂單數量構成比
B3: 資料繳交日 | C3: 月份 | D3: 日期 | F3: 訂單量 | I3: 品類訂單量
I4: 18℃-飯糰 | O4: 18℃-壽司手卷 | U4: 4℃-飯糰 | W4: 4℃-壽司手卷 | Y4: 主食 | AE4: 便當 | AG4: 熱食義麵 | AI4: 季節調理麵 | AK4: 微波小吃
F5: 日 | G5: 週累積 | H5: 月累積 | I5: 一配 | K5: 二配 | M5: 合計 | O5: 一配 | Q5: 二配 | S5: 合計 | U5: 一配 | W5: 一配 | Y5: 一配 | AA5: 二配 | AC5: 合計 | AE5: 一配 | AG5: 一配 | AI5: 一配 | AK5: 一配
I6: 訂單數 | J6: 比例(%) | K6: 訂單數 | L6: 比例(%) | M6: 訂單數 | N6: 比例(%) | O6: 訂單數 | P6: 比例(%) | Q6: 訂單數 | R6: 比例(%) | S6: 訂單數 | T6: 比例(%) | U6: 訂單數 | V6: 比例(%) | W6: 訂單數 | X6: 比例(%) | Y6: 訂單數 | Z6: 比例(%) | AA6: 訂單數 | AB6: 比例(%) | AC6: 訂單數 | AD6: 比例(%) | AE6: 訂單數 | AF6: 比例(%) | AG6: 訂單數 | AH6: 比例(%) | AI6: 訂單數 | AJ6: 比例(%) | AK6: 訂單數 | AL6: 比例(%)
B7: =#REF!+7 -> #REF! | D7: 46140 | E7: 二 | F7: =SUM(M7,S7,U7,W7,AC7,AE7,AG7,AI7,AK7) -> 214895 | G7: =SUM(F7:F13) -> 1262288 | I7: 56898 | J7: =I7/$F7 -> 0.26477117 | K7: 67514 | L7: =K7/$F7 -> 0.31417204 | M7: =I7+K7 -> 124412 | N7: =M7/$F7 -> 0.5789432 | O7: 11239 | P7: =O7/$F7 -> 0.05229996 | Q7: 0 | R7: =Q7/$F7 -> 0 | S7: =O7+Q7 -> 11239 | T7: =S7/$F7 -> 0.05229996 | U7: 3808 | V7: =U7/$F7 -> 0.017720282 | W7: 4795 | X7: =W7/$F7 -> 0.022313223 | Y7: 3963 | Z7: =Y7/$F7 -> 0.018441564 | AA7: 13498 | AB7: =AA7/$F7 -> 0.062812071 | AC7: =Y7+AA7 -> 17461 | AD7: =AC7/$F7 -> 0.081253635 | AE7: 26331 | AF7: =AE7/$F7 -> 0.12252961 | AG7: 0 | AH7: =AG7/$F7 -> 0 | AI7: 23117 | AJ7: =AI7/$F7 -> 0.10757347 | AK7: 3732 | AL7: =AK7/$F7 -> 0.017366621
D8: 46141 | E8: 三 | F8: =SUM(M8,S8,U8,W8,AC8,AE8,AG8,AI8,AK8) -> 189446 | I8: 54628 | J8: =I8/$F8 -> 0.28835658 | K8: 56301 | L8: =K8/$F8 -> 0.29718759 | M8: =I8+K8 -> 110929 | N8: =M8/$F8 -> 0.58554417 | O8: 10410 | P8: =O8/$F8 -> 0.054949695 | Q8: 0 | R8: =Q8/$F8 -> 0 | S8: =O8+Q8 -> 10410 | T8: =S8/$F8 -> 0.054949695 | U8: 3448 | V8: =U8/$F8 -> 0.018200437 | W8: 5590 | X8: =W8/$F8 -> 0.029507089 | Y8: 3075 | Z8: =Y8/$F8 -> 0.016231538 | AA8: 10603 | AB8: =AA8/$F8 -> 0.055968455 | AC8: =Y8+AA8 -> 13678 | AD8: =AC8/$F8 -> 0.072199994 | AE8: 23123 | AF8: =AE8/$F8 -> 0.12205589 | AG8: 0 | AH8: =AG8/$F8 -> 0 | AI8: 19061 | AJ8: =AI8/$F8 -> 0.10061442 | AK8: 3207 | AL8: =AK8/$F8 -> 0.016928307
D9: 46142 | E9: 四 | F9: =SUM(M9,S9,U9,W9,AC9,AE9,AG9,AI9,AK9) -> 150674 | I9: 36437 | J9: =I9/$F9 -> 0.24182673 | K9: 49687 | L9: =K9/$F9 -> 0.32976492 | M9: =I9+K9 -> 86124 | N9: =M9/$F9 -> 0.57159165 | O9: 7319 | P9: =O9/$F9 -> 0.048575069 | Q9: 0 | R9: =Q9/$F9 -> 0 | S9: =O9+Q9 -> 7319 | T9: =S9/$F9 -> 0.048575069 | U9: 3009 | V9: =U9/$F9 -> 0.019970267 | W9: 4105 | X9: =W9/$F9 -> 0.027244249 | Y9: 2633 | Z9: =Y9/$F9 -> 0.017474813 | AA9: 9415 | AB9: =AA9/$F9 -> 0.062485897 | AC9: =Y9+AA9 -> 12048 | AD9: =AC9/$F9 -> 0.07996071 | AE9: 17526 | AF9: =AE9/$F9 -> 0.11631735 | AG9: 0 | AH9: =AG9/$F9 -> 0 | AI9: 17120 | AJ9: =AI9/$F9 -> 0.11362279 | AK9: 3423 | AL9: =AK9/$F9 -> 0.022717921
C10: 五 | D10: 46143 | E10: 五 | F10: =SUM(M10,S10,U10,W10,AC10,AE10,AG10,AI10,AK10) -> 140738 | H10: =SUM(F10:F20) -> 1990958 | I10: 35108 | J10: =I10/$F10 -> 0.24945644 | K10: 47984 | L10: =K10/$F10 -> 0.34094559 | M10: =I10+K10 -> 83092 | N10: =M10/$F10 -> 0.59040202 | O10: 7180 | P10: =O10/$F10 -> 0.051016783 | Q10: 0 | R10: =Q10/$F10 -> 0 | S10: =O10+Q10 -> 7180 | T10: =S10/$F10 -> 0.051016783 | U10: 2658 | V10: =U10/$F10 -> 0.018886157 | W10: 2200 | X10: =W10/$F10 -> 0.015631883 | Y10: 2704 | Z10: =Y10/$F10 -> 0.019213006 | AA10: 10892 | AB10: =AA10/$F10 -> 0.077392033 | AC10: =Y10+AA10 -> 13596 | AD10: =AC10/$F10 -> 0.096605039 | AE10: 15422 | AF10: =AE10/$F10 -> 0.1095795 | AG10: 0 | AH10: =AG10/$F10 -> 0 | AI10: 13263 | AJ10: =AI10/$F10 -> 0.09423894 | AK10: 3327 | AL10: =AK10/$F10 -> 0.023639671
D11: 46144 | E11: 六 | F11: =SUM(M11,S11,U11,W11,AC11,AE11,AG11,AI11,AK11) -> 150228 | I11: 33372 | J11: =I11/$F11 -> 0.22214234 | K11: 56972 | L11: =K11/$F11 -> 0.37923689 | M11: =I11+K11 -> 90344 | N11: =M11/$F11 -> 0.60137924 | O11: 6959 | P11: =O11/$F11 -> 0.046322922 | Q11: 0 | R11: =Q11/$F11 -> 0 | S11: =O11+Q11 -> 6959 | T11: =S11/$F11 -> 0.046322922 | U11: 2800 | V11: =U11/$F11 -> 0.018638336 | W11: 1872 | X11: =W11/$F11 -> 0.012461059 | Y11: 3209 | Z11: =Y11/$F11 -> 0.021360865 | AA11: 12056 | AB11: =AA11/$F11 -> 0.080251351 | AC11: =Y11+AA11 -> 15265 | AD11: =AC11/$F11 -> 0.10161222 | AE11: 17040 | AF11: =AE11/$F11 -> 0.11342759 | AG11: 0 | AH11: =AG11/$F11 -> 0 | AI11: 12768 | AJ11: =AI11/$F11 -> 0.084990814 | AK11: 3180 | AL11: =AK11/$F11 -> 0.021167825
D12: 46145 | E12: 日 | F12: =SUM(M12,S12,U12,W12,AC12,AE12,AG12,AI12,AK12) -> 212432 | I12: 55360 | J12: =I12/$F12 -> 0.26060104 | K12: 68288 | L12: =K12/$F12 -> 0.32145816 | M12: =I12+K12 -> 123648 | N12: =M12/$F12 -> 0.5820592 | O12: 11280 | P12: =O12/$F12 -> 0.053099345 | Q12: 0 | R12: =Q12/$F12 -> 0 | S12: =O12+Q12 -> 11280 | T12: =S12/$F12 -> 0.053099345 | U12: 3993 | V12: =U12/$F12 -> 0.018796603 | W12: 2692 | X12: =W12/$F12 -> 0.01267229 | Y12: 4101 | Z12: =Y12/$F12 -> 0.019305001 | AA12: 14261 | AB12: =AA12/$F12 -> 0.06713207 | AC12: =Y12+AA12 -> 18362 | AD12: =AC12/$F12 -> 0.086437072 | AE12: 30259 | AF12: =AE12/$F12 -> 0.14244088 | AG12: 0 | AH12: =AG12/$F12 -> 0 | AI12: 19003 | AJ12: =AI12/$F12 -> 0.089454508 | AK12: 3195 | AL12: =AK12/$F12 -> 0.015040107
D13: 46146 | E13: 一 | F13: =SUM(M13,S13,U13,W13,AC13,AE13,AG13,AI13,AK13) -> 203875 | I13: 53553 | J13: =I13/$F13 -> 0.26267566 | K13: 66674 | L13: =K13/$F13 -> 0.32703372 | M13: =I13+K13 -> 120227 | N13: =M13/$F13 -> 0.58970938 | O13: 10449 | P13: =O13/$F13 -> 0.051251993 | Q13: 0 | R13: =Q13/$F13 -> 0 | S13: =O13+Q13 -> 10449 | T13: =S13/$F13 -> 0.051251993 | U13: 3801 | V13: =U13/$F13 -> 0.018643777 | W13: 2732 | X13: =W13/$F13 -> 0.013400368 | Y13: 4022 | Z13: =Y13/$F13 -> 0.019727774 | AA13: 14040 | AB13: =AA13/$F13 -> 0.068865727 | AC13: =Y13+AA13 -> 18062 | AD13: =AC13/$F13 -> 0.088593501 | AE13: 27589 | AF13: =AE13/$F13 -> 0.13532311 | AG13: 0 | AH13: =AG13/$F13 -> 0 | AI13: 17442 | AJ13: =AI13/$F13 -> 0.085552422 | AK13: 3573 | AL13: =AK13/$F13 -> 0.017525445
B14: =D15+7 -> 46155 | D14: 46147 | E14: 二 | F14: =SUM(M14,S14,U14,W14,AC14,AE14,AG14,AI14,AK14) -> 198337 | G14: =SUM(F14:F20) -> 1283685 | I14: 51170 | J14: =I14/$F14 -> 0.25799523 | K14: 64604 | L14: =K14/$F14 -> 0.32572843 | M14: =I14+K14 -> 115774 | N14: =M14/$F14 -> 0.58372366 | O14: 10926 | P14: =O14/$F14 -> 0.055088057 | Q14: 0 | R14: =Q14/$F14 -> 0 | S14: =O14+Q14 -> 10926 | T14: =S14/$F14 -> 0.055088057 | U14: 3463 | V14: =U14/$F14 -> 0.017460181 | W14: 2204 | X14: =W14/$F14 -> 0.0111124 | Y14: 3941 | Z14: =Y14/$F14 -> 0.019870221 | AA14: 13524 | AB14: =AA14/$F14 -> 0.068186975 | AC14: =Y14+AA14 -> 17465 | AD14: =AC14/$F14 -> 0.088057196 | AE14: 27258 | AF14: =AE14/$F14 -> 0.13743275 | AG14: 0 | AH14: =AG14/$F14 -> 0 | AI14: 17647 | AJ14: =AI14/$F14 -> 0.088974826 | AK14: 3600 | AL14: =AK14/$F14 -> 0.018150925
D15: =D14+1 -> 46148 | E15: 三 | F15: =SUM(M15,S15,U15,W15,AC15,AE15,AG15,AI15,AK15) -> 188660 | I15: 50301 | J15: =I15/$F15 -> 0.2666225 | K15: 61649 | L15: =K15/$F15 -> 0.32677303 | M15: =I15+K15 -> 111950 | N15: =M15/$F15 -> 0.59339553 | O15: 10750 | P15: =O15/$F15 -> 0.056980812 | Q15: 0 | R15: =Q15/$F15 -> 0 | S15: =O15+Q15 -> 10750 | T15: =S15/$F15 -> 0.056980812 | U15: 3404 | V15: =U15/$F15 -> 0.01804304 | W15: 2480 | X15: =W15/$F15 -> 0.013145341 | Y15: 3437 | Z15: =Y15/$F15 -> 0.018217958 | AA15: 12509 | AB15: =AA15/$F15 -> 0.066304463 | AC15: =Y15+AA15 -> 15946 | AD15: =AC15/$F15 -> 0.084522421 | AE15: 24611 | AF15: =AE15/$F15 -> 0.13045161 | AG15: 0 | AH15: =AG15/$F15 -> 0 | AI15: 15589 | AJ15: =AI15/$F15 -> 0.082630128 | AK15: 3930 | AL15: =AK15/$F15 -> 0.020831125
D16: =D15+1 -> 46149 | E16: 四 | F16: =SUM(M16,S16,U16,W16,AC16,AE16,AG16,AI16,AK16) -> 175320 | I16: 49517 | J16: =I16/$F16 -> 0.28243783 | K16: 55273 | L16: =K16/$F16 -> 0.31526922 | M16: =I16+K16 -> 104790 | N16: =M16/$F16 -> 0.59770705 | O16: 10999 | P16: =O16/$F16 -> 0.06273671 | Q16: 0 | R16: =Q16/$F16 -> 0 | S16: =O16+Q16 -> 10999 | T16: =S16/$F16 -> 0.06273671 | U16: 3266 | V16: =U16/$F16 -> 0.018628793 | W16: 2341 | X16: =W16/$F16 -> 0.013352726 | Y16: 3254 | Z16: =Y16/$F16 -> 0.018560347 | AA16: 10334 | AB16: =AA16/$F16 -> 0.058943646 | AC16: =Y16+AA16 -> 13588 | AD16: =AC16/$F16 -> 0.077503993 | AE16: 21569 | AF16: =AE16/$F16 -> 0.12302647 | AG16: 0 | AH16: =AG16/$F16 -> 0 | AI16: 15086 | AJ16: =AI16/$F16 -> 0.086048369 | AK16: 3681 | AL16: =AK16/$F16 -> 0.020995893
D17: =D16+1 -> 46150 | E17: 五 | F17: =SUM(M17,S17,U17,W17,AC17,AE17,AG17,AI17,AK17) -> 151315 | I17: 37424 | J17: =I17/$F17 -> 0.24732512 | K17: 51364 | L17: =K17/$F17 -> 0.33945081 | M17: =I17+K17 -> 88788 | N17: =M17/$F17 -> 0.58677593 | O17: 8469 | P17: =O17/$F17 -> 0.055969335 | Q17: 0 | R17: =Q17/$F17 -> 0 | S17: =O17+Q17 -> 8469 | T17: =S17/$F17 -> 0.055969335 | U17: 2801 | V17: =U17/$F17 -> 0.018511053 | W17: 1468 | X17: =W17/$F17 -> 0.0097016158 | Y17: 3057 | Z17: =Y17/$F17 -> 0.020202888 | AA17: 10274 | AB17: =AA17/$F17 -> 0.067898093 | AC17: =Y17+AA17 -> 13331 | AD17: =AC17/$F17 -> 0.088100981 | AE17: 17380 | AF17: =AE17/$F17 -> 0.11485973 | AG17: 0 | AH17: =AG17/$F17 -> 0 | AI17: 15523 | AJ17: =AI17/$F17 -> 0.10258732 | AK17: 3555 | AL17: =AK17/$F17 -> 0.023494036
D18: =D17+1 -> 46151 | E18: 六 | F18: =SUM(M18,S18,U18,W18,AC18,AE18,AG18,AI18,AK18) -> 161184 | I18: 36162 | J18: =I18/$F18 -> 0.22435229 | K18: 59339 | L18: =K18/$F18 -> 0.36814448 | M18: =I18+K18 -> 95501 | N18: =M18/$F18 -> 0.59249677 | O18: 8234 | P18: =O18/$F18 -> 0.051084475 | Q18: 0 | R18: =Q18/$F18 -> 0 | S18: =O18+Q18 -> 8234 | T18: =S18/$F18 -> 0.051084475 | U18: 3051 | V18: =U18/$F18 -> 0.018928678 | W18: 1521 | X18: =W18/$F18 -> 0.0094364205 | Y18: 3517 | Z18: =Y18/$F18 -> 0.021819784 | AA18: 9935 | AB18: =AA18/$F18 -> 0.061637632 | AC18: =Y18+AA18 -> 13452 | AD18: =AC18/$F18 -> 0.083457415 | AE18: 19828 | AF18: =AE18/$F18 -> 0.12301469 | AG18: 0 | AH18: =AG18/$F18 -> 0 | AI18: 16213 | AJ18: =AI18/$F18 -> 0.10058691 | AK18: 3384 | AL18: =AK18/$F18 -> 0.02099464
D19: =D18+1 -> 46152 | E19: 日 | F19: =SUM(M19,S19,U19,W19,AC19,AE19,AG19,AI19,AK19) -> 206176 | I19: 52910 | J19: =I19/$F19 -> 0.25662541 | K19: 67329 | L19: =K19/$F19 -> 0.3265608 | M19: =I19+K19 -> 120239 | N19: =M19/$F19 -> 0.58318621 | O19: 11202 | P19: =O19/$F19 -> 0.054332221 | Q19: 0 | R19: =Q19/$F19 -> 0 | S19: =O19+Q19 -> 11202 | T19: =S19/$F19 -> 0.054332221 | U19: 3981 | V19: =U19/$F19 -> 0.019308746 | W19: 1679 | X19: =W19/$F19 -> 0.0081435279 | Y19: 4027 | Z19: =Y19/$F19 -> 0.019531856 | AA19: 10888 | AB19: =AA19/$F19 -> 0.05280925 | AC19: =Y19+AA19 -> 14915 | AD19: =AC19/$F19 -> 0.072341107 | AE19: 29764 | AF19: =AE19/$F19 -> 0.1443621 | AG19: 0 | AH19: =AG19/$F19 -> 0 | AI19: 20976 | AJ19: =AI19/$F19 -> 0.10173832 | AK19: 3420 | AL19: =AK19/$F19 -> 0.01658777
D20: =D19+1 -> 46153 | E20: 一 | F20: =SUM(M20,S20,U20,W20,AC20,AE20,AG20,AI20,AK20) -> 202693 | I20: 51286 | J20: =I20/$F20 -> 0.25302304 | K20: 66042 | L20: =K20/$F20 -> 0.3258228 | M20: =I20+K20 -> 117328 | N20: =M20/$F20 -> 0.57884584 | O20: 10684 | P20: =O20/$F20 -> 0.052710256 | Q20: 0 | R20: =Q20/$F20 -> 0 | S20: =O20+Q20 -> 10684 | T20: =S20/$F20 -> 0.052710256 | U20: 3704 | V20: =U20/$F20 -> 0.018273941 | W20: 1900 | X20: =W20/$F20 -> 0.009373782 | Y20: 4114 | Z20: =Y20/$F20 -> 0.020296705 | AA20: 16001 | AB20: =AA20/$F20 -> 0.078942045 | AC20: =Y20+AA20 -> 20115 | AD20: =AC20/$F20 -> 0.09923875 | AE20: 26926 | AF20: =AE20/$F20 -> 0.13284129 | AG20: 0 | AH20: =AG20/$F20 -> 0 | AI20: 18031 | AJ20: =AI20/$F20 -> 0.088957191 | AK20: 4005 | AL20: =AK20/$F20 -> 0.019758946

Sheet （５-1）品群別人時生產性(18℃-飯糰)
B1: 5月平均人時性 | C1: =AVERAGE(L7,L47) -> 754.59166
B2: 產線配置圖－每週更新(0428-0504) | N2: 資料繳交 | O2: 日期 | P2: 46140 | U2: 46141 | Z2: 46142 | AE2: 46143 | AJ2: 46144 | AO2: 46145 | AT2: 46146
P3: 46140 | U3: 46141 | Z3: 46142 | AE3: 46143 | AJ3: 46144 | AO3: 46145 | AT3: 46146
B4: 品群 | C4: 商品名稱 | E4: 計畫 | H4: 平均人時性 | I4: 實績 (週平均) | L4: 平均人時性 | M4: 排名 | O4: 日報 | P4: 實際 | T4: 平均人時性 | U4: 實際 | Y4: 平均人時性 | Z4: 實際 | AD4: 平均人時性 | AE4: 實際 | AI4: 平均人時性 | AJ4: 實際 | AN4: 平均人時性 | AO4: 實際 | AS4: 平均人時性 | AT4: 實際 | AX4: 平均人時性
E5: 產線配置圖 | I5: 產線配置圖 | P5: 生產實績 | U5: 生產實績 | Z5: 生產實績 | AE5: 生產實績 | AJ5: 生產實績 | AO5: 生產實績 | AT5: 生產實績
E6: 人數 | F6: 產能／時 | G6: 人時性 | I6: 人數 | J6: 產能／時 | K6: 人時性 | P6: 人數 | Q6: 產能／時 | R6: 人時性 | S6: 排名 | U6: 人數 | V6: 產能／時 | W6: 人時性 | X6: 排名 | Z6: 人數 | AA6: 產能／時 | AB6: 人時性 | AC6: 排名 | AE6: 人數 | AF6: 產能／時 | AG6: 人時性 | AH6: 排名 | AJ6: 人數 | AK6: 產能／時 | AL6: 人時性 | AM6: 排名 | AO6: 人數 | AP6: 產能／時 | AQ6: 人時性 | AR6: 排名 | AT6: 人數 | AU6: 產能／時 | AV6: 人時性 | AW6: 排名
B7: 18℃-飯糰 | C7: 1 | D7: 一配鹽蔥燒肉飯糰 | E7: 4 | F7: 3600 | G7: =F7/E7 -> 900 | H7: =AVERAGE(G7:G41) -> 848.69464 | I7: =AVERAGE(P7,U7,Z7,AE7,AJ7,AO7,AT7) -> 4 | J7: =AVERAGE(Q7,V7,AA7,AF7,AK7,AP7,AU7) -> 3183.5771 | K7: =AVERAGE(R7,W7,AB7,AG7,AL7,AQ7,AV7) -> 795.89426 | L7: =IFERROR(AVERAGE(K7:K41),"-") -> 754.59133 | M7: =RANK(K7, K$7:$K$41) -> 17 | P7: 4 | Q7: 3179.3643 | R7: =IFERROR(Q7/P7,"") -> 794.84108 | S7: =RANK(R7, R$7:R$41) -> 17 | T7: =AVERAGE(R7:R41) -> 754.59534 | U7: 4 | V7: 3179.0043 | W7: =IFERROR(V7/U7,"") -> 794.75108 | X7: =RANK(W7, W$7:W$41) -> 17 | Y7: =AVERAGE(W7:W41) -> 754.62263 | Z7: 4 | AA7: 3184.6142 | AB7: =IFERROR(AA7/Z7,"") -> 796.15354 | AC7: =RANK(AB7, AB$7:AB$41) -> 16 | AD7: =AVERAGE(AB7:AB41) -> 754.7045 | AE7: 4 | AF7: 3184.6142 | AG7: =IFERROR(AF7/AE7,"") -> 796.15354 | AH7: =RANK(AG7, AG$7:AG$41) -> 16 | AI7: =AVERAGE(AG7:AG41) -> 754.61017 | AJ7: 4 | AK7: 3186.0542 | AL7: =IFERROR(AK7/AJ7,"") -> 796.51354 | AM7: =RANK(AL7, AL$7:AL$41) -> 15 | AN7: =AVERAGE(AL7:AL41) -> 754.60773 | AO7: 4 | AP7: 3186.4142 | AQ7: =IFERROR(AP7/AO7,"") -> 796.60354 | AR7: =RANK(AQ7, AQ$7:AQ$41) -> 15 | AS7: =AVERAGE(AQ7:AQ41) -> 754.5317 | AT7: 4 | AU7: 3184.9742 | AV7: =IFERROR(AU7/AT7,"") -> 796.24354 | AW7: =RANK(AV7, AV$7:AV$41) -> 16 | AX7: =AVERAGE(AV7:AV41) -> 754.46724
C8: 2 | D8: 一配鮪魚飯糰 | E8: 3 | F8: 3600 | G8: =F8/E8 -> 1200 | I8: =AVERAGE(P8,U8,Z8,AE8,AJ8,AO8,AT8) -> 3 | J8: =AVERAGE(Q8,V8,AA8,AF8,AK8,AP8,AU8) -> 3181.5653 | K8: =AVERAGE(R8,W8,AB8,AG8,AL8,AQ8,AV8) -> 1060.5218 | M8: =RANK(K8, K$7:$K$41) -> 6 | P8: 3 | Q8: 3182.6453 | R8: =IFERROR(Q8/P8,"") -> 1060.8818 | S8: =RANK(R8, R$7:R$41) -> 5 | U8: 3 | V8: 3181.9253 | W8: =IFERROR(V8/U8,"") -> 1060.6418 | X8: =RANK(W8, W$7:W$41) -> 6 | Z8: 3 | AA8: 3181.5653 | AB8: =IFERROR(AA8/Z8,"") -> 1060.5218 | AC8: =RANK(AB8, AB$7:AB$41) -> 6 | AE8: 3 | AF8: 3181.5653 | AG8: =IFERROR(AF8/AE8,"") -> 1060.5218 | AH8: =RANK(AG8, AG$7:AG$41) -> 6 | AJ8: 3 | AK8: 3181.5653 | AL8: =IFERROR(AK8/AJ8,"") -> 1060.5218 | AM8: =RANK(AL8, AL$7:AL$41) -> 6 | AO8: 3 | AP8: 3181.5653 | AQ8: =IFERROR(AP8/AO8,"") -> 1060.5218 | AR8: =RANK(AQ8, AQ$7:AQ$41) -> 6 | AT8: 3 | AU8: 3180.1253 | AV8: =IFERROR(AU8/AT8,"") -> 1060.0418 | AW8: =RANK(AV8, AV$7:AV$41) -> 6
C9: 3 | D9: 一配雞肉飯飯糰 | E9: 5 | F9: 3600 | G9: =F9/E9 -> 720 | I9: =AVERAGE(P9,U9,Z9,AE9,AJ9,AO9,AT9) -> 5 | J9: =AVERAGE(Q9,V9,AA9,AF9,AK9,AP9,AU9) -> 3185.2615 | K9: =AVERAGE(R9,W9,AB9,AG9,AL9,AQ9,AV9) -> 637.05231 | M9: =RANK(K9, K$7:$K$41) -> 24 | P9: 5 | Q9: 3183.6158 | R9: =IFERROR(Q9/P9,"") -> 636.72317 | S9: =RANK(R9, R$7:R$41) -> 24 | U9: 5 | V9: 3184.6958 | W9: =IFERROR(V9/U9,"") -> 636.93917 | X9: =RANK(W9, W$7:W$41) -> 24 | Z9: 5 | AA9: 3184.6958 | AB9: =IFERROR(AA9/Z9,"") -> 636.93917 | AC9: =RANK(AB9, AB$7:AB$41) -> 24 | AE9: 5 | AF9: 3186.1358 | AG9: =IFERROR(AF9/AE9,"") -> 637.22717 | AH9: =RANK(AG9, AG$7:AG$41) -> 24 | AJ9: 5 | AK9: 3185.0558 | AL9: =IFERROR(AK9/AJ9,"") -> 637.01117 | AM9: =RANK(AL9, AL$7:AL$41) -> 24 | AO9: 5 | AP9: 3185.7758 | AQ9: =IFERROR(AP9/AO9,"") -> 637.15517 | AR9: =RANK(AQ9, AQ$7:AQ$41) -> 24 | AT9: 5 | AU9: 3186.8558 | AV9: =IFERROR(AU9/AT9,"") -> 637.37117 | AW9: =RANK(AV9, AV$7:AV$41) -> 22
C10: 4 | D10: 一配壹號醬炙烤牛飯糰 | E10: 5 | F10: 3300 | G10: =F10/E10 -> 660 | I10: =AVERAGE(P10,U10,Z10,AE10,AJ10,AO10,AT10) -> 5 | J10: =AVERAGE(Q10,V10,AA10,AF10,AK10,AP10,AU10) -> 2952.0175 | K10: =AVERAGE(R10,W10,AB10,AG10,AL10,AQ10,AV10) -> 590.40349 | M10: =RANK(K10, K$7:$K$41) -> 27 | P10: 5 | Q10: 2951.6875 | R10: =IFERROR(Q10/P10,"") -> 590.33749 | S10: =RANK(R10, R$7:R$41) -> 27 | U10: 5 | V10: 2952.6775 | W10: =IFERROR(V10/U10,"") -> 590.53549 | X10: =RANK(W10, W$7:W$41) -> 27 | Z10: 5 | AA10: 2951.3575 | AB10: =IFERROR(AA10/Z10,"") -> 590.27149 | AC10: =RANK(AB10, AB$7:AB$41) -> 27 | AE10: 5 | AF10: 2952.0175 | AG10: =IFERROR(AF10/AE10,"") -> 590.40349 | AH10: =RANK(AG10, AG$7:AG$41) -> 27 | AJ10: 5 | AK10: 2952.6775 | AL10: =IFERROR(AK10/AJ10,"") -> 590.53549 | AM10: =RANK(AL10, AL$7:AL$41) -> 27 | AO10: 5 | AP10: 2952.3475 | AQ10: =IFERROR(AP10/AO10,"") -> 590.46949 | AR10: =RANK(AQ10, AQ$7:AQ$41) -> 27 | AT10: 5 | AU10: 2951.3575 | AV10: =IFERROR(AU10/AT10,"") -> 590.27149 | AW10: =RANK(AV10, AV$7:AV$41) -> 27
C11: 5 | D11: 一配明太子龍蝦風味沙拉飯糰 | E11: 3 | F11: 3600 | G11: =F11/E11 -> 1200 | I11: =AVERAGE(P11,U11,Z11,AE11,AJ11,AO11,AT11) -> 3 | J11: =AVERAGE(Q11,V11,AA11,AF11,AK11,AP11,AU11) -> 3183.204 | K11: =AVERAGE(R11,W11,AB11,AG11,AL11,AQ11,AV11) -> 1061.068 | M11: =RANK(K11, K$7:$K$41) -> 5 | P11: 3 | Q11: 3183.7183 | R11: =IFERROR(Q11/P11,"") -> 1061.2394 | S11: =RANK(R11, R$7:R$41) -> 4 | U11: 3 | V11: 3182.9983 | W11: =IFERROR(V11/U11,"") -> 1060.9994 | X11: =RANK(W11, W$7:W$41) -> 5 | Z11: 3 | AA11: 3184.4383 | AB11: =IFERROR(AA11/Z11,"") -> 1061.4794 | AC11: =RANK(AB11, AB$7:AB$41) -> 4 | AE11: 3 | AF11: 3183.3583 | AG11: =IFERROR(AF11/AE11,"") -> 1061.1194 | AH11: =RANK(AG11, AG$7:AG$41) -> 4 | AJ11: 3 | AK11: 3182.2783 | AL11: =IFERROR(AK11/AJ11,"") -> 1060.7594 | AM11: =RANK(AL11, AL$7:AL$41) -> 5 | AO11: 3 | AP11: 3182.2783 | AQ11: =IFERROR(AP11/AO11,"") -> 1060.7594 | AR11: =RANK(AQ11, AQ$7:AQ$41) -> 5 | AT11: 3 | AU11: 3183.3583 | AV11: =IFERROR(AU11/AT11,"") -> 1061.1194 | AW11: =RANK(AV11, AV$7:AV$41) -> 4
