Workbook

Sheet 生產管理報表(月)
A1: 大溪廠生產管理報表
A3: 月別 | B3: 2 | C3: 工廠 | D3: 大溪廠
A4: （１）收支狀況 | E4: ※單位：千元 | G4: （２）ＫＰＩ達成進度
A5: 項目 | B5: 當月 | C5: 前月 | D5: 差異 | E5: 累計 | G5: 項目 | H5: KPI | I5: 當月 | J5: 前月 | K5: 累計 | L5: ※補充
A6: 業績金額 | B6: ='（１）收支狀況'!#REF!/1000 -> #REF! | C6: 146299.94 | D6: =B6-C6 -> #REF! | G6: 人時性(個/月均) | I6: ='（２）ＫＰＩ達成進度'!#REF! -> #REF! | J6: 458.38414 | L6: 個／MH
A7: 訂單數量 | B7: ='（１）收支狀況'!#REF! -> #REF! | C7: 4768701 | D7: =B7-C7 -> #REF! | G7: 人時達成率(%/月均) | H7: 0.8 | I7: ='（２）ＫＰＩ達成進度'!#REF! -> #REF! | J7: 0.92118999 | L7: 達成率
A8: 材料費 | B8: ='（１）收支狀況'!#REF!/1000 -> #REF! | C8: 93253 | D8: =B8-C8 -> #REF! | G8: 半成品-報廢(%) | H8: 0.0025 | I8: ='（２）ＫＰＩ達成進度'!#REF! -> #REF! | J8: 0.0024135432 | L8: 報廢率
A9: 材料費率 | B9: ='（１）收支狀況'!#REF! -> #REF! | C9: 0.655 | D9: =B9-C9 -> #REF! | G9: 半成品-超用(%) | H9: 0.004 | I9: ='（２）ＫＰＩ達成進度'!#REF! -> #REF! | J9: 0.0055994433 | L9: 超用率
A10: 勞務成本 | B10: ='（１）收支狀況'!#REF!/1000 -> #REF! | C10: 22378 | D10: =B10-C10 -> #REF! | G10: 固定產線-導入率(%) | H10: 0.8 | I10: ='（２）ＫＰＩ達成進度'!#REF! -> #REF! | J10: 0.9 | L10: 導入率
A11: 勞務費率 | B11: ='（１）收支狀況'!#REF! -> #REF! | C11: 0.157 | D11: =B11-C11 -> #REF! | G11: 教育訓練-實施率(%) | H11: 1 | I11: ='（２）ＫＰＩ達成進度'!#REF! -> #REF! | J11: 0.057692308 | L11: 實施率
A13: （３）業績構成比 | E13: ※單位：千元 | G13: （４）訂單數量構成比 | K13: ※單位：個
B14: 當月 | C14: 比例 | D14: 前月 | E14: 差異 | H14: 當月 | I14: 比例 | J14: 前月 | K14: 差異
A15: 18℃-飯糰(061,063) | B15: =SUM('（３）業績構成比'!M7:M11)/1000 -> 7427.5341 | C15: =IFERROR(B15/$B$6,"") | D15: 0.36139567 | E15: =IFERROR(C15-D15,"") | G15: 18℃-飯糰(061,063) | H15: =SUM('（４）訂單數量構成比'!M7:M11) -> 398562 | I15: =IFERROR(H15/$B$7,"") | J15: 0.58577126 | K15: =IFERROR(I15-J15,"")
A16: 18℃-壽司手卷(071,072,075,076) | B16: =SUM('（３）業績構成比'!S7:S11)/1000 -> 1730.8008 | C16: =IFERROR(B16/$B$6,"") | D16: 0.069633574 | E16: =IFERROR(C16-D16,"") | G16: 18℃-壽司手卷(071,072,075,076) | H16: =SUM('（４）訂單數量構成比'!S7:S11) -> 65963 | I16: =IFERROR(H16/$B$7,"") | J16: 0.081693946 | K16: =IFERROR(I16-J16,"")
A17: 4℃-飯糰(065) | B17: =SUM('（３）業績構成比'!U7:U11)/1000 -> 682.08573 | C17: =IFERROR(B17/$B$6,"") | D17: 0.022453222 | E17: =IFERROR(C17-D17,"") | G17: 4℃-飯糰(065) | H17: =SUM('（４）訂單數量構成比'!U7:U11) -> 27561 | I17: =IFERROR(H17/$B$7,"") | J17: 0.024966128 | K17: =IFERROR(I17-J17,"")
A18: 4℃-壽司手卷(077) | B18: =SUM('（３）業績構成比'!W7:W11)/1000 -> 600.06628 | C18: =IFERROR(B18/$B$6,"") | D18: 0.008585039 | E18: =IFERROR(C18-D18,"") | G18: 4℃-壽司手卷(077) | H18: =SUM('（４）訂單數量構成比'!W7:W11) -> 23628 | I18: =IFERROR(H18/$B$7,"") | J18: 0.0097963785 | K18: =IFERROR(I18-J18,"")
A19: 主食(091,092,093,094,095) | B19: =SUM('（３）業績構成比'!AC7:AC11)/1000 -> 3695.499 | C19: =IFERROR(B19/$B$6,"") | D19: 0.16215294 | E19: =IFERROR(C19-D19,"") | G19: 主食(091,092,093,094,095) | H19: =SUM('（４）訂單數量構成比'!AC7:AC11) -> 66565 | I19: =IFERROR(H19/$B$7,"") | J19: 0.089953008 | K19: =IFERROR(I19-J19,"")
A20: 便當(083) | B20: =SUM('（３）業績構成比'!AE7:AE11)/1000 -> 5944.2205 | C20: =IFERROR(B20/$B$6,"") | D20: 0.27057088 | E20: =IFERROR(C20-D20,"") | G20: 便當(083) | H20: =SUM('（４）訂單數量構成比'!AE7:AE11) -> 98405 | I20: =IFERROR(H20/$B$7,"") | J20: 0.13708178 | K20: =IFERROR(I20-J20,"")
A21: 熱食義麵(122,123,124,126) | B21: =SUM('（３）業績構成比'!AG7:AG11)/1000 -> 0 | C21: =IFERROR(B21/$B$6,"") | D21: 0.029234371 | E21: =IFERROR(C21-D21,"") | G21: 熱食義麵(122,123,124,126) | H21: =SUM('（４）訂單數量構成比'!AG7:AG11) -> 0 | I21: =IFERROR(H21/$B$7,"") | J21: 0.015652481 | K21: =IFERROR(I21-J21,"")
A22: 季節調理麵(111,112) | B22: =SUM('（３）業績構成比'!AI7:AI11)/1000 -> 596.88324 | C22: =IFERROR(B22/$B$6,"") | D22: 0.040564166 | E22: =IFERROR(C22-D22,"") | G22: 季節調理麵(111,112) | H22: =SUM('（４）訂單數量構成比'!AI7:AI11) -> 9351 | I22: =IFERROR(H22/$B$7,"") | J22: 0.022004735 | K22: =IFERROR(I22-J22,"")
A23: 微波小吃(153,154,155) | B23: =SUM('（３）業績構成比'!AK7:AK11)/1000 -> 689.80344 | C23: =IFERROR(B23/$B$6,"") | D23: 0.035410133 | E23: =IFERROR(C23-D23,"") | G23: 微波小吃(153,154,155) | H23: =SUM('（４）訂單數量構成比'!AK7:AK11) -> 23340 | I23: =IFERROR(H23/$B$7,"") | J23: 0.033080287 | K23: =IFERROR(I23-J23,"")
C24: =SUM(C15:C23) -> 0 | D24: =SUM(D15:D23) -> 1 | I24: =SUM(I15:I23) -> 0 | J24: =SUM(J15:J23) -> 1
A26: （５）品群別人時生產性
A27: 品群 | B27: 當月 | C27: 前月 | D27: 差異 | E27: 累計
A28: 18℃-飯A15:A23糰(061,063) | B28: ='（５-1）品群別人時生產性(18℃-飯糰)'!C1 -> 770.4937 | C28: 768.96509 | D28: =B28-C28 -> 1.528613
A29: 18℃-壽司手卷(071,072,075,076) | B29: ='（５-2）品群別人時生產性(18℃-壽司手卷)'!C1 -> 307.16311 | C29: 280.52358 | D29: =B29-C29 -> 26.63953
A30: 4℃-飯糰(065) | B30: ='（５-3）品群別人時生產性(4℃-飯糰)'!C1 -> 330.85325 | C30: 258.56167 | D30: =B30-C30 -> 72.291581
A31: 4℃-壽司手卷(077) | B31: ='（５-4）品群別人時生產性(4℃-壽司手卷)'!C1 -> 493.70226 | C31: 486.07171 | D31: =B31-C31 -> 7.6305537
A32: 主食(091,092,093,094,095) | B32: ='（５-5）品群別人時生產性(微波主食) '!C1 -> 78.207319 | C32: 68.891235 | D32: =B32-C32 -> 9.3160837
A33: 便當(083) | B33: ='（５-6）品群別人時生產性(便當)'!C1 -> 76.642721 | C33: 78.306367 | D33: =B33-C33 -> -1.6636458
A34: 熱食義麵(122,123,124,126) | B34: ='（５-7）品群別人時生產性(熱食義麵) '!C1 -> 0 | C34: 76.250133 | D34: =B34-C34 -> -76.250133
A35: 季節調理麵(111,112) | B35: ='（５-8）品群別人時生產性(季節調理麵) '!C1 -> 84.601424 | C35: 110.8083 | D35: =B35-C35 -> -26.206881
A36: 微波小吃(153,154,155) | B36: ='（５-9）品群別人時生產性(微波小吃)'!C1 -> 83.048343 | C36: 76.123665 | D36: =B36-C36 -> 6.9246778

Sheet 生產管理報表(週) 
A1: 大溪廠生產管理報表
A3: 月別 | B3: 3 | C3: 週別 | D3: W1 | E3: 工廠 | F3: 大溪廠
A4: （１）收支狀況 | E4: ※單位：千元 | G4: （２）ＫＰＩ達成進度
A5: 項目 | B5: 當週 | C5: 前週 | D5: 差異 | E5: 累計 | G5: 項目 | H5: KPI | I5: 當週 | J5: 前週 | K5: 累計 | L5: ※補充
A6: 業績金額 | B6: ='（１）收支狀況'!G12/1000 -> 33854.096 | C6: 32338.42 | D6: =B6-C6 -> 1515.676 | E6: 33854.096 | G6: 人時性(個/月均) | H6: 497.6 | I6: ='（２）ＫＰＩ達成進度'!G12 -> 413.80533 | J6: 468.73197 | K6: ='（２）ＫＰＩ達成進度'!H10 -> 423.20739 | L6: 個／MH
A7: 訂單數量 | B7: ='（１）收支狀況'!J12 -> 1137743 | C7: 1076054 | D7: =B7-C7 -> 61689 | E7: 1137743 | G7: 人時達成率(%/月均) | H7: 0.8 | I7: ='（２）ＫＰＩ達成進度'!J12 -> 0.83160235 | J7: 0.94198547 | K7: ='（２）ＫＰＩ達成進度'!K10 -> 0.85049716 | L7: 達成率
A8: 材料費 | B8: ='（１）收支狀況'!M12/1000 -> 22517.866 | C8: 21241.351 | D8: =B8-C8 -> 1276.5157 | E8: 22517.866 | G8: 半成品-報廢(%) | H8: 0.0025 | I8: ='（２）ＫＰＩ達成進度'!M12 -> 0.0020348075 | J8: 0.0022409997 | K8: ='（２）ＫＰＩ達成進度'!N10 -> 0.0020460086 | L8: 報廢率
A9: 材料費率 | B9: ='（１）收支狀況'!P12 -> 0.66514452 | C9: 0.65684565 | D9: =B9-C9 -> 0.0082988638 | E9: 0.66514452 | G9: 半成品-超用(%) | H9: 0.004 | I9: ='（２）ＫＰＩ達成進度'!P12 -> 0.0050385612 | J9: 0.0050772955 | K9: ='（２）ＫＰＩ達成進度'!Q10 -> 0.0050579793 | L9: 超用率
A10: 勞務成本 | B10: ='（１）收支狀況'!S12/1000 -> 5405.1639 | C10: 5488.2978 | D10: =B10-C10 -> -83.133812 | E10: 5405.1639 | G10: 固定產線-導入率(%) | H10: 0.8 | I10: ='（２）ＫＰＩ達成進度'!S12 -> 0.9 | J10: 0.9 | K10: ='（２）ＫＰＩ達成進度'!T10 -> 0.9 | L10: 導入率
A11: 勞務費率 | B11: ='（１）收支狀況'!V12 -> 0.15966056 | C11: 0.16971447 | D11: =B11-C11 -> -0.010053908 | E11: 0.15966056 | G11: 教育訓練-實施率(%) | H11: 1 | I11: =10/52*100% -> 0.19230769 | J11: 0.17307692 | K11: ='（２）ＫＰＩ達成進度'!W10 -> 0.18803419 | L11: 實施率
A13: （３）業績構成比 | E13: ※單位：千元 | G13: （４）訂單數量構成比 | K13: ※單位：個
B14: 當週 | C14: 比例 | D14: 前週 | E14: 差異 | H14: 當週 | I14: 比例 | J14: 前週 | K14: 差異
A15: 18℃-飯糰(061,063) | B15: =SUM('（３）業績構成比'!M14:M20)/1000 -> 12088.957 | C15: =IFERROR(B15/$B$6,"") -> 0.35708992 | D15: 0.34854538 | E15: =IFERROR(C15-D15,"") -> 0.0085445397 | G15: 18℃-飯糰(061,063) | H15: =SUM('（４）訂單數量構成比'!M14:M20) -> 645390 | I15: =IFERROR(H15/$B$7,"") -> 0.56725464 | J15: 0.56176642 | K15: =IFERROR(I15-J15,"") -> 0.0054882267
A16: 18℃-壽司手卷(071,072,075,076) | B16: =SUM('（３）業績構成比'!S14:S20)/1000 -> 2809.6224 | C16: =IFERROR(B16/$B$6,"") -> 0.082992096 | D16: 0.077659535 | E16: =IFERROR(C16-D16,"") -> 0.0053325608 | G16: 18℃-壽司手卷(071,072,075,076) | H16: =SUM('（４）訂單數量構成比'!S14:S20) -> 114606 | I16: =IFERROR(H16/$B$7,"") -> 0.10073101 | J16: 0.089098688 | K16: =IFERROR(I16-J16,"") -> 0.01163232
A17: 4℃-飯糰(065) | B17: =SUM('（３）業績構成比'!U14:U20)/1000 -> 810.63364 | C17: =IFERROR(B17/$B$6,"") -> 0.023944921 | D17: 0.030516848 | E17: =IFERROR(C17-D17,"") -> -0.0065719275 | G17: 4℃-飯糰(065) | H17: =SUM('（４）訂單數量構成比'!U14:U20) -> 30587 | I17: =IFERROR(H17/$B$7,"") -> 0.026883927 | J17: 0.036542776 | K17: =IFERROR(I17-J17,"") -> -0.0096588485
A18: 4℃-壽司手卷(077) | B18: =SUM('（３）業績構成比'!W14:W20)/1000 -> 563.87273 | C18: =IFERROR(B18/$B$6,"") -> 0.016655968 | D18: 0.026662267 | E18: =IFERROR(C18-D18,"") -> -0.010006299 | G18: 4℃-壽司手卷(077) | H18: =SUM('（４）訂單數量構成比'!W14:W20) -> 21361 | I18: =IFERROR(H18/$B$7,"") -> 0.01877489 | J18: 0.031208471 | K18: =IFERROR(I18-J18,"") -> -0.012433581
A19: 主食(091,092,093,094,095) | B19: =SUM('（３）業績構成比'!AC14:AC20)/1000 -> 7314.4163 | C19: =IFERROR(B19/$B$6,"") -> 0.21605706 | D19: 0.18359017 | E19: =IFERROR(C19-D19,"") -> 0.032466883 | G19: 主食(091,092,093,094,095) | H19: =SUM('（４）訂單數量構成比'!AC14:AC20) -> 139738 | I19: =IFERROR(H19/$B$7,"") -> 0.12282036 | J19: 0.10117615 | K19: =IFERROR(I19-J19,"") -> 0.021644207
A20: 便當(083) | B20: =SUM('（３）業績構成比'!AE14:AE20)/1000 -> 9696.3549 | C20: =IFERROR(B20/$B$6,"") -> 0.286416 | D20: 0.28346202 | E20: =IFERROR(C20-D20,"") -> 0.0029539812 | G20: 便當(083) | H20: =SUM('（４）訂單數量構成比'!AE14:AE20) -> 159788 | I20: =IFERROR(H20/$B$7,"") -> 0.14044296 | J20: 0.1408591 | K20: =IFERROR(I20-J20,"") -> -0.00041613715
A21: 熱食義麵(122,123,124,126) | B21: =SUM('（３）業績構成比'!AG14:AG20)/1000 -> 0 | C21: =IFERROR(B21/$B$6,"") -> 0 | D21: 0 | E21: =IFERROR(C21-D21,"") -> 0 | G21: 熱食義麵(122,123,124,126) | H21: =SUM('（４）訂單數量構成比'!AG14:AG20) -> 0 | I21: =IFERROR(H21/$B$7,"") -> 0 | J21: 0 | K21: =IFERROR(I21-J21,"") -> 0
A22: 季節調理麵(111,112) | B22: =SUM('（３）業績構成比'!AI14:AI20)/1000 -> 72.5584 | C22: =IFERROR(B22/$B$6,"") -> 0.002143268 | D22: 0.023826783 | E22: =IFERROR(C22-D22,"") -> -0.021683515 | G22: 季節調理麵(111,112) | H22: =SUM('（４）訂單數量構成比'!AI14:AI20) -> 1010 | I22: =IFERROR(H22/$B$7,"") -> 0.00088772245 | J22: 0.010936254 | K22: =IFERROR(I22-J22,"") -> -0.010048532
A23: 微波小吃(153,154,155) | B23: =SUM('（３）業績構成比'!AK14:AK20)/1000 -> 497.6811 | C23: =IFERROR(B23/$B$6,"") -> 0.014700765 | D23: 0.025736988 | E23: =IFERROR(C23-D23,"") -> -0.011036224 | G23: 微波小吃(153,154,155) | H23: =SUM('（４）訂單數量構成比'!AK14:AK20) -> 25263 | I23: =IFERROR(H23/$B$7,"") -> 0.022204487 | J23: 0.028412143 | K23: =IFERROR(I23-J23,"") -> -0.0062076556
C24: =SUM(C15:C23) -> 1 | D24: =SUM(D15:D23) -> 1 | I24: =SUM(I15:I23) -> 1 | J24: =SUM(J15:J23) -> 1
A26: （５）品群別人時生產性
A27: 品群 | B27: 當週 | C27: 前週 | D27: 差異 | E27: 累計
A28: 18℃-飯糰(061,063) | B28: ='（５-1）品群別人時生產性(18℃-飯糰)'!L45 -> 770.4937 | C28: 770.91906 | D28: =B28-C28 -> -0.42535871 | E28: ='（５-1）品群別人時生產性(18℃-飯糰)'!C1 -> 770.4937
A29: 18℃-壽司手卷(071,072,075,076) | B29: ='（５-2）品群別人時生產性(18℃-壽司手卷)'!L27 -> 307.16311 | C29: 300.55928 | D29: =B29-C29 -> 6.6038259 | E29: ='（５-2）品群別人時生產性(18℃-壽司手卷)'!C1 -> 307.16311
A30: 4℃-飯糰(065) | B30: ='（５-3）品群別人時生產性(4℃-飯糰)'!L27 -> 330.85325 | C30: 317.4626 | D30: =B30-C30 -> 13.390644 | E30: ='（５-3）品群別人時生產性(4℃-飯糰)'!C1 -> 330.85325
A31: 4℃-壽司手卷(077) | B31: ='（５-4）品群別人時生產性(4℃-壽司手卷)'!L27 -> 493.70226 | C31: 481.20057 | D31: =B31-C31 -> 12.501694 | E31: ='（５-4）品群別人時生產性(4℃-壽司手卷)'!C1 -> 493.70226
A32: 主食(091,092,093,094,095) | B32: ='（５-5）品群別人時生產性(微波主食) '!L27 -> 78.207319 | C32: 79.96347 | D32: =B32-C32 -> -1.7561514 | E32: ='（５-5）品群別人時生產性(微波主食) '!C1 -> 78.207319
A33: 便當(083) | B33: ='（５-6）品群別人時生產性(便當)'!L27 -> 76.642721 | C33: 78.283794 | D33: =B33-C33 -> -1.6410727 | E33: ='（５-6）品群別人時生產性(便當)'!C1 -> 76.642721
A34: 熱食義麵(122,123,124,126) | B34: 0 | C34: 0 | D34: =B34-C34 -> 0 | E34: ='（５-7）品群別人時生產性(熱食義麵) '!C1 -> 0
A35: 季節調理麵(111,112) | B35: ='（５-8）品群別人時生產性(季節調理麵) '!L27 -> 84.601424 | C35: 84.576459 | D35: =B35-C35 -> 0.0249649 | E35: ='（５-8）品群別人時生產性(季節調理麵) '!C1 -> 84.601424
A36: 微波小吃(153,154,155) | B36: ='（５-9）品群別人時生產性(微波小吃)'!L27 -> 83.048343 | C36: 78.042646 | D36: =B36-C36 -> 5.0056966 | E36: ='（５-9）品群別人時生產性(微波小吃)'!C1 -> 83.048343

Sheet （１）收支狀況
B2: （１）收支狀況
B3: 資料繳交日 | C3: 月份 | D3: 日期 | F3: 營業額(元) | I3: 訂單數量(個) | L3: 材料費(元) | O3: 材料費率（材料費／營業額） | R3: 勞務成本（全廠人事成本） | U3: 勞務費率（勞務成本／營業額）
F4: 日 | G4: 週累積 | H4: 月累積 | I4: 日 | J4: 週累積 | K4: 月累積 | L4: 日 | M4: 週累積 | N4: 月累積 | O4: 日 | P4: 週累積 | Q4: 月累積 | R4: 日 | S4: 週累積 | T4: 月累積 | U4: 日 | V4: 週累積 | W4: 月累積
B5: =D6+7 -> 46085 | D5: 46077 | E5: 二 | F5: 5238957.1 | G5: =SUM(F5:F11) -> 32338420 | I5: 175154 | J5: =SUM(I5:I11) -> 1076054 | L5: 3399597.1 | M5: =SUM(L5:L11) -> 21241351 | O5: =L5/F5 -> 0.64890722 | P5: =M5/G5 -> 0.65684565 | R5: 840082.55 | S5: =SUM(R5:R11) -> 5488297.8 | U5: =R5/F5 -> 0.16035301 | V5: =S5/G5 -> 0.16971447
D6: =D5+1 -> 46078 | E6: 三 | F6: 4692647.5 | I6: 156618 | L6: 3098792.2 | O6: =L6/F6 -> 0.66035052 | R6: 789675.12 | U6: =R6/F6 -> 0.16827923
D7: =D6+1 -> 46079 | E7: 四 | F7: 3909306.8 | I7: 129387 | L7: 2647205.3 | O7: =L7/F7 -> 0.67715464 | R7: 725122.7 | U7: =R7/F7 -> 0.18548626
D8: =D7+1 -> 46080 | E8: 五 | F8: 3610052.1 | I8: 120519 | L8: 2369385.1 | O8: =L8/F8 -> 0.6563299 | R8: 750061.99 | U8: =R8/F8 -> 0.20777041
D9: =D8+1 -> 46081 | E9: 六 | F9: 3915929.6 | I9: 131697 | L9: 2568526.9 | O9: =L9/F9 -> 0.65591753 | R9: 774937.55 | U9: =R9/F9 -> 0.19789364
C10: 三 | D10: =D9+1 -> 46082 | E10: 日 | F10: 5447490.3 | H10: =SUM(F10:F40) -> 44825623 | I10: 179915 | K10: =SUM(I10:I40) -> 1500422 | L10: 3643303.9 | N10: =SUM(L10:L40) -> 29675711 | O10: =L10/F10 -> 0.66880412 | Q10: =N10/H10 -> 0.66202561 | R10: 804587.51 | T10: =SUM(R10:R40) -> 7013581.8 | U10: =R10/F10 -> 0.14769875 | W10: =T10/H10 -> 0.15646368
D11: =D10+1 -> 46083 | E11: 一 | F11: 5524036.8 | I11: 182764 | L11: 3514540.3 | O11: =L11/F11 -> 0.6362268 | R11: 803830.36 | U11: =R11/F11 -> 0.14551503
B12: =B5+7 -> 46092 | D12: =D11+1 -> 46084 | E12: 二 | F12: 5503117.1 | G12: =SUM(F12:F18) -> 33854096 | I12: 182389 | J12: =SUM(I12:I18) -> 1137743 | L12: 3633986.2 | M12: =SUM(L12:L18) -> 22517866 | O12: =L12/F12 -> 0.66035052 | P12: =M12/G12 -> 0.66514452 | R12: 830265.73 | S12: =SUM(R12:R18) -> 5405163.9 | U12: =R12/F12 -> 0.1508719 | V12: =S12/G12 -> 0.15966056
D13: =D12+1 -> 46085 | E13: 三 | F13: 5072703.1 | I13: 171444 | L13: 3462721.3 | O13: =L13/F13 -> 0.68261856 | R13: 794675.29 | U13: =R13/F13 -> 0.15665717
D14: =D13+1 -> 46086 | E14: 四 | F14: 4496570 | I14: 153251 | L14: 3011033.1 | O14: =L14/F14 -> 0.66962887 | R14: 724960.16 | U14: =R14/F14 -> 0.16122515
D15: =D14+1 -> 46087 | E15: 五 | F15: 3821772.9 | I15: 131075 | L15: 2509131.8 | O15: =L15/F15 -> 0.65653608 | R15: 685553.83 | U15: =R15/F15 -> 0.1793811
D16: =D15+1 -> 46088 | E16: 六 | F16: 4127790.8 | I16: 139687 | L16: 3057288.7 | O16: =L16/F16 -> 0.74065979 | R16: 750910.44 | U16: =R16/F16 -> 0.18191582
D17: =D16+1 -> 46089 | E17: 日 | F17: 5624946 | I17: 184408 | L17: 3467402.3 | O17: =L17/F17 -> 0.61643299 | R17: 835817.77 | U17: =R17/F17 -> 0.14859125
D18: =D17+1 -> 46090 | E18: 一 | F18: 5207196.3 | I18: 175489 | L18: 3376303.1 | O18: =L18/F18 -> 0.64839175 | R18: 782980.74 | U18: =R18/F18 -> 0.15036513
B19: =B12+7 -> 46099 | D19: =D18+1 -> 46091 | E19: 二 | G19: =SUM(F19:F25) -> 0 | J19: =SUM(I19:I25) -> 0 | M19: =SUM(L19:L25) -> 0 | O19: =L19/F19 -> #DIV/0! | P19: =M19/G19 -> #DIV/0! | S19: =SUM(R19:R25) -> 0 | U19: =R19/F19 -> #DIV/0! | V19: =S19/G19 -> #DIV/0!
D20: =D19+1 -> 46092 | E20: 三 | O20: =L20/F20 -> #DIV/0! | U20: =R20/F20 -> #DIV/0!
D21: =D20+1 -> 46093 | E21: 四 | O21: =L21/F21 -> #DIV/0! | U21: =R21/F21 -> #DIV/0!
D22: =D21+1 -> 46094 | E22: 五 | O22: =L22/F22 -> #DIV/0! | U22: =R22/F22 -> #DIV/0!
D23: =D22+1 -> 46095 | E23: 六 | O23: =L23/F23 -> #DIV/0! | U23: =R23/F23 -> #DIV/0!
D24: =D23+1 -> 46096 | E24: 日 | O24: =L24/F24 -> #DIV/0! | U24: =R24/F24 -> #DIV/0!
D25: =D24+1 -> 46097 | E25: 一 | O25: =L25/F25 -> #DIV/0! | U25: =R25/F25 -> #DIV/0!
B26: =B19+7 -> 46106 | D26: =D25+1 -> 46098 | E26: 二 | G26: =SUM(F26:F32) -> 0 | J26: =SUM(I26:I32) -> 0 | M26: =SUM(L26:L32) -> 0 | O26: =L26/F26 -> #DIV/0! | P26: =M26/G26 -> #DIV/0! | S26: =SUM(R26:R32) -> 0 | U26: =R26/F26 -> #DIV/0! | V26: =S26/G26 -> #DIV/0!
D27: =D26+1 -> 46099 | E27: 三 | O27: =L27/F27 -> #DIV/0! | U27: =R27/F27 -> #DIV/0!
D28: =D27+1 -> 46100 | E28: 四 | O28: =L28/F28 -> #DIV/0! | U28: =R28/F28 -> #DIV/0!
D29: =D28+1 -> 46101 | E29: 五 | O29: =L29/F29 -> #DIV/0! | U29: =R29/F29 -> #DIV/0!
D30: =D29+1 -> 46102 | E30: 六 | O30: =L30/F30 -> #DIV/0! | U30: =R30/F30 -> #DIV/0!
D31: =D30+1 -> 46103 | E31: 日 | O31: =L31/F31 -> #DIV/0! | U31: =R31/F31 -> #DIV/0!
D32: =D31+1 -> 46104 | E32: 一 | O32: =L32/F32 -> #DIV/0! | U32: =R32/F32 -> #DIV/0!
B33: =B26+7 -> 46113 | D33: =D32+1 -> 46105 | E33: 二 | G33: =SUM(F33:F39) -> 0 | J33: =SUM(I33:I39) -> 0 | M33: =SUM(L33:L39) -> 0 | O33: =L33/F33 -> #DIV/0! | P33: =M33/G33 -> #DIV/0! | S33: =SUM(R33:R39) -> 0 | U33: =R33/F33 -> #DIV/0! | V33: =S33/G33 -> #DIV/0!
D34: =D33+1 -> 46106 | E34: 三 | O34: =L34/F34 -> #DIV/0! | U34: =R34/F34 -> #DIV/0!
D35: =D34+1 -> 46107 | E35: 四 | O35: =L35/F35 -> #DIV/0! | U35: =R35/F35 -> #DIV/0!
D36: =D35+1 -> 46108 | E36: 五 | O36: =L36/F36 -> #DIV/0! | U36: =R36/F36 -> #DIV/0!
D37: =D36+1 -> 46109 | E37: 六 | O37: =L37/F37 -> #DIV/0! | U37: =R37/F37 -> #DIV/0!
D38: =D37+1 -> 46110 | E38: 日 | O38: =L38/F38 -> #DIV/0! | U38: =R38/F38 -> #DIV/0!
D39: =D38+1 -> 46111 | E39: 一 | O39: =L39/F39 -> #DIV/0! | U39: =R39/F39 -> #DIV/0!
B40: =B33+7 -> 46120 | D40: =D39+1 -> 46112 | E40: 二 | G40: =SUM(F40:F46) -> 0 | J40: =SUM(I40:I46) -> 0 | M40: =SUM(L40:L46) -> 0 | O40: =L40/F40 -> #DIV/0! | P40: =M40/G40 -> #DIV/0! | U40: =R40/F40 -> #DIV/0!
D41: =D40+1 -> 46113 | E41: 三 | O41: =L41/F41 -> #DIV/0!
...

Sheet （２）ＫＰＩ達成進度
B1: 人時生產性基準值 | C1: 497.6
B2: （２）ＫＰＩ達成進度
B3: 資料繳交日 | C3: 月份 | D3: 日期 | F3: 人時生產性(個/人) | I3: 人時生產性達成率(%) | L3: 半成品報廢(%) | O3: 半成品超用(%) | R3: 固定產線-導入率(固定產線數/總產線數) | U3: 教育訓練-實施率(進度/計畫)
F4: 日 | G4: 週平均 | H4: 月平均 | I4: 日 | J4: 週平均 | K4: 月平均 | L4: 日 | M4: 週平均 | N4: 月平均 | O4: 日 | P4: 週平均 | Q4: 月平均 | R4: 日 | S4: 週平均 | T4: 月平均 | U4: 日 | V4: 週平均 | W4: 月平均
B5: =D6+7 -> 46085 | D5: 46077 | E5: 二 | F5: 464.32904 | G5: =AVERAGE(F5:F11) -> 468.73197 | I5: =F5/$C$1 -> 0.93313713 | J5: =AVERAGE(I5:I11) -> 0.94198547 | L5: 0.0023089761 | M5: =AVERAGE(L5:L11) -> 0.0022409997 | O5: 0.0050852114 | P5: =AVERAGE(O5:O11) -> 0.0050772955 | R5: 0.9 | S5: =AVERAGE(R5:R11) -> 0.9 | U5: =9/52*100% -> 0.17307692 | V5: =AVERAGE(U5:U11) -> 0.17307692
D6: =D5+1 -> 46078 | E6: 三 | F6: 465.03721 | I6: =F6/$C$1 -> 0.93456032 | L6: 0.0023055099 | O6: 0.0050598022 | R6: 0.9 | U6: =9/52*100% -> 0.17307692
D7: =D6+1 -> 46079 | E7: 四 | F7: 463.62331 | I7: =F7/$C$1 -> 0.93171887 | L7: 0.0022997824 | O7: 0.0050498788 | R7: 0.9 | U7: =9/52*100% -> 0.17307692
D8: =D7+1 -> 46080 | E8: 五 | F8: 486.84866 | I8: =F8/$C$1 -> 0.97839362 | L8: 0.002298035 | O8: 0.0050264345 | R8: 0.9 | U8: =9/52*100% -> 0.17307692
D9: =D8+1 -> 46081 | E9: 六 | F9: 489.05639 | I9: =F9/$C$1 -> 0.98283036 | L9: 0.0023042698 | O9: 0.0050678558 | R9: 0.9 | U9: =9/52*100% -> 0.17307692
C10: 三 | D10: =D9+1 -> 46082 | E10: 日 | F10: 467.10925 | H10: =AVERAGEIF(F10:F40,"<>0") -> 423.20739 | I10: =F10/$C$1 -> 0.93872437 | K10: =AVERAGEIF(I10:I40,"<>0") -> 0.85049716 | L10: 0.0020801358 | N10: =AVERAGEIF(L10:L40,"<>0") -> 0.0020460086 | O10: 0.0051182745 | Q10: =AVERAGEIF(O10:O40,"<>0") -> 0.0050579793 | R10: 0.9 | T10: =AVERAGEIF(R10:R40,"<>0") -> 0.9 | U10: =9/52*100% -> 0.17307692 | W10: =AVERAGEIF(U10:U40,"<>0") -> 0.18803419
D11: =D10+1 -> 46083 | E11: 一 | F11: 445.11993 | I11: =F11/$C$1 -> 0.89453362 | L11: 0.002090289 | O11: 0.0051336112 | R11: 0.9 | U11: =9/52*100% -> 0.17307692
B12: =B5+7 -> 46092 | D12: =D11+1 -> 46084 | E12: 二 | F12: 401.96086 | G12: =AVERAGE(F12:F18) -> 413.80533 | I12: =F12/$C$1 -> 0.80779915 | J12: =AVERAGE(I12:I18) -> 0.83160235 | L12: 0.0020397948 | M12: =AVERAGE(L12:L18) -> 0.0020348075 | O12: 0.0050565527 | P12: =AVERAGE(O12:O18) -> 0.0050385612 | R12: 0.9 | S12: =AVERAGE(R12:R18) -> 0.9 | U12: =10/52*100% -> 0.19230769 | V12: =AVERAGE(U12:U18) -> 0.19230769
D13: =D12+1 -> 46085 | E13: 三 | F13: 422.79757 | I13: =F13/$C$1 -> 0.84967357 | L13: 0.0020279247 | O13: 0.0050497071 | R13: 0.9 | U13: =10/52*100% -> 0.19230769
D14: =D13+1 -> 46086 | E14: 四 | F14: 422.7799 | I14: =F14/$C$1 -> 0.84963807 | L14: 0.00204997 | O14: 0.0050196275 | R14: 0.9 | U14: =10/52*100% -> 0.19230769
D15: =D14+1 -> 46087 | E15: 五 | F15: 423.29065 | I15: =F15/$C$1 -> 0.8506645 | L15: 0.0020297876 | O15: 0.0050801225 | R15: 0.9 | U15: =10/52*100% -> 0.19230769
D16: =D15+1 -> 46088 | E16: 六 | F16: 424.20122 | I16: =F16/$C$1 -> 0.85249442 | L16: 0.0020559928 | O16: 0.00500156 | R16: 0.9 | U16: =10/52*100% -> 0.19230769
D17: =D16+1 -> 46089 | E17: 日 | F17: 404.7422 | I17: =F17/$C$1 -> 0.81338867 | L17: 0.0020164628 | O17: 0.00503752 | R17: 0.9 | U17: =10/52*100% -> 0.19230769
D18: =D17+1 -> 46090 | E18: 一 | F18: 396.8649 | I18: =F18/$C$1 -> 0.79755808 | L18: 0.0020237198 | O18: 0.0050248385 | R18: 0.9 | U18: =10/52*100% -> 0.19230769
B19: =B12+7 -> 46099 | D19: =D18+1 -> 46091 | E19: 二 | G19: =AVERAGE(F19:F25) -> #DIV/0! | I19: =F19/$C$1 -> 0 | J19: =AVERAGE(I19:I25) -> 0 | M19: =AVERAGE(L19:L25) -> #DIV/0! | P19: =AVERAGE(O19:O25) -> #DIV/0! | S19: =AVERAGE(R19:R25) -> #DIV/0! | V19: =AVERAGE(U19:U25) -> #DIV/0!
D20: =D19+1 -> 46092 | E20: 三 | I20: =F20/$C$1 -> 0
D21: =D20+1 -> 46093 | E21: 四 | I21: =F21/$C$1 -> 0
D22: =D21+1 -> 46094 | E22: 五 | I22: =F22/$C$1 -> 0
D23: =D22+1 -> 46095 | E23: 六 | I23: =F23/$C$1 -> 0
D24: =D23+1 -> 46096 | E24: 日 | I24: =F24/$C$1 -> 0
D25: =D24+1 -> 46097 | E25: 一 | I25: =F25/$C$1 -> 0
B26: =B19+7 -> 46106 | D26: =D25+1 -> 46098 | E26: 二 | G26: =AVERAGE(F26:F32) -> #DIV/0! | I26: =F26/$C$1 -> 0 | J26: =AVERAGE(I26:I32) -> 0 | M26: =AVERAGE(L26:L32) -> #DIV/0! | P26: =AVERAGE(O26:O32) -> #DIV/0! | S26: =AVERAGE(R26:R32) -> #DIV/0! | V26: =AVERAGE(U26:U32) -> #DIV/0!
D27: =D26+1 -> 46099 | E27: 三 | I27: =F27/$C$1 -> 0
D28: =D27+1 -> 46100 | E28: 四 | I28: =F28/$C$1 -> 0
D29: =D28+1 -> 46101 | E29: 五 | I29: =F29/$C$1 -> 0
D30: =D29+1 -> 46102 | E30: 六 | I30: =F30/$C$1 -> 0
D31: =D30+1 -> 46103 | E31: 日 | I31: =F31/$C$1 -> 0
D32: =D31+1 -> 46104 | E32: 一 | I32: =F32/$C$1 -> 0
B33: =B26+7 -> 46113 | D33: =D32+1 -> 46105 | E33: 二 | G33: =AVERAGE(F33:F39) -> #DIV/0! | I33: =F33/$C$1 -> 0 | J33: =AVERAGE(I33:I39) -> 0 | M33: =AVERAGE(L33:L39) -> #DIV/0! | P33: =AVERAGE(O33:O39) -> #DIV/0! | S33: =AVERAGE(R33:R39) -> #DIV/0! | V33: =AVERAGE(U33:U39) -> #DIV/0!
D34: =D33+1 -> 46106 | E34: 三 | I34: =F34/$C$1 -> 0
D35: =D34+1 -> 46107 | E35: 四 | I35: =F35/$C$1 -> 0
D36: =D35+1 -> 46108 | E36: 五 | I36: =F36/$C$1 -> 0
D37: =D36+1 -> 46109 | E37: 六 | I37: =F37/$C$1 -> 0
D38: =D37+1 -> 46110 | E38: 日 | I38: =F38/$C$1 -> 0
D39: =D38+1 -> 46111 | E39: 一 | I39: =F39/$C$1 -> 0
B40: =B33+7 -> 46120 | D40: =D39+1 -> 46112 | E40: 二 | G40: =AVERAGE(F40:F46) -> #DIV/0! | I40: =F40/$C$1 -> 0 | J40: =AVERAGE(I40:I46) -> 0 | M40: =AVERAGE(L40:L46) -> #DIV/0! | P40: =AVERAGE(O40:O46) -> #DIV/0! | S40: =AVERAGE(R40:R46) -> #DIV/0! | V40: =AVERAGE(U40:U46) -> #DIV/0!
...

Sheet （３）業績構成比
B2: （3）業績構成比
B3: 資料繳交日 | C3: 月份 | D3: 日期 | F3: 營業額 | I3: 品類業績
I4: 18℃-飯糰 | O4: 18℃-壽司手卷 | U4: 4℃-飯糰 | W4: 4℃-壽司手卷 | Y4: 主食 | AE4: 便當 | AG4: 熱食義麵 | AI4: 季節調理麵 | AK4: 微波小吃
F5: 日 | G5: 週累積 | H5: 月累積 | I5: 一配 | K5: 二配 | M5: 合計 | O5: 一配 | Q5: 二配 | S5: 合計 | U5: 一配 | W5: 一配 | Y5: 一配 | AA5: 二配 | AC5: 合計 | AE5: 一配 | AG5: 一配 | AI5: 一配 | AK5: 一配
I6: 業績(元) | J6: 比例(%) | K6: 業績(元) | L6: 比例(%) | M6: 業績(元) | N6: 比例(%) | O6: 業績(元) | P6: 比例(%) | Q6: 業績(元) | R6: 比例(%) | S6: 業績(元) | T6: 比例(%) | U6: 業績(元) | V6: 比例(%) | W6: 業績(元) | X6: 比例(%) | Y6: 業績(元) | Z6: 比例(%) | AA6: 業績(元) | AB6: 比例(%) | AC6: 業績(元) | AD6: 比例(%) | AE6: 業績(元) | AF6: 比例(%) | AG6: 業績(元) | AH6: 比例(%) | AI6: 業績(元) | AJ6: 比例(%) | AK6: 業績(元) | AL6: 比例(%)
B7: =D8+7 -> 46085 | D7: 46077 | E7: 二 | F7: =SUM(M7,S7,U7,W7,AC7,AE7,AG7,AI7,AK7) -> 5238957.1 | G7: =SUM(F7:F13) -> 32338420 | I7: 815562.13 | J7: =I7/$F7 -> 0.15567261 | K7: 962970.78 | L7: =K7/$F7 -> 0.18380963 | M7: =I7+K7 -> 1778532.9 | N7: =M7/$F7 -> 0.33948224 | O7: 220466.87 | P7: =O7/$F7 -> 0.042082206 | Q7: 178349.54 | R7: =Q7/$F7 -> 0.034042947 | S7: =O7+Q7 -> 398816.41 | T7: =S7/$F7 -> 0.076125153 | U7: 185358.41 | V7: =U7/$F7 -> 0.035380784 | W7: 233726.34 | X7: =W7/$F7 -> 0.044613143 | Y7: 262050.32 | Z7: =Y7/$F7 -> 0.050019558 | AA7: 622985.41 | AB7: =AA7/$F7 -> 0.11891401 | AC7: =Y7+AA7 -> 885035.73 | AD7: =AC7/$F7 -> 0.16893357 | AE7: 1459250.8 | AF7: =AE7/F7 -> 0.27853842 | AG7: 0 | AH7: =AG7/$F7 -> 0 | AI7: 147496.78 | AJ7: =AI7/$F7 -> 0.028153844 | AK7: 150739.66 | AL7: =AK7/$F7 -> 0.028772837
D8: 46078 | E8: 三 | F8: =SUM(M8,S8,U8,W8,AC8,AE8,AG8,AI8,AK8) -> 4692647.5 | I8: 799279.1 | J8: =I8/$F8 -> 0.17032583 | K8: 843869.38 | L8: =K8/$F8 -> 0.17982799 | M8: =I8+K8 -> 1643148.5 | N8: =M8/F8 -> 0.35015383 | O8: 220683.48 | P8: =O8/$F8 -> 0.0470275 | Q8: 169504.31 | R8: =Q8/$F8 -> 0.036121254 | S8: =O8+Q8 -> 390187.79 | T8: =S8/F8 -> 0.083148753 | U8: 148052.14 | V8: =U8/F8 -> 0.031549811 | W8: 127954.87 | X8: =W8/$F8 -> 0.027267096 | Y8: 246268.26 | Z8: =Y8/$F8 -> 0.052479599 | AA8: 471199.58 | AB8: =AA8/$F8 -> 0.10041231 | AC8: =Y8+AA8 -> 717467.84 | AD8: =AC8/$F8 -> 0.15289191 | AE8: 1390723.7 | AF8: =AE8/F8 -> 0.29636227 | AG8: 0 | AH8: =AG8/$F8 -> 0 | AI8: 133540.96 | AJ8: =AI8/$F8 -> 0.028457488 | AK8: 141571.74 | AL8: =AK8/$F8 -> 0.030168842
D9: 46079 | E9: 四 | F9: =SUM(M9,S9,U9,W9,AC9,AE9,AG9,AI9,AK9) -> 3909306.8 | I9: 569381.54 | J9: =I9/$F9 -> 0.1456477 | K9: 745558.51 | L9: =K9/$F9 -> 0.19071374 | M9: =I9+K9 -> 1314940.1 | N9: =M9/$F9 -> 0.33636143 | O9: 181316.11 | P9: =O9/$F9 -> 0.046380629 | Q9: 144695.62 | R9: =Q9/$F9 -> 0.037013114 | S9: =O9+Q9 -> 326011.73 | T9: =S9/$F9 -> 0.083393743 | U9: 126261.09 | V9: =U9/$F9 -> 0.032297565 | W9: 117881.98 | X9: =W9/$F9 -> 0.03015419 | Y9: 228101.86 | Z9: =Y9/$F9 -> 0.058348416 | AA9: 422415.5 | AB9: =AA9/$F9 -> 0.10805381 | AC9: =Y9+AA9 -> 650517.36 | AD9: =AC9/$F9 -> 0.16640223 | AE9: 1113115.7 | AF9: =AE9/F9 -> 0.28473481 | AG9: 0 | AH9: =AG9/$F9 -> 0 | AI9: 126738.1 | AJ9: =AI9/$F9 -> 0.032419584 | AK9: 133840.79 | AL9: =AK9/$F9 -> 0.034236451
D10: 46080 | E10: 五 | F10: =SUM(M10,S10,U10,W10,AC10,AE10,AG10,AI10,AK10) -> 3610052.1 | I10: 545361.13 | J10: =I10/$F10 -> 0.15106739 | K10: 729491.75 | L10: =K10/$F10 -> 0.20207236 | M10: =I10+K10 -> 1274852.9 | N10: =M10/F10 -> 0.35313975 | O10: 174530.93 | P10: =O10/$F10 -> 0.048345821 | Q10: 138334.66 | R10: =Q10/$F10 -> 0.038319298 | S10: =O10+Q10 -> 312865.59 | T10: =S10/F10 -> 0.086665119 | U10: 105159.82 | V10: =U10/F10 -> 0.029129724 | W10: 54549.87 | X10: =W10/$F10 -> 0.015110549 | Y10: 204485.54 | Z10: =Y10/$F10 -> 0.056643377 | AA10: 465150.64 | AB10: =AA10/$F10 -> 0.12884873 | AC10: =Y10+AA10 -> 669636.18 | AD10: =AC10/$F10 -> 0.18549211 | AE10: 952067.01 | AF10: =AE10/F10 -> 0.26372667 | AG10: 0 | AH10: =AG10/$F10 -> 0 | AI10: 118704.2 | AJ10: =AI10/$F10 -> 0.032881576 | AK10: 122216.51 | AL10: =AK10/$F10 -> 0.033854501
D11: 46081 | E11: 六 | F11: =SUM(M11,S11,U11,W11,AC11,AE11,AG11,AI11,AK11) -> 3915929.6 | I11: 533505.22 | J11: =I11/$F11 -> 0.13623974 | K11: 882554.59 | L11: =K11/$F11 -> 0.2253755 | M11: =I11+K11 -> 1416059.8 | N11: =M11/$F11 -> 0.36161524 | O11: 166313.67 | P11: =O11/$F11 -> 0.042471057 | Q11: 136605.65 | R11: =Q11/$F11 -> 0.034884603 | S11: =O11+Q11 -> 302919.32 | T11: =S11/$F11 -> 0.07735566 | U11: 117254.27 | V11: =U11/$F11 -> 0.029942895 | W11: 65953.22 | X11: =W11/$F11 -> 0.016842289 | Y11: 222027.47 | Z11: =Y11/$F11 -> 0.056698534 | AA11: 550814.38 | AB11: =AA11/$F11 -> 0.14065993 | AC11: =Y11+AA11 -> 772841.85 | AD11: =AC11/$F11 -> 0.19735846 | AE11: 1029063.2 | AF11: =AE11/F11 -> 0.262789 | AG11: 0 | AH11: =AG11/$F11 -> 0 | AI11: 70403.2 | AJ11: =AI11/$F11 -> 0.017978668 | AK11: 141434.74 | AL11: =AK11/$F11 -> 0.036117794
C12: 三 | D12: 46082 | E12: 日 | F12: =SUM(M12,S12,U12,W12,AC12,AE12,AG12,AI12,AK12) -> 5447490.3 | H12: =SUM(F12:F42) -> 44825623 | I12: 880068.55 | J12: =I12/$F12 -> 0.16155486 | K12: 1018931.3 | L12: =K12/$F12 -> 0.18704601 | M12: =I12+K12 -> 1898999.9 | N12: =M12/F12 -> 0.34860087 | O12: 229722.55 | P12: =O12/$F12 -> 0.042170346 | Q12: 170790.6 | R12: =Q12/$F12 -> 0.031352163 | S12: =O12+Q12 -> 400513.15 | T12: =S12/F12 -> 0.073522509 | U12: 173999.36 | V12: =U12/F12 -> 0.031941197 | W12: 148402.32 | X12: =W12/$F12 -> 0.027242329 | Y12: 296339.4 | Z12: =Y12/$F12 -> 0.054399253 | AA12: 622748.12 | AB12: =AA12/$F12 -> 0.11431835 | AC12: =Y12+AA12 -> 919087.52 | AD12: =AC12/$F12 -> 0.16871761 | AE12: 1756824.7 | AF12: =AE12/F12 -> 0.32250167 | AG12: 0 | AH12: =AG12/$F12 -> 0 | AI12: 81107.36 | AJ12: =AI12/$F12 -> 0.014888941 | AK12: 68556 | AL12: =AK12/$F12 -> 0.012584878
D13: 46083 | E13: 一 | F13: =SUM(M13,S13,U13,W13,AC13,AE13,AG13,AI13,AK13) -> 5524036.8 | I13: 846957.8 | J13: =I13/$F13 -> 0.15332226 | K13: 1097915.2 | L13: =K13/$F13 -> 0.19875234 | M13: =I13+K13 -> 1944873 | N13: =M13/$F13 -> 0.3520746 | O13: 211406.03 | P13: =O13/$F13 -> 0.038270207 | Q13: 168666.66 | R13: =Q13/$F13 -> 0.030533225 | S13: =O13+Q13 -> 380072.69 | T13: =S13/$F13 -> 0.068803432 | U13: 130781.56 | V13: =U13/$F13 -> 0.023674998 | W13: 113746.98 | X13: =W13/$F13 -> 0.020591279 | Y13: 253080.66 | Z13: =Y13/$F13 -> 0.045814442 | AA13: 1069349 | AB13: =AA13/$F13 -> 0.19358108 | AC13: =Y13+AA13 -> 1322429.7 | AD13: =AC13/$F13 -> 0.23939552 | AE13: 1465668.8 | AF13: =AE13/F13 -> 0.26532568 | AG13: 0 | AH13: =AG13/$F13 -> 0 | AI13: 92529.92 | AJ13: =AI13/$F13 -> 0.016750417 | AK13: 73934.1 | AL13: =AK13/$F13 -> 0.013384071
B14: =D15+7 -> 46092 | D14: 46084 | E14: 二 | F14: =SUM(M14,S14,U14,W14,AC14,AE14,AG14,AI14,AK14) -> 5503117.1 | G14: =SUM(F14:F20) -> 33854096 | I14: 830881.12 | J14: =I14/$F14 -> 0.15098373 | K14: 1064970 | L14: =K14/$F14 -> 0.19352123 | M14: =I14+K14 -> 1895851.1 | N14: =M14/$F14 -> 0.34450496 | O14: 287774.4 | P14: =O14/$F14 -> 0.052292982 | Q14: 169433.19 | R14: =Q14/$F14 -> 0.030788585 | S14: =O14+Q14 -> 457207.59 | T14: =S14/$F14 -> 0.083081567 | U14: 122084.54 | V14: =U14/$F14 -> 0.022184616 | W14: 86700.45 | X14: =W14/$F14 -> 0.015754789 | Y14: 202214.74 | Z14: =Y14/$F14 -> 0.036745491 | AA14: 974142.5 | AB14: =AA14/$F14 -> 0.1770165 | AC14: =Y14+AA14 -> 1176357.2 | AD14: =AC14/$F14 -> 0.21376199 | AE14: 1623033.4 | AF14: =AE14/F14 -> 0.29492984 | AG14: 0 | AH14: =AG14/$F14 -> 0 | AI14: 72558.4 | AJ14: =AI14/$F14 -> 0.013184964 | AK14: 69324.3 | AL14: =AK14/$F14 -> 0.012597279
D15: 46085 | E15: 三 | F15: =SUM(M15,S15,U15,W15,AC15,AE15,AG15,AI15,AK15) -> 5072703.1 | I15: 815697.95 | J15: =I15/$F15 -> 0.16080144 | K15: 1020941.8 | L15: =K15/$F15 -> 0.2012619 | M15: =I15+K15 -> 1836639.8 | N15: =M15/F15 -> 0.36206333 | O15: 271042.24 | P15: =O15/$F15 -> 0.053431521 | Q15: 176841.24 | R15: =Q15/$F15 -> 0.034861343 | S15: =O15+Q15 -> 447883.48 | T15: =S15/F15 -> 0.088292863 | U15: 113916.98 | V15: =U15/F15 -> 0.022456859 | W15: 80208.43 | X15: =W15/$F15 -> 0.015811773 | Y15: 188760.25 | Z15: =Y15/$F15 -> 0.037210979 | AA15: 879092.45 | AB15: =AA15/$F15 -> 0.17329862 | AC15: =Y15+AA15 -> 1067852.7 | AD15: =AC15/$F15 -> 0.2105096 | AE15: 1451322 | AF15: =AE15/F15 -> 0.28610427 | AG15: 0 | AH15: =AG15/$F15 -> 0 | AI15: 0 | AJ15: =AI15/$F15 -> 0 | AK15: 74879.7 | AL15: =AK15/$F15 -> 0.014761302
D16: 46086 | E16: 四 | F16: =SUM(M16,S16,U16,W16,AC16,AE16,AG16,AI16,AK16) -> 4496570 | I16: 759369.68 | J16: =I16/$F16 -> 0.16887754 | K16: 904680.65 | L16: =K16/$F16 -> 0.2011935 | M16: =I16+K16 -> 1664050.3 | N16: =M16/$F16 -> 0.37007104 | O16: 250314.85 | P16: =O16/$F16 -> 0.055667954 | Q16: 157714.79 | R16: =Q16/$F16 -> 0.035074466 | S16: =O16+Q16 -> 408029.64 | T16: =S16/$F16 -> 0.09074242 | U16: 98671.55 | V16: =U16/$F16 -> 0.021943737 | W16: 81953.75 | X16: =W16/$F16 -> 0.018225837 | Y16: 185070.2 | Z16: =Y16/$F16 -> 0.041158083 | AA16: 699113.47 | AB16: =AA16/$F16 -> 0.15547706 | AC16: =Y16+AA16 -> 884183.67 | AD16: =AC16/$F16 -> 0.19663514 | AE16: 1289233.8 | AF16: =AE16/F16 -> 0.28671495 | AG16: 0 | AH16: =AG16/$F16 -> 0 | AI16: 0 | AJ16: =AI16/$F16 -> 0 | AK16: 70447.2 | AL16: =AK16/$F16 -> 0.015666875
D17: 46087 | E17: 五 | F17: =SUM(M17,S17,U17,W17,AC17,AE17,AG17,AI17,AK17) -> 3821772.9 | I17: 565614.91 | J17: =I17/$F17 -> 0.14799804 | K17: 832303.86 | L17: =K17/$F17 -> 0.21777952 | M17: =I17+K17 -> 1397918.8 | N17: =M17/F17 -> 0.36577756 | O17: 196738.65 | P17: =O17/$F17 -> 0.051478373 | Q17: 127782.41 | R17: =Q17/$F17 -> 0.033435375 | S17: =O17+Q17 -> 324521.06 | T17: =S17/F17 -> 0.084913748 | U17: 108285.89 | V17: =U17/F17 -> 0.028333942 | W17: 79685.59 | X17: =W17/$F17 -> 0.020850425 | Y17: 196026.81 | Z17: =Y17/$F17 -> 0.051292114 | AA17: 672018.14 | AB17: =AA17/$F17 -> 0.17583937 | AC17: =Y17+AA17 -> 868044.95 | AD17: =AC17/$F17 -> 0.22713148 | AE17: 974997.04 | AF17: =AE17/F17 -> 0.25511643 | AG17: 0 | AH17: =AG17/$F17 -> 0 | AI17: 0 | AJ17: =AI17/$F17 -> 0 | AK17: 68319.6 | AL17: =AK17/$F17 -> 0.017876415
D18: 46088 | E18: 六 | F18: =SUM(M18,S18,U18,W18,AC18,AE18,AG18,AI18,AK18) -> 4127790.8 | I18: 535411.8 | J18: =I18/$F18 -> 0.12970904 | K18: 954382.02 | L18: =K18/$F18 -> 0.23120891 | M18: =I18+K18 -> 1489793.8 | N18: =M18/$F18 -> 0.36091795 | O18: 191833.54 | P18: =O18/$F18 -> 0.046473658 | Q18: 123847.85 | R18: =Q18/$F18 -> 0.030003422 | S18: =O18+Q18 -> 315681.39 | T18: =S18/$F18 -> 0.07647708 | U18: 101929.25 | V18: =U18/$F18 -> 0.024693415 | W18: 65524.79 | X18: =W18/$F18 -> 0.015874058 | Y18: 216407.24 | Z18: =Y18/$F18 -> 0.052426891 | AA18: 773297.13 | AB18: =AA18/$F18 -> 0.18733922 | AC18: =Y18+AA18 -> 989704.37 | AD18: =AC18/$F18 -> 0.23976611 | AE18: 1094887.3 | AF18: =AE18/F18 -> 0.26524777 | AG18: 0 | AH18: =AG18/$F18 -> 0 | AI18: 0 | AJ18: =AI18/$F18 -> 0 | AK18: 70269.9 | AL18: =AK18/$F18 -> 0.01702361
D19: 46089 | E19: 日 | F19: =SUM(M19,S19,U19,W19,AC19,AE19,AG19,AI19,AK19) -> 5624946 | I19: 852217.39 | J19: =I19/$F19 -> 0.15150677 | K19: 1075261.6 | L19: =K19/$F19 -> 0.19115946 | M19: =I19+K19 -> 1927479 | N19: =M19/F19 -> 0.34266623 | O19: 281846.31 | P19: =O19/$F19 -> 0.050106492 | Q19: 159148.46 | R19: =Q19/$F19 -> 0.028293331 | S19: =O19+Q19 -> 440994.77 | T19: =S19/F19 -> 0.078399823 | U19: 129839.87 | V19: =U19/F19 -> 0.023082865 | W19: 81957.96 | X19: =W19/$F19 -> 0.014570444 | Y19: 246041.18 | Z19: =Y19/$F19 -> 0.043741074 | AA19: 937191.64 | AB19: =AA19/$F19 -> 0.16661345 | AC19: =Y19+AA19 -> 1183232.8 | AD19: =AC19/$F19 -> 0.21035452 | AE19: 1792767.3 | AF19: =AE19/F19 -> 0.31871725 | AG19: 0 | AH19: =AG19/$F19 -> 0 | AI19: 0 | AJ19: =AI19/$F19 -> 0 | AK19: 68674.2 | AL19: =AK19/$F19 -> 0.012208864
D20: 46090 | E20: 一 | F20: =SUM(M20,S20,U20,W20,AC20,AE20,AG20,AI20,AK20) -> 5207196.3 | I20: 822660.51 | J20: =I20/$F20 -> 0.15798531 | K20: 1054563.2 | L20: =K20/$F20 -> 0.20252035 | M20: =I20+K20 -> 1877223.7 | N20: =M20/$F20 -> 0.36050565 | O20: 254532.38 | P20: =O20/$F20 -> 0.048880888 | Q20: 160772.09 | R20: =Q20/$F20 -> 0.030874982 | S20: =O20+Q20 -> 415304.47 | T20: =S20/$F20 -> 0.07975587 | U20: 135905.56 | V20: =U20/$F20 -> 0.026099565 | W20: 87841.76 | X20: =W20/$F20 -> 0.016869301 | Y20: 235368.42 | Z20: =Y20/$F20 -> 0.045200605 | AA20: 909672.18 | AB20: =AA20/$F20 -> 0.1746952 | AC20: =Y20+AA20 -> 1145040.6 | AD20: =AC20/$F20 -> 0.2198958 | AE20: 1470114 | AF20: =AE20/F20 -> 0.28232352 | AG20: 0 | AH20: =AG20/$F20 -> 0 | AI20: 0 | AJ20: =AI20/$F20 -> 0 | AK20: 75766.2 | AL20: =AK20/$F20 -> 0.014550287
B21: =B14+7 -> 46099 | D21: 46091 | E21: 二 | G21: =SUM(F21:F27) -> 0 | J21: =I21/$F21 -> #DIV/0! | L21: =K21/$F21 -> #DIV/0! | M21: =I21+K21 -> 0 | N21: =M21/F21 -> #DIV/0! | P21: =O21/$F21 -> #DIV/0! | R21: =Q21/$F21 -> #DIV/0! | S21: =O21+Q21 -> 0 | T21: =S21/F21 -> #DIV/0! | V21: =U21/F21 -> #DIV/0! | X21: =W21/$F21 -> #DIV/0! | Z21: =Y21/$F21 -> #DIV/0! | AB21: =AA21/$F21 -> #DIV/0! | AC21: =Y21+AA21 -> 0 | AD21: =AC21/$F21 -> #DIV/0! | AF21: =AE21/F21 -> #DIV/0! | AH21: =AG21/$F21 -> #DIV/0! | AJ21: =AI21/$F21 -> #DIV/0! | AL21: =AK21/$F21 -> #DIV/0!
D22: 46092 | E22: 三 | J22: =I22/$F22 -> #DIV/0! | L22: =K22/$F22 -> #DIV/0! | M22: =I22+K22 -> 0 | N22: =M22/$F22 -> #DIV/0! | P22: =O22/$F22 -> #DIV/0! | R22: =Q22/$F22 -> #DIV/0! | S22: =O22+Q22 -> 0 | T22: =S22/$F22 -> #DIV/0! | V22: =U22/$F22 -> #DIV/0! | X22: =W22/$F22 -> #DIV/0! | Z22: =Y22/$F22 -> #DIV/0! | AB22: =AA22/$F22 -> #DIV/0! | AC22: =Y22+AA22 -> 0 | AD22: =AC22/$F22 -> #DIV/0! | AF22: =AE22/F22 -> #DIV/0! | AH22: =AG22/$F22 -> #DIV/0! | AJ22: =AI22/$F22 -> #DIV/0! | AL22: =AK22/$F22 -> #DIV/0!
D23: 46093 | E23: 四 | J23: =I23/$F23 -> #DIV/0! | L23: =K23/$F23 -> #DIV/0! | M23: =I23+K23 -> 0 | N23: =M23/F23 -> #DIV/0! | P23: =O23/$F23 -> #DIV/0! | R23: =Q23/$F23 -> #DIV/0! | S23: =O23+Q23 -> 0 | T23: =S23/F23 -> #DIV/0! | V23: =U23/F23 -> #DIV/0! | X23: =W23/$F23 -> #DIV/0! | Z23: =Y23/$F23 -> #DIV/0! | AB23: =AA23/$F23 -> #DIV/0! | AC23: =Y23+AA23 -> 0 | AD23: =AC23/$F23 -> #DIV/0! | AF23: =AE23/F23 -> #DIV/0! | AH23: =AG23/$F23 -> #DIV/0! | AJ23: =AI23/$F23 -> #DIV/0! | AL23: =AK23/$F23 -> #DIV/0!
D24: 46094 | E24: 五 | J24: =I24/$F24 -> #DIV/0! | L24: =K24/$F24 -> #DIV/0! | M24: =I24+K24 -> 0 | N24: =M24/$F24 -> #DIV/0! | P24: =O24/$F24 -> #DIV/0! | R24: =Q24/$F24 -> #DIV/0! | S24: =O24+Q24 -> 0 | T24: =S24/$F24 -> #DIV/0! | V24: =U24/$F24 -> #DIV/0! | X24: =W24/$F24 -> #DIV/0! | Z24: =Y24/$F24 -> #DIV/0! | AB24: =AA24/$F24 -> #DIV/0! | AC24: =Y24+AA24 -> 0 | AD24: =AC24/$F24 -> #DIV/0! | AF24: =AE24/F24 -> #DIV/0! | AH24: =AG24/$F24 -> #DIV/0! | AJ24: =AI24/$F24 -> #DIV/0! | AL24: =AK24/$F24 -> #DIV/0!
D25: 46095 | E25: 六 | J25: =I25/$F25 -> #DIV/0! | L25: =K25/$F25 -> #DIV/0! | M25: =I25+K25 -> 0 | N25: =M25/$F25 -> #DIV/0! | P25: =O25/$F25 -> #DIV/0! | R25: =Q25/$F25 -> #DIV/0! | S25: =O25+Q25 -> 0 | T25: =S25/$F25 -> #DIV/0! | V25: =U25/$F25 -> #DIV/0! | X25: =W25/$F25 -> #DIV/0! | Z25: =Y25/$F25 -> #DIV/0! | AB25: =AA25/$F25 -> #DIV/0! | AC25: =Y25+AA25 -> 0 | AD25: =AC25/$F25 -> #DIV/0! | AF25: =AE25/F25 -> #DIV/0! | AH25: =AG25/$F25 -> #DIV/0! | AJ25: =AI25/$F25 -> #DIV/0! | AL25: =AK25/$F25 -> #DIV/0!
D26: 46096 | E26: 日 | J26: =I26/$F26 -> #DIV/0! | L26: =K26/$F26 -> #DIV/0! | M26: =I26+K26 -> 0 | N26: =M26/F26 -> #DIV/0! | P26: =O26/$F26 -> #DIV/0! | R26: =Q26/$F26 -> #DIV/0! | S26: =O26+Q26 -> 0 | T26: =S26/F26 -> #DIV/0! | V26: =U26/F26 -> #DIV/0! | X26: =W26/$F26 -> #DIV/0! | Z26: =Y26/$F26 -> #DIV/0! | AB26: =AA26/$F26 -> #DIV/0! | AC26: =Y26+AA26 -> 0 | AD26: =AC26/$F26 -> #DIV/0! | AF26: =AE26/F26 -> #DIV/0! | AH26: =AG26/$F26 -> #DIV/0! | AJ26: =AI26/$F26 -> #DIV/0! | AL26: =AK26/$F26 -> #DIV/0!
D27: 46097 | E27: 一 | J27: =I27/$F27 -> #DIV/0! | L27: =K27/$F27 -> #DIV/0! | M27: =I27+K27 -> 0 | N27: =M27/$F27 -> #DIV/0! | P27: =O27/$F27 -> #DIV/0! | R27: =Q27/$F27 -> #DIV/0! | S27: =O27+Q27 -> 0 | T27: =S27/$F27 -> #DIV/0! | V27: =U27/$F27 -> #DIV/0! | X27: =W27/$F27 -> #DIV/0! | Z27: =Y27/$F27 -> #DIV/0! | AB27: =AA27/$F27 -> #DIV/0! | AC27: =Y27+AA27 -> 0 | AD27: =AC27/$F27 -> #DIV/0! | AF27: =AE27/F27 -> #DIV/0! | AH27: =AG27/$F27 -> #DIV/0! | AJ27: =AI27/$F27 -> #DIV/0! | AL27: =AK27/$F27 -> #DIV/0!
B28: =B21+7 -> 46106 | D28: 46098 | E28: 二 | G28: =SUM(F28:F34) -> 0 | J28: =I28/$F28 -> #DIV/0! | L28: =K28/$F28 -> #DIV/0! | M28: =I28+K28 -> 0 | N28: =M28/F28 -> #DIV/0! | P28: =O28/$F28 -> #DIV/0! | R28: =Q28/$F28 -> #DIV/0! | S28: =O28+Q28 -> 0 | T28: =S28/F28 -> #DIV/0! | V28: =U28/F28 -> #DIV/0! | X28: =W28/$F28 -> #DIV/0! | Z28: =Y28/$F28 -> #DIV/0! | AB28: =AA28/$F28 -> #DIV/0! | AC28: =Y28+AA28 -> 0 | AD28: =AC28/$F28 -> #DIV/0! | AF28: =AE28/F28 -> #DIV/0! | AH28: =AG28/$F28 -> #DIV/0! | AJ28: =AI28/$F28 -> #DIV/0! | AL28: =AK28/$F28 -> #DIV/0!
D29: 46099 | E29: 三 | J29: =I29/$F29 -> #DIV/0! | L29: =K29/$F29 -> #DIV/0! | M29: =I29+K29 -> 0 | N29: =M29/$F29 -> #DIV/0! | P29: =O29/$F29 -> #DIV/0! | R29: =Q29/$F29 -> #DIV/0! | S29: =O29+Q29 -> 0 | T29: =S29/$F29 -> #DIV/0! | V29: =U29/$F29 -> #DIV/0! | X29: =W29/$F29 -> #DIV/0! | Z29: =Y29/$F29 -> #DIV/0! | AB29: =AA29/$F29 -> #DIV/0! | AC29: =Y29+AA29 -> 0 | AD29: =AC29/$F29 -> #DIV/0! | AF29: =AE29/F29 -> #DIV/0! | AH29: =AG29/$F29 -> #DIV/0! | AJ29: =AI29/$F29 -> #DIV/0! | AL29: =AK29/$F29 -> #DIV/0!
D30: 46100 | E30: 四 | J30: =I30/$F30 -> #DIV/0! | L30: =K30/$F30 -> #DIV/0! | M30: =I30+K30 -> 0 | N30: =M30/F30 -> #DIV/0! | P30: =O30/$F30 -> #DIV/0! | R30: =Q30/$F30 -> #DIV/0! | S30: =O30+Q30 -> 0 | T30: =S30/F30 -> #DIV/0! | V30: =U30/F30 -> #DIV/0! | X30: =W30/$F30 -> #DIV/0! | Z30: =Y30/$F30 -> #DIV/0! | AB30: =AA30/$F30 -> #DIV/0! | AC30: =Y30+AA30 -> 0 | AD30: =AC30/$F30 -> #DIV/0! | AF30: =AE30/F30 -> #DIV/0! | AH30: =AG30/$F30 -> #DIV/0! | AJ30: =AI30/$F30 -> #DIV/0! | AL30: =AK30/$F30 -> #DIV/0!
D31: 46101 | E31: 五 | J31: =I31/$F31 -> #DIV/0! | L31: =K31/$F31 -> #DIV/0! | M31: =I31+K31 -> 0 | N31: =M31/$F31 -> #DIV/0! | P31: =O31/$F31 -> #DIV/0! | R31: =Q31/$F31 -> #DIV/0! | S31: =O31+Q31 -> 0 | T31: =S31/$F31 -> #DIV/0! | V31: =U31/$F31 -> #DIV/0! | X31: =W31/$F31 -> #DIV/0! | Z31: =Y31/$F31 -> #DIV/0! | AB31: =AA31/$F31 -> #DIV/0! | AC31: =Y31+AA31 -> 0 | AD31: =AC31/$F31 -> #DIV/0! | AF31: =AE31/F31 -> #DIV/0! | AH31: =AG31/$F31 -> #DIV/0! | AJ31: =AI31/$F31 -> #DIV/0! | AL31: =AK31/$F31 -> #DIV/0!
D32: 46102 | E32: 六 | J32: =I32/$F32 -> #DIV/0! | L32: =K32/$F32 -> #DIV/0! | M32: =I32+K32 -> 0 | N32: =M32/$F32 -> #DIV/0! | P32: =O32/$F32 -> #DIV/0! | R32: =Q32/$F32 -> #DIV/0! | S32: =O32+Q32 -> 0 | T32: =S32/$F32 -> #DIV/0! | V32: =U32/$F32 -> #DIV/0! | X32: =W32/$F32 -> #DIV/0! | Z32: =Y32/$F32 -> #DIV/0! | AB32: =AA32/$F32 -> #DIV/0! | AC32: =Y32+AA32 -> 0 | AD32: =AC32/$F32 -> #DIV/0! | AF32: =AE32/F32 -> #DIV/0! | AH32: =AG32/$F32 -> #DIV/0! | AJ32: =AI32/$F32 -> #DIV/0! | AL32: =AK32/$F32 -> #DIV/0!
D33: 46103 | E33: 日 | J33: =I33/$F33 -> #DIV/0! | L33: =K33/$F33 -> #DIV/0! | M33: =I33+K33 -> 0 | N33: =M33/F33 -> #DIV/0! | P33: =O33/$F33 -> #DIV/0! | R33: =Q33/$F33 -> #DIV/0! | S33: =O33+Q33 -> 0 | T33: =S33/F33 -> #DIV/0! | V33: =U33/F33 -> #DIV/0! | X33: =W33/$F33 -> #DIV/0! | Z33: =Y33/$F33 -> #DIV/0! | AB33: =AA33/$F33 -> #DIV/0! | AC33: =Y33+AA33 -> 0 | AD33: =AC33/$F33 -> #DIV/0! | AF33: =AE33/F33 -> #DIV/0! | AH33: =AG33/$F33 -> #DIV/0! | AJ33: =AI33/$F33 -> #DIV/0! | AL33: =AK33/$F33 -> #DIV/0!
D34: 46104 | E34: 一 | J34: =I34/$F34 -> #DIV/0! | L34: =K34/$F34 -> #DIV/0! | M34: =I34+K34 -> 0 | N34: =M34/$F34 -> #DIV/0! | P34: =O34/$F34 -> #DIV/0! | R34: =Q34/$F34 -> #DIV/0! | S34: =O34+Q34 -> 0 | T34: =S34/$F34 -> #DIV/0! | V34: =U34/$F34 -> #DIV/0! | X34: =W34/$F34 -> #DIV/0! | Z34: =Y34/$F34 -> #DIV/0! | AB34: =AA34/$F34 -> #DIV/0! | AC34: =Y34+AA34 -> 0 | AD34: =AC34/$F34 -> #DIV/0! | AF34: =AE34/F34 -> #DIV/0! | AH34: =AG34/$F34 -> #DIV/0! | AJ34: =AI34/$F34 -> #DIV/0! | AL34: =AK34/$F34 -> #DIV/0!
B35: =B28+7 -> 46113 | D35: 46105 | E35: 二 | G35: =SUM(F35:F41) -> 0 | J35: =I35/$F35 -> #DIV/0! | L35: =K35/$F35 -> #DIV/0! | M35: =I35+K35 -> 0 | N35: =M35/F35 -> #DIV/0! | P35: =O35/$F35 -> #DIV/0! | R35: =Q35/$F35 -> #DIV/0! | S35: =O35+Q35 -> 0 | T35: =S35/F35 -> #DIV/0! | V35: =U35/F35 -> #DIV/0! | X35: =W35/$F35 -> #DIV/0! | Z35: =Y35/$F35 -> #DIV/0! | AB35: =AA35/$F35 -> #DIV/0! | AC35: =Y35+AA35 -> 0 | AD35: =AC35/$F35 -> #DIV/0! | AF35: =AE35/F35 -> #DIV/0! | AH35: =AG35/$F35 -> #DIV/0! | AJ35: =AI35/$F35 -> #DIV/0! | AL35: =AK35/$F35 -> #DIV/0!
D36: 46106 | E36: 三 | J36: =I36/$F36 -> #DIV/0! | L36: =K36/$F36 -> #DIV/0! | M36: =I36+K36 -> 0 | N36: =M36/$F36 -> #DIV/0! | P36: =O36/$F36 -> #DIV/0! | R36: =Q36/$F36 -> #DIV/0! | S36: =O36+Q36 -> 0 | T36: =S36/$F36 -> #DIV/0! | V36: =U36/$F36 -> #DIV/0! | X36: =W36/$F36 -> #DIV/0! | Z36: =Y36/$F36 -> #DIV/0! | AB36: =AA36/$F36 -> #DIV/0! | AC36: =Y36+AA36 -> 0 | AD36: =AC36/$F36 -> #DIV/0! | AF36: =AE36/F36 -> #DIV/0! | AH36: =AG36/$F36 -> #DIV/0! | AJ36: =AI36/$F36 -> #DIV/0! | AL36: =AK36/$F36 -> #DIV/0!
D37: 46107 | E37: 四 | J37: =I37/$F37 -> #DIV/0! | L37: =K37/$F37 -> #DIV/0! | M37: =I37+K37 -> 0 | N37: =M37/F37 -> #DIV/0! | P37: =O37/$F37 -> #DIV/0! | R37: =Q37/$F37 -> #DIV/0! | S37: =O37+Q37 -> 0 | T37: =S37/F37 -> #DIV/0! | V37: =U37/F37 -> #DIV/0! | X37: =W37/$F37 -> #DIV/0! | Z37: =Y37/$F37 -> #DIV/0! | AB37: =AA37/$F37 -> #DIV/0! | AC37: =Y37+AA37 -> 0 | AD37: =AC37/$F37 -> #DIV/0! | AF37: =AE37/F37 -> #DIV/0! | AH37: =AG37/$F37 -> #DIV/0! | AJ37: =AI37/$F37 -> #DIV/0! | AL37: =AK37/$F37 -> #DIV/0!
D38: 46108 | E38: 五 | J38: =I38/$F38 -> #DIV/0! | L38: =K38/$F38 -> #DIV/0! | M38: =I38+K38 -> 0 | N38: =M38/$F38 -> #DIV/0! | P38: =O38/$F38 -> #DIV/0! | R38: =Q38/$F38 -> #DIV/0! | S38: =O38+Q38 -> 0 | T38: =S38/$F38 -> #DIV/0! | V38: =U38/$F38 -> #DIV/0! | X38: =W38/$F38 -> #DIV/0! | Z38: =Y38/$F38 -> #DIV/0! | AB38: =AA38/$F38 -> #DIV/0! | AC38: =Y38+AA38 -> 0 | AD38: =AC38/$F38 -> #DIV/0! | AF38: =AE38/F38 -> #DIV/0! | AH38: =AG38/$F38 -> #DIV/0! | AJ38: =AI38/$F38 -> #DIV/0! | AL38: =AK38/$F38 -> #DIV/0!
D39: 46109 | E39: 六 | J39: =I39/$F39 -> #DIV/0! | L39: =K39/$F39 -> #DIV/0! | M39: =I39+K39 -> 0 | N39: =M39/$F39 -> #DIV/0! | P39: =O39/$F39 -> #DIV/0! | R39: =Q39/$F39 -> #DIV/0! | S39: =O39+Q39 -> 0 | T39: =S39/$F39 -> #DIV/0! | V39: =U39/$F39 -> #DIV/0! | X39: =W39/$F39 -> #DIV/0! | Z39: =Y39/$F39 -> #DIV/0! | AB39: =AA39/$F39 -> #DIV/0! | AC39: =Y39+AA39 -> 0 | AD39: =AC39/$F39 -> #DIV/0! | AF39: =AE39/F39 -> #DIV/0! | AH39: =AG39/$F39 -> #DIV/0! | AJ39: =AI39/$F39 -> #DIV/0! | AL39: =AK39/$F39 -> #DIV/0!
D40: 46110 | E40: 日 | J40: =I40/$F40 -> #DIV/0! | L40: =K40/$F40 -> #DIV/0! | M40: =I40+K40 -> 0 | N40: =M40/F40 -> #DIV/0! | P40: =O40/$F40 -> #DIV/0! | R40: =Q40/$F40 -> #DIV/0! | S40: =O40+Q40 -> 0 | T40: =S40/F40 -> #DIV/0! | V40: =U40/F40 -> #DIV/0! | X40: =W40/$F40 -> #DIV/0! | Z40: =Y40/$F40 -> #DIV/0! | AB40: =AA40/$F40 -> #DIV/0! | AC40: =Y40+AA40 -> 0 | AD40: =AC40/$F40 -> #DIV/0! | AF40: =AE40/F40 -> #DIV/0! | AH40: =AG40/$F40 -> #DIV/0! | AJ40: =AI40/$F40 -> #DIV/0! | AL40: =AK40/$F40 -> #DIV/0!
D41: 46111 | E41: 一 | J41: =I41/$F41 -> #DIV/0! | L41: =K41/$F41 -> #DIV/0! | M41: =I41+K41 -> 0 | N41: =M41/$F41 -> #DIV/0! | P41: =O41/$F41 -> #DIV/0! | R41: =Q41/$F41 -> #DIV/0! | S41: =O41+Q41 -> 0 | T41: =S41/$F41 -> #DIV/0! | V41: =U41/$F41 -> #DIV/0! | X41: =W41/$F41 -> #DIV/0! | Z41: =Y41/$F41 -> #DIV/0! | AB41: =AA41/$F41 -> #DIV/0! | AC41: =Y41+AA41 -> 0 | AD41: =AC41/$F41 -> #DIV/0! | AF41: =AE41/F41 -> #DIV/0! | AH41: =AG41/$F41 -> #DIV/0! | AJ41: =AI41/$F41 -> #DIV/0! | AL41: =AK41/$F41 -> #DIV/0!
...

Sheet （４）訂單數量構成比
B2: （4）訂單數量構成比
B3: 資料繳交日 | C3: 月份 | D3: 日期 | F3: 訂單量 | I3: 品類訂單量
I4: 18℃-飯糰 | O4: 18℃-壽司手卷 | U4: 4℃-飯糰 | W4: 4℃-壽司手卷 | Y4: 主食 | AE4: 便當 | AG4: 熱食義麵 | AI4: 季節調理麵 | AK4: 微波小吃
F5: 日 | G5: 週累積 | H5: 月累積 | I5: 一配 | K5: 二配 | M5: 合計 | O5: 一配 | Q5: 二配 | S5: 合計 | U5: 一配 | W5: 一配 | Y5: 一配 | AA5: 二配 | AC5: 合計 | AE5: 一配 | AG5: 一配 | AI5: 一配 | AK5: 一配
I6: 訂單數 | J6: 比例(%) | K6: 訂單數 | L6: 比例(%) | M6: 訂單數 | N6: 比例(%) | O6: 訂單數 | P6: 比例(%) | Q6: 訂單數 | R6: 比例(%) | S6: 訂單數 | T6: 比例(%) | U6: 訂單數 | V6: 比例(%) | W6: 訂單數 | X6: 比例(%) | Y6: 訂單數 | Z6: 比例(%) | AA6: 訂單數 | AB6: 比例(%) | AC6: 訂單數 | AD6: 比例(%) | AE6: 訂單數 | AF6: 比例(%) | AG6: 訂單數 | AH6: 比例(%) | AI6: 訂單數 | AJ6: 比例(%) | AK6: 訂單數 | AL6: 比例(%)
B7: =D15 -> 46085 | D7: 46077 | E7: 二 | F7: =SUM(M7,S7,U7,W7,AC7,AE7,AG7,AI7,AK7) -> 175154 | G7: =SUM(F7:F13) -> 1076054 | I7: 41576 | J7: =I7/$F7 -> 0.23736826 | K7: 53591 | L7: =K7/$F7 -> 0.30596504 | M7: =I7+K7 -> 95167 | N7: =M7/$F7 -> 0.5433333 | O7: 8958 | P7: =O7/$F7 -> 0.051143565 | Q7: 6240 | R7: =Q7/$F7 -> 0.035625792 | S7: =O7+Q7 -> 15198 | T7: =S7/$F7 -> 0.086769357 | U7: 7835 | V7: =U7/$F7 -> 0.044732064 | W7: 9313 | X7: =W7/$F7 -> 0.053170353 | Y7: 4616 | Z7: =Y7/$F7 -> 0.026353951 | AA7: 11354 | AB7: =AA7/$F7 -> 0.064822956 | AC7: =Y7+AA7 -> 15970 | AD7: =AC7/$F7 -> 0.091176907 | AE7: 24205 | AF7: =AE7/$F7 -> 0.13819268 | AG7: 0 | AH7: =AG7/$F7 -> 0 | AI7: 2347 | AJ7: =AI7/$F7 -> 0.013399637 | AK7: 5119 | AL7: =AK7/$F7 -> 0.02922571
D8: 46078 | E8: 三 | F8: =SUM(M8,S8,U8,W8,AC8,AE8,AG8,AI8,AK8) -> 156618 | I8: 40753 | J8: =I8/$F8 -> 0.26020636 | K8: 47002 | L8: =K8/$F8 -> 0.30010599 | M8: =I8+K8 -> 87755 | N8: =M8/$F8 -> 0.56031235 | O8: 8950 | P8: =O8/$F8 -> 0.057145411 | Q8: 5935 | R8: =Q8/$F8 -> 0.03789475 | S8: =O8+Q8 -> 14885 | T8: =S8/$F8 -> 0.095040161 | U8: 5976 | V8: =U8/$F8 -> 0.038156534 | W8: 5080 | X8: =W8/$F8 -> 0.032435608 | Y8: 4338 | Z8: =Y8/$F8 -> 0.027697966 | AA8: 8607 | AB8: =AA8/$F8 -> 0.054955369 | AC8: =Y8+AA8 -> 12945 | AD8: =AC8/$F8 -> 0.082653335 | AE8: 22954 | AF8: =AE8/$F8 -> 0.14656042 | AG8: 0 | AH8: =AG8/$F8 -> 0 | AI8: 2130 | AJ8: =AI8/$F8 -> 0.013599969 | AK8: 4893 | AL8: =AK8/$F8 -> 0.03124162
D9: 46079 | E9: 四 | F9: =SUM(M9,S9,U9,W9,AC9,AE9,AG9,AI9,AK9) -> 129387 | I9: 29097 | J9: =I9/$F9 -> 0.22488349 | K9: 41590 | L9: =K9/$F9 -> 0.32143878 | M9: =I9+K9 -> 70687 | N9: =M9/$F9 -> 0.54632227 | O9: 7351 | P9: =O9/$F9 -> 0.056814054 | Q9: 5068 | R9: =Q9/$F9 -> 0.039169314 | S9: =O9+Q9 -> 12419 | T9: =S9/$F9 -> 0.095983368 | U9: 5083 | V9: =U9/$F9 -> 0.039285245 | W9: 4674 | X9: =W9/$F9 -> 0.036124186 | Y9: 4018 | Z9: =Y9/$F9 -> 0.031054124 | AA9: 7686 | AB9: =AA9/$F9 -> 0.059403186 | AC9: =Y9+AA9 -> 11704 | AD9: =AC9/$F9 -> 0.09045731 | AE9: 18371 | AF9: =AE9/$F9 -> 0.1419849 | AG9: 0 | AH9: =AG9/$F9 -> 0 | AI9: 2016 | AJ9: =AI9/$F9 -> 0.015581163 | AK9: 4433 | AL9: =AK9/$F9 -> 0.034261556
D10: 46080 | E10: 五 | F10: =SUM(M10,S10,U10,W10,AC10,AE10,AG10,AI10,AK10) -> 120519 | I10: 27884 | J10: =I10/$F10 -> 0.23136601 | K10: 40646 | L10: =K10/$F10 -> 0.33725803 | M10: =I10+K10 -> 68530 | N10: =M10/$F10 -> 0.56862403 | O10: 7105 | P10: =O10/$F10 -> 0.05895336 | Q10: 4845 | R10: =Q10/$F10 -> 0.04020113 | S10: =O10+Q10 -> 11950 | T10: =S10/$F10 -> 0.09915449 | U10: 4096 | V10: =U10/$F10 -> 0.033986342 | W10: 2067 | X10: =W10/$F10 -> 0.017150823 | Y10: 3602 | Z10: =Y10/$F10 -> 0.029887404 | AA10: 8442 | AB10: =AA10/$F10 -> 0.070047047 | AC10: =Y10+AA10 -> 12044 | AD10: =AC10/$F10 -> 0.09993445 | AE10: 15752 | AF10: =AE10/$F10 -> 0.13070138 | AG10: 0 | AH10: =AG10/$F10 -> 0 | AI10: 1878 | AJ10: =AI10/$F10 -> 0.015582605 | AK10: 4202 | AL10: =AK10/$F10 -> 0.034865872
D11: 46081 | E11: 六 | F11: =SUM(M11,S11,U11,W11,AC11,AE11,AG11,AI11,AK11) -> 131697 | I11: 27309 | J11: =I11/$F11 -> 0.20736235 | K11: 49114 | L11: =K11/$F11 -> 0.37293181 | M11: =I11+K11 -> 76423 | N11: =M11/$F11 -> 0.58029416 | O11: 6731 | P11: =O11/$F11 -> 0.051109744 | Q11: 4780 | R11: =Q11/$F11 -> 0.036295436 | S11: =O11+Q11 -> 11511 | T11: =S11/$F11 -> 0.08740518 | U11: 4571 | V11: =U11/$F11 -> 0.03470846 | W11: 2494 | X11: =W11/$F11 -> 0.018937409 | Y11: 3911 | Z11: =Y11/$F11 -> 0.029696956 | AA11: 9991 | AB11: =AA11/$F11 -> 0.075863535 | AC11: =Y11+AA11 -> 13902 | AD11: =AC11/$F11 -> 0.10556049 | AE11: 17123 | AF11: =AE11/$F11 -> 0.13001815 | AG11: 0 | AH11: =AG11/$F11 -> 0 | AI11: 980 | AJ11: =AI11/$F11 -> 0.0074413236 | AK11: 4693 | AL11: =AK11/$F11 -> 0.035634828
C12: 三 | D12: 46082 | E12: 日 | F12: =SUM(M12,S12,U12,W12,AC12,AE12,AG12,AI12,AK12) -> 179915 | H12: =SUM(F12:F42) -> 1500422 | I12: 45109 | J12: =I12/$F12 -> 0.25072395 | K12: 56909 | L12: =K12/$F12 -> 0.31631048 | M12: =I12+K12 -> 102018 | N12: =M12/$F12 -> 0.56703443 | O12: 9378 | P12: =O12/$F12 -> 0.052124614 | Q12: 5980 | R12: =Q12/$F12 -> 0.033237918 | S12: =O12+Q12 -> 15358 | T12: =S12/$F12 -> 0.085362532 | U12: 6798 | V12: =U12/$F12 -> 0.037784509 | W12: 5640 | X12: =W12/$F12 -> 0.031348137 | Y12: 5220 | Z12: =Y12/$F12 -> 0.029013701 | AA12: 11326 | AB12: =AA12/$F12 -> 0.06295195 | AC12: =Y12+AA12 -> 16546 | AD12: =AC12/$F12 -> 0.09196565 | AE12: 28946 | AF12: =AE12/$F12 -> 0.16088709 | AG12: 0 | AH12: =AG12/$F12 -> 0 | AI12: 1129 | AJ12: =AI12/$F12 -> 0.0062751855 | AK12: 3480 | AL12: =AK12/$F12 -> 0.019342467
D13: 46083 | E13: 一 | F13: =SUM(M13,S13,U13,W13,AC13,AE13,AG13,AI13,AK13) -> 182764 | I13: 43427 | J13: =I13/$F13 -> 0.23761244 | K13: 60484 | L13: =K13/$F13 -> 0.33094045 | M13: =I13+K13 -> 103911 | N13: =M13/$F13 -> 0.56855289 | O13: 8646 | P13: =O13/$F13 -> 0.047306909 | Q13: 5908 | R13: =Q13/$F13 -> 0.032325841 | S13: =O13+Q13 -> 14554 | T13: =S13/$F13 -> 0.07963275 | U13: 4963 | V13: =U13/$F13 -> 0.027155238 | W13: 4314 | X13: =W13/$F13 -> 0.023604211 | Y13: 4458 | Z13: =Y13/$F13 -> 0.024392112 | AA13: 21302 | AB13: =AA13/$F13 -> 0.11655468 | AC13: =Y13+AA13 -> 25760 | AD13: =AC13/$F13 -> 0.14094679 | AE13: 24221 | AF13: =AE13/$F13 -> 0.1325261 | AG13: 0 | AH13: =AG13/$F13 -> 0 | AI13: 1288 | AJ13: =AI13/$F13 -> 0.0070473397 | AK13: 3753 | AL13: =AK13/$F13 -> 0.020534679
B14: =B7+7 -> 46092 | D14: 46084 | E14: 二 | F14: =SUM(M14,S14,U14,W14,AC14,AE14,AG14,AI14,AK14) -> 182389 | G14: =SUM(F14:F20) -> 1137743 | I14: 42651 | J14: =I14/$F14 -> 0.23384634 | K14: 58621 | L14: =K14/$F14 -> 0.32140644 | M14: =I14+K14 -> 101272 | N14: =M14/$F14 -> 0.55525278 | O14: 13280 | P14: =O14/$F14 -> 0.072811409 | Q14: 5934 | R14: =Q14/$F14 -> 0.032534857 | S14: =O14+Q14 -> 19214 | T14: =S14/$F14 -> 0.10534627 | U14: 4542 | V14: =U14/$F14 -> 0.024902818 | W14: 3285 | X14: =W14/$F14 -> 0.018010955 | Y14: 3562 | Z14: =Y14/$F14 -> 0.019529687 | AA14: 19243 | AB14: =AA14/$F14 -> 0.10550527 | AC14: =Y14+AA14 -> 22805 | AD14: =AC14/$F14 -> 0.12503495 | AE14: 26742 | AF14: =AE14/$F14 -> 0.14662068 | AG14: 0 | AH14: =AG14/$F14 -> 0 | AI14: 1010 | AJ14: =AI14/$F14 -> 0.0055376147 | AK14: 3519 | AL14: =AK14/$F14 -> 0.019293927
D15: 46085 | E15: 三 | F15: =SUM(M15,S15,U15,W15,AC15,AE15,AG15,AI15,AK15) -> 171444 | I15: 41657 | J15: =I15/$F15 -> 0.2429773 | K15: 56001 | L15: =K15/$F15 -> 0.3266431 | M15: =I15+K15 -> 97658 | N15: =M15/$F15 -> 0.5696204 | O15: 11933 | P15: =O15/$F15 -> 0.069602902 | Q15: 6206 | R15: =Q15/$F15 -> 0.036198409 | S15: =O15+Q15 -> 18139 | T15: =S15/$F15 -> 0.10580131 | U15: 4259 | V15: =U15/$F15 -> 0.024841931 | W15: 3035 | X15: =W15/$F15 -> 0.017702573 | Y15: 3325 | Z15: =Y15/$F15 -> 0.019394088 | AA15: 17352 | AB15: =AA15/$F15 -> 0.10121089 | AC15: =Y15+AA15 -> 20677 | AD15: =AC15/$F15 -> 0.12060498 | AE15: 23875 | AF15: =AE15/$F15 -> 0.1392583 | AG15: 0 | AH15: =AG15/$F15 -> 0 | AI15: 0 | AJ15: =AI15/$F15 -> 0 | AK15: 3801 | AL15: =AK15/$F15 -> 0.022170505
D16: 46086 | E16: 四 | F16: =SUM(M16,S16,U16,W16,AC16,AE16,AG16,AI16,AK16) -> 153251 | I16: 38873 | J16: =I16/$F16 -> 0.25365577 | K16: 49420 | L16: =K16/$F16 -> 0.3224775 | M16: =I16+K16 -> 88293 | N16: =M16/$F16 -> 0.57613327 | O16: 10955 | P16: =O16/$F16 -> 0.071484036 | Q16: 5524 | R16: =Q16/$F16 -> 0.036045442 | S16: =O16+Q16 -> 16479 | T16: =S16/$F16 -> 0.10752948 | U16: 3735 | V16: =U16/$F16 -> 0.024371782 | W16: 3103 | X16: =W16/$F16 -> 0.020247829 | Y16: 3260 | Z16: =Y16/$F16 -> 0.021272292 | AA16: 13639 | AB16: =AA16/$F16 -> 0.088997788 | AC16: =Y16+AA16 -> 16899 | AD16: =AC16/$F16 -> 0.11027008 | AE16: 21166 | AF16: =AE16/$F16 -> 0.13811329 | AG16: 0 | AH16: =AG16/$F16 -> 0 | AI16: 0 | AJ16: =AI16/$F16 -> 0 | AK16: 3576 | AL16: =AK16/$F16 -> 0.023334269
D17: 46087 | E17: 五 | F17: =SUM(M17,S17,U17,W17,AC17,AE17,AG17,AI17,AK17) -> 131075 | I17: 28949 | J17: =I17/$F17 -> 0.22085829 | K17: 45623 | L17: =K17/$F17 -> 0.3480679 | M17: =I17+K17 -> 74572 | N17: =M17/$F17 -> 0.56892619 | O17: 8718 | P17: =O17/$F17 -> 0.066511539 | Q17: 4474 | R17: =Q17/$F17 -> 0.03413313 | S17: =O17+Q17 -> 13192 | T17: =S17/$F17 -> 0.10064467 | U17: 4167 | V17: =U17/$F17 -> 0.031790959 | W17: 3023 | X17: =W17/$F17 -> 0.023063132 | Y17: 3453 | Z17: =Y17/$F17 -> 0.026343696 | AA17: 13042 | AB17: =AA17/$F17 -> 0.099500286 | AC17: =Y17+AA17 -> 16495 | AD17: =AC17/$F17 -> 0.12584398 | AE17: 16158 | AF17: =AE17/$F17 -> 0.12327294 | AG17: 0 | AH17: =AG17/$F17 -> 0 | AI17: 0 | AJ17: =AI17/$F17 -> 0 | AK17: 3468 | AL17: =AK17/$F17 -> 0.026458135
D18: 46088 | E18: 六 | F18: =SUM(M18,S18,U18,W18,AC18,AE18,AG18,AI18,AK18) -> 139687 | I18: 27370 | J18: =I18/$F18 -> 0.19593806 | K18: 52622 | L18: =K18/$F18 -> 0.37671365 | M18: =I18+K18 -> 79992 | N18: =M18/$F18 -> 0.57265171 | O18: 8516 | P18: =O18/$F18 -> 0.060964871 | Q18: 4336 | R18: =Q18/$F18 -> 0.031040827 | S18: =O18+Q18 -> 12852 | T18: =S18/$F18 -> 0.092005698 | U18: 3830 | V18: =U18/$F18 -> 0.027418443 | W18: 2479 | X18: =W18/$F18 -> 0.01774682 | Y18: 3812 | Z18: =Y18/$F18 -> 0.027289583 | AA18: 14992 | AB18: =AA18/$F18 -> 0.10732566 | AC18: =Y18+AA18 -> 18804 | AD18: =AC18/$F18 -> 0.13461525 | AE18: 18163 | AF18: =AE18/$F18 -> 0.13002642 | AG18: 0 | AH18: =AG18/$F18 -> 0 | AI18: 0 | AJ18: =AI18/$F18 -> 0 | AK18: 3567 | AL18: =AK18/$F18 -> 0.025535662
D19: 46089 | E19: 日 | F19: =SUM(M19,S19,U19,W19,AC19,AE19,AG19,AI19,AK19) -> 184408 | I19: 43794 | J19: =I19/$F19 -> 0.23748427 | K19: 59347 | L19: =K19/$F19 -> 0.32182443 | M19: =I19+K19 -> 103141 | N19: =M19/$F19 -> 0.55930871 | O19: 12412 | P19: =O19/$F19 -> 0.067307275 | Q19: 5576 | R19: =Q19/$F19 -> 0.0302373 | S19: =O19+Q19 -> 17988 | T19: =S19/$F19 -> 0.097544575 | U19: 4916 | V19: =U19/$F19 -> 0.026658279 | W19: 3108 | X19: =W19/$F19 -> 0.016853933 | Y19: 4334 | Z19: =Y19/$F19 -> 0.023502234 | AA19: 18040 | AB19: =AA19/$F19 -> 0.097826559 | AC19: =Y19+AA19 -> 22374 | AD19: =AC19/$F19 -> 0.12132879 | AE19: 29395 | AF19: =AE19/$F19 -> 0.15940198 | AG19: 0 | AH19: =AG19/$F19 -> 0 | AI19: 0 | AJ19: =AI19/$F19 -> 0 | AK19: 3486 | AL19: =AK19/$F19 -> 0.018903735
D20: 46090 | E20: 一 | F20: =SUM(M20,S20,U20,W20,AC20,AE20,AG20,AI20,AK20) -> 175489 | I20: 42280 | J20: =I20/$F20 -> 0.24092678 | K20: 58182 | L20: =K20/$F20 -> 0.33154215 | M20: =I20+K20 -> 100462 | N20: =M20/$F20 -> 0.57246893 | O20: 11112 | P20: =O20/$F20 -> 0.063320208 | Q20: 5630 | R20: =Q20/$F20 -> 0.032081783 | S20: =O20+Q20 -> 16742 | T20: =S20/$F20 -> 0.095401991 | U20: 5138 | V20: =U20/$F20 -> 0.029278188 | W20: 3328 | X20: =W20/$F20 -> 0.018964152 | Y20: 4146 | Z20: =Y20/$F20 -> 0.023625412 | AA20: 17538 | AB20: =AA20/$F20 -> 0.099937888 | AC20: =Y20+AA20 -> 21684 | AD20: =AC20/$F20 -> 0.1235633 | AE20: 24289 | AF20: =AE20/$F20 -> 0.13840754 | AG20: 0 | AH20: =AG20/$F20 -> 0 | AI20: 0 | AJ20: =AI20/$F20 -> 0 | AK20: 3846 | AL20: =AK20/$F20 -> 0.021915904
B21: =B14+7 -> 46099 | D21: 46091 | E21: 二 | G21: =SUM(F21:F27) -> 0 | J21: =I21/$F21 -> #DIV/0! | L21: =K21/$F21 -> #DIV/0! | M21: =I21+K21 -> 0 | N21: =M21/$F21 -> #DIV/0! | P21: =O21/$F21 -> #DIV/0! | R21: =Q21/$F21 -> #DIV/0! | S21: =O21+Q21 -> 0 | T21: =S21/$F21 -> #DIV/0! | V21: =U21/$F21 -> #DIV/0! | X21: =W21/$F21 -> #DIV/0! | Z21: =Y21/$F21 -> #DIV/0! | AB21: =AA21/$F21 -> #DIV/0! | AC21: =Y21+AA21 -> 0 | AD21: =AC21/$F21 -> #DIV/0! | AF21: =AE21/$F21 -> #DIV/0! | AH21: =AG21/$F21 -> #DIV/0! | AJ21: =AI21/$F21 -> #DIV/0! | AL21: =AK21/$F21 -> #DIV/0!
D22: 46092 | E22: 三 | J22: =I22/$F22 -> #DIV/0! | L22: =K22/$F22 -> #DIV/0! | M22: =I22+K22 -> 0 | N22: =M22/$F22 -> #DIV/0! | P22: =O22/$F22 -> #DIV/0! | R22: =Q22/$F22 -> #DIV/0! | S22: =O22+Q22 -> 0 | T22: =S22/$F22 -> #DIV/0! | V22: =U22/$F22 -> #DIV/0! | X22: =W22/$F22 -> #DIV/0! | Z22: =Y22/$F22 -> #DIV/0! | AB22: =AA22/$F22 -> #DIV/0! | AC22: =Y22+AA22 -> 0 | AD22: =AC22/$F22 -> #DIV/0! | AF22: =AE22/$F22 -> #DIV/0! | AH22: =AG22/$F22 -> #DIV/0! | AJ22: =AI22/$F22 -> #DIV/0! | AL22: =AK22/$F22 -> #DIV/0!
D23: 46093 | E23: 四 | J23: =I23/$F23 -> #DIV/0! | L23: =K23/$F23 -> #DIV/0! | M23: =I23+K23 -> 0 | N23: =M23/$F23 -> #DIV/0! | P23: =O23/$F23 -> #DIV/0! | R23: =Q23/$F23 -> #DIV/0! | S23: =O23+Q23 -> 0 | T23: =S23/$F23 -> #DIV/0! | V23: =U23/$F23 -> #DIV/0! | X23: =W23/$F23 -> #DIV/0! | Z23: =Y23/$F23 -> #DIV/0! | AB23: =AA23/$F23 -> #DIV/0! | AC23: =Y23+AA23 -> 0 | AD23: =AC23/$F23 -> #DIV/0! | AF23: =AE23/$F23 -> #DIV/0! | AH23: =AG23/$F23 -> #DIV/0! | AJ23: =AI23/$F23 -> #DIV/0! | AL23: =AK23/$F23 -> #DIV/0!
D24: 46094 | E24: 五 | J24: =I24/$F24 -> #DIV/0! | L24: =K24/$F24 -> #DIV/0! | M24: =I24+K24 -> 0 | N24: =M24/$F24 -> #DIV/0! | P24: =O24/$F24 -> #DIV/0! | R24: =Q24/$F24 -> #DIV/0! | S24: =O24+Q24 -> 0 | T24: =S24/$F24 -> #DIV/0! | V24: =U24/$F24 -> #DIV/0! | X24: =W24/$F24 -> #DIV/0! | Z24: =Y24/$F24 -> #DIV/0! | AB24: =AA24/$F24 -> #DIV/0! | AC24: =Y24+AA24 -> 0 | AD24: =AC24/$F24 -> #DIV/0! | AF24: =AE24/$F24 -> #DIV/0! | AH24: =AG24/$F24 -> #DIV/0! | AJ24: =AI24/$F24 -> #DIV/0! | AL24: =AK24/$F24 -> #DIV/0!
