Workbook

Sheet 數值累積總表(月)
B1: 項目 | D1: 1月 | E1: 2月 | F1: 3月 | G1: 4月 | H1: 5月 | I1: 6月 | J1: 7月 | K1: 8月 | L1: 9月 | M1: 10月 | N1: 11月 | O1: 12月 | P1: 合計/平均
B2: （１）收支狀況 | C2: 業績金額(千元) | D2: 146299.94 | E2: 116569.43 | F2: 148838 | P2: =SUM(D2:O2) -> 411707.36
C3: 訂單數量 | D3: 4768701 | E3: 3787002 | F3: 5045753 | P3: =SUM(D3:O3) -> 13601456
C4: 材料費(千元) | D4: 93253 | E4: 74777 | F4: 93614 | P4: =SUM(D4:O4) -> 261644
C5: 材料費率(%) | D5: 0.655 | E5: 0.653 | F5: 0.648 | G5: =IFERROR(G4/G2, "") | H5: =IFERROR(H4/H2, "") | I5: =IFERROR(I4/I2, "") | J5: =IFERROR(J4/J2, "") | K5: =IFERROR(K4/K2, "") | L5: =IFERROR(L4/L2, "") | M5: =IFERROR(M4/M2, "") | N5: =IFERROR(N4/N2, "") | O5: =IFERROR(O4/O2, "") | P5: =AVERAGEIF(D5:O5, ">0") -> 0.652
C6: 勞務成本(千元) | D6: 22378 | E6: 22860 | F6: 22710 | P6: =SUM(D6:O6) -> 67948
C7: 勞務費率(%) | D7: 0.157 | E7: 0.2 | F7: 0.157 | G7: =IFERROR(G6/G2, "") | H7: =IFERROR(H6/H2, "") | I7: =IFERROR(I6/I2, "") | J7: =IFERROR(J6/J2, "") | K7: =IFERROR(K6/K2, "") | L7: =IFERROR(L6/L2, "") | M7: =IFERROR(M6/M2, "") | N7: =IFERROR(N6/N2, "") | O7: =IFERROR(O6/O2, "") | P7: =AVERAGEIF(D7:O7, ">0") -> 0.17133333
B9: （２）ＫＰＩ達成進度 | C9: 人時性KPI | D9: 497.6 | E9: 497.6 | F9: 497.6 | P9: =AVERAGEIF(D9:O9, ">0") -> 497.6
C10: 人時性(個/月均) | D10: 458.38414 | E10: 476.04172 | F10: 409.81563 | P10: =AVERAGEIF(D10:O10, ">0") -> 448.0805
C11: 人時達成率(%/月均) | D11: =IFERROR(D10/D9, "") -> 0.92118999 | E11: =IFERROR(E10/E9, "") -> 0.95667547 | F11: =IFERROR(F10/F9, "") -> 0.82358447 | G11: =IFERROR(G10/G9, "") | H11: =IFERROR(H10/H9, "") | I11: =IFERROR(I10/I9, "") | J11: =IFERROR(J10/J9, "") | K11: =IFERROR(K10/K9, "") | ... O11: =IFERROR(O10/O9, "") | P11: =AVERAGEIF(D11:O11, ">0") -> 0.90048331
C12: 半成品-報廢(%) | D12: 0.0024135432 | E12: 0.0023657636 | F12: 0.0020222248 | P12: =AVERAGEIF(D12:O12, ">0") -> 0.0022671772
C13: 半成品-超用(%) | D13: 0.0055994433 | E13: 0.0052393001 | F13: 0.0048799138 | P13: =AVERAGEIF(D13:O13, ">0") -> 0.0052395524
C14: 固定產線-導入率(%) | D14: 0.9 | E14: 0.9 | F14: 0.9 | P14: =AVERAGEIF(D14:O14, ">0") -> 0.9
C15: 教育訓練-實施率(%) | D15: 0.057692308 | E15: 0.13873626 | F15: 0.21960298 | P15: 0.2196
B17: （３）業績構成比 | C17: 18℃-飯糰(061,063) | D17: 0.36139567 | E17: 0.34737657 | F17: 0.36414345 | P17: =AVERAGEIF(D17:O17, ">0") -> 0.35763856
C18: 18℃-壽司手卷(071,072,075,076) | D18: 0.069633574 | E18: 0.077793665 | F18: 0.084480826 | P18: =AVERAGEIF(D18:O18, ">0") -> 0.077302689
C19: 4℃-飯糰(065) | D19: 0.022453222 | E19: 0.02167645 | F19: 0.02436516 | P19: =AVERAGEIF(D19:O19, ">0") -> 0.022831611
C20: 4℃-壽司手卷(077) | D20: 0.008585039 | E20: 0.0099523222 | F20: 0.014684918 | P20: =AVERAGEIF(D20:O20, ">0") -> 0.011074093
C21: 主食(091,092,093,094,095) | D21: 0.16215294 | E21: 0.18214708 | F21: 0.20289324 | P21: =AVERAGEIF(D21:O21, ">0") -> 0.18239775
C22: 便當(083) | D22: 0.27057088 | E22: 0.27529226 | F22: 0.29293399 | P22: =AVERAGEIF(D22:O22, ">0") -> 0.27959904
C23: 熱食義麵(122,123,124,126) | D23: 0.029234371 | E23: 0.0089796819 | F23: 0 | P23: =AVERAGEIF(D23:O23, ">0") -> 0.019107026
C24: 季節調理麵(111,112) | D24: 0.040564166 | E24: 0.040109499 | F24: 0.0016541185 | P24: =AVERAGEIF(D24:O24, ">0") -> 0.027442594
C25: 微波小吃(153,154,155) | D25: 0.035410133 | E25: 0.036672477 | F25: 0.01484429 | P25: =AVERAGEIF(D25:O25, ">0") -> 0.028975633
B27: （４）訂單數量構成比 | C27: 18℃-飯糰(061,063) | D27: 0.58577126 | E27: 0.57025346 | F27: 0.57640852 | P27: =AVERAGEIF(D27:O27, ">0") -> 0.57747775
C28: 18℃-壽司手卷(071,072,075,076) | D28: 0.081693946 | E28: 0.091615478 | F28: 0.10179987 | P28: =AVERAGEIF(D28:O28, ">0") -> 0.091703098
C29: 4℃-飯糰(065) | D29: 0.024966128 | E29: 0.023825971 | F29: 0.026809081 | P29: =AVERAGEIF(D29:O29, ">0") -> 0.025200393
C30: 4℃-壽司手卷(077) | D30: 0.0097963785 | E30: 0.011706622 | F30: 0.016401516 | P30: =AVERAGEIF(D30:O30, ">0") -> 0.012634839
C31: 主食(091,092,093,094,095) | D31: 0.089953008 | E31: 0.10114835 | F31: 0.11343936 | P31: =AVERAGEIF(D31:O31, ">0") -> 0.10151357
C32: 便當(083) | D32: 0.13708178 | E32: 0.14060779 | F32: 0.14223546 | P32: =AVERAGEIF(D32:O32, ">0") -> 0.13997501
C33: 熱食義麵(122,123,124,126) | D33: 0.015652481 | E33: 0.0048238686 | F33: 0 | P33: =AVERAGEIF(D33:O33, ">0") -> 0.010238175
C34: 季節調理麵(111,112) | D34: 0.022004735 | E34: 0.020902022 | F34: 0.00067918505 | P34: =AVERAGEIF(D34:O34, ">0") -> 0.014528647
C35: 微波小吃(153,154,155) | D35: 0.033080287 | E35: 0.035116432 | F35: 0.02222701 | P35: =AVERAGEIF(D35:O35, ">0") -> 0.030141243
B37: （５）品群別人時生產性 | C37: 18℃-飯糰(061,063) | D37: 768.96509 | E37: 774.12086 | F37: 757.59042 | P37: =AVERAGEIF(D37:O37, ">0") -> 766.89213
C38: 18℃-壽司手卷(071,072,075,076) | D38: 280.52358 | E38: 304.46478 | F38: 311.70582 | P38: =AVERAGEIF(D38:O38, ">0") -> 298.89806
C39: 4℃-飯糰(065) | D39: 258.56167 | E39: 203.24374 | F39: 331.13667 | P39: =AVERAGEIF(D39:O39, ">0") -> 264.31403
C40: 4℃-壽司手卷(077) | D40: 486.07171 | E40: 490.19814 | F40: 493.97618 | P40: =AVERAGEIF(D40:O40, ">0") -> 490.08201
C41: 主食(091,092,093,094,095) | D41: 82.669482 | E41: 81.452412 | F41: 79.949999 | P41: =AVERAGEIF(D41:O41, ">0") -> 81.357298
C42: 便當(083) | D42: 78.306367 | E42: 77.971323 | F42: 77.906797 | P42: =AVERAGEIF(D42:O42, ">0") -> 78.061495
C43: 熱食義麵(122,123,124,126) | D43: 76.250133 | E43: 72.949976 | F43: 0 | P43: =AVERAGEIF(D43:O43, ">0") -> 74.600054
C44: 季節調理麵(111,112) | D44: 110.8083 | E44: 97.157501 | F44: 84.601424 | P44: =AVERAGEIF(D44:O44, ">0") -> 97.52241
...

Sheet 生產管理報表(月)
A1: 大溪廠生產管理報表
A3: 月別 | B3: 3 | C3: 工廠 | D3: 大溪廠
A4: （１）收支狀況 | E4: ※單位：千元 | G4: （２）ＫＰＩ達成進度
A5: 項目 | B5: 當月 | C5: 前月 | D5: 差異 | E5: 累計 | G5: 項目 | H5: KPI | I5: 當月 | J5: 前月 | K5: 累計 | L5: ※補充
A6: 業績金額 | B6: ='（１）收支狀況'!H10/1000 -> 148838 | C6: ='數值累積總表(月)'!E2 -> 116569.43 | D6: =B6-C6 -> 32268.568 | E6: ='數值累積總表(月)'!P2 -> 411707.36 | G6: 人時性(個/月均) | H6: 497.6 | I6: ='（２）ＫＰＩ達成進度'!H10 -> 409.82815 | J6: ='數值累積總表(月)'!E10 -> 476.04172 | K6: ='數值累積總表(月)'!P10 -> 448.0805 | L6: 個／MH
A7: 訂單數量 | B7: ='（１）收支狀況'!K10 -> 5045753 | C7: ='數值累積總表(月)'!E3 -> 3787002 | D7: =B7-C7 -> 1258751 | E7: ='數值累積總表(月)'!P3 -> 13601456 | G7: 人時達成率(%/月均) | H7: 0.8 | I7: ='（２）ＫＰＩ達成進度'!K10 -> 0.82360963 | J7: ='數值累積總表(月)'!E11 -> 0.95667547 | K7: ='數值累積總表(月)'!P11 -> 0.90048331 | L7: 達成率
A8: 材料費 | B8: 93614 | C8: ='數值累積總表(月)'!E4 -> 74777 | D8: =B8-C8 -> 18837 | E8: ='數值累積總表(月)'!P4 -> 261644 | G8: 半成品-報廢(%) | H8: 0.0025 | I8: ='（２）ＫＰＩ達成進度'!N10 -> 0.0020218797 | J8: ='數值累積總表(月)'!E12 -> 0.0023657636 | K8: ='數值累積總表(月)'!P12 -> 0.0022671772 | L8: 報廢率
A9: 材料費率 | B9: 0.648 | C9: ='數值累積總表(月)'!E5 -> 0.653 | D9: =B9-C9 -> -0.005 | E9: ='數值累積總表(月)'!P5 -> 0.652 | G9: 半成品-超用(%) | H9: 0.004 | I9: ='（２）ＫＰＩ達成進度'!Q10 -> 0.0048669349 | J9: ='數值累積總表(月)'!E13 -> 0.0052393001 | K9: ='數值累積總表(月)'!P13 -> 0.0052395524 | L9: 超用率
A10: 勞務成本 | B10: 22710 | C10: ='數值累積總表(月)'!E6 -> 22860 | D10: =B10-C10 -> -150 | E10: ='數值累積總表(月)'!P6 -> 67948 | G10: 固定產線-導入率(%) | H10: 0.8 | I10: ='（２）ＫＰＩ達成進度'!T10 -> 0.9 | J10: ='數值累積總表(月)'!E14 -> 0.9 | K10: ='數值累積總表(月)'!P14 -> 0.9 | L10: 導入率
A11: 勞務費率 | B11: 0.157 | C11: ='數值累積總表(月)'!E7 -> 0.2 | D11: =B11-C11 -> -0.043 | E11: ='數值累積總表(月)'!P7 -> 0.17133333 | G11: 教育訓練-實施率(%) | H11: 1 | I11: ='（２）ＫＰＩ達成進度'!W10 -> 0.21960298 | J11: ='數值累積總表(月)'!E15 -> 0.13873626 | K11: ='數值累積總表(月)'!P15 -> 0.2196 | L11: 實施率
A13: （３）業績構成比 | E13: ※單位：千元 | G13: （４）訂單數量構成比 | K13: ※單位：個
B14: 當月 | C14: 比例 | D14: 前月 | E14: 差異 | H14: 當月 | I14: 比例 | J14: 前月 | K14: 差異
A15: 18℃-飯糰(061,063) | B15: =SUM('（３）業績構成比'!M12:M42)/1000 -> 54198.383 | C15: =IFERROR(B15/$B$6,"") -> 0.36414345 | D15: ='數值累積總表(月)'!E17 -> 0.34737657 | E15: =IFERROR(C15-D15,"") -> 0.016766884 | G15: 18℃-飯糰(061,063) | H15: =SUM('（４）訂單數量構成比'!M12:M42) -> 2908415 | I15: =IFERROR(H15/$B$7,"") -> 0.57640852 | J15: ='數值累積總表(月)'!E27 -> 0.57025346 | K15: =IFERROR(I15-J15,"") -> 0.0061550545
A16: 18℃-壽司手卷(071,072,075,076) | B16: =SUM('（３）業績構成比'!S12:S42)/1000 -> 12573.957 | C16: =IFERROR(B16/$B$6,"") -> 0.084480826 | D16: ='數值累積總表(月)'!E18 -> 0.077793665 | E16: =IFERROR(C16-D16,"") -> 0.0066871614 | G16: 18℃-壽司手卷(071,072,075,076) | H16: =SUM('（４）訂單數量構成比'!S12:S42) -> 513657 | I16: =IFERROR(H16/$B$7,"") -> 0.10179987 | J16: ='數值累積總表(月)'!E28 -> 0.091615478 | K16: =IFERROR(I16-J16,"") -> 0.010184392
A17: 4℃-飯糰(065) | B17: =SUM('（３）業績構成比'!U12:U42)/1000 -> 3626.4617 | C17: =IFERROR(B17/$B$6,"") -> 0.02436516 | D17: ='數值累積總表(月)'!E19 -> 0.02167645 | E17: =IFERROR(C17-D17,"") -> 0.0026887106 | G17: 4℃-飯糰(065) | H17: =SUM('（４）訂單數量構成比'!U12:U42) -> 135272 | I17: =IFERROR(H17/$B$7,"") -> 0.026809081 | J17: ='數值累積總表(月)'!E29 -> 0.023825971 | K17: =IFERROR(I17-J17,"") -> 0.0029831098
A18: 4℃-壽司手卷(077) | B18: =SUM('（３）業績構成比'!W12:W42)/1000 -> 2185.6738 | C18: =IFERROR(B18/$B$6,"") -> 0.014684918 | D18: ='數值累積總表(月)'!E20 -> 0.0099523222 | E18: =IFERROR(C18-D18,"") -> 0.0047325959 | G18: 4℃-壽司手卷(077) | H18: =SUM('（４）訂單數量構成比'!W12:W42) -> 82758 | I18: =IFERROR(H18/$B$7,"") -> 0.016401516 | J18: ='數值累積總表(月)'!E30 -> 0.011706622 | K18: =IFERROR(I18-J18,"") -> 0.0046948945
A19: 主食(091,092,093,094,095) | B19: =SUM('（３）業績構成比'!AC12:AC42)/1000 -> 30198.224 | C19: =IFERROR(B19/$B$6,"") -> 0.20289324 | D19: ='數值累積總表(月)'!E21 -> 0.18214708 | E19: =IFERROR(C19-D19,"") -> 0.020746161 | G19: 主食(091,092,093,094,095) | H19: =SUM('（４）訂單數量構成比'!AC12:AC42) -> 572387 | I19: =IFERROR(H19/$B$7,"") -> 0.11343936 | J19: ='數值累積總表(月)'!E31 -> 0.10114835 | K19: =IFERROR(I19-J19,"") -> 0.012291013
A20: 便當(083) | B20: =SUM('（３）業績構成比'!AE12:AE42)/1000 -> 43599.709 | C20: =IFERROR(B20/$B$6,"") -> 0.29293399 | D20: ='數值累積總表(月)'!E22 -> 0.27529226 | E20: =IFERROR(C20-D20,"") -> 0.017641737 | G20: 便當(083) | H20: =SUM('（４）訂單數量構成比'!AE12:AE42) -> 717685 | I20: =IFERROR(H20/$B$7,"") -> 0.14223546 | J20: ='數值累積總表(月)'!E32 -> 0.14060779 | K20: =IFERROR(I20-J20,"") -> 0.0016276654
A21: 熱食義麵(122,123,124,126) | B21: =SUM('（３）業績構成比'!AG12:AG42)/1000 -> 0 | C21: =IFERROR(B21/$B$6,"") -> 0 | D21: ='數值累積總表(月)'!E23 -> 0.0089796819 | E21: =IFERROR(C21-D21,"") -> -0.0089796819 | G21: 熱食義麵(122,123,124,126) | H21: =SUM('（４）訂單數量構成比'!AG12:AG42) -> 0 | I21: =IFERROR(H21/$B$7,"") -> 0 | J21: ='數值累積總表(月)'!E33 -> 0.0048238686 | K21: =IFERROR(I21-J21,"") -> -0.0048238686
A22: 季節調理麵(111,112) | B22: =SUM('（３）業績構成比'!AI12:AI42)/1000 -> 246.19568 | C22: =IFERROR(B22/$B$6,"") -> 0.0016541185 | D22: ='數值累積總表(月)'!E24 -> 0.040109499 | E22: =IFERROR(C22-D22,"") -> -0.03845538 | G22: 季節調理麵(111,112) | H22: =SUM('（４）訂單數量構成比'!AI12:AI42) -> 3427 | I22: =IFERROR(H22/$B$7,"") -> 0.00067918505 | J22: ='數值累積總表(月)'!E34 -> 0.020902022 | K22: =IFERROR(I22-J22,"") -> -0.020222837
A23: 微波小吃(153,154,155) | B23: =SUM('（３）業績構成比'!AK12:AK42)/1000 -> 2209.3944 | C23: =IFERROR(B23/$B$6,"") -> 0.01484429 | D23: ='數值累積總表(月)'!E25 -> 0.036672477 | E23: =IFERROR(C23-D23,"") -> -0.021828188 | G23: 微波小吃(153,154,155) | H23: =SUM('（４）訂單數量構成比'!AK12:AK42) -> 112152 | I23: =IFERROR(H23/$B$7,"") -> 0.02222701 | J23: ='數值累積總表(月)'!E35 -> 0.035116432 | K23: =IFERROR(I23-J23,"") -> -0.012889423
C24: =SUM(C15:C23) -> 1 | D24: =SUM(D15:D23) -> 1 | I24: =SUM(I15:I23) -> 1 | J24: =SUM(J15:J23) -> 1
A26: （５）品群別人時生產性
A27: 品群 | B27: 當月 | C27: 前月 | D27: 差異 | E27: 累計
A28: 18℃-飯A15:A23糰(061,063) | B28: ='（５-1）品群別人時生產性(18℃-飯糰)'!C1 -> 757.59042 | C28: ='數值累積總表(月)'!E37 -> 774.12086 | D28: =B28-C28 -> -16.53044 | E28: ='數值累積總表(月)'!P37 -> 766.89213
A29: 18℃-壽司手卷(071,072,075,076) | B29: ='（５-2）品群別人時生產性(18℃-壽司手卷)'!C1 -> 311.70582 | C29: ='數值累積總表(月)'!E38 -> 304.46478 | D29: =B29-C29 -> 7.2410358 | E29: ='數值累積總表(月)'!P38 -> 298.89806
A30: 4℃-飯糰(065) | B30: ='（５-3）品群別人時生產性(4℃-飯糰)'!C1 -> 331.13667 | C30: ='數值累積總表(月)'!E39 -> 203.24374 | D30: =B30-C30 -> 127.89293 | E30: ='數值累積總表(月)'!P39 -> 264.31403
A31: 4℃-壽司手卷(077) | B31: ='（５-4）品群別人時生產性(4℃-壽司手卷)'!C1 -> 493.97618 | C31: ='數值累積總表(月)'!E40 -> 490.19814 | D31: =B31-C31 -> 3.7780393 | E31: ='數值累積總表(月)'!P40 -> 490.08201
A32: 主食(091,092,093,094,095) | B32: ='（５-5）品群別人時生產性(微波主食) '!C1 -> 79.949999 | C32: ='數值累積總表(月)'!E41 -> 81.452412 | D32: =B32-C32 -> -1.5024123 | E32: ='數值累積總表(月)'!P41 -> 81.357298
A33: 便當(083) | B33: ='（５-6）品群別人時生產性(便當)'!C1 -> 77.906797 | C33: ='數值累積總表(月)'!E42 -> 77.971323 | D33: =B33-C33 -> -0.064525766 | E33: ='數值累積總表(月)'!P42 -> 78.061495
A34: 熱食義麵(122,123,124,126) | B34: ='（５-7）品群別人時生產性(熱食義麵) '!C1 -> 0 | C34: ='數值累積總表(月)'!E43 -> 72.949976 | D34: =B34-C34 -> -72.949976 | E34: ='數值累積總表(月)'!P43 -> 74.600054
A35: 季節調理麵(111,112) | B35: ='（５-8）品群別人時生產性(季節調理麵) '!C1 -> 84.601424 | C35: ='數值累積總表(月)'!E44 -> 97.157501 | D35: =B35-C35 -> -12.556077 | E35: ='數值累積總表(月)'!P44 -> 97.52241
A36: 微波小吃(153,154,155) | B36: ='（５-9）品群別人時生產性(微波小吃)'!C1 -> 83.044479 | C36: ='數值累積總表(月)'!E45 -> 77.592138 | D36: =B36-C36 -> 5.4523404 | E36: ='數值累積總表(月)'!P45 -> 78.920094

Sheet 生產管理報表(週) 
A1: 大溪廠生產管理報表
A3: 月別 | B3: 4 | C3: 週別 | D3: W1 | E3: 工廠 | F3: 大溪廠
A4: （１）收支狀況 | E4: ※單位：千元 | G4: （２）ＫＰＩ達成進度
A5: 項目 | B5: 當週 | C5: 前週 | D5: 差異 | E5: 累計 | G5: 項目 | H5: KPI | I5: 當週 | J5: 前週 | K5: 累計 | L5: ※補充
A6: 業績金額 | B6: ='（１）收支狀況'!G40/1000 -> 30121.755 | C6: 32252.127 | D6: =B6-C6 -> -2130.3721 | E6: ='（１）收支狀況'!H10:H10/1000 -> 148838 | G6: 人時性(個/月均) | I6: ='（２）ＫＰＩ達成進度'!G40 -> 410.90558 | J6: 416.99684 | K6: ='（２）ＫＰＩ達成進度'!H10 -> 409.82815 | L6: 個／MH
A7: 訂單數量 | B7: ='（１）收支狀況'!J40 -> 995977 | C7: 1105590 | D7: =B7-C7 -> -109613 | E7: ='（１）收支狀況'!K10:K10 -> 5045753 | G7: 人時達成率(%/月均) | H7: 0.8 | I7: ='（２）ＫＰＩ達成進度'!J40 -> 0.82577488 | J7: 0.83801616 | K7: ='（２）ＫＰＩ達成進度'!K10 -> 0.82360963 | L7: 達成率
A8: 材料費 | B8: ='（１）收支狀況'!M40/1000 -> 20020.074 | C8: 21273.508 | D8: =B8-C8 -> -1253.4345 | E8: ='（１）收支狀況'!N10:N10/1000 -> 98384.727 | G8: 半成品-報廢(%) | H8: 0.0025 | I8: ='（２）ＫＰＩ達成進度'!M40 -> 0.002010833 | J8: 0.0020062482 | K8: ='（２）ＫＰＩ達成進度'!N10 -> 0.0020218797 | L8: 報廢率
A9: 材料費率 | B9: ='（１）收支狀況'!P40 -> 0.66463837 | C9: 0.65960017 | D9: =B9-C9 -> 0.0050381958 | E9: ='（１）收支狀況'!Q10 -> 0.66101888 | G9: 半成品-超用(%) | H9: 0.004 | I9: ='（２）ＫＰＩ達成進度'!P40 -> 0.0044376523 | J9: 0.0045274475 | K9: ='（２）ＫＰＩ達成進度'!Q10 -> 0.0048669349 | L9: 超用率
A10: 勞務成本 | B10: ='（１）收支狀況'!S40/1000 -> 5296.9028 | C10: 5198.276 | D10: =B10-C10 -> 98.626784 | E10: ='（１）收支狀況'!T10/1000 -> 23834.465 | G10: 固定產線-導入率(%) | H10: 0.8 | I10: ='（２）ＫＰＩ達成進度'!S40 -> 0.9 | J10: 0.9 | K10: ='（２）ＫＰＩ達成進度'!T10 -> 0.9 | L10: 導入率
A11: 勞務費率 | B11: ='（１）收支狀況'!V40 -> 0.17584974 | C11: 0.16117622 | D11: =B11-C11 -> 0.014673518 | E11: ='（１）收支狀況'!W10 -> 0.16013697 | G11: 教育訓練-實施率(%) | H11: 1 | I11: =14/52*100% -> 0.26923077 | J11: 0.25 | K11: ='（２）ＫＰＩ達成進度'!W10 -> 0.21960298 | L11: 實施率
A13: （３）業績構成比 | E13: ※單位：千元 | G13: （４）訂單數量構成比 | K13: ※單位：個
B14: 當週 | C14: 比例 | D14: 前週 | E14: 差異 | H14: 當週 | I14: 比例 | J14: 前週 | K14: 差異
A15: 18℃-飯糰(061,063) | B15: =SUM('（３）業績構成比'!M42:M48)/1000 -> 10717.808 | C15: =IFERROR(B15/$B$6,"") -> 0.3558162 | D15: 0.3697172 | E15: =IFERROR(C15-D15,"") -> -0.013900994 | G15: 18℃-飯糰(061,063) | H15: =SUM('（４）訂單數量構成比'!M42:M48) -> 577172 | I15: =IFERROR(H15/$B$7,"") -> 0.57950334 | J15: 0.58327228 | K15: =IFERROR(I15-J15,"") -> -0.003768938
A16: 18℃-壽司手卷(071,072,075,076) | B16: =SUM('（３）業績構成比'!S42:S48)/1000 -> 2325.489 | C16: =IFERROR(B16/$B$6,"") -> 0.077202971 | D16: 0.088579641 | E16: =IFERROR(C16-D16,"") -> -0.011376669 | G16: 18℃-壽司手卷(071,072,075,076) | H16: =SUM('（４）訂單數量構成比'!S42:S48) -> 92852 | I16: =IFERROR(H16/$B$7,"") -> 0.093227052 | J16: 0.10566485 | K16: =IFERROR(I16-J16,"") -> -0.012437796
A17: 4℃-飯糰(065) | B17: =SUM('（３）業績構成比'!U42:U48)/1000 -> 712.35164 | C17: =IFERROR(B17/$B$6,"") -> 0.023649075 | D17: 0.024091208 | E17: =IFERROR(C17-D17,"") -> -0.0004421333 | G17: 4℃-飯糰(065) | H17: =SUM('（４）訂單數量構成比'!U42:U48) -> 25977 | I17: =IFERROR(H17/$B$7,"") -> 0.026081928 | J17: 0.025749148 | K17: =IFERROR(I17-J17,"") -> 0.00033278008
A18: 4℃-壽司手卷(077) | B18: =SUM('（３）業績構成比'!W42:W48)/1000 -> 370.31261 | C18: =IFERROR(B18/$B$6,"") -> 0.012293859 | D18: 0.012003448 | E18: =IFERROR(C18-D18,"") -> 0.00029041139 | G18: 4℃-壽司手卷(077) | H18: =SUM('（４）訂單數量構成比'!W42:W48) -> 14005 | I18: =IFERROR(H18/$B$7,"") -> 0.01406157 | J18: 0.013238181 | K18: =IFERROR(I18-J18,"") -> 0.00082338918
A19: 主食(091,092,093,094,095) | B19: =SUM('（３）業績構成比'!AC42:AC48)/1000 -> 5428.5814 | C19: =IFERROR(B19/$B$6,"") -> 0.18022129 | D19: 0.18867097 | E19: =IFERROR(C19-D19,"") -> -0.0084496807 | G19: 主食(091,092,093,094,095) | H19: =SUM('（４）訂單數量構成比'!AC42:AC48) -> 102309 | I19: =IFERROR(H19/$B$7,"") -> 0.10272225 | J19: 0.10414258 | K19: =IFERROR(I19-J19,"") -> -0.0014203329
A20: 便當(083) | B20: =SUM('（３）業績構成比'!AE42:AE48)/1000 -> 10120.77 | C20: =IFERROR(B20/$B$6,"") -> 0.33599538 | D20: 0.3014113 | E20: =IFERROR(C20-D20,"") -> 0.034584079 | G20: 便當(083) | H20: =SUM('（４）訂單數量構成比'!AE42:AE48) -> 161000 | I20: =IFERROR(H20/$B$7,"") -> 0.16165032 | J20: 0.14494161 | K20: =IFERROR(I20-J20,"") -> 0.016708704
A21: 熱食義麵(122,123,124,126) | B21: =SUM('（３）業績構成比'!AG42:AG48)/1000 -> 0 | C21: =IFERROR(B21/$B$6,"") -> 0 | D21: 0 | E21: =IFERROR(C21-D21,"") -> 0 | G21: 熱食義麵(122,123,124,126) | H21: =SUM('（４）訂單數量構成比'!AG42:AG48) -> 0 | I21: =IFERROR(H21/$B$7,"") -> 0 | J21: 0 | K21: =IFERROR(I21-J21,"") -> 0
A22: 季節調理麵(111,112) | B22: =SUM('（３）業績構成比'!AI42:AI48)/1000 -> 0 | C22: =IFERROR(B22/$B$6,"") -> 0 | D22: 0 | E22: =IFERROR(C22-D22,"") -> 0 | G22: 季節調理麵(111,112) | H22: =SUM('（４）訂單數量構成比'!AI42:AI48) -> 0 | I22: =IFERROR(H22/$B$7,"") -> 0 | J22: 0 | K22: =IFERROR(I22-J22,"") -> 0
A23: 微波小吃(153,154,155) | B23: =SUM('（３）業績構成比'!AK42:AK48)/1000 -> 446.4414 | C23: =IFERROR(B23/$B$6,"") -> 0.014821228 | D23: 0.015526241 | E23: =IFERROR(C23-D23,"") -> -0.00070501299 | G23: 微波小吃(153,154,155) | H23: =SUM('（４）訂單數量構成比'!AK42:AK48) -> 22662 | I23: =IFERROR(H23/$B$7,"") -> 0.022753537 | J23: 0.022991344 | K23: =IFERROR(I23-J23,"") -> -0.00023780651
C24: =SUM(C15:C23) -> 1 | D24: =SUM(D15:D23) -> 1 | I24: =SUM(I15:I23) -> 1 | J24: =SUM(J15:J23) -> 1
A26: （５）品群別人時生產性
A27: 品群 | B27: 當週 | C27: 前週 | D27: 差異 | E27: 累計
A28: 18℃-飯糰(061,063) | B28: ='（５-1）品群別人時生產性(18℃-飯糰)'!L197 -> 738.89977 | C28: 746.14935 | D28: =B28-C28 -> -7.249577 | E28: ='（５-1）品群別人時生產性(18℃-飯糰)'!C1 -> 757.59042
A29: 18℃-壽司手卷(071,072,075,076) | B29: ='（５-2）品群別人時生產性(18℃-壽司手卷)'!L107 -> 316.081 | C29: 316.0034 | D29: =B29-C29 -> 0.077604884 | E29: ='（５-2）品群別人時生產性(18℃-壽司手卷)'!C1 -> 311.70582
A30: 4℃-飯糰(065) | B30: ='（５-3）品群別人時生產性(4℃-飯糰)'!L107 -> 331.18525 | C30: 331.5815 | D30: =B30-C30 -> -0.39624772 | E30: ='（５-3）品群別人時生產性(4℃-飯糰)'!C1 -> 331.13667
A31: 4℃-壽司手卷(077) | B31: ='（５-4）品群別人時生產性(4℃-壽司手卷)'!L107 -> 493.97915 | C31: 493.9075 | D31: =B31-C31 -> 0.071650932 | E31: ='（５-4）品群別人時生產性(4℃-壽司手卷)'!C1 -> 493.97618
A32: 主食(091,092,093,094,095) | B32: ='（５-5）品群別人時生產性(微波主食) '!L107 -> 80.926906 | C32: 80.897159 | D32: =B32-C32 -> 0.029746958 | E32: ='（５-5）品群別人時生產性(微波主食) '!C1 -> 79.949999
A33: 便當(083) | B33: ='（５-6）品群別人時生產性(便當)'!L107 -> 77.801136 | C33: 78.90158 | D33: =B33-C33 -> -1.1004433 | E33: ='（５-6）品群別人時生產性(便當)'!C1 -> 77.906797
A34: 熱食義麵(122,123,124,126) | B34: 0 | C34: 0 | D34: =B34-C34 -> 0 | E34: ='（５-7）品群別人時生產性(熱食義麵) '!C1 -> 0
A35: 季節調理麵(111,112) | B35: 0 | C35: 0 | D35: =B35-C35 -> 0 | E35: ='（５-8）品群別人時生產性(季節調理麵) '!C1 -> 84.601424
A36: 微波小吃(153,154,155) | B36: ='（５-9）品群別人時生產性(微波小吃)'!L107 -> 83.04829 | C36: 83.046578 | D36: =B36-C36 -> 0.0017124993 | E36: ='（５-9）品群別人時生產性(微波小吃)'!C1 -> 83.044479

Sheet （１）收支狀況
B2: （１）收支狀況
B3: 資料繳交日 | C3: 月份 | D3: 日期 | F3: 營業額(元) | I3: 訂單數量(個) | L3: 材料費(元) | O3: 材料費率（材料費／營業額） | R3: 勞務成本（全廠人事成本） | U3: 勞務費率（勞務成本／營業額）
F4: 日 | G4: 週累積 | H4: 月累積 | I4: 日 | J4: 週累積 | K4: 月累積 | L4: 日 | M4: 週累積 | N4: 月累積 | O4: 日 | P4: 週累積 | Q4: 月累積 | R4: 日 | S4: 週累積 | T4: 月累積 | U4: 日 | V4: 週累積 | W4: 月累積
B5: =D6+7 -> 46085 | D5: 46077 | E5: 二 | F5: 5238957.1 | G5: =SUM(F5:F11) -> 32338420 | I5: 175154 | J5: =SUM(I5:I11) -> 1076054 | L5: 3399597.1 | M5: =SUM(L5:L11) -> 21241351 | O5: =L5/F5 -> 0.64890722 | P5: =M5/G5 -> 0.65684565 | R5: 840082.55 | S5: =SUM(R5:R11) -> 5488297.8 | U5: =R5/F5 -> 0.16035301 | V5: =S5/G5 -> 0.16971447
D6: =D5+1 -> 46078 | E6: 三 | F6: 4692647.5 | I6: 156618 | L6: 3098792.2 | O6: =L6/F6 -> 0.66035052 | R6: 789675.12 | U6: =R6/F6 -> 0.16827923
D7: =D6+1 -> 46079 | E7: 四 | F7: 3909306.8 | I7: 129387 | L7: 2647205.3 | O7: =L7/F7 -> 0.67715464 | R7: 725122.7 | U7: =R7/F7 -> 0.18548626
D8: =D7+1 -> 46080 | E8: 五 | F8: 3610052.1 | I8: 120519 | L8: 2369385.1 | O8: =L8/F8 -> 0.6563299 | R8: 750061.99 | U8: =R8/F8 -> 0.20777041
D9: =D8+1 -> 46081 | E9: 六 | F9: 3915929.6 | I9: 131697 | L9: 2568526.9 | O9: =L9/F9 -> 0.65591753 | R9: 774937.55 | U9: =R9/F9 -> 0.19789364
C10: 三 | D10: =D9+1 -> 46082 | E10: 日 | F10: 5447490.3 | H10: =SUM(F10:F40) -> 1.48838e+08 | I10: 179915 | K10: =SUM(I10:I40) -> 5045753 | L10: 3643303.9 | N10: =SUM(L10:L40) -> 98384727 | O10: =L10/F10 -> 0.66880412 | Q10: =N10/H10 -> 0.66101888 | R10: 804587.51 | T10: =SUM(R10:R40) -> 23834465 | U10: =R10/F10 -> 0.14769875 | W10: =T10/H10 -> 0.16013697
D11: =D10+1 -> 46083 | E11: 一 | F11: 5524036.8 | I11: 182764 | L11: 3514540.3 | O11: =L11/F11 -> 0.6362268 | R11: 803830.36 | U11: =R11/F11 -> 0.14551503
B12: =B5+7 -> 46092 | D12: =D11+1 -> 46084 | E12: 二 | F12: 5503117.1 | G12: =SUM(F12:F18) -> 33854096 | I12: 182389 | J12: =SUM(I12:I18) -> 1137743 | L12: 3633986.2 | M12: =SUM(L12:L18) -> 22517866 | O12: =L12/F12 -> 0.66035052 | P12: =M12/G12 -> 0.66514452 | R12: 830265.73 | S12: =SUM(R12:R18) -> 5405163.9 | U12: =R12/F12 -> 0.1508719 | V12: =S12/G12 -> 0.15966056
D13: =D12+1 -> 46085 | E13: 三 | F13: 5072703.1 | I13: 171444 | L13: 3462721.3 | O13: =L13/F13 -> 0.68261856 | R13: 794675.29 | U13: =R13/F13 -> 0.15665717
D14: =D13+1 -> 46086 | E14: 四 | F14: 4496570 | I14: 153251 | L14: 3011033.1 | O14: =L14/F14 -> 0.66962887 | R14: 724960.16 | U14: =R14/F14 -> 0.16122515
D15: =D14+1 -> 46087 | E15: 五 | F15: 3821772.9 | I15: 131075 | L15: 2509131.8 | O15: =L15/F15 -> 0.65653608 | R15: 685553.83 | U15: =R15/F15 -> 0.1793811
D16: =D15+1 -> 46088 | E16: 六 | F16: 4127790.8 | I16: 139687 | L16: 3057288.7 | O16: =L16/F16 -> 0.74065979 | R16: 750910.44 | U16: =R16/F16 -> 0.18191582
D17: =D16+1 -> 46089 | E17: 日 | F17: 5624946 | I17: 184408 | L17: 3467402.3 | O17: =L17/F17 -> 0.61643299 | R17: 835817.77 | U17: =R17/F17 -> 0.14859125
D18: =D17+1 -> 46090 | E18: 一 | F18: 5207196.3 | I18: 175489 | L18: 3376303.1 | O18: =L18/F18 -> 0.64839175 | R18: 782980.74 | U18: =R18/F18 -> 0.15036513
B19: =B12+7 -> 46099 | D19: =D18+1 -> 46091 | E19: 二 | F19: 5094346.5 | G19: =SUM(F19:F25) -> 32874070 | I19: 171919 | J19: =SUM(I19:I25) -> 1114939 | L19: 3469092.4 | M19: =SUM(L19:L25) -> 21771219 | O19: =L19/F19 -> 0.68096907 | P19: =M19/G19 -> 0.66226115 | R19: 815273.37 | S19: =SUM(R19:R25) -> 5363313.2 | U19: =R19/F19 -> 0.16003493 | V19: =S19/G19 -> 0.16314722
D20: =D19+1 -> 46092 | E20: 三 | F20: 4787261.3 | I20: 163607 | L20: 3043809.9 | O20: =L20/F20 -> 0.63581443 | R20: 784041.2 | U20: =R20/F20 -> 0.16377656
D21: =D20+1 -> 46093 | E21: 四 | F21: 4340566.7 | I21: 150153 | L21: 2939234.9 | O21: =L21/F21 -> 0.67715464 | R21: 743956.58 | U21: =R21/F21 -> 0.17139619
D22: =D21+1 -> 46094 | E22: 五 | F22: 3843289.1 | I22: 130207 | L22: 2539106.6 | O22: =L22/F22 -> 0.66065979 | R22: 712778.8 | U22: =R22/F22 -> 0.18546062
D23: =D22+1 -> 46095 | E23: 六 | F23: 4118703.8 | I23: 139203 | L23: 2754181.5 | O23: =L23/F23 -> 0.66870103 | R23: 704575.66 | U23: =R23/F23 -> 0.17106733
D24: =D23+1 -> 46096 | E24: 日 | F24: 5467294.6 | I24: 181125 | L24: 3588348.9 | O24: =L24/F24 -> 0.6563299 | R24: 827032.39 | U24: =R24/F24 -> 0.15126904
D25: =D24+1 -> 46097 | E25: 一 | F25: 5222607.7 | I25: 178725 | L25: 3437445 | O25: =L25/F25 -> 0.65818557 | R25: 775655.23 | U25: =R25/F25 -> 0.14851876
B26: =B19+7 -> 46106 | D26: =D25+1 -> 46098 | E26: 二 | F26: 5386755.9 | G26: =SUM(F26:F32) -> 33319857 | I26: 183844 | J26: =SUM(I26:I32) -> 1145620 | L26: 3448301.2 | M26: =SUM(L26:L32) -> 21956430 | O26: =L26/F26 -> 0.64014433 | P26: =M26/G26 -> 0.65895933 | R26: 835414.33 | S26: =SUM(R26:R32) -> 5396122.2 | U26: =R26/F26 -> 0.15508673 | V26: =S26/G26 -> 0.16194914
D27: =D26+1 -> 46099 | E27: 三 | F27: 4992178.2 | I27: 172254 | L27: 3347023.9 | O27: =L27/F27 -> 0.67045361 | R27: 798270.96 | U27: =R27/F27 -> 0.15990434
D28: =D27+1 -> 46100 | E28: 四 | F28: 4465947.2 | I28: 157187 | L28: 2975794.1 | O28: =L28/F28 -> 0.6663299 | R28: 739644.11 | U28: =R28/F28 -> 0.16561864
D29: =D28+1 -> 46101 | E29: 五 | F29: 3808013.8 | I29: 133801 | L29: 2437678.5 | O29: =L29/F29 -> 0.64014433 | R29: 691617.07 | U29: =R29/F29 -> 0.18162147
D30: =D29+1 -> 46102 | E30: 六 | F30: 4071503.5 | I30: 141397 | L30: 2767950.8 | O30: =L30/F30 -> 0.67983505 | R30: 737899.23 | U30: =R30/F30 -> 0.18123507
D31: =D30+1 -> 46103 | E31: 日 | F31: 5501397.2 | I31: 183666 | L31: 3580105.1 | O31: =L31/F31 -> 0.65076289 | R31: 823068.39 | U31: =R31/F31 -> 0.14961079
D32: =D31+1 -> 46104 | E32: 一 | F32: 5094060.9 | I32: 173471 | L32: 3399576.7 | O32: =L32/F32 -> 0.66736082 | R32: 770208.09 | U32: =R32/F32 -> 0.15119727
B33: =B26+7 -> 46113 | D33: =D32+1 -> 46105 | E33: 二 | F33: 4902681.6 | G33: =SUM(F33:F39) -> 32252127 | I33: 168684 | J33: =SUM(I33:I39) -> 1105590 | L33: 3217776.5 | M33: =SUM(L33:L39) -> 21273508 | O33: =L33/F33 -> 0.6563299 | P33: =M33/G33 -> 0.65960017 | R33: 769537.38 | S33: =SUM(R33:R39) -> 5198276 | U33: =R33/F33 -> 0.15696254 | V33: =S33/G33 -> 0.16117622
D34: =D33+1 -> 46106 | E34: 三 | F34: 4675847.4 | I34: 162126 | L34: 3087698.2 | O34: =L34/F34 -> 0.66035052 | R34: 754913.82 | U34: =R34/F34 -> 0.16144963
D35: =D34+1 -> 46107 | E35: 四 | F35: 4316808.3 | I35: 150942 | L35: 2899115 | O35: =L35/F35 -> 0.67158763 | R35: 720741.67 | U35: =R35/F35 -> 0.16696171
D36: =D35+1 -> 46108 | E36: 五 | F36: 3793881.8 | I36: 130555 | L36: 2432152 | O36: =L36/F36 -> 0.64107216 | R36: 711990.07 | U36: =R36/F36 -> 0.18766796
D37: =D36+1 -> 46109 | E37: 六 | F37: 4079657.9 | I37: 139511 | L37: 2742371.2 | O37: =L37/F37 -> 0.67220619 | R37: 710266.78 | U37: =R37/F37 -> 0.1740996
D38: =D37+1 -> 46110 | E38: 日 | F38: 5382127.6 | I38: 178715 | L38: 3557419.9 | O38: =L38/F38 -> 0.66096907 | R38: 820657.25 | U38: =R38/F38 -> 0.15247822
D39: =D38+1 -> 46111 | E39: 一 | F39: 5101122.3 | I39: 175057 | L39: 3336975.4 | O39: =L39/F39 -> 0.65416495 | R39: 710169.01 | U39: =R39/F39 -> 0.13921819
B40: =B33+7 -> 46120 | D40: =D39+1 -> 46112 | E40: 二 | F40: 5566322 | G40: =SUM(F40:F46) -> 30121755 | I40: 179182 | J40: =SUM(I40:I46) -> 995977 | L40: 3707859.1 | M40: =SUM(L40:L46) -> 20020074 | O40: =L40/F40 -> 0.66612371 | P40: =M40/G40 -> 0.66463837 | R40: 863172.14 | S40: =SUM(R40:R46) -> 5296902.8 | U40: =R40/F40 -> 0.15507046 | V40: =S40/G40 -> 0.17584974
D41: =D40+1 -> 46113 | E41: 三 | F41: 4658389.7 | I41: 156110 | L41: 3067045.4 | O41: =L41/F41 -> 0.65839175 | R41: 766317.89 | U41: =R41/F41 -> 0.16450274
...

Sheet （２）ＫＰＩ達成進度
B1: 人時生產性基準值 | C1: 497.6
B2: （２）ＫＰＩ達成進度
B3: 資料繳交日 | C3: 月份 | D3: 日期 | F3: 人時生產性(個/人) | I3: 人時生產性達成率(%) | L3: 半成品報廢(%) | O3: 半成品超用(%) | R3: 固定產線-導入率(固定產線數/總產線數) | U3: 教育訓練-實施率(進度/計畫)
F4: 日 | G4: 週平均 | H4: 月平均 | I4: 日 | J4: 週平均 | K4: 月平均 | L4: 日 | M4: 週平均 | N4: 月平均 | O4: 日 | P4: 週平均 | Q4: 月平均 | R4: 日 | S4: 週平均 | T4: 月平均 | U4: 日 | V4: 週平均 | W4: 月平均
B5: =D6+7 -> 46085 | D5: 46077 | E5: 二 | F5: 464.32904 | G5: =AVERAGE(F5:F11) -> 468.73197 | I5: =F5/$C$1 -> 0.93313713 | J5: =AVERAGE(I5:I11) -> 0.94198547 | L5: 0.0023089761 | M5: =AVERAGE(L5:L11) -> 0.0022409997 | O5: 0.0050852114 | P5: =AVERAGE(O5:O11) -> 0.0050772955 | R5: 0.9 | S5: =AVERAGE(R5:R11) -> 0.9 | U5: =9/52*100% -> 0.17307692 | V5: =AVERAGE(U5:U11) -> 0.17307692
D6: =D5+1 -> 46078 | E6: 三 | F6: 465.03721 | I6: =F6/$C$1 -> 0.93456032 | L6: 0.0023055099 | O6: 0.0050598022 | R6: 0.9 | U6: =9/52*100% -> 0.17307692
D7: =D6+1 -> 46079 | E7: 四 | F7: 463.62331 | I7: =F7/$C$1 -> 0.93171887 | L7: 0.0022997824 | O7: 0.0050498788 | R7: 0.9 | U7: =9/52*100% -> 0.17307692
D8: =D7+1 -> 46080 | E8: 五 | F8: 486.84866 | I8: =F8/$C$1 -> 0.97839362 | L8: 0.002298035 | O8: 0.0050264345 | R8: 0.9 | U8: =9/52*100% -> 0.17307692
D9: =D8+1 -> 46081 | E9: 六 | F9: 489.05639 | I9: =F9/$C$1 -> 0.98283036 | L9: 0.0023042698 | O9: 0.0050678558 | R9: 0.9 | U9: =9/52*100% -> 0.17307692
C10: 三 | D10: =D9+1 -> 46082 | E10: 日 | F10: 467.10925 | H10: =AVERAGEIF(F10:F40,"<>0") -> 409.82815 | I10: =F10/$C$1 -> 0.93872437 | K10: =AVERAGEIF(I10:I40,"<>0") -> 0.82360963 | L10: 0.0020801358 | N10: =AVERAGEIF(L10:L40,"<>0") -> 0.0020218797 | O10: 0.0051182745 | Q10: =AVERAGEIF(O10:O40,"<>0") -> 0.0048669349 | R10: 0.9 | T10: =AVERAGEIF(R10:R40,"<>0") -> 0.9 | U10: =9/52*100% -> 0.17307692 | W10: =AVERAGEIF(U10:U40,"<>0") -> 0.21960298
D11: =D10+1 -> 46083 | E11: 一 | F11: 445.11993 | I11: =F11/$C$1 -> 0.89453362 | L11: 0.002090289 | O11: 0.0051336112 | R11: 0.9 | U11: =9/52*100% -> 0.17307692
B12: =B5+7 -> 46092 | D12: =D11+1 -> 46084 | E12: 二 | F12: 401.96086 | G12: =AVERAGE(F12:F18) -> 413.80533 | I12: =F12/$C$1 -> 0.80779915 | J12: =AVERAGE(I12:I18) -> 0.83160235 | L12: 0.0020397948 | M12: =AVERAGE(L12:L18) -> 0.0020348075 | O12: 0.0050565527 | P12: =AVERAGE(O12:O18) -> 0.0050385612 | R12: 0.9 | S12: =AVERAGE(R12:R18) -> 0.9 | U12: =10/52*100% -> 0.19230769 | V12: =AVERAGE(U12:U18) -> 0.19230769
D13: =D12+1 -> 46085 | E13: 三 | F13: 422.79757 | I13: =F13/$C$1 -> 0.84967357 | L13: 0.0020279247 | O13: 0.0050497071 | R13: 0.9 | U13: =10/52*100% -> 0.19230769
D14: =D13+1 -> 46086 | E14: 四 | F14: 422.7799 | I14: =F14/$C$1 -> 0.84963807 | L14: 0.00204997 | O14: 0.0050196275 | R14: 0.9 | U14: =10/52*100% -> 0.19230769
D15: =D14+1 -> 46087 | E15: 五 | F15: 423.29065 | I15: =F15/$C$1 -> 0.8506645 | L15: 0.0020297876 | O15: 0.0050801225 | R15: 0.9 | U15: =10/52*100% -> 0.19230769
D16: =D15+1 -> 46088 | E16: 六 | F16: 424.20122 | I16: =F16/$C$1 -> 0.85249442 | L16: 0.0020559928 | O16: 0.00500156 | R16: 0.9 | U16: =10/52*100% -> 0.19230769
D17: =D16+1 -> 46089 | E17: 日 | F17: 404.7422 | I17: =F17/$C$1 -> 0.81338867 | L17: 0.0020164628 | O17: 0.00503752 | R17: 0.9 | U17: =10/52*100% -> 0.19230769
D18: =D17+1 -> 46090 | E18: 一 | F18: 396.8649 | I18: =F18/$C$1 -> 0.79755808 | L18: 0.0020237198 | O18: 0.0050248385 | R18: 0.9 | U18: =10/52*100% -> 0.19230769
B19: =B12+7 -> 46099 | D19: =D18+1 -> 46091 | E19: 二 | F19: 392.51459 | G19: =AVERAGE(F19:F25) -> 392.43176 | I19: =F19/$C$1 -> 0.78881549 | J19: =AVERAGE(I19:I25) -> 0.78864904 | L19: 0.002017708 | M19: =AVERAGE(L19:L25) -> 0.0020197511 | O19: 0.0050322367 | P19: =AVERAGE(O19:O25) -> 0.0050087597 | R19: 0.9 | S19: =AVERAGE(R19:R25) -> 0.9 | U19: =11/52*100% -> 0.21153846 | V19: =AVERAGE(U19:U25) -> 0.21153846
D20: =D19+1 -> 46092 | E20: 三 | F20: 391.54418 | I20: =F20/$C$1 -> 0.78686532 | L20: 0.0020163199 | O20: 0.0050263544 | R20: 0.9 | U20: =11/52*100% -> 0.21153846
D21: =D20+1 -> 46093 | E21: 四 | F21: 391.47562 | I21: =F21/$C$1 -> 0.78672754 | L21: 0.0020283347 | O21: 0.0050357554 | R21: 0.9 | U21: =11/52*100% -> 0.21153846
D22: =D21+1 -> 46094 | E22: 五 | F22: 395.13761 | I22: =F22/$C$1 -> 0.79408683 | L22: 0.0020163307 | O22: 0.0053638098 | R22: 0.9 | U22: =11/52*100% -> 0.21153846
D23: =D22+1 -> 46095 | E23: 六 | F23: 391.54924 | I23: =F23/$C$1 -> 0.78687547 | L23: 0.0020344156 | O23: 0.005378284 | R23: 0.9 | U23: =11/52*100% -> 0.21153846
D24: =D23+1 -> 46096 | E24: 日 | F24: 392.71578 | I24: =F24/$C$1 -> 0.78921981 | L24: 0.0020156149 | O24: 0.0046699916 | R24: 0.9 | U24: =11/52*100% -> 0.21153846
D25: =D24+1 -> 46097 | E25: 一 | F25: 392.08533 | I25: =F25/$C$1 -> 0.78795283 | L25: 0.0020095336 | O25: 0.0045548858 | R25: 0.9 | U25: =11/52*100% -> 0.21153846
B26: =B19+7 -> 46106 | D26: =D25+1 -> 46098 | E26: 二 | F26: 400.20531 | G26: =AVERAGE(F26:F32) -> 402.80033 | I26: =F26/$C$1 -> 0.80427112 | J26: =AVERAGE(I26:I32) -> 0.80948619 | L26: 0.0020115592 | M26: =AVERAGE(L26:L32) -> 0.0020100958 | O26: 0.005010306 | P26: =AVERAGE(O26:O32) -> 0.0048745927 | R26: 0.9 | S26: =AVERAGE(R26:R32) -> 0.9 | U26: =12/52*100% -> 0.23076923 | V26: =AVERAGE(U26:U32) -> 0.23076923
D27: =D26+1 -> 46099 | E27: 三 | F27: 400.32306 | I27: =F27/$C$1 -> 0.80450776 | L27: 0.0020084188 | O27: 0.0050035344 | R27: 0.9 | U27: =12/52*100% -> 0.23076923
D28: =D27+1 -> 46100 | E28: 四 | F28: 399.38335 | I28: =F28/$C$1 -> 0.80261928 | L28: 0.0020024371 | O28: 0.0048816167 | R28: 0.9 | U28: =12/52*100% -> 0.23076923
D29: =D28+1 -> 46101 | E29: 五 | F29: 401.404 | I29: =F29/$C$1 -> 0.80668005 | L29: 0.0020056843 | O29: 0.0048724363 | R29: 0.9 | U29: =12/52*100% -> 0.23076923
D30: =D29+1 -> 46102 | E30: 六 | F30: 400.81668 | I30: =F30/$C$1 -> 0.80549977 | L30: 0.0020097473 | O30: 0.0048515454 | R30: 0.9 | U30: =12/52*100% -> 0.23076923
D31: =D30+1 -> 46103 | E31: 日 | F31: 400.96779 | I31: =F31/$C$1 -> 0.80580343 | L31: 0.0020223339 | O31: 0.0047545108 | R31: 0.9 | U31: =12/52*100% -> 0.23076923
D32: =D31+1 -> 46104 | E32: 一 | F32: 416.5021 | I32: =F32/$C$1 -> 0.83702191 | L32: 0.0020104901 | O32: 0.004748199 | R32: 0.9 | U32: =12/52*100% -> 0.23076923
B33: =B26+7 -> 46113 | D33: =D32+1 -> 46105 | E33: 二 | F33: 416.77438 | G33: =AVERAGE(F33:F39) -> 416.99684 | I33: =F33/$C$1 -> 0.83756909 | J33: =AVERAGE(I33:I39) -> 0.83801616 | L33: 0.0020062219 | M33: =AVERAGE(L33:L39) -> 0.0020062482 | O33: 0.0046821906 | P33: =AVERAGE(O33:O39) -> 0.0045274475 | R33: 0.9 | S33: =AVERAGE(R33:R39) -> 0.9 | U33: =13/52*100% -> 0.25 | V33: =AVERAGE(U33:U39) -> 0.25
D34: =D33+1 -> 46106 | E34: 三 | F34: 416.76589 | I34: =F34/$C$1 -> 0.83755203 | L34: 0.0020039151 | O34: 0.004658294 | R34: 0.9 | U34: =13/52*100% -> 0.25
D35: =D34+1 -> 46107 | E35: 四 | F35: 417.50917 | I35: =F35/$C$1 -> 0.83904575 | L35: 0.0020063307 | O35: 0.0044976332 | R35: 0.9 | U35: =13/52*100% -> 0.25
D36: =D35+1 -> 46108 | E36: 五 | F36: 417.53161 | I36: =F36/$C$1 -> 0.83909085 | L36: 0.0020097254 | O36: 0.004541902 | R36: 0.9 | U36: =13/52*100% -> 0.25
D37: =D36+1 -> 46109 | E37: 六 | F37: 416.84179 | I37: =F37/$C$1 -> 0.83770457 | L37: 0.0020101293 | O37: 0.0044162258 | R37: 0.9 | U37: =13/52*100% -> 0.25
D38: =D37+1 -> 46110 | E38: 日 | F38: 416.92232 | I38: =F38/$C$1 -> 0.8378664 | L38: 0.002005875 | O38: 0.0044501829 | R38: 0.9 | U38: =13/52*100% -> 0.25
D39: =D38+1 -> 46111 | E39: 一 | F39: 416.63274 | I39: =F39/$C$1 -> 0.83728444 | L39: 0.0020015402 | O39: 0.0044457038 | R39: 0.9 | U39: =13/52*100% -> 0.25
B40: =B33+7 -> 46120 | D40: =D39+1 -> 46112 | E40: 二 | F40: 410.20375 | G40: =AVERAGE(F40:F46) -> 410.90558 | I40: =F40/$C$1 -> 0.82436445 | J40: =AVERAGE(I40:I46) -> 0.82577488 | L40: 0.0020115287 | M40: =AVERAGE(L40:L46) -> 0.002010833 | O40: 0.0044775692 | P40: =AVERAGE(O40:O46) -> 0.0044376523 | R40: 0.9 | S40: =AVERAGE(R40:R46) -> 0.9 | U40: =14/52*100% -> 0.26923077 | V40: =AVERAGE(U40:U46) -> 0.26923077
...

Sheet （３）業績構成比
B2: （3）業績構成比
B3: 資料繳交日 | C3: 月份 | D3: 日期 | F3: 營業額 | I3: 品類業績
I4: 18℃-飯糰 | O4: 18℃-壽司手卷 | U4: 4℃-飯糰 | W4: 4℃-壽司手卷 | Y4: 主食 | AE4: 便當 | AG4: 熱食義麵 | AI4: 季節調理麵 | AK4: 微波小吃
F5: 日 | G5: 週累積 | H5: 月累積 | I5: 一配 | K5: 二配 | M5: 合計 | O5: 一配 | Q5: 二配 | S5: 合計 | U5: 一配 | W5: 一配 | Y5: 一配 | AA5: 二配 | AC5: 合計 | AE5: 一配 | AG5: 一配 | AI5: 一配 | AK5: 一配
I6: 業績(元) | J6: 比例(%) | K6: 業績(元) | L6: 比例(%) | M6: 業績(元) | N6: 比例(%) | O6: 業績(元) | P6: 比例(%) | Q6: 業績(元) | R6: 比例(%) | S6: 業績(元) | T6: 比例(%) | U6: 業績(元) | V6: 比例(%) | W6: 業績(元) | X6: 比例(%) | Y6: 業績(元) | Z6: 比例(%) | AA6: 業績(元) | AB6: 比例(%) | AC6: 業績(元) | AD6: 比例(%) | AE6: 業績(元) | AF6: 比例(%) | AG6: 業績(元) | AH6: 比例(%) | AI6: 業績(元) | AJ6: 比例(%) | AK6: 業績(元) | AL6: 比例(%)
B7: =D8+7 -> 46085 | D7: 46077 | E7: 二 | F7: =SUM(M7,S7,U7,W7,AC7,AE7,AG7,AI7,AK7) -> 5238957.1 | G7: =SUM(F7:F13) -> 32338420 | I7: 815562.13 | J7: =I7/$F7 -> 0.15567261 | K7: 962970.78 | L7: =K7/$F7 -> 0.18380963 | M7: =I7+K7 -> 1778532.9 | N7: =M7/$F7 -> 0.33948224 | O7: 220466.87 | P7: =O7/$F7 -> 0.042082206 | Q7: 178349.54 | R7: =Q7/$F7 -> 0.034042947 | S7: =O7+Q7 -> 398816.41 | T7: =S7/$F7 -> 0.076125153 | U7: 185358.41 | V7: =U7/$F7 -> 0.035380784 | W7: 233726.34 | X7: =W7/$F7 -> 0.044613143 | Y7: 262050.32 | Z7: =Y7/$F7 -> 0.050019558 | AA7: 622985.41 | AB7: =AA7/$F7 -> 0.11891401 | AC7: =Y7+AA7 -> 885035.73 | AD7: =AC7/$F7 -> 0.16893357 | AE7: 1459250.8 | AF7: =AE7/F7 -> 0.27853842 | AG7: 0 | AH7: =AG7/$F7 -> 0 | AI7: 147496.78 | AJ7: =AI7/$F7 -> 0.028153844 | AK7: 150739.66 | AL7: =AK7/$F7 -> 0.028772837
D8: 46078 | E8: 三 | F8: =SUM(M8,S8,U8,W8,AC8,AE8,AG8,AI8,AK8) -> 4692647.5 | I8: 799279.1 | J8: =I8/$F8 -> 0.17032583 | K8: 843869.38 | L8: =K8/$F8 -> 0.17982799 | M8: =I8+K8 -> 1643148.5 | N8: =M8/F8 -> 0.35015383 | O8: 220683.48 | P8: =O8/$F8 -> 0.0470275 | Q8: 169504.31 | R8: =Q8/$F8 -> 0.036121254 | S8: =O8+Q8 -> 390187.79 | T8: =S8/F8 -> 0.083148753 | U8: 148052.14 | V8: =U8/F8 -> 0.031549811 | W8: 127954.87 | X8: =W8/$F8 -> 0.027267096 | Y8: 246268.26 | Z8: =Y8/$F8 -> 0.052479599 | AA8: 471199.58 | AB8: =AA8/$F8 -> 0.10041231 | AC8: =Y8+AA8 -> 717467.84 | AD8: =AC8/$F8 -> 0.15289191 | AE8: 1390723.7 | AF8: =AE8/F8 -> 0.29636227 | AG8: 0 | AH8: =AG8/$F8 -> 0 | AI8: 133540.96 | AJ8: =AI8/$F8 -> 0.028457488 | AK8: 141571.74 | AL8: =AK8/$F8 -> 0.030168842
D9: 46079 | E9: 四 | F9: =SUM(M9,S9,U9,W9,AC9,AE9,AG9,AI9,AK9) -> 3909306.8 | I9: 569381.54 | J9: =I9/$F9 -> 0.1456477 | K9: 745558.51 | L9: =K9/$F9 -> 0.19071374 | M9: =I9+K9 -> 1314940.1 | N9: =M9/$F9 -> 0.33636143 | O9: 181316.11 | P9: =O9/$F9 -> 0.046380629 | Q9: 144695.62 | R9: =Q9/$F9 -> 0.037013114 | S9: =O9+Q9 -> 326011.73 | T9: =S9/$F9 -> 0.083393743 | U9: 126261.09 | V9: =U9/$F9 -> 0.032297565 | W9: 117881.98 | X9: =W9/$F9 -> 0.03015419 | Y9: 228101.86 | Z9: =Y9/$F9 -> 0.058348416 | AA9: 422415.5 | AB9: =AA9/$F9 -> 0.10805381 | AC9: =Y9+AA9 -> 650517.36 | AD9: =AC9/$F9 -> 0.16640223 | AE9: 1113115.7 | AF9: =AE9/F9 -> 0.28473481 | AG9: 0 | AH9: =AG9/$F9 -> 0 | AI9: 126738.1 | AJ9: =AI9/$F9 -> 0.032419584 | AK9: 133840.79 | AL9: =AK9/$F9 -> 0.034236451
D10: 46080 | E10: 五 | F10: =SUM(M10,S10,U10,W10,AC10,AE10,AG10,AI10,AK10) -> 3610052.1 | I10: 545361.13 | J10: =I10/$F10 -> 0.15106739 | K10: 729491.75 | L10: =K10/$F10 -> 0.20207236 | M10: =I10+K10 -> 1274852.9 | N10: =M10/F10 -> 0.35313975 | O10: 174530.93 | P10: =O10/$F10 -> 0.048345821 | Q10: 138334.66 | R10: =Q10/$F10 -> 0.038319298 | S10: =O10+Q10 -> 312865.59 | T10: =S10/F10 -> 0.086665119 | U10: 105159.82 | V10: =U10/F10 -> 0.029129724 | W10: 54549.87 | X10: =W10/$F10 -> 0.015110549 | Y10: 204485.54 | Z10: =Y10/$F10 -> 0.056643377 | AA10: 465150.64 | AB10: =AA10/$F10 -> 0.12884873 | AC10: =Y10+AA10 -> 669636.18 | AD10: =AC10/$F10 -> 0.18549211 | AE10: 952067.01 | AF10: =AE10/F10 -> 0.26372667 | AG10: 0 | AH10: =AG10/$F10 -> 0 | AI10: 118704.2 | AJ10: =AI10/$F10 -> 0.032881576 | AK10: 122216.51 | AL10: =AK10/$F10 -> 0.033854501
D11: 46081 | E11: 六 | F11: =SUM(M11,S11,U11,W11,AC11,AE11,AG11,AI11,AK11) -> 3915929.6 | I11: 533505.22 | J11: =I11/$F11 -> 0.13623974 | K11: 882554.59 | L11: =K11/$F11 -> 0.2253755 | M11: =I11+K11 -> 1416059.8 | N11: =M11/$F11 -> 0.36161524 | O11: 166313.67 | P11: =O11/$F11 -> 0.042471057 | Q11: 136605.65 | R11: =Q11/$F11 -> 0.034884603 | S11: =O11+Q11 -> 302919.32 | T11: =S11/$F11 -> 0.07735566 | U11: 117254.27 | V11: =U11/$F11 -> 0.029942895 | W11: 65953.22 | X11: =W11/$F11 -> 0.016842289 | Y11: 222027.47 | Z11: =Y11/$F11 -> 0.056698534 | AA11: 550814.38 | AB11: =AA11/$F11 -> 0.14065993 | AC11: =Y11+AA11 -> 772841.85 | AD11: =AC11/$F11 -> 0.19735846 | AE11: 1029063.2 | AF11: =AE11/F11 -> 0.262789 | AG11: 0 | AH11: =AG11/$F11 -> 0 | AI11: 70403.2 | AJ11: =AI11/$F11 -> 0.017978668 | AK11: 141434.74 | AL11: =AK11/$F11 -> 0.036117794
C12: 三 | D12: 46082 | E12: 日 | F12: =SUM(M12,S12,U12,W12,AC12,AE12,AG12,AI12,AK12) -> 5447490.3 | H12: =SUM(F12:F42) -> 1.48838e+08 | I12: 880068.55 | J12: =I12/$F12 -> 0.16155486 | K12: 1018931.3 | L12: =K12/$F12 -> 0.18704601 | M12: =I12+K12 -> 1898999.9 | N12: =M12/F12 -> 0.34860087 | O12: 229722.55 | P12: =O12/$F12 -> 0.042170346 | Q12: 170790.6 | R12: =Q12/$F12 -> 0.031352163 | S12: =O12+Q12 -> 400513.15 | T12: =S12/F12 -> 0.073522509 | U12: 173999.36 | V12: =U12/F12 -> 0.031941197 | W12: 148402.32 | X12: =W12/$F12 -> 0.027242329 | Y12: 296339.4 | Z12: =Y12/$F12 -> 0.054399253 | AA12: 622748.12 | AB12: =AA12/$F12 -> 0.11431835 | AC12: =Y12+AA12 -> 919087.52 | AD12: =AC12/$F12 -> 0.16871761 | AE12: 1756824.7 | AF12: =AE12/F12 -> 0.32250167 | AG12: 0 | AH12: =AG12/$F12 -> 0 | AI12: 81107.36 | AJ12: =AI12/$F12 -> 0.014888941 | AK12: 68556 | AL12: =AK12/$F12 -> 0.012584878
D13: 46083 | E13: 一 | F13: =SUM(M13,S13,U13,W13,AC13,AE13,AG13,AI13,AK13) -> 5524036.8 | I13: 846957.8 | J13: =I13/$F13 -> 0.15332226 | K13: 1097915.2 | L13: =K13/$F13 -> 0.19875234 | M13: =I13+K13 -> 1944873 | N13: =M13/$F13 -> 0.3520746 | O13: 211406.03 | P13: =O13/$F13 -> 0.038270207 | Q13: 168666.66 | R13: =Q13/$F13 -> 0.030533225 | S13: =O13+Q13 -> 380072.69 | T13: =S13/$F13 -> 0.068803432 | U13: 130781.56 | V13: =U13/$F13 -> 0.023674998 | W13: 113746.98 | X13: =W13/$F13 -> 0.020591279 | Y13: 253080.66 | Z13: =Y13/$F13 -> 0.045814442 | AA13: 1069349 | AB13: =AA13/$F13 -> 0.19358108 | AC13: =Y13+AA13 -> 1322429.7 | AD13: =AC13/$F13 -> 0.23939552 | AE13: 1465668.8 | AF13: =AE13/F13 -> 0.26532568 | AG13: 0 | AH13: =AG13/$F13 -> 0 | AI13: 92529.92 | AJ13: =AI13/$F13 -> 0.016750417 | AK13: 73934.1 | AL13: =AK13/$F13 -> 0.013384071
B14: =D15+7 -> 46092 | D14: 46084 | E14: 二 | F14: =SUM(M14,S14,U14,W14,AC14,AE14,AG14,AI14,AK14) -> 5503117.1 | G14: =SUM(F14:F20) -> 33854096 | I14: 830881.12 | J14: =I14/$F14 -> 0.15098373 | K14: 1064970 | L14: =K14/$F14 -> 0.19352123 | M14: =I14+K14 -> 1895851.1 | N14: =M14/$F14 -> 0.34450496 | O14: 287774.4 | P14: =O14/$F14 -> 0.052292982 | Q14: 169433.19 | R14: =Q14/$F14 -> 0.030788585 | S14: =O14+Q14 -> 457207.59 | T14: =S14/$F14 -> 0.083081567 | U14: 122084.54 | V14: =U14/$F14 -> 0.022184616 | W14: 86700.45 | X14: =W14/$F14 -> 0.015754789 | Y14: 202214.74 | Z14: =Y14/$F14 -> 0.036745491 | AA14: 974142.5 | AB14: =AA14/$F14 -> 0.1770165 | AC14: =Y14+AA14 -> 1176357.2 | AD14: =AC14/$F14 -> 0.21376199 | AE14: 1623033.4 | AF14: =AE14/F14 -> 0.29492984 | AG14: 0 | AH14: =AG14/$F14 -> 0 | AI14: 72558.4 | AJ14: =AI14/$F14 -> 0.013184964 | AK14: 69324.3 | AL14: =AK14/$F14 -> 0.012597279
D15: 46085 | E15: 三 | F15: =SUM(M15,S15,U15,W15,AC15,AE15,AG15,AI15,AK15) -> 5072703.1 | I15: 815697.95 | J15: =I15/$F15 -> 0.16080144 | K15: 1020941.8 | L15: =K15/$F15 -> 0.2012619 | M15: =I15+K15 -> 1836639.8 | N15: =M15/F15 -> 0.36206333 | O15: 271042.24 | P15: =O15/$F15 -> 0.053431521 | Q15: 176841.24 | R15: =Q15/$F15 -> 0.034861343 | S15: =O15+Q15 -> 447883.48 | T15: =S15/F15 -> 0.088292863 | U15: 113916.98 | V15: =U15/F15 -> 0.022456859 | W15: 80208.43 | X15: =W15/$F15 -> 0.015811773 | Y15: 188760.25 | Z15: =Y15/$F15 -> 0.037210979 | AA15: 879092.45 | AB15: =AA15/$F15 -> 0.17329862 | AC15: =Y15+AA15 -> 1067852.7 | AD15: =AC15/$F15 -> 0.2105096 | AE15: 1451322 | AF15: =AE15/F15 -> 0.28610427 | AG15: 0 | AH15: =AG15/$F15 -> 0 | AI15: 0 | AJ15: =AI15/$F15 -> 0 | AK15: 74879.7 | AL15: =AK15/$F15 -> 0.014761302
D16: 46086 | E16: 四 | F16: =SUM(M16,S16,U16,W16,AC16,AE16,AG16,AI16,AK16) -> 4496570 | I16: 759369.68 | J16: =I16/$F16 -> 0.16887754 | K16: 904680.65 | L16: =K16/$F16 -> 0.2011935 | M16: =I16+K16 -> 1664050.3 | N16: =M16/$F16 -> 0.37007104 | O16: 250314.85 | P16: =O16/$F16 -> 0.055667954 | Q16: 157714.79 | R16: =Q16/$F16 -> 0.035074466 | S16: =O16+Q16 -> 408029.64 | T16: =S16/$F16 -> 0.09074242 | U16: 98671.55 | V16: =U16/$F16 -> 0.021943737 | W16: 81953.75 | X16: =W16/$F16 -> 0.018225837 | Y16: 185070.2 | Z16: =Y16/$F16 -> 0.041158083 | AA16: 699113.47 | AB16: =AA16/$F16 -> 0.15547706 | AC16: =Y16+AA16 -> 884183.67 | AD16: =AC16/$F16 -> 0.19663514 | AE16: 1289233.8 | AF16: =AE16/F16 -> 0.28671495 | AG16: 0 | AH16: =AG16/$F16 -> 0 | AI16: 0 | AJ16: =AI16/$F16 -> 0 | AK16: 70447.2 | AL16: =AK16/$F16 -> 0.015666875
D17: 46087 | E17: 五 | F17: =SUM(M17,S17,U17,W17,AC17,AE17,AG17,AI17,AK17) -> 3821772.9 | I17: 565614.91 | J17: =I17/$F17 -> 0.14799804 | K17: 832303.86 | L17: =K17/$F17 -> 0.21777952 | M17: =I17+K17 -> 1397918.8 | N17: =M17/F17 -> 0.36577756 | O17: 196738.65 | P17: =O17/$F17 -> 0.051478373 | Q17: 127782.41 | R17: =Q17/$F17 -> 0.033435375 | S17: =O17+Q17 -> 324521.06 | T17: =S17/F17 -> 0.084913748 | U17: 108285.89 | V17: =U17/F17 -> 0.028333942 | W17: 79685.59 | X17: =W17/$F17 -> 0.020850425 | Y17: 196026.81 | Z17: =Y17/$F17 -> 0.051292114 | AA17: 672018.14 | AB17: =AA17/$F17 -> 0.17583937 | AC17: =Y17+AA17 -> 868044.95 | AD17: =AC17/$F17 -> 0.22713148 | AE17: 974997.04 | AF17: =AE17/F17 -> 0.25511643 | AG17: 0 | AH17: =AG17/$F17 -> 0 | AI17: 0 | AJ17: =AI17/$F17 -> 0 | AK17: 68319.6 | AL17: =AK17/$F17 -> 0.017876415
D18: 46088 | E18: 六 | F18: =SUM(M18,S18,U18,W18,AC18,AE18,AG18,AI18,AK18) -> 4127790.8 | I18: 535411.8 | J18: =I18/$F18 -> 0.12970904 | K18: 954382.02 | L18: =K18/$F18 -> 0.23120891 | M18: =I18+K18 -> 1489793.8 | N18: =M18/$F18 -> 0.36091795 | O18: 191833.54 | P18: =O18/$F18 -> 0.046473658 | Q18: 123847.85 | R18: =Q18/$F18 -> 0.030003422 | S18: =O18+Q18 -> 315681.39 | T18: =S18/$F18 -> 0.07647708 | U18: 101929.25 | V18: =U18/$F18 -> 0.024693415 | W18: 65524.79 | X18: =W18/$F18 -> 0.015874058 | Y18: 216407.24 | Z18: =Y18/$F18 -> 0.052426891 | AA18: 773297.13 | AB18: =AA18/$F18 -> 0.18733922 | AC18: =Y18+AA18 -> 989704.37 | AD18: =AC18/$F18 -> 0.23976611 | AE18: 1094887.3 | AF18: =AE18/F18 -> 0.26524777 | AG18: 0 | AH18: =AG18/$F18 -> 0 | AI18: 0 | AJ18: =AI18/$F18 -> 0 | AK18: 70269.9 | AL18: =AK18/$F18 -> 0.01702361
D19: 46089 | E19: 日 | F19: =SUM(M19,S19,U19,W19,AC19,AE19,AG19,AI19,AK19) -> 5624946 | I19: 852217.39 | J19: =I19/$F19 -> 0.15150677 | K19: 1075261.6 | L19: =K19/$F19 -> 0.19115946 | M19: =I19+K19 -> 1927479 | N19: =M19/F19 -> 0.34266623 | O19: 281846.31 | P19: =O19/$F19 -> 0.050106492 | Q19: 159148.46 | R19: =Q19/$F19 -> 0.028293331 | S19: =O19+Q19 -> 440994.77 | T19: =S19/F19 -> 0.078399823 | U19: 129839.87 | V19: =U19/F19 -> 0.023082865 | W19: 81957.96 | X19: =W19/$F19 -> 0.014570444 | Y19: 246041.18 | Z19: =Y19/$F19 -> 0.043741074 | AA19: 937191.64 | AB19: =AA19/$F19 -> 0.16661345 | AC19: =Y19+AA19 -> 1183232.8 | AD19: =AC19/$F19 -> 0.21035452 | AE19: 1792767.3 | AF19: =AE19/F19 -> 0.31871725 | AG19: 0 | AH19: =AG19/$F19 -> 0 | AI19: 0 | AJ19: =AI19/$F19 -> 0 | AK19: 68674.2 | AL19: =AK19/$F19 -> 0.012208864
D20: 46090 | E20: 一 | F20: =SUM(M20,S20,U20,W20,AC20,AE20,AG20,AI20,AK20) -> 5207196.3 | I20: 822660.51 | J20: =I20/$F20 -> 0.15798531 | K20: 1054563.2 | L20: =K20/$F20 -> 0.20252035 | M20: =I20+K20 -> 1877223.7 | N20: =M20/$F20 -> 0.36050565 | O20: 254532.38 | P20: =O20/$F20 -> 0.048880888 | Q20: 160772.09 | R20: =Q20/$F20 -> 0.030874982 | S20: =O20+Q20 -> 415304.47 | T20: =S20/$F20 -> 0.07975587 | U20: 135905.56 | V20: =U20/$F20 -> 0.026099565 | W20: 87841.76 | X20: =W20/$F20 -> 0.016869301 | Y20: 235368.42 | Z20: =Y20/$F20 -> 0.045200605 | AA20: 909672.18 | AB20: =AA20/$F20 -> 0.1746952 | AC20: =Y20+AA20 -> 1145040.6 | AD20: =AC20/$F20 -> 0.2198958 | AE20: 1470114 | AF20: =AE20/F20 -> 0.28232352 | AG20: 0 | AH20: =AG20/$F20 -> 0 | AI20: 0 | AJ20: =AI20/$F20 -> 0 | AK20: 75766.2 | AL20: =AK20/$F20 -> 0.014550287
B21: =D22+7 -> 46099 | D21: 46091 | E21: 二 | F21: =SUM(M21,S21,U21,W21,AC21,AE21,AG21,AI21,AK21) -> 5094346.5 | G21: =SUM(F21:F27) -> 32874070 | I21: 807843.41 | J21: =I21/$F21 -> 0.15857645 | K21: 1030178.4 | L21: =K21/$F21 -> 0.20221993 | M21: =I21+K21 -> 1838021.8 | N21: =M21/$F21 -> 0.36079639 | O21: 271243.9 | P21: =O21/$F21 -> 0.053244101 | Q21: 159494 | R21: =Q21/$F21 -> 0.031308039 | S21: =O21+Q21 -> 430737.9 | T21: =S21/$F21 -> 0.08455214 | U21: 116434.24 | V21: =U21/$F21 -> 0.022855579 | W21: 78826.87 | X21: =W21/$F21 -> 0.015473402 | Y21: 226512.3 | Z21: =Y21/$F21 -> 0.044463465 | AA21: 899228.06 | AB21: =AA21/$F21 -> 0.1765149 | AC21: =Y21+AA21 -> 1125740.4 | AD21: =AC21/$F21 -> 0.22097836 | AE21: 1431892.3 | AF21: =AE21/F21 -> 0.28107478 | AG21: 0 | AH21: =AG21/$F21 -> 0 | AI21: 0 | AJ21: =AI21/$F21 -> 0 | AK21: 72693 | AL21: =AK21/$F21 -> 0.014269347
D22: 46092 | E22: 三 | F22: =SUM(M22,S22,U22,W22,AC22,AE22,AG22,AI22,AK22) -> 4787261.3 | I22: 781949.41 | J22: =I22/$F22 -> 0.16333961 | K22: 977079.32 | L22: =K22/$F22 -> 0.20409985 | M22: =I22+K22 -> 1759028.7 | N22: =M22/F22 -> 0.36743946 | O22: 258881.73 | P22: =O22/$F22 -> 0.054077209 | Q22: 156677.39 | R22: =Q22/$F22 -> 0.032727979 | S22: =O22+Q22 -> 415559.12 | T22: =S22/F22 -> 0.086805188 | U22: 121306.9 | V22: =U22/F22 -> 0.025339519 | W22: 88332.53 | X22: =W22/$F22 -> 0.018451579 | Y22: 207380.81 | Z22: =Y22/$F22 -> 0.0433193 | AA22: 818354.55 | AB22: =AA22/$F22 -> 0.1709442 | AC22: =Y22+AA22 -> 1025735.4 | AD22: =AC22/$F22 -> 0.2142635 | AE22: 1299818.6 | AF22: =AE22/F22 -> 0.27151611 | AG22: 0 | AH22: =AG22/$F22 -> 0 | AI22: 0 | AJ22: =AI22/$F22 -> 0 | AK22: 77480.1 | AL22: =AK22/$F22 -> 0.01618464
D23: 46093 | E23: 四 | F23: =SUM(M23,S23,U23,W23,AC23,AE23,AG23,AI23,AK23) -> 4340566.7 | I23: 753783.91 | J23: =I23/$F23 -> 0.17366025 | K23: 877314.46 | L23: =K23/$F23 -> 0.2021198 | M23: =I23+K23 -> 1631098.4 | N23: =M23/$F23 -> 0.37578005 | O23: 251565.22 | P23: =O23/$F23 -> 0.057956769 | Q23: 150375.46 | R23: =Q23/$F23 -> 0.0346442 | S23: =O23+Q23 -> 401940.68 | T23: =S23/$F23 -> 0.092600969 | U23: 117010.15 | V23: =U23/$F23 -> 0.026957344 | W23: 71085.01 | X23: =W23/$F23 -> 0.016376896 | Y23: 194494.02 | Z23: =Y23/$F23 -> 0.04480844 | AA23: 634941.25 | AB23: =AA23/$F23 -> 0.14628073 | AC23: =Y23+AA23 -> 829435.27 | AD23: =AC23/$F23 -> 0.19108917 | AE23: 1213049 | AF23: =AE23/F23 -> 0.27946789 | AG23: 0 | AH23: =AG23/$F23 -> 0 | AI23: 0 | AJ23: =AI23/$F23 -> 0 | AK23: 76948.2 | AL23: =AK23/$F23 -> 0.017727685
D24: 46094 | E24: 五 | F24: =SUM(M24,S24,U24,W24,AC24,AE24,AG24,AI24,AK24) -> 3843289.1 | I24: 573975.47 | J24: =I24/$F24 -> 0.14934486 | K24: 816225.13 | L24: =K24/$F24 -> 0.21237672 | M24: =I24+K24 -> 1390200.6 | N24: =M24/F24 -> 0.36172157 | O24: 185737.19 | P24: =O24/$F24 -> 0.048327665 | Q24: 118476.73 | R24: =Q24/$F24 -> 0.03082691 | S24: =O24+Q24 -> 304213.92 | T24: =S24/F24 -> 0.079154575 | U24: 102084.05 | V24: =U24/F24 -> 0.026561637 | W24: 54659.41 | X24: =W24/$F24 -> 0.014222039 | Y24: 191428.44 | Z24: =Y24/$F24 -> 0.049808493 | AA24: 703211.52 | AB24: =AA24/$F24 -> 0.18297128 | AC24: =Y24+AA24 -> 894639.96 | AD24: =AC24/$F24 -> 0.23277977 | AE24: 1028344.2 | AF24: =AE24/F24 -> 0.26756879 | AG24: 0 | AH24: =AG24/$F24 -> 0 | AI24: 0 | AJ24: =AI24/$F24 -> 0 | AK24: 69147 | AL24: =AK24/$F24 -> 0.017991621
D25: 46095 | E25: 六 | F25: =SUM(M25,S25,U25,W25,AC25,AE25,AG25,AI25,AK25) -> 4118703.8 | I25: 551491.26 | J25: =I25/$F25 -> 0.13389923 | K25: 949671.47 | L25: =K25/$F25 -> 0.23057533 | M25: =I25+K25 -> 1501162.7 | N25: =M25/$F25 -> 0.36447455 | O25: 173302.42 | P25: =O25/$F25 -> 0.042076932 | Q25: 115724.43 | R25: =Q25/$F25 -> 0.028097294 | S25: =O25+Q25 -> 289026.85 | T25: =S25/$F25 -> 0.070174226 | U25: 101894.11 | V25: =U25/$F25 -> 0.024739363 | W25: 57240.58 | X25: =W25/$F25 -> 0.013897717 | Y25: 212490.11 | Z25: =Y25/$F25 -> 0.051591501 | AA25: 780383.38 | AB25: =AA25/$F25 -> 0.18947305 | AC25: =Y25+AA25 -> 992873.49 | AD25: =AC25/$F25 -> 0.24106455 | AE25: 1109132 | AF25: =AE25/F25 -> 0.26929153 | AG25: 0 | AH25: =AG25/$F25 -> 0 | AI25: 0 | AJ25: =AI25/$F25 -> 0 | AK25: 67374 | AL25: =AK25/$F25 -> 0.016358059
D26: 46096 | E26: 日 | F26: =SUM(M26,S26,U26,W26,AC26,AE26,AG26,AI26,AK26) -> 5467294.6 | I26: 843803.95 | J26: =I26/$F26 -> 0.15433665 | K26: 1075482.2 | L26: =K26/$F26 -> 0.19671196 | M26: =I26+K26 -> 1919286.2 | N26: =M26/F26 -> 0.35104861 | O26: 262713.42 | P26: =O26/$F26 -> 0.048051813 | Q26: 152639.3 | R26: =Q26/$F26 -> 0.027918616 | S26: =O26+Q26 -> 415352.72 | T26: =S26/F26 -> 0.075970429 | U26: 137935.52 | V26: =U26/F26 -> 0.025229209 | W26: 64624.58 | X26: =W26/$F26 -> 0.011820212 | Y26: 253080.66 | Z26: =Y26/$F26 -> 0.046289925 | AA26: 932493 | AB26: =AA26/$F26 -> 0.1705584 | AC26: =Y26+AA26 -> 1185573.7 | AD26: =AC26/$F26 -> 0.21684832 | AE26: 1672597.3 | AF26: =AE26/F26 -> 0.30592777 | AG26: 0 | AH26: =AG26/$F26 -> 0 | AI26: 0 | AJ26: =AI26/$F26 -> 0 | AK26: 71924.7 | AL26: =AK26/$F26 -> 0.013155446
D27: 46097 | E27: 一 | F27: =SUM(M27,S27,U27,W27,AC27,AE27,AG27,AI27,AK27) -> 5222607.7 | I27: 821624.16 | J27: =I27/$F27 -> 0.15732067 | K27: 1158382.2 | L27: =K27/$F27 -> 0.2218015 | M27: =I27+K27 -> 1980006.4 | N27: =M27/$F27 -> 0.37912217 | O27: 250081.2 | P27: =O27/$F27 -> 0.047884355 | Q27: 155437 | R27: =Q27/$F27 -> 0.029762335 | S27: =O27+Q27 -> 405518.2 | T27: =S27/$F27 -> 0.07764669 | U27: 128918.03 | V27: =U27/$F27 -> 0.024684609 | W27: 73732.21 | X27: =W27/$F27 -> 0.014117892 | Y27: 241896.97 | Z27: =Y27/$F27 -> 0.046317278 | AA27: 882633.85 | AB27: =AA27/$F27 -> 0.16900252 | AC27: =Y27+AA27 -> 1124530.8 | AD27: =AC27/$F27 -> 0.2153198 | AE27: 1439277.6 | AF27: =AE27/F27 -> 0.275586 | AG27: 0 | AH27: =AG27/$F27 -> 0 | AI27: 0 | AJ27: =AI27/$F27 -> 0 | AK27: 70624.5 | AL27: =AK27/$F27 -> 0.013522842
B28: =D29+7 -> 46106 | D28: 46098 | E28: 二 | F28: =SUM(M28,S28,U28,W28,AC28,AE28,AG28,AI28,AK28) -> 5386755.9 | G28: =SUM(F28:F34) -> 33319857 | I28: 819850.68 | J28: =I28/$F28 -> 0.15219748 | K28: 1139067.1 | L28: =K28/$F28 -> 0.21145697 | M28: =I28+K28 -> 1958917.8 | N28: =M28/$F28 -> 0.36365445 | O28: 338811.96 | P28: =O28/$F28 -> 0.062897218 | Q28: 160574.43 | R28: =Q28/$F28 -> 0.029809116 | S28: =O28+Q28 -> 499386.39 | T28: =S28/$F28 -> 0.092706334 | U28: 128088.44 | V28: =U28/$F28 -> 0.023778401 | W28: 69813.99 | X28: =W28/$F28 -> 0.012960303 | Y28: 225887.83 | Z28: =Y28/$F28 -> 0.041933927 | AA28: 832095.48 | AB28: =AA28/$F28 -> 0.15447061 | AC28: =Y28+AA28 -> 1057983.3 | AD28: =AC28/$F28 -> 0.19640454 | AE28: 1599341.1 | AF28: =AE28/F28 -> 0.29690246 | AG28: 0 | AH28: =AG28/$F28 -> 0 | AI28: 0 | AJ28: =AI28/$F28 -> 0 | AK28: 73224.9 | AL28: =AK28/$F28 -> 0.013593506
D29: 46099 | E29: 三 | F29: =SUM(M29,S29,U29,W29,AC29,AE29,AG29,AI29,AK29) -> 4992178.2 | I29: 797653.17 | J29: =I29/$F29 -> 0.15978059 | K29: 1085995 | L29: =K29/$F29 -> 0.21753932 | M29: =I29+K29 -> 1883648.2 | N29: =M29/F29 -> 0.37731991 | O29: 302953.4 | P29: =O29/$F29 -> 0.060685614 | Q29: 163103.89 | R29: =Q29/$F29 -> 0.032671889 | S29: =O29+Q29 -> 466057.29 | T29: =S29/F29 -> 0.093357503 | U29: 112605.86 | V29: =U29/F29 -> 0.022556458 | W29: 69856.5 | X29: =W29/$F29 -> 0.01399319 | Y29: 185808.21 | Z29: =Y29/$F29 -> 0.037219867 | AA29: 717688.72 | AB29: =AA29/$F29 -> 0.14376264 | AC29: =Y29+AA29 -> 903496.93 | AD29: =AC29/$F29 -> 0.18098251 | AE29: 1481692.8 | AF29: =AE29/F29 -> 0.29680287 | AG29: 0 | AH29: =AG29/$F29 -> 0 | AI29: 0 | AJ29: =AI29/$F29 -> 0 | AK29: 74820.6 | AL29: =AK29/$F29 -> 0.014987566
D30: 46100 | E30: 四 | F30: =SUM(M30,S30,U30,W30,AC30,AE30,AG30,AI30,AK30) -> 4465947.2 | I30: 775144.91 | J30: =I30/$F30 -> 0.17356786 | K30: 976799.45 | L30: =K30/$F30 -> 0.21872168 | M30: =I30+K30 -> 1751944.4 | N30: =M30/$F30 -> 0.39228954 | O30: 290629.46 | P30: =O30/$F30 -> 0.065076779 | Q30: 156703.49 | R30: =Q30/$F30 -> 0.035088523 | S30: =O30+Q30 -> 447332.95 | T30: =S30/$F30 -> 0.1001653 | U30: 109740.16 | V30: =U30/$F30 -> 0.024572651 | W30: 69458.98 | X30: =W30/$F30 -> 0.015553023 | Y30: 176952.09 | Z30: =Y30/$F30 -> 0.039622522 | AA30: 591093.82 | AB30: =AA30/$F30 -> 0.13235576 | AC30: =Y30+AA30 -> 768045.91 | AD30: =AC30/$F30 -> 0.17197828 | AE30: 1243895 | AF30: =AE30/F30 -> 0.27852883 | AG30: 0 | AH30: =AG30/$F30 -> 0 | AI30: 0 | AJ30: =AI30/$F30 -> 0 | AK30: 75529.8 | AL30: =AK30/$F30 -> 0.016912381
D31: 46101 | E31: 五 | F31: =SUM(M31,S31,U31,W31,AC31,AE31,AG31,AI31,AK31) -> 3808013.8 | I31: 589074.3 | J31: =I31/$F31 -> 0.15469332 | K31: 892198.36 | L31: =K31/$F31 -> 0.23429494 | M31: =I31+K31 -> 1481272.7 | N31: =M31/F31 -> 0.38898826 | O31: 236807.41 | P31: =O31/$F31 -> 0.062186594 | Q31: 125220.64 | R31: =Q31/$F31 -> 0.032883452 | S31: =O31+Q31 -> 362028.05 | T31: =S31/F31 -> 0.095070046 | U31: 91302.24 | V31: =U31/F31 -> 0.023976341 | W31: 47037.68 | X31: =W31/$F31 -> 0.012352287 | Y31: 179620.28 | Z31: =Y31/$F31 -> 0.04716902 | AA31: 616121.15 | AB31: =AA31/$F31 -> 0.16179593 | AC31: =Y31+AA31 -> 795741.43 | AD31: =AC31/$F31 -> 0.20896495 | AE31: 964380.67 | AF31: =AE31/F31 -> 0.25325031 | AG31: 0 | AH31: =AG31/$F31 -> 0 | AI31: 0 | AJ31: =AI31/$F31 -> 0 | AK31: 66251.1 | AL31: =AK31/$F31 -> 0.01739781
D32: 46102 | E32: 六 | F32: =SUM(M32,S32,U32,W32,AC32,AE32,AG32,AI32,AK32) -> 4071503.5 | I32: 559096.29 | J32: =I32/$F32 -> 0.13731937 | K32: 995771.27 | L32: =K32/$F32 -> 0.2445709 | M32: =I32+K32 -> 1554867.6 | N32: =M32/$F32 -> 0.38189027 | O32: 220236.06 | P32: =O32/$F32 -> 0.054092072 | Q32: 119582.46 | R32: =Q32/$F32 -> 0.02937059 | S32: =O32+Q32 -> 339818.52 | T32: =S32/$F32 -> 0.083462662 | U32: 93877.92 | V32: =U32/$F32 -> 0.02305731 | W32: 51233.12 | X32: =W32/$F32 -> 0.012583342 | Y32: 198581.46 | Z32: =Y32/$F32 -> 0.048773496 | AA32: 704003.3 | AB32: =AA32/$F32 -> 0.17290991 | AC32: =Y32+AA32 -> 902584.76 | AD32: =AC32/$F32 -> 0.22168341 | AE32: 1061984 | AF32: =AE32/F32 -> 0.26083338 | AG32: 0 | AH32: =AG32/$F32 -> 0 | AI32: 0 | AJ32: =AI32/$F32 -> 0 | AK32: 67137.6 | AL32: =AK32/$F32 -> 0.016489633
D33: 46103 | E33: 日 | F33: =SUM(M33,S33,U33,W33,AC33,AE33,AG33,AI33,AK33) -> 5501397.2 | I33: 841377.18 | J33: =I33/$F33 -> 0.15293882 | K33: 1106539.4 | L33: =K33/$F33 -> 0.20113789 | M33: =I33+K33 -> 1947916.6 | N33: =M33/F33 -> 0.35407671 | O33: 322406.6 | P33: =O33/$F33 -> 0.058604494 | Q33: 152896.97 | R33: =Q33/$F33 -> 0.027792389 | S33: =O33+Q33 -> 475303.57 | T33: =S33/F33 -> 0.086396883 | U33: 131149.62 | V33: =U33/F33 -> 0.023839329 | W33: 55524 | X33: =W33/$F33 -> 0.010092709 | Y33: 230599.74 | Z33: =Y33/$F33 -> 0.041916577 | AA33: 823314.61 | AB33: =AA33/$F33 -> 0.14965555 | AC33: =Y33+AA33 -> 1053914.4 | AD33: =AC33/$F33 -> 0.19157212 | AE33: 1770333.2 | AF33: =AE33/F33 -> 0.32179702 | AG33: 0 | AH33: =AG33/$F33 -> 0 | AI33: 0 | AJ33: =AI33/$F33 -> 0 | AK33: 67255.8 | AL33: =AK33/$F33 -> 0.012225222
D34: 46104 | E34: 一 | F34: =SUM(M34,S34,U34,W34,AC34,AE34,AG34,AI34,AK34) -> 5094060.9 | I34: 777432.91 | J34: =I34/$F34 -> 0.15261555 | K34: 1085000.7 | L34: =K34/$F34 -> 0.21299326 | M34: =I34+K34 -> 1862433.6 | N34: =M34/$F34 -> 0.36560881 | O34: 287518.68 | P34: =O34/$F34 -> 0.05644194 | Q34: 155574.51 | R34: =Q34/$F34 -> 0.030540371 | S34: =O34+Q34 -> 443093.19 | T34: =S34/$F34 -> 0.086982311 | U34: 120567.11 | V34: =U34/$F34 -> 0.023668172 | W34: 65519.41 | X34: =W34/$F34 -> 0.012861921 | Y34: 229237.26 | Z34: =Y34/$F34 -> 0.045000887 | AA34: 765801.78 | AB34: =AA34/$F34 -> 0.15033228 | AC34: =Y34+AA34 -> 995039.04 | AD34: =AC34/$F34 -> 0.19533316 | AE34: 1539798.2 | AF34: =AE34/F34 -> 0.30227322 | AG34: 0 | AH34: =AG34/$F34 -> 0 | AI34: 0 | AJ34: =AI34/$F34 -> 0 | AK34: 67610.4 | AL34: =AK34/$F34 -> 0.013272397
B35: =D36+7 -> 46113 | D35: 46105 | E35: 二 | F35: =SUM(M35,S35,U35,W35,AC35,AE35,AG35,AI35,AK35) -> 4902681.6 | G35: =SUM(F35:F41) -> 32252127 | I35: 755646.37 | J35: =I35/$F35 -> 0.1541292 | K35: 1062250.7 | L35: =K35/$F35 -> 0.21666729 | M35: =I35+K35 -> 1817897.1 | N35: =M35/$F35 -> 0.37079648 | O35: 289343.34 | P35: =O35/$F35 -> 0.059017363 | Q35: 155689.04 | R35: =Q35/$F35 -> 0.031755895 | S35: =O35+Q35 -> 445032.38 | T35: =S35/$F35 -> 0.090773257 | U35: 118411.66 | V35: =U35/$F35 -> 0.024152427 | W35: 60207.69 | X35: =W35/$F35 -> 0.012280563 | Y35: 217826.49 | Z35: =Y35/$F35 -> 0.044430071 | AA35: 733801.88 | AB35: =AA35/$F35 -> 0.14967357 | AC35: =Y35+AA35 -> 951628.37 | AD35: =AC35/$F35 -> 0.19410364 | AE35: 1437166 | AF35: =AE35/F35 -> 0.29313876 | AG35: 0 | AH35: =AG35/$F35 -> 0 | AI35: 0 | AJ35: =AI35/$F35 -> 0 | AK35: 72338.4 | AL35: =AK35/$F35 -> 0.014754864
