Workbook

Sheet 日別報廢率總表 
A1: 大溪廠半成品管理日別總表 | V1: 半成品品項數
A2: 日期 | B2: 營業額 | C2: 報廢額 | D2: 報廢率 KPI 0.25% | E2: 超用額 | F2: 超用率 | G2: 廢棄前10名 | I2: 超用前10名 | K2: 共用類廢棄
G3: 金額總計 | H3: 構成比 | I3: 金額總計 | J3: 構成比 | K3: 金額總計 | L3: 構成比 KPI 15%
A4: 45901 | B4: ='0901分析標準表'!$C$3 -> 7806641.3 | C4: ='0901分析標準表'!$D$5 -> 18890.799 | D4: =C4/B4 -> 0.0024198369 | E4: ='0901分析標準表'!$F$5 -> 57786.602 | F4: =E4/B4 -> 0.0074022361 | G4: ='0901分析標準表'!$H$5 -> 4046.0189 | H4: =G4/C4 -> 0.21417934 | I4: ='0901分析標準表'!$J$5 -> 13156.282 | J4: =I4/E4 -> 0.22767011 | K4: ='0901分析標準表'!$L$5 -> 2627.0037 | L4: =K4/C4 -> 0.1390626 | M4: 1.5i為取樣不穩 2.2i展開量105% 3.1i研發設定，小片的規格不符合指示書設定重量 4.2i製程不穩 | V4: 165
A5: =A4+1 -> 45902 | B5: ='0902分析標準表'!$C$3 -> 8169292.4 | C5: ='0902分析標準表'!$D$5 -> 19804.524 | D5: =C5/B5 -> 0.0024242643 | E5: ='0902分析標準表'!$F$5 -> 60496.908 | F5: =E5/B5 -> 0.0074054037 | G5: ='0902分析標準表'!$H$5 -> 4567.9905 | H5: =G5/C5 -> 0.23065389 | I5: ='0902分析標準表'!$J$5 -> 16402.993 | J5: =I5/E5 -> 0.2711377 | K5: ='0902分析標準表'!$L$5 -> 2613.1789 | L5: =K5/C5 -> 0.13194859 | M5: 1.3i為取樣不穩 2.4i展開量105% 3.1i研發設定，小片的規格不符合指示書設定重量 4.2i製程不穩 | V5: 168
A6: =A5+1 -> 45903 | B6: ='0903分析標準表'!$C$3 -> 7774607.2 | C6: ='0903分析標準表'!$D$5 -> 18796.061 | D6: =C6/B6 -> 0.0024176219 | E6: ='0903分析標準表'!$F$5 -> 57180.863 | F6: =E6/B6 -> 0.0073548234 | G6: ='0903分析標準表'!$H$5 -> 4000.8863 | H6: =G6/C6 -> 0.2128577 | I6: ='0903分析標準表'!$J$5 -> 14191.893 | J6: =I6/E6 -> 0.24819306 | K6: ='0903分析標準表'!$L$5 -> 2163.5179 | L6: =K6/C6 -> 0.11510486 | M6: 1.3i為取樣不穩 2.3i展開量105% 3.1i研發設定，小片的規格不符合指示書設定重量 4.2i製程不穩 5.1i原物料規格 | V6: 168
A7: =A6+1 -> 45904 | B7: ='0904分析標準表'!$C$3 -> 6925705.3 | C7: ='0904分析標準表'!$D$5 -> 16721.351 | D7: =C7/B7 -> 0.0024143896 | E7: ='0904分析標準表'!$F$5 -> 50847.621 | F7: =E7/B7 -> 0.007341869 | G7: ='0904分析標準表'!$H$5 -> 4283.4053 | H7: =G7/C7 -> 0.25616383 | I7: ='0904分析標準表'!$J$5 -> 19270.511 | J7: =I7/E7 -> 0.37898549 | K7: ='0904分析標準表'!$L$5 -> 2640.4546 | L7: =K7/C7 -> 0.15790917 | M7: 1.2i為取樣不穩 2.4i展開量105% 3.1i研發設定，小片的規格不符合指示書設定重量 4.2i製程不穩 5.1i原物料規格 | V7: 168
A8: =A7+1 -> 45905 | B8: ='0905分析標準表'!$C$3 -> 5813361.8 | C8: ='0905分析標準表'!$D$5 -> 14011.298 | D8: =C8/B8 -> 0.0024101885 | E8: ='0905分析標準表'!$F$5 -> 41910.745 | F8: =E8/B8 -> 0.0072093819 | G8: ='0905分析標準表'!$H$5 -> 3162.0398 | H8: =G8/C8 -> 0.22567787 | I8: ='0905分析標準表'!$J$5 -> 16692.996 | J8: =I8/E8 -> 0.3982987 | K8: ='0905分析標準表'!$L$5 -> 2269.5211 | L8: =K8/C8 -> 0.16197794 | M8: 1.2i為取樣不穩 2.2i展開量105% 3.1i研發設定，小片的規格不符合指示書設定重量 4.3i製程不穩 5.2i原物料規格 | V8: 168
A9: =A8+1 -> 45906 | B9: ='0906分析標準表'!$C$3 -> 6064269.1 | C9: ='0906分析標準表'!$D$5 -> 14614.187 | D9: =C9/B9 -> 0.0024098843 | E9: ='0906分析標準表'!$F$5 -> 43815.584 | F9: =E9/B9 -> 0.0072252045 | G9: ='0906分析標準表'!$H$5 -> 4195.5954 | H9: =G9/C9 -> 0.28709058 | I9: ='0906分析標準表'!$J$5 -> 19012.177 | J9: =I9/E9 -> 0.43391359 | K9: ='0906分析標準表'!$L$5 -> 2184.1961 | L9: =K9/C9 -> 0.14945724 | M9: 1.4i為取樣不穩 2.1i展開量105% 3.1i研發設定，小片的規格不符合指示書設定重量 4.3i製程不穩 5.1i原物料規格 | V9: 168
A10: =A9+1 -> 45907 | B10: ='0907分析標準表'!$C$3 -> 8031264.4 | C10: ='0907分析標準表'!$D$5 -> 19417.673 | D10: =C10/B10 -> 0.0024177604 | E10: ='0907分析標準表'!$F$5 -> 58646.034 | F10: =E10/B10 -> 0.0073022168 | G10: ='0907分析標準表'!$H$5 -> 2976.0915 | H10: =G10/C10 -> 0.15326716 | I10: ='0907分析標準表'!$J$5 -> 18030.284 | J10: =I10/E10 -> 0.30744252 | K10: ='0907分析標準表'!$L$5 -> 2858.7592 | L10: =K10/C10 -> 0.1472246 | M10: 1.5i為取樣不穩 2.1i展開量105% 3.1i研發設定，小片的規格不符合指示書設定重量 4.2i製程不穩 5.2i原物料規格 | V10: 168
A11: =A10+1 -> 45908 | B11: ='0908分析標準表'!$C$3 -> 7945762.3 | C11: ='0908分析標準表'!$D$5 -> 19226.28 | D11: =C11/B11 -> 0.0024196898 | E11: ='0908分析標準表'!$F$5 -> 57407.437 | F11: =E11/B11 -> 0.0072249125 | G11: ='0908分析標準表'!$H$5 -> 3542.9086 | H11: =G11/C11 -> 0.18427427 | I11: ='0908分析標準表'!$J$5 -> 15998.35 | J11: =I11/E11 -> 0.27868078 | K11: ='0908分析標準表'!$L$5 -> 2450.7745 | L11: =K11/C11 -> 0.12747003 | M11: 1.3i為取樣不穩 2.3i展開量105% 3.1i研發設定，小片的規格不符合指示書設定重量 4.2i製程不穩 5.1i原物料規格 | V11: 169
A12: =A11+1 -> 45909 | B12: ='0909分析標準表'!$C$3 -> 7852972.2 | C12: ='0909分析標準表'!$D$5 -> 18989.068 | D12: =C12/B12 -> 0.002418074 | E12: ='0909分析標準表'!$F$5 -> 56792.052 | F12: =E12/B12 -> 0.0072319181 | G12: ='0909分析標準表'!$H$5 -> 6211.8668 | H12: =G12/C12 -> 0.32712858 | I12: ='0909分析標準表'!$J$5 -> 13180.342 | J12: =I12/E12 -> 0.23208074 | K12: ='0909分析標準表'!$L$5 -> 3586.7374 | L12: =K12/C12 -> 0.18888433 | M12: 1.2i為取樣不穩 2.4i展開量105% 3.1i研發設定，小片的規格不符合指示書設定重量 4.1i製程不穩 5.2i原物料規格 | V12: 170
A13: =A12+1 -> 45910 | B13: ='0910分析標準表'!$C$3 -> 7585453.3 | C13: ='0910分析標準表'!$D$5 -> 18325.581 | D13: =C13/B13 -> 0.0024158847 | E13: ='0910分析標準表'!$F$5 -> 54158.093 | F13: =E13/B13 -> 0.0071397306 | G13: ='0910分析標準表'!$H$5 -> 4007.0428 | H13: =G13/C13 -> 0.21865844 | I13: ='0910分析標準表'!$J$5 -> 14337.106 | J13: =I13/E13 -> 0.26472694 | K13: ='0910分析標準表'!$L$5 -> 2265.1703 | L13: =K13/C13 -> 0.12360701 | M13: 1.5i為取樣不穩 2.1i展開量105% 3.1i研發設定，小片的規格不符合指示書設定重量 4.3i製程不穩 | V13: 168
A14: =A13+1 -> 45911 | B14: ='0911分析標準表'!$C$3 -> 6980689.7 | C14: ='0911分析標準表'!$D$5 -> 16847.966 | D14: =C14/B14 -> 0.0024135103 | E14: ='0911分析標準表'!$F$5 -> 49744.602 | F14: =E14/B14 -> 0.0071260297 | G14: ='0911分析標準表'!$H$5 -> 3838.4942 | H14: =G14/C14 -> 0.22783131 | I14: ='0911分析標準表'!$J$5 -> 19399.405 | J14: =I14/E14 -> 0.38998011 | K14: ='0911分析標準表'!$L$5 -> 2555.1956 | L14: =K14/C14 -> 0.15166196 | M14: 1.5i為取樣不穩 2.2i展開量105% 3.1i研發設定，小片的規格不符合指示書設定重量 4.1i製程不穩 5.1i原物料規格 | V14: 168
A15: =A14+1 -> 45912 | B15: ='0912分析標準表'!$C$3 -> 5798799.4 | C15: ='0912分析標準表'!$D$5 -> 13984.861 | D15: =C15/B15 -> 0.0024116822 | E15: ='0912分析標準表'!$F$5 -> 41420.318 | F15: =E15/B15 -> 0.0071429126 | G15: ='0912分析標準表'!$H$5 -> 6707.2372 | H15: =G15/C15 -> 0.47960698 | I15: ='0912分析標準表'!$J$5 -> 18841.758 | J15: =I15/E15 -> 0.45489167 | K15: ='0912分析標準表'!$L$5 -> 1633.6051 | L15: =K15/C15 -> 0.11681239 | M15: 1.5i為取樣不穩 2.2i展開量105% 3.1i研發設定，小片的規格不符合指示書設定重量 4.1i製程不穩 5.1i其他原因 | V15: 168
A16: =A15+1 -> 45913 | B16: ='0913分析標準表'!$C$3 -> 6087959.4 | C16: ='0913分析標準表'!$D$5 -> 14694.913 | D16: =C16/B16 -> 0.0024137665 | E16: ='0913分析標準表'!$F$5 -> 43322.471 | F16: =E16/B16 -> 0.0071160907 | G16: ='0913分析標準表'!$H$5 -> 5166.7466 | H16: =G16/C16 -> 0.35160104 | I16: ='0913分析標準表'!$J$5 -> 15600.561 | J16: =I16/E16 -> 0.36010322 | K16: ='0913分析標準表'!$L$5 -> 1361.5699 | L16: =K16/C16 -> 0.092655869 | M16: 1.3i為取樣不穩 2.4i展開量105% 3.1i研發設定，小片的規格不符合指示書設定重量 4.2i製程不穩 | V16: 168
A17: =A16+1 -> 45914 | B17: ='0914分析標準表'!$C$3 -> 8034432.2 | C17: ='0914分析標準表'!$D$5 -> 19430.678 | D17: =C17/B17 -> 0.0024184258 | E17: ='0914分析標準表'!$F$5 -> 57482.401 | F17: =E17/B17 -> 0.0071545069 | G17: ='0914分析標準表'!$H$5 -> 4041.6025 | H17: =G17/C17 -> 0.20800111 | I17: ='0914分析標準表'!$J$5 -> 12757.079 | J17: =I17/E17 -> 0.22193018 | K17: ='0914分析標準表'!$L$5 -> 2790.8796 | L17: =K17/C17 -> 0.14363264 | M17: 1.4i為取樣不穩 2.2i展開量105% 3.1i研發設定，小片的規格不符合指示書設定重量 4.2i製程不穩 5.1i原物料規格 | V17: 160
A18: =A17+1 -> 45915 | B18: ='0915分析標準表'!$C$3 -> 7902070 | C18: ='0915分析標準表'!$D$5 -> 19089.992 | D18: =C18/B18 -> 0.0024158217 | E18: ='0915分析標準表'!$F$5 -> 56342.009 | F18: =E18/B18 -> 0.0071300317 | G18: ='0915分析標準表'!$H$5 -> 4866.0188 | H18: =G18/C18 -> 0.25489894 | I18: ='0915分析標準表'!$J$5 -> 20849.636 | J18: =I18/E18 -> 0.37005489 | K18: ='0915分析標準表'!$L$5 -> 3670.1785 | L18: =K18/C18 -> 0.19225668 | M18: 1.5i為取樣不穩 2.1i展開量105% 3.1i研發設定，小片的規格不符合指示書設定重量 4.1i製程不穩 5.2i原物料規格 | V18: 158
A19: =A18+1 -> 45916 | B19: ='0916分析標準表'!$C$3 -> 8643585.1 | C19: ='0916分析標準表'!$D$5 -> 21007.84 | D19: =C19/B19 -> 0.0024304544 | E19: ='0916分析標準表'!$F$5 -> 62334.438 | F19: =E19/B19 -> 0.0072116417 | G19: ='0916分析標準表'!$H$5 -> 7198.9206 | H19: =G19/C19 -> 0.34267782 | I19: ='0916分析標準表'!$J$5 -> 26760.536 | J19: =I19/E19 -> 0.4293058 | K19: ='0916分析標準表'!$L$5 -> 3222.8437 | L19: =K19/C19 -> 0.15341148 | M19: 1.4i為取樣不穩 2.5i展開量105% 3.1i研發設定，小片的規格不符合指示書設定重量 | V19: 174
A20: =A19+1 -> 45917 | B20: ='0917分析標準表'!$C$3 -> 8026958.5 | C20: ='0917分析標準表'!$D$5 -> 19476.861 | D20: =C20/B20 -> 0.002426431 | E20: ='0917分析標準表'!$F$5 -> 57892.892 | F20: =E20/B20 -> 0.0072123074 | G20: ='0917分析標準表'!$H$5 -> 5695.657 | H20: =G20/C20 -> 0.29243197 | I20: ='0917分析標準表'!$J$5 -> 25858.326 | J20: =I20/E20 -> 0.44665805 | K20: ='0917分析標準表'!$L$5 -> 3625.0326 | L20: =K20/C20 -> 0.18611996 | M20: 1.2i為取樣不穩 2.6i展開量105% 3.1i研發設定，小片的規格不符合指示書設定重量 4.1i原物料規格 | V20: 174
A21: =A20+1 -> 45918 | B21: ='0918分析標準表'!$C$3 -> 7356981 | C21: ='0918分析標準表'!$D$5 -> 17831.618 | D21: =C21/B21 -> 0.0024237684 | E21: ='0918分析標準表'!$F$5 -> 53044.101 | F21: =E21/B21 -> 0.0072100365 | G21: ='0918分析標準表'!$H$5 -> 5863.3725 | H21: =G21/C21 -> 0.32881887 | I21: ='0918分析標準表'!$J$5 -> 23351.343 | J21: =I21/E21 -> 0.44022506 | K21: ='0918分析標準表'!$L$5 -> 3415.2734 | L21: =K21/C21 -> 0.19152908 | M21: 1.6i為取樣不穩 2.2i展開量105% 3.1i研發設定，小片的規格不符合指示書設定重量 4.1i原物料規格 | V21: 174
A22: =A21+1 -> 45919 | B22: ='0919分析標準表'!$C$3 -> 5796047.9 | C22: ='0919分析標準表'!$D$5 -> 14036.895 | D22: =C22/B22 -> 0.0024218046 | E22: ='0919分析標準表'!$F$5 -> 41419.956 | F22: =E22/B22 -> 0.0071462412 | G22: ='0919分析標準表'!$H$5 -> 4383.8855 | H22: =G22/C22 -> 0.31231161 | I22: ='0919分析標準表'!$J$5 -> 13311.998 | J22: =I22/E22 -> 0.32139092 | K22: ='0919分析標準表'!$L$5 -> 2181.3901 | L22: =K22/C22 -> 0.15540403 | M22: 1.5i為取樣不穩 2.4i展開量105% 3.1i研發設定，小片的規格不符合指示書設定重量 | V22: 174
A23: =A22+1 -> 45920 | B23: ='0920分析標準表'!$C$3 -> 5974025.3 | C23: ='0920分析標準表'!$D$5 -> 14470.434 | D23: =C23/B23 -> 0.002422225 | E23: ='0920分析標準表'!$F$5 -> 42713.631 | F23: =E23/B23 -> 0.0071498913 | G23: ='0920分析標準表'!$H$5 -> 3120.7277 | H23: =G23/C23 -> 0.21566235 | I23: ='0920分析標準表'!$J$5 -> 15543.565 | J23: =I23/E23 -> 0.36390174 | K23: ='0920分析標準表'!$L$5 -> 2506.6467 | L23: =K23/C23 -> 0.1732254 | M23: 1.4i為取樣不穩 2.4i展開量105% 3.1i研發設定，小片的規格不符合指示書設定重量 4.1i原物料規格 | V23: 174
A24: =A23+1 -> 45921 | B24: ='0921分析標準表'!$C$3 -> 7966442.2 | C24: ='0921分析標準表'!$D$5 -> 19329.103 | D24: =C24/B24 -> 0.0024263156 | E24: ='0921分析標準表'!$F$5 -> 57386.624 | F24: =E24/B24 -> 0.0072035449 | G24: ='0921分析標準表'!$H$5 -> 5551.8348 | H24: =G24/C24 -> 0.28722672 | I24: ='0921分析標準表'!$J$5 -> 15889.63 | J24: =I24/E24 -> 0.27688734 | K24: ='0921分析標準表'!$L$5 -> 2023.2663 | L24: =K24/C24 -> 0.10467461 | M24: 1.5i為取樣不穩 2.4i展開量105% 3.1i研發設定，小片的規格不符合指示書設定重量 | V24: 174
A25: =A24+1 -> 45922 | B25: ='0922分析標準表'!$C$3 -> 7692372.9 | C25: ='0922分析標準表'!$D$5 -> 18648.763 | D25: =C25/B25 -> 0.0024243187 | E25: ='0922分析標準表'!$F$5 -> 55273.626 | F25: =E25/B25 -> 0.0071855104 | G25: ='0922分析標準表'!$H$5 -> 4858.09 | H25: =G25/C25 -> 0.26050468 | I25: ='0922分析標準表'!$J$5 -> 17210.06 | J25: =I25/E25 -> 0.31136116 | K25: ='0922分析標準表'!$L$5 -> 3705.746 | L25: =K25/C25 -> 0.1987127 | M25: 1.6i為取樣不穩 2.3i展開量105% 3.1i研發設定，小片的規格不符合指示書設定重量 | V25: 174
A26: =A25+1 -> 45923 | B26: ='0923分析標準表'!$C$3 -> 7459138 | C26: ='0923分析標準表'!$D$5 -> 18065.41 | D26: =C26/B26 -> 0.0024219166 | E26: ='0923分析標準表'!$F$5 -> 54022.948 | F26: =E26/B26 -> 0.0072425189 | G26: ='0923分析標準表'!$H$5 -> 3771.3058 | H26: =G26/C26 -> 0.20875838 | I26: ='0923分析標準表'!$J$5 -> 22897.348 | J26: =I26/E26 -> 0.42384484 | K26: ='0923分析標準表'!$L$5 -> 2962.7928 | L26: =K26/C26 -> 0.16400363 | M26: 1.6i為取樣不穩 2.2i展開量105% 3.1i研發設定，小片的規格不符合指示書設定重量 4.1i原物料規格 | V26: 174
A27: =A26+1 -> 45924 | B27: ='0924分析標準表'!$C$3 -> 7098839 | C27: ='0924分析標準表'!$D$5 -> 17168.15 | D27: =C27/B27 -> 0.0024184448 | E27: ='0924分析標準表'!$F$5 -> 50583.885 | F27: =E27/B27 -> 0.007125656 | G27: ='0924分析標準表'!$H$5 -> 3368.697 | H27: =G27/C27 -> 0.19621782 | I27: ='0924分析標準表'!$J$5 -> 21401.144 | J27: =I27/E27 -> 0.42308226 | K27: ='0924分析標準表'!$L$5 -> 2233.6144 | L27: =K27/C27 -> 0.13010222 | M27: 1.5i為取樣不穩 2.4i展開量105% 3.1i研發設定，小片的規格不符合指示書設定重量 | V27: 174
A28: =A27+1 -> 45925 | B28: ='0925分析標準表'!$C$3 -> 6557727.1 | C28: ='0925分析標準表'!$D$5 -> 15819.225 | D28: =C28/B28 -> 0.0024123031 | E28: ='0925分析標準表'!$F$5 -> 46633.562 | F28: =E28/B28 -> 0.0071112386 | G28: ='0925分析標準表'!$H$5 -> 4625.5322 | H28: =G28/C28 -> 0.29239942 | I28: ='0925分析標準表'!$J$5 -> 16899.604 | J28: =I28/E28 -> 0.36239144 | K28: ='0925分析標準表'!$L$5 -> 4091.5539 | L28: =K28/C28 -> 0.25864439 | M28: 1.7i為取樣不穩 2.1i展開量105% 3.1i研發設定，小片的規格不符合指示書設定重量 4.1i原物料規格 | V28: 174
A29: =A28+1 -> 45926 | B29: ='0926分析標準表'!$C$3 -> 5226513.3 | C29: ='0926分析標準表'!$D$5 -> 12595.986 | D29: =C29/B29 -> 0.002410017 | E29: ='0926分析標準表'!$F$5 -> 37138 | F29: =E29/B29 -> 0.0071056933 | G29: ='0926分析標準表'!$H$5 -> 3258.012 | H29: =G29/C29 -> 0.25865479 | I29: ='0926分析標準表'!$J$5 -> 18684.236 | J29: =I29/E29 -> 0.5031029 | K29: ='0926分析標準表'!$L$5 -> 2389.5566 | L29: =K29/C29 -> 0.18970779 | M29: 1.4i為取樣不穩 2.5i展開量105% 3.1i研發設定，小片的規格不符合指示書設定重量 | V29: 174
A30: =A29+1 -> 45927 | B30: ='0927分析標準表'!$C$3 -> 5183430.2 | C30: ='0927分析標準表'!$D$5 -> 12493.837 | D30: =C30/B30 -> 0.0024103416 | E30: ='0927分析標準表'!$F$5 -> 36775.807 | F30: =E30/B30 -> 0.0070948784 | G30: ='0927分析標準表'!$H$5 -> 3846.5122 | H30: =G30/C30 -> 0.30787276 | I30: ='0927分析標準表'!$J$5 -> 17045.617 | J30: =I30/E30 -> 0.46350081 | K30: ='0927分析標準表'!$L$5 -> 2265.2746 | L30: =K30/C30 -> 0.18131136 | M30: 1.5i為取樣不穩 2.3i展開量105% 3.1i研發設定，小片的規格不符合指示書設定重量 4.1i原物料規格 | V30: 174
A31: =A30+1 -> 45928 | B31: ='0928分析標準表'!$C$3 -> 5811925.4 | C31: ='0928分析標準表'!$D$5 -> 14019.259 | D31: =C31/B31 -> 0.0024121541 | E31: ='0928分析標準表'!$F$5 -> 41276.034 | F31: =E31/B31 -> 0.0071019553 | G31: ='0928分析標準表'!$H$5 -> 5539.4813 | H31: =G31/C31 -> 0.39513366 | I31: ='0928分析標準表'!$J$5 -> 16378.96 | J31: =I31/E31 -> 0.39681525 | K31: ='0928分析標準表'!$L$5 -> 3326.6535 | L31: =K31/C31 -> 0.23729167 | M31: 1.3i為取樣不穩 2.5i展開量105% 3.1i研發設定，小片的規格不符合指示書設定重量 4.1i原物料規格 | V31: 170
A32: =A31+1 -> 45929 | B32: ='0929分析標準表'!$C$3 -> 7679816.1 | C32: ='0929分析標準表'!$D$5 -> 18535.723 | D32: =C32/B32 -> 0.0024135634 | E32: ='0929分析標準表'!$F$5 -> 54681.688 | F32: =E32/B32 -> 0.0071201819 | G32: ='0929分析標準表'!$H$5 -> 5601.3797 | H32: =G32/C32 -> 0.30219375 | I32: ='0929分析標準表'!$J$5 -> 20571.504 | J32: =I32/E32 -> 0.37620464 | K32: ='0929分析標準表'!$L$5 -> 2344.9751 | L32: =K32/C32 -> 0.12651112 | M32: 1.7i為取樣不穩 2.1i研發設定，小片的規格不符合指示書設定重量 3.2i原物料規格 | V32: 171
A33: =A32+1 -> 45930 | B33: ='0930分析標準表'!$C$3 -> 8504391 | C33: ='0930分析標準表'!$D$5 -> 20545.406 | D33: =C33/B33 -> 0.0024158586 | E33: ='0930分析標準表'!$F$5 -> 60659.852 | F33: =E33/B33 -> 0.0071327685 | G33: ='0930分析標準表'!$H$5 -> 4665.3513 | H33: =G33/C33 -> 0.22707516 | I33: ='0930分析標準表'!$J$5 -> 22203.494 | J33: =I33/E33 -> 0.36603278 | K33: ='0930分析標準表'!$L$5 -> 3042.6479 | L33: =K33/C33 -> 0.14809383 | M33: 1.7i為取樣不穩 2.1i研發設定，小片的規格不符合指示書設定重量 3.2i原物料規格 | V33: 182
A35: ※淺黃色為工廠自填項目
A36: ※日期紅色為新品日

Sheet 0930分析標準表
A1: 大溪廠半成品管理分析
A2: 日期 | C2: 營業額 | D2: 報廢展開 | F2: 超用展開 | H2: 報廢展開 | J2: 超用展開 | L2: 報廢展開
A3: 45930 | C3: 8504391 | D3: 總報廢 | F3: 總超用 | H3: 報廢-前10名 | J3: 超用-前10名 | L3: 共用類-總報廢
D4: 金額 | E4: 占比(營業額) | F4: 金額 | G4: 占比(營業額) | H4: 金額 | I4: 占比(總報廢) | J4: 金額 | K4: 占比(總超用) | L4: 金額 | M4: 占比(總報廢)
A5: 年度KPI目標0.25% | D5: 20545.406 | E5: =D5/C3 -> 0.0024158586 | F5: 60659.852 | G5: =F5/C3 -> 0.0071327685 | H5: =SUM(C12:C21) -> 4665.3513 | I5: =H5/D5 -> 0.22707516 | J5: =SUM(C28:C37) -> 22203.494 | K5: =J5/F5 -> 0.36603278 | L5: 3042.6479 | M5: =L5/D5 -> 0.14809383
A7: 報廢金額前十名半成品
A8: 明細展開 | D8: 生產資訊 | O8: 類別 | P8: 分析原因 (請填寫8大原因) | Q8: 其他原因說明 | R8: 備註-商品名稱
A9: 排序 | B9: 半成品 | D9: 生產端 | J9: 組合端
B10: 名稱 | C10: 報廢金額 排序 | D10: 產出量 | J10: 報廢 | L10: 超用
D11: 訂單需求 (kg) | E11: 實際產出 (kg) | F11: 補單 (kg) | G11: 單價 (元) | H11: 實際生產 (對比訂單需求) | I11: 差異 (元) | J11: kg | K11: 占比 | L11: kg | M11: 占比 | N11: 金額 (元)
A12: 1 | B12: 烤銀鮭魚肚 | C12: 1081.5 | D12: 3901 | E12: 3971 | F12: 0 | G12: 15.45 | H12: =(E12+F12)/D12 -> 1.0179441 | I12: 1081.5 | J12: 70 | K12: =J12/D12 -> 0.017944117 | L12: =((E12+F12)-D12)-J12 -> 0 | M12: =L12/D12 -> 0 | N12: =L12*G12 -> 0 | O12: 調理端 | P12: 研發設定 | Q12: 研發設定，小片的規格不符合指示書設定重量 | R12: 一配贅沢鮭魚肚飯糰
A13: 2 | B13: 8切蒸四角魚板 | C13: 915.12 | D13: 10216 | E13: 10960 | F13: 0 | G13: 1.23 | H13: =(E13+F13)/D13 -> 1.0728269 | I13: 915.12 | J13: 744 | K13: =J13/D13 -> 0.072826938 | L13: =((E13+F13)-D13)-J13 -> 0 | M13: =L13/D13 -> 0 | N13: =L13*G13 -> 0 | O13: 調理端 | P13: 原物料規格 | Q13: 破損 | R13: 韓式部隊鍋
A14: 3 | B14: 部隊鍋湯凍 | C14: 389.025 | D14: 1225.92 | E14: 1247.22 | F14: 40.2 | G14: 51.87 | H14: =(E14+F14)/D14 -> 1.0501664 | I14: 3190.005 | J14: 7.5 | K14: =J14/D14 -> 0.0061178543 | L14: =((E14+F14)-D14)-J14 -> 54 | M14: =L14/D14 -> 0.044048551 | N14: =L14*G14 -> 2800.98 | O14: 調理端 | P14: 取樣不穩 | R14: 韓式部隊鍋
A15: 4 | B15: (V)消毒小黃瓜絲 | C15: 367.792 | D15: 263.02 | E15: 266.53 | F15: 0 | G15: 144.8 | H15: =(E15+F15)/D15 -> 1.013345 | I15: 508.248 | J15: 2.54 | K15: =J15/D15 -> 0.0096570603 | L15: =((E15+F15)-D15)-J15 -> 0.97 | M15: =L15/D15 -> 0.0036879325 | N15: =L15*G15 -> 140.456 | O15: 調理端 | P15: 取樣不穩 | R15: 共用類
A16: 5 | B16: 薑炒筍尾 | C16: 367.3 | D16: 54.13 | E16: 56.2 | F16: 0 | G16: 183.65 | H16: =(E16+F16)/D16 -> 1.0382413 | I16: 380.1555 | J16: 2 | K16: =J16/D16 -> 0.036948088 | L16: =((E16+F16)-D16)-J16 -> 0.07 | M16: =L16/D16 -> 0.0012931831 | N16: =L16*G16 -> 12.8555 | O16: 調理端 | P16: 取樣不穩 | R16: 經典滷肉飯
A17: 6 | B17: 煮日製細扁麵 | C17: 329.5875 | D17: 317.68 | E17: 327.1 | F17: 0 | G17: 39.95 | H17: =(E17+F17)/D17 -> 1.0296525 | I17: 376.329 | J17: 8.25 | K17: =J17/D17 -> 0.025969529 | L17: =((E17+F17)-D17)-J17 -> 1.17 | M17: =L17/D17 -> 0.0036829514 | N17: =L17*G17 -> 46.7415 | O17: 調理端 | P17: 取樣不穩 | R17: 金沙豆腐細扁麵
A18: 7 | B18: 奶油蕈菇起司醬(113年) | C18: 313.775 | D18: 166.81 | E18: 169.56 | F18: 0 | G18: 114.1 | H18: =(E18+F18)/D18 -> 1.0164858 | I18: 313.775 | J18: 2.75 | K18: =J18/D18 -> 0.016485822 | L18: =((E18+F18)-D18)-J18 -> 0 | M18: =L18/D18 -> 0 | N18: =L18*G18 -> 0 | O18: 調理端 | P18: 取樣不穩 | R18: 大口法式蕈菇起司雞排飯糰(113年)
A19: 8 | B19: 消毒青蔥絲 | C19: 303.1212 | D19: 49.95 | E19: 51.99 | F19: 0 | G19: 248.46 | H19: =(E19+F19)/D19 -> 1.0408408 | I19: 506.8584 | J19: 1.22 | K19: =J19/D19 -> 0.024424424 | L19: =((E19+F19)-D19)-J19 -> 0.82 | M19: =L19/D19 -> 0.016416416 | N19: =L19*G19 -> 203.7372 | O19: 調理端 | P19: 取樣不穩 | R19: 共用類
A20: 9 | B20: 炸馬鈴薯塊 | C20: 300.322 | D20: 59.93 | E20: 60.86 | F20: 1.82 | G20: 176.66 | H20: =(E20+F20)/D20 -> 1.0458869 | I20: 485.815 | J20: 1.7 | K20: =J20/D20 -> 0.028366427 | L20: =((E20+F20)-D20)-J20 -> 1.05 | M20: =L20/D20 -> 0.017520441 | N20: =L20*G20 -> 185.493 | O20: 調理端 | P20: 取樣不穩 | R20: 妮妮家漢堡排
A21: 10 | B21: (V)川燙小青花菜 | C21: 297.8086 | D21: 1122.6 | E21: 1125.77 | F21: 6.04 | G21: 147.43 | H21: =(E21+F21)/D21 -> 1.0082042 | I21: 1357.8303 | J21: 2.02 | K21: =J21/D21 -> 0.0017993943 | L21: =((E21+F21)-D21)-J21 -> 7.19 | M21: =L21/D21 -> 0.0064047746 | N21: =L21*G21 -> 1060.0217 | O21: 調理端 | P21: 原物料規格 | Q21: 大顆比例高 | R21: 共用類
A23: 超用金額前十名半成品
A24: 明細展開 | D24: 生產資訊 | O24: 類別 | P24: 分析原因 (請填寫8大原因) | Q24: 其他原因說明 | R24: 備註-商品名稱
A25: 排序 | B25: 半成品 | D25: 生產端 | J25: 組合端
B26: 名稱 | C26: 超用金額 排序 | D26: 產出量 | J26: 報廢 | M26: 超用
D27: 訂單需求 (kg) | E27: 實際產出 (kg) | F27: 補單 (kg) | G27: 單價 (元) | H27: 實際生產 (對比訂單需求) | I27: 差異 (元) | J27: kg | K27: 占比 | L27: 金額 (元) | M27: kg | N27: 占比
A28: 1 | B28: 炙燒韓式牛五花 | C28: 3774 | D28: 58.18 | E28: 60.98 | F28: 3.2 | G28: 629 | H28: =(E28+F28)/D28 -> 1.1031282 | I28: 3774 | J28: 0 | K28: =J28/D28 -> 0 | L28: =J28*G28 -> 0 | M28: =((E28+F28)-D28)-J28 -> 6 | N28: =M28/D28 -> 0.10312822 | O28: 組合室 | P28: 取樣不穩 | R28: 壹號醬炙烤牛飯糰
A29: 2 | B29: 焙炒芝麻肉鬆 | C29: 3286.7814 | D29: 498.2 | E29: 506.32 | F29: 9.1 | G29: 190.87 | H29: =(E29+F29)/D29 -> 1.0345644 | I29: 3286.7814 | J29: 0 | K29: =J29/D29 -> 0 | L29: =J29*G29 -> 0 | M29: =((E29+F29)-D29)-J29 -> 17.22 | N29: =M29/D29 -> 0.034564432 | O29: 組合室 | P29: 取樣不穩 | R29: 經典肉鬆飯糰(114年)
A30: 3 | B30: 部隊鍋湯凍 | C30: 2800.98 | D30: 1225.92 | E30: 1247.22 | F30: 40.2 | G30: 51.87 | H30: =(E30+F30)/D30 -> 1.0501664 | I30: 3190.005 | J30: 7.5 | K30: =J30/D30 -> 0.0061178543 | L30: =J30*G30 -> 389.025 | M30: =((E30+F30)-D30)-J30 -> 54 | N30: =M30/D30 -> 0.044048551 | O30: 組合室 | P30: 取樣不穩 | R30: 韓式部隊鍋
A31: 4 | B31: 炒照燒牛蒡腿丁 | C31: 2535.0805 | D31: 66.04 | E31: 60.77 | F31: 12.6 | G31: 345.85 | H31: =(E31+F31)/D31 -> 1.1109933 | I31: 2535.0805 | J31: 0 | K31: =J31/D31 -> 0 | L31: =J31*G31 -> 0 | M31: =((E31+F31)-D31)-J31 -> 7.33 | N31: =M31/D31 -> 0.11099334 | O31: 組合室 | P31: 取樣不穩 | R31: 一配照燒雞肉飯糰
A32: 5 | B32: 煮中華冷麵(110年) | C32: 2446.5129 | D32: 5223.99 | E32: 5203.9 | F32: 82.2 | G32: 39.39 | H32: =(E32+F32)/D32 -> 1.0118894 | I32: 2446.5129 | J32: 0 | K32: =J32/D32 -> 0 | L32: =J32*G32 -> 0 | M32: =((E32+F32)-D32)-J32 -> 62.11 | N32: =M32/D32 -> 0.01188938 | O32: 組合室 | P32: 研發設定 | Q32: 雙圈秤重範圍 | R32: 共用類
A33: 6 | B33: 烤照燒雞腿丁 | C33: 1851.7442 | D33: 119.88 | E33: 120.07 | F33: 4.84 | G33: 368.14 | H33: =(E33+F33)/D33 -> 1.0419586 | I33: 1851.7442 | J33: 0 | K33: =J33/D33 -> 0 | L33: =J33*G33 -> 0 | M33: =((E33+F33)-D33)-J33 -> 5.03 | N33: =M33/D33 -> 0.041958625 | O33: 組合室 | P33: 取樣不穩 | R33: 海陸雙拼肉肉餐盒
A34: 7 | B34: 切-究極燒肉片 | C34: 1655.2901 | D34: 49.09 | E34: 48.78 | F34: 2.7 | G34: 692.59 | H34: =(E34+F34)/D34 -> 1.0486861 | I34: 1655.2901 | J34: 0 | K34: =J34/D34 -> 0 | L34: =J34*G34 -> 0 | M34: =((E34+F34)-D34)-J34 -> 2.39 | N34: =M34/D34 -> 0.048686087 | O34: 組合室 | P34: 取樣不穩 | R34: 壹號醬雞豚雙拼
A35: 8 | B35: 歐姆蛋-黑咖哩醬 | C35: 1377.4879 | D35: 356.86 | E35: 352.49 | F35: 25.2 | G35: 66.13 | H35: =(E35+F35)/D35 -> 1.0583702 | I35: 1377.4879 | J35: 0 | K35: =J35/D35 -> 0 | L35: =J35*G35 -> 0 | M35: =((E35+F35)-D35)-J35 -> 20.83 | N35: =M35/D35 -> 0.058370229 | O35: 組合室 | P35: 取樣不穩 | R35: 二配里肌豬排可可咖哩歐姆蛋飯
A36: 9 | B36: 烤BBQ雞丁(112年) | C36: 1295.3922 | D36: 117.06 | E36: 115.27 | F36: 5.33 | G36: 365.93 | H36: =(E36+F36)/D36 -> 1.0302409 | I36: 1295.3922 | J36: 0 | K36: =J36/D36 -> 0 | L36: =J36*G36 -> 0 | M36: =((E36+F36)-D36)-J36 -> 3.54 | N36: =M36/D36 -> 0.030240902 | O36: 組合室 | P36: 取樣不穩 | R36: 美式雞丁餐盒(113年)
A37: 10 | B37: 蒸-醬香雞肉絲CL | C37: 1180.2252 | D37: 149.84 | E37: 149.66 | F37: 3.36 | G37: 371.14 | H37: =(E37+F37)/D37 -> 1.0212226 | I37: 1180.2252 | J37: 0 | K37: =J37/D37 -> 0 | L37: =J37*G37 -> 0 | M37: =((E37+F37)-D37)-J37 -> 3.18 | N37: =M37/D37 -> 0.021222637 | O37: 組合室 | P37: 取樣不穩 | R37: 共用類
A39: 共用類報廢金額前十名半成品
A40: 明細展開
A41: 排序 | B41: 半成品
B42: 名稱 | C42: 報廢金額 排序 | D42: 共用類總金額 占比
A44: 1 | B44: (V)消毒小黃瓜絲 | C44: 367.792 | D44: =C44/$L$5 -> 0.12087892
...

Sheet 0929分析標準表
A1: 大溪廠半成品管理分析
A2: 日期 | C2: 營業額 | D2: 報廢展開 | F2: 超用展開 | H2: 報廢展開 | J2: 超用展開 | L2: 報廢展開
A3: 45929 | C3: 7679816.1 | D3: 總報廢 | F3: 總超用 | H3: 報廢-前10名 | J3: 超用-前10名 | L3: 共用類-總報廢
D4: 金額 | E4: 占比(營業額) | F4: 金額 | G4: 占比(營業額) | H4: 金額 | I4: 占比(總報廢) | J4: 金額 | K4: 占比(總超用) | L4: 金額 | M4: 占比(總報廢)
A5: 年度KPI目標0.25% | D5: 18535.723 | E5: =D5/C3 -> 0.0024135634 | F5: 54681.688 | G5: =F5/C3 -> 0.0071201819 | H5: =SUM(C12:C21) -> 5601.3797 | I5: =H5/D5 -> 0.30219375 | J5: =SUM(C28:C37) -> 20571.504 | K5: =J5/F5 -> 0.37620464 | L5: 2344.9751 | M5: =L5/D5 -> 0.12651112
A7: 報廢金額前十名半成品
A8: 明細展開 | D8: 生產資訊 | O8: 類別 | P8: 分析原因 (請填寫8大原因) | Q8: 其他原因說明 | R8: 備註-商品名稱
A9: 排序 | B9: 半成品 | D9: 生產端 | J9: 組合端
B10: 名稱 | C10: 報廢金額 排序 | D10: 產出量 | J10: 報廢 | L10: 超用
D11: 訂單需求 (kg) | E11: 實際產出 (kg) | F11: 補單 (kg) | G11: 單價 (元) | H11: 實際生產 (對比訂單需求) | I11: 差異 (元) | J11: kg | K11: 占比 | L11: kg | M11: 占比 | N11: 金額 (元)
A12: 1 | B12: 煮烏龍冷麵(113年) | C12: 1114.1832 | D12: 505.78 | E12: 509.96 | F12: 14.44 | G12: 82.41 | H12: =(E12+F12)/D12 -> 1.0368144 | I12: 1534.4742 | J12: 13.52 | K12: =J12/D12 -> 0.02673099 | L12: =((E12+F12)-D12)-J12 -> 5.1 | M12: =L12/D12 -> 0.010083435 | N12: =L12*G12 -> 420.291 | O12: 調理端 | P12: 取樣不穩 | R12: 芝麻鰹魚烏龍冷麵
A13: 2 | B13: 切-烤台式肉片 | C13: 1059.8666 | D13: 35.57 | E13: 37.26 | F13: 0 | G13: 627.14 | H13: =(E13+F13)/D13 -> 1.0475119 | I13: 1059.8666 | J13: 1.69 | K13: =J13/D13 -> 0.047511948 | L13: =((E13+F13)-D13)-J13 -> -2.220446e-15 | M13: =L13/D13 -> -6.2424685e-17 | N13: =L13*G13 -> -1.3925305e-12 | O13: 調理端 | P13: 取樣不穩 | R13: 姨次滿足熟成牛豚雙拼
A14: 3 | B14: 清炒高麗菜 | C14: 908.868 | D14: 190.32 | E14: 197.72 | F14: 0 | G14: 122.82 | H14: =(E14+F14)/D14 -> 1.0388819 | I14: 908.868 | J14: 7.4 | K14: =J14/D14 -> 0.038881883 | L14: =((E14+F14)-D14)-J14 -> 0 | M14: =L14/D14 -> 0 | N14: =L14*G14 -> 0 | O14: 調理端 | P14: 取樣不穩 | R14: 美式雞丁餐盒(113年)
A15: 4 | B15: 烤銀鮭魚肚 | C15: 695.25 | D15: 3956 | E15: 4001 | F15: 0 | G15: 15.45 | H15: =(E15+F15)/D15 -> 1.0113751 | I15: 695.25 | J15: 45 | K15: =J15/D15 -> 0.011375126 | L15: =((E15+F15)-D15)-J15 -> 0 | M15: =L15/D15 -> 0 | N15: =L15*G15 -> 0 | O15: 調理端 | P15: 研發設定 | Q15: 研發設定，小片的規格不符合指示書設定重量 | R15: 一配贅沢鮭魚肚飯糰
A16: 5 | B16: 炒油蔥醬 | C16: 316.1925 | D16: 203.38 | E16: 208.84 | F16: 0 | G16: 152.75 | H16: =(E16+F16)/D16 -> 1.0268463 | I16: 834.015 | J16: 2.07 | K16: =J16/D16 -> 0.010177992 | L16: =((E16+F16)-D16)-J16 -> 3.39 | M16: =L16/D16 -> 0.016668306 | N16: =L16*G16 -> 517.8225 | O16: 調理端 | P16: 取樣不穩 | R16: 雞肉飯飯糰
A17: 6 | B17: 消毒青蔥絲 | C17: 313.0596 | D17: 47.43 | E17: 49.59 | F17: 0 | G17: 248.46 | H17: =(E17+F17)/D17 -> 1.0455408 | I17: 536.6736 | J17: 1.26 | K17: =J17/D17 -> 0.026565465 | L17: =((E17+F17)-D17)-J17 -> 0.9 | M17: =L17/D17 -> 0.018975332 | N17: =L17*G17 -> 223.614 | O17: 調理端 | P17: 取樣不穩 | R17: 共用類
A18: 7 | B18: 烤黑胡椒洋蔥絲 | C18: 300.3404 | D18: 112.2 | E18: 114.62 | F18: 0 | G18: 141.67 | H18: =(E18+F18)/D18 -> 1.0215686 | I18: 342.8414 | J18: 2.12 | K18: =J18/D18 -> 0.018894831 | L18: =((E18+F18)-D18)-J18 -> 0.3 | M18: =L18/D18 -> 0.0026737968 | N18: =L18*G18 -> 42.501 | O18: 調理端 | P18: 取樣不穩 | R18: 糖燻野郎三十天熟成牛飯
A19: 8 | B19: 熟化去皮馬鈴薯滾刀17-23g | C19: 299.52 | D19: 148.96 | E19: 152.08 | F19: 0 | G19: 96 | H19: =(E19+F19)/D19 -> 1.0209452 | I19: 299.52 | J19: 3.12 | K19: =J19/D19 -> 0.02094522 | L19: =((E19+F19)-D19)-J19 -> 4.4408921e-15 | M19: =L19/D19 -> 2.9812648e-17 | N19: =L19*G19 -> 4.2632564e-13 | O19: 調理端 | P19: 原物料規格 | R19: 嫩烤香料雞胸排蔬滿盒
A20: 9 | B20: (V)川燙小青花菜 | C20: 297.8086 | D20: 802.38 | E20: 798.24 | F20: 12.96 | G20: 147.43 | H20: =(E20+F20)/D20 -> 1.0109923 | I20: 1300.3326 | J20: 2.02 | K20: =J20/D20 -> 0.0025175104 | L20: =((E20+F20)-D20)-J20 -> 6.8 | M20: =L20/D20 -> 0.0084747875 | N20: =L20*G20 -> 1002.524 | O20: 調理端 | P20: 原物料規格 | Q20: 大顆比例高 | R20: 共用類
A21: 10 | B21: 蒜炒洋菇片 | C21: 296.2908 | D21: 46.8 | E21: 48.36 | F21: 0 | G21: 189.93 | H21: =(E21+F21)/D21 -> 1.0333333 | I21: 296.2908 | J21: 1.56 | K21: =J21/D21 -> 0.033333333 | L21: =((E21+F21)-D21)-J21 -> 2.220446e-15 | M21: =L21/D21 -> 4.7445428e-17 | N21: =L21*G21 -> 4.2172932e-13 | O21: 調理端 | P21: 取樣不穩 | R21: 美式雞丁餐盒(113年)
A23: 超用金額前十名半成品
A24: 明細展開 | D24: 生產資訊 | O24: 類別 | P24: 分析原因 (請填寫8大原因) | Q24: 其他原因說明 | R24: 備註-商品名稱
A25: 排序 | B25: 半成品 | D25: 生產端 | J25: 組合端
B26: 名稱 | C26: 超用金額 排序 | D26: 產出量 | J26: 報廢 | M26: 超用
D27: 訂單需求 (kg) | E27: 實際產出 (kg) | F27: 補單 (kg) | G27: 單價 (元) | H27: 實際生產 (對比訂單需求) | I27: 差異 (元) | J27: kg | K27: 占比 | L27: 金額 (元) | M27: kg | N27: 占比
A28: 1 | B28: 切筋子1cm | C28: 3514.8624 | D28: 14.04 | E28: 14.92 | F28: 0.8 | G28: 2092.18 | H28: =(E28+F28)/D28 -> 1.1196581 | I28: 3514.8624 | J28: 0 | K28: =J28/D28 -> 0 | L28: =J28*G28 -> 0 | M28: =((E28+F28)-D28)-J28 -> 1.68 | N28: =M28/D28 -> 0.11965812 | O28: 組合室 | P28: 取樣不穩 | R28: 一配筋子銀鮭飯糰
A29: 2 | B29: 拌鹽烤豬肉片(114年) | C29: 2886.4752 | D29: 376.16 | E29: 383.39 | F29: 3.61 | G29: 266.28 | H29: =(E29+F29)/D29 -> 1.0288175 | I29: 2886.4752 | J29: 0 | K29: =J29/D29 -> 0 | L29: =J29*G29 -> 0 | M29: =((E29+F29)-D29)-J29 -> 10.84 | N29: =M29/D29 -> 0.028817524 | O29: 組合室 | P29: 取樣不穩 | R29: 鹽蔥燒肉飯糰
A30: 3 | B30: 切-烤牛五花(112年) | C30: 2707.8366 | D30: 201.03 | E30: 199.91 | F30: 5.59 | G30: 605.78 | H30: =(E30+F30)/D30 -> 1.0222355 | I30: 2707.8366 | J30: 0 | K30: =J30/D30 -> 0 | L30: =J30*G30 -> 0 | M30: =((E30+F30)-D30)-J30 -> 4.47 | N30: =M30/D30 -> 0.022235487 | O30: 組合室 | P30: 研發設定 | Q30: 雙圈秤重範圍 | R30: 糖燻野郎三十天熟成牛飯
A31: 4 | B31: 碳香燒肉醬 | C31: 2622.4261 | D31: 109.71 | E31: 107.28 | F31: 25.46 | G31: 113.87 | H31: =(E31+F31)/D31 -> 1.2099171 | I31: 2622.4261 | J31: 0 | K31: =J31/D31 -> 0 | L31: =J31*G31 -> 0 | M31: =((E31+F31)-D31)-J31 -> 23.03 | N31: =M31/D31 -> 0.20991705 | O31: 組合室 | P31: 取樣不穩 | R31: 壹號醬雞豚雙拼
A32: 5 | B32: 煮中華冷麵(110年) | C32: 1675.2567 | D32: 5243.67 | E32: 5207.9 | F32: 78.3 | G32: 39.39 | H32: =(E32+F32)/D32 -> 1.0081107 | I32: 1675.2567 | J32: 0 | K32: =J32/D32 -> 0 | L32: =J32*G32 -> 0 | M32: =((E32+F32)-D32)-J32 -> 42.53 | N32: =M32/D32 -> 0.0081107316 | O32: 組合室 | P32: 研發設定 | Q32: 雙圈秤重範圍 | R32: 共用類
A33: 6 | B33: 古早味肉燥（真空包） | C33: 1506.4104 | D33: 32.49 | E33: 32.63 | F33: 3.3 | G33: 437.91 | H33: =(E33+F33)/D33 -> 1.1058787 | I33: 1506.4104 | J33: 0 | K33: =J33/D33 -> 0 | L33: =J33*G33 -> 0 | M33: =((E33+F33)-D33)-J33 -> 3.44 | N33: =M33/D33 -> 0.10587873 | O33: 組合室 | P33: 取樣不穩 | R33: 擔仔炊粉湯
A34: 7 | B34: 鮮食雙色起司絲 | C34: 1488 | D34: 140.57 | E34: 140.78 | F34: 7.23 | G34: 200 | H34: =(E34+F34)/D34 -> 1.0529274 | I34: 1488 | J34: 0 | K34: =J34/D34 -> 0 | L34: =J34*G34 -> 0 | M34: =((E34+F34)-D34)-J34 -> 7.44 | N34: =M34/D34 -> 0.052927367 | O34: 組合室 | P34: 取樣不穩 | R34: 共用類
A35: 8 | B35: 焗飯-奶香白醬(114年) | C35: 1464.7892 | D35: 357.84 | E35: 338.52 | F35: 40.18 | G35: 70.22 | H35: =(E35+F35)/D35 -> 1.0582942 | I35: 1464.7892 | J35: 0 | K35: =J35/D35 -> 0 | L35: =J35*G35 -> 0 | M35: =((E35+F35)-D35)-J35 -> 20.86 | N35: =M35/D35 -> 0.05829421 | O35: 組合室 | P35: 取樣不穩 | R35: 二配哞哞培根奶香海陸焗飯
A36: 9 | B36: 切-究極燒肉片 | C36: 1392.1059 | D36: 51.97 | E36: 50.38 | F36: 3.6 | G36: 692.59 | H36: =(E36+F36)/D36 -> 1.0386762 | I36: 1392.1059 | J36: 0 | K36: =J36/D36 -> 0 | L36: =J36*G36 -> 0 | M36: =((E36+F36)-D36)-J36 -> 2.01 | N36: =M36/D36 -> 0.038676159 | O36: 組合室 | P36: 取樣不穩 | R36: 壹號醬雞豚雙拼
A37: 10 | B37: 歐姆蛋-黑咖哩醬 | C37: 1313.3418 | D37: 359.94 | E37: 358.8 | F37: 21 | G37: 66.13 | H37: =(E37+F37)/D37 -> 1.0551759 | I37: 1313.3418 | J37: 0 | K37: =J37/D37 -> 0 | L37: =J37*G37 -> 0 | M37: =((E37+F37)-D37)-J37 -> 19.86 | N37: =M37/D37 -> 0.055175863 | O37: 組合室 | P37: 取樣不穩 | R37: 二配里肌豬排可可咖哩歐姆蛋飯
A39: 共用類報廢金額前十名半成品
A40: 明細展開
A41: 排序 | B41: 半成品
B42: 名稱 | C42: 報廢金額 排序 | D42: 共用類總金額 占比
A44: 1 | B44: 消毒青蔥絲 | C44: 313.0596 | D44: =C44/$L$5 -> 0.13350231
...

Sheet 0928分析標準表
A1: 大溪廠半成品管理分析
A2: 日期 | C2: 營業額 | D2: 報廢展開 | F2: 超用展開 | H2: 報廢展開 | J2: 超用展開 | L2: 報廢展開
A3: 45928 | C3: 5811925.4 | D3: 總報廢 | F3: 總超用 | H3: 報廢-前10名 | J3: 超用-前10名 | L3: 共用類-總報廢
D4: 金額 | E4: 占比(營業額) | F4: 金額 | G4: 占比(營業額) | H4: 金額 | I4: 占比(總報廢) | J4: 金額 | K4: 占比(總超用) | L4: 金額 | M4: 占比(總報廢)
A5: 年度KPI目標0.25% | D5: 14019.259 | E5: =D5/C3 -> 0.0024121541 | F5: 41276.034 | G5: =F5/C3 -> 0.0071019553 | H5: =SUM(C12:C21) -> 5539.4813 | I5: =H5/D5 -> 0.39513366 | J5: =SUM(C28:C37) -> 16378.96 | K5: =J5/F5 -> 0.39681525 | L5: 3326.6535 | M5: =L5/D5 -> 0.23729167
A7: 報廢金額前十名半成品
A8: 明細展開 | D8: 生產資訊 | O8: 類別 | P8: 分析原因 (請填寫8大原因) | Q8: 其他原因說明 | R8: 備註-商品名稱
A9: 排序 | B9: 半成品 | D9: 生產端 | J9: 組合端
B10: 名稱 | C10: 報廢金額 排序 | D10: 產出量 | J10: 報廢 | L10: 超用
D11: 訂單需求 (kg) | E11: 實際產出 (kg) | F11: 補單 (kg) | G11: 單價 (元) | H11: 實際生產 (對比訂單需求) | I11: 差異 (元) | J11: kg | K11: 占比 | L11: kg | M11: 占比 | N11: 金額 (元)
A12: 1 | B12: 奶油蕈菇起司醬(113年) | C12: 868.301 | D12: 146.45 | E12: 154.06 | F12: 0 | G12: 114.1 | H12: =(E12+F12)/D12 -> 1.0519631 | I12: 868.301 | J12: 7.61 | K12: =J12/D12 -> 0.051963127 | L12: =((E12+F12)-D12)-J12 -> 1.3322676e-14 | M12: =L12/D12 -> 9.0970818e-17 | N12: =L12*G12 -> 1.5201174e-12 | O12: 調理端 | P12: 展開量105% | R12: 大口法式蕈菇起司雞排飯糰(113年)
A13: 2 | B13: 消毒細切紅蘿蔔絲 | C13: 774.9728 | D13: 272.03 | E13: 280.27 | F13: 0 | G13: 95.44 | H13: =(E13+F13)/D13 -> 1.0302908 | I13: 786.4256 | J13: 8.12 | K13: =J13/D13 -> 0.029849649 | L13: =((E13+F13)-D13)-J13 -> 0.12 | M13: =L13/D13 -> 0.00044112782 | N13: =L13*G13 -> 11.4528 | O13: 調理端 | P13: 取樣不穩 | R13: 共用類
A14: 3 | B14: 消毒青蔥絲 | C14: 723.0186 | D14: 40.18 | E14: 43.09 | F14: 0 | G14: 248.46 | H14: =(E14+F14)/D14 -> 1.0724241 | I14: 723.0186 | J14: 2.91 | K14: =J14/D14 -> 0.072424092 | L14: =((E14+F14)-D14)-J14 -> -3.5527137e-15 | M14: =L14/D14 -> -8.8419952e-17 | N14: =L14*G14 -> -8.8270724e-13 | O14: 調理端 | P14: 展開量105% | R14: 共用類
A15: 4 | B15: 烤銀鮭魚肚 | C15: 710.7 | D15: 2471 | E15: 2517 | F15: 0 | G15: 15.45 | H15: =(E15+F15)/D15 -> 1.0186159 | I15: 710.7 | J15: 46 | K15: =J15/D15 -> 0.018615945 | L15: =((E15+F15)-D15)-J15 -> 0 | M15: =L15/D15 -> 0 | N15: =L15*G15 -> 0 | O15: 調理端 | P15: 研發設定 | Q15: 研發設定，小片的規格不符合指示書設定重量 | R15: 一配贅沢鮭魚肚飯糰
A16: 5 | B16: 熟化去皮馬鈴薯滾刀17-23g | C16: 580.8 | D16: 91.24 | E16: 97.29 | F16: 0 | G16: 96 | H16: =(E16+F16)/D16 -> 1.0663086 | I16: 580.8 | J16: 6.05 | K16: =J16/D16 -> 0.066308637 | L16: =((E16+F16)-D16)-J16 -> 0 | M16: =L16/D16 -> 0 | N16: =L16*G16 -> 0 | O16: 調理端 | P16: 原物料規格 | R16: 嫩烤香料雞胸排蔬滿盒
A17: 6 | B17: 切-究極燒肉片 | C17: 464.0353 | D17: 39.19 | E17: 38.49 | F17: 3.6 | G17: 692.59 | H17: =(E17+F17)/D17 -> 1.0739985 | I17: 2008.511 | J17: 0.67 | K17: =J17/D17 -> 0.017096198 | L17: =((E17+F17)-D17)-J17 -> 2.23 | M17: =L17/D17 -> 0.056902271 | N17: =L17*G17 -> 1544.4757 | O17: 調理端 | P17: 展開量105% | R17: 壹號醬雞豚雙拼
A18: 7 | B18: (V)炒素雞肉絲(114年) | C18: 446.661 | D18: 11 | E18: 11.9 | F18: 0 | G18: 496.29 | H18: =(E18+F18)/D18 -> 1.0818182 | I18: 446.661 | J18: 0.9 | K18: =J18/D18 -> 0.081818182 | L18: =((E18+F18)-D18)-J18 -> 0 | M18: =L18/D18 -> 0 | N18: =L18*G18 -> 0 | O18: 調理端 | P18: 展開量105% | R18: 二配油蔥G絲飯糰
A19: 8 | B19: 消毒蔥花 | C19: 359.0248 | D19: 25.53 | E19: 27.19 | F19: 0 | G19: 216.28 | H19: =(E19+F19)/D19 -> 1.0650215 | I19: 359.0248 | J19: 1.66 | K19: =J19/D19 -> 0.065021543 | L19: =((E19+F19)-D19)-J19 -> 0 | M19: =L19/D19 -> 0 | N19: =L19*G19 -> 0 | O19: 調理端 | P19: 展開量105% | R19: 共用類
A20: 9 | B20: 炸馬鈴薯塊 | C20: 351.5534 | D20: 47.65 | E20: 49.64 | F20: 0 | G20: 176.66 | H20: =(E20+F20)/D20 -> 1.0417629 | I20: 351.5534 | J20: 1.99 | K20: =J20/D20 -> 0.041762854 | L20: =((E20+F20)-D20)-J20 -> 1.9984014e-15 | M20: =L20/D20 -> 4.193917e-17 | N20: =L20*G20 -> 3.530376e-13 | O20: 調理端 | P20: 取樣不穩 | R20: 妮妮家漢堡排
A21: 10 | B21: 113年川燙綠豆芽 | C21: 260.4144 | D21: 48.52 | E21: 47.53 | F21: 3.38 | G21: 108.96 | H21: =(E21+F21)/D21 -> 1.049258 | I21: 260.4144 | J21: 2.39 | K21: =J21/D21 -> 0.049258038 | L21: =((E21+F21)-D21)-J21 -> 7.5495166e-15 | M21: =L21/D21 -> 1.5559597e-16 | N21: =L21*G21 -> 8.2259533e-13 | O21: 調理端 | P21: 取樣不穩 | R21: 越式牛肉寬粉
A23: 超用金額前十名半成品
A24: 明細展開 | D24: 生產資訊 | O24: 類別 | P24: 分析原因 (請填寫8大原因) | Q24: 其他原因說明 | R24: 備註-商品名稱
A25: 排序 | B25: 半成品 | D25: 生產端 | J25: 組合端
B26: 名稱 | C26: 超用金額 排序 | D26: 產出量 | J26: 報廢 | M26: 超用
D27: 訂單需求 (kg) | E27: 實際產出 (kg) | F27: 補單 (kg) | G27: 單價 (元) | H27: 實際生產 (對比訂單需求) | I27: 差異 (元) | J27: kg | K27: 占比 | L27: 金額 (元) | M27: kg | N27: 占比
A28: 1 | B28: (V)川燙小青花菜 | C28: 2394.2632 | D28: 531.09 | E28: 531.51 | F28: 15.82 | G28: 147.43 | H28: =(E28+F28)/D28 -> 1.0305786 | I28: 2394.2632 | J28: 0 | K28: =J28/D28 -> 0 | L28: =J28*G28 -> 0 | M28: =((E28+F28)-D28)-J28 -> 16.24 | N28: =M28/D28 -> 0.030578621 | O28: 組合室 | P28: 原物料規格 | Q28: 大顆比例高 | R28: 共用類
A29: 2 | B29: 切-烤牛五花(112年) | C29: 1859.7446 | D29: 168.34 | E29: 164.53 | F29: 6.88 | G29: 605.78 | H29: =(E29+F29)/D29 -> 1.0182369 | I29: 1859.7446 | J29: 0 | K29: =J29/D29 -> 0 | L29: =J29*G29 -> 0 | M29: =((E29+F29)-D29)-J29 -> 3.07 | N29: =M29/D29 -> 0.018236902 | O29: 組合室 | P29: 研發設定 | Q29: 雙圈秤重範圍 | R29: 糖燻野郎三十天熟成牛飯
A30: 3 | B30: 蒸-醬香雞肉絲CL | C30: 1811.1632 | D30: 120.52 | E30: 120.99 | F30: 4.41 | G30: 371.14 | H30: =(E30+F30)/D30 -> 1.0404912 | I30: 1811.1632 | J30: 0 | K30: =J30/D30 -> 0 | L30: =J30*G30 -> 0 | M30: =((E30+F30)-D30)-J30 -> 4.88 | N30: =M30/D30 -> 0.040491205 | O30: 組合室 | P30: 取樣不穩 | R30: 共用類
A31: 4 | B31: 切筋子1cm | C31: 1694.6658 | D31: 8.37 | E31: 7.98 | F31: 1.2 | G31: 2092.18 | H31: =(E31+F31)/D31 -> 1.0967742 | I31: 1694.6658 | J31: 0 | K31: =J31/D31 -> 0 | L31: =J31*G31 -> 0 | M31: =((E31+F31)-D31)-J31 -> 0.81 | N31: =M31/D31 -> 0.096774194 | O31: 組合室 | P31: 取樣不穩 | R31: 一配筋子銀鮭飯糰
A32: 5 | B32: 煮中華冷麵(110年) | C32: 1672.8933 | D32: 4725.93 | E32: 4706.3 | F32: 62.1 | G32: 39.39 | H32: =(E32+F32)/D32 -> 1.0089866 | I32: 1672.8933 | J32: 0 | K32: =J32/D32 -> 0 | L32: =J32*G32 -> 0 | M32: =((E32+F32)-D32)-J32 -> 42.47 | N32: =M32/D32 -> 0.008986591 | O32: 組合室 | P32: 取樣不穩 | R32: 共用類
A33: 6 | B33: 切-究極燒肉片 | C33: 1544.4757 | D33: 39.19 | E33: 38.49 | F33: 3.6 | G33: 692.59 | H33: =(E33+F33)/D33 -> 1.0739985 | I33: 2008.511 | J33: 0.67 | K33: =J33/D33 -> 0.017096198 | L33: =J33*G33 -> 464.0353 | M33: =((E33+F33)-D33)-J33 -> 2.23 | N33: =M33/D33 -> 0.056902271 | O33: 組合室 | P33: 取樣不穩 | R33: 壹號醬雞豚雙拼
A34: 7 | B34: 蘑菇湯凍 | C34: 1490.7402 | D34: 256.32 | E34: 246.09 | F34: 24 | G34: 108.26 | H34: =(E34+F34)/D34 -> 1.0537219 | I34: 1490.7402 | J34: 0 | K34: =J34/D34 -> 0 | L34: =J34*G34 -> 0 | M34: =((E34+F34)-D34)-J34 -> 13.77 | N34: =M34/D34 -> 0.05372191 | O34: 組合室 | P34: 取樣不穩 | R34: 二配鐵板蘑菇肉醬起司焗飯
A35: 8 | B35: 煮牛肉片(A7) | C35: 1402.4918 | D35: 41.59 | E35: 41.93 | F35: 1.8 | G35: 655.37 | H35: =(E35+F35)/D35 -> 1.0514547 | I35: 1402.4918 | J35: 0 | K35: =J35/D35 -> 0 | L35: =J35*G35 -> 0 | M35: =((E35+F35)-D35)-J35 -> 2.14 | N35: =M35/D35 -> 0.051454677 | O35: 組合室 | P35: 取樣不穩 | R35: 越式牛肉寬粉
A36: 9 | B36: 蒸金沙醬 | C36: 1316.13 | D36: 14.82 | E36: 15.82 | F36: 0 | G36: 1316.13 | H36: =(E36+F36)/D36 -> 1.0674764 | I36: 1316.13 | J36: 0 | K36: =J36/D36 -> 0 | L36: =J36*G36 -> 0 | M36: =((E36+F36)-D36)-J36 -> 1 | N36: =M36/D36 -> 0.067476383 | O36: 組合室 | P36: 取樣不穩 | R36: 金沙豆腐細扁麵
A37: 10 | B37: 切-鹽烤牛肉 | C37: 1192.392 | D37: 47.98 | E37: 48.4 | F37: 1.38 | G37: 662.44 | H37: =(E37+F37)/D37 -> 1.0375156 | I37: 1192.392 | J37: 0 | K37: =J37/D37 -> 0 | L37: =J37*G37 -> 0 | M37: =((E37+F37)-D37)-J37 -> 1.8 | N37: =M37/D37 -> 0.037515632 | O37: 組合室 | P37: 取樣不穩 | R37: 共用類
A39: 共用類報廢金額前十名半成品
A40: 明細展開
A41: 排序 | B41: 半成品
B42: 名稱 | C42: 報廢金額 排序 | D42: 共用類總金額 占比
A44: 1 | B44: 消毒細切紅蘿蔔絲 | C44: 774.9728 | D44: =C44/$L$5 -> 0.23295868
...

Sheet 0927分析標準表
A1: 大溪廠半成品管理分析
A2: 日期 | C2: 營業額 | D2: 報廢展開 | F2: 超用展開 | H2: 報廢展開 | J2: 超用展開 | L2: 報廢展開
A3: 45927 | C3: 5183430.2 | D3: 總報廢 | F3: 總超用 | H3: 報廢-前10名 | J3: 超用-前10名 | L3: 共用類-總報廢
D4: 金額 | E4: 占比(營業額) | F4: 金額 | G4: 占比(營業額) | H4: 金額 | I4: 占比(總報廢) | J4: 金額 | K4: 占比(總超用) | L4: 金額 | M4: 占比(總報廢)
A5: 年度KPI目標0.25% | D5: 12493.837 | E5: =D5/C3 -> 0.0024103416 | F5: 36775.807 | G5: =F5/C3 -> 0.0070948784 | H5: =SUM(C12:C21) -> 3846.5122 | I5: =H5/D5 -> 0.30787276 | J5: =SUM(C28:C37) -> 17045.617 | K5: =J5/F5 -> 0.46350081 | L5: 2265.2746 | M5: =L5/D5 -> 0.18131136
A7: 報廢金額前十名半成品
A8: 明細展開 | D8: 生產資訊 | O8: 類別 | P8: 分析原因 (請填寫8大原因) | Q8: 其他原因說明 | R8: 備註-商品名稱
A9: 排序 | B9: 半成品 | D9: 生產端 | J9: 組合端
B10: 名稱 | C10: 報廢金額 排序 | D10: 產出量 | J10: 報廢 | L10: 超用
D11: 訂單需求 (kg) | E11: 實際產出 (kg) | F11: 補單 (kg) | G11: 單價 (元) | H11: 實際生產 (對比訂單需求) | I11: 差異 (元) | J11: kg | K11: 占比 | L11: kg | M11: 占比 | N11: 金額 (元)
A12: 1 | B12: 鹽麴銀鮭熟肉 | C12: 839.5 | D12: 7.97 | E12: 9.12 | F12: 0 | G12: 730 | H12: =(E12+F12)/D12 -> 1.1442911 | I12: 839.5 | J12: 1.15 | K12: =J12/D12 -> 0.14429109 | L12: =((E12+F12)-D12)-J12 -> 0 | M12: =L12/D12 -> 0 | N12: =L12*G12 -> 0 | O12: 調理端 | P12: 展開量105% | R12: 一配筋子銀鮭飯糰
A13: 2 | B13: 烤銀鮭魚肚 | C13: 463.5 | D13: 2361 | E13: 2391 | F13: 0 | G13: 15.45 | H13: =(E13+F13)/D13 -> 1.0127065 | I13: 463.5 | J13: 30 | K13: =J13/D13 -> 0.01270648 | L13: =((E13+F13)-D13)-J13 -> 0 | M13: =L13/D13 -> 0 | N13: =L13*G13 -> 0 | O13: 調理端 | P13: 研發設定 | Q13: 研發設定，小片的規格不符合指示書設定重量 | R13: 一配贅沢鮭魚肚飯糰
A14: 3 | B14: 烤黑胡椒洋蔥絲 | C14: 355.5917 | D14: 83.54 | E14: 87.02 | F14: 0 | G14: 141.67 | H14: =(E14+F14)/D14 -> 1.0416567 | I14: 493.0116 | J14: 2.51 | K14: =J14/D14 -> 0.030045487 | L14: =((E14+F14)-D14)-J14 -> 0.97 | M14: =L14/D14 -> 0.011611204 | N14: =L14*G14 -> 137.4199 | O14: 調理端 | P14: 取樣不穩 | R14: 糖燻野郎三十天熟成牛飯
A15: 4 | B15: 清炒高麗菜 | C15: 337.755 | D15: 115.11 | E15: 121.57 | F15: 0 | G15: 122.82 | H15: =(E15+F15)/D15 -> 1.0561202 | I15: 793.4172 | J15: 2.75 | K15: =J15/D15 -> 0.023890192 | L15: =((E15+F15)-D15)-J15 -> 3.71 | M15: =L15/D15 -> 0.032230041 | N15: =L15*G15 -> 455.6622 | O15: 調理端 | P15: 展開量105% | R15: 美式雞丁餐盒(113年)
A16: 5 | B16: (V)川燙小青花菜 | C16: 324.346 | D16: 449.78 | E16: 450.23 | F16: 5.92 | G16: 147.43 | H16: =(E16+F16)/D16 -> 1.0141625 | I16: 939.1291 | J16: 2.2 | K16: =J16/D16 -> 0.0048912802 | L16: =((E16+F16)-D16)-J16 -> 4.17 | M16: =L16/D16 -> 0.0092711993 | N16: =L16*G16 -> 614.7831 | O16: 調理端 | P16: 原物料規格 | Q16: 大顆比例高 | R16: 共用類
A17: 6 | B17: 妮妮-烤漢堡排肉 | C17: 318.9 | D17: 2854 | E17: 2844 | F17: 40 | G17: 10.63 | H17: =(E17+F17)/D17 -> 1.0105116 | I17: 318.9 | J17: 30 | K17: =J17/D17 -> 0.010511563 | L17: =((E17+F17)-D17)-J17 -> 0 | M17: =L17/D17 -> 0 | N17: =L17*G17 -> 0 | O17: 調理端 | P17: 取樣不穩 | R17: 妮妮家漢堡排
A18: 7 | B18: 煮紅蘿蔔塊(VN101) | C18: 310.9827 | D18: 73.21 | E18: 76.02 | F18: 0 | G18: 110.67 | H18: =(E18+F18)/D18 -> 1.0383827 | I18: 310.9827 | J18: 2.81 | K18: =J18/D18 -> 0.038382735 | L18: =((E18+F18)-D18)-J18 -> 0 | M18: =L18/D18 -> 0 | N18: =L18*G18 -> 0 | O18: 調理端 | P18: 取樣不穩 | R18: 健身G肉餐盒(113年)
A19: 8 | B19: 蒜炒紅k高麗菜(111年) | C19: 304.2592 | D19: 339.26 | E19: 332.84 | F19: 13.5 | G19: 127.84 | H19: =(E19+F19)/D19 -> 1.020869 | I19: 905.1072 | J19: 2.38 | K19: =J19/D19 -> 0.0070152685 | L19: =((E19+F19)-D19)-J19 -> 4.7 | M19: =L19/D19 -> 0.013853682 | N19: =L19*G19 -> 600.848 | O19: 調理端 | P19: 取樣不穩 | R19: 共用類
A20: 9 | B20: 川燙毛豆玉米 | C20: 296.7956 | D20: 186.62 | E20: 186.04 | F20: 3.36 | G20: 157.87 | H20: =(E20+F20)/D20 -> 1.0148966 | I20: 438.8786 | J20: 1.88 | K20: =J20/D20 -> 0.010073947 | L20: =((E20+F20)-D20)-J20 -> 0.9 | M20: =L20/D20 -> 0.0048226342 | N20: =L20*G20 -> 142.083 | O20: 調理端 | P20: 取樣不穩 | R20: 共用類
A21: 10 | B21: 川燙韭菜綠豆芽A7 | C21: 294.882 | D21: 24.49 | E21: 21.54 | F21: 5.4 | G21: 120.36 | H21: =(E21+F21)/D21 -> 1.1000408 | I21: 294.882 | J21: 2.45 | K21: =J21/D21 -> 0.10004083 | L21: =((E21+F21)-D21)-J21 -> 0 | M21: =L21/D21 -> 0 | N21: =L21*G21 -> 0 | O21: 調理端 | P21: 展開量105% | R21: 擔仔炊粉湯
A23: 超用金額前十名半成品
A24: 明細展開 | D24: 生產資訊 | O24: 類別 | P24: 分析原因 (請填寫8大原因) | Q24: 其他原因說明 | R24: 備註-商品名稱
A25: 排序 | B25: 半成品 | D25: 生產端 | J25: 組合端
B26: 名稱 | C26: 超用金額 排序 | D26: 產出量 | J26: 報廢 | M26: 超用
D27: 訂單需求 (kg) | E27: 實際產出 (kg) | F27: 補單 (kg) | G27: 單價 (元) | H27: 實際生產 (對比訂單需求) | I27: 差異 (元) | J27: kg | K27: 占比 | L27: 金額 (元) | M27: kg | N27: 占比
A28: 1 | B28: 蒸-全熟雞肉絲CL(113年) | C28: 3823.1424 | D28: 152.06 | E28: 158.42 | F28: 2.6 | G28: 426.69 | H28: =(E28+F28)/D28 -> 1.0589241 | I28: 3823.1424 | J28: 0 | K28: =J28/D28 -> 0 | L28: =J28*G28 -> 0 | M28: =((E28+F28)-D28)-J28 -> 8.96 | N28: =M28/D28 -> 0.058924109 | O28: 組合室 | P28: 取樣不穩 | R28: 雞肉飯飯糰
A29: 2 | B29: 切-烤牛五花(112年) | C29: 2980.4376 | D29: 149.68 | E29: 151.16 | F29: 3.44 | G29: 605.78 | H29: =(E29+F29)/D29 -> 1.0328701 | I29: 2980.4376 | J29: 0 | K29: =J29/D29 -> 0 | L29: =J29*G29 -> 0 | M29: =((E29+F29)-D29)-J29 -> 4.92 | N29: =M29/D29 -> 0.032870123 | O29: 組合室 | P29: 研發設定 | Q29: 雙圈秤重範圍 | R29: 糖燻野郎三十天熟成牛飯
A30: 3 | B30: 炙燒韓式牛五花 | C30: 2126.02 | D30: 36.84 | E30: 38.09 | F30: 2.56 | G30: 629 | H30: =(E30+F30)/D30 -> 1.1034202 | I30: 2396.49 | J30: 0.43 | K30: =J30/D30 -> 0.011672096 | L30: =J30*G30 -> 270.47 | M30: =((E30+F30)-D30)-J30 -> 3.38 | N30: =M30/D30 -> 0.0917481 | O30: 組合室 | P30: 取樣不穩 | R30: 壹號醬炙烤牛飯糰
A31: 4 | B31: 分切炙燒炭火燒肉片(主食) | C31: 1729.64 | D31: 52.78 | E31: 52.87 | F31: 2.66 | G31: 628.96 | H31: =(E31+F31)/D31 -> 1.0521031 | I31: 1729.64 | J31: 0 | K31: =J31/D31 -> 0 | L31: =J31*G31 -> 0 | M31: =((E31+F31)-D31)-J31 -> 2.75 | N31: =M31/D31 -> 0.052103069 | O31: 組合室 | P31: 研發設定 | Q31: 雙圈秤重範圍 | R31: 蒜蒜燒豚飯
A32: 5 | B32: 煮中華冷麵(110年) | C32: 1204.1523 | D32: 3409.53 | E32: 3393 | F32: 47.1 | G32: 39.39 | H32: =(E32+F32)/D32 -> 1.008966 | I32: 1204.1523 | J32: 0 | K32: =J32/D32 -> 0 | L32: =J32*G32 -> 0 | M32: =((E32+F32)-D32)-J32 -> 30.57 | N32: =M32/D32 -> 0.0089660452 | O32: 組合室 | P32: 取樣不穩 | R32: 共用類
A33: 6 | B33: 川燙白蝦仁6號 | C33: 1186.636 | D33: 1113 | E33: 982.69 | F33: 400 | G33: 4.4 | H33: =(E33+F33)/D33 -> 1.2423091 | I33: 1186.636 | J33: 0 | K33: =J33/D33 -> 0 | L33: =J33*G33 -> 0 | M33: =((E33+F33)-D33)-J33 -> 269.69 | N33: =M33/D33 -> 0.24230907 | O33: 組合室 | P33: 取樣不穩 | R33: 擔仔炊粉湯
A34: 7 | B34: 鮮食雙色起司絲 | C34: 1052 | D34: 108.52 | E34: 108.65 | F34: 5.35 | G34: 200 | H34: =(E34+F34)/D34 -> 1.0504976 | I34: 1096 | J34: 0.22 | K34: =J34/D34 -> 0.0020272761 | L34: =J34*G34 -> 44 | M34: =((E34+F34)-D34)-J34 -> 5.26 | N34: =M34/D34 -> 0.048470328 | O34: 組合室 | P34: 取樣不穩 | R34: 共用類
A35: 8 | B35: 歐姆蛋-黑咖哩醬 | C35: 1004.5147 | D35: 283.5 | E35: 277.69 | F35: 21 | G35: 66.13 | H35: =(E35+F35)/D35 -> 1.0535802 | I35: 1004.5147 | J35: 0 | K35: =J35/D35 -> 0 | L35: =J35*G35 -> 0 | M35: =((E35+F35)-D35)-J35 -> 15.19 | N35: =M35/D35 -> 0.053580247 | O35: 組合室 | P35: 取樣不穩 | R35: 二配里肌豬排可可咖哩歐姆蛋飯
A36: 9 | B36: 煮牛肉片(A7) | C36: 1002.7161 | D36: 41.69 | E36: 40.22 | F36: 3 | G36: 655.37 | H36: =(E36+F36)/D36 -> 1.0366994 | I36: 1002.7161 | J36: 0 | K36: =J36/D36 -> 0 | L36: =J36*G36 -> 0 | M36: =((E36+F36)-D36)-J36 -> 1.53 | N36: =M36/D36 -> 0.036699448 | O36: 組合室 | P36: 取樣不穩 | R36: 越式牛肉寬粉
A37: 10 | B37: 炒油蔥醬 | C37: 936.3575 | D37: 123.56 | E37: 129.04 | F37: 0.65 | G37: 152.75 | H37: =(E37+F37)/D37 -> 1.0496115 | I37: 936.3575 | J37: 0 | K37: =J37/D37 -> 0 | L37: =J37*G37 -> 0 | M37: =((E37+F37)-D37)-J37 -> 6.13 | N37: =M37/D37 -> 0.049611525 | O37: 組合室 | P37: 取樣不穩 | R37: 雞肉飯飯糰
A39: 共用類報廢金額前十名半成品
A40: 明細展開
A41: 排序 | B41: 半成品
B42: 名稱 | C42: 報廢金額 排序 | D42: 共用類總金額 占比
A44: 1 | B44: (V)川燙小青花菜 | C44: 324.346 | D44: =C44/$L$5 -> 0.14318176
...

Sheet 0926分析標準表
A1: 大溪廠半成品管理分析
A2: 日期 | C2: 營業額 | D2: 報廢展開 | F2: 超用展開 | H2: 報廢展開 | J2: 超用展開 | L2: 報廢展開
A3: 45926 | C3: 5226513.3 | D3: 總報廢 | F3: 總超用 | H3: 報廢-前10名 | J3: 超用-前10名 | L3: 共用類-總報廢
D4: 金額 | E4: 占比(營業額) | F4: 金額 | G4: 占比(營業額) | H4: 金額 | I4: 占比(總報廢) | J4: 金額 | K4: 占比(總超用) | L4: 金額 | M4: 占比(總報廢)
A5: 年度KPI目標0.25% | D5: 12595.986 | E5: =D5/C3 -> 0.002410017 | F5: 37138 | G5: =F5/C3 -> 0.0071056933 | H5: =SUM(C12:C21) -> 3258.012 | I5: =H5/D5 -> 0.25865479 | J5: =SUM(C28:C37) -> 18684.236 | K5: =J5/F5 -> 0.5031029 | L5: 2389.5566 | M5: =L5/D5 -> 0.18970779
A7: 報廢金額前十名半成品
A8: 明細展開 | D8: 生產資訊 | O8: 類別 | P8: 分析原因 (請填寫8大原因) | Q8: 其他原因說明 | R8: 備註-商品名稱
A9: 排序 | B9: 半成品 | D9: 生產端 | J9: 組合端
B10: 名稱 | C10: 報廢金額 排序 | D10: 產出量 | J10: 報廢 | L10: 超用
D11: 訂單需求 (kg) | E11: 實際產出 (kg) | F11: 補單 (kg) | G11: 單價 (元) | H11: 實際生產 (對比訂單需求) | I11: 差異 (元) | J11: kg | K11: 占比 | L11: kg | M11: 占比 | N11: 金額 (元)
A12: 1 | B12: 烤銀鮭魚肚 | C12: 556.2 | D12: 2503 | E12: 2539 | F12: 0 | G12: 15.45 | H12: =(E12+F12)/D12 -> 1.0143827 | I12: 556.2 | J12: 36 | K12: =J12/D12 -> 0.014382741 | L12: =((E12+F12)-D12)-J12 -> 0 | M12: =L12/D12 -> 0 | N12: =L12*G12 -> 0 | O12: 調理端 | P12: 研發設定 | Q12: 研發設定，小片的規格不符合指示書設定重量 | R12: 一配贅沢鮭魚肚飯糰
A13: 2 | B13: (V)消毒小黃瓜絲 | C13: 330.144 | D13: 185.72 | E13: 188 | F13: 0 | G13: 144.8 | H13: =(E13+F13)/D13 -> 1.0122765 | I13: 330.144 | J13: 2.28 | K13: =J13/D13 -> 0.012276545 | L13: =((E13+F13)-D13)-J13 -> 0 | M13: =L13/D13 -> 0 | N13: =L13*G13 -> 0 | O13: 調理端 | P13: 取樣不穩 | R13: 共用類
A14: 3 | B14: 炒洋菇片(烘焙油) | C14: 306.9154 | D14: 22.56 | E14: 23.78 | F14: 0 | G14: 251.57 | H14: =(E14+F14)/D14 -> 1.054078 | I14: 306.9154 | J14: 1.22 | K14: =J14/D14 -> 0.054078014 | L14: =((E14+F14)-D14)-J14 -> 2.4424907e-15 | M14: =L14/D14 -> 1.0826643e-16 | N14: =L14*G14 -> 6.1445737e-13 | O14: 調理端 | P14: 展開量105% | R14: 二配鐵板蘑菇肉醬起司焗飯
A15: 4 | B15: 113年川燙綠豆芽 | C15: 305.088 | D15: 45.39 | E15: 48.19 | F15: 0 | G15: 108.96 | H15: =(E15+F15)/D15 -> 1.0616876 | I15: 305.088 | J15: 2.8 | K15: =J15/D15 -> 0.061687596 | L15: =((E15+F15)-D15)-J15 -> 0 | M15: =L15/D15 -> 0 | N15: =L15*G15 -> 0 | O15: 調理端 | P15: 展開量105% | R15: 越式牛肉寬粉
A16: 5 | B16: 清炒高麗菜 | C16: 299.6808 | D16: 120.11 | E16: 122.55 | F16: 0 | G16: 122.82 | H16: =(E16+F16)/D16 -> 1.0203147 | I16: 299.6808 | J16: 2.44 | K16: =J16/D16 -> 0.020314712 | L16: =((E16+F16)-D16)-J16 -> 0 | M16: =L16/D16 -> 0 | N16: =L16*G16 -> 0 | O16: 調理端 | P16: 取樣不穩 | R16: 美式雞丁餐盒(113年)
A17: 6 | B17: 蒸-醬香雞肉絲CL | C17: 296.912 | D17: 81.78 | E17: 81.83 | F17: 2.1 | G17: 371.14 | H17: =(E17+F17)/D17 -> 1.02629 | I17: 797.951 | J17: 0.8 | K17: =J17/D17 -> 0.0097823429 | L17: =((E17+F17)-D17)-J17 -> 1.35 | M17: =L17/D17 -> 0.016507704 | N17: =L17*G17 -> 501.039 | O17: 調理端 | P17: 取樣不穩 | R17: 共用類
A18: 7 | B18: 奶油蕈菇起司醬(113年) | C18: 296.66 | D18: 122.72 | E18: 125.32 | F18: 0 | G18: 114.1 | H18: =(E18+F18)/D18 -> 1.0211864 | I18: 296.66 | J18: 2.6 | K18: =J18/D18 -> 0.021186441 | L18: =((E18+F18)-D18)-J18 -> -5.7731597e-15 | M18: =L18/D18 -> -4.7043349e-17 | N18: =L18*G18 -> -6.5871752e-13 | O18: 調理端 | P18: 取樣不穩 | R18: 大口法式蕈菇起司雞排飯糰(113年)
A19: 8 | B19: 炒紅K高麗菜(飯糰) | C19: 296.583 | D19: 31.2 | E19: 34.1 | F19: 0 | G19: 102.27 | H19: =(E19+F19)/D19 -> 1.0929487 | I19: 296.583 | J19: 2.9 | K19: =J19/D19 -> 0.092948718 | L19: =((E19+F19)-D19)-J19 -> -4.8849813e-15 | M19: =L19/D19 -> -1.5656991e-16 | N19: =L19*G19 -> -4.9958704e-13 | O19: 調理端 | P19: 展開量105% | R19: 大口蒜味香腸燒肉雙拼飯糰
A20: 9 | B20: 消毒細切紅蘿蔔絲 | C20: 293.0008 | D20: 189.15 | E20: 188.41 | F20: 11.2 | G20: 95.44 | H20: =(E20+F20)/D20 -> 1.0553 | I20: 998.3024 | J20: 3.07 | K20: =J20/D20 -> 0.016230505 | L20: =((E20+F20)-D20)-J20 -> 7.39 | M20: =L20/D20 -> 0.039069522 | N20: =L20*G20 -> 705.3016 | O20: 調理端 | P20: 展開量105% | R20: 共用類
A21: 10 | B21: 川燙韭菜綠豆芽A7 | C21: 276.828 | D21: 23.94 | E21: 23.92 | F21: 2.32 | G21: 120.36 | H21: =(E21+F21)/D21 -> 1.0960735 | I21: 276.828 | J21: 2.3 | K21: =J21/D21 -> 0.096073517 | L21: =((E21+F21)-D21)-J21 -> 0 | M21: =L21/D21 -> 0 | N21: =L21*G21 -> 0 | O21: 調理端 | P21: 展開量105% | R21: 擔仔炊粉湯
A23: 超用金額前十名半成品
A24: 明細展開 | D24: 生產資訊 | O24: 類別 | P24: 分析原因 (請填寫8大原因) | Q24: 其他原因說明 | R24: 備註-商品名稱
A25: 排序 | B25: 半成品 | D25: 生產端 | J25: 組合端
B26: 名稱 | C26: 超用金額 排序 | D26: 產出量 | J26: 報廢 | M26: 超用
D27: 訂單需求 (kg) | E27: 實際產出 (kg) | F27: 補單 (kg) | G27: 單價 (元) | H27: 實際生產 (對比訂單需求) | I27: 差異 (元) | J27: kg | K27: 占比 | L27: 金額 (元) | M27: kg | N27: 占比
A28: 1 | B28: 蒸-全熟雞肉絲CL(113年) | C28: 3515.9256 | D28: 159.24 | E28: 165.4 | F28: 2.08 | G28: 426.69 | H28: =(E28+F28)/D28 -> 1.0517458 | I28: 3515.9256 | J28: 0 | K28: =J28/D28 -> 0 | L28: =J28*G28 -> 0 | M28: =((E28+F28)-D28)-J28 -> 8.24 | N28: =M28/D28 -> 0.051745793 | O28: 組合室 | P28: 取樣不穩 | R28: 雞肉飯飯糰
A29: 2 | B29: 切-烤牛五花(112年) | C29: 3053.1312 | D29: 150.54 | E29: 151.48 | F29: 4.1 | G29: 605.78 | H29: =(E29+F29)/D29 -> 1.0334795 | I29: 3053.1312 | J29: 0 | K29: =J29/D29 -> 0 | L29: =J29*G29 -> 0 | M29: =((E29+F29)-D29)-J29 -> 5.04 | N29: =M29/D29 -> 0.033479474 | O29: 組合室 | P29: 研發設定 | Q29: 雙圈秤重範圍 | R29: 糖燻野郎三十天熟成牛飯
A30: 3 | B30: 炙燒韓式牛五花 | C30: 2490.84 | D30: 37.2 | E30: 39.96 | F30: 1.2 | G30: 629 | H30: =(E30+F30)/D30 -> 1.1064516 | I30: 2490.84 | J30: 0 | K30: =J30/D30 -> 0 | L30: =J30*G30 -> 0 | M30: =((E30+F30)-D30)-J30 -> 3.96 | N30: =M30/D30 -> 0.10645161 | O30: 組合室 | P30: 取樣不穩 | R30: 壹號醬炙烤牛飯糰
A31: 4 | B31: 蘑菇湯凍 | C31: 2043.9488 | D31: 240.64 | E31: 236.32 | F31: 23.2 | G31: 108.26 | H31: =(E31+F31)/D31 -> 1.0784574 | I31: 2043.9488 | J31: 0 | K31: =J31/D31 -> 0 | L31: =J31*G31 -> 0 | M31: =((E31+F31)-D31)-J31 -> 18.88 | N31: =M31/D31 -> 0.078457447 | O31: 組合室 | P31: 研發設定 | Q31: 雙圈秤重範圍 | R31: 二配鐵板蘑菇肉醬起司焗飯
A32: 5 | B32: 粗剝-蒸鰤魚 | C32: 1706.5375 | D32: 6.55 | E32: 6.6 | F32: 1.2 | G32: 1365.23 | H32: =(E32+F32)/D32 -> 1.1908397 | I32: 1706.5375 | J32: 0 | K32: =J32/D32 -> 0 | L32: =J32*G32 -> 0 | M32: =((E32+F32)-D32)-J32 -> 1.25 | N32: =M32/D32 -> 0.19083969 | O32: 組合室 | P32: 取樣不穩 | R32: 一配照燒鰤魚大根飯糰
A33: 6 | B33: (V)川燙小青花菜 | C33: 1379.9448 | D33: 481.13 | E33: 478.71 | F33: 11.78 | G33: 147.43 | H33: =(E33+F33)/D33 -> 1.0194542 | I33: 1379.9448 | J33: 0 | K33: =J33/D33 -> 0 | L33: =J33*G33 -> 0 | M33: =((E33+F33)-D33)-J33 -> 9.36 | N33: =M33/D33 -> 0.019454202 | O33: 組合室 | P33: 原物料規格 | Q33: 大顆比例高 | R33: 共用類
A34: 7 | B34: 切-鹽烤牛肉 | C34: 1172.5188 | D34: 45.22 | E34: 45.84 | F34: 1.15 | G34: 662.44 | H34: =(E34+F34)/D34 -> 1.039142 | I34: 1172.5188 | J34: 0 | K34: =J34/D34 -> 0 | L34: =J34*G34 -> 0 | M34: =((E34+F34)-D34)-J34 -> 1.77 | N34: =M34/D34 -> 0.039141973 | O34: 組合室 | P34: 取樣不穩 | R34: 共用類
A35: 8 | B35: 拌鹽烤豬肉片(114年) | C35: 1139.6784 | D35: 246.08 | E35: 248.84 | F35: 1.52 | G35: 266.28 | H35: =(E35+F35)/D35 -> 1.0173927 | I35: 1139.6784 | J35: 0 | K35: =J35/D35 -> 0 | L35: =J35*G35 -> 0 | M35: =((E35+F35)-D35)-J35 -> 4.28 | N35: =M35/D35 -> 0.017392718 | O35: 組合室 | P35: 取樣不穩 | R35: 鹽蔥燒肉飯糰
A36: 9 | B36: 切-究極燒肉片 | C36: 1135.8476 | D36: 35.93 | E36: 35.77 | F36: 1.8 | G36: 692.59 | H36: =(E36+F36)/D36 -> 1.0456443 | I36: 1135.8476 | J36: 0 | K36: =J36/D36 -> 0 | L36: =J36*G36 -> 0 | M36: =((E36+F36)-D36)-J36 -> 1.64 | N36: =M36/D36 -> 0.045644308 | O36: 組合室 | P36: 取樣不穩 | R36: 壹號醬雞豚雙拼
A37: 10 | B37: 炒培根片(114年) | C37: 1045.863 | D37: 18.33 | E37: 18.93 | F37: 1.35 | G37: 536.34 | H37: =(E37+F37)/D37 -> 1.106383 | I37: 1045.863 | J37: 0 | K37: =J37/D37 -> 0 | L37: =J37*G37 -> 0 | M37: =((E37+F37)-D37)-J37 -> 1.95 | N37: =M37/D37 -> 0.10638298 | O37: 組合室 | P37: 取樣不穩 | R37: 二配哞哞培根奶香海陸焗飯
A39: 共用類報廢金額前十名半成品
A40: 明細展開
A41: 排序 | B41: 半成品
B42: 名稱 | C42: 報廢金額 排序 | D42: 共用類總金額 占比
A44: 1 | B44: (V)消毒小黃瓜絲 | C44: 330.144 | D44: =C44/$L$5 -> 0.1381612
...

Sheet 0925分析標準表
A1: 大溪廠半成品管理分析
A2: 日期 | C2: 營業額 | D2: 報廢展開 | F2: 超用展開 | H2: 報廢展開 | J2: 超用展開 | L2: 報廢展開
A3: 45925 | C3: 6557727.1 | D3: 總報廢 | F3: 總超用 | H3: 報廢-前10名 | J3: 超用-前10名 | L3: 共用類-總報廢
D4: 金額 | E4: 占比(營業額) | F4: 金額 | G4: 占比(營業額) | H4: 金額 | I4: 占比(總報廢) | J4: 金額 | K4: 占比(總超用) | L4: 金額 | M4: 占比(總報廢)
A5: 年度KPI目標0.25% | D5: 15819.225 | E5: =D5/C3 -> 0.0024123031 | F5: 46633.562 | G5: =F5/C3 -> 0.0071112386 | H5: =SUM(C12:C21) -> 4625.5322 | I5: =H5/D5 -> 0.29239942 | J5: =SUM(C28:C37) -> 16899.604 | K5: =J5/F5 -> 0.36239144 | L5: 4091.5539 | M5: =L5/D5 -> 0.25864439
A7: 報廢金額前十名半成品
A8: 明細展開 | D8: 生產資訊 | O8: 類別 | P8: 分析原因 (請填寫8大原因) | Q8: 其他原因說明 | R8: 備註-商品名稱
A9: 排序 | B9: 半成品 | D9: 生產端 | J9: 組合端
B10: 名稱 | C10: 報廢金額 排序 | D10: 產出量 | J10: 報廢 | L10: 超用
D11: 訂單需求 (kg) | E11: 實際產出 (kg) | F11: 補單 (kg) | G11: 單價 (元) | H11: 實際生產 (對比訂單需求) | I11: 差異 (元) | J11: kg | K11: 占比 | L11: kg | M11: 占比 | N11: 金額 (元)
A12: 1 | B12: (V)川燙小青花菜 | C12: 1480.1972 | D12: 716.94 | E12: 726.98 | F12: 0 | G12: 147.43 | H12: =(E12+F12)/D12 -> 1.014004 | I12: 1480.1972 | J12: 10.04 | K12: =J12/D12 -> 0.014003961 | L12: =((E12+F12)-D12)-J12 -> -3.5527137e-14 | M12: =L12/D12 -> -4.9553849e-17 | N12: =L12*G12 -> -5.2377658e-12 | O12: 調理端 | P12: 原物料規格 | Q12: 大顆比例高 | R12: 共用類
A13: 2 | B13: 烤銀鮭魚肚 | C13: 849.75 | D13: 3759 | E13: 3814 | F13: 0 | G13: 15.45 | H13: =(E13+F13)/D13 -> 1.0146316 | I13: 849.75 | J13: 55 | K13: =J13/D13 -> 0.014631551 | L13: =((E13+F13)-D13)-J13 -> 0 | M13: =L13/D13 -> 0 | N13: =L13*G13 -> 0 | O13: 調理端 | P13: 研發設定 | Q13: 研發設定，小片的規格不符合指示書設定重量 | R13: 一配贅沢鮭魚肚飯糰
A14: 3 | B14: 消毒細切紅蘿蔔絲 | C14: 386.532 | D14: 182.38 | E14: 186.43 | F14: 0 | G14: 95.44 | H14: =(E14+F14)/D14 -> 1.0222064 | I14: 386.532 | J14: 4.05 | K14: =J14/D14 -> 0.022206382 | L14: =((E14+F14)-D14)-J14 -> 1.1546319e-14 | M14: =L14/D14 -> 6.3309132e-17 | N14: =L14*G14 -> 1.1019807e-12 | O14: 調理端 | P14: 取樣不穩 | R14: 共用類
A15: 4 | B15: 113年川燙綠豆芽 | C15: 276.7584 | D15: 51.66 | E15: 54.2 | F15: 0 | G15: 108.96 | H15: =(E15+F15)/D15 -> 1.0491676 | I15: 276.7584 | J15: 2.54 | K15: =J15/D15 -> 0.049167635 | L15: =((E15+F15)-D15)-J15 -> 6.2172489e-15 | M15: =L15/D15 -> 1.2034938e-16 | N15: =L15*G15 -> 6.7743144e-13 | O15: 調理端 | P15: 取樣不穩 | R15: 越式牛肉寬粉
A16: 5 | B16: 炸馬鈴薯塊 | C16: 273.823 | D16: 65.21 | E16: 66.76 | F16: 0 | G16: 176.66 | H16: =(E16+F16)/D16 -> 1.0237694 | I16: 273.823 | J16: 1.55 | K16: =J16/D16 -> 0.023769361 | L16: =((E16+F16)-D16)-J16 -> 1.1324275e-14 | M16: =L16/D16 -> 1.7365856e-16 | N16: =L16*G16 -> 2.0005464e-12 | O16: 調理端 | P16: 取樣不穩 | R16: 妮妮家漢堡排
A17: 6 | B17: 消毒青蔥絲 | C17: 273.306 | D17: 29.9 | E17: 31 | F17: 0 | G17: 248.46 | H17: =(E17+F17)/D17 -> 1.0367893 | I17: 273.306 | J17: 1.1 | K17: =J17/D17 -> 0.036789298 | L17: =((E17+F17)-D17)-J17 -> 0 | M17: =L17/D17 -> 0 | N17: =L17*G17 -> 0 | O17: 調理端 | P17: 取樣不穩 | R17: 共用類
A18: 7 | B18: (V)消毒小黃瓜絲 | C18: 272.224 | D18: 180.11 | E18: 181.99 | F18: 0 | G18: 144.8 | H18: =(E18+F18)/D18 -> 1.0104381 | I18: 272.224 | J18: 1.88 | K18: =J18/D18 -> 0.010438066 | L18: =((E18+F18)-D18)-J18 -> -4.4408921e-15 | M18: =L18/D18 -> -2.4656555e-17 | N18: =L18*G18 -> -6.4304118e-13 | O18: 調理端 | P18: 取樣不穩 | R18: 共用類
A19: 8 | B19: 大口椒麻醬 | C19: 271.8298 | D19: 25.63 | E19: 27.2 | F19: 0 | G19: 173.14 | H19: =(E19+F19)/D19 -> 1.0612563 | I19: 271.8298 | J19: 1.57 | K19: =J19/D19 -> 0.06125634 | L19: =((E19+F19)-D19)-J19 -> 0 | M19: =L19/D19 -> 0 | N19: =L19*G19 -> 0 | O19: 調理端 | P19: 展開量105% | R19: 大口花椒香麻雞飯糰
A20: 9 | B20: 洋蔥壹號醬 | C20: 271.1463 | D20: 42.52 | E20: 44.55 | F20: 0 | G20: 153.19 | H20: =(E20+F20)/D20 -> 1.0477422 | I20: 310.9757 | J20: 1.77 | K20: =J20/D20 -> 0.041627469 | L20: =((E20+F20)-D20)-J20 -> 0.26 | M20: =L20/D20 -> 0.0061147695 | N20: =L20*G20 -> 39.8294 | O20: 調理端 | P20: 取樣不穩 | R20: 壹號醬炙烤牛飯糰
A21: 10 | B21: 薑炒筍尾 | C21: 269.9655 | D21: 44.95 | E21: 44.3 | F21: 2.6 | G21: 183.65 | H21: =(E21+F21)/D21 -> 1.0433815 | I21: 358.1175 | J21: 1.47 | K21: =J21/D21 -> 0.032703003 | L21: =((E21+F21)-D21)-J21 -> 0.48 | M21: =L21/D21 -> 0.010678532 | N21: =L21*G21 -> 88.152 | O21: 調理端 | P21: 取樣不穩 | R21: 經典滷肉飯
A23: 超用金額前十名半成品
A24: 明細展開 | D24: 生產資訊 | O24: 類別 | P24: 分析原因 (請填寫8大原因) | Q24: 其他原因說明 | R24: 備註-商品名稱
A25: 排序 | B25: 半成品 | D25: 生產端 | J25: 組合端
B26: 名稱 | C26: 超用金額 排序 | D26: 產出量 | J26: 報廢 | M26: 超用
D27: 訂單需求 (kg) | E27: 實際產出 (kg) | F27: 補單 (kg) | G27: 單價 (元) | H27: 實際生產 (對比訂單需求) | I27: 差異 (元) | J27: kg | K27: 占比 | L27: 金額 (元) | M27: kg | N27: 占比
A28: 1 | B28: 炒照燒牛蒡腿丁 | C28: 3586.4645 | D28: 63.59 | E28: 63.18 | F28: 11.2 | G28: 345.85 | H28: =(E28+F28)/D28 -> 1.1696808 | I28: 3731.7215 | J28: 0.42 | K28: =J28/D28 -> 0.0066048121 | L28: =J28*G28 -> 145.257 | M28: =((E28+F28)-D28)-J28 -> 10.37 | N28: =M28/D28 -> 0.16307596 | O28: 組合室 | P28: 取樣不穩 | R28: 一配照燒雞肉飯糰
A29: 2 | B29: 切烤雞胸肉(111年) | C29: 2413.8208 | D29: 214.66 | E29: 213.58 | F29: 7 | G29: 407.74 | H29: =(E29+F29)/D29 -> 1.0275785 | I29: 2413.8208 | J29: 0 | K29: =J29/D29 -> 0 | L29: =J29*G29 -> 0 | M29: =((E29+F29)-D29)-J29 -> 5.92 | N29: =M29/D29 -> 0.027578496 | O29: 組合室 | P29: 研發設定 | Q29: 雙圈秤重範圍 | R29: 健身G肉餐盒(113年)
A30: 3 | B30: 蒸-醬香雞肉絲CL | C30: 1981.8876 | D30: 89.69 | E30: 89.78 | F30: 5.25 | G30: 371.14 | H30: =(E30+F30)/D30 -> 1.0595384 | I30: 1981.8876 | J30: 0 | K30: =J30/D30 -> 0 | L30: =J30*G30 -> 0 | M30: =((E30+F30)-D30)-J30 -> 5.34 | N30: =M30/D30 -> 0.05953841 | O30: 組合室 | P30: 取樣不穩 | R30: 共用類
A31: 4 | B31: 切-烤牛五花(112年) | C31: 1678.0106 | D31: 175.53 | E31: 172.28 | F31: 6.02 | G31: 605.78 | H31: =(E31+F31)/D31 -> 1.0157808 | I31: 1678.0106 | J31: 0 | K31: =J31/D31 -> 0 | L31: =J31*G31 -> 0 | M31: =((E31+F31)-D31)-J31 -> 2.77 | N31: =M31/D31 -> 0.015780778 | O31: 組合室 | P31: 研發設定 | Q31: 雙圈秤重範圍 | R31: 糖燻野郎三十天熟成牛飯
A32: 5 | B32: 切-究極燒肉片 | C32: 1378.2541 | D32: 44.3 | E32: 44.49 | F32: 1.8 | G32: 692.59 | H32: =(E32+F32)/D32 -> 1.044921 | I32: 1378.2541 | J32: 0 | K32: =J32/D32 -> 0 | L32: =J32*G32 -> 0 | M32: =((E32+F32)-D32)-J32 -> 1.99 | N32: =M32/D32 -> 0.044920993 | O32: 組合室 | P32: 取樣不穩 | R32: 壹號醬雞豚雙拼
A33: 6 | B33: 蘑菇白醬 | C33: 1277.7084 | D33: 210.72 | E33: 207.96 | F33: 15.6 | G33: 99.51 | H33: =(E33+F33)/D33 -> 1.0609339 | I33: 1277.7084 | J33: 0 | K33: =J33/D33 -> 0 | L33: =J33*G33 -> 0 | M33: =((E33+F33)-D33)-J33 -> 12.84 | N33: =M33/D33 -> 0.060933941 | O33: 組合室 | P33: 取樣不穩 | R33: 二配黃金雞排蘑菇白醬歐姆蛋飯
A34: 7 | B34: 煮牛肉片(A7) | C34: 1218.9882 | D34: 44.28 | E34: 43.02 | F34: 3.12 | G34: 655.37 | H34: =(E34+F34)/D34 -> 1.0420054 | I34: 1218.9882 | J34: 0 | K34: =J34/D34 -> 0 | L34: =J34*G34 -> 0 | M34: =((E34+F34)-D34)-J34 -> 1.86 | N34: =M34/D34 -> 0.04200542 | O34: 組合室 | P34: 取樣不穩 | R34: 越式牛肉寬粉
A35: 8 | B35: 煮中華冷麵(110年) | C35: 1192.3353 | D35: 3145.53 | E35: 3132.3 | F35: 43.5 | G35: 39.39 | H35: =(E35+F35)/D35 -> 1.0096232 | I35: 1192.3353 | J35: 0 | K35: =J35/D35 -> 0 | L35: =J35*G35 -> 0 | M35: =((E35+F35)-D35)-J35 -> 30.27 | N35: =M35/D35 -> 0.0096231796 | O35: 組合室 | P35: 研發設定 | Q35: 雙圈秤重範圍 | R35: 共用類
A36: 9 | B36: 112炒高級芝麻肉鬆 | C36: 1110.1344 | D36: 236.11 | E36: 236.88 | F36: 5.1 | G36: 189.12 | H36: =(E36+F36)/D36 -> 1.0248613 | I36: 1110.1344 | J36: 0 | K36: =J36/D36 -> 0 | L36: =J36*G36 -> 0 | M36: =((E36+F36)-D36)-J36 -> 5.87 | N36: =M36/D36 -> 0.024861293 | O36: 組合室 | P36: 取樣不穩 | R36: 經典肉鬆飯糰
A37: 10 | B37: 鮮食雙色起司絲 | C37: 1062 | D37: 114.89 | E37: 116.14 | F37: 4.86 | G37: 200 | H37: =(E37+F37)/D37 -> 1.0531813 | I37: 1222 | J37: 0.8 | K37: =J37/D37 -> 0.0069631822 | L37: =J37*G37 -> 160 | M37: =((E37+F37)-D37)-J37 -> 5.31 | N37: =M37/D37 -> 0.046218122 | O37: 組合室 | P37: 取樣不穩 | R37: 共用類
A39: 共用類報廢金額前十名半成品
A40: 明細展開
A41: 排序 | B41: 半成品
B42: 名稱 | C42: 報廢金額 排序 | D42: 共用類總金額 占比
