Workbook

Sheet 生產管理報表(月)
A1: 大溪廠生產管理報表
A3: 月別 | B3: 9 | C3: 工廠 | D3: 大溪廠
A4: （１）收支狀況 | E4: ※單位：千元 | G4: （２）ＫＰＩ達成進度
A5: 項目 | B5: 當月 | C5: 前月 | D5: 差異 | E5: 累計 | G5: 項目 | H5: KPI | I5: 當月 | J5: 前月 | K5: 累計 | L5: ※補充
A6: 業績金額 | B6: ='（１）收支狀況'!H36/1000 -> 108773.28 | C6: 225660.05 | D6: =B6-C6 -> -116886.77 | G6: 人時性(個/月均) | H6: 497.6 | I6: ='（２）ＫＰＩ達成進度'!H36 -> 399.95592 | J6: 413.83356 | L6: 個／MH
A7: 訂單數量 | B7: ='（１）收支狀況'!K36 -> 3584635 | C7: 7168725 | D7: =B7-C7 -> -3584090 | G7: 人時達成率(%/月均) | H7: 0.8 | I7: ='（２）ＫＰＩ達成進度'!K36 -> 0.80376993 | J7: 0.83165909 | L7: 達成率
A8: 材料費 | B8: ='（１）收支狀況'!N36/1000 -> 72618.555 | C8: 156124.67 | D8: =B8-C8 -> -83506.112 | G8: 半成品-報廢(%) | H8: 0.0025 | I8: ='（２）ＫＰＩ達成進度'!N36 -> 0.0024160534 | J8: 0.0024177654 | L8: 報廢率
A9: 材料費率 | B9: ='（１）收支狀況'!Q36 -> 0.66761391 | C9: 0.69185781 | D9: =B9-C9 -> -0.024243905 | G9: 半成品-超用(%) | H9: 0.004 | I9: ='（２）ＫＰＩ達成進度'!Q36 -> 0.0072338179 | J9: 0.0081428095 | L9: 超用率
A10: 勞務成本 | B10: ='（１）收支狀況'!T36/1000 -> 14807.125 | C10: 31193.59 | D10: =B10-C10 -> -16386.466 | G10: 固定產線-導入率(%) | H10: 0.8 | I10: ='（２）ＫＰＩ達成進度'!T36 -> 0.9 | J10: 0.9 | L10: 導入率
A11: 勞務費率 | B11: ='（１）收支狀況'!W36 -> 0.13612833 | C11: 0.13823267 | D11: =B11-C11 -> -0.0021043409 | G11: 教育訓練-實施率(%) | H11: 1 | I11: ='（２）ＫＰＩ達成進度'!W36 -> 0.43066667 | J11: 0.75038462 | L11: 實施率
A13: （３）業績構成比 | E13: ※單位：千元 | G13: （４）訂單數量構成比 | K13: ※單位：個
B14: 當月 | C14: 比例 | D14: 前月 | E14: 差異 | H14: 當月 | I14: 比例 | J14: 前月 | K14: 差異
A15: 18℃-飯糰(061,063) | B15: =SUM('（３）業績構成比'!M38:M67)/1000 -> 34546.491 | C15: =IFERROR(B15/$B$6,"") -> 0.31760089 | D15: 0.25352922 | E15: =IFERROR(C15-D15,"") -> 0.064071668 | G15: 18℃-飯糰(061,063) | H15: =SUM('（４）訂單數量構成比'!M38:M67) -> 1791396 | I15: =IFERROR(H15/$B$7,"") -> 0.49974293 | J15: 0.43223837 | K15: =IFERROR(I15-J15,"") -> 0.067504562
A16: 18℃-壽司手卷(071,072,075,076) | B16: =SUM('（３）業績構成比'!S38:S67)/1000 -> 6847.6996 | C16: =IFERROR(B16/$B$6,"") -> 0.062953876 | D16: 0.0653469 | E16: =IFERROR(C16-D16,"") -> -0.002393024 | G16: 18℃-壽司手卷(071,072,075,076) | H16: =SUM('（４）訂單數量構成比'!S38:S67) -> 262016 | I16: =IFERROR(H16/$B$7,"") -> 0.073094192 | J16: 0.079993583 | K16: =IFERROR(I16-J16,"") -> -0.0068993909
A17: 4℃-飯糰(065) | B17: =SUM('（３）業績構成比'!U38:U67)/1000 -> 9402.287 | C17: =IFERROR(B17/$B$6,"") -> 0.086439308 | D17: 0.089846437 | E17: =IFERROR(C17-D17,"") -> -0.0034071294 | G17: 4℃-飯糰(065) | H17: =SUM('（４）訂單數量構成比'!U38:U67) -> 291358 | I17: =IFERROR(H17/$B$7,"") -> 0.081279684 | J17: 0.089895484 | K17: =IFERROR(I17-J17,"") -> -0.0086157995
A18: 4℃-壽司手卷(077) | B18: =SUM('（３）業績構成比'!W38:W67)/1000 -> 1223.036 | C18: =IFERROR(B18/$B$6,"") -> 0.011243901 | D18: 0.016167533 | E18: =IFERROR(C18-D18,"") -> -0.0049236312 | G18: 4℃-壽司手卷(077) | H18: =SUM('（４）訂單數量構成比'!W38:W67) -> 41471 | I18: =IFERROR(H18/$B$7,"") -> 0.0115691 | J18: 0.017204733 | K18: =IFERROR(I18-J18,"") -> -0.0056356333
A19: 主食(091,092,093,094,095) | B19: =SUM('（３）業績構成比'!AC38:AC67)/1000 -> 18719.299 | C19: =IFERROR(B19/$B$6,"") -> 0.17209465 | D19: 0.17176909 | E19: =IFERROR(C19-D19,"") -> 0.00032556004 | G19: 主食(091,092,093,094,095) | H19: =SUM('（４）訂單數量構成比'!AC38:AC67) -> 349225 | I19: =IFERROR(H19/$B$7,"") -> 0.09742275 | J19: 0.10051188 | K19: =IFERROR(I19-J19,"") -> -0.0030891261
A20: 便當(083) | B20: =SUM('（３）業績構成比'!AE38:AE67)/1000 -> 17643.433 | C20: =IFERROR(B20/$B$6,"") -> 0.16220374 | D20: 0.18961737 | E20: =IFERROR(C20-D20,"") -> -0.027413624 | G20: 便當(083) | H20: =SUM('（４）訂單數量構成比'!AE38:AE67) -> 285753 | I20: =IFERROR(H20/$B$7,"") -> 0.079716066 | J20: 0.095108405 | K20: =IFERROR(I20-J20,"") -> -0.015392339
A21: 熱食義麵(122,123,124,126) | B21: =SUM('（３）業績構成比'!AG38:AG67)/1000 -> 1400.1285 | C21: =IFERROR(B21/$B$6,"") -> 0.012871989 | D21: 0.016374118 | E21: =IFERROR(C21-D21,"") -> -0.0035021292 | G21: 熱食義麵(122,123,124,126) | H21: =SUM('（４）訂單數量構成比'!AG38:AG67) -> 28274 | I21: =IFERROR(H21/$B$7,"") -> 0.0078875534 | J21: 0.010408545 | K21: =IFERROR(I21-J21,"") -> -0.002520992
A22: 季節調理麵(111,112) | B22: =SUM('（３）業績構成比'!AI38:AI67)/1000 -> 16403.422 | C22: =IFERROR(B22/$B$6,"") -> 0.15080378 | D22: 0.17141258 | E22: =IFERROR(C22-D22,"") -> -0.020608806 | G22: 季節調理麵(111,112) | H22: =SUM('（４）訂單數量構成比'!AI38:AI67) -> 455413 | I22: =IFERROR(H22/$B$7,"") -> 0.12704585 | J22: 0.15034305 | K22: =IFERROR(I22-J22,"") -> -0.023297203
A23: 微波小吃(153,154,155) | B23: =SUM('（３）業績構成比'!AK38:AK67)/1000 -> 2587.4841 | C23: =IFERROR(B23/$B$6,"") -> 0.023787865 | D23: 0.02593675 | E23: =IFERROR(C23-D23,"") -> -0.0021488846 | G23: 微波小吃(153,154,155) | H23: =SUM('（４）訂單數量構成比'!AK38:AK67) -> 79729 | I23: =IFERROR(H23/$B$7,"") -> 0.022241874 | J23: 0.024295952 | K23: =IFERROR(I23-J23,"") -> -0.0020540782
C24: =SUM(C15:C23) -> 1 | D24: =SUM(D15:D23) -> 1 | I24: =SUM(I15:I23) -> 1 | J24: =SUM(J15:J23) -> 1
A26: （５）品群別人時生產性
A27: 品群 | B27: 當月 | C27: 前月 | D27: 差異 | E27: 累計
A28: 18℃-飯A15:A23糰(061,063) | B28: ='（５-1）品群別人時生產性(18℃-飯糰)'!C1 -> 754.38251 | C28: 740.12217 | D28: 0
A29: 18℃-壽司手卷(071,072,075,076) | B29: ='（５-2）品群別人時生產性(18℃-壽司手卷)'!C1 -> 248.36619 | C29: 252.7812 | D29: 0
A30: 4℃-飯糰(065) | B30: ='（５-3）品群別人時生產性(4℃-飯糰)'!C1 -> 265.30197 | C30: 256.34305 | D30: 0
A31: 4℃-壽司手卷(077) | B31: ='（５-4）品群別人時生產性(4℃-壽司手卷)'!C1 -> 417.43952 | C31: 332.30282 | D31: 0
A32: 主食(091,092,093,094,095) | B32: ='（５-5）品群別人時生產性(微波主食) '!C1 -> 75.989407 | C32: 73.167141 | D32: 0
A33: 便當(083) | B33: ='（５-6）品群別人時生產性(便當)'!C1 -> 72.024708 | C33: 75.579281 | D33: 0
A34: 熱食義麵(122,123,124,126) | B34: ='（５-7）品群別人時生產性(熱食義麵) '!C1 -> 71.775097 | C34: 71.272091 | D34: 0
A35: 季節調理麵(111,112) | B35: ='（５-8）品群別人時生產性(季節調理麵) '!C1 -> 153.39354 | C35: 146.00815 | D35: 0
A36: 微波小吃(153,154,155) | B36: ='（５-9）品群別人時生產性(微波小吃)'!C1 -> 75.420247 | C36: 74.10752 | D36: 0

Sheet 生產管理報表(週) 
A1: 大溪廠生產管理報表
A3: 月別 | B3: 9 | C3: 週別 | D3: W2 | E3: 工廠 | F3: 大溪廠
A4: （１）收支狀況 | E4: ※單位：千元 | G4: （２）ＫＰＩ達成進度
A5: 項目 | B5: 當週 | C5: 前週 | D5: 差異 | E5: 累計 | G5: 項目 | H5: KPI | I5: 當週 | J5: 前週 | K5: 累計 | L5: ※補充
A6: 業績金額 | B6: ='（１）收支狀況'!G44/1000 -> 50242.376 | C6: 50724.262 | D6: =B6-C6 -> -481.88624 | E6: ='（１）收支狀況'!H5:H5/1000 -> 225660.05 | G6: 人時性(個/月均) | I6: ='（２）ＫＰＩ達成進度'!G44 -> 405.13281 | J6: 393.30515 | K6: ='（２）ＫＰＩ達成進度'!H5 -> 413.83356 | L6: 個／MH
A7: 訂單數量 | B7: ='（１）收支狀況'!J44 -> 1658017 | C7: 1673814 | D7: =B7-C7 -> -15797 | E7: ='（１）收支狀況'!K5:K5 -> 7168725 | G7: 人時達成率(%/月均) | H7: 0.8 | I7: ='（２）ＫＰＩ達成進度'!J44 -> 0.81417365 | J7: 0.79040424 | K7: ='（２）ＫＰＩ達成進度'!K5 -> 0.83165909 | L7: 達成率
A8: 材料費 | B8: ='（１）收支狀況'!M44/1000 -> 33439.915 | C8: 33748.28 | D8: =B8-C8 -> -308.36491 | E8: ='（１）收支狀況'!N5:N5/1000 -> 156124.67 | G8: 半成品-報廢(%) | H8: 0.0025 | I8: ='（２）ＫＰＩ達成進度'!M44 -> 0.0024153093 | J8: 0.002416257 | K8: ='（２）ＫＰＩ達成進度'!N5 -> 0.0024177654 | L8: 報廢率
A9: 材料費率 | B9: ='（１）收支狀況'!P44 -> 0.66557193 | C9: 0.66532816 | D9: =B9-C9 -> 0.00024376986 | E9: ='（１）收支狀況'!Q5 -> 0.69185781 | G9: 半成品-超用(%) | H9: 0.004 | I9: ='（２）ＫＰＩ達成進度'!P44 -> 0.0071487457 | J9: 0.0072948303 | K9: ='（２）ＫＰＩ達成進度'!Q5 -> 0.0081428095 | L9: 超用率
A10: 勞務成本 | B10: ='（１）收支狀況'!S44/1000 -> 6824.3662 | C10: 7050.3069 | D10: =B10-C10 -> -225.94063 | E10: ='（１）收支狀況'!T5/1000 -> 31193.59 | G10: 固定產線-導入率(%) | H10: 0.8 | I10: ='（２）ＫＰＩ達成進度'!S44 -> 0.9 | J10: 0.9 | K10: ='（２）ＫＰＩ達成進度'!T5 -> 0.9 | L10: 導入率
A11: 勞務費率 | B11: ='（１）收支狀況'!V44 -> 0.13582889 | C11: 0.13899279 | D11: =B11-C11 -> -0.0031639012 | E11: ='（１）收支狀況'!W5 -> 0.13823267 | G11: 教育訓練-實施率(%) | H11: 1 | I11: =37/52*100% -> 0.71153846 | J11: 0.69230769 | K11: ='（２）ＫＰＩ達成進度'!W5 -> 0.75038462 | L11: 實施率
A13: （３）業績構成比 | E13: ※單位：千元 | G13: （４）訂單數量構成比 | K13: ※單位：個
B14: 當週 | C14: 比例 | D14: 前週 | E14: 差異 | H14: 當週 | I14: 比例 | J14: 前週 | K14: 差異
A15: 18℃-飯糰(061,063) | B15: =SUM('（３）業績構成比'!M46:M52)/1000 -> 16438.872 | C15: =IFERROR(B15/$B$6,"") -> 0.32719138 | D15: 0.31610845 | E15: =IFERROR(C15-D15,"") -> 0.011082922 | G15: 18℃-飯糰(061,063) | H15: =SUM('（４）訂單數量構成比'!M46:M52) -> 845264 | I15: =IFERROR(H15/$B$7,"") -> 0.50980418 | J15: 0.49716396 | K15: =IFERROR(I15-J15,"") -> 0.01264022
A16: 18℃-壽司手卷(071,072,075,076) | B16: =SUM('（３）業績構成比'!S46:S52)/1000 -> 3053.241 | C16: =IFERROR(B16/$B$6,"") -> 0.060770235 | D16: 0.06419875 | E16: =IFERROR(C16-D16,"") -> -0.0034285147 | G16: 18℃-壽司手卷(071,072,075,076) | H16: =SUM('（４）訂單數量構成比'!S46:S52) -> 116601 | I16: =IFERROR(H16/$B$7,"") -> 0.070325576 | J16: 0.07447064 | K16: =IFERROR(I16-J16,"") -> -0.0041450644
A17: 4℃-飯糰(065) | B17: =SUM('（３）業績構成比'!U46:U52)/1000 -> 4387.8016 | C17: =IFERROR(B17/$B$6,"") -> 0.087332685 | D17: 0.085014626 | E17: =IFERROR(C17-D17,"") -> 0.0023180595 | G17: 4℃-飯糰(065) | H17: =SUM('（４）訂單數量構成比'!U46:U52) -> 135914 | I17: =IFERROR(H17/$B$7,"") -> 0.081973828 | J17: 0.079887013 | K17: =IFERROR(I17-J17,"") -> 0.0020868152
A18: 4℃-壽司手卷(077) | B18: =SUM('（３）業績構成比'!W46:W52)/1000 -> 553.25382 | C18: =IFERROR(B18/$B$6,"") -> 0.011011697 | D18: 0.011446221 | E18: =IFERROR(C18-D18,"") -> -0.00043452411 | G18: 4℃-壽司手卷(077) | H18: =SUM('（４）訂單數量構成比'!W46:W52) -> 18780 | I18: =IFERROR(H18/$B$7,"") -> 0.011326784 | J18: 0.011754592 | K18: =IFERROR(I18-J18,"") -> -0.00042780787
A19: 主食(091,092,093,094,095) | B19: =SUM('（３）業績構成比'!AC46:AC52)/1000 -> 8354.7 | C19: =IFERROR(B19/$B$6,"") -> 0.16628792 | D19: 0.17397688 | E19: =IFERROR(C19-D19,"") -> -0.0076889629 | G19: 主食(091,092,093,094,095) | H19: =SUM('（４）訂單數量構成比'!AC46:AC52) -> 155483 | I19: =IFERROR(H19/$B$7,"") -> 0.093776481 | J19: 0.098390861 | K19: =IFERROR(I19-J19,"") -> -0.0046143795
A20: 便當(083) | B20: =SUM('（３）業績構成比'!AE46:AE52)/1000 -> 8245.3857 | C20: =IFERROR(B20/$B$6,"") -> 0.16411218 | D20: 0.15942744 | E20: =IFERROR(C20-D20,"") -> 0.0046847352 | G20: 便當(083) | H20: =SUM('（４）訂單數量構成比'!AE46:AE52) -> 133890 | I20: =IFERROR(H20/$B$7,"") -> 0.080753092 | J20: 0.078071399 | K20: =IFERROR(I20-J20,"") -> 0.0026816938
A21: 熱食義麵(122,123,124,126) | B21: =SUM('（３）業績構成比'!AG46:AG52)/1000 -> 641.13544 | C21: =IFERROR(B21/$B$6,"") -> 0.01276085 | D21: 0.012902234 | E21: =IFERROR(C21-D21,"") -> -0.00014138405 | G21: 熱食義麵(122,123,124,126) | H21: =SUM('（４）訂單數量構成比'!AG46:AG52) -> 12947 | I21: =IFERROR(H21/$B$7,"") -> 0.0078087257 | J21: 0.0078957399 | K21: =IFERROR(I21-J21,"") -> -8.7014184e-05
A22: 季節調理麵(111,112) | B22: =SUM('（３）業績構成比'!AI46:AI52)/1000 -> 7367.5191 | C22: =IFERROR(B22/$B$6,"") -> 0.14663954 | D22: 0.15327198 | E22: =IFERROR(C22-D22,"") -> -0.0066324379 | G22: 季節調理麵(111,112) | H22: =SUM('（４）訂單數量構成比'!AI46:AI52) -> 201596 | I22: =IFERROR(H22/$B$7,"") -> 0.12158862 | J22: 0.13048881 | K22: =IFERROR(I22-J22,"") -> -0.0089001912
A23: 微波小吃(153,154,155) | B23: =SUM('（３）業績構成比'!AK46:AK52)/1000 -> 1200.4673 | C23: =IFERROR(B23/$B$6,"") -> 0.023893521 | D23: 0.023653414 | E23: =IFERROR(C23-D23,"") -> 0.00024010678 | G23: 微波小吃(153,154,155) | H23: =SUM('（４）訂單數量構成比'!AK46:AK52) -> 37542 | I23: =IFERROR(H23/$B$7,"") -> 0.022642711 | J23: 0.021876983 | K23: =IFERROR(I23-J23,"") -> 0.0007657284
C24: =SUM(C15:C23) -> 1 | D24: =SUM(D15:D23) -> 1 | I24: =SUM(I15:I23) -> 1 | J24: =SUM(J15:J23) -> 1
A26: （５）品群別人時生產性
A27: 品群 | B27: 當週 | C27: 前週 | D27: 差異 | E27: 累計
A28: 18℃-飯糰(061,063) | B28: ='（５-1）品群別人時生產性(18℃-飯糰)'!L217 -> 750.00008 | C28: 757.02679 | D28: =B28-C28 -> -7.026712 | E28: ='（５-1）品群別人時生產性(18℃-飯糰)'!C1 -> 754.38251
A29: 18℃-壽司手卷(071,072,075,076) | B29: ='（５-2）品群別人時生產性(18℃-壽司手卷)'!L127 -> 243.85708 | C29: 252.87531 | D29: =B29-C29 -> -9.0182247 | E29: ='（５-2）品群別人時生產性(18℃-壽司手卷)'!C1 -> 248.36619
A30: 4℃-飯糰(065) | B30: ='（５-3）品群別人時生產性(4℃-飯糰)'!L127 -> 265.95335 | C30: 264.65059 | D30: =B30-C30 -> 1.3027627 | E30: ='（５-3）品群別人時生產性(4℃-飯糰)'!C1 -> 265.30197
A31: 4℃-壽司手卷(077) | B31: ='（５-4）品群別人時生產性(4℃-壽司手卷)'!L127 -> 463.59488 | C31: 371.28416 | D31: =B31-C31 -> 92.310718 | E31: ='（５-4）品群別人時生產性(4℃-壽司手卷)'!C1 -> 417.43952
A32: 主食(091,092,093,094,095) | B32: ='（５-5）品群別人時生產性(微波主食) '!L127 -> 76.209165 | C32: 75.769649 | D32: =B32-C32 -> 0.43951601 | E32: ='（５-5）品群別人時生產性(微波主食) '!C1 -> 75.989407
A33: 便當(083) | B33: ='（５-6）品群別人時生產性(便當)'!L127 -> 72.184822 | C33: 71.864593 | D33: =B33-C33 -> 0.3202289 | E33: ='（５-6）品群別人時生產性(便當)'!C1 -> 72.024708
A34: 熱食義麵(122,123,124,126) | B34: ='（５-7）品群別人時生產性(熱食義麵) '!L127 -> 71.887347 | C34: 71.662848 | D34: =B34-C34 -> 0.22449914 | E34: ='（５-7）品群別人時生產性(熱食義麵) '!C1 -> 71.775097
A35: 季節調理麵(111,112) | B35: ='（５-8）品群別人時生產性(季節調理麵) '!L127 -> 153.58611 | C35: 153.20097 | D35: =B35-C35 -> 0.3851414 | E35: ='（５-8）品群別人時生產性(季節調理麵) '!C1 -> 153.39354
A36: 微波小吃(153,154,155) | B36: ='（５-9）品群別人時生產性(微波小吃)'!L127 -> 76.299686 | C36: 74.540808 | D36: =B36-C36 -> 1.7588775 | E36: ='（５-9）品群別人時生產性(微波小吃)'!C1 -> 75.420247

Sheet （１）收支狀況
B2: （１）收支狀況
B3: 資料繳交日 | C3: 月份 | D3: 日期 | F3: 營業額(元) | I3: 訂單數量(個) | L3: 材料費(元) | O3: 材料費率（材料費／營業額） | R3: 勞務成本（全廠人事成本） | U3: 勞務費率（勞務成本／營業額）
F4: 日 | G4: 週累積 | H4: 月累積 | I4: 日 | J4: 週累積 | K4: 月累積 | L4: 日 | M4: 週累積 | N4: 月累積 | O4: 日 | P4: 週累積 | Q4: 月累積 | R4: 日 | S4: 週累積 | T4: 月累積 | U4: 日 | V4: 週累積 | W4: 月累積
B5: 45910 | C5: 八 | D5: 45870 | E5: 五 | F5: 5795364.7 | G5: =SUM(F5:F8) -> 27982997 | H5: =SUM(F5:F35) -> 2.2566005e+08 | I5: 183531 | J5: =SUM(I5:I8) -> 876019 | K5: =SUM(I5:I35) -> 7168725 | L5: 4092107 | M5: =SUM(L5:L8) -> 19436107 | N5: =SUM(L5:L35) -> 1.5612467e+08 | O5: =L5/F5 -> 0.7061 | P5: =M5/G5 -> 0.69456846 | Q5: =N5/H5 -> 0.69185781 | R5: 891841 | S5: =SUM(R5:R8) -> 4014259.6 | T5: =SUM(R5:R35) -> 31193590 | U5: =R5/F5 -> 0.15388868 | V5: =S5/G5 -> 0.14345352 | W5: =T5/H5 -> 0.13823267
D6: 45871 | E6: 六 | F6: 6281761 | I6: 197498 | L6: 4425500.6 | O6: =L6/F6 -> 0.7045 | R6: 933551.29 | U6: =R6/F6 -> 0.14861299
D7: 45872 | E7: 日 | F7: 8003391.1 | I7: 248740 | L7: 5487125 | O7: =L7/F7 -> 0.6856 | R7: 1102691.3 | U7: =R7/F7 -> 0.13777801
D8: 45873 | E8: 一 | F8: 7902480.4 | I8: 246250 | L8: 5431374.8 | O8: =L8/F8 -> 0.6873 | R8: 1086176 | U8: =R8/F8 -> 0.13744748
D9: 45874 | E9: 二 | F9: 9130487.1 | G9: =SUM(F9:F15) -> 53787022 | I9: 275843 | J9: =SUM(I9:I15) -> 1673202 | L9: 6235209.6 | M9: =SUM(L9:L15) -> 36823749 | O9: =L9/F9 -> 0.6829 | P9: =M9/G9 -> 0.68462146 | R9: 1198581 | S9: =SUM(R9:R15) -> 7406479.7 | U9: =R9/F9 -> 0.1312724 | V9: =S9/G9 -> 0.13770013
D10: 45875 | E10: 三 | F10: 8314895.1 | I10: 255183 | L10: 5738940.6 | O10: =L10/F10 -> 0.6902 | R10: 1101959 | U10: =R10/F10 -> 0.13252831
D11: 45876 | E11: 四 | F11: 7555343.1 | I11: 235184 | L11: 5185987.5 | O11: =L11/F11 -> 0.6864 | R11: 1033014.8 | U11: =R11/F11 -> 0.13672639
D12: 45877 | E12: 五 | F12: 6209389.7 | I12: 195967 | L12: 4214933.7 | O12: =L12/F12 -> 0.6788 | R12: 940377.97 | U12: =R12/F12 -> 0.15144451
D13: 45878 | E13: 六 | F13: 6591313.1 | I13: 208309 | L13: 4526254.7 | O13: =L13/F13 -> 0.6867 | R13: 957572 | U13: =R13/F13 -> 0.14527788
D14: 45879 | E14: 日 | F14: 8170415.2 | I14: 256296 | L14: 5606538.9 | O14: =L14/F14 -> 0.6862 | R14: 1100462 | U14: =R14/F14 -> 0.13468863
D15: 45880 | E15: 一 | F15: 7815178.3 | I15: 246420 | L15: 5315884.3 | O15: =L15/F15 -> 0.6802 | R15: 1074513 | U15: =R15/F15 -> 0.13749053
B16: =D24 -> 45889 | D16: 45881 | E16: 二 | F16: 7841558.5 | G16: =SUM(F16:F22) -> 52217932 | I16: 239747 | J16: =SUM(I16:I22) -> 1628812 | L16: 5453803.9 | M16: =SUM(L16:L22) -> 35703457 | O16: =L16/F16 -> 0.6955 | P16: =M16/G16 -> 0.68373939 | R16: 1079138.9 | S16: =SUM(R16:R22) -> 7072355.9 | U16: =R16/F16 -> 0.13761791 | V16: =S16/G16 -> 0.13543922
D17: 45882 | E17: 三 | F17: 7976719.9 | I17: 246278 | L17: 5268623.5 | O17: =L17/F17 -> 0.6605 | R17: 1080253.7 | U17: =R17/F17 -> 0.1354258
D18: 45883 | E18: 四 | F18: 7479649 | I18: 233538 | L18: 5208827.6 | O18: =L18/F18 -> 0.6964 | R18: 1003496.7 | U18: =R18/F18 -> 0.13416361
D19: 45884 | E19: 五 | F19: 6364780.2 | I19: 198328 | L19: 4519630.4 | O19: =L19/F19 -> 0.7101 | R19: 934083.81 | U19: =R19/F19 -> 0.14675822
D20: 45885 | E20: 六 | F20: 6421067.8 | I20: 202709 | L20: 4356052.4 | O20: =L20/F20 -> 0.6784 | R20: 931231.33 | U20: =R20/F20 -> 0.14502749
D21: 45886 | E21: 日 | F21: 8145084.9 | I21: 254386 | L21: 5559020.4 | O21: =L21/F21 -> 0.6825 | R21: 1090508.3 | U21: =R21/F21 -> 0.13388544
D22: 45887 | E22: 一 | F22: 7989071.6 | I22: 253826 | L22: 5337498.7 | O22: =L22/F22 -> 0.6681 | R22: 953643.13 | U22: =R22/F22 -> 0.11936846
B23: =D24 -> 45889 | D23: 45888 | E23: 二 | F23: 7909637 | G23: =SUM(F23:F29) -> 50567324 | I23: 255899 | J23: =SUM(I23:I29) -> 1643193 | L23: 5546237.5 | M23: =SUM(L23:L29) -> 35420864 | O23: =L23/F23 -> 0.7012 | P23: =M23/G23 -> 0.70046942 | R23: 1069724.4 | S23: =SUM(R23:R29) -> 6924132.9 | U23: =R23/F23 -> 0.13524317 | V23: =S23/G23 -> 0.136929
D24: 45889 | E24: 三 | F24: 7775987.8 | I24: 251326 | L24: 5404311.5 | O24: =L24/F24 -> 0.695 | R24: 1044733.1 | U24: =R24/F24 -> 0.13435375
D25: 45890 | E25: 四 | F25: 7246465.3 | I25: 234557 | L25: 5066003.9 | O25: =L25/F25 -> 0.6991 | R25: 1004617.8 | U25: =R25/F25 -> 0.13863556
D26: 45891 | E26: 五 | F26: 5933586.3 | I26: 195333 | L26: 4169531.1 | O26: =L26/F26 -> 0.7027 | R26: 915576.34 | U26: =R26/F26 -> 0.15430404
D27: 45892 | E27: 六 | F27: 6081229.5 | I27: 200546 | L27: 4329227.3 | O27: =L27/F27 -> 0.7119 | R27: 920449.84 | U27: =R27/F27 -> 0.15135917
D28: 45893 | E28: 日 | F28: 7894027 | I28: 255114 | L28: 5555026.8 | O28: =L28/F28 -> 0.7037 | R28: 1049747.4 | U28: =R28/F28 -> 0.13297996
D29: 45894 | E29: 一 | F29: 7726391.3 | I29: 250418 | L29: 5350526 | O29: =L29/F29 -> 0.6925 | R29: 919284.12 | U29: =R29/F29 -> 0.11897975
B30: =D38 -> 45903 | D30: 45895 | E30: 二 | F30: 7423824.2 | G30: =SUM(F30:F36) -> 48911413 | I30: 242071 | J30: =SUM(I30:I36) -> 1600303 | L30: 5190737.9 | M30: =SUM(L30:L36) -> 34039750 | O30: =L30/F30 -> 0.6992 | P30: =M30/G30 -> 0.69594696 | R30: 1019343.9 | S30: =SUM(R30:R36) -> 6708813.6 | U30: =R30/F30 -> 0.13730712 | V30: =S30/G30 -> 0.13716254
D31: 45896 | E31: 三 | F31: 7268105.9 | I31: 237593 | L31: 5102210.3 | O31: =L31/F31 -> 0.702 | R31: 1002052.9 | U31: =R31/F31 -> 0.13786988
D32: 45897 | E32: 四 | F32: 6765305.7 | I32: 223084 | L32: 4751274.2 | O32: =L32/F32 -> 0.7023 | R32: 957969.59 | U32: =R32/F32 -> 0.14160034
D33: 45898 | E33: 五 | F33: 5760799.9 | I33: 190353 | L33: 3966310.7 | O33: =L33/F33 -> 0.6885 | R33: 876104.08 | U33: =R33/F33 -> 0.15208028
D34: 45899 | E34: 六 | F34: 6161593.8 | I34: 202704 | L34: 4425872.8 | O34: =L34/F34 -> 0.7183 | R34: 907804 | U34: =R34/F34 -> 0.14733266
D35: 45900 | E35: 日 | F35: 7725142.4 | I35: 251694 | L35: 5304082.8 | O35: =L35/F35 -> 0.6866 | R35: 1013087.7 | U35: =R35/F35 -> 0.13114162
D36: 45901 | E36: 一 | F36: 7806641.3 | H36: =SUM(F36:F65) -> 1.0877328e+08 | I36: 252804 | K36: =SUM(I36:I65) -> 3584635 | L36: 5299260.8 | N36: =SUM(L36:L65) -> 72618555 | O36: =L36/F36 -> 0.67881443 | Q36: =N36/H36 -> 0.66761391 | R36: 932451.5 | T36: =SUM(R36:R65) -> 14807125 | U36: =R36/F36 -> 0.11944336 | W36: =T36/H36 -> 0.13612833
B37: =B30+7 -> 45910 | D37: 45902 | E37: 二 | F37: 8169292.4 | G37: =SUM(F37:F43) -> 50724262 | I37: 267176 | J37: =SUM(I37:I43) -> 1673814 | L37: 5332358.2 | M37: =SUM(L37:L43) -> 33879379 | O37: =L37/F37 -> 0.65273196 | P37: =M37/G37 -> 0.66791269 | R37: 1087307.4 | S37: =SUM(R37:R43) -> 7050306.9 | U37: =R37/F37 -> 0.13309689 | V37: =S37/G37 -> 0.13899279
D38: 45903 | E38: 三 | F38: 7774607.2 | I38: 255665 | L38: 5250264.4 | O38: =L38/F38 -> 0.67530928 | R38: 1043986.6 | U38: =R38/F38 -> 0.13428158
D39: 45904 | E39: 四 | F39: 6925705.3 | I39: 230570 | L39: 4667711.2 | O39: =L39/F39 -> 0.67396907 | R39: 1014007.1 | U39: =R39/F39 -> 0.14641211
D40: 45905 | E40: 五 | F40: 5813361.8 | I40: 194911 | L40: 3942598 | O40: =L40/F40 -> 0.67819588 | R40: 910686.1 | U40: =R40/F40 -> 0.15665395
D41: 45906 | E41: 六 | F41: 6064269.1 | I41: 202561 | L41: 4096507.5 | O41: =L41/F41 -> 0.67551546 | R41: 899985.38 | U41: =R41/F41 -> 0.14840789
...

Sheet （２）ＫＰＩ達成進度
B1: 人時生產性基準值 | C1: 497.6
B2: （２）ＫＰＩ達成進度
B3: 資料繳交日 | C3: 月份 | D3: 日期 | F3: 人時生產性(個/人) | I3: 人時生產性達成率(%) | L3: 半成品報廢(%) | O3: 半成品超用(%) | R3: 固定產線-導入率(固定產線數/總產線數) | U3: 教育訓練-實施率(進度/計畫)
F4: 日 | G4: 週平均 | H4: 月平均 | I4: 日 | J4: 週平均 | K4: 月平均 | L4: 日 | M4: 週平均 | N4: 月平均 | O4: 日 | P4: 週平均 | Q4: 月平均 | R4: 日 | S4: 週平均 | T4: 月平均 | U4: 日 | V4: 週平均 | W4: 月平均
B5: =D17 -> 45882 | C5: 八 | D5: 45870 | E5: 五 | F5: 415.527 | G5: =AVERAGE(F5:F8) -> 418.38175 | H5: =AVERAGEIF(F5:F35,"<>0") -> 413.83356 | I5: =F5/$C$1 -> 0.8350623 | J5: =AVERAGE(I5:I8) -> 0.84079934 | K5: =AVERAGEIF(I5:I35,"<>0") -> 0.83165909 | L5: 0.002417538 | M5: =AVERAGE(L5:L8) -> 0.0024205689 | N5: =AVERAGEIF(L5:L35,"<>0") -> 0.0024177654 | O5: 0.0085448906 | P5: =AVERAGE(O5:O8) -> 0.0085892866 | Q5: =AVERAGEIF(O5:O35,"<>0") -> 0.0081428095 | R5: 0.9 | S5: =AVERAGE(R5:R8) -> 0.9 | T5: =AVERAGEIF(R5:R35,"<>0") -> 0.9 | U5: 0 | V5: =AVERAGE(U5:U8) -> 0 | W5: =AVERAGEIF(U5:U35,"<>0") -> 0.75038462
D6: 45871 | E6: 六 | F6: 418.1 | I6: =F6/$C$1 -> 0.84023312 | L6: 0.0024160533 | O6: 0.0086255174 | R6: 0.9 | U6: 0
D7: 45872 | E7: 日 | F7: 419.9 | I7: =F7/$C$1 -> 0.84385048 | L7: 0.0024263181 | O7: 0.0086427574 | R7: 0.9 | U7: 0
D8: 45873 | E8: 一 | F8: 420 | I8: =F8/$C$1 -> 0.84405145 | L8: 0.0024223663 | O8: 0.0085439811 | R8: 0.9 | U8: 0
D9: 45874 | E9: 二 | F9: 419.8 | G9: =AVERAGE(F9:F15) -> 419.83519 | I9: =F9/$C$1 -> 0.84364952 | J9: =AVERAGE(I9:I15) -> 0.84372023 | L9: 0.0024296155 | M9: =AVERAGE(L9:L15) -> 0.0024214907 | O9: 0.0086847829 | P9: =AVERAGE(O9:O15) -> 0.0085040814 | R9: 0.9 | S9: =AVERAGE(R9:R15) -> 0.9 | U9: 0 | V9: =AVERAGE(U9:U15) -> 0.38571429
D10: 45875 | E10: 三 | F10: 421 | I10: =F10/$C$1 -> 0.84606109 | L10: 0.0024244781 | O10: 0.008500829 | R10: 0.9 | U10: 0.45
D11: 45876 | E11: 四 | F11: 420.6 | I11: =F11/$C$1 -> 0.84525723 | L11: 0.0024176818 | O11: 0.0084839303 | R11: 0.9 | U11: 0.45
D12: 45877 | E12: 五 | F12: 419.4 | I12: =F12/$C$1 -> 0.84284566 | L12: 0.0024163613 | O12: 0.0085590273 | R12: 0.9 | U12: 0.45
D13: 45878 | E13: 六 | F13: 420.2 | I13: =F13/$C$1 -> 0.84445338 | L13: 0.00242 | O13: 0.0084 | R13: 0.9 | U13: 0.45
D14: 45879 | E14: 日 | F14: 418.68018 | I14: =F14/$C$1 -> 0.84139907 | L14: 0.0024222979 | O14: 0.0085 | R14: 0.9 | U14: 0.45
D15: 45880 | E15: 一 | F15: 419.16613 | I15: =F15/$C$1 -> 0.84237567 | L15: 0.00242 | O15: 0.0084 | R15: 0.9 | U15: 0.45
B16: =D24 -> 45889 | D16: 45881 | E16: 二 | F16: 419.23663 | G16: =AVERAGE(F16:F22) -> 420.94939 | I16: =F16/$C$1 -> 0.84251734 | J16: =AVERAGE(I16:I22) -> 0.84595938 | L16: 0.0024217026 | M16: =AVERAGE(L16:L22) -> 0.002418752 | O16: 0.0084720068 | P16: =AVERAGE(O16:O22) -> 0.0081582528 | R16: 0.9 | S16: =AVERAGE(R16:R22) -> 0.9 | U16: 0.655 | V16: =AVERAGE(U16:U22) -> 0.68428571
D17: 45882 | E17: 三 | F17: 427.85642 | I17: =F17/$C$1 -> 0.85984007 | L17: 0.0024241149 | O17: 0.0081359947 | R17: 0.9 | U17: 0.655
D18: 45883 | E18: 四 | F18: 418.61209 | I18: =F18/$C$1 -> 0.84126225 | L18: 0.0024201768 | O18: 0.0081898479 | R18: 0.9 | U18: 0.655
D19: 45884 | E19: 五 | F19: 420.16325 | I19: =F19/$C$1 -> 0.84437951 | L19: 0.0024141277 | O19: 0.0081708847 | R19: 0.9 | U19: 0.655
D20: 45885 | E20: 六 | F20: 419.93987 | I20: =F20/$C$1 -> 0.84393061 | L20: 0.0024138604 | O20: 0.0080622203 | R20: 0.9 | U20: 0.655
D21: 45886 | E21: 日 | F21: 419.34528 | I21: =F21/$C$1 -> 0.84273569 | L21: 0.0024195531 | O21: 0.0080721648 | R21: 0.9 | U21: 0.655
D22: 45887 | E22: 一 | F22: 421.49217 | I22: =F22/$C$1 -> 0.84705017 | L22: 0.0024177288 | O22: 0.0080046503 | R22: 0.9 | U22: 0.86
B23: =D24 -> 45889 | D23: 45888 | E23: 二 | F23: 401.41204 | G23: =AVERAGE(F23:F29) -> 403.24594 | I23: =F23/$C$1 -> 0.80669622 | J23: =AVERAGE(I23:I29) -> 0.81038171 | L23: 0.0024143458 | M23: =AVERAGE(L23:L29) -> 0.0024149588 | O23: 0.007989011 | P23: =AVERAGE(O23:O29) -> 0.0079209009 | R23: 0.9 | S23: =AVERAGE(R23:R29) -> 0.9 | U23: 0.86 | V23: =AVERAGE(U23:U29) -> 0.86
D24: 45889 | E24: 三 | F24: 402.00153 | I24: =F24/$C$1 -> 0.8078809 | L24: 0.0024116918 | O24: 0.0079602811 | R24: 0.9 | U24: 0.86
D25: 45890 | E25: 四 | F25: 403.35327 | I25: =F25/$C$1 -> 0.81059741 | L25: 0.0024104642 | O25: 0.0079450513 | R25: 0.9 | U25: 0.86
D26: 45891 | E26: 五 | F26: 404.16454 | I26: =F26/$C$1 -> 0.81222776 | L26: 0.0024195756 | O26: 0.0079444846 | R26: 0.9 | U26: 0.86
D27: 45892 | E27: 六 | F27: 404.34743 | I27: =F27/$C$1 -> 0.81259533 | L27: 0.0024159401 | O27: 0.0079281099 | R27: 0.9 | U27: 0.86
D28: 45893 | E28: 日 | F28: 403.52441 | I28: =F28/$C$1 -> 0.81094133 | L28: 0.0024182023 | O28: 0.0078440617 | R28: 0.9 | U28: 0.86
D29: 45894 | E29: 一 | F29: 403.91837 | I29: =F29/$C$1 -> 0.81173305 | L29: 0.0024144917 | O29: 0.0078353068 | R29: 0.9 | U29: 0.86
B30: =D38 -> 45903 | D30: 45895 | E30: 二 | F30: 405.17091 | G30: =AVERAGE(F30:F36) -> 408.19612 | I30: =F30/$C$1 -> 0.81425023 | J30: =AVERAGE(I30:I36) -> 0.82032982 | L30: 0.0024095768 | M30: =AVERAGE(L30:L36) -> 0.002414554 | O30: 0.0078142649 | P30: =AVERAGE(O30:O36) -> 0.0076270768 | R30: 0.9 | S30: =AVERAGE(R30:R36) -> 0.9 | U30: 1 | V30: =AVERAGE(U30:U36) -> 1
D31: 45896 | E31: 三 | F31: 405.6353 | I31: =F31/$C$1 -> 0.81518348 | L31: 0.0024120074 | O31: 0.0077428535 | R31: 0.9 | U31: 1
D32: 45897 | E32: 四 | F32: 405.5346 | I32: =F32/$C$1 -> 0.81498111 | L32: 0.0024118158 | O32: 0.0076901971 | R32: 0.9 | U32: 1
D33: 45898 | E33: 五 | F33: 403.0451 | I33: =F33/$C$1 -> 0.80997809 | L33: 0.0024182681 | O33: 0.007702409 | R33: 0.9 | U33: 1
D34: 45899 | E34: 六 | F34: 406.13914 | I34: =F34/$C$1 -> 0.81619602 | L34: 0.002416121 | O34: 0.0076018123 | R34: 0.9 | U34: 1
D35: 45900 | E35: 日 | F35: 421.57475 | I35: =F35/$C$1 -> 0.84721614 | L35: 0.002414252 | O35: 0.0074357648 | R35: 0.9 | U35: 1
D36: 45901 | E36: 一 | F36: 410.27303 | H36: =AVERAGEIF(F36:F65,"<>0") -> 399.95592 | I36: =F36/$C$1 -> 0.82450367 | K36: =AVERAGEIF(I36:I65,"<>0") -> 0.80376993 | L36: 0.0024198369 | N36: =AVERAGEIF(L36:L65,"<>0") -> 0.0024160534 | O36: 0.0074022361 | Q36: =AVERAGEIF(O36:O65,"<>0") -> 0.0072338179 | R36: 0.9 | T36: =AVERAGEIF(R36:R65,"<>0") -> 0.9 | U36: 1 | W36: =AVERAGEIF(U36:U65,"<>0") -> 0.43066667
B37: =B30+7 -> 45910 | D37: 45902 | E37: 二 | F37: 387.26986 | G37: =AVERAGE(F37:F43) -> 393.30515 | I37: =F37/$C$1 -> 0.77827544 | J37: =AVERAGE(I37:I43) -> 0.79040424 | L37: 0.0024242643 | M37: =AVERAGE(L37:L43) -> 0.002416257 | O37: 0.0074054037 | P37: =AVERAGE(O37:O43) -> 0.0072948303 | R37: 0.9 | S37: =AVERAGE(R37:R43) -> 0.9 | U37: 0.16 | V37: =AVERAGE(U37:U43) -> 0.16
D38: 45903 | E38: 三 | F38: 386.40391 | I38: =F38/$C$1 -> 0.77653519 | L38: 0.0024176219 | O38: 0.0073548234 | R38: 0.9 | U38: 0.16
D39: 45904 | E39: 四 | F39: 400.03121 | I39: =F39/$C$1 -> 0.80392124 | L39: 0.0024143896 | O39: 0.007341869 | R39: 0.9 | U39: 0.16
D40: 45905 | E40: 五 | F40: 402.82661 | I40: =F40/$C$1 -> 0.80953901 | L40: 0.0024101885 | O40: 0.0072093819 | R40: 0.9 | U40: 0.16
...

Sheet （３）業績構成比
B2: （3）業績構成比
B3: 資料繳交日 | C3: 月份 | D3: 日期 | F3: 營業額 | I3: 品類業績
I4: 18℃-飯糰 | O4: 18℃-壽司手卷 | U4: 4℃-飯糰 | W4: 4℃-壽司手卷 | Y4: 主食 | AE4: 便當 | AG4: 熱食義麵 | AI4: 季節調理麵 | AK4: 微波小吃
F5: 日 | G5: 週累積 | H5: 月累積 | I5: 一配 | K5: 二配 | M5: 合計 | O5: 一配 | Q5: 二配 | S5: 合計 | U5: 一配 | W5: 一配 | Y5: 一配 | AA5: 二配 | AC5: 合計 | AE5: 一配 | AG5: 一配 | AI5: 一配 | AK5: 一配
I6: 業績(元) | J6: 比例(%) | K6: 業績(元) | L6: 比例(%) | M6: 業績(元) | N6: 比例(%) | O6: 業績(元) | P6: 比例(%) | Q6: 業績(元) | R6: 比例(%) | S6: 業績(元) | T6: 比例(%) | U6: 業績(元) | V6: 比例(%) | W6: 業績(元) | X6: 比例(%) | Y6: 業績(元) | Z6: 比例(%) | AA6: 業績(元) | AB6: 比例(%) | AC6: 業績(元) | AD6: 比例(%) | AE6: 業績(元) | AF6: 比例(%) | AG6: 業績(元) | AH6: 比例(%) | AI6: 業績(元) | AJ6: 比例(%) | AK6: 業績(元) | AL6: 比例(%)
B7: =D19 -> 45882 | C7: 八 | D7: 45870 | E7: 五 | F7: =SUM(M7,S7,U7,W7,AC7,AE7,AG7,AI7,AK7) -> 5795364.7 | G7: =SUM(F7:F10) -> 27982997 | H7: =SUM(F7:F37) -> 2.2566005e+08 | I7: 616776.13 | J7: =I7/$F7 -> 0.10642577 | K7: 913483.89 | L7: =K7/$F7 -> 0.15762319 | M7: =I7+K7 -> 1530260 | N7: =M7/$F7 -> 0.26404896 | O7: 218583.35 | P7: =O7/$F7 -> 0.037716927 | Q7: 174098.34 | R7: =Q7/$F7 -> 0.030040964 | S7: =O7+Q7 -> 392681.69 | T7: =S7/$F7 -> 0.067757891 | U7: 430343.55 | V7: =U7/$F7 -> 0.074256509 | W7: 44217.57 | X7: =W7/$F7 -> 0.0076298166 | Y7: 374102.73 | Z7: =Y7/$F7 -> 0.06455206 | AA7: 461451.86 | AB7: =AA7/$F7 -> 0.0796243 | AC7: =Y7+AA7 -> 835554.59 | AD7: =AC7/$F7 -> 0.14417636 | AE7: 1152005.7 | AF7: =AE7/$F7 -> 0.19878053 | AG7: 143112.8 | AH7: =AG7/$F7 -> 0.024694356 | AI7: 1080951.3 | AJ7: =AI7/$F7 -> 0.18651997 | AK7: 186237.56 | AL7: =AK7/$F7 -> 0.032135607
D8: 45871 | E8: 六 | F8: =SUM(M8,S8,U8,W8,AC8,AE8,AG8,AI8,AK8) -> 6281761 | I8: 596870.47 | J8: =I8/$F8 -> 0.095016425 | K8: 1049002 | L8: =K8/$F8 -> 0.1669917 | M8: =I8+K8 -> 1645872.4 | N8: =M8/F8 -> 0.26200813 | O8: 218490.67 | P8: =O8/$F8 -> 0.034781755 | Q8: 178581.35 | R8: =Q8/$F8 -> 0.028428549 | S8: =O8+Q8 -> 397072.02 | T8: =S8/$F8 -> 0.063210304 | U8: 447379.41 | V8: =U8/$F8 -> 0.071218789 | W8: 49260.36 | X8: =W8/$F8 -> 0.0078418074 | Y8: 405644.63 | Z8: =Y8/$F8 -> 0.064574986 | AA8: 576275.75 | AB8: =AA8/$F8 -> 0.09173793 | AC8: =Y8+AA8 -> 981920.38 | AD8: =AC8/$F8 -> 0.15631292 | AE8: 1234302.9 | AF8: =AE8/$F8 -> 0.19648995 | AG8: 142518.56 | AH8: =AG8/$F8 -> 0.022687676 | AI8: 1193542.9 | AJ8: =AI8/$F8 -> 0.19000133 | AK8: 189891.96 | AL8: =AK8/$F8 -> 0.030229097
D9: 45872 | E9: 日 | F9: =SUM(M9,S9,U9,W9,AC9,AE9,AG9,AI9,AK9) -> 8003391.1 | I9: 848942.04 | J9: =I9/$F9 -> 0.10607279 | K9: 1169510.8 | L9: =K9/$F9 -> 0.14612691 | M9: =I9+K9 -> 2018452.8 | N9: =M9/$F9 -> 0.2521997 | O9: 301163.75 | P9: =O9/$F9 -> 0.037629518 | Q9: 209598.16 | R9: =Q9/$F9 -> 0.026188669 | S9: =O9+Q9 -> 510761.91 | T9: =S9/$F9 -> 0.063818187 | U9: 616088.77 | V9: =U9/$F9 -> 0.076978466 | W9: 57303.14 | X9: =W9/$F9 -> 0.0071598575 | Y9: 477605.86 | Z9: =Y9/$F9 -> 0.059675437 | AA9: 626376.66 | AB9: =AA9/$F9 -> 0.078263907 | AC9: =Y9+AA9 -> 1103982.5 | AD9: =AC9/$F9 -> 0.13793934 | AE9: 1793787 | AF9: =AE9/F9 -> 0.22412837 | AG9: 165941.52 | AH9: =AG9/$F9 -> 0.020733901 | AI9: 1515492 | AJ9: =AI9/$F9 -> 0.18935624 | AK9: 221581.38 | AL9: =AK9/$F9 -> 0.027685937
D10: 45873 | E10: 一 | F10: =SUM(M10,S10,U10,W10,AC10,AE10,AG10,AI10,AK10) -> 7902480.4 | I10: 842391.31 | J10: =I10/$F10 -> 0.10659834 | K10: 1149789.2 | L10: =K10/$F10 -> 0.14549725 | M10: =I10+K10 -> 1992180.5 | N10: =M10/F10 -> 0.25209559 | O10: 290166.83 | P10: =O10/$F10 -> 0.03671845 | Q10: 213916.58 | R10: =Q10/$F10 -> 0.027069549 | S10: =O10+Q10 -> 504083.41 | T10: =S10/F10 -> 0.063787999 | U10: 640822.6 | V10: =U10/F10 -> 0.081091324 | W10: 53404.08 | X10: =W10/$F10 -> 0.0067578883 | Y10: 497824.67 | Z10: =Y10/$F10 -> 0.062996002 | AA10: 589956.91 | AB10: =AA10/$F10 -> 0.07465465 | AC10: =Y10+AA10 -> 1087781.6 | AD10: =AC10/$F10 -> 0.13765065 | AE10: 1725586.6 | AF10: =AE10/F10 -> 0.21836012 | AG10: 154155.76 | AH10: =AG10/$F10 -> 0.019507263 | AI10: 1521645.6 | AJ10: =AI10/$F10 -> 0.19255291 | AK10: 222820.3 | AL10: =AK10/$F10 -> 0.028196248
D11: 45874 | E11: 二 | F11: =SUM(M11,S11,U11,W11,AC11,AE11,AG11,AI11,AK11) -> 9130487.1 | G11: =SUM(F11:F17) -> 53787022 | I11: 836074.89 | J11: =I11/$F11 -> 0.091569582 | K11: 1136887.2 | L11: =K11/$F11 -> 0.1245155 | M11: =I11+K11 -> 1972962.1 | N11: =M11/$F11 -> 0.21608508 | O11: 279337.22 | P11: =O11/$F11 -> 0.030593901 | Q11: 209656.24 | R11: =Q11/$F11 -> 0.022962219 | S11: =O11+Q11 -> 488993.46 | T11: =S11/$F11 -> 0.05355612 | U11: 880200.31 | V11: =U11/$F11 -> 0.096402339 | W11: 272272.92 | X11: =W11/$F11 -> 0.029820197 | Y11: 1409752.6 | Z11: =Y11/$F11 -> 0.15440059 | AA11: 575027.18 | AB11: =AA11/$F11 -> 0.062978806 | AC11: =Y11+AA11 -> 1984779.8 | AD11: =AC11/$F11 -> 0.2173794 | AE11: 1744245 | AF11: =AE11/F11 -> 0.19103526 | AG11: 141973.84 | AH11: =AG11/$F11 -> 0.015549427 | AI11: 1439367 | AJ11: =AI11/$F11 -> 0.15764405 | AK11: 205692.76 | AL11: =AK11/$F11 -> 0.022528126
D12: 45875 | E12: 三 | F12: =SUM(M12,S12,U12,W12,AC12,AE12,AG12,AI12,AK12) -> 8314895.1 | I12: 832343.12 | J12: =I12/$F12 -> 0.10010266 | K12: 1112911.5 | L12: =K12/$F12 -> 0.13384552 | M12: =I12+K12 -> 1945254.6 | N12: =M12/F12 -> 0.23394818 | O12: 277957.88 | P12: =O12/$F12 -> 0.03342891 | Q12: 209774.03 | R12: =Q12/$F12 -> 0.025228704 | S12: =O12+Q12 -> 487731.91 | T12: =S12/F12 -> 0.058657614 | U12: 774575.22 | V12: =U12/F12 -> 0.09315514 | W12: 177984.95 | X12: =W12/$F12 -> 0.021405556 | Y12: 979735.06 | Z12: =Y12/$F12 -> 0.11782891 | AA12: 552698.59 | AB12: =AA12/$F12 -> 0.066470903 | AC12: =Y12+AA12 -> 1532433.6 | AD12: =AC12/$F12 -> 0.18429982 | AE12: 1736477.1 | AF12: =AE12/F12 -> 0.20883933 | AG12: 145588.8 | AH12: =AG12/$F12 -> 0.017509397 | AI12: 1301970.3 | AJ12: =AI12/$F12 -> 0.15658289 | AK12: 212878.54 | AL12: =AK12/$F12 -> 0.025602072
D13: 45876 | E13: 四 | F13: =SUM(M13,S13,U13,W13,AC13,AE13,AG13,AI13,AK13) -> 7555343.1 | I13: 805376.99 | J13: =I13/$F13 -> 0.10659701 | K13: 1026230.4 | L13: =K13/$F13 -> 0.13582844 | M13: =I13+K13 -> 1831607.4 | N13: =M13/$F13 -> 0.24242545 | O13: 270818.45 | P13: =O13/$F13 -> 0.035844626 | Q13: 196345.4 | R13: =Q13/$F13 -> 0.025987622 | S13: =O13+Q13 -> 467163.85 | T13: =S13/$F13 -> 0.061832248 | U13: 725659.63 | V13: =U13/$F13 -> 0.096045887 | W13: 159956.52 | X13: =W13/$F13 -> 0.021171311 | Y13: 759398.2 | Z13: =Y13/$F13 -> 0.10051141 | AA13: 476992.26 | AB13: =AA13/$F13 -> 0.063133104 | AC13: =Y13+AA13 -> 1236390.5 | AD13: =AC13/$F13 -> 0.16364451 | AE13: 1584827.4 | AF13: =AE13/F13 -> 0.20976246 | AG13: 135635.28 | AH13: =AG13/$F13 -> 0.017952233 | AI13: 1219076.2 | AJ13: =AI13/$F13 -> 0.16135285 | AK13: 195026.38 | AL13: =AK13/$F13 -> 0.025813041
D14: 45877 | E14: 五 | F14: =SUM(M14,S14,U14,W14,AC14,AE14,AG14,AI14,AK14) -> 6209389.7 | I14: 600872.41 | J14: =I14/$F14 -> 0.096768352 | K14: 940206.09 | L14: =K14/$F14 -> 0.15141683 | M14: =I14+K14 -> 1541078.5 | N14: =M14/F14 -> 0.24818518 | O14: 213245.04 | P14: =O14/$F14 -> 0.034342351 | Q14: 178556.89 | R14: =Q14/$F14 -> 0.028755948 | S14: =O14+Q14 -> 391801.93 | T14: =S14/F14 -> 0.063098299 | U14: 572209.15 | V14: =U14/F14 -> 0.092152236 | W14: 134737.35 | X14: =W14/$F14 -> 0.021698968 | Y14: 573795.71 | Z14: =Y14/$F14 -> 0.092407746 | AA14: 458873.56 | AB14: =AA14/$F14 -> 0.073899945 | AC14: =Y14+AA14 -> 1032669.3 | AD14: =AC14/$F14 -> 0.16630769 | AE14: 1166486.3 | AF14: =AE14/F14 -> 0.18785844 | AG14: 111519.04 | AH14: =AG14/$F14 -> 0.017959742 | AI14: 1087287 | AJ14: =AI14/$F14 -> 0.17510368 | AK14: 171601.22 | AL14: =AK14/$F14 -> 0.027635763
D15: 45878 | E15: 六 | F15: =SUM(M15,S15,U15,W15,AC15,AE15,AG15,AI15,AK15) -> 6591313.1 | I15: 576824.54 | J15: =I15/$F15 -> 0.087512842 | K15: 1061661.3 | L15: =K15/$F15 -> 0.16106977 | M15: =I15+K15 -> 1638485.8 | N15: =M15/$F15 -> 0.24858261 | O15: 210458.83 | P15: =O15/$F15 -> 0.031929727 | Q15: 175507.77 | R15: =Q15/$F15 -> 0.026627133 | S15: =O15+Q15 -> 385966.6 | T15: =S15/$F15 -> 0.05855686 | U15: 615172.46 | V15: =U15/$F15 -> 0.09333079 | W15: 168615.52 | X15: =W15/$F15 -> 0.025581476 | Y15: 628681.46 | Z15: =Y15/$F15 -> 0.095380306 | AA15: 553490.4 | AB15: =AA15/$F15 -> 0.083972706 | AC15: =Y15+AA15 -> 1182171.9 | AD15: =AC15/$F15 -> 0.17935301 | AE15: 1159684.6 | AF15: =AE15/F15 -> 0.17594137 | AG15: 117808.08 | AH15: =AG15/$F15 -> 0.017873234 | AI15: 1148985.1 | AJ15: =AI15/$F15 -> 0.17431809 | AK15: 174423.06 | AL15: =AK15/$F15 -> 0.026462566
D16: 45879 | E16: 日 | F16: =SUM(M16,S16,U16,W16,AC16,AE16,AG16,AI16,AK16) -> 8170415.3 | I16: 834483.57 | J16: =I16/$F16 -> 0.10213478 | K16: 1183422 | L16: =K16/$F16 -> 0.14484233 | M16: =I16+K16 -> 2017905.6 | N16: =M16/F16 -> 0.24697711 | O16: 293053.1 | P16: =O16/$F16 -> 0.035867589 | Q16: 206898.61 | R16: =Q16/$F16 -> 0.0253229 | S16: =O16+Q16 -> 499951.71 | T16: =S16/F16 -> 0.06119049 | U16: 786444.54 | V16: =U16/F16 -> 0.096255149 | W16: 190554.87 | X16: =W16/$F16 -> 0.023322544 | Y16: 661083.02 | Z16: =Y16/$F16 -> 0.080911802 | AA16: 593610.63 | AB16: =AA16/$F16 -> 0.072653667 | AC16: =Y16+AA16 -> 1254693.6 | AD16: =AC16/$F16 -> 0.15356547 | AE16: 1730952 | AF16: =AE16/F16 -> 0.21185606 | AG16: 148956.16 | AH16: =AG16/$F16 -> 0.018231162 | AI16: 1342564.1 | AJ16: =AI16/$F16 -> 0.16432018 | AK16: 198392.62 | AL16: =AK16/$F16 -> 0.024281828
D17: 45880 | E17: 一 | F17: =SUM(M17,S17,U17,W17,AC17,AE17,AG17,AI17,AK17) -> 7815178.3 | I17: 822329.48 | J17: =I17/$F17 -> 0.1052221 | K17: 1143104.3 | L17: =K17/$F17 -> 0.14626721 | M17: =I17+K17 -> 1965433.8 | N17: =M17/$F17 -> 0.25148931 | O17: 281152.03 | P17: =O17/$F17 -> 0.035975127 | Q17: 212068.8 | R17: =Q17/$F17 -> 0.027135504 | S17: =O17+Q17 -> 493220.83 | T17: =S17/$F17 -> 0.063110631 | U17: 749380.3 | V17: =U17/$F17 -> 0.095887806 | W17: 137647.83 | X17: =W17/$F17 -> 0.017612884 | Y17: 658221.96 | Z17: =Y17/$F17 -> 0.084223537 | AA17: 568146.73 | AB17: =AA17/$F17 -> 0.072697859 | AC17: =Y17+AA17 -> 1226368.7 | AD17: =AC17/$F17 -> 0.1569214 | AE17: 1599032.4 | AF17: =AE17/F17 -> 0.20460601 | AG17: 131673.68 | AH17: =AG17/$F17 -> 0.016848455 | AI17: 1310668 | AJ17: =AI17/$F17 -> 0.16770801 | AK17: 201752.72 | AL17: =AK17/$F17 -> 0.025815498
B18: =D26 -> 45889 | D18: 45881 | E18: 二 | F18: =SUM(M18,S18,U18,W18,AC18,AE18,AG18,AI18,AK18) -> 7841558.5 | G18: =SUM(F18:F24) -> 52217932 | I18: 745380.02 | J18: =I18/$F18 -> 0.095055086 | K18: 1078484.5 | L18: =K18/$F18 -> 0.13753446 | M18: =I18+K18 -> 1823864.5 | N18: =M18/F18 -> 0.23258954 | O18: 257418.86 | P18: =O18/$F18 -> 0.032827512 | Q18: 200491.16 | R18: =Q18/$F18 -> 0.025567769 | S18: =O18+Q18 -> 457910.02 | T18: =S18/F18 -> 0.058395282 | U18: 706456.98 | V18: =U18/F18 -> 0.090091399 | W18: 127825.59 | X18: =W18/$F18 -> 0.016301044 | Y18: 987966.2 | Z18: =Y18/$F18 -> 0.12599105 | AA18: 569382.14 | AB18: =AA18/$F18 -> 0.072610839 | AC18: =Y18+AA18 -> 1557348.3 | AD18: =AC18/$F18 -> 0.19860189 | AE18: 1609473.9 | AF18: =AE18/F18 -> 0.20524924 | AG18: 121472.56 | AH18: =AG18/$F18 -> 0.01549087 | AI18: 1244098 | AJ18: =AI18/$F18 -> 0.15865443 | AK18: 193108.64 | AL18: =AK18/$F18 -> 0.024626309
D19: 45882 | E19: 三 | F19: =SUM(M19,S19,U19,W19,AC19,AE19,AG19,AI19,AK19) -> 7976719.9 | I19: 797234.09 | J19: =I19/$F19 -> 0.099945102 | K19: 1075806.2 | L19: =K19/$F19 -> 0.13486825 | M19: =I19+K19 -> 1873040.3 | N19: =M19/$F19 -> 0.23481335 | O19: 266310.62 | P19: =O19/$F19 -> 0.033385981 | Q19: 200827.92 | R19: =Q19/$F19 -> 0.025176755 | S19: =O19+Q19 -> 467138.54 | T19: =S19/$F19 -> 0.058562736 | U19: 739331.86 | V19: =U19/$F19 -> 0.0926862 | W19: 161708.71 | X19: =W19/$F19 -> 0.020272582 | Y19: 936877.14 | Z19: =Y19/$F19 -> 0.11745143 | AA19: 550621.21 | AB19: =AA19/$F19 -> 0.069028525 | AC19: =Y19+AA19 -> 1487498.4 | AD19: =AC19/$F19 -> 0.18647995 | AE19: 1614253.9 | AF19: =AE19/F19 -> 0.20237064 | AG19: 127613.04 | AH19: =AG19/$F19 -> 0.015998185 | AI19: 1313198.8 | AJ19: =AI19/$F19 -> 0.16462892 | AK19: 192936.44 | AL19: =AK19/$F19 -> 0.024187441
D20: 45883 | E20: 四 | F20: =SUM(M20,S20,U20,W20,AC20,AE20,AG20,AI20,AK20) -> 7479649 | I20: 786765.2 | J20: =I20/$F20 -> 0.10518745 | K20: 1004644.2 | L20: =K20/$F20 -> 0.13431702 | M20: =I20+K20 -> 1791409.4 | N20: =M20/F20 -> 0.23950447 | O20: 260845.29 | P20: =O20/$F20 -> 0.034874001 | Q20: 196030.23 | R20: =Q20/$F20 -> 0.02620848 | S20: =O20+Q20 -> 456875.52 | T20: =S20/F20 -> 0.061082481 | U20: 704969.96 | V20: =U20/F20 -> 0.094251743 | W20: 160120.81 | X20: =W20/$F20 -> 0.02140753 | Y20: 823676.36 | Z20: =Y20/$F20 -> 0.11012233 | AA20: 488398.07 | AB20: =AA20/$F20 -> 0.065296923 | AC20: =Y20+AA20 -> 1312074.4 | AD20: =AC20/$F20 -> 0.17541925 | AE20: 1455498.9 | AF20: =AE20/F20 -> 0.19459455 | AG20: 123948.56 | AH20: =AG20/$F20 -> 0.016571441 | AI20: 1281098.6 | AJ20: =AI20/$F20 -> 0.1712779 | AK20: 193652.92 | AL20: =AK20/$F20 -> 0.025890643
D21: 45884 | E21: 五 | F21: =SUM(M21,S21,U21,W21,AC21,AE21,AG21,AI21,AK21) -> 6364780.2 | I21: 589436.89 | J21: =I21/$F21 -> 0.092609151 | K21: 913476.45 | L21: =K21/$F21 -> 0.1435205 | M21: =I21+K21 -> 1502913.3 | N21: =M21/$F21 -> 0.23612965 | O21: 207789.04 | P21: =O21/$F21 -> 0.032646695 | Q21: 171639.61 | R21: =Q21/$F21 -> 0.026967091 | S21: =O21+Q21 -> 379428.65 | T21: =S21/$F21 -> 0.059613787 | U21: 584428.01 | V21: =U21/$F21 -> 0.091822182 | W21: 132492.67 | X21: =W21/$F21 -> 0.020816535 | Y21: 719692.18 | Z21: =Y21/$F21 -> 0.11307416 | AA21: 473959.41 | AB21: =AA21/$F21 -> 0.074465951 | AC21: =Y21+AA21 -> 1193651.6 | AD21: =AC21/$F21 -> 0.18754011 | AE21: 1139974.4 | AF21: =AE21/F21 -> 0.17910664 | AG21: 103298.72 | AH21: =AG21/$F21 -> 0.016229739 | AI21: 1149935.2 | AJ21: =AI21/$F21 -> 0.18067162 | AK21: 178657.68 | AL21: =AK21/$F21 -> 0.028069733
D22: 45885 | E22: 六 | F22: =SUM(M22,S22,U22,W22,AC22,AE22,AG22,AI22,AK22) -> 6421067.8 | I22: 566021.5 | J22: =I22/$F22 -> 0.088150682 | K22: 1030734.3 | L22: =K22/$F22 -> 0.16052382 | M22: =I22+K22 -> 1596755.8 | N22: =M22/F22 -> 0.2486745 | O22: 204431.69 | P22: =O22/$F22 -> 0.031837647 | Q22: 172164.23 | R22: =Q22/$F22 -> 0.026812399 | S22: =O22+Q22 -> 376595.92 | T22: =S22/F22 -> 0.058650046 | U22: 564425.66 | V22: =U22/F22 -> 0.08790215 | W22: 126109.67 | X22: =W22/$F22 -> 0.019639984 | Y22: 734713.27 | Z22: =Y22/$F22 -> 0.11442229 | AA22: 546919.48 | AB22: =AA22/$F22 -> 0.085175784 | AC22: =Y22+AA22 -> 1281632.8 | AD22: =AC22/$F22 -> 0.19959807 | AE22: 1080430.9 | AF22: =AE22/F22 -> 0.16826343 | AG22: 104437.68 | AH22: =AG22/$F22 -> 0.016264846 | AI22: 1118197.2 | AJ22: =AI22/$F22 -> 0.17414506 | AK22: 172482.16 | AL22: =AK22/$F22 -> 0.026861912
D23: 45886 | E23: 日 | F23: =SUM(M23,S23,U23,W23,AC23,AE23,AG23,AI23,AK23) -> 8145084.9 | I23: 822755.01 | J23: =I23/$F23 -> 0.10101245 | K23: 1151709.1 | L23: =K23/$F23 -> 0.14139927 | M23: =I23+K23 -> 1974464.1 | N23: =M23/$F23 -> 0.24241172 | O23: 292053.28 | P23: =O23/$F23 -> 0.035856383 | Q23: 209484.59 | R23: =Q23/$F23 -> 0.025719141 | S23: =O23+Q23 -> 501537.87 | T23: =S23/$F23 -> 0.061575524 | U23: 737537.42 | V23: =U23/$F23 -> 0.090549998 | W23: 143713.23 | X23: =W23/$F23 -> 0.017644166 | Y23: 872798.68 | Z23: =Y23/$F23 -> 0.10715649 | AA23: 590584.6 | AB23: =AA23/$F23 -> 0.072508097 | AC23: =Y23+AA23 -> 1463383.3 | AD23: =AC23/$F23 -> 0.17966458 | AE23: 1637637.3 | AF23: =AE23/F23 -> 0.20105835 | AG23: 133307.84 | AH23: =AG23/$F23 -> 0.016366661 | AI23: 1353127.5 | AJ23: =AI23/$F23 -> 0.16612811 | AK23: 200376.28 | AL23: =AK23/$F23 -> 0.024600883
D24: 45887 | E24: 一 | F24: =SUM(M24,S24,U24,W24,AC24,AE24,AG24,AI24,AK24) -> 7989071.6 | I24: 814780.46 | J24: =I24/$F24 -> 0.10198688 | K24: 1220188.7 | L24: =K24/$F24 -> 0.15273223 | M24: =I24+K24 -> 2034969.2 | N24: =M24/F24 -> 0.25471911 | O24: 281514.66 | P24: =O24/$F24 -> 0.035237469 | Q24: 215920.9 | R24: =Q24/$F24 -> 0.027027033 | S24: =O24+Q24 -> 497435.56 | T24: =S24/F24 -> 0.062264502 | U24: 722096.91 | V24: =U24/F24 -> 0.090385586 | W24: 140073.84 | X24: =W24/$F24 -> 0.017533181 | Y24: 804543.45 | Z24: =Y24/$F24 -> 0.1007055 | AA24: 580810.69 | AB24: =AA24/$F24 -> 0.072700649 | AC24: =Y24+AA24 -> 1385354.1 | AD24: =AC24/$F24 -> 0.17340615 | AE24: 1580478.6 | AF24: =AE24/F24 -> 0.19783007 | AG24: 123651.44 | AH24: =AG24/$F24 -> 0.015477573 | AI24: 1313311.8 | AJ24: =AI24/$F24 -> 0.16438854 | AK24: 191700.1 | AL24: =AK24/$F24 -> 0.023995291
B25: =D26 -> 45889 | D25: 45888 | E25: 二 | F25: =SUM(M25,S25,U25,W25,AC25,AE25,AG25,AI25,AK25) -> 7909637 | G25: =SUM(F25:F31) -> 50567324 | I25: 875139.89 | J25: =I25/$F25 -> 0.11064223 | K25: 1199689.1 | L25: =K25/$F25 -> 0.15167435 | M25: =I25+K25 -> 2074829 | N25: =M25/$F25 -> 0.26231658 | O25: 386552.85 | P25: =O25/$F25 -> 0.048871124 | Q25: 213050.47 | R25: =Q25/$F25 -> 0.026935556 | S25: =O25+Q25 -> 599603.32 | T25: =S25/$F25 -> 0.075806679 | U25: 713433.99 | V25: =U25/$F25 -> 0.090198069 | W25: 115894.22 | X25: =W25/$F25 -> 0.01465228 | Y25: 808258.98 | Z25: =Y25/$F25 -> 0.10218661 | AA25: 555157.81 | AB25: =AA25/$F25 -> 0.07018752 | AC25: =Y25+AA25 -> 1363416.8 | AD25: =AC25/$F25 -> 0.17237413 | AE25: 1493682.2 | AF25: =AE25/F25 -> 0.18884333 | AG25: 104883.36 | AH25: =AG25/$F25 -> 0.013260199 | AI25: 1255426.7 | AJ25: =AI25/$F25 -> 0.15872115 | AK25: 188467.54 | AL25: =AK25/$F25 -> 0.023827584
D26: 45889 | E26: 三 | F26: =SUM(M26,S26,U26,W26,AC26,AE26,AG26,AI26,AK26) -> 7775987.8 | I26: 860655.66 | J26: =I26/$F26 -> 0.1106812 | K26: 1171588.6 | L26: =K26/$F26 -> 0.15066749 | M26: =I26+K26 -> 2032244.2 | N26: =M26/F26 -> 0.26134869 | O26: 342777.47 | P26: =O26/$F26 -> 0.044081534 | Q26: 206194.99 | R26: =Q26/$F26 -> 0.026516887 | S26: =O26+Q26 -> 548972.46 | T26: =S26/F26 -> 0.070598421 | U26: 704925.1 | V26: =U26/F26 -> 0.090654091 | W26: 109592.45 | X26: =W26/$F26 -> 0.014093701 | Y26: 808561.34 | Z26: =Y26/$F26 -> 0.10398182 | AA26: 523625.55 | AB26: =AA26/$F26 -> 0.067338783 | AC26: =Y26+AA26 -> 1332186.9 | AD26: =AC26/$F26 -> 0.1713206 | AE26: 1429884.7 | AF26: =AE26/F26 -> 0.18388464 | AG26: 108498.32 | AH26: =AG26/$F26 -> 0.013952995 | AI26: 1311648.6 | AJ26: =AI26/$F26 -> 0.16867936 | AK26: 198034.92 | AL26: =AK26/$F26 -> 0.025467494
D27: 45890 | E27: 四 | F27: =SUM(M27,S27,U27,W27,AC27,AE27,AG27,AI27,AK27) -> 7246465.3 | I27: 837051.52 | J27: =I27/$F27 -> 0.1155117 | K27: 1063532.9 | L27: =K27/$F27 -> 0.14676575 | M27: =I27+K27 -> 1900584.4 | N27: =M27/$F27 -> 0.26227745 | O27: 327033.76 | P27: =O27/$F27 -> 0.045130108 | Q27: 200389.36 | R27: =Q27/$F27 -> 0.027653394 | S27: =O27+Q27 -> 527423.12 | T27: =S27/$F27 -> 0.072783502 | U27: 650068.18 | V27: =U27/$F27 -> 0.089708313 | W27: 89651.69 | X27: =W27/$F27 -> 0.012371782 | Y27: 757874.34 | Z27: =Y27/$F27 -> 0.10458538 | AA27: 457038.84 | AB27: =AA27/$F27 -> 0.06307059 | AC27: =Y27+AA27 -> 1214913.2 | AD27: =AC27/$F27 -> 0.16765597 | AE27: 1326002.9 | AF27: =AE27/F27 -> 0.18298617 | AG27: 106368.96 | AH27: =AG27/$F27 -> 0.014678737 | AI27: 1246380.6 | AJ27: =AI27/$F27 -> 0.17199842 | AK27: 185072.24 | AL27: =AK27/$F27 -> 0.025539657
D28: 45891 | E28: 五 | F28: =SUM(M28,S28,U28,W28,AC28,AE28,AG28,AI28,AK28) -> 5933586.3 | I28: 647996.12 | J28: =I28/$F28 -> 0.10920817 | K28: 956263.61 | L28: =K28/$F28 -> 0.16116115 | M28: =I28+K28 -> 1604259.7 | N28: =M28/F28 -> 0.27036932 | O28: 278125.58 | P28: =O28/$F28 -> 0.046873099 | Q28: 172268.36 | R28: =Q28/$F28 -> 0.029032755 | S28: =O28+Q28 -> 450393.94 | T28: =S28/F28 -> 0.075905854 | U28: 533718.82 | V28: =U28/F28 -> 0.089948774 | W28: 86994.8 | X28: =W28/$F28 -> 0.01466142 | Y28: 608937.53 | Z28: =Y28/$F28 -> 0.10262554 | AA28: 447191.99 | AB28: =AA28/$F28 -> 0.075366223 | AC28: =Y28+AA28 -> 1056129.5 | AD28: =AC28/$F28 -> 0.17799177 | AE28: 956499.18 | AF28: =AE28/F28 -> 0.16120085 | AG28: 84629.68 | AH28: =AG28/$F28 -> 0.014262821 | AI28: 997418.16 | AJ28: =AI28/$F28 -> 0.16809702 | AK28: 163542.52 | AL28: =AK28/$F28 -> 0.027562171
D29: 45892 | E29: 六 | F29: =SUM(M29,S29,U29,W29,AC29,AE29,AG29,AI29,AK29) -> 6081229.5 | I29: 619306.15 | J29: =I29/$F29 -> 0.10183897 | K29: 1066731.6 | L29: =K29/$F29 -> 0.17541379 | M29: =I29+K29 -> 1686037.7 | N29: =M29/$F29 -> 0.27725276 | O29: 267588.99 | P29: =O29/$F29 -> 0.044002449 | Q29: 172897.79 | R29: =Q29/$F29 -> 0.028431387 | S29: =O29+Q29 -> 440486.78 | T29: =S29/$F29 -> 0.072433836 | U29: 514063.4 | V29: =U29/$F29 -> 0.084532807 | W29: 95936.6 | X29: =W29/$F29 -> 0.015775856 | Y29: 566519.53 | Z29: =Y29/$F29 -> 0.093158715 | AA29: 562403.13 | AB29: =AA29/$F29 -> 0.092481813 | AC29: =Y29+AA29 -> 1128922.7 | AD29: =AC29/$F29 -> 0.18564053 | AE29: 976636.64 | AF29: =AE29/F29 -> 0.16059855 | AG29: 89928.32 | AH29: =AG29/$F29 -> 0.014787852 | AI29: 983684.71 | AJ29: =AI29/$F29 -> 0.16175754 | AK29: 165532.72 | AL29: =AK29/$F29 -> 0.027220272
D30: 45893 | E30: 日 | F30: =SUM(M30,S30,U30,W30,AC30,AE30,AG30,AI30,AK30) -> 7894027 | I30: 872202.07 | J30: =I30/$F30 -> 0.11048886 | K30: 1195900.3 | L30: =K30/$F30 -> 0.15149433 | M30: =I30+K30 -> 2068102.4 | N30: =M30/F30 -> 0.26198319 | O30: 363786.14 | P30: =O30/$F30 -> 0.046083721 | Q30: 208411.41 | R30: =Q30/$F30 -> 0.026401152 | S30: =O30+Q30 -> 572197.55 | T30: =S30/F30 -> 0.072484873 | U30: 698698.72 | V30: =U30/F30 -> 0.088509796 | W30: 113281.8 | X30: =W30/$F30 -> 0.014350318 | Y30: 747412.49 | Z30: =Y30/$F30 -> 0.094680761 | AA30: 583843.15 | AB30: =AA30/$F30 -> 0.073960115 | AC30: =Y30+AA30 -> 1331255.6 | AD30: =AC30/$F30 -> 0.16864088 | AE30: 1488193.9 | AF30: =AE30/F30 -> 0.18852151 | AG30: 116718.64 | AH30: =AG30/$F30 -> 0.01478569 | AI30: 1314262 | AJ30: =AI30/$F30 -> 0.16648815 | AK30: 191316.38 | AL30: =AK30/$F30 -> 0.024235587
D31: 45894 | E31: 一 | F31: =SUM(M31,S31,U31,W31,AC31,AE31,AG31,AI31,AK31) -> 7726391.3 | I31: 861464.1 | J31: =I31/$F31 -> 0.11149631 | K31: 1178385.3 | L31: =K31/$F31 -> 0.15251431 | M31: =I31+K31 -> 2039849.4 | N31: =M31/$F31 -> 0.26401062 | O31: 335216.99 | P31: =O31/$F31 -> 0.043385971 | Q31: 212122.75 | R31: =Q31/$F31 -> 0.027454311 | S31: =O31+Q31 -> 547339.74 | T31: =S31/$F31 -> 0.070840282 | U31: 707385.36 | V31: =U31/$F31 -> 0.091554431 | W31: 105252.38 | X31: =W31/$F31 -> 0.01362245 | Y31: 751110.57 | Z31: =Y31/$F31 -> 0.097213633 | AA31: 562370.03 | AB31: =AA31/$F31 -> 0.072785601 | AC31: =Y31+AA31 -> 1313480.6 | AD31: =AC31/$F31 -> 0.16999923 | AE31: 1398384.2 | AF31: =AE31/F31 -> 0.18098802 | AG31: 114886.4 | AH31: =AG31/$F31 -> 0.014869348 | AI31: 1308832.2 | AJ31: =AI31/$F31 -> 0.16939761 | AK31: 190981.04 | AL31: =AK31/$F31 -> 0.024718013
B32: =D40 -> 45903 | D32: 45895 | E32: 二 | F32: =SUM(M32,S32,U32,W32,AC32,AE32,AG32,AI32,AK32) -> 7423824.2 | G32: =SUM(F32:F38) -> 48911413 | I32: 842650.86 | J32: =I32/$F32 -> 0.11350631 | K32: 1145762.5 | L32: =K32/$F32 -> 0.15433589 | M32: =I32+K32 -> 1988413.3 | N32: =M32/F32 -> 0.26784219 | O32: 320661.17 | P32: =O32/$F32 -> 0.04319353 | Q32: 207484.48 | R32: =Q32/$F32 -> 0.027948464 | S32: =O32+Q32 -> 528145.65 | T32: =S32/F32 -> 0.071141993 | U32: 682417.34 | V32: =U32/F32 -> 0.091922616 | W32: 82680.51 | X32: =W32/$F32 -> 0.011137186 | Y32: 733012.91 | Z32: =Y32/$F32 -> 0.098737913 | AA32: 533320.82 | AB32: =AA32/$F32 -> 0.071839096 | AC32: =Y32+AA32 -> 1266333.7 | AD32: =AC32/$F32 -> 0.17057701 | AE32: 1287486.1 | AF32: =AE32/F32 -> 0.17342626 | AG32: 107161.28 | AH32: =AG32/$F32 -> 0.014434781 | AI32: 1296175.7 | AJ32: =AI32/$F32 -> 0.17459677 | AK32: 185010.56 | AL32: =AK32/$F32 -> 0.024921194
D33: 45896 | E33: 三 | F33: =SUM(M33,S33,U33,W33,AC33,AE33,AG33,AI33,AK33) -> 7268105.9 | I33: 839770.28 | J33: =I33/$F33 -> 0.11554183 | K33: 1116611.5 | L33: =K33/$F33 -> 0.15363171 | M33: =I33+K33 -> 1956381.8 | N33: =M33/$F33 -> 0.26917354 | O33: 317414.83 | P33: =O33/$F33 -> 0.04367229 | Q33: 197560.26 | R33: =Q33/$F33 -> 0.027181808 | S33: =O33+Q33 -> 514975.09 | T33: =S33/$F33 -> 0.070854098 | U33: 667417.43 | V33: =U33/$F33 -> 0.091828248 | W33: 79724.71 | X33: =W33/$F33 -> 0.010969118 | Y33: 696912.67 | Z33: =Y33/$F33 -> 0.095886422 | AA33: 475648.24 | AB33: =AA33/$F33 -> 0.065443218 | AC33: =Y33+AA33 -> 1172560.9 | AD33: =AC33/$F33 -> 0.16132964 | AE33: 1293168.5 | AF33: =AE33/F33 -> 0.17792373 | AG33: 101516 | AH33: =AG33/$F33 -> 0.013967325 | AI33: 1299956.4 | AJ33: =AI33/$F33 -> 0.17885766 | AK33: 182405 | AL33: =AK33/$F33 -> 0.025096635
D34: 45897 | E34: 四 | F34: =SUM(M34,S34,U34,W34,AC34,AE34,AG34,AI34,AK34) -> 6765305.7 | I34: 827273.28 | J34: =I34/$F34 -> 0.12228173 | K34: 1028776 | L34: =K34/$F34 -> 0.15206644 | M34: =I34+K34 -> 1856049.3 | N34: =M34/F34 -> 0.27434817 | O34: 306488.28 | P34: =O34/$F34 -> 0.045302946 | Q34: 192799.86 | R34: =Q34/$F34 -> 0.028498322 | S34: =O34+Q34 -> 499288.14 | T34: =S34/F34 -> 0.073801268 | U34: 614875.06 | V34: =U34/F34 -> 0.090886515 | W34: 77381.76 | X34: =W34/$F34 -> 0.011438029 | Y34: 646786.2 | Z34: =Y34/$F34 -> 0.095603396 | AA34: 413163.04 | AB34: =AA34/$F34 -> 0.06107086 | AC34: =Y34+AA34 -> 1059949.2 | AD34: =AC34/$F34 -> 0.15667426 | AE34: 1163189.9 | AF34: =AE34/F34 -> 0.17193457 | AG34: 96861.12 | AH34: =AG34/$F34 -> 0.014317331 | AI34: 1219415 | AJ34: =AI34/$F34 -> 0.18024537 | AK34: 178296.2 | AL34: =AK34/$F34 -> 0.026354493
D35: 45898 | E35: 五 | F35: =SUM(M35,S35,U35,W35,AC35,AE35,AG35,AI35,AK35) -> 5760799.9 | I35: 629840.5 | J35: =I35/$F35 -> 0.10933213 | K35: 939469.28 | L35: =K35/$F35 -> 0.16307966 | M35: =I35+K35 -> 1569309.8 | N35: =M35/$F35 -> 0.27241178 | O35: 239787.18 | P35: =O35/$F35 -> 0.041623938 | Q35: 166844.3 | R35: =Q35/$F35 -> 0.028962002 | S35: =O35+Q35 -> 406631.48 | T35: =S35/$F35 -> 0.070585941 | U35: 528955.49 | V35: =U35/$F35 -> 0.091819799 | W35: 73950.1 | X35: =W35/$F35 -> 0.012836776 | Y35: 552893.37 | Z35: =Y35/$F35 -> 0.095975104 | AA35: 418581.21 | AB35: =AA35/$F35 -> 0.072660258 | AC35: =Y35+AA35 -> 971474.58 | AD35: =AC35/$F35 -> 0.16863536 | AE35: 869604.68 | AF35: =AE35/F35 -> 0.15095207 | AG35: 83193.6 | AH35: =AG35/$F35 -> 0.014441328 | AI35: 1099490.1 | AJ35: =AI35/$F35 -> 0.19085719 | AK35: 158190.1 | AL35: =AK35/$F35 -> 0.027459746
D36: 45899 | E36: 六 | F36: =SUM(M36,S36,U36,W36,AC36,AE36,AG36,AI36,AK36) -> 6161593.8 | I36: 604104.1 | J36: =I36/$F36 -> 0.09804348 | K36: 1074398.9 | L36: =K36/$F36 -> 0.17437028 | M36: =I36+K36 -> 1678503 | N36: =M36/F36 -> 0.27241376 | O36: 235559.91 | P36: =O36/$F36 -> 0.038230354 | Q36: 171855.07 | R36: =Q36/$F36 -> 0.027891334 | S36: =O36+Q36 -> 407414.98 | T36: =S36/F36 -> 0.066121688 | U36: 548781.84 | V36: =U36/F36 -> 0.089064917 | W36: 83288.54 | X36: =W36/$F36 -> 0.013517369 | Y36: 575890.97 | Z36: =Y36/$F36 -> 0.093464611 | AA36: 556021.18 | AB36: =AA36/$F36 -> 0.09023983 | AC36: =Y36+AA36 -> 1131912.1 | AD36: =AC36/$F36 -> 0.18370444 | AE36: 936764.86 | AF36: =AE36/F36 -> 0.15203288 | AG36: 90968.24 | AH36: =AG36/$F36 -> 0.014763752 | AI36: 1110801.5 | AJ36: =AI36/$F36 -> 0.18027827 | AK36: 173158.74 | AL36: =AK36/$F36 -> 0.028102914
D37: 45900 | E37: 日 | F37: =SUM(M37,S37,U37,W37,AC37,AE37,AG37,AI37,AK37) -> 7725142.4 | I37: 868294.42 | J37: =I37/$F37 -> 0.1123985 | K37: 1191648 | L37: =K37/$F37 -> 0.1542558 | M37: =I37+K37 -> 2059942.4 | N37: =M37/$F37 -> 0.2666543 | O37: 341134.58 | P37: =O37/$F37 -> 0.044159002 | Q37: 205826.31 | R37: =Q37/$F37 -> 0.026643691 | S37: =O37+Q37 -> 546960.89 | T37: =S37/$F37 -> 0.070802694 | U37: 712487.81 | V37: =U37/$F37 -> 0.092229732 | W37: 96736.97 | X37: =W37/$F37 -> 0.012522354 | Y37: 750918.44 | Z37: =Y37/$F37 -> 0.097204479 | AA37: 528276.45 | AB37: =AA37/$F37 -> 0.068384041 | AC37: =Y37+AA37 -> 1279194.9 | AD37: =AC37/$F37 -> 0.16558852 | AE37: 1424431.1 | AF37: =AE37/F37 -> 0.18438898 | AG37: 112757.04 | AH37: =AG37/$F37 -> 0.014596112 | AI37: 1302963.7 | AJ37: =AI37/$F37 -> 0.16866533 | AK37: 189667.54 | AL37: =AK37/$F37 -> 0.02455198
D38: 45901 | E38: 一 | F38: =SUM(M38,S38,U38,W38,AC38,AE38,AG38,AI38,AK38) -> 7806641.3 | H38: =SUM(F38:F67) -> 1.0877328e+08 | I38: 848588.53 | J38: =I38/$F38 -> 0.10870085 | K38: 1224661.8 | L38: =K38/$F38 -> 0.15687435 | M38: =I38+K38 -> 2073250.3 | N38: =M38/F38 -> 0.2655752 | O38: 328547.87 | P38: =O38/$F38 -> 0.042085688 | Q38: 209476.46 | R38: =Q38/$F38 -> 0.026833109 | S38: =O38+Q38 -> 538024.33 | T38: =S38/F38 -> 0.068918797 | U38: 702181.23 | V38: =U38/F38 -> 0.089946649 | W38: 89181.09 | X38: =W38/$F38 -> 0.011423746 | Y38: 739848.56 | Z38: =Y38/$F38 -> 0.094771686 | AA38: 799901.73 | AB38: =AA38/$F38 -> 0.10246426 | AC38: =Y38+AA38 -> 1539750.3 | AD38: =AC38/$F38 -> 0.19723595 | AE38: 1311208.1 | AF38: =AE38/F38 -> 0.16796059 | AG38: 104536.72 | AH38: =AG38/$F38 -> 0.013390742 | AI38: 1261294.4 | AJ38: =AI38/$F38 -> 0.16156685 | AK38: 187214.86 | AL38: =AK38/$F38 -> 0.023981486
B39: =D47 -> 45910 | D39: 45902 | E39: 二 | F39: =SUM(M39,S39,U39,W39,AC39,AE39,AG39,AI39,AK39) -> 8169292.4 | G39: =SUM(F39:F45) -> 50724262 | I39: 1302143.7 | J39: =I39/$F39 -> 0.15939492 | K39: 1245426.8 | L39: =K39/$F39 -> 0.15245222 | M39: =I39+K39 -> 2547570.5 | N39: =M39/$F39 -> 0.31184714 | O39: 321541.51 | P39: =O39/$F39 -> 0.039359775 | Q39: 214295.64 | R39: =Q39/$F39 -> 0.026231848 | S39: =O39+Q39 -> 535837.15 | T39: =S39/$F39 -> 0.065591623 | U39: 681820.89 | V39: =U39/$F39 -> 0.083461438 | W39: 81275.72 | X39: =W39/$F39 -> 0.0099489302 | Y39: 715738.99 | Z39: =Y39/$F39 -> 0.087613339 | AA39: 839618.3 | AB39: =AA39/$F39 -> 0.10277736 | AC39: =Y39+AA39 -> 1555357.3 | AD39: =AC39/$F39 -> 0.1903907 | AE39: 1297300 | AF39: =AE39/F39 -> 0.158802 | AG39: 99436.16 | AH39: =AG39/$F39 -> 0.012171943 | AI39: 1187007.9 | AJ39: =AI39/$F39 -> 0.14530119 | AK39: 183686.8 | AL39: =AK39/$F39 -> 0.022485032
D40: 45903 | E40: 三 | F40: =SUM(M40,S40,U40,W40,AC40,AE40,AG40,AI40,AK40) -> 7774607.2 | I40: 1232066.8 | J40: =I40/$F40 -> 0.15847319 | K40: 1207209.5 | L40: =K40/$F40 -> 0.15527595 | M40: =I40+K40 -> 2439276.3 | N40: =M40/F40 -> 0.31374914 | O40: 296103.12 | P40: =O40/$F40 -> 0.038085927 | Q40: 203555.42 | R40: =Q40/$F40 -> 0.026182084 | S40: =O40+Q40 -> 499658.54 | T40: =S40/F40 -> 0.064268011 | U40: 654758.87 | V40: =U40/F40 -> 0.084217614 | W40: 79250.32 | X40: =W40/$F40 -> 0.010193482 | Y40: 673547.3 | Z40: =Y40/$F40 -> 0.086634255 | AA40: 730602 | AB40: =AA40/$F40 -> 0.093972851 | AC40: =Y40+AA40 -> 1404149.3 | AD40: =AC40/$F40 -> 0.18060711 | AE40: 1269715.2 | AF40: =AE40/F40 -> 0.16331567 | AG40: 98792.4 | AH40: =AG40/$F40 -> 0.01270706 | AI40: 1150287.3 | AJ40: =AI40/$F40 -> 0.1479544 | AK40: 178718.96 | AL40: =AK40/$F40 -> 0.022987523
D41: 45904 | E41: 四 | F41: =SUM(M41,S41,U41,W41,AC41,AE41,AG41,AI41,AK41) -> 6925705.3 | I41: 1129887.6 | J41: =I41/$F41 -> 0.16314405 | K41: 1068397.7 | L41: =K41/$F41 -> 0.15426554 | M41: =I41+K41 -> 2198285.3 | N41: =M41/$F41 -> 0.31740959 | O41: 278699.43 | P41: =O41/$F41 -> 0.040241306 | Q41: 205084.15 | R41: =Q41/$F41 -> 0.029612024 | S41: =O41+Q41 -> 483783.58 | T41: =S41/$F41 -> 0.06985333 | U41: 610503.39 | V41: =U41/$F41 -> 0.088150356 | W41: 75191.45 | X41: =W41/$F41 -> 0.010856865 | Y41: 614110.43 | Z41: =Y41/$F41 -> 0.088671175 | AA41: 502137.16 | AB41: =AA41/$F41 -> 0.072503397 | AC41: =Y41+AA41 -> 1116247.6 | AD41: =AC41/$F41 -> 0.16117457 | AE41: 1122214.9 | AF41: =AE41/F41 -> 0.16203618 | AG41: 88888.4 | AH41: =AG41/$F41 -> 0.012834563 | AI41: 1068726.1 | AJ41: =AI41/$F41 -> 0.15431297 | AK41: 161864.62 | AL41: =AK41/$F41 -> 0.023371572
...

Sheet （４）訂單數量構成比
B2: （4）訂單數量構成比
B3: 資料繳交日 | C3: 月份 | D3: 日期 | F3: 訂單量 | I3: 品類訂單量
I4: 18℃-飯糰 | O4: 18℃-壽司手卷 | U4: 4℃-飯糰 | W4: 4℃-壽司手卷 | Y4: 主食 | AE4: 便當 | AG4: 熱食義麵 | AI4: 季節調理麵 | AK4: 微波小吃
F5: 日 | G5: 週累積 | H5: 月累積 | I5: 一配 | K5: 二配 | M5: 合計 | O5: 一配 | Q5: 二配 | S5: 合計 | U5: 一配 | W5: 一配 | Y5: 一配 | AA5: 二配 | AC5: 合計 | AE5: 一配 | AG5: 一配 | AI5: 一配 | AK5: 一配
I6: 訂單數 | J6: 比例(%) | K6: 訂單數 | L6: 比例(%) | M6: 訂單數 | N6: 比例(%) | O6: 訂單數 | P6: 比例(%) | Q6: 訂單數 | R6: 比例(%) | S6: 訂單數 | T6: 比例(%) | U6: 訂單數 | V6: 比例(%) | W6: 訂單數 | X6: 比例(%) | Y6: 訂單數 | Z6: 比例(%) | AA6: 訂單數 | AB6: 比例(%) | AC6: 訂單數 | AD6: 比例(%) | AE6: 訂單數 | AF6: 比例(%) | AG6: 訂單數 | AH6: 比例(%) | AI6: 訂單數 | AJ6: 比例(%) | AK6: 訂單數 | AL6: 比例(%)
B7: =D19 -> 45882 | C7: 八 | D7: 45870 | E7: 五 | F7: =SUM(M7,S7,U7,W7,AC7,AE7,AG7,AI7,AK7) -> 183531 | G7: =SUM(F7:F10) -> 876019 | H7: =SUM(F7:F37) -> 7168725 | I7: 31628 | J7: =I7/$F7 -> 0.17233056 | K7: 50104 | L7: =K7/$F7 -> 0.2730002 | M7: =I7+K7 -> 81732 | N7: =M7/$F7 -> 0.44533076 | O7: 9137 | P7: =O7/$F7 -> 0.049784505 | Q7: 6171 | R7: =Q7/$F7 -> 0.033623747 | S7: =O7+Q7 -> 15308 | T7: =S7/$F7 -> 0.083408253 | U7: 13104 | V7: =U7/$F7 -> 0.071399382 | W7: 1539 | X7: =W7/$F7 -> 0.0083855044 | Y7: 6704 | Z7: =Y7/$F7 -> 0.036527889 | AA7: 9062 | AB7: =AA7/$F7 -> 0.049375855 | AC7: =Y7+AA7 -> 15766 | AD7: =AC7/$F7 -> 0.085903744 | AE7: 17811 | AF7: =AE7/$F7 -> 0.097046276 | AG7: 2890 | AH7: =AG7/$F7 -> 0.015746659 | AI7: 29829 | AJ7: =AI7/$F7 -> 0.1625284 | AK7: 5552 | AL7: =AK7/$F7 -> 0.03025102
D8: 45871 | E8: 六 | F8: =SUM(M8,S8,U8,W8,AC8,AE8,AG8,AI8,AK8) -> 197498 | I8: 30584 | J8: =I8/$F8 -> 0.15485726 | K8: 57366 | L8: =K8/$F8 -> 0.2904637 | M8: =I8+K8 -> 87950 | N8: =M8/$F8 -> 0.44532097 | O8: 9109 | P8: =O8/$F8 -> 0.046121986 | Q8: 6337 | R8: =Q8/$F8 -> 0.032086401 | S8: =O8+Q8 -> 15446 | T8: =S8/$F8 -> 0.078208387 | U8: 13610 | V8: =U8/$F8 -> 0.06891209 | W8: 1716 | X8: =W8/$F8 -> 0.0086886956 | Y8: 7259 | Z8: =Y8/$F8 -> 0.036754803 | AA8: 11318 | AB8: =AA8/$F8 -> 0.057306909 | AC8: =Y8+AA8 -> 18577 | AD8: =AC8/$F8 -> 0.094061712 | AE8: 18950 | AF8: =AE8/$F8 -> 0.095950339 | AG8: 2878 | AH8: =AG8/$F8 -> 0.014572299 | AI8: 32821 | AJ8: =AI8/$F8 -> 0.16618396 | AK8: 5550 | AL8: =AK8/$F8 -> 0.02810155
