Workbook

Sheet 數值累積總表(月)
B1: 項目 | D1: 1月 | E1: 2月 | F1: 3月 | G1: 4月 | H1: 5月 | I1: 6月 | J1: 7月 | K1: 8月 | L1: 9月 | M1: 10月 | N1: 11月 | O1: 12月 | P1: 合計/平均
B2: （１）收支狀況 | C2: 業績金額(千元) | D2: 146299.94 | E2: 116569.43 | F2: 148838 | G2: 160648.31 | H2: 181836.63 | P2: =SUM(D2:O2) -> 754192.31
C3: 訂單數量 | D3: 4768701 | E3: 3787002 | F3: 5045753 | G3: 5396292 | H3: 6084520 | P3: =SUM(D3:O3) -> 25082268
C4: 材料費(千元) | D4: 93253 | E4: 74777 | F4: 93614 | G4: 104435 | H4: 116562 | P4: =SUM(D4:O4) -> 482641
C5: 材料費率(%) | D5: 0.655 | E5: 0.653 | F5: 0.648 | G5: 0.663 | H5: 0.672 | I5: =IFERROR(I4/I2, "") | J5: =IFERROR(J4/J2, "") | K5: =IFERROR(K4/K2, "") | L5: =IFERROR(L4/L2, "") | M5: =IFERROR(M4/M2, "") | N5: =IFERROR(N4/N2, "") | O5: =IFERROR(O4/O2, "") | P5: =AVERAGEIF(D5:O5, ">0") -> 0.6582
C6: 勞務成本(千元) | D6: 22378 | E6: 22860 | F6: 22710 | G6: 23226 | H6: 24474 | P6: =SUM(D6:O6) -> 115648
C7: 勞務費率(%) | D7: 0.157 | E7: 0.2 | F7: 0.157 | G7: 0.147 | H7: 0.141 | I7: =IFERROR(I6/I2, "") | J7: =IFERROR(J6/J2, "") | K7: =IFERROR(K6/K2, "") | L7: =IFERROR(L6/L2, "") | M7: =IFERROR(M6/M2, "") | N7: =IFERROR(N6/N2, "") | O7: =IFERROR(O6/O2, "") | P7: =AVERAGEIF(D7:O7, ">0") -> 0.1604
B9: （２）ＫＰＩ達成進度 | C9: 人時性KPI | D9: 497.6 | E9: 497.6 | F9: 497.6 | G9: 497.6 | H9: 497.6 | P9: =AVERAGEIF(D9:O9, ">0") -> 497.6
C10: 人時性(個/月均) | D10: 458.38414 | E10: 476.04172 | F10: 409.81563 | G10: 402.86432 | H10: 419.38046 | P10: =AVERAGEIF(D10:O10, ">0") -> 433.29725
C11: 人時達成率(%/月均) | D11: =IFERROR(D10/D9, "") -> 0.92118999 | E11: =IFERROR(E10/E9, "") -> 0.95667547 | F11: =IFERROR(F10/F9, "") -> 0.82358447 | G11: =IFERROR(G10/G9, "") -> 0.80961479 | H11: 0.94796667 | I11: =IFERROR(I10/I9, "") | J11: =IFERROR(J10/J9, "") | K11: =IFERROR(K10/K9, "") | L11: =IFERROR(L10/L9, "") | M11: =IFERROR(M10/M9, "") | N11: =IFERROR(N10/N9, "") | O11: =IFERROR(O10/O9, "") | P11: =AVERAGEIF(D11:O11, ">0") -> 0.89180628
C12: 半成品-報廢(%) | D12: 0.0024135432 | E12: 0.0023657636 | F12: 0.0020222248 | G12: 0.0020113648 | H12: 0.002008824 | P12: =AVERAGEIF(D12:O12, ">0") -> 0.0021643441
C13: 半成品-超用(%) | D13: 0.0055994433 | E13: 0.0052393001 | F13: 0.0048799138 | G13: 0.0043085188 | H13: 0.0061874817 | P13: =AVERAGEIF(D13:O13, ">0") -> 0.0052429315
C14: 固定產線-導入率(%) | D14: 0.9 | E14: 0.9 | F14: 0.9 | G14: 0.9 | H14: 0.9 | P14: =AVERAGEIF(D14:O14, ">0") -> 0.9
C15: 教育訓練-實施率(%) | D15: 0.057692308 | E15: 0.13873626 | F15: 0.21960298 | G15: 0.30384615 | H15: 0.38709677 | P15: =MAX(D15:O15) -> 0.38709677
B17: （３）業績構成比 | C17: 18℃-飯糰(061,063) | D17: 0.36139567 | E17: 0.34737657 | F17: 0.36414345 | G17: 0.38079956 | H17: 0.3631831 | P17: =AVERAGEIF(D17:O17, ">0") -> 0.36337967
C18: 18℃-壽司手卷(071,072,075,076) | D18: 0.069633574 | E18: 0.077793665 | F18: 0.084480826 | G18: 0.060267904 | H18: 0.041707027 | P18: =AVERAGEIF(D18:O18, ">0") -> 0.066776599
C19: 4℃-飯糰(065) | D19: 0.022453222 | E19: 0.02167645 | F19: 0.02436516 | G19: 0.018891118 | H19: 0.013969 | P19: =AVERAGEIF(D19:O19, ">0") -> 0.02027099
C20: 4℃-壽司手卷(077) | D20: 0.008585039 | E20: 0.0099523222 | F20: 0.014684918 | G20: 0.028316296 | H20: 0.034128078 | P20: =AVERAGEIF(D20:O20, ">0") -> 0.019133331
C21: 主食(091,092,093,094,095) | D21: 0.16215294 | E21: 0.18214708 | F21: 0.20289324 | G21: 0.15628268 | H21: 0.13415544 | P21: =AVERAGEIF(D21:O21, ">0") -> 0.16752628
C22: 便當(083) | D22: 0.27057088 | E22: 0.27529226 | F22: 0.29293399 | G22: 0.27842234 | H22: 0.26474822 | P22: =AVERAGEIF(D22:O22, ">0") -> 0.27639354
C23: 熱食義麵(122,123,124,126) | D23: 0.029234371 | E23: 0.0089796819 | F23: 0 | G23: 0 | H23: 0 | P23: =AVERAGEIF(D23:O23, ">0") -> 0.019107026
C24: 季節調理麵(111,112) | D24: 0.040564166 | E24: 0.040109499 | F24: 0.0016541185 | G24: 0.064343547 | H24: 0.13502459 | P24: =AVERAGEIF(D24:O24, ">0") -> 0.056339185
C25: 微波小吃(153,154,155) | D25: 0.035410133 | E25: 0.036672477 | F25: 0.01484429 | G25: 0.012676559 | H25: 0.013084541 | P25: =AVERAGEIF(D25:O25, ">0") -> 0.0225376
B27: （４）訂單數量構成比 | C27: 18℃-飯糰(061,063) | D27: 0.58577126 | E27: 0.57025346 | F27: 0.57640852 | G27: 0.58366912 | H27: 0.56064801 | P27: =AVERAGEIF(D27:O27, ">0") -> 0.57535007
C28: 18℃-壽司手卷(071,072,075,076) | D28: 0.081693946 | E28: 0.091615478 | F28: 0.10179987 | G28: 0.068907687 | H28: 0.044634581 | P28: =AVERAGEIF(D28:O28, ">0") -> 0.077730312
C29: 4℃-飯糰(065) | D29: 0.024966128 | E29: 0.023825971 | F29: 0.026809081 | G29: 0.020313393 | H29: 0.014309264 | P29: =AVERAGEIF(D29:O29, ">0") -> 0.022044767
C30: 4℃-壽司手卷(077) | D30: 0.0097963785 | E30: 0.011706622 | F30: 0.016401516 | G30: 0.031347822 | H30: 0.048132803 | P30: =AVERAGEIF(D30:O30, ">0") -> 0.023477028
C31: 主食(091,092,093,094,095) | D31: 0.089953008 | E31: 0.10114835 | F31: 0.11343936 | G31: 0.089562981 | H31: 0.075610895 | P31: =AVERAGEIF(D31:O31, ">0") -> 0.093942919
C32: 便當(083) | D32: 0.13708178 | E32: 0.14060779 | F32: 0.14223546 | G32: 0.13317793 | H32: 0.12743437 | P32: =AVERAGEIF(D32:O32, ">0") -> 0.13610747
C33: 熱食義麵(122,123,124,126) | D33: 0.015652481 | E33: 0.0048238686 | F33: 0 | G33: 0 | H33: 0 | P33: =AVERAGEIF(D33:O33, ">0") -> 0.010238175
C34: 季節調理麵(111,112) | D34: 0.022004735 | E34: 0.020902022 | F34: 0.00067918505 | G34: 0.05386458 | H34: 0.1102248 | P34: =AVERAGEIF(D34:O34, ">0") -> 0.041535064
C35: 微波小吃(153,154,155) | D35: 0.033080287 | E35: 0.035116432 | F35: 0.02222701 | G35: 0.019156487 | H35: 0.019005279 | P35: =AVERAGEIF(D35:O35, ">0") -> 0.025717099
B37: （５）品群別人時生產性 | C37: 18℃-飯糰(061,063) | D37: 768.96509 | E37: 774.12086 | F37: 757.59042 | G37: 740.76981 | H37: 765.35782 | P37: =AVERAGEIF(D37:O37, ">0") -> 761.3608
C38: 18℃-壽司手卷(071,072,075,076) | D38: 280.52358 | E38: 304.46478 | F38: 311.70582 | G38: 320.67204 | H38: 308.11597 | P38: =AVERAGEIF(D38:O38, ">0") -> 305.09644
C39: 4℃-飯糰(065) | D39: 258.56167 | E39: 203.24374 | F39: 331.13667 | G39: 331.07659 | H39: 209.58696 | P39: =AVERAGEIF(D39:O39, ">0") -> 266.72113
C40: 4℃-壽司手卷(077) | D40: 486.07171 | E40: 490.19814 | F40: 493.97618 | G40: 416.8019 | H40: 367.70757 | P40: =AVERAGEIF(D40:O40, ">0") -> 450.9511
C41: 主食(091,092,093,094,095) | D41: 82.669482 | E41: 81.452412 | F41: 79.949999 | G41: 82.282454 | H41: 81.903989 | P41: =AVERAGEIF(D41:O41, ">0") -> 81.651667
C42: 便當(083) | D42: 78.306367 | E42: 77.971323 | F42: 77.906797 | G42: 78.189351 | H42: 79.190462 | P42: =AVERAGEIF(D42:O42, ">0") -> 78.31286
C43: 熱食義麵(122,123,124,126) | D43: 76.250133 | E43: 72.949976 | F43: 0 | G43: 0 | H43: 0 | P43: =AVERAGEIF(D43:O43, ">0") -> 74.600054
C44: 季節調理麵(111,112) | D44: 110.8083 | E44: 97.157501 | F44: 84.601424 | G44: 159.74229 | H44: 161.80618 | P44: =AVERAGEIF(D44:O44, ">0") -> 122.82314
...

Sheet 生產管理報表(月)
A1: 大溪廠生產管理報表
A3: 月別 | B3: 5 | C3: 工廠 | D3: 大溪廠
A4: （１）收支狀況 | E4: ※單位：千元 | G4: （２）ＫＰＩ達成進度
A5: 項目 | B5: 當月 | C5: 前月 | D5: 差異 | E5: 累計 | G5: 項目 | H5: KPI | I5: 當月 | J5: 前月 | K5: 累計 | L5: ※補充
A6: 業績金額 | B6: ='（１）收支狀況'!H11/1000 -> 53412.637 | C6: 181836.63 | D6: =B6-C6 -> -128423.99 | E6: ='數值累積總表(月)'!P2 -> 754192.31 | G6: 人時性(個/月均) | H6: 497.6 | I6: ='（２）ＫＰＩ達成進度'!H11 -> 433.03614 | J6: 419.38046 | K6: ='數值累積總表(月)'!P10 -> 433.29725 | L6: 個／MH
A7: 訂單數量 | B7: ='（１）收支狀況'!K11 -> 1760864 | C7: 6084520 | D7: =B7-C7 -> -4323656 | E7: ='數值累積總表(月)'!P3 -> 25082268 | G7: 人時達成率(%/月均) | H7: 0.8 | I7: ='（２）ＫＰＩ達成進度'!K11 -> 0.97883395 | J7: 0.94796667 | K7: ='數值累積總表(月)'!P11 -> 0.89180628 | L7: 達成率
A8: 材料費 | B8: ='（１）收支狀況'!N11/1000 -> 36078.352 | C8: 122511 | D8: =B8-C8 -> -86432.646 | E8: ='數值累積總表(月)'!P4 -> 482641 | G8: 半成品-報廢(%) | H8: 0.0025 | I8: ='（２）ＫＰＩ達成進度'!N11 -> 0.002009727 | J8: 0.002008824 | K8: ='數值累積總表(月)'!P12 -> 0.0021643441 | L8: 報廢率
A9: 材料費率 | B9: ='（１）收支狀況'!Q11 -> 0.67546472 | C9: 0.67374214 | D9: =B9-C9 -> 0.001722582 | E9: ='數值累積總表(月)'!P5 -> 0.6582 | G9: 半成品-超用(%) | H9: 0.004 | I9: ='（２）ＫＰＩ達成進度'!Q11 -> 0.006149808 | J9: 0.0061874817 | K9: ='數值累積總表(月)'!P13 -> 0.0052429315 | L9: 超用率
A10: 勞務成本 | B10: ='（１）收支狀況'!T11/1000 -> 7300.0896 | C10: 25634.58 | D10: =B10-C10 -> -18334.491 | E10: ='數值累積總表(月)'!P6 -> 115648 | G10: 固定產線-導入率(%) | H10: 0.8 | I10: ='（２）ＫＰＩ達成進度'!T11 -> 0.9 | J10: 0.9 | K10: ='數值累積總表(月)'!P14 -> 0.9 | L10: 導入率
A11: 勞務費率 | B11: ='（１）收支狀況'!W11 -> 0.13667346 | C11: 0.14097589 | D11: =B11-C11 -> -0.0043024356 | E11: ='數值累積總表(月)'!P7 -> 0.1604 | G11: 教育訓練-實施率(%) | H11: 1 | I11: ='（２）ＫＰＩ達成進度'!W11 -> 0.43990385 | J11: 0.38709677 | K11: ='數值累積總表(月)'!P15 -> 0.38709677 | L11: 實施率
A13: （３）業績構成比 | E13: ※單位：千元 | G13: （４）訂單數量構成比 | K13: ※單位：個
B14: 當月 | C14: 比例 | D14: 前月 | E14: 差異 | H14: 當月 | I14: 比例 | J14: 前月 | K14: 差異
A15: 18℃-飯糰(061,063) | B15: =SUM('（３）業績構成比'!M7:M12)/1000 -> 12726.262 | C15: =IFERROR(B15/$B$6,"") -> 0.23826314 | D15: 0.3631831 | E15: =IFERROR(C15-D15,"") -> -0.12491996 | G15: 18℃-飯糰(061,063) | H15: =SUM('（４）訂單數量構成比'!M7:M12) -> 666176 | I15: =IFERROR(H15/$B$7,"") -> 0.37832337 | J15: 0.56064801 | K15: =IFERROR(I15-J15,"") -> -0.18232464
A16: 18℃-壽司手卷(071,072,075,076) | B16: =SUM('（３）業績構成比'!S7:S12)/1000 -> 1435.3239 | C16: =IFERROR(B16/$B$6,"") -> 0.026872365 | D16: 0.041707027 | E16: =IFERROR(C16-D16,"") -> -0.014834662 | G16: 18℃-壽司手卷(071,072,075,076) | H16: =SUM('（４）訂單數量構成比'!S7:S12) -> 49700 | I16: =IFERROR(H16/$B$7,"") -> 0.028224781 | J16: 0.044634581 | K16: =IFERROR(I16-J16,"") -> -0.0164098
A17: 4℃-飯糰(065) | B17: =SUM('（３）業績構成比'!U7:U12)/1000 -> 429.61995 | C17: =IFERROR(B17/$B$6,"") -> 0.008043414 | D17: 0.013969 | E17: =IFERROR(C17-D17,"") -> -0.0059255861 | G17: 4℃-飯糰(065) | H17: =SUM('（４）訂單數量構成比'!U7:U12) -> 14335 | I17: =IFERROR(H17/$B$7,"") -> 0.0081408899 | J17: 0.014309264 | K17: =IFERROR(I17-J17,"") -> -0.0061683736
A18: 4℃-壽司手卷(077) | B18: =SUM('（３）業績構成比'!W7:W12)/1000 -> 2413.7967 | C18: =IFERROR(B18/$B$6,"") -> 0.04519149 | D18: 0.034128078 | E18: =IFERROR(C18-D18,"") -> 0.011063412 | G18: 4℃-壽司手卷(077) | H18: =SUM('（４）訂單數量構成比'!W7:W12) -> 93777 | I18: =IFERROR(H18/$B$7,"") -> 0.053256242 | J18: 0.048132803 | K18: =IFERROR(I18-J18,"") -> 0.0051234398
A19: 主食(091,092,093,094,095) | B19: =SUM('（３）業績構成比'!AC7:AC12)/1000 -> 4370.9224 | C19: =IFERROR(B19/$B$6,"") -> 0.081833114 | D19: 0.13415544 | E19: =IFERROR(C19-D19,"") -> -0.052322325 | G19: 主食(091,092,093,094,095) | H19: =SUM('（４）訂單數量構成比'!AC7:AC12) -> 80914 | I19: =IFERROR(H19/$B$7,"") -> 0.045951306 | J19: 0.075610895 | K19: =IFERROR(I19-J19,"") -> -0.029659589
A20: 便當(083) | B20: =SUM('（３）業績構成比'!AE7:AE12)/1000 -> 9225.3851 | C20: =IFERROR(B20/$B$6,"") -> 0.17271915 | D20: 0.26474822 | E20: =IFERROR(C20-D20,"") -> -0.092029073 | G20: 便當(083) | H20: =SUM('（４）訂單數量構成比'!AE7:AE12) -> 147494 | I20: =IFERROR(H20/$B$7,"") -> 0.083762289 | J20: 0.12743437 | K20: =IFERROR(I20-J20,"") -> -0.043672085
A21: 熱食義麵(122,123,124,126) | B21: =SUM('（３）業績構成比'!AG7:AG12)/1000 -> 0 | C21: =IFERROR(B21/$B$6,"") -> 0 | D21: 0 | E21: =IFERROR(C21-D21,"") -> 0 | G21: 熱食義麵(122,123,124,126) | H21: =SUM('（４）訂單數量構成比'!AG7:AG12) -> 0 | I21: =IFERROR(H21/$B$7,"") -> 0 | J21: 0 | K21: =IFERROR(I21-J21,"") -> 0
A22: 季節調理麵(111,112) | B22: =SUM('（３）業績構成比'!AI7:AI12)/1000 -> 7523.4979 | C22: =IFERROR(B22/$B$6,"") -> 0.14085614 | D22: 0.13502459 | E22: =IFERROR(C22-D22,"") -> 0.0058315476 | G22: 季節調理麵(111,112) | H22: =SUM('（４）訂單數量構成比'!AI7:AI12) -> 203616 | I22: =IFERROR(H22/$B$7,"") -> 0.11563414 | J22: 0.1102248 | K22: =IFERROR(I22-J22,"") -> 0.0054093433
A23: 微波小吃(153,154,155) | B23: =SUM('（３）業績構成比'!AK7:AK12)/1000 -> 663.33942 | C23: =IFERROR(B23/$B$6,"") -> 0.012419148 | D23: 0.013084541 | E23: =IFERROR(C23-D23,"") -> -0.00066539354 | G23: 微波小吃(153,154,155) | H23: =SUM('（４）訂單數量構成比'!AK7:AK12) -> 28536 | I23: =IFERROR(H23/$B$7,"") -> 0.016205681 | J23: 0.019005279 | K23: =IFERROR(I23-J23,"") -> -0.0027995981
C24: =SUM(C15:C23) -> 0.72619796 | D24: =SUM(D15:D23) -> 1 | I24: =SUM(I15:I23) -> 0.7294987 | J24: =SUM(J15:J23) -> 1
A26: （５）品群別人時生產性
A27: 品群 | B27: 當月 | C27: 前月 | D27: 差異 | E27: 累計
A28: 18℃-飯A15:A23糰(061,063) | B28: ='（５-1）品群別人時生產性(18℃-飯糰)'!C1 -> 791.32419 | C28: 765.35782 | D28: =B28-C28 -> 25.966374 | E28: ='數值累積總表(月)'!P37 -> 761.3608
A29: 18℃-壽司手卷(071,072,075,076) | B29: ='（５-2）品群別人時生產性(18℃-壽司手卷)'!C1 -> 298.03264 | C29: 308.11597 | D29: =B29-C29 -> -10.083335 | E29: ='數值累積總表(月)'!P38 -> 305.09644
A30: 4℃-飯糰(065) | B30: ='（５-3）品群別人時生產性(4℃-飯糰)'!C1 -> 118.59923 | C30: 209.58696 | D30: =B30-C30 -> -90.987733 | E30: ='數值累積總表(月)'!P39 -> 266.72113
A31: 4℃-壽司手卷(077) | B31: ='（５-4）品群別人時生產性(4℃-壽司手卷)'!C1 -> 370.29269 | C31: 367.70757 | D31: =B31-C31 -> 2.5851246 | E31: ='數值累積總表(月)'!P40 -> 450.9511
A32: 主食(091,092,093,094,095) | B32: ='（５-5）品群別人時生產性(微波主食) '!C1 -> 83.410714 | C32: 81.903989 | D32: =B32-C32 -> 1.506725 | E32: ='數值累積總表(月)'!P41 -> 81.651667
A33: 便當(083) | B33: ='（５-6）品群別人時生產性(便當)'!C1 -> 79.415025 | C33: 79.190462 | D33: =B33-C33 -> 0.22456312 | E33: ='數值累積總表(月)'!P42 -> 78.31286
A34: 熱食義麵(122,123,124,126) | B34: ='（５-7）品群別人時生產性(熱食義麵) '!C1 -> 0 | C34: 0 | D34: =B34-C34 -> 0 | E34: ='數值累積總表(月)'!P43 -> 74.600054
A35: 季節調理麵(111,112) | B35: ='（５-8）品群別人時生產性(季節調理麵) '!C1 -> 156.76906 | C35: 161.80618 | D35: =B35-C35 -> -5.0371259 | E35: ='數值累積總表(月)'!P44 -> 122.82314
A36: 微波小吃(153,154,155) | B36: ='（５-9）品群別人時生產性(微波小吃)'!C1 -> 121.82808 | C36: 89.419713 | D36: =B36-C36 -> 32.408366 | E36: ='數值累積總表(月)'!P45 -> 81.848904

Sheet 生產管理報表(週) 
A1: 大溪廠生產管理報表
A3: 月別 | B3: 6 | C3: 週別 | D3: W1 | E3: 工廠 | F3: 大溪廠
A4: （１）收支狀況 | E4: ※單位：千元 | G4: （２）ＫＰＩ達成進度
A5: 項目 | B5: 當週 | C5: 前週 | D5: 差異 | E5: 累計 | G5: 項目 | H5: KPI | I5: 當週 | J5: 前週 | K5: 累計 | L5: ※補充
A6: 業績金額 | B6: ='（１）收支狀況'!G12/1000 -> 46456.915 | C6: 45743.869 | D6: =B6-C6 -> 713.04633 | E6: ='（１）收支狀況'!H11:H11/1000 -> 53412.637 | G6: 人時性(個/月均) | H6: 442.4 | I6: ='（２）ＫＰＩ達成進度'!G12 -> 433.10659 | J6: 428.73368 | K6: ='（２）ＫＰＩ達成進度'!H11 -> 433.03614 | L6: 個／MH
A7: 訂單數量 | B7: ='（１）收支狀況'!J12 -> 1530504 | C7: 1514908 | D7: =B7-C7 -> 15596 | E7: ='（１）收支狀況'!K11:K11 -> 1760864 | G7: 人時達成率(%/月均) | H7: 0.8 | I7: ='（２）ＫＰＩ達成進度'!J12 -> 0.97899319 | J7: 0.96910868 | K7: ='（２）ＫＰＩ達成進度'!K11 -> 0.97883395 | L7: 達成率
A8: 材料費 | B8: ='（１）收支狀況'!M12/1000 -> 31402.673 | C8: 30950.167 | D8: =B8-C8 -> 452.50546 | E8: ='（１）收支狀況'!N11:N11/1000 -> 36078.352 | G8: 半成品-報廢(%) | H8: 0.0025 | I8: ='（２）ＫＰＩ達成進度'!M12 -> 0.0020099903 | J8: 0.002008889 | K8: ='（２）ＫＰＩ達成進度'!N11 -> 0.002009727 | L8: 報廢率
A9: 材料費率 | B9: ='（１）收支狀況'!P12 -> 0.6759526 | C9: 0.67659706 | D9: =B9-C9 -> -0.00064445929 | E9: ='（１）收支狀況'!Q11 -> 0.67546472 | G9: 半成品-超用(%) | H9: 0.004 | I9: ='（２）ＫＰＩ達成進度'!P12 -> 0.0061443653 | J9: 0.0061801862 | K9: ='（２）ＫＰＩ達成進度'!Q11 -> 0.006149808 | L9: 超用率
A10: 勞務成本 | B10: ='（１）收支狀況'!S12/1000 -> 6456.1666 | C10: 6254.241 | D10: =B10-C10 -> 201.92559 | E10: ='（１）收支狀況'!T11/1000 -> 7300.0896 | G10: 固定產線-導入率(%) | H10: 0.8 | I10: ='（２）ＫＰＩ達成進度'!S12 -> 0.9 | J10: 0.9 | K10: ='（２）ＫＰＩ達成進度'!T11 -> 0.9 | L10: 導入率
A11: 勞務費率 | B11: ='（１）收支狀況'!V12 -> 0.13897106 | C11: 0.13672304 | D11: =B11-C11 -> 0.0022480125 | E11: ='（１）收支狀況'!W11 -> 0.13667346 | G11: 教育訓練-實施率(%) | H11: 1 | I11: =23/52*100% -> 0.44230769 | J11: 0.42307692 | K11: ='（２）ＫＰＩ達成進度'!W11 -> 0.43990385 | L11: 實施率
A13: （３）業績構成比 | E13: ※單位：千元 | G13: （４）訂單數量構成比 | K13: ※單位：個
B14: 當週 | C14: 比例 | D14: 前週 | E14: 差異 | H14: 當週 | I14: 比例 | J14: 前週 | K14: 差異
A15: 18℃-飯糰(061,063) | B15: =SUM('（３）業績構成比'!M14:M20)/1000 -> 14265.023 | C15: =IFERROR(B15/$B$6,"") -> 0.3070592 | D15: 0.32785502 | E15: =IFERROR(C15-D15,"") -> -0.020795827 | G15: 18℃-飯糰(061,063) | H15: =SUM('（４）訂單數量構成比'!M14:M120) -> 755670 | I15: =IFERROR(H15/$B$7,"") -> 0.49373932 | J15: 0.51917014 | K15: =IFERROR(I15-J15,"") -> -0.025430824
A16: 18℃-壽司手卷(071,072,075,076) | B16: =SUM('（３）業績構成比'!S14:S20)/1000 -> 1674.2423 | C16: =IFERROR(B16/$B$6,"") -> 0.036038601 | D16: 0.037064806 | E16: =IFERROR(C16-D16,"") -> -0.0010262049 | G16: 18℃-壽司手卷(071,072,075,076) | H16: =SUM('（４）訂單數量構成比'!S14:S20) -> 57990 | I16: =IFERROR(H16/$B$7,"") -> 0.03788948 | J16: 0.038758789 | K16: =IFERROR(I16-J16,"") -> -0.00086930977
A17: 4℃-飯糰(065) | B17: =SUM('（３）業績構成比'!U14:U20)/1000 -> 526.15332 | C17: =IFERROR(B17/$B$6,"") -> 0.011325619 | D17: 0.011163438 | E17: =IFERROR(C17-D17,"") -> 0.00016218127 | G17: 4℃-飯糰(065) | H17: =SUM('（４）訂單數量構成比'!U14:U20) -> 17556 | I17: =IFERROR(H17/$B$7,"") -> 0.011470731 | J17: 0.011247548 | K17: =IFERROR(I17-J17,"") -> 0.0002231835
A18: 4℃-壽司手卷(077) | B18: =SUM('（３）業績構成比'!W14:W20)/1000 -> 2981.2756 | C18: =IFERROR(B18/$B$6,"") -> 0.064172912 | D18: 0.060067406 | E18: =IFERROR(C18-D18,"") -> 0.004105506 | G18: 4℃-壽司手卷(077) | H18: =SUM('（４）訂單數量構成比'!W14:W20) -> 118870 | I18: =IFERROR(H18/$B$7,"") -> 0.077667226 | J18: 0.07124327 | K18: =IFERROR(I18-J18,"") -> 0.0064239557
A19: 主食(091,092,093,094,095) | B19: =SUM('（３）業績構成比'!AC14:AC20)/1000 -> 5250.8287 | C19: =IFERROR(B19/$B$6,"") -> 0.11302577 | D19: 0.11397861 | E19: =IFERROR(C19-D19,"") -> -0.00095283853 | G19: 主食(091,092,093,094,095) | H19: =SUM('（４）訂單數量構成比'!AC14:AC20) -> 97114 | I19: =IFERROR(H19/$B$7,"") -> 0.063452301 | J19: 0.063704859 | K19: =IFERROR(I19-J19,"") -> -0.00025255796
A20: 便當(083) | B20: =SUM('（３）業績構成比'!AE14:AE20)/1000 -> 10546.284 | C20: =IFERROR(B20/$B$6,"") -> 0.22701215 | D20: 0.23996189 | E20: =IFERROR(C20-D20,"") -> -0.012949743 | G20: 便當(083) | H20: =SUM('（４）訂單數量構成比'!AE14:AE20) -> 168184 | I20: =IFERROR(H20/$B$7,"") -> 0.10988798 | J20: 0.11578327 | K20: =IFERROR(I20-J20,"") -> -0.0058952841
A21: 熱食義麵(122,123,124,126) | B21: =SUM('（３）業績構成比'!AG14:AG20)/1000 -> 0 | C21: =IFERROR(B21/$B$6,"") -> 0 | D21: 0 | E21: =IFERROR(C21-D21,"") -> 0 | G21: 熱食義麵(122,123,124,126) | H21: =SUM('（４）訂單數量構成比'!AG14:AG20) -> 0 | I21: =IFERROR(H21/$B$7,"") -> 0 | J21: 0 | K21: =IFERROR(I21-J21,"") -> 0
A22: 季節調理麵(111,112) | B22: =SUM('（３）業績構成比'!AI14:AI20)/1000 -> 9058.0383 | C22: =IFERROR(B22/$B$6,"") -> 0.19497718 | D22: 0.1882229 | E22: =IFERROR(C22-D22,"") -> 0.0067542795 | G22: 季節調理麵(111,112) | H22: =SUM('（４）訂單數量構成比'!AI14:AI20) -> 239808 | I22: =IFERROR(H22/$B$7,"") -> 0.15668564 | J22: 0.15374531 | K22: =IFERROR(I22-J22,"") -> 0.0029403309
A23: 微波小吃(153,154,155) | B23: =SUM('（３）業績構成比'!AK14:AK20)/1000 -> 2155.07 | C23: =IFERROR(B23/$B$6,"") -> 0.046388573 | D23: 0.021685927 | E23: =IFERROR(C23-D23,"") -> 0.024702646 | G23: 微波小吃(153,154,155) | H23: =SUM('（４）訂單數量構成比'!AK14:AK20) -> 75312 | I23: =IFERROR(H23/$B$7,"") -> 0.04920732 | J23: 0.026346814 | K23: =IFERROR(I23-J23,"") -> 0.022860505
C24: =SUM(C15:C23) -> 1 | D24: =SUM(D15:D23) -> 1 | I24: =SUM(I15:I23) -> 1 | J24: =SUM(J15:J23) -> 1
A26: （５）品群別人時生產性
A27: 品群 | B27: 當週 | C27: 前週 | D27: 差異 | E27: 累計
A28: 18℃-飯糰(061,063) | B28: ='（５-1）品群別人時生產性(18℃-飯糰)'!L47 -> 791.32419 | C28: 786.32217 | D28: =B28-C28 -> 5.0020182 | E28: ='（５-1）品群別人時生產性(18℃-飯糰)'!C1 -> 791.32419
A29: 18℃-壽司手卷(071,072,075,076) | B29: ='（５-2）品群別人時生產性(18℃-壽司手卷)'!L27 -> 298.03264 | C29: 297.7718 | D29: =B29-C29 -> 0.26083304 | E29: ='（５-2）品群別人時生產性(18℃-壽司手卷)'!C1 -> 298.03264
A30: 4℃-飯糰(065) | B30: ='（５-3）品群別人時生產性(4℃-飯糰)'!L27 -> 118.59923 | C30: 118.59923 | D30: =B30-C30 -> 0 | E30: ='（５-3）品群別人時生產性(4℃-飯糰)'!C1 -> 118.59923
A31: 4℃-壽司手卷(077) | B31: ='（５-4）品群別人時生產性(4℃-壽司手卷)'!L27 -> 370.29269 | C31: 353.61817 | D31: =B31-C31 -> 16.674519 | E31: ='（５-4）品群別人時生產性(4℃-壽司手卷)'!C1 -> 370.29269
A32: 主食(091,092,093,094,095) | B32: ='（５-5）品群別人時生產性(微波主食) '!L27 -> 83.410714 | C32: 72.075562 | D32: =B32-C32 -> 11.335152 | E32: ='（５-5）品群別人時生產性(微波主食) '!C1 -> 83.410714
A33: 便當(083) | B33: ='（５-6）品群別人時生產性(便當)'!L27 -> 79.415025 | C33: 79.739369 | D33: =B33-C33 -> -0.32434409 | E33: ='（５-6）品群別人時生產性(便當)'!C1 -> 79.415025
A34: 熱食義麵(122,123,124,126) | B34: ='（５-7）品群別人時生產性(熱食義麵) '!L27 -> 0 | C34: 0 | D34: =B34-C34 -> 0 | E34: ='（５-7）品群別人時生產性(熱食義麵) '!C1 -> 0
A35: 季節調理麵(111,112) | B35: ='（５-8）品群別人時生產性(季節調理麵) '!L27 -> 156.76906 | C35: 159.9798 | D35: =B35-C35 -> -3.2107372 | E35: ='（５-8）品群別人時生產性(季節調理麵) '!C1 -> 156.76906
A36: 微波小吃(153,154,155) | B36: ='（５-9）品群別人時生產性(微波小吃)'!L27 -> 121.82808 | C36: 114.90234 | D36: =B36-C36 -> 6.9257342 | E36: ='（５-9）品群別人時生產性(微波小吃)'!C1 -> 121.82808

Sheet （１）收支狀況
B2: （１）收支狀況
B3: 資料繳交日 | C3: 月份 | D3: 日期 | F3: 營業額(元) | I3: 訂單數量(個) | L3: 材料費(元) | O3: 材料費率（材料費／營業額） | R3: 勞務成本（全廠人事成本） | U3: 勞務費率（勞務成本／營業額）
F4: 日 | G4: 週累積 | H4: 月累積 | I4: 日 | J4: 週累積 | K4: 月累積 | L4: 日 | M4: 週累積 | N4: 月累積 | O4: 日 | P4: 週累積 | Q4: 月累積 | R4: 日 | S4: 週累積 | T4: 月累積 | U4: 日 | V4: 週累積 | W4: 月累積
B5: 46176 | C5: 五 | D5: 46168 | E5: 二 | F5: 6878064.2 | G5: =SUM(F5:F11) -> 45743869 | I5: 228475 | J5: =SUM(I5:I11) -> 1514908 | L5: 4648295.1 | M5: =SUM(L5:L11) -> 30950167 | O5: =L5/F5 -> 0.67581443 | P5: =M5/G5 -> 0.67659706 | R5: 946742.79 | S5: =SUM(R5:R11) -> 6254241 | U5: =R5/F5 -> 0.13764669 | V5: =S5/G5 -> 0.13672304
D6: =D5+1 -> 46169 | E6: 三 | F6: 6712279.9 | I6: 223731 | L6: 4588154.7 | O6: =L6/F6 -> 0.68354639 | R6: 911346.69 | U6: =R6/F6 -> 0.13577305
D7: =D6+1 -> 46170 | E7: 四 | F7: 6322728.4 | I7: 210315 | L7: 4256043.6 | O7: =L7/F7 -> 0.67313402 | R7: 881006.97 | U7: =R7/F7 -> 0.13933968
D8: =D7+1 -> 46171 | E8: 五 | F8: 5695002.6 | I8: 188020 | L8: 3839371.2 | O8: =L8/F8 -> 0.67416495 | R8: 830800.09 | U8: =R8/F8 -> 0.1458823
D9: =D8+1 -> 46172 | E9: 六 | F9: 5706651.9 | I9: 190453 | L9: 3894289.8 | O9: =L9/F9 -> 0.68241237 | R9: 845100.99 | U9: =R9/F9 -> 0.14809051
D10: =D9+1 -> 46173 | E10: 日 | F10: 7473420.7 | I10: 243554 | L10: 5048334.2 | O10: =L10/F10 -> 0.67550515 | R10: 995320.52 | U10: =R10/F10 -> 0.13318138
C11: 六 | D11: =D10+1 -> 46174 | E11: 一 | F11: 6955721.3 | H11: =SUM(F11:F40) -> 53412637 | I11: 230360 | K11: =SUM(I11:I40) -> 1760864 | L11: 4675678.9 | N11: =SUM(L11:L40) -> 36078352 | O11: =L11/F11 -> 0.67220619 | Q11: =N11/H11 -> 0.67546472 | R11: 843922.99 | T11: =SUM(R11:R40) -> 7300089.6 | U11: =R11/F11 -> 0.12132789 | W11: =T11/H11 -> 0.13667346
B12: =B5+7 -> 46183 | D12: =D11+1 -> 46175 | E12: 二 | F12: 7317703 | G12: =SUM(F12:F18) -> 46456915 | I12: 241153 | J12: =SUM(I12:I18) -> 1530504 | L12: 4901654 | M12: =SUM(L12:L18) -> 31402673 | O12: =L12/F12 -> 0.66983505 | P12: =M12/G12 -> 0.6759526 | R12: 989402.71 | S12: =SUM(R12:R18) -> 6456166.6 | U12: =R12/F12 -> 0.13520673 | V12: =S12/G12 -> 0.13897106
D13: =D12+1 -> 46176 | E13: 三 | F13: 6765416.7 | I13: 224497 | L13: 4515671.5 | O13: =L13/F13 -> 0.66746392 | R13: 930479.73 | U13: =R13/F13 -> 0.13753473
D14: =D13+1 -> 46177 | E14: 四 | F14: 6422003.3 | I14: 214546 | L14: 4430123 | O14: =L14/F14 -> 0.68983505 | R14: 888963.79 | U14: =R14/F14 -> 0.13842469
D15: =D14+1 -> 46178 | E15: 五 | F15: 5340875.9 | I15: 177694 | L15: 3671108.9 | O15: =L15/F15 -> 0.68736082 | R15: 822252.59 | U15: =R15/F15 -> 0.15395463
D16: =D15+1 -> 46179 | E16: 六 | F16: 5830113.3 | I16: 192072 | L16: 3916033 | O16: =L16/F16 -> 0.67169072 | R16: 859500.82 | U16: =R16/F16 -> 0.14742438
D17: =D16+1 -> 46180 | E17: 日 | F17: 7640961.5 | I17: 246810 | L17: 5135513.9 | O17: =L17/F17 -> 0.67210309 | R17: 999498.05 | U17: =R17/F17 -> 0.13080789
D18: =D17+1 -> 46181 | E18: 一 | F18: 7139841.6 | I18: 233732 | L18: 4832568.6 | O18: =L18/F18 -> 0.67684536 | R18: 966068.93 | U18: =R18/F18 -> 0.13530677
B19: =B12+7 -> 46190 | D19: =D18+1 -> 46182 | E19: 二 | G19: =SUM(F19:F25) -> 0 | J19: =SUM(I19:I25) -> 0 | M19: =SUM(L19:L25) -> 0 | O19: =L19/F19 -> #DIV/0! | P19: =M19/G19 -> #DIV/0! | S19: =SUM(R19:R25) -> 0 | U19: =R19/F19 -> #DIV/0! | V19: =S19/G19 -> #DIV/0!
D20: =D19+1 -> 46183 | E20: 三 | O20: =L20/F20 -> #DIV/0! | U20: =R20/F20 -> #DIV/0!
D21: =D20+1 -> 46184 | E21: 四 | O21: =L21/F21 -> #DIV/0! | U21: =R21/F21 -> #DIV/0!
D22: =D21+1 -> 46185 | E22: 五 | O22: =L22/F22 -> #DIV/0! | U22: =R22/F22 -> #DIV/0!
D23: =D22+1 -> 46186 | E23: 六 | O23: =L23/F23 -> #DIV/0! | U23: =R23/F23 -> #DIV/0!
D24: =D23+1 -> 46187 | E24: 日 | O24: =L24/F24 -> #DIV/0! | U24: =R24/F24 -> #DIV/0!
D25: =D24+1 -> 46188 | E25: 一 | O25: =L25/F25 -> #DIV/0! | U25: =R25/F25 -> #DIV/0!
B26: =B19+7 -> 46197 | D26: =D25+1 -> 46189 | E26: 二 | G26: =SUM(F26:F32) -> 0 | J26: =SUM(I26:I32) -> 0 | M26: =SUM(L26:L32) -> 0 | O26: =L26/F26 -> #DIV/0! | P26: =M26/G26 -> #DIV/0! | S26: =SUM(R26:R32) -> 0 | U26: =R26/F26 -> #DIV/0! | V26: =S26/G26 -> #DIV/0!
D27: =D26+1 -> 46190 | E27: 三 | O27: =L27/F27 -> #DIV/0! | U27: =R27/F27 -> #DIV/0!
D28: =D27+1 -> 46191 | E28: 四 | O28: =L28/F28 -> #DIV/0! | U28: =R28/F28 -> #DIV/0!
D29: =D28+1 -> 46192 | E29: 五 | O29: =L29/F29 -> #DIV/0! | U29: =R29/F29 -> #DIV/0!
D30: =D29+1 -> 46193 | E30: 六 | O30: =L30/F30 -> #DIV/0! | U30: =R30/F30 -> #DIV/0!
D31: =D30+1 -> 46194 | E31: 日 | O31: =L31/F31 -> #DIV/0! | U31: =R31/F31 -> #DIV/0!
D32: =D31+1 -> 46195 | E32: 一 | O32: =L32/F32 -> #DIV/0! | U32: =R32/F32 -> #DIV/0!
B33: =B26+7 -> 46204 | D33: =D32+1 -> 46196 | E33: 二 | G33: =SUM(F33:F39) -> 0 | J33: =SUM(I33:I39) -> 0 | M33: =SUM(L33:L39) -> 0 | O33: =L33/F33 -> #DIV/0! | P33: =M33/G33 -> #DIV/0! | S33: =SUM(R33:R39) -> 0 | U33: =R33/F33 -> #DIV/0! | V33: =S33/G33 -> #DIV/0!
D34: =D33+1 -> 46197 | E34: 三 | O34: =L34/F34 -> #DIV/0! | U34: =R34/F34 -> #DIV/0!
D35: =D34+1 -> 46198 | E35: 四 | O35: =L35/F35 -> #DIV/0! | U35: =R35/F35 -> #DIV/0!
D36: =D35+1 -> 46199 | E36: 五 | O36: =L36/F36 -> #DIV/0! | U36: =R36/F36 -> #DIV/0!
D37: =D36+1 -> 46200 | E37: 六 | O37: =L37/F37 -> #DIV/0! | U37: =R37/F37 -> #DIV/0!
D38: =D37+1 -> 46201 | E38: 日 | O38: =L38/F38 -> #DIV/0! | U38: =R38/F38 -> #DIV/0!
D39: =D38+1 -> 46202 | E39: 一 | O39: =L39/F39 -> #DIV/0! | U39: =R39/F39 -> #DIV/0!
B40: =B33+7 -> 46211 | D40: =D39+1 -> 46203 | E40: 二 | G40: =SUM(F40:F46) -> 0 | J40: =SUM(I40:I46) -> 0 | M40: =SUM(L40:L46) -> 0 | O40: =L40/F40 -> #DIV/0! | P40: =M40/G40 -> #DIV/0! | S40: =SUM(R40:R46) -> 0 | U40: =R40/F40 -> #DIV/0! | V40: =S40/G40 -> #DIV/0!
D41: =D40+1 -> 46204 | E41: 三 | O41: =L41/F41 -> #DIV/0! | U41: =R41/F41 -> #DIV/0!
...

Sheet （２）ＫＰＩ達成進度
B1: 人時生產性基準值 | C1: 442.4
B2: （２）ＫＰＩ達成進度
B3: 資料繳交日 | C3: 月份 | D3: 日期 | F3: 人時生產性(個/人) | I3: 人時生產性達成率(%) | L3: 半成品報廢(%) | O3: 半成品超用(%) | R3: 固定產線-導入率(固定產線數/總產線數) | U3: 教育訓練-實施率(進度/計畫)
F4: 日 | G4: 週平均 | H4: 月平均 | I4: 日 | J4: 週平均 | K4: 月平均 | L4: 日 | M4: 週平均 | N4: 月平均 | O4: 日 | P4: 週平均 | Q4: 月平均 | R4: 日 | S4: 週平均 | T4: 月平均 | U4: 日 | V4: 週平均 | W4: 月平均
B5: 46176 | C5: 五 | D5: 46168 | E5: 二 | F5: 427.33285 | G5: =AVERAGE(F5:F11) -> 428.73368 | I5: =F5/$C$1 -> 0.96594224 | J5: =AVERAGE(I5:I11) -> 0.96910868 | L5: 0.0020162331 | M5: =AVERAGE(L5:L11) -> 0.0020087453 | O5: 0.006210495 | P5: =AVERAGE(O5:O11) -> 0.0061812892 | R5: 0.9 | S5: =AVERAGE(R5:R11) -> 0.9 | U5: =22/52*100% -> 0.42307692 | V5: =AVERAGE(U5:U11) -> 0.42307692
D6: =D5+1 -> 46169 | E6: 三 | F6: 426.22277 | I6: =F6/$C$1 -> 0.96343303 | L6: 0.0020104612 | O6: 0.0062075441 | R6: 0.9 | U6: =22/52*100% -> 0.42307692
D7: =D6+1 -> 46170 | E7: 四 | F7: 426.32681 | I7: =F7/$C$1 -> 0.96366821 | L7: 0.0020040913 | O7: 0.0061481244 | R7: 0.9 | U7: =22/52*100% -> 0.42307692
D8: =D7+1 -> 46171 | E8: 五 | F8: 426.09601 | I8: =F8/$C$1 -> 0.96314649 | L8: 0.0020037176 | O8: 0.0061263084 | R8: 0.9 | U8: =22/52*100% -> 0.42307692
D9: =D8+1 -> 46172 | E9: 六 | F9: 429.99426 | I9: =F9/$C$1 -> 0.9719581 | L9: 0.0020067372 | O9: 0.0061783149 | R9: 0.9 | U9: =22/52*100% -> 0.42307692
D10: =D9+1 -> 46173 | E10: 日 | F10: 432.62004 | I10: =F10/$C$1 -> 0.97789339 | L10: 0.0020120936 | O10: 0.0062103305 | R10: 0.9 | U10: =22/52*100% -> 0.42307692
C11: 六 | D11: =D10+1 -> 46174 | E11: 一 | F11: 432.54302 | H11: =AVERAGEIF(F11:F40,"<>0") -> 433.03614 | I11: =F11/$C$1 -> 0.97771931 | K11: =AVERAGEIF(I11:I40,"<>0") -> 0.97883395 | L11: 0.0020078834 | N11: =AVERAGEIF(L11:L40,"<>0") -> 0.002009727 | O11: 0.0061879069 | Q11: =AVERAGEIF(O11:O40,"<>0") -> 0.006149808 | R11: 0.9 | T11: =AVERAGEIF(R11:R40,"<>0") -> 0.9 | U11: =22/52*100% -> 0.42307692 | W11: =AVERAGEIF(U11:U40,"<>0") -> 0.43990385
B12: =B5+7 -> 46183 | D12: =D11+1 -> 46175 | E12: 二 | F12: 432.51149 | G12: =AVERAGE(F12:F18) -> 433.10659 | I12: =F12/$C$1 -> 0.97764802 | J12: =AVERAGE(I12:I18) -> 0.97899319 | L12: 0.0020155692 | M12: =AVERAGE(L12:L18) -> 0.0020099903 | O12: 0.006210038 | P12: =AVERAGE(O12:O18) -> 0.0061443653 | R12: 0.9 | S12: =AVERAGE(R12:R18) -> 0.9 | U12: =23/52*100% -> 0.44230769 | V12: =AVERAGE(U12:U18) -> 0.44230769
D13: =D12+1 -> 46176 | E13: 三 | F13: 432.69164 | I13: =F13/$C$1 -> 0.97805525 | L13: 0.0020117009 | O13: 0.006161842 | R13: 0.9 | U13: =23/52*100% -> 0.44230769
D14: =D13+1 -> 46177 | E14: 四 | F14: 432.96499 | I14: =F14/$C$1 -> 0.97867314 | L14: 0.0020099563 | O14: 0.0061341209 | R14: 0.9 | U14: =23/52*100% -> 0.44230769
D15: =D14+1 -> 46178 | E15: 五 | F15: 431.62381 | I15: =F15/$C$1 -> 0.97564152 | L15: 0.0020057811 | O15: 0.0061231124 | R15: 0.9 | U15: =23/52*100% -> 0.44230769
D16: =D15+1 -> 46179 | E16: 六 | F16: 431.78573 | I16: =F16/$C$1 -> 0.97600752 | L16: 0.0020076393 | O16: 0.0061299679 | R16: 0.9 | U16: =23/52*100% -> 0.44230769
D17: =D16+1 -> 46180 | E17: 日 | F17: 433.85504 | I17: =F17/$C$1 -> 0.980685 | L17: 0.0020117449 | O17: 0.0061439495 | R17: 0.9 | U17: =23/52*100% -> 0.44230769
D18: =D17+1 -> 46181 | E18: 一 | F18: 436.3134 | I18: =F18/$C$1 -> 0.98624187 | L18: 0.0020075407 | O18: 0.0061075268 | R18: 0.9 | U18: =23/52*100% -> 0.44230769
B19: =B12+7 -> 46190 | D19: =D18+1 -> 46182 | E19: 二 | G19: =AVERAGE(F19:F25) -> #DIV/0! | I19: =F19/$C$1 -> 0 | J19: =AVERAGE(I19:I25) -> 0 | M19: =AVERAGE(L19:L25) -> #DIV/0! | P19: =AVERAGE(O19:O25) -> #DIV/0! | S19: =AVERAGE(R19:R25) -> #DIV/0! | V19: =AVERAGE(U19:U25) -> #DIV/0!
D20: =D19+1 -> 46183 | E20: 三 | I20: =F20/$C$1 -> 0
D21: =D20+1 -> 46184 | E21: 四 | I21: =F21/$C$1 -> 0
D22: =D21+1 -> 46185 | E22: 五 | I22: =F22/$C$1 -> 0
D23: =D22+1 -> 46186 | E23: 六 | I23: =F23/$C$1 -> 0
D24: =D23+1 -> 46187 | E24: 日 | I24: =F24/$C$1 -> 0
D25: =D24+1 -> 46188 | E25: 一 | I25: =F25/$C$1 -> 0
B26: =B19+7 -> 46197 | D26: =D25+1 -> 46189 | E26: 二 | G26: =AVERAGE(F26:F32) -> #DIV/0! | I26: =F26/$C$1 -> 0 | J26: =AVERAGE(I26:I32) -> 0 | M26: =AVERAGE(L26:L32) -> #DIV/0! | P26: =AVERAGE(O26:O32) -> #DIV/0! | S26: =AVERAGE(R26:R32) -> #DIV/0! | V26: =AVERAGE(U26:U32) -> #DIV/0!
D27: =D26+1 -> 46190 | E27: 三 | I27: =F27/$C$1 -> 0
D28: =D27+1 -> 46191 | E28: 四 | I28: =F28/$C$1 -> 0
D29: =D28+1 -> 46192 | E29: 五 | I29: =F29/$C$1 -> 0
D30: =D29+1 -> 46193 | E30: 六 | I30: =F30/$C$1 -> 0
D31: =D30+1 -> 46194 | E31: 日 | I31: =F31/$C$1 -> 0
D32: =D31+1 -> 46195 | E32: 一 | I32: =F32/$C$1 -> 0
B33: =B26+7 -> 46204 | D33: =D32+1 -> 46196 | E33: 二 | G33: =AVERAGE(F33:F39) -> #DIV/0! | I33: =F33/$C$1 -> 0 | J33: =AVERAGE(I33:I39) -> 0 | M33: =AVERAGE(L33:L39) -> #DIV/0! | P33: =AVERAGE(O33:O39) -> #DIV/0! | S33: =AVERAGE(R33:R39) -> #DIV/0! | V33: =AVERAGE(U33:U39) -> #DIV/0!
D34: =D33+1 -> 46197 | E34: 三 | I34: =F34/$C$1 -> 0
D35: =D34+1 -> 46198 | E35: 四 | I35: =F35/$C$1 -> 0
D36: =D35+1 -> 46199 | E36: 五 | I36: =F36/$C$1 -> 0
D37: =D36+1 -> 46200 | E37: 六 | I37: =F37/$C$1 -> 0
D38: =D37+1 -> 46201 | E38: 日 | I38: =F38/$C$1 -> 0
D39: =D38+1 -> 46202 | E39: 一 | I39: =F39/$C$1 -> 0
B40: =B33+7 -> 46211 | D40: =D39+1 -> 46203 | E40: 二 | G40: =AVERAGE(F40:F46) -> #DIV/0! | I40: =F40/$C$1 -> 0 | J40: =AVERAGE(I40:I46) -> 0 | M40: =AVERAGE(L40:L46) -> #DIV/0! | P40: =AVERAGE(O40:O46) -> #DIV/0! | S40: =AVERAGE(R40:R46) -> #DIV/0! | V40: =AVERAGE(U40:U46) -> #DIV/0!
...

Sheet （３）業績構成比
B2: （3）業績構成比
B3: 資料繳交日 | C3: 月份 | D3: 日期 | F3: 營業額 | I3: 品類業績
I4: 18℃-飯糰 | O4: 18℃-壽司手卷 | U4: 4℃-飯糰 | W4: 4℃-壽司手卷 | Y4: 主食 | AE4: 便當 | AG4: 熱食義麵 | AI4: 季節調理麵 | AK4: 微波小吃
F5: 日 | G5: 週累積 | H5: 月累積 | I5: 一配 | K5: 二配 | M5: 合計 | O5: 一配 | Q5: 二配 | S5: 合計 | U5: 一配 | W5: 一配 | Y5: 一配 | AA5: 二配 | AC5: 合計 | AE5: 一配 | AG5: 一配 | AI5: 一配 | AK5: 一配
I6: 業績(元) | J6: 比例(%) | K6: 業績(元) | L6: 比例(%) | M6: 業績(元) | N6: 比例(%) | O6: 業績(元) | P6: 比例(%) | Q6: 業績(元) | R6: 比例(%) | S6: 業績(元) | T6: 比例(%) | U6: 業績(元) | V6: 比例(%) | W6: 業績(元) | X6: 比例(%) | Y6: 業績(元) | Z6: 比例(%) | AA6: 業績(元) | AB6: 比例(%) | AC6: 業績(元) | AD6: 比例(%) | AE6: 業績(元) | AF6: 比例(%) | AG6: 業績(元) | AH6: 比例(%) | AI6: 業績(元) | AJ6: 比例(%) | AK6: 業績(元) | AL6: 比例(%)
B7: =D8+7 -> 46176 | C7: 五 | D7: 46168 | E7: 二 | F7: =SUM(M7,S7,U7,W7,AC7,AE7,AG7,AI7,AK7) -> 6878064.2 | G7: =SUM(F7:F13) -> 45743869 | I7: 1146496.9 | J7: =I7/$F7 -> 0.16668889 | K7: 1202631.8 | L7: =K7/$F7 -> 0.17485033 | M7: =I7+K7 -> 2349128.7 | N7: =M7/$F7 -> 0.34153921 | O7: 253149.29 | P7: =O7/$F7 -> 0.036805311 | Q7: 0 | R7: =Q7/$F7 -> 0 | S7: =O7+Q7 -> 253149.29 | T7: =S7/$F7 -> 0.036805311 | U7: 82986.93 | V7: =U7/$F7 -> 0.012065449 | W7: 512720.57 | X7: =W7/$F7 -> 0.074544313 | Y7: 210730.24 | Z7: =Y7/$F7 -> 0.030638016 | AA7: 606164.46 | AB7: =AA7/$F7 -> 0.088130096 | AC7: =Y7+AA7 -> 816894.7 | AD7: =AC7/$F7 -> 0.11876811 | AE7: 1699147 | AF7: =AE7/F7 -> 0.24703855 | AG7: 0 | AH7: =AG7/$F7 -> 0 | AI7: 1091284.9 | AJ7: =AI7/$F7 -> 0.15866164 | AK7: 72752.1 | AL7: =AK7/$F7 -> 0.010577409
D8: 46169 | E8: 三 | F8: =SUM(M8,S8,U8,W8,AC8,AE8,AG8,AI8,AK8) -> 6712279.9 | I8: 1127682.9 | J8: =I8/$F8 -> 0.16800296 | K8: 1165408 | L8: =K8/$F8 -> 0.17362327 | M8: =I8+K8 -> 2293090.9 | N8: =M8/F8 -> 0.34162623 | O8: 251528.67 | P8: =O8/$F8 -> 0.037472912 | Q8: 0 | R8: =Q8/$F8 -> 0 | S8: =O8+Q8 -> 251528.67 | T8: =S8/F8 -> 0.037472912 | U8: 74745.18 | V8: =U8/F8 -> 0.011135588 | W8: 367760.25 | X8: =W8/$F8 -> 0.054789171 | Y8: 200852.26 | Z8: =Y8/$F8 -> 0.029923106 | AA8: 547025.24 | AB8: =AA8/$F8 -> 0.081496191 | AC8: =Y8+AA8 -> 747877.5 | AD8: =AC8/$F8 -> 0.1114193 | AE8: 1618030.1 | AF8: =AE8/F8 -> 0.24105522 | AG8: 0 | AH8: =AG8/$F8 -> 0 | AI8: 1285726.9 | AJ8: =AI8/$F8 -> 0.19154846 | AK8: 73520.4 | AL8: =AK8/$F8 -> 0.010953119
D9: 46170 | E9: 四 | F9: =SUM(M9,S9,U9,W9,AC9,AE9,AG9,AI9,AK9) -> 6322728.4 | I9: 1089331.6 | J9: =I9/$F9 -> 0.17228822 | K9: 1017738 | L9: =K9/$F9 -> 0.160965 | M9: =I9+K9 -> 2107069.6 | N9: =M9/$F9 -> 0.33325321 | O9: 259420.86 | P9: =O9/$F9 -> 0.041029891 | Q9: 0 | R9: =Q9/$F9 -> 0 | S9: =O9+Q9 -> 259420.86 | T9: =S9/$F9 -> 0.041029891 | U9: 63086.85 | V9: =U9/$F9 -> 0.009977789 | W9: 365622.49 | X9: =W9/$F9 -> 0.057826695 | Y9: 179222.89 | Z9: =Y9/$F9 -> 0.028345815 | AA9: 440019.09 | AB9: =AA9/$F9 -> 0.069593229 | AC9: =Y9+AA9 -> 619241.98 | AD9: =AC9/$F9 -> 0.097939044 | AE9: 1493806.2 | AF9: =AE9/F9 -> 0.23625975 | AG9: 0 | AH9: =AG9/$F9 -> 0 | AI9: 1342082.9 | AJ9: =AI9/$F9 -> 0.21226326 | AK9: 72397.5 | AL9: =AK9/$F9 -> 0.011450357
D10: 46171 | E10: 五 | F10: =SUM(M10,S10,U10,W10,AC10,AE10,AG10,AI10,AK10) -> 5695002.6 | I10: 839625.92 | J10: =I10/$F10 -> 0.14743205 | K10: 948812.1 | L10: =K10/$F10 -> 0.16660433 | M10: =I10+K10 -> 1788438 | N10: =M10/F10 -> 0.31403638 | O10: 203759.43 | P10: =O10/$F10 -> 0.035778637 | Q10: 0 | R10: =Q10/$F10 -> 0 | S10: =O10+Q10 -> 203759.43 | T10: =S10/F10 -> 0.035778637 | U10: 59490.45 | V10: =U10/F10 -> 0.010446079 | W10: 333533.79 | X10: =W10/$F10 -> 0.058566047 | Y10: 161056.49 | Z10: =Y10/$F10 -> 0.028280319 | AA10: 461282.12 | AB10: =AA10/$F10 -> 0.080997701 | AC10: =Y10+AA10 -> 622338.61 | AD10: =AC10/$F10 -> 0.10927802 | AE10: 1199515.7 | AF10: =AE10/F10 -> 0.21062601 | AG10: 0 | AH10: =AG10/$F10 -> 0 | AI10: 1424098.6 | AJ10: =AI10/$F10 -> 0.2500611 | AK10: 63828 | AL10: =AK10/$F10 -> 0.011207721
D11: 46172 | E11: 六 | F11: =SUM(M11,S11,U11,W11,AC11,AE11,AG11,AI11,AK11) -> 5706651.9 | I11: 751160.99 | J11: =I11/$F11 -> 0.13162902 | K11: 1112618.3 | L11: =K11/$F11 -> 0.19496866 | M11: =I11+K11 -> 1863779.2 | N11: =M11/$F11 -> 0.32659768 | O11: 196826.19 | P11: =O11/$F11 -> 0.03449066 | Q11: 0 | R11: =Q11/$F11 -> 0 | S11: =O11+Q11 -> 196826.19 | T11: =S11/$F11 -> 0.03449066 | U11: 66713.22 | V11: =U11/$F11 -> 0.011690431 | W11: 408357.98 | X11: =W11/$F11 -> 0.071558243 | Y11: 183991.57 | Z11: =Y11/$F11 -> 0.032241597 | AA11: 539970.03 | AB11: =AA11/$F11 -> 0.094621162 | AC11: =Y11+AA11 -> 723961.6 | AD11: =AC11/$F11 -> 0.12686276 | AE11: 1264118.4 | AF11: =AE11/F11 -> 0.22151665 | AG11: 0 | AH11: =AG11/$F11 -> 0 | AI11: 1118830.8 | AJ11: =AI11/$F11 -> 0.19605731 | AK11: 64064.4 | AL11: =AK11/$F11 -> 0.011226267
D12: 46173 | E12: 日 | F12: =SUM(M12,S12,U12,W12,AC12,AE12,AG12,AI12,AK12) -> 7473420.7 | I12: 1067325.3 | J12: =I12/$F12 -> 0.14281616 | K12: 1257430.8 | L12: =K12/$F12 -> 0.16825372 | M12: =I12+K12 -> 2324756.1 | N12: =M12/F12 -> 0.31106988 | O12: 270639.44 | P12: =O12/$F12 -> 0.036213596 | Q12: 0 | R12: =Q12/$F12 -> 0 | S12: =O12+Q12 -> 270639.44 | T12: =S12/F12 -> 0.036213596 | U12: 82597.32 | V12: =U12/F12 -> 0.011052144 | W12: 425801.57 | X12: =W12/$F12 -> 0.056975458 | Y12: 218507.73 | Z12: =Y12/$F12 -> 0.029237981 | AA12: 622100.29 | AB12: =AA12/$F12 -> 0.083241706 | AC12: =Y12+AA12 -> 840608.02 | AD12: =AC12/$F12 -> 0.11247969 | AE12: 1950767.6 | AF12: =AE12/F12 -> 0.26102741 | AG12: 0 | AH12: =AG12/$F12 -> 0 | AI12: 1261473.6 | AJ12: =AI12/$F12 -> 0.16879468 | AK12: 316777.02 | AL12: =AK12/$F12 -> 0.042387152
C13: 六 | D13: 46174 | E13: 一 | F13: =SUM(M13,S13,U13,W13,AC13,AE13,AG13,AI13,AK13) -> 6955721.3 | H13: =SUM(F13:F43) -> 53412637 | I13: 1048097 | J13: =I13/$F13 -> 0.15068128 | K13: 1222997.8 | L13: =K13/$F13 -> 0.17582616 | M13: =I13+K13 -> 2271094.7 | N13: =M13/$F13 -> 0.32650744 | O13: 260163.76 | P13: =O13/$F13 -> 0.037402844 | Q13: 0 | R13: =Q13/$F13 -> 0 | S13: =O13+Q13 -> 260163.76 | T13: =S13/$F13 -> 0.037402844 | U13: 81038.88 | V13: =U13/$F13 -> 0.01165068 | W13: 333918.92 | X13: =W13/$F13 -> 0.048006368 | Y13: 226569.07 | Z13: =Y13/$F13 -> 0.032573052 | AA13: 616331.11 | AB13: =AA13/$F13 -> 0.088607792 | AC13: =Y13+AA13 -> 842900.18 | AD13: =AC13/$F13 -> 0.12118084 | AE13: 1751400.3 | AF13: =AE13/F13 -> 0.25179276 | AG13: 0 | AH13: =AG13/$F13 -> 0 | AI13: 1086545.8 | AJ13: =AI13/$F13 -> 0.15620893 | AK13: 328658.78 | AL13: =AK13/$F13 -> 0.047250136
B14: =D15+7 -> 46183 | D14: 46175 | E14: 二 | F14: =SUM(M14,S14,U14,W14,AC14,AE14,AG14,AI14,AK14) -> 7317703 | G14: =SUM(F14:F20) -> 46456915 | I14: 1029605.2 | J14: =I14/$F14 -> 0.1407006 | K14: 1183857.8 | L14: =K14/$F14 -> 0.16177997 | M14: =I14+K14 -> 2213463 | N14: =M14/$F14 -> 0.30248057 | O14: 258730.68 | P14: =O14/$F14 -> 0.035356816 | Q14: 0 | R14: =Q14/$F14 -> 0 | S14: =O14+Q14 -> 258730.68 | T14: =S14/$F14 -> 0.035356816 | U14: 85414.5 | V14: =U14/$F14 -> 0.01167231 | W14: 526935.54 | X14: =W14/$F14 -> 0.072008325 | Y14: 212149.49 | Z14: =Y14/$F14 -> 0.028991268 | AA14: 580222.44 | AB14: =AA14/$F14 -> 0.079290241 | AC14: =Y14+AA14 -> 792371.93 | AD14: =AC14/$F14 -> 0.10828151 | AE14: 1664130.4 | AF14: =AE14/F14 -> 0.22741158 | AG14: 0 | AH14: =AG14/$F14 -> 0 | AI14: 1452930.7 | AJ14: =AI14/$F14 -> 0.19855011 | AK14: 323726.33 | AL14: =AK14/$F14 -> 0.04423879
D15: 46176 | E15: 三 | F15: =SUM(M15,S15,U15,W15,AC15,AE15,AG15,AI15,AK15) -> 6765416.7 | I15: 1010811.7 | J15: =I15/$F15 -> 0.14940863 | K15: 1127213.4 | L15: =K15/$F15 -> 0.16661403 | M15: =I15+K15 -> 2138025 | N15: =M15/F15 -> 0.31602267 | O15: 255813.28 | P15: =O15/$F15 -> 0.037811903 | Q15: 0 | R15: =Q15/$F15 -> 0 | S15: =O15+Q15 -> 255813.28 | T15: =S15/F15 -> 0.037811903 | U15: 72107.82 | V15: =U15/F15 -> 0.010658297 | W15: 448349.06 | X15: =W15/$F15 -> 0.066270724 | Y15: 190747.2 | Z15: =Y15/$F15 -> 0.02819445 | AA15: 533381.17 | AB15: =AA15/$F15 -> 0.078839367 | AC15: =Y15+AA15 -> 724128.37 | AD15: =AC15/$F15 -> 0.10703382 | AE15: 1550012.2 | AF15: =AE15/F15 -> 0.22910816 | AG15: 0 | AH15: =AG15/$F15 -> 0 | AI15: 1274874.8 | AJ15: =AI15/$F15 -> 0.18843995 | AK15: 302106.21 | AL15: =AK15/$F15 -> 0.044654487
D16: 46177 | E16: 四 | F16: =SUM(M16,S16,U16,W16,AC16,AE16,AG16,AI16,AK16) -> 6422003.3 | I16: 984740.83 | J16: =I16/$F16 -> 0.15333857 | K16: 1008778 | L16: =K16/$F16 -> 0.15708151 | M16: =I16+K16 -> 1993518.8 | N16: =M16/$F16 -> 0.31042008 | O16: 249957.04 | P16: =O16/$F16 -> 0.038921973 | Q16: 0 | R16: =Q16/$F16 -> 0 | S16: =O16+Q16 -> 249957.04 | T16: =S16/$F16 -> 0.038921973 | U16: 73816.11 | V16: =U16/$F16 -> 0.01149425 | W16: 467698.89 | X16: =W16/$F16 -> 0.072827569 | Y16: 172126.64 | Z16: =Y16/$F16 -> 0.026802639 | AA16: 430983.48 | AB16: =AA16/$F16 -> 0.067110442 | AC16: =Y16+AA16 -> 603110.12 | AD16: =AC16/$F16 -> 0.093913081 | AE16: 1356292.4 | AF16: =AE16/F16 -> 0.21119459 | AG16: 0 | AH16: =AG16/$F16 -> 0 | AI16: 1386350.6 | AJ16: =AI16/$F16 -> 0.2158751 | AK16: 291259.38 | AL16: =AK16/$F16 -> 0.045353352
D17: 46178 | E17: 五 | F17: =SUM(M17,S17,U17,W17,AC17,AE17,AG17,AI17,AK17) -> 5340875.9 | I17: 738554.92 | J17: =I17/$F17 -> 0.13828348 | K17: 916431.33 | L17: =K17/$F17 -> 0.17158821 | M17: =I17+K17 -> 1654986.2 | N17: =M17/F17 -> 0.30987169 | O17: 198769.24 | P17: =O17/$F17 -> 0.0372166 | Q17: 0 | R17: =Q17/$F17 -> 0 | S17: =O17+Q17 -> 198769.24 | T17: =S17/F17 -> 0.0372166 | U17: 57302.64 | V17: =U17/F17 -> 0.010729072 | W17: 282180.75 | X17: =W17/$F17 -> 0.052834171 | Y17: 146636.91 | Z17: =Y17/$F17 -> 0.027455592 | AA17: 454927.38 | AB17: =AA17/$F17 -> 0.085178422 | AC17: =Y17+AA17 -> 601564.29 | AD17: =AC17/$F17 -> 0.11263401 | AE17: 1017236.4 | AF17: =AE17/F17 -> 0.19046246 | AG17: 0 | AH17: =AG17/$F17 -> 0 | AI17: 1272378.6 | AJ17: =AI17/$F17 -> 0.23823407 | AK17: 256457.77 | AL17: =AK17/$F17 -> 0.048017923
D18: 46179 | E18: 六 | F18: =SUM(M18,S18,U18,W18,AC18,AE18,AG18,AI18,AK18) -> 5830113.3 | I18: 701273.12 | J18: =I18/$F18 -> 0.12028465 | K18: 1075289.3 | L18: =K18/$F18 -> 0.18443712 | M18: =I18+K18 -> 1776562.4 | N18: =M18/$F18 -> 0.30472176 | O18: 189086.32 | P18: =O18/$F18 -> 0.032432701 | Q18: 0 | R18: =Q18/$F18 -> 0 | S18: =O18+Q18 -> 189086.32 | T18: =S18/$F18 -> 0.032432701 | U18: 63686.25 | V18: =U18/$F18 -> 0.010923673 | W18: 339898.14 | X18: =W18/$F18 -> 0.058300434 | Y18: 189895.65 | Z18: =Y18/$F18 -> 0.032571519 | AA18: 571191.63 | AB18: =AA18/$F18 -> 0.097972646 | AC18: =Y18+AA18 -> 761087.28 | AD18: =AC18/$F18 -> 0.13054417 | AE18: 1207978.1 | AF18: =AE18/F18 -> 0.20719633 | AG18: 0 | AH18: =AG18/$F18 -> 0 | AI18: 1203401.2 | AJ18: =AI18/$F18 -> 0.20641129 | AK18: 288413.59 | AL18: =AK18/$F18 -> 0.049469637
D19: 46180 | E19: 日 | F19: =SUM(M19,S19,U19,W19,AC19,AE19,AG19,AI19,AK19) -> 7640961.5 | I19: 1028874.6 | J19: =I19/$F19 -> 0.1346525 | K19: 1231966.4 | L19: =K19/$F19 -> 0.16123186 | M19: =I19+K19 -> 2260841 | N19: =M19/F19 -> 0.29588436 | O19: 262547.42 | P19: =O19/$F19 -> 0.034360521 | Q19: 0 | R19: =Q19/$F19 -> 0 | S19: =O19+Q19 -> 262547.42 | T19: =S19/F19 -> 0.034360521 | U19: 90269.64 | V19: =U19/F19 -> 0.011813911 | W19: 500696.74 | X19: =W19/$F19 -> 0.065527976 | Y19: 227761.24 | Z19: =Y19/$F19 -> 0.029807929 | AA19: 675296.01 | AB19: =AA19/$F19 -> 0.088378407 | AC19: =Y19+AA19 -> 903057.25 | AD19: =AC19/$F19 -> 0.11818634 | AE19: 1948052 | AF19: =AE19/F19 -> 0.25494854 | AG19: 0 | AH19: =AG19/$F19 -> 0 | AI19: 1334115.2 | AJ19: =AI19/$F19 -> 0.17460043 | AK19: 341382.33 | AL19: =AK19/$F19 -> 0.044677928
D20: 46181 | E20: 一 | F20: =SUM(M20,S20,U20,W20,AC20,AE20,AG20,AI20,AK20) -> 7139841.6 | I20: 1020569.8 | J20: =I20/$F20 -> 0.14294012 | K20: 1207056.8 | L20: =K20/$F20 -> 0.16905933 | M20: =I20+K20 -> 2227626.6 | N20: =M20/$F20 -> 0.31199945 | O20: 259338.27 | P20: =O20/$F20 -> 0.036322693 | Q20: 0 | R20: =Q20/$F20 -> 0 | S20: =O20+Q20 -> 259338.27 | T20: =S20/$F20 -> 0.036322693 | U20: 83556.36 | V20: =U20/$F20 -> 0.011702831 | W20: 415516.44 | X20: =W20/$F20 -> 0.058196871 | Y20: 238320.46 | Z20: =Y20/$F20 -> 0.033378956 | AA20: 627188.98 | AB20: =AA20/$F20 -> 0.087843543 | AC20: =Y20+AA20 -> 865509.44 | AD20: =AC20/$F20 -> 0.1212225 | AE20: 1802582.8 | AF20: =AE20/F20 -> 0.25246819 | AG20: 0 | AH20: =AG20/$F20 -> 0 | AI20: 1133987.2 | AJ20: =AI20/$F20 -> 0.15882526 | AK20: 351724.41 | AL20: =AK20/$F20 -> 0.049262215

Sheet （４）訂單數量構成比
B2: （4）訂單數量構成比
B3: 資料繳交日 | C3: 月份 | D3: 日期 | F3: 訂單量 | I3: 品類訂單量
I4: 18℃-飯糰 | O4: 18℃-壽司手卷 | U4: 4℃-飯糰 | W4: 4℃-壽司手卷 | Y4: 主食 | AE4: 便當 | AG4: 熱食義麵 | AI4: 季節調理麵 | AK4: 微波小吃
F5: 日 | G5: 週累積 | H5: 月累積 | I5: 一配 | K5: 二配 | M5: 合計 | O5: 一配 | Q5: 二配 | S5: 合計 | U5: 一配 | W5: 一配 | Y5: 一配 | AA5: 二配 | AC5: 合計 | AE5: 一配 | AG5: 一配 | AI5: 一配 | AK5: 一配
I6: 訂單數 | J6: 比例(%) | K6: 訂單數 | L6: 比例(%) | M6: 訂單數 | N6: 比例(%) | O6: 訂單數 | P6: 比例(%) | Q6: 訂單數 | R6: 比例(%) | S6: 訂單數 | T6: 比例(%) | U6: 訂單數 | V6: 比例(%) | W6: 訂單數 | X6: 比例(%) | Y6: 訂單數 | Z6: 比例(%) | AA6: 訂單數 | AB6: 比例(%) | AC6: 訂單數 | AD6: 比例(%) | AE6: 訂單數 | AF6: 比例(%) | AG6: 訂單數 | AH6: 比例(%) | AI6: 訂單數 | AJ6: 比例(%) | AK6: 訂單數 | AL6: 比例(%)
B7: =D8+7 -> 46176 | D7: 46168 | E7: 二 | F7: =SUM(M7,S7,U7,W7,AC7,AE7,AG7,AI7,AK7) -> 228475 | G7: =SUM(F7:F13) -> 1514908 | I7: 57344 | J7: =I7/$F7 -> 0.25098588 | K7: 64932 | L7: =K7/$F7 -> 0.2841974 | M7: =I7+K7 -> 122276 | N7: =M7/$F7 -> 0.53518328 | O7: 8767 | P7: =O7/$F7 -> 0.038371813 | Q7: 0 | R7: =Q7/$F7 -> 0 | S7: =O7+Q7 -> 8767 | T7: =S7/$F7 -> 0.038371813 | U7: 2769 | V7: =U7/$F7 -> 0.012119488 | W7: 18761 | X7: =W7/$F7 -> 0.082114017 | Y7: 3712 | Z7: =Y7/$F7 -> 0.016246854 | AA7: 11414 | AB7: =AA7/$F7 -> 0.049957326 | AC7: =Y7+AA7 -> 15126 | AD7: =AC7/$F7 -> 0.06620418 | AE7: 27471 | AF7: =AE7/$F7 -> 0.12023635 | AG7: 0 | AH7: =AG7/$F7 -> 0 | AI7: 29612 | AJ7: =AI7/$F7 -> 0.12960718 | AK7: 3693 | AL7: =AK7/$F7 -> 0.016163694
D8: =D7+1 -> 46169 | E8: 三 | F8: =SUM(M8,S8,U8,W8,AC8,AE8,AG8,AI8,AK8) -> 223731 | I8: 56388 | J8: =I8/$F8 -> 0.25203481 | K8: 62812 | L8: =K8/$F8 -> 0.28074786 | M8: =I8+K8 -> 119200 | N8: =M8/$F8 -> 0.53278267 | O8: 8707 | P8: =O8/$F8 -> 0.038917271 | Q8: 0 | R8: =Q8/$F8 -> 0 | S8: =O8+Q8 -> 8707 | T8: =S8/$F8 -> 0.038917271 | U8: 2494 | V8: =U8/$F8 -> 0.011147315 | W8: 15103 | X8: =W8/$F8 -> 0.067505174 | Y8: 3538 | Z8: =Y8/$F8 -> 0.015813633 | AA8: 10312 | AB8: =AA8/$F8 -> 0.046091065 | AC8: =Y8+AA8 -> 13850 | AD8: =AC8/$F8 -> 0.061904698 | AE8: 25741 | AF8: =AE8/$F8 -> 0.11505335 | AG8: 0 | AH8: =AG8/$F8 -> 0 | AI8: 34904 | AJ8: =AI8/$F8 -> 0.15600878 | AK8: 3732 | AL8: =AK8/$F8 -> 0.016680746
D9: =D8+1 -> 46170 | E9: 四 | F9: =SUM(M9,S9,U9,W9,AC9,AE9,AG9,AI9,AK9) -> 210315 | I9: 54513 | J9: =I9/$F9 -> 0.25919692 | K9: 54796 | L9: =K9/$F9 -> 0.26054252 | M9: =I9+K9 -> 109309 | N9: =M9/$F9 -> 0.51973944 | O9: 8973 | P9: =O9/$F9 -> 0.042664575 | Q9: 0 | R9: =Q9/$F9 -> 0 | S9: =O9+Q9 -> 8973 | T9: =S9/$F9 -> 0.042664575 | U9: 2105 | V9: =U9/$F9 -> 0.010008796 | W9: 14825 | X9: =W9/$F9 -> 0.070489504 | Y9: 3157 | Z9: =Y9/$F9 -> 0.015010817 | AA9: 8261 | AB9: =AA9/$F9 -> 0.039279176 | AC9: =Y9+AA9 -> 11418 | AD9: =AC9/$F9 -> 0.054289994 | AE9: 23807 | AF9: =AE9/$F9 -> 0.11319687 | AG9: 0 | AH9: =AG9/$F9 -> 0 | AI9: 36203 | AJ9: =AI9/$F9 -> 0.17213703 | AK9: 3675 | AL9: =AK9/$F9 -> 0.017473789
D10: =D9+1 -> 46171 | E10: 五 | F10: =SUM(M10,S10,U10,W10,AC10,AE10,AG10,AI10,AK10) -> 188020 | I10: 42032 | J10: =I10/$F10 -> 0.22355069 | K10: 51213 | L10: =K10/$F10 -> 0.2723806 | M10: =I10+K10 -> 93245 | N10: =M10/$F10 -> 0.49593128 | O10: 7060 | P10: =O10/$F10 -> 0.037549197 | Q10: 0 | R10: =Q10/$F10 -> 0 | S10: =O10+Q10 -> 7060 | T10: =S10/$F10 -> 0.037549197 | U10: 1985 | V10: =U10/$F10 -> 0.010557388 | W10: 13193 | X10: =W10/$F10 -> 0.070168067 | Y10: 2837 | Z10: =Y10/$F10 -> 0.01508882 | AA10: 8678 | AB10: =AA10/$F10 -> 0.046154664 | AC10: =Y10+AA10 -> 11515 | AD10: =AC10/$F10 -> 0.061243485 | AE10: 19178 | AF10: =AE10/$F10 -> 0.10199979 | AG10: 0 | AH10: =AG10/$F10 -> 0 | AI10: 38604 | AJ10: =AI10/$F10 -> 0.20531858 | AK10: 3240 | AL10: =AK10/$F10 -> 0.017232209
D11: =D10+1 -> 46172 | E11: 六 | F11: =SUM(M11,S11,U11,W11,AC11,AE11,AG11,AI11,AK11) -> 190453 | I11: 38704 | J11: =I11/$F11 -> 0.20322074 | K11: 60151 | L11: =K11/$F11 -> 0.3158312 | M11: =I11+K11 -> 98855 | N11: =M11/$F11 -> 0.51905194 | O11: 6816 | P11: =O11/$F11 -> 0.035788357 | Q11: 0 | R11: =Q11/$F11 -> 0 | S11: =O11+Q11 -> 6816 | T11: =S11/$F11 -> 0.035788357 | U11: 2226 | V11: =U11/$F11 -> 0.011687923 | W11: 15440 | X11: =W11/$F11 -> 0.08106987 | Y11: 3241 | Z11: =Y11/$F11 -> 0.017017322 | AA11: 10183 | AB11: =AA11/$F11 -> 0.05346726 | AC11: =Y11+AA11 -> 13424 | AD11: =AC11/$F11 -> 0.070484581 | AE11: 20185 | AF11: =AE11/$F11 -> 0.10598415 | AG11: 0 | AH11: =AG11/$F11 -> 0 | AI11: 30255 | AJ11: =AI11/$F11 -> 0.15885809 | AK11: 3252 | AL11: =AK11/$F11 -> 0.017075079
D12: =D11+1 -> 46173 | E12: 日 | F12: =SUM(M12,S12,U12,W12,AC12,AE12,AG12,AI12,AK12) -> 243554 | I12: 55092 | J12: =I12/$F12 -> 0.22620035 | K12: 68199 | L12: =K12/$F12 -> 0.28001593 | M12: =I12+K12 -> 123291 | N12: =M12/$F12 -> 0.50621628 | O12: 9377 | P12: =O12/$F12 -> 0.038500702 | Q12: 0 | R12: =Q12/$F12 -> 0 | S12: =O12+Q12 -> 9377 | T12: =S12/$F12 -> 0.038500702 | U12: 2756 | V12: =U12/$F12 -> 0.011315766 | W12: 16455 | X12: =W12/$F12 -> 0.067562019 | Y12: 3849 | Z12: =Y12/$F12 -> 0.015803477 | AA12: 11732 | AB12: =AA12/$F12 -> 0.048170016 | AC12: =Y12+AA12 -> 15581 | AD12: =AC12/$F12 -> 0.063973493 | AE12: 31112 | AF12: =AE12/$F12 -> 0.12774169 | AG12: 0 | AH12: =AG12/$F12 -> 0 | AI12: 34038 | AJ12: =AI12/$F12 -> 0.13975545 | AK12: 10944 | AL12: =AK12/$F12 -> 0.044934594
C13: 六 | D13: =D12+1 -> 46174 | E13: 一 | F13: =SUM(M13,S13,U13,W13,AC13,AE13,AG13,AI13,AK13) -> 230360 | H13: =SUM(F13:F43) -> 1760864 | I13: 54096 | J13: =I13/$F13 -> 0.23483244 | K13: 66223 | L13: =K13/$F13 -> 0.28747612 | M13: =I13+K13 -> 120319 | N13: =M13/$F13 -> 0.52230856 | O13: 9016 | P13: =O13/$F13 -> 0.039138739 | Q13: 0 | R13: =Q13/$F13 -> 0 | S13: =O13+Q13 -> 9016 | T13: =S13/$F13 -> 0.039138739 | U13: 2704 | V13: =U13/$F13 -> 0.011738149 | W13: 14150 | X13: =W13/$F13 -> 0.061425595 | Y13: 3991 | Z13: =Y13/$F13 -> 0.017325056 | AA13: 11602 | AB13: =AA13/$F13 -> 0.050364647 | AC13: =Y13+AA13 -> 15593 | AD13: =AC13/$F13 -> 0.067689703 | AE13: 27907 | AF13: =AE13/$F13 -> 0.12114516 | AG13: 0 | AH13: =AG13/$F13 -> 0 | AI13: 29294 | AJ13: =AI13/$F13 -> 0.12716617 | AK13: 11377 | AL13: =AK13/$F13 -> 0.049387915
B14: =D15+7 -> 46183 | D14: =D13+1 -> 46175 | E14: 二 | F14: =SUM(M14,S14,U14,W14,AC14,AE14,AG14,AI14,AK14) -> 241153 | G14: =SUM(F14:F20) -> 1530504 | I14: 53173 | J14: =I14/$F14 -> 0.22049487 | K14: 64036 | L14: =K14/$F14 -> 0.26554096 | M14: =I14+K14 -> 117209 | N14: =M14/$F14 -> 0.48603584 | O14: 8964 | P14: =O14/$F14 -> 0.037171422 | Q14: 0 | R14: =Q14/$F14 -> 0 | S14: =O14+Q14 -> 8964 | T14: =S14/$F14 -> 0.037171422 | U14: 2850 | V14: =U14/$F14 -> 0.011818223 | W14: 21332 | X14: =W14/$F14 -> 0.088458365 | Y14: 3737 | Z14: =Y14/$F14 -> 0.015496386 | AA14: 10926 | AB14: =AA14/$F14 -> 0.045307336 | AC14: =Y14+AA14 -> 14663 | AD14: =AC14/$F14 -> 0.060803722 | AE14: 26610 | AF14: =AE14/$F14 -> 0.11034488 | AG14: 0 | AH14: =AG14/$F14 -> 0 | AI14: 38232 | AJ14: =AI14/$F14 -> 0.15853836 | AK14: 11293 | AL14: =AK14/$F14 -> 0.046829191
D15: =D14+1 -> 46176 | E15: 三 | F15: =SUM(M15,S15,U15,W15,AC15,AE15,AG15,AI15,AK15) -> 224497 | I15: 52127 | J15: =I15/$F15 -> 0.23219464 | K15: 60867 | L15: =K15/$F15 -> 0.27112612 | M15: =I15+K15 -> 112994 | N15: =M15/$F15 -> 0.50332076 | O15: 8859 | P15: =O15/$F15 -> 0.039461552 | Q15: 0 | R15: =Q15/$F15 -> 0 | S15: =O15+Q15 -> 8859 | T15: =S15/$F15 -> 0.039461552 | U15: 2406 | V15: =U15/$F15 -> 0.010717292 | W15: 17980 | X15: =W15/$F15 -> 0.080090157 | Y15: 3360 | Z15: =Y15/$F15 -> 0.014966792 | AA15: 10024 | AB15: =AA15/$F15 -> 0.044650931 | AC15: =Y15+AA15 -> 13384 | AD15: =AC15/$F15 -> 0.059617723 | AE15: 24743 | AF15: =AE15/$F15 -> 0.11021528 | AG15: 0 | AH15: =AG15/$F15 -> 0 | AI15: 33531 | AJ15: =AI15/$F15 -> 0.14936057 | AK15: 10600 | AL15: =AK15/$F15 -> 0.047216667
D16: =D15+1 -> 46177 | E16: 四 | F16: =SUM(M16,S16,U16,W16,AC16,AE16,AG16,AI16,AK16) -> 214546 | I16: 50789 | J16: =I16/$F16 -> 0.23672779 | K16: 54552 | L16: =K16/$F16 -> 0.25426715 | M16: =I16+K16 -> 105341 | N16: =M16/$F16 -> 0.49099494 | O16: 8651 | P16: =O16/$F16 -> 0.040322355 | Q16: 0 | R16: =Q16/$F16 -> 0 | S16: =O16+Q16 -> 8651 | T16: =S16/$F16 -> 0.040322355 | U16: 2463 | V16: =U16/$F16 -> 0.011480056 | W16: 18363 | X16: =W16/$F16 -> 0.085590037 | Y16: 3032 | Z16: =Y16/$F16 -> 0.014132167 | AA16: 8088 | AB16: =AA16/$F16 -> 0.037698209 | AC16: =Y16+AA16 -> 11120 | AD16: =AC16/$F16 -> 0.051830377 | AE16: 21609 | AF16: =AE16/$F16 -> 0.10071966 | AG16: 0 | AH16: =AG16/$F16 -> 0 | AI16: 36680 | AJ16: =AI16/$F16 -> 0.17096567 | AK16: 10319 | AL16: =AK16/$F16 -> 0.048096912
D17: =D16+1 -> 46178 | E17: 五 | F17: =SUM(M17,S17,U17,W17,AC17,AE17,AG17,AI17,AK17) -> 177694 | I17: 38009 | J17: =I17/$F17 -> 0.21390143 | K17: 49507 | L17: =K17/$F17 -> 0.27860817 | M17: =I17+K17 -> 87516 | N17: =M17/$F17 -> 0.4925096 | O17: 6889 | P17: =O17/$F17 -> 0.038768895 | Q17: 0 | R17: =Q17/$F17 -> 0 | S17: =O17+Q17 -> 6889 | T17: =S17/$F17 -> 0.038768895 | U17: 1912 | V17: =U17/$F17 -> 0.010760071 | W17: 11359 | X17: =W17/$F17 -> 0.063924499 | Y17: 2583 | Z17: =Y17/$F17 -> 0.014536225 | AA17: 8542 | AB17: =AA17/$F17 -> 0.048071404 | AC17: =Y17+AA17 -> 11125 | AD17: =AC17/$F17 -> 0.062607629 | AE17: 16127 | AF17: =AE17/$F17 -> 0.090757144 | AG17: 0 | AH17: =AG17/$F17 -> 0 | AI17: 33709 | AJ17: =AI17/$F17 -> 0.18970252 | AK17: 9057 | AL17: =AK17/$F17 -> 0.050969644
D18: =D17+1 -> 46179 | E18: 六 | F18: =SUM(M18,S18,U18,W18,AC18,AE18,AG18,AI18,AK18) -> 192072 | I18: 36167 | J18: =I18/$F18 -> 0.18829918 | K18: 58205 | L18: =K18/$F18 -> 0.3030374 | M18: =I18+K18 -> 94372 | N18: =M18/$F18 -> 0.49133658 | O18: 6553 | P18: =O18/$F18 -> 0.034117414 | Q18: 0 | R18: =Q18/$F18 -> 0 | S18: =O18+Q18 -> 6553 | T18: =S18/$F18 -> 0.034117414 | U18: 2125 | V18: =U18/$F18 -> 0.011063559 | W18: 13584 | X18: =W18/$F18 -> 0.070723479 | Y18: 3345 | Z18: =Y18/$F18 -> 0.017415344 | AA18: 10760 | AB18: =AA18/$F18 -> 0.056020659 | AC18: =Y18+AA18 -> 14105 | AD18: =AC18/$F18 -> 0.073436003 | AE18: 19251 | AF18: =AE18/$F18 -> 0.10022804 | AG18: 0 | AH18: =AG18/$F18 -> 0 | AI18: 31960 | AJ18: =AI18/$F18 -> 0.16639593 | AK18: 10122 | AL18: =AK18/$F18 -> 0.052698988
D19: =D18+1 -> 46180 | E19: 日 | F19: =SUM(M19,S19,U19,W19,AC19,AE19,AG19,AI19,AK19) -> 246810 | I19: 53285 | J19: =I19/$F19 -> 0.21589482 | K19: 66768 | L19: =K19/$F19 -> 0.27052388 | M19: =I19+K19 -> 120053 | N19: =M19/$F19 -> 0.4864187 | O19: 9093 | P19: =O19/$F19 -> 0.036842105 | Q19: 0 | R19: =Q19/$F19 -> 0 | S19: =O19+Q19 -> 9093 | T19: =S19/$F19 -> 0.036842105 | U19: 3012 | V19: =U19/$F19 -> 0.012203719 | W19: 19628 | X19: =W19/$F19 -> 0.079526761 | Y19: 4012 | Z19: =Y19/$F19 -> 0.016255419 | AA19: 12716 | AB19: =AA19/$F19 -> 0.051521413 | AC19: =Y19+AA19 -> 16728 | AD19: =AC19/$F19 -> 0.067776832 | AE19: 31076 | AF19: =AE19/$F19 -> 0.12591062 | AG19: 0 | AH19: =AG19/$F19 -> 0 | AI19: 35421 | AJ19: =AI19/$F19 -> 0.14351525 | AK19: 11799 | AL19: =AK19/$F19 -> 0.047806005
D20: =D19+1 -> 46181 | E20: 一 | F20: =SUM(M20,S20,U20,W20,AC20,AE20,AG20,AI20,AK20) -> 233732 | I20: 52794 | J20: =I20/$F20 -> 0.22587408 | K20: 65391 | L20: =K20/$F20 -> 0.27976914 | M20: =I20+K20 -> 118185 | N20: =M20/$F20 -> 0.50564322 | O20: 8981 | P20: =O20/$F20 -> 0.038424349 | Q20: 0 | R20: =Q20/$F20 -> 0 | S20: =O20+Q20 -> 8981 | T20: =S20/$F20 -> 0.038424349 | U20: 2788 | V20: =U20/$F20 -> 0.011928191 | W20: 16624 | X20: =W20/$F20 -> 0.071124194 | Y20: 4198 | Z20: =Y20/$F20 -> 0.017960741 | AA20: 11791 | AB20: =AA20/$F20 -> 0.050446665 | AC20: =Y20+AA20 -> 15989 | AD20: =AC20/$F20 -> 0.068407407 | AE20: 28768 | AF20: =AE20/$F20 -> 0.12308114 | AG20: 0 | AH20: =AG20/$F20 -> 0 | AI20: 30275 | AJ20: =AI20/$F20 -> 0.12952869 | AK20: 12122 | AL20: =AK20/$F20 -> 0.051862817

Sheet （５-1）品群別人時生產性(18℃-飯糰)
B1: 6月平均人時性 | C1: =AVERAGE(L47) -> 791.32419
B2: 產線配置圖－每週更新(0526-0601) | N2: 資料繳交 | O2: 日期 | P2: 46168 | U2: 46169 | Z2: 46170 | AE2: 46171 | AJ2: 46172 | AO2: 46173 | AT2: 46174
P3: 46168 | U3: 46169 | Z3: 46170 | AE3: 46171 | AJ3: 46172 | AO3: 46173 | AT3: 46174
B4: 品群 | C4: 商品名稱 | E4: 計畫 | H4: 平均人時性 | I4: 實績 (週平均) | L4: 平均人時性 | M4: 排名 | O4: 日報 | P4: 實際 | T4: 平均人時性 | U4: 實際 | Y4: 平均人時性 | Z4: 實際 | AD4: 平均人時性 | AE4: 實際 | AI4: 平均人時性 | AJ4: 實際 | AN4: 平均人時性 | AO4: 實際 | AS4: 平均人時性 | AT4: 實際 | AX4: 平均人時性
E5: 產線配置圖 | I5: 產線配置圖 | P5: 生產實績 | U5: 生產實績 | Z5: 生產實績 | AE5: 生產實績 | AJ5: 生產實績 | AO5: 生產實績 | AT5: 生產實績
E6: 人數 | F6: 產能／時 | G6: 人時性 | I6: 人數 | J6: 產能／時 | K6: 人時性 | P6: 人數 | Q6: 產能／時 | R6: 人時性 | S6: 排名 | U6: 人數 | V6: 產能／時 | W6: 人時性 | X6: 排名 | Z6: 人數 | AA6: 產能／時 | AB6: 人時性 | AC6: 排名 | AE6: 人數 | AF6: 產能／時 | AG6: 人時性 | AH6: 排名 | AJ6: 人數 | AK6: 產能／時 | AL6: 人時性 | AM6: 排名 | AO6: 人數 | AP6: 產能／時 | AQ6: 人時性 | AR6: 排名 | AT6: 人數 | AU6: 產能／時 | AV6: 人時性 | AW6: 排名
B7: 18℃-飯糰 | C7: 1 | D7: 一配鹽蔥燒肉飯糰 | E7: 4 | F7: 3600 | G7: =F7/E7 -> 900 | H7: =AVERAGE(G7:G41) -> 882.55656 | I7: =AVERAGE(P7,U7,Z7,AE7,AJ7,AO7,AT7) -> 4 | J7: =AVERAGE(Q7,V7,AA7,AF7,AK7,AP7,AU7) -> 3185.8101 | K7: =AVERAGE(R7,W7,AB7,AG7,AL7,AQ7,AV7) -> 796.45252 | L7: =IFERROR(AVERAGE(K7:K41),"-") -> 786.32217 | M7: =RANK(K7, K$7:$K$41) -> 19 | P7: 4 | Q7: 3186.4787 | R7: =IFERROR(Q7/P7,"") -> 796.61967 | S7: =RANK(R7, R$7:R$41) -> 17 | T7: =AVERAGE(R7:R41) -> 786.09927 | U7: 4 | V7: 3185.3987 | W7: =IFERROR(V7/U7,"") -> 796.34967 | X7: =RANK(W7, W$7:W$41) -> 18 | Y7: =AVERAGE(W7:W41) -> 786.19113 | Z7: 4 | AA7: 3185.7587 | AB7: =IFERROR(AA7/Z7,"") -> 796.43967 | AC7: =RANK(AB7, AB$7:AB$41) -> 19 | AD7: =AVERAGE(AB7:AB41) -> 786.25655 | AE7: 4 | AF7: 3184.6787 | AG7: =IFERROR(AF7/AE7,"") -> 796.16967 | AH7: =RANK(AG7, AG$7:AG$41) -> 19 | AI7: =AVERAGE(AG7:AG41) -> 786.31662 | AJ7: 4 | AK7: 3185.3987 | AL7: =IFERROR(AK7/AJ7,"") -> 796.34967 | AM7: =RANK(AL7, AL$7:AL$41) -> 19 | AN7: =AVERAGE(AL7:AL41) -> 790.952 | AO7: 4 | AP7: 3186.4787 | AQ7: =IFERROR(AP7/AO7,"") -> 796.61967 | AR7: =RANK(AQ7, AQ$7:AQ$41) -> 19 | AS7: =AVERAGE(AQ7:AQ41) -> 791.01215 | AT7: 4 | AU7: 3186.4787 | AV7: =IFERROR(AU7/AT7,"") -> 796.61967 | AW7: =RANK(AV7, AV$7:AV$41) -> 19 | AX7: =AVERAGE(AV7:AV41) -> 791.04099
C8: 2 | D8: 一配鮪魚飯糰 | E8: 3 | F8: 3600 | G8: =F8/E8 -> 1200 | I8: =AVERAGE(P8,U8,Z8,AE8,AJ8,AO8,AT8) -> 3 | J8: =AVERAGE(Q8,V8,AA8,AF8,AK8,AP8,AU8) -> 3185.3527 | K8: =AVERAGE(R8,W8,AB8,AG8,AL8,AQ8,AV8) -> 1061.7842 | M8: =RANK(K8, K$7:$K$41) -> 7 | P8: 3 | Q8: 3185.0441 | R8: =IFERROR(Q8/P8,"") -> 1061.6814 | S8: =RANK(R8, R$7:R$41) -> 7 | U8: 3 | V8: 3183.6041 | W8: =IFERROR(V8/U8,"") -> 1061.2014 | X8: =RANK(W8, W$7:W$41) -> 7 | Z8: 3 | AA8: 3185.4041 | AB8: =IFERROR(AA8/Z8,"") -> 1061.8014 | AC8: =RANK(AB8, AB$7:AB$41) -> 7 | AE8: 3 | AF8: 3186.8441 | AG8: =IFERROR(AF8/AE8,"") -> 1062.2814 | AH8: =RANK(AG8, AG$7:AG$41) -> 7 | AJ8: 3 | AK8: 3186.1241 | AL8: =IFERROR(AK8/AJ8,"") -> 1062.0414 | AM8: =RANK(AL8, AL$7:AL$41) -> 7 | AO8: 3 | AP8: 3186.1241 | AQ8: =IFERROR(AP8/AO8,"") -> 1062.0414 | AR8: =RANK(AQ8, AQ$7:AQ$41) -> 7 | AT8: 3 | AU8: 3184.3241 | AV8: =IFERROR(AU8/AT8,"") -> 1061.4414 | AW8: =RANK(AV8, AV$7:AV$41) -> 7
C9: 3 | D9: 一配雞肉飯飯糰 | E9: 5 | F9: 3600 | G9: =F9/E9 -> 720 | I9: =AVERAGE(P9,U9,Z9,AE9,AJ9,AO9,AT9) -> 5 | J9: =AVERAGE(Q9,V9,AA9,AF9,AK9,AP9,AU9) -> 3192.3073 | K9: =AVERAGE(R9,W9,AB9,AG9,AL9,AQ9,AV9) -> 638.46145 | M9: =RANK(K9, K$7:$K$41) -> 22 | P9: 5 | Q9: 3191.1758 | R9: =IFERROR(Q9/P9,"") -> 638.23517 | S9: =RANK(R9, R$7:R$41) -> 22 | U9: 5 | V9: 3190.8158 | W9: =IFERROR(V9/U9,"") -> 638.16317 | X9: =RANK(W9, W$7:W$41) -> 23 | Z9: 5 | AA9: 3191.8958 | AB9: =IFERROR(AA9/Z9,"") -> 638.37917 | AC9: =RANK(AB9, AB$7:AB$41) -> 22 | AE9: 5 | AF9: 3191.5358 | AG9: =IFERROR(AF9/AE9,"") -> 638.30717 | AH9: =RANK(AG9, AG$7:AG$41) -> 22 | AJ9: 5 | AK9: 3192.9758 | AL9: =IFERROR(AK9/AJ9,"") -> 638.59517 | AM9: =RANK(AL9, AL$7:AL$41) -> 22 | AO9: 5 | AP9: 3193.6958 | AQ9: =IFERROR(AP9/AO9,"") -> 638.73917 | AR9: =RANK(AQ9, AQ$7:AQ$41) -> 22 | AT9: 5 | AU9: 3194.0558 | AV9: =IFERROR(AU9/AT9,"") -> 638.81117 | AW9: =RANK(AV9, AV$7:AV$41) -> 22
C10: 4 | D10: 一配壹號醬炙烤牛飯糰 | E10: 5 | F10: 3300 | G10: =F10/E10 -> 660 | I10: =AVERAGE(P10,U10,Z10,AE10,AJ10,AO10,AT10) -> 5 | J10: =AVERAGE(Q10,V10,AA10,AF10,AK10,AP10,AU10) -> 2979.1422 | K10: =AVERAGE(R10,W10,AB10,AG10,AL10,AQ10,AV10) -> 595.82845 | M10: =RANK(K10, K$7:$K$41) -> 29 | P10: 5 | Q10: 2979.7551 | R10: =IFERROR(Q10/P10,"") -> 595.95102 | S10: =RANK(R10, R$7:R$41) -> 29 | U10: 5 | V10: 2978.7651 | W10: =IFERROR(V10/U10,"") -> 595.75302 | X10: =RANK(W10, W$7:W$41) -> 29 | Z10: 5 | AA10: 2978.7651 | AB10: =IFERROR(AA10/Z10,"") -> 595.75302 | AC10: =RANK(AB10, AB$7:AB$41) -> 29 | AE10: 5 | AF10: 2979.0951 | AG10: =IFERROR(AF10/AE10,"") -> 595.81902 | AH10: =RANK(AG10, AG$7:AG$41) -> 29 | AJ10: 5 | AK10: 2978.7651 | AL10: =IFERROR(AK10/AJ10,"") -> 595.75302 | AM10: =RANK(AL10, AL$7:AL$41) -> 28 | AO10: 5 | AP10: 2979.7551 | AQ10: =IFERROR(AP10/AO10,"") -> 595.95102 | AR10: =RANK(AQ10, AQ$7:AQ$41) -> 28 | AT10: 5 | AU10: 2979.0951 | AV10: =IFERROR(AU10/AT10,"") -> 595.81902 | AW10: =RANK(AV10, AV$7:AV$41) -> 28
