Workbook

Sheet 數值累積總表(月)
B1: 項目 | D1: 1月 | E1: 2月 | F1: 3月 | G1: 4月 | H1: 5月 | I1: 6月 | J1: 7月 | K1: 8月 | L1: 9月 | M1: 10月 | N1: 11月 | O1: 12月 | P1: 合計/平均
B2: （１）收支狀況 | C2: 業績金額(千元) | D2: 146299.94 | E2: 116569.43 | F2: 148838 | P2: =SUM(D2:O2) -> 411707.36
C3: 訂單數量 | D3: 4768701 | E3: 3787002 | F3: 5045753 | P3: =SUM(D3:O3) -> 13601456
C4: 材料費(千元) | D4: 93253 | E4: 74777 | F4: 93614 | P4: =SUM(D4:O4) -> 261644
C5: 材料費率(%) | D5: 0.655 | E5: 0.653 | F5: 0.648 | G5: =IFERROR(G4/G2, "") | H5: =IFERROR(H4/H2, "") | I5: =IFERROR(I4/I2, "") | J5: =IFERROR(J4/J2, "") | K5: =IFERROR(K4/K2, "") | L5: =IFERROR(L4/L2, "") | M5: =IFERROR(M4/M2, "") | N5: =IFERROR(N4/N2, "") | O5: =IFERROR(O4/O2, "") | P5: =AVERAGEIF(D5:O5, ">0") -> 0.652
C6: 勞務成本(千元) | D6: 22378 | E6: 22860 | F6: 22710 | P6: =SUM(D6:O6) -> 67948
C7: 勞務費率(%) | D7: 0.157 | E7: 0.2 | F7: 0.157 | G7: =IFERROR(G6/G2, "") | H7: =IFERROR(H6/H2, "") | I7: =IFERROR(I6/I2, "") | J7: =IFERROR(J6/J2, "") | K7: =IFERROR(K6/K2, "") | L7: =IFERROR(L6/L2, "") | M7: =IFERROR(M6/M2, "") | N7: =IFERROR(N6/N2, "") | O7: =IFERROR(O6/O2, "") | P7: =AVERAGEIF(D7:O7, ">0") -> 0.17133333
B9: （２）ＫＰＩ達成進度 | C9: 人時性KPI | D9: 497.6 | E9: 497.6 | F9: 497.6 | P9: =AVERAGEIF(D9:O9, ">0") -> 497.6
C10: 人時性(個/月均) | D10: 458.38414 | E10: 476.04172 | F10: 409.81563 | P10: =AVERAGEIF(D10:O10, ">0") -> 448.0805
C11: 人時達成率(%/月均) | D11: =IFERROR(D10/D9, "") -> 0.92118999 | E11: =IFERROR(E10/E9, "") -> 0.95667547 | F11: =IFERROR(F10/F9, "") -> 0.82358447 | G11: =IFERROR(G10/G9, "") | H11: =IFERROR(H10/H9, "") | I11: =IFERROR(I10/I9, "") | J11: =IFERROR(J10/J9, "") | K11: =IFERROR(K10/K9, "") | ... O11: =IFERROR(O10/O9, "") | P11: =AVERAGEIF(D11:O11, ">0") -> 0.90048331
C12: 半成品-報廢(%) | D12: 0.0024135432 | E12: 0.0023657636 | F12: 0.0020222248 | P12: =AVERAGEIF(D12:O12, ">0") -> 0.0022671772
C13: 半成品-超用(%) | D13: 0.0055994433 | E13: 0.0052393001 | F13: 0.0048799138 | P13: =AVERAGEIF(D13:O13, ">0") -> 0.0052395524
C14: 固定產線-導入率(%) | D14: 0.9 | E14: 0.9 | F14: 0.9 | P14: =AVERAGEIF(D14:O14, ">0") -> 0.9
C15: 教育訓練-實施率(%) | D15: 0.057692308 | E15: 0.13873626 | F15: 0.21960298 | P15: 0.2196
B17: （３）業績構成比 | C17: 18℃-飯糰(061,063) | D17: 0.36139567 | E17: 0.34737657 | F17: 0.36414345 | P17: =AVERAGEIF(D17:O17, ">0") -> 0.35763856
C18: 18℃-壽司手卷(071,072,075,076) | D18: 0.069633574 | E18: 0.077793665 | F18: 0.084480826 | P18: =AVERAGEIF(D18:O18, ">0") -> 0.077302689
C19: 4℃-飯糰(065) | D19: 0.022453222 | E19: 0.02167645 | F19: 0.02436516 | P19: =AVERAGEIF(D19:O19, ">0") -> 0.022831611
C20: 4℃-壽司手卷(077) | D20: 0.008585039 | E20: 0.0099523222 | F20: 0.014684918 | P20: =AVERAGEIF(D20:O20, ">0") -> 0.011074093
C21: 主食(091,092,093,094,095) | D21: 0.16215294 | E21: 0.18214708 | F21: 0.20289324 | P21: =AVERAGEIF(D21:O21, ">0") -> 0.18239775
C22: 便當(083) | D22: 0.27057088 | E22: 0.27529226 | F22: 0.29293399 | P22: =AVERAGEIF(D22:O22, ">0") -> 0.27959904
C23: 熱食義麵(122,123,124,126) | D23: 0.029234371 | E23: 0.0089796819 | F23: 0 | P23: =AVERAGEIF(D23:O23, ">0") -> 0.019107026
C24: 季節調理麵(111,112) | D24: 0.040564166 | E24: 0.040109499 | F24: 0.0016541185 | P24: =AVERAGEIF(D24:O24, ">0") -> 0.027442594
C25: 微波小吃(153,154,155) | D25: 0.035410133 | E25: 0.036672477 | F25: 0.01484429 | P25: =AVERAGEIF(D25:O25, ">0") -> 0.028975633
B27: （４）訂單數量構成比 | C27: 18℃-飯糰(061,063) | D27: 0.58577126 | E27: 0.57025346 | F27: 0.57640852 | P27: =AVERAGEIF(D27:O27, ">0") -> 0.57747775
C28: 18℃-壽司手卷(071,072,075,076) | D28: 0.081693946 | E28: 0.091615478 | F28: 0.10179987 | P28: =AVERAGEIF(D28:O28, ">0") -> 0.091703098
C29: 4℃-飯糰(065) | D29: 0.024966128 | E29: 0.023825971 | F29: 0.026809081 | P29: =AVERAGEIF(D29:O29, ">0") -> 0.025200393
C30: 4℃-壽司手卷(077) | D30: 0.0097963785 | E30: 0.011706622 | F30: 0.016401516 | P30: =AVERAGEIF(D30:O30, ">0") -> 0.012634839
C31: 主食(091,092,093,094,095) | D31: 0.089953008 | E31: 0.10114835 | F31: 0.11343936 | P31: =AVERAGEIF(D31:O31, ">0") -> 0.10151357
C32: 便當(083) | D32: 0.13708178 | E32: 0.14060779 | F32: 0.14223546 | P32: =AVERAGEIF(D32:O32, ">0") -> 0.13997501
C33: 熱食義麵(122,123,124,126) | D33: 0.015652481 | E33: 0.0048238686 | F33: 0 | P33: =AVERAGEIF(D33:O33, ">0") -> 0.010238175
C34: 季節調理麵(111,112) | D34: 0.022004735 | E34: 0.020902022 | F34: 0.00067918505 | P34: =AVERAGEIF(D34:O34, ">0") -> 0.014528647
C35: 微波小吃(153,154,155) | D35: 0.033080287 | E35: 0.035116432 | F35: 0.02222701 | P35: =AVERAGEIF(D35:O35, ">0") -> 0.030141243
B37: （５）品群別人時生產性 | C37: 18℃-飯糰(061,063) | D37: 768.96509 | E37: 774.12086 | F37: 757.59042 | P37: =AVERAGEIF(D37:O37, ">0") -> 766.89213
C38: 18℃-壽司手卷(071,072,075,076) | D38: 280.52358 | E38: 304.46478 | F38: 311.70582 | P38: =AVERAGEIF(D38:O38, ">0") -> 298.89806
C39: 4℃-飯糰(065) | D39: 258.56167 | E39: 203.24374 | F39: 331.13667 | P39: =AVERAGEIF(D39:O39, ">0") -> 264.31403
C40: 4℃-壽司手卷(077) | D40: 486.07171 | E40: 490.19814 | F40: 493.97618 | P40: =AVERAGEIF(D40:O40, ">0") -> 490.08201
C41: 主食(091,092,093,094,095) | D41: 82.669482 | E41: 81.452412 | F41: 79.949999 | P41: =AVERAGEIF(D41:O41, ">0") -> 81.357298
C42: 便當(083) | D42: 78.306367 | E42: 77.971323 | F42: 77.906797 | P42: =AVERAGEIF(D42:O42, ">0") -> 78.061495
C43: 熱食義麵(122,123,124,126) | D43: 76.250133 | E43: 72.949976 | F43: 0 | P43: =AVERAGEIF(D43:O43, ">0") -> 74.600054
C44: 季節調理麵(111,112) | D44: 110.8083 | E44: 97.157501 | F44: 84.601424 | P44: =AVERAGEIF(D44:O44, ">0") -> 97.52241
...

Sheet 生產管理報表(月)
A1: 大溪廠生產管理報表
A3: 月別 | B3: 4 | C3: 工廠 | D3: 大溪廠
A4: （１）收支狀況 | E4: ※單位：千元 | G4: （２）ＫＰＩ達成進度
A5: 項目 | B5: 當月 | C5: 前月 | D5: 差異 | E5: 累計 | G5: 項目 | H5: KPI | I5: 當月 | J5: 前月 | K5: 累計 | L5: ※補充
A6: 業績金額 | B6: ='（１）收支狀況'!#REF!/1000 -> #REF! | C6: ='數值累積總表(月)'!E2 -> 116569.43 | D6: =B6-C6 -> #REF! | E6: ='數值累積總表(月)'!P2 -> 411707.36 | G6: 人時性(個/月均) | H6: 497.6 | I6: ='（２）ＫＰＩ達成進度'!#REF! -> #REF! | J6: ='數值累積總表(月)'!E10 -> 476.04172 | K6: ='數值累積總表(月)'!P10 -> 448.0805 | L6: 個／MH
A7: 訂單數量 | B7: ='（１）收支狀況'!#REF! -> #REF! | C7: ='數值累積總表(月)'!E3 -> 3787002 | D7: =B7-C7 -> #REF! | E7: ='數值累積總表(月)'!P3 -> 13601456 | G7: 人時達成率(%/月均) | H7: 0.8 | I7: ='（２）ＫＰＩ達成進度'!#REF! -> #REF! | J7: ='數值累積總表(月)'!E11 -> 0.95667547 | K7: ='數值累積總表(月)'!P11 -> 0.90048331 | L7: 達成率
A8: 材料費 | B8: 93614 | C8: ='數值累積總表(月)'!E4 -> 74777 | D8: =B8-C8 -> 18837 | E8: ='數值累積總表(月)'!P4 -> 261644 | G8: 半成品-報廢(%) | H8: 0.0025 | I8: ='（２）ＫＰＩ達成進度'!#REF! -> #REF! | J8: ='數值累積總表(月)'!E12 -> 0.0023657636 | K8: ='數值累積總表(月)'!P12 -> 0.0022671772 | L8: 報廢率
A9: 材料費率 | B9: 0.648 | C9: ='數值累積總表(月)'!E5 -> 0.653 | D9: =B9-C9 -> -0.005 | E9: ='數值累積總表(月)'!P5 -> 0.652 | G9: 半成品-超用(%) | H9: 0.004 | I9: ='（２）ＫＰＩ達成進度'!#REF! -> #REF! | J9: ='數值累積總表(月)'!E13 -> 0.0052393001 | K9: ='數值累積總表(月)'!P13 -> 0.0052395524 | L9: 超用率
A10: 勞務成本 | B10: 22710 | C10: ='數值累積總表(月)'!E6 -> 22860 | D10: =B10-C10 -> -150 | E10: ='[1]數值累積總表(月)'!P6 -> 67948 | G10: 固定產線-導入率(%) | H10: 0.8 | I10: ='（２）ＫＰＩ達成進度'!#REF! -> #REF! | J10: ='數值累積總表(月)'!E14 -> 0.9 | K10: ='數值累積總表(月)'!P14 -> 0.9 | L10: 導入率
A11: 勞務費率 | B11: 0.157 | C11: ='數值累積總表(月)'!E7 -> 0.2 | D11: =B11-C11 -> -0.043 | E11: ='數值累積總表(月)'!P7 -> 0.17133333 | G11: 教育訓練-實施率(%) | H11: 1 | I11: ='（２）ＫＰＩ達成進度'!#REF! -> #REF! | J11: ='數值累積總表(月)'!E15 -> 0.13873626 | K11: ='數值累積總表(月)'!P15 -> 0.2196 | L11: 實施率
A13: （３）業績構成比 | E13: ※單位：千元 | G13: （４）訂單數量構成比 | K13: ※單位：個
B14: 當月 | C14: 比例 | D14: 前月 | E14: 差異 | H14: 當月 | I14: 比例 | J14: 前月 | K14: 差異
A15: 18℃-飯糰(061,063) | B15: =SUM('（３）業績構成比'!M7:M7)/1000 -> 1881.5817 | C15: =IFERROR(B15/$B$6,"") | D15: ='數值累積總表(月)'!E17 -> 0.34737657 | E15: =IFERROR(C15-D15,"") | G15: 18℃-飯糰(061,063) | H15: =SUM('（４）訂單數量構成比'!M7:M7) -> 101435 | I15: =IFERROR(H15/$B$7,"") | J15: ='數值累積總表(月)'!E27 -> 0.57025346 | K15: =IFERROR(I15-J15,"")
A16: 18℃-壽司手卷(071,072,075,076) | B16: =SUM('（３）業績構成比'!S7:S7)/1000 -> 431.49773 | C16: =IFERROR(B16/$B$6,"") | D16: ='數值累積總表(月)'!E18 -> 0.077793665 | E16: =IFERROR(C16-D16,"") | G16: 18℃-壽司手卷(071,072,075,076) | H16: =SUM('（４）訂單數量構成比'!S7:S7) -> 17522 | I16: =IFERROR(H16/$B$7,"") | J16: ='數值累積總表(月)'!E28 -> 0.091615478 | K16: =IFERROR(I16-J16,"")
A17: 4℃-飯糰(065) | B17: =SUM('（３）業績構成比'!U7:U7)/1000 -> 121.14007 | C17: =IFERROR(B17/$B$6,"") | D17: ='數值累積總表(月)'!E19 -> 0.02167645 | E17: =IFERROR(C17-D17,"") | G17: 4℃-飯糰(065) | H17: =SUM('（４）訂單數量構成比'!U7:U7) -> 4406 | I17: =IFERROR(H17/$B$7,"") | J17: ='數值累積總表(月)'!E29 -> 0.023825971 | K17: =IFERROR(I17-J17,"")
A18: 4℃-壽司手卷(077) | B18: =SUM('（３）業績構成比'!W7:W7)/1000 -> 55.5702 | C18: =IFERROR(B18/$B$6,"") | D18: ='數值累積總表(月)'!E20 -> 0.0099523222 | E18: =IFERROR(C18-D18,"") | G18: 4℃-壽司手卷(077) | H18: =SUM('（４）訂單數量構成比'!W7:W7) -> 2100 | I18: =IFERROR(H18/$B$7,"") | J18: ='數值累積總表(月)'!E30 -> 0.011706622 | K18: =IFERROR(I18-J18,"")
A19: 主食(091,092,093,094,095) | B19: =SUM('（３）業績構成比'!AC7:AC7)/1000 -> 901.91559 | C19: =IFERROR(B19/$B$6,"") | D19: ='數值累積總表(月)'!E21 -> 0.18214708 | E19: =IFERROR(C19-D19,"") | G19: 主食(091,092,093,094,095) | H19: =SUM('（４）訂單數量構成比'!AC7:AC7) -> 17063 | I19: =IFERROR(H19/$B$7,"") | J19: ='數值累積總表(月)'!E31 -> 0.10114835 | K19: =IFERROR(I19-J19,"")
A20: 便當(083) | B20: =SUM('（３）業績構成比'!AE7:AE7)/1000 -> 2104.1695 | C20: =IFERROR(B20/$B$6,"") | D20: ='數值累積總表(月)'!E22 -> 0.27529226 | E20: =IFERROR(C20-D20,"") | G20: 便當(083) | H20: =SUM('（４）訂單數量構成比'!AE7:AE7) -> 33080 | I20: =IFERROR(H20/$B$7,"") | J20: ='數值累積總表(月)'!E32 -> 0.14060779 | K20: =IFERROR(I20-J20,"")
A21: 熱食義麵(122,123,124,126) | B21: =SUM('（３）業績構成比'!AG7:AG7)/1000 -> 0 | C21: =IFERROR(B21/$B$6,"") | D21: ='數值累積總表(月)'!E23 -> 0.0089796819 | E21: =IFERROR(C21-D21,"") | G21: 熱食義麵(122,123,124,126) | H21: =SUM('（４）訂單數量構成比'!AG7:AG7) -> 0 | I21: =IFERROR(H21/$B$7,"") | J21: ='數值累積總表(月)'!E33 -> 0.0048238686 | K21: =IFERROR(I21-J21,"")
A22: 季節調理麵(111,112) | B22: =SUM('（３）業績構成比'!AI7:AI7)/1000 -> 0 | C22: =IFERROR(B22/$B$6,"") | D22: ='數值累積總表(月)'!E24 -> 0.040109499 | E22: =IFERROR(C22-D22,"") | G22: 季節調理麵(111,112) | H22: =SUM('（４）訂單數量構成比'!AI7:AI7) -> 0 | I22: =IFERROR(H22/$B$7,"") | J22: ='數值累積總表(月)'!E34 -> 0.020902022 | K22: =IFERROR(I22-J22,"")
A23: 微波小吃(153,154,155) | B23: =SUM('（３）業績構成比'!AK7:AK7)/1000 -> 70.4472 | C23: =IFERROR(B23/$B$6,"") | D23: ='數值累積總表(月)'!E25 -> 0.036672477 | E23: =IFERROR(C23-D23,"") | G23: 微波小吃(153,154,155) | H23: =SUM('（４）訂單數量構成比'!AK7:AK7) -> 3576 | I23: =IFERROR(H23/$B$7,"") | J23: ='數值累積總表(月)'!E35 -> 0.035116432 | K23: =IFERROR(I23-J23,"")
C24: =SUM(C15:C23) -> 0 | D24: =SUM(D15:D23) -> 1 | I24: =SUM(I15:I23) -> 0 | J24: =SUM(J15:J23) -> 1
A26: （５）品群別人時生產性
A27: 品群 | B27: 當月 | C27: 前月 | D27: 差異 | E27: 累計
A28: 18℃-飯A15:A23糰(061,063) | B28: ='（５-1）品群別人時生產性(18℃-飯糰)'!C1 -> 738.6893 | C28: ='數值累積總表(月)'!E37 -> 774.12086 | D28: =B28-C28 -> -35.431563 | E28: ='數值累積總表(月)'!P37 -> 766.89213
A29: 18℃-壽司手卷(071,072,075,076) | B29: ='（５-2）品群別人時生產性(18℃-壽司手卷)'!C1 -> 321.22081 | C29: ='數值累積總表(月)'!E38 -> 304.46478 | D29: =B29-C29 -> 16.756025 | E29: ='數值累積總表(月)'!P38 -> 298.89806
A30: 4℃-飯糰(065) | B30: ='（５-3）品群別人時生產性(4℃-飯糰)'!C1 -> 331.22036 | C30: ='數值累積總表(月)'!E39 -> 203.24374 | D30: =B30-C30 -> 127.97661 | E30: ='數值累積總表(月)'!P39 -> 264.31403
A31: 4℃-壽司手卷(077) | B31: ='（５-4）品群別人時生產性(4℃-壽司手卷)'!C1 -> 432.90881 | C31: ='數值累積總表(月)'!E40 -> 490.19814 | D31: =B31-C31 -> -57.289332 | E31: ='數值累積總表(月)'!P40 -> 490.08201
A32: 主食(091,092,093,094,095) | B32: ='（５-5）品群別人時生產性(微波主食) '!C1 -> 81.701029 | C32: ='數值累積總表(月)'!E41 -> 81.452412 | D32: =B32-C32 -> 0.24861744 | E32: ='數值累積總表(月)'!P41 -> 81.357298
A33: 便當(083) | B33: ='（５-6）品群別人時生產性(便當)'!C1 -> 78.068145 | C33: ='數值累積總表(月)'!E42 -> 77.971323 | D33: =B33-C33 -> 0.096822523 | E33: ='數值累積總表(月)'!P42 -> 78.061495
A34: 熱食義麵(122,123,124,126) | B34: ='（５-7）品群別人時生產性(熱食義麵) '!C1 -> 0 | C34: ='數值累積總表(月)'!E43 -> 72.949976 | D34: =B34-C34 -> -72.949976 | E34: ='數值累積總表(月)'!P43 -> 74.600054
A35: 季節調理麵(111,112) | B35: ='（５-8）品群別人時生產性(季節調理麵) '!C1 -> 52.468496 | C35: ='數值累積總表(月)'!E44 -> 97.157501 | D35: =B35-C35 -> -44.689005 | E35: ='數值累積總表(月)'!P44 -> 97.52241
A36: 微波小吃(153,154,155) | B36: ='（５-9）品群別人時生產性(微波小吃)'!C1 -> 83.050675 | C36: ='數值累積總表(月)'!E45 -> 77.592138 | D36: =B36-C36 -> 5.4585371 | E36: ='數值累積總表(月)'!P45 -> 78.920094

Sheet 生產管理報表(週) 
A1: 大溪廠生產管理報表
A3: 月別 | B3: 4 | C3: 週別 | D3: W3 | E3: 工廠 | F3: 大溪廠
A4: （１）收支狀況 | E4: ※單位：千元 | G4: （２）ＫＰＩ達成進度
A5: 項目 | B5: 當週 | C5: 前週 | D5: 差異 | E5: 累計 | G5: 項目 | H5: KPI | I5: 當週 | J5: 前週 | K5: 累計 | L5: ※補充
A6: 業績金額 | B6: ='（１）收支狀況'!G19/1000 -> 42842.571 | C6: 35260.13 | D6: =B6-C6 -> 7582.4411 | E6: ='（１）收支狀況'!H6:H6/1000 -> 102658.13 | G6: 人時性(個/月均) | H6: 442.4 | I6: ='（２）ＫＰＩ達成進度'!G19 -> 393.52033 | J6: 407.834 | K6: ='（２）ＫＰＩ達成進度'!H6 -> 403.78078 | L6: 個／MH
A7: 訂單數量 | B7: ='（１）收支狀況'!J19 -> 1445720 | C7: 1171613 | D7: =B7-C7 -> 274107 | E7: ='（１）收支狀況'!K6:K6 -> 3434128 | G7: 人時達成率(%/月均) | H7: 0.8 | I7: ='（２）ＫＰＩ達成進度'!J19 -> 0.88951251 | J7: 0.92186709 | K7: ='（２）ＫＰＩ達成進度'!K6 -> 0.91270521 | L7: 達成率
A8: 材料費 | B8: ='（１）收支狀況'!M19/1000 -> 28823.931 | C8: 23080.517 | D8: =B8-C8 -> 5743.4144 | E8: ='（１）收支狀況'!N6:N6/1000 -> 68216.662 | G8: 半成品-報廢(%) | H8: 0.0025 | I8: ='（２）ＫＰＩ達成進度'!M19 -> 0.0020149066 | J8: 0.0020153951 | K8: ='（２）ＫＰＩ達成進度'!N6 -> 0.0020138207 | L8: 報廢率
A9: 材料費率 | B9: ='（１）收支狀況'!P19 -> 0.67278715 | C9: 0.65457832 | D9: =B9-C9 -> 0.018208823 | E9: ='（１）收支狀況'!Q6 -> 0.66450324 | G9: 半成品-超用(%) | H9: 0.004 | I9: ='（２）ＫＰＩ達成進度'!P19 -> 0.0043163657 | J9: 0.0043307228 | K9: ='（２）ＫＰＩ達成進度'!Q6 -> 0.0043557808 | L9: 超用率
A10: 勞務成本 | B10: ='（１）收支狀況'!S19/1000 -> 6142.9209 | C10: 5724.5626 | D10: =B10-C10 -> 418.35831 | E10: ='（１）收支狀況'!T6/1000 -> 16301.214 | G10: 固定產線-導入率(%) | H10: 0.8 | I10: ='（２）ＫＰＩ達成進度'!S19 -> 0.9 | J10: 0.9 | K10: ='（２）ＫＰＩ達成進度'!T6 -> 0.9 | L10: 導入率
A11: 勞務費率 | B11: ='（１）收支狀況'!V19 -> 0.14338357 | C11: 0.16235229 | D11: =B11-C11 -> -0.018968711 | E11: ='（１）收支狀況'!W6 -> 0.15879126 | G11: 教育訓練-實施率(%) | H11: 1 | I11: =16/52*100% -> 0.30769231 | J11: 0.28846154 | K11: ='（２）ＫＰＩ達成進度'!W6 -> 0.28942308 | L11: 實施率
A13: （３）業績構成比 | E13: ※單位：千元 | G13: （４）訂單數量構成比 | K13: ※單位：個
B14: 當週 | C14: 比例 | D14: 前週 | E14: 差異 | H14: 當週 | I14: 比例 | J14: 前週 | K14: 差異
A15: 18℃-飯糰(061,063) | B15: =SUM('（３）業績構成比'!M21:M27)/1000 -> 16972.904 | C15: =IFERROR(B15/$B$6,"") -> 0.39616913 | D15: 0.35823353 | E15: =IFERROR(C15-D15,"") -> 0.037935597 | G15: 18℃-飯糰(061,063) | H15: =SUM('（４）訂單數量構成比'!M21:M27) -> 854327 | I15: =IFERROR(H15/$B$7,"") -> 0.59093531 | J15: 0.5750013 | K15: =IFERROR(I15-J15,"") -> 0.015934011
A16: 18℃-壽司手卷(071,072,075,076) | B16: =SUM('（３）業績構成比'!S21:S27)/1000 -> 2346.8853 | C16: =IFERROR(B16/$B$6,"") -> 0.054779283 | D16: 0.076066138 | E16: =IFERROR(C16-D16,"") -> -0.021286855 | G16: 18℃-壽司手卷(071,072,075,076) | H16: =SUM('（４）訂單數量構成比'!S21:S27) -> 88052 | I16: =IFERROR(H16/$B$7,"") -> 0.060905293 | J16: 0.089145477 | K16: =IFERROR(I16-J16,"") -> -0.028240184
A17: 4℃-飯糰(065) | B17: =SUM('（３）業績構成比'!U21:U27)/1000 -> 736.84255 | C17: =IFERROR(B17/$B$6,"") -> 0.017198841 | D17: 0.020699085 | E17: =IFERROR(C17-D17,"") -> -0.0035002445 | G17: 4℃-飯糰(065) | H17: =SUM('（４）訂單數量構成比'!U21:U27) -> 26510 | I17: =IFERROR(H17/$B$7,"") -> 0.018336884 | J17: 0.022621804 | K17: =IFERROR(I17-J17,"") -> -0.0042849203
A18: 4℃-壽司手卷(077) | B18: =SUM('（３）業績構成比'!W21:W27)/1000 -> 1271.2051 | C18: =IFERROR(B18/$B$6,"") -> 0.02967154 | D18: 0.036981819 | E18: =IFERROR(C18-D18,"") -> -0.0073102787 | G18: 4℃-壽司手卷(077) | H18: =SUM('（４）訂單數量構成比'!W21:W27) -> 48063 | I18: =IFERROR(H18/$B$7,"") -> 0.033245027 | J18: 0.037947684 | K18: =IFERROR(I18-J18,"") -> -0.0047026574
A19: 主食(091,092,093,094,095) | B19: =SUM('（３）業績構成比'!AC21:AC27)/1000 -> 6020.3211 | C19: =IFERROR(B19/$B$6,"") -> 0.14052194 | D19: 0.17738386 | E19: =IFERROR(C19-D19,"") -> -0.036861926 | G19: 主食(091,092,093,094,095) | H19: =SUM('（４）訂單數量構成比'!AC21:AC27) -> 114666 | I19: =IFERROR(H19/$B$7,"") -> 0.079314113 | J19: 0.1004743 | K19: =IFERROR(I19-J19,"") -> -0.02116019
A20: 便當(083) | B20: =SUM('（３）業績構成比'!AE21:AE27)/1000 -> 10968.131 | C20: =IFERROR(B20/$B$6,"") -> 0.25601011 | D20: 0.31678583 | E20: =IFERROR(C20-D20,"") -> -0.060775722 | G20: 便當(083) | H20: =SUM('（４）訂單數量構成比'!AE21:AE27) -> 176301 | I20: =IFERROR(H20/$B$7,"") -> 0.12194685 | J20: 0.15365142 | K20: =IFERROR(I20-J20,"") -> -0.031704569
A21: 熱食義麵(122,123,124,126) | B21: =SUM('（３）業績構成比'!AG21:AG27)/1000 -> 0 | C21: =IFERROR(B21/$B$6,"") -> 0 | D21: 0 | E21: =IFERROR(C21-D21,"") -> 0 | G21: 熱食義麵(122,123,124,126) | H21: =SUM('（４）訂單數量構成比'!AG21:AG27) -> 0 | I21: =IFERROR(H21/$B$7,"") -> 0 | J21: 0 | K21: =IFERROR(I21-J21,"") -> 0
A22: 季節調理麵(111,112) | B22: =SUM('（３）業績構成比'!AI21:AI27)/1000 -> 4044.2029 | C22: =IFERROR(B22/$B$6,"") -> 0.094396831 | D22: 0 | E22: =IFERROR(C22-D22,"") -> 0.094396831 | G22: 季節調理麵(111,112) | H22: =SUM('（４）訂單數量構成比'!AI21:AI27) -> 113330 | I22: =IFERROR(H22/$B$7,"") -> 0.078390006 | J22: 0 | K22: =IFERROR(I22-J22,"") -> 0.078390006
A23: 微波小吃(153,154,155) | B23: =SUM('（３）業績構成比'!AK21:AK27)/1000 -> 482.0787 | C23: =IFERROR(B23/$B$6,"") -> 0.011252329 | D23: 0.013849731 | E23: =IFERROR(C23-D23,"") -> -0.0025974017 | G23: 微波小吃(153,154,155) | H23: =SUM('（４）訂單數量構成比'!AK21:AK27) -> 24471 | I23: =IFERROR(H23/$B$7,"") -> 0.016926514 | J23: 0.02115801 | K23: =IFERROR(I23-J23,"") -> -0.0042314962
C24: =SUM(C15:C23) -> 1 | D24: =SUM(D15:D23) -> 1 | I24: =SUM(I15:I23) -> 1 | J24: =SUM(J15:J23) -> 1
A26: （５）品群別人時生產性
A27: 品群 | B27: 當週 | C27: 前週 | D27: 差異 | E27: 累計
A28: 18℃-飯糰(061,063) | B28: ='（５-1）品群別人時生產性(18℃-飯糰)'!L83 -> 728.27543 | C28: 748.8927 | D28: =B28-C28 -> -20.617266 | E28: ='（５-1）品群別人時生產性(18℃-飯糰)'!C1 -> 738.6893
A29: 18℃-壽司手卷(071,072,075,076) | B29: ='（５-2）品群別人時生產性(18℃-壽司手卷)'!L47 -> 319.00268 | C29: 328.57875 | D29: =B29-C29 -> -9.5760684 | E29: ='（５-2）品群別人時生產性(18℃-壽司手卷)'!C1 -> 321.22081
A30: 4℃-飯糰(065) | B30: ='（５-3）品群別人時生產性(4℃-飯糰)'!L47 -> 331.25346 | C30: 331.22235 | D30: =B30-C30 -> 0.031113404 | E30: ='（５-3）品群別人時生產性(4℃-飯糰)'!C1 -> 331.22036
A31: 4℃-壽司手卷(077) | B31: ='（５-4）品群別人時生產性(4℃-壽司手卷)'!L47 -> 397.22974 | C31: 407.51753 | D31: =B31-C31 -> -10.287791 | E31: ='（５-4）品群別人時生產性(4℃-壽司手卷)'!C1 -> 432.90881
A32: 主食(091,092,093,094,095) | B32: ='（５-5）品群別人時生產性(微波主食) '!L47 -> 83.235516 | C32: 80.940665 | D32: =B32-C32 -> 2.2948503 | E32: ='（５-5）品群別人時生產性(微波主食) '!C1 -> 81.701029
A33: 便當(083) | B33: ='（５-6）品群別人時生產性(便當)'!L47 -> 78.328113 | C33: 78.075186 | D33: =B33-C33 -> 0.25292765 | E33: ='（５-6）品群別人時生產性(便當)'!C1 -> 78.068145
A34: 熱食義麵(122,123,124,126) | B34: ='（５-7）品群別人時生產性(熱食義麵) '!L47 -> 0 | C34: 0 | D34: =B34-C34 -> 0 | E34: ='（５-7）品群別人時生產性(熱食義麵) '!C1 -> 0
A35: 季節調理麵(111,112) | B35: ='（５-6）品群別人時生產性(便當)'!L47 -> 78.328113 | C35: 0 | D35: =B35-C35 -> 78.328113 | E35: ='（５-8）品群別人時生產性(季節調理麵) '!C1 -> 52.468496
A36: 微波小吃(153,154,155) | B36: ='（５-9）品群別人時生產性(微波小吃)'!L47 -> 83.065202 | C36: 83.038534 | D36: =B36-C36 -> 0.026668125 | E36: ='（５-9）品群別人時生產性(微波小吃)'!C1 -> 83.050675

Sheet （１）收支狀況
B2: （１）收支狀況
B3: 資料繳交日 | C3: 月份 | D3: 日期 | F3: 營業額(元) | I3: 訂單數量(個) | L3: 材料費(元) | O3: 材料費率（材料費／營業額） | R3: 勞務成本（全廠人事成本） | U3: 勞務費率（勞務成本／營業額）
F4: 日 | G4: 週累積 | H4: 月累積 | I4: 日 | J4: 週累積 | K4: 月累積 | L4: 日 | M4: 週累積 | N4: 月累積 | O4: 日 | P4: 週累積 | Q4: 月累積 | R4: 日 | S4: 週累積 | T4: 月累積 | U4: 日 | V4: 週累積 | W4: 月累積
B5: 46120 | D5: 46112 | E5: 二 | F5: 5566322 | G5: =SUM(F5:F11) -> 30121755 | I5: 179182 | J5: =SUM(I5:I11) -> 995977 | L5: 3707859.1 | M5: =SUM(L5:L11) -> 20020074 | O5: =L5/F5 -> 0.66612371 | P5: =M5/G5 -> 0.66463837 | R5: 863172.14 | S5: =SUM(R5:R11) -> 5296902.8 | U5: =R5/F5 -> 0.15507046 | V5: =S5/G5 -> 0.17584974
C6: 四 | D6: =D5+1 -> 46113 | E6: 三 | F6: 4658389.7 | H6: =SUM(F6:F35) -> 1.0265813e+08 | I6: 156110 | K6: =SUM(I6:I35) -> 3434128 | L6: 3067045.4 | N6: =SUM(L6:L35) -> 68216662 | O6: =L6/F6 -> 0.65839175 | Q6: =N6/H6 -> 0.66450324 | R6: 766317.89 | T6: =SUM(R6:R35) -> 16301214 | U6: =R6/F6 -> 0.16450274 | W6: =T6/H6 -> 0.15879126
D7: =D6+1 -> 46114 | E7: 四 | F7: 3718970.8 | I7: 125387 | L7: 2504899.4 | O7: =L7/F7 -> 0.67354639 | R7: 713559.72 | U7: =R7/F7 -> 0.19187021
D8: =D7+1 -> 46115 | E8: 五 | F8: 3549995.8 | I8: 119195 | L8: 2351927.1 | O8: =L8/F8 -> 0.66251546 | R8: 705005.24 | U8: =R8/F8 -> 0.19859326
D9: =D8+1 -> 46116 | E9: 六 | F9: 3467991.9 | I9: 114970 | L9: 2303676.2 | O9: =L9/F9 -> 0.66426804 | R9: 709401.68 | U9: =R9/F9 -> 0.2045569
D10: =D9+1 -> 46117 | E10: 日 | F10: 3900098.7 | I10: 129122 | L10: 2586288.2 | O10: =L10/F10 -> 0.66313402 | R10: 736893.51 | U10: =R10/F10 -> 0.18894227
D11: =D10+1 -> 46118 | E11: 一 | F11: 5259985.6 | I11: 172011 | L11: 3498378.5 | O11: =L11/F11 -> 0.66509278 | R11: 802552.6 | U11: =R11/F11 -> 0.15257696
B12: =B5+7 -> 46127 | D12: =D11+1 -> 46119 | E12: 二 | F12: 5422854.1 | G12: =SUM(F12:F18) -> 35260130 | I12: 179797 | J12: =SUM(I12:I18) -> 1171613 | L12: 3563094.7 | M12: =SUM(L12:L18) -> 23080517 | O12: =L12/F12 -> 0.65705155 | P12: =M12/G12 -> 0.65457832 | R12: 884507 | S12: =SUM(R12:R18) -> 5724562.6 | U12: =R12/F12 -> 0.16310728 | V12: =S12/G12 -> 0.16235229
D13: =D12+1 -> 46120 | E13: 三 | F13: 5000122.2 | I13: 166150 | L13: 3305441.6 | O13: =L13/F13 -> 0.66107216 | R13: 818122.79 | U13: =R13/F13 -> 0.16362056
D14: =D13+1 -> 46121 | E14: 四 | F14: 4626484.2 | I14: 155377 | L14: 3006928.6 | O14: =L14/F14 -> 0.64993814 | R14: 757121.41 | U14: =R14/F14 -> 0.16364941
D15: =D14+1 -> 46122 | E15: 五 | F15: 4119112.5 | I15: 137940 | L15: 2680565.5 | O15: =L15/F15 -> 0.65076289 | R15: 747813.04 | U15: =R15/F15 -> 0.18154713
D16: =D15+1 -> 46123 | E16: 六 | F16: 4445689.3 | I16: 148324 | L16: 3008585.8 | O16: =L16/F16 -> 0.67674227 | R16: 783926.04 | U16: =R16/F16 -> 0.17633397
D17: =D16+1 -> 46124 | E17: 日 | F17: 5887717.4 | I17: 191499 | L17: 3810263.6 | O17: =L17/F17 -> 0.64715464 | R17: 882575.08 | U17: =R17/F17 -> 0.14990106
D18: =D17+1 -> 46125 | E18: 一 | F18: 5758150 | I18: 192526 | L18: 3705636.7 | O18: =L18/F18 -> 0.64354639 | R18: 850497.28 | U18: =R18/F18 -> 0.14770322
B19: =B12+7 -> 46134 | D19: =D18+1 -> 46126 | E19: 二 | F19: 6972503.3 | G19: =SUM(F19:F25) -> 42842571 | I19: 236038 | J19: =SUM(I19:I25) -> 1445720 | L19: 4734401.6 | M19: =SUM(L19:L25) -> 28823931 | O19: =L19/F19 -> 0.67901031 | P19: =M19/G19 -> 0.67278715 | R19: 982263.52 | S19: =SUM(R19:R25) -> 6142920.9 | U19: =R19/F19 -> 0.14087674 | V19: =S19/G19 -> 0.14338357
D20: =D19+1 -> 46127 | E20: 三 | F20: 6457162.2 | I20: 218111 | L20: 4305928.6 | O20: =L20/F20 -> 0.66684536 | R20: 906270.98 | U20: =R20/F20 -> 0.14035128
D21: =D20+1 -> 46128 | E21: 四 | F21: 5781414.6 | I21: 197163 | L21: 3881534.5 | O21: =L21/F21 -> 0.67138144 | R21: 843663.48 | U21: =R21/F21 -> 0.14592683
D22: =D21+1 -> 46129 | E22: 五 | F22: 5012455.3 | I22: 171515 | L22: 3414877.3 | O22: =L22/F22 -> 0.68127835 | R22: 796938.67 | U22: =R22/F22 -> 0.15899167
D23: =D22+1 -> 46130 | E23: 六 | F23: 5245500.3 | I23: 179200 | L23: 3454675.7 | O23: =L23/F23 -> 0.65859794 | R23: 802448.93 | U23: =R23/F23 -> 0.15297853
D24: =D23+1 -> 46131 | E24: 日 | F24: 6890291.9 | I24: 227448 | L24: 4653717.3 | O24: =L24/F24 -> 0.67540206 | R24: 922125.71 | U24: =R24/F24 -> 0.1338297
D25: =D24+1 -> 46132 | E25: 一 | F25: 6483243.3 | I25: 216245 | L25: 4378795.9 | O25: =L25/F25 -> 0.67540206 | R25: 889209.66 | U25: =R25/F25 -> 0.13715507
B26: =B19+7 -> 46141 | D26: =D25+1 -> 46133 | E26: 二 | G26: =SUM(F26:F32) -> 0 | J26: =SUM(I26:I32) -> 0 | M26: =SUM(L26:L32) -> 0 | O26: =L26/F26 -> #DIV/0! | P26: =M26/G26 -> #DIV/0! | S26: =SUM(R26:R32) -> 0 | U26: =R26/F26 -> #DIV/0! | V26: =S26/G26 -> #DIV/0!
D27: =D26+1 -> 46134 | E27: 三 | O27: =L27/F27 -> #DIV/0! | U27: =R27/F27 -> #DIV/0!
D28: =D27+1 -> 46135 | E28: 四 | O28: =L28/F28 -> #DIV/0! | U28: =R28/F28 -> #DIV/0!
D29: =D28+1 -> 46136 | E29: 五 | O29: =L29/F29 -> #DIV/0! | U29: =R29/F29 -> #DIV/0!
D30: =D29+1 -> 46137 | E30: 六 | O30: =L30/F30 -> #DIV/0! | U30: =R30/F30 -> #DIV/0!
D31: =D30+1 -> 46138 | E31: 日 | O31: =L31/F31 -> #DIV/0! | U31: =R31/F31 -> #DIV/0!
D32: =D31+1 -> 46139 | E32: 一 | O32: =L32/F32 -> #DIV/0! | U32: =R32/F32 -> #DIV/0!
B33: =B26+7 -> 46148 | D33: =D32+1 -> 46140 | E33: 二 | G33: =SUM(F33:F39) -> 0 | J33: =SUM(I33:I39) -> 0 | M33: =SUM(L33:L39) -> 0 | O33: =L33/F33 -> #DIV/0! | P33: =M33/G33 -> #DIV/0! | S33: =SUM(R33:R39) -> 0 | U33: =R33/F33 -> #DIV/0! | V33: =S33/G33 -> #DIV/0!
D34: =D33+1 -> 46141 | E34: 三 | O34: =L34/F34 -> #DIV/0! | U34: =R34/F34 -> #DIV/0!
D35: =D34+1 -> 46142 | E35: 四 | O35: =L35/F35 -> #DIV/0! | U35: =R35/F35 -> #DIV/0!
D36: =D35+1 -> 46143 | E36: 五 | O36: =L36/F36 -> #DIV/0! | U36: =R36/F36 -> #DIV/0!
D37: =D36+1 -> 46144 | E37: 六 | O37: =L37/F37 -> #DIV/0! | U37: =R37/F37 -> #DIV/0!
D38: =D37+1 -> 46145 | E38: 日 | O38: =L38/F38 -> #DIV/0! | U38: =R38/F38 -> #DIV/0!
D39: =D38+1 -> 46146 | E39: 一 | O39: =L39/F39 -> #DIV/0! | U39: =R39/F39 -> #DIV/0!

Sheet （２）ＫＰＩ達成進度
B1: 人時生產性基準值 | C1: 442.4
B2: （２）ＫＰＩ達成進度
B3: 資料繳交日 | C3: 月份 | D3: 日期 | F3: 人時生產性(個/人) | I3: 人時生產性達成率(%) | L3: 半成品報廢(%) | O3: 半成品超用(%) | R3: 固定產線-導入率(固定產線數/總產線數) | U3: 教育訓練-實施率(進度/計畫)
F4: 日 | G4: 週平均 | H4: 月平均 | I4: 日 | J4: 週平均 | K4: 月平均 | L4: 日 | M4: 週平均 | N4: 月平均 | O4: 日 | P4: 週平均 | Q4: 月平均 | R4: 日 | S4: 週平均 | T4: 月平均 | U4: 日 | V4: 週平均 | W4: 月平均
B5: 46120 | D5: 46112 | E5: 二 | F5: 410.20375 | G5: =AVERAGE(F5:F11) -> 410.90558 | I5: =F5/$C$1 -> 0.92722367 | J5: =AVERAGE(I5:I11) -> 0.92881008 | L5: 0.0020115287 | M5: =AVERAGE(L5:L11) -> 0.002010833 | O5: 0.0044775692 | P5: =AVERAGE(O5:O11) -> 0.0044376523 | R5: 0.9 | S5: =AVERAGE(R5:R11) -> 0.9 | U5: =14/52*100% -> 0.26923077 | V5: =AVERAGE(U5:U11) -> 0.26923077
C6: 四 | D6: =D5+1 -> 46113 | E6: 三 | F6: 412.3539 | H6: =AVERAGEIF(F6:F35,"<>0") -> 403.78078 | I6: =F6/$C$1 -> 0.93208386 | K6: =AVERAGEIF(I6:I35,"<>0") -> 0.91270521 | L6: 0.0020102006 | N6: =AVERAGEIF(L6:L35,"<>0") -> 0.0020138207 | O6: 0.0044516756 | Q6: =AVERAGEIF(O6:O35,"<>0") -> 0.0043557808 | R6: 0.9 | T6: =AVERAGEIF(R6:R35,"<>0") -> 0.9 | U6: =14/52*100% -> 0.26923077 | W6: =AVERAGEIF(U6:U35,"<>0") -> 0.28942308
D7: =D6+1 -> 46114 | E7: 四 | F7: 413.12637 | I7: =F7/$C$1 -> 0.93382994 | L7: 0.0020157613 | O7: 0.0044335572 | R7: 0.9 | U7: =14/52*100% -> 0.26923077
D8: =D7+1 -> 46115 | E8: 五 | F8: 413.20841 | I8: =F8/$C$1 -> 0.9340154 | L8: 0.0020102222 | O8: 0.0044111784 | R8: 0.9 | U8: =14/52*100% -> 0.26923077
D9: =D8+1 -> 46116 | E9: 六 | F9: 410.99928 | I9: =F9/$C$1 -> 0.92902189 | L9: 0.002005793 | O9: 0.0044036967 | R9: 0.9 | U9: =14/52*100% -> 0.26923077
D10: =D9+1 -> 46117 | E10: 日 | F10: 410.97079 | I10: =F10/$C$1 -> 0.92895748 | L10: 0.0020082164 | O10: 0.0044119437 | R10: 0.9 | U10: =14/52*100% -> 0.26923077
D11: =D10+1 -> 46118 | E11: 一 | F11: 405.47656 | I11: =F11/$C$1 -> 0.91653833 | L11: 0.002014109 | O11: 0.0044739455 | R11: 0.9 | U11: =14/52*100% -> 0.26923077
B12: =B5+7 -> 46127 | D12: =D11+1 -> 46119 | E12: 二 | F12: 404.90475 | G12: =AVERAGE(F12:F18) -> 407.834 | I12: =F12/$C$1 -> 0.91524583 | J12: =AVERAGE(I12:I18) -> 0.92186709 | L12: 0.0020201585 | M12: =AVERAGE(L12:L18) -> 0.0020153951 | O12: 0.0043276383 | P12: =AVERAGE(O12:O18) -> 0.0043307228 | R12: 0.9 | S12: =AVERAGE(R12:R18) -> 0.9 | U12: =15/52*100% -> 0.28846154 | V12: =AVERAGE(U12:U18) -> 0.28846154
D13: =D12+1 -> 46120 | E13: 三 | F13: 405.31668 | I13: =F13/$C$1 -> 0.91617695 | L13: 0.0020155733 | O13: 0.0043342109 | R13: 0.9 | U13: =15/52*100% -> 0.28846154
D14: =D13+1 -> 46121 | E14: 四 | F14: 407.25962 | I14: =F14/$C$1 -> 0.92056875 | L14: 0.002013879 | O14: 0.0041880141 | R14: 0.9 | U14: =15/52*100% -> 0.28846154
D15: =D14+1 -> 46122 | E15: 五 | F15: 407.72238 | I15: =F15/$C$1 -> 0.92161479 | L15: 0.0020055706 | O15: 0.0041643234 | R15: 0.9 | U15: =15/52*100% -> 0.28846154
D16: =D15+1 -> 46123 | E16: 六 | F16: 407.72238 | I16: =F16/$C$1 -> 0.92161479 | L16: 0.0020123063 | O16: 0.0045432982 | R16: 0.9 | U16: =15/52*100% -> 0.28846154
D17: =D16+1 -> 46124 | E17: 日 | F17: 407.43387 | I17: =F17/$C$1 -> 0.92096263 | L17: 0.0020202072 | O17: 0.0043819396 | R17: 0.9 | U17: =15/52*100% -> 0.28846154
D18: =D17+1 -> 46125 | E18: 一 | F18: 414.47832 | I18: =F18/$C$1 -> 0.9368859 | L18: 0.0020200704 | O18: 0.0043756351 | R18: 0.9 | U18: =15/52*100% -> 0.28846154
B19: =B12+7 -> 46134 | D19: =D18+1 -> 46126 | E19: 二 | F19: 390.84595 | G19: =AVERAGE(F19:F25) -> 393.52033 | I19: =F19/$C$1 -> 0.88346733 | J19: =AVERAGE(I19:I25) -> 0.88951251 | L19: 0.0020252908 | M19: =AVERAGE(L19:L25) -> 0.0020149066 | O19: 0.0043072154 | P19: =AVERAGE(O19:O25) -> 0.0043163657 | R19: 0.9 | S19: =AVERAGE(R19:R25) -> 0.9 | U19: =16/52*100% -> 0.30769231 | V19: =AVERAGE(U19:U25) -> 0.30769231
D20: =D19+1 -> 46127 | E20: 三 | F20: 391.6932 | I20: =F20/$C$1 -> 0.88538247 | L20: 0.0020180784 | O20: 0.0042965399 | R20: 0.9 | U20: =16/52*100% -> 0.30769231
D21: =D20+1 -> 46128 | E21: 四 | F21: 395.47062 | I21: =F21/$C$1 -> 0.89392093 | L21: 0.0020143241 | O21: 0.0042908731 | R21: 0.9 | U21: =16/52*100% -> 0.30769231
D22: =D21+1 -> 46129 | E22: 五 | F22: 393.86102 | I22: =F22/$C$1 -> 0.8902826 | L22: 0.0020086653 | O22: 0.0042765285 | R22: 0.9 | U22: =16/52*100% -> 0.30769231
D23: =D22+1 -> 46130 | E23: 六 | F23: 394.15729 | I23: =F23/$C$1 -> 0.89095227 | L23: 0.0020099673 | O23: 0.0044085363 | R23: 0.9 | U23: =16/52*100% -> 0.30769231
D24: =D23+1 -> 46131 | E24: 日 | F24: 394.19777 | I24: =F24/$C$1 -> 0.89104378 | L24: 0.002015922 | O24: 0.004311963 | R24: 0.9 | U24: =16/52*100% -> 0.30769231
D25: =D24+1 -> 46132 | E25: 一 | F25: 394.41649 | I25: =F25/$C$1 -> 0.89153817 | L25: 0.0020120983 | O25: 0.0043229041 | R25: 0.9 | U25: =16/52*100% -> 0.30769231
B26: =B19+7 -> 46141 | D26: =D25+1 -> 46133 | E26: 二 | G26: =AVERAGE(F26:F32) -> #DIV/0! | J26: =AVERAGE(I26:I32) -> #DIV/0! | M26: =AVERAGE(L26:L32) -> #DIV/0! | P26: =AVERAGE(O26:O32) -> #DIV/0! | S26: =AVERAGE(R26:R32) -> #DIV/0! | V26: =AVERAGE(U26:U32) -> #DIV/0!
D27: =D26+1 -> 46134 | E27: 三
D28: =D27+1 -> 46135 | E28: 四
D29: =D28+1 -> 46136 | E29: 五
D30: =D29+1 -> 46137 | E30: 六
D31: =D30+1 -> 46138 | E31: 日
D32: =D31+1 -> 46139 | E32: 一
B33: =B26+7 -> 46148 | D33: =D32+1 -> 46140 | E33: 二 | G33: =AVERAGE(F33:F39) -> #DIV/0! | J33: =AVERAGE(I33:I39) -> #DIV/0! | M33: =AVERAGE(L33:L39) -> #DIV/0! | P33: =AVERAGE(O33:O39) -> #DIV/0! | S33: =AVERAGE(R33:R39) -> #DIV/0! | V33: =AVERAGE(U33:U39) -> #DIV/0!
D34: =D33+1 -> 46141 | E34: 三
D35: =D34+1 -> 46142 | E35: 四
D36: =D35+1 -> 46143 | E36: 五
D37: =D36+1 -> 46144 | E37: 六
D38: =D37+1 -> 46145 | E38: 日
D39: =D38+1 -> 46146 | E39: 一

Sheet （３）業績構成比
B2: （3）業績構成比
B3: 資料繳交日 | C3: 月份 | D3: 日期 | F3: 營業額 | I3: 品類業績
I4: 18℃-飯糰 | O4: 18℃-壽司手卷 | U4: 4℃-飯糰 | W4: 4℃-壽司手卷 | Y4: 主食 | AE4: 便當 | AG4: 熱食義麵 | AI4: 季節調理麵 | AK4: 微波小吃
F5: 日 | G5: 週累積 | H5: 月累積 | I5: 一配 | K5: 二配 | M5: 合計 | O5: 一配 | Q5: 二配 | S5: 合計 | U5: 一配 | W5: 一配 | Y5: 一配 | AA5: 二配 | AC5: 合計 | AE5: 一配 | AG5: 一配 | AI5: 一配 | AK5: 一配
I6: 業績(元) | J6: 比例(%) | K6: 業績(元) | L6: 比例(%) | M6: 業績(元) | N6: 比例(%) | O6: 業績(元) | P6: 比例(%) | Q6: 業績(元) | R6: 比例(%) | S6: 業績(元) | T6: 比例(%) | U6: 業績(元) | V6: 比例(%) | W6: 業績(元) | X6: 比例(%) | Y6: 業績(元) | Z6: 比例(%) | AA6: 業績(元) | AB6: 比例(%) | AC6: 業績(元) | AD6: 比例(%) | AE6: 業績(元) | AF6: 比例(%) | AG6: 業績(元) | AH6: 比例(%) | AI6: 業績(元) | AJ6: 比例(%) | AK6: 業績(元) | AL6: 比例(%)
B7: 46120 | D7: 46112 | E7: 二 | F7: =SUM(M7,S7,U7,W7,AC7,AE7,AG7,AI7,AK7) -> 5566322 | G7: =SUM(F7:F13) -> 30121755 | I7: 752249.45 | J7: =I7/$F7 -> 0.135143 | K7: 1129332.2 | L7: =K7/$F7 -> 0.20288661 | M7: =I7+K7 -> 1881581.7 | N7: =M7/$F7 -> 0.33802961 | O7: 273203.44 | P7: =O7/$F7 -> 0.049081501 | Q7: 158294.29 | R7: =Q7/$F7 -> 0.028437861 | S7: =O7+Q7 -> 431497.73 | T7: =S7/$F7 -> 0.077519362 | U7: 121140.07 | V7: =U7/$F7 -> 0.021763037 | W7: 55570.2 | X7: =W7/$F7 -> 0.0099832888 | Y7: 210219.31 | Z7: =Y7/$F7 -> 0.037766286 | AA7: 691696.28 | AB7: =AA7/$F7 -> 0.12426451 | AC7: =Y7+AA7 -> 901915.59 | AD7: =AC7/$F7 -> 0.1620308 | AE7: 2104169.5 | AF7: =AE7/F7 -> 0.37801793 | AG7: 0 | AH7: =AG7/$F7 -> 0 | AI7: 0 | AJ7: =AI7/$F7 -> 0 | AK7: 70447.2 | AL7: =AK7/$F7 -> 0.012655969
C8: 四 | D8: 46113 | E8: 三 | F8: =SUM(M8,S8,U8,W8,AC8,AE8,AG8,AI8,AK8) -> 4658389.7 | H8: =SUM(F8:F37) -> 1.0265813e+08 | I8: 719533.41 | J8: =I8/$F8 -> 0.15445968 | K8: 970987.48 | L8: =K8/$F8 -> 0.20843844 | M8: =I8+K8 -> 1690520.9 | N8: =M8/F8 -> 0.36289812 | O8: 261602.18 | P8: =O8/$F8 -> 0.056157212 | Q8: 149817.69 | R8: =Q8/$F8 -> 0.032160832 | S8: =O8+Q8 -> 411419.87 | T8: =S8/F8 -> 0.088318044 | U8: 107039.32 | V8: =U8/F8 -> 0.022977751 | W8: 53783.39 | X8: =W8/$F8 -> 0.01154549 | Y8: 181153.07 | Z8: =Y8/$F8 -> 0.038887487 | AA8: 510626.16 | AB8: =AA8/$F8 -> 0.10961431 | AC8: =Y8+AA8 -> 691779.23 | AD8: =AC8/$F8 -> 0.14850179 | AE8: 1631567.7 | AF8: =AE8/F8 -> 0.35024286 | AG8: 0 | AH8: =AG8/$F8 -> 0 | AI8: 0 | AJ8: =AI8/$F8 -> 0 | AK8: 72279.3 | AL8: =AK8/$F8 -> 0.015515941
D9: 46114 | E9: 四 | F9: =SUM(M9,S9,U9,W9,AC9,AE9,AG9,AI9,AK9) -> 3718970.8 | I9: 518858.25 | J9: =I9/$F9 -> 0.13951662 | K9: 839779.06 | L9: =K9/$F9 -> 0.22580953 | M9: =I9+K9 -> 1358637.3 | N9: =M9/$F9 -> 0.36532615 | O9: 182456.07 | P9: =O9/$F9 -> 0.049060904 | Q9: 128612.81 | R9: =Q9/$F9 -> 0.034582904 | S9: =O9+Q9 -> 311068.88 | T9: =S9/$F9 -> 0.083643807 | U9: 100483.61 | V9: =U9/$F9 -> 0.027019198 | W9: 56261.58 | X9: =W9/$F9 -> 0.015128266 | Y9: 162305.43 | Z9: =Y9/$F9 -> 0.043642566 | AA9: 451157.26 | AB9: =AA9/$F9 -> 0.1213124 | AC9: =Y9+AA9 -> 613462.69 | AD9: =AC9/$F9 -> 0.16495496 | AE9: 1213869.5 | AF9: =AE9/F9 -> 0.3263993 | AG9: 0 | AH9: =AG9/$F9 -> 0 | AI9: 0 | AJ9: =AI9/$F9 -> 0 | AK9: 65187.3 | AL9: =AK9/$F9 -> 0.017528317
D10: 46115 | E10: 五 | F10: =SUM(M10,S10,U10,W10,AC10,AE10,AG10,AI10,AK10) -> 3549995.8 | I10: 491564.32 | J10: =I10/$F10 -> 0.13846898 | K10: 782541.59 | L10: =K10/$F10 -> 0.22043451 | M10: =I10+K10 -> 1274105.9 | N10: =M10/F10 -> 0.35890349 | O10: 173037.11 | P10: =O10/$F10 -> 0.048742905 | Q10: 126119.12 | R10: =Q10/$F10 -> 0.035526554 | S10: =O10+Q10 -> 299156.23 | T10: =S10/F10 -> 0.084269459 | U10: 90274.5 | V10: =U10/F10 -> 0.025429466 | W10: 51525.3 | X10: =W10/$F10 -> 0.014514186 | Y10: 165257.47 | Z10: =Y10/$F10 -> 0.046551455 | AA10: 533278.96 | AB10: =AA10/$F10 -> 0.1502196 | AC10: =Y10+AA10 -> 698536.43 | AD10: =AC10/$F10 -> 0.19677106 | AE10: 1069673.6 | AF10: =AE10/F10 -> 0.30131685 | AG10: 0 | AH10: =AG10/$F10 -> 0 | AI10: 0 | AJ10: =AI10/$F10 -> 0 | AK10: 66723.9 | AL10: =AK10/$F10 -> 0.018795487
D11: 46116 | E11: 六 | F11: =SUM(M11,S11,U11,W11,AC11,AE11,AG11,AI11,AK11) -> 3467991.9 | I11: 462930.57 | J11: =I11/$F11 -> 0.13348664 | K11: 745948.21 | L11: =K11/$F11 -> 0.21509514 | M11: =I11+K11 -> 1208878.8 | N11: =M11/$F11 -> 0.34858178 | O11: 165347.73 | P11: =O11/$F11 -> 0.047678234 | Q11: 120162.98 | R11: =Q11/$F11 -> 0.034649153 | S11: =O11+Q11 -> 285510.71 | T11: =S11/$F11 -> 0.082327387 | U11: 88877.66 | V11: =U11/$F11 -> 0.02562799 | W11: 54072.54 | X11: =W11/$F11 -> 0.015591888 | Y11: 179279.66 | Z11: =Y11/$F11 -> 0.051695525 | AA11: 516766.39 | AB11: =AA11/$F11 -> 0.14901027 | AC11: =Y11+AA11 -> 696046.05 | AD11: =AC11/$F11 -> 0.20070579 | AE11: 1077988.3 | AF11: =AE11/F11 -> 0.31083935 | AG11: 0 | AH11: =AG11/$F11 -> 0 | AI11: 0 | AJ11: =AI11/$F11 -> 0 | AK11: 56617.8 | AL11: =AK11/$F11 -> 0.016325817
D12: 46117 | E12: 日 | F12: =SUM(M12,S12,U12,W12,AC12,AE12,AG12,AI12,AK12) -> 3900098.7 | I12: 479277.5 | J12: =I12/$F12 -> 0.12288856 | K12: 911676.73 | L12: =K12/$F12 -> 0.23375735 | M12: =I12+K12 -> 1390954.2 | N12: =M12/F12 -> 0.3566459 | O12: 173959.83 | P12: =O12/$F12 -> 0.044603955 | Q12: 131401.9 | R12: =Q12/$F12 -> 0.033691942 | S12: =O12+Q12 -> 305361.73 | T12: =S12/F12 -> 0.078295897 | U12: 89975.67 | V12: =U12/F12 -> 0.023070101 | W12: 44345.78 | X12: =W12/$F12 -> 0.011370425 | Y12: 184161.88 | Z12: =Y12/$F12 -> 0.047219799 | AA12: 669396.06 | AB12: =AA12/$F12 -> 0.17163567 | AC12: =Y12+AA12 -> 853557.94 | AD12: =AC12/$F12 -> 0.21885547 | AE12: 1167677.8 | AF12: =AE12/F12 -> 0.29939698 | AG12: 0 | AH12: =AG12/$F12 -> 0 | AI12: 0 | AJ12: =AI12/$F12 -> 0 | AK12: 48225.6 | AL12: =AK12/$F12 -> 0.012365225
D13: 46118 | E13: 一 | F13: =SUM(M13,S13,U13,W13,AC13,AE13,AG13,AI13,AK13) -> 5259985.6 | I13: 734783.02 | J13: =I13/$F13 -> 0.13969297 | K13: 1178346.5 | L13: =K13/$F13 -> 0.22402086 | M13: =I13+K13 -> 1913129.6 | N13: =M13/$F13 -> 0.36371384 | O13: 244577.85 | P13: =O13/$F13 -> 0.046497817 | Q13: 36895.96 | R13: =Q13/$F13 -> 0.0070144602 | S13: =O13+Q13 -> 281473.81 | T13: =S13/$F13 -> 0.053512277 | U13: 114560.81 | V13: =U13/$F13 -> 0.021779681 | W13: 54753.82 | X13: =W13/$F13 -> 0.0104095 | Y13: 233835.63 | Z13: =Y13/$F13 -> 0.044455564 | AA13: 739447.82 | AB13: =AA13/$F13 -> 0.14057982 | AC13: =Y13+AA13 -> 973283.45 | AD13: =AC13/$F13 -> 0.18503538 | AE13: 1855823.9 | AF13: =AE13/F13 -> 0.3528192 | AG13: 0 | AH13: =AG13/$F13 -> 0 | AI13: 0 | AJ13: =AI13/$F13 -> 0 | AK13: 66960.3 | AL13: =AK13/$F13 -> 0.01273013
B14: =D15+7 -> 46127 | D14: 46119 | E14: 二 | F14: =SUM(M14,S14,U14,W14,AC14,AE14,AG14,AI14,AK14) -> 5422854.1 | G14: =SUM(F14:F20) -> 35260130 | I14: 726498.72 | J14: =I14/$F14 -> 0.13396981 | K14: 1140765 | L14: =K14/$F14 -> 0.21036246 | M14: =I14+K14 -> 1867263.7 | N14: =M14/$F14 -> 0.34433227 | O14: 412715.15 | P14: =O14/$F14 -> 0.07610663 | Q14: 36588.28 | R14: =Q14/$F14 -> 0.0067470523 | S14: =O14+Q14 -> 449303.43 | T14: =S14/$F14 -> 0.082853682 | U14: 107099.04 | V14: =U14/$F14 -> 0.019749571 | W14: 299758.41 | X14: =W14/$F14 -> 0.055276872 | Y14: 221005.61 | Z14: =Y14/$F14 -> 0.040754482 | AA14: 703046 | AB14: =AA14/$F14 -> 0.12964502 | AC14: =Y14+AA14 -> 924051.61 | AD14: =AC14/$F14 -> 0.1703995 | AE14: 1709067.7 | AF14: =AE14/F14 -> 0.31516019 | AG14: 0 | AH14: =AG14/$F14 -> 0 | AI14: 0 | AJ14: =AI14/$F14 -> 0 | AK14: 66310.2 | AL14: =AK14/$F14 -> 0.012227915
D15: 46120 | E15: 三 | F15: =SUM(M15,S15,U15,W15,AC15,AE15,AG15,AI15,AK15) -> 5000122.2 | I15: 715108.15 | J15: =I15/$F15 -> 0.14301813 | K15: 1092771.8 | L15: =K15/$F15 -> 0.21854901 | M15: =I15+K15 -> 1807879.9 | N15: =M15/F15 -> 0.36156715 | O15: 284132.89 | P15: =O15/$F15 -> 0.056825189 | Q15: 38434.36 | R15: =Q15/$F15 -> 0.0076866841 | S15: =O15+Q15 -> 322567.25 | T15: =S15/F15 -> 0.064511873 | U15: 102456.79 | V15: =U15/F15 -> 0.020490857 | W15: 189354.67 | X15: =W15/$F15 -> 0.037870008 | Y15: 245587.02 | Z15: =Y15/$F15 -> 0.049116203 | AA15: 667171.61 | AB15: =AA15/$F15 -> 0.13343106 | AC15: =Y15+AA15 -> 912758.63 | AD15: =AC15/$F15 -> 0.18254726 | AE15: 1593830.4 | AF15: =AE15/F15 -> 0.31875828 | AG15: 0 | AH15: =AG15/$F15 -> 0 | AI15: 0 | AJ15: =AI15/$F15 -> 0 | AK15: 71274.6 | AL15: =AK15/$F15 -> 0.014254572
D16: 46121 | E16: 四 | F16: =SUM(M16,S16,U16,W16,AC16,AE16,AG16,AI16,AK16) -> 4626484.2 | I16: 707984.22 | J16: =I16/$F16 -> 0.15302856 | K16: 986475.33 | L16: =K16/$F16 -> 0.21322354 | M16: =I16+K16 -> 1694459.6 | N16: =M16/$F16 -> 0.3662521 | O16: 284757.63 | P16: =O16/$F16 -> 0.061549465 | Q16: 39126.64 | R16: =Q16/$F16 -> 0.0084571 | S16: =O16+Q16 -> 323884.27 | T16: =S16/$F16 -> 0.070006565 | U16: 100285.57 | V16: =U16/$F16 -> 0.02167641 | W16: 179198.42 | X16: =W16/$F16 -> 0.038733174 | Y16: 208629.75 | Z16: =Y16/$F16 -> 0.045094664 | AA16: 570556.21 | AB16: =AA16/$F16 -> 0.12332393 | AC16: =Y16+AA16 -> 779185.96 | AD16: =AC16/$F16 -> 0.16841859 | AE16: 1477841.3 | AF16: =AE16/F16 -> 0.31943074 | AG16: 0 | AH16: =AG16/$F16 -> 0 | AI16: 0 | AJ16: =AI16/$F16 -> 0 | AK16: 71629.2 | AL16: =AK16/$F16 -> 0.015482426
D17: 46122 | E17: 五 | F17: =SUM(M17,S17,U17,W17,AC17,AE17,AG17,AI17,AK17) -> 4119112.5 | I17: 546375 | J17: =I17/$F17 -> 0.13264386 | K17: 932111.57 | L17: =K17/$F17 -> 0.22628942 | M17: =I17+K17 -> 1478486.6 | N17: =M17/F17 -> 0.35893328 | O17: 345940.9 | P17: =O17/$F17 -> 0.083984329 | Q17: 30947.48 | R17: =Q17/$F17 -> 0.0075131427 | S17: =O17+Q17 -> 376888.38 | T17: =S17/F17 -> 0.091497472 | U17: 86602.33 | V17: =U17/F17 -> 0.021024512 | W17: 98150.12 | X17: =W17/$F17 -> 0.023827978 | Y17: 186205.6 | Z17: =Y17/$F17 -> 0.045205272 | AA17: 584960.54 | AB17: =AA17/$F17 -> 0.1420113 | AC17: =Y17+AA17 -> 771166.14 | AD17: =AC17/$F17 -> 0.18721658 | AE17: 1238494.6 | AF17: =AE17/F17 -> 0.30067027 | AG17: 0 | AH17: =AG17/$F17 -> 0 | AI17: 0 | AJ17: =AI17/$F17 -> 0 | AK17: 69324.3 | AL17: =AK17/$F17 -> 0.016829912
D18: 46123 | E18: 六 | F18: =SUM(M18,S18,U18,W18,AC18,AE18,AG18,AI18,AK18) -> 4445689.3 | I18: 527618.04 | J18: =I18/$F18 -> 0.11868082 | K18: 1046469.2 | L18: =K18/$F18 -> 0.23538965 | M18: =I18+K18 -> 1574087.3 | N18: =M18/$F18 -> 0.35407047 | O18: 321897.41 | P18: =O18/$F18 -> 0.072406637 | Q18: 31178.24 | R18: =Q18/$F18 -> 0.0070131397 | S18: =O18+Q18 -> 353075.65 | T18: =S18/$F18 -> 0.079419777 | U18: 96924.85 | V18: =U18/$F18 -> 0.021801985 | W18: 161005.28 | X18: =W18/$F18 -> 0.036216044 | Y18: 201817.35 | Z18: =Y18/$F18 -> 0.045396189 | AA18: 653197.6 | AB18: =AA18/$F18 -> 0.14692831 | AC18: =Y18+AA18 -> 855014.95 | AD18: =AC18/$F18 -> 0.1923245 | AE18: 1338680.1 | AF18: =AE18/F18 -> 0.30111867 | AG18: 0 | AH18: =AG18/$F18 -> 0 | AI18: 0 | AJ18: =AI18/$F18 -> 0 | AK18: 66901.2 | AL18: =AK18/$F18 -> 0.015048555
D19: 46124 | E19: 日 | F19: =SUM(M19,S19,U19,W19,AC19,AE19,AG19,AI19,AK19) -> 5887717.4 | I19: 784944.8 | J19: =I19/$F19 -> 0.13331903 | K19: 1182563.4 | L19: =K19/$F19 -> 0.20085261 | M19: =I19+K19 -> 1967508.2 | N19: =M19/F19 -> 0.33417165 | O19: 468701.41 | P19: =O19/$F19 -> 0.079606642 | Q19: 39331.76 | R19: =Q19/$F19 -> 0.006680307 | S19: =O19+Q19 -> 508033.17 | T19: =S19/F19 -> 0.086286949 | U19: 121800.06 | V19: =U19/F19 -> 0.020687144 | W19: 201043.55 | X19: =W19/$F19 -> 0.034146264 | Y19: 278343.31 | Z19: =Y19/$F19 -> 0.04727525 | AA19: 752453.89 | AB19: =AA19/$F19 -> 0.12780061 | AC19: =Y19+AA19 -> 1030797.2 | AD19: =AC19/$F19 -> 0.17507586 | AE19: 1988442.6 | AF19: =AE19/F19 -> 0.33772725 | AG19: 0 | AH19: =AG19/$F19 -> 0 | AI19: 0 | AJ19: =AI19/$F19 -> 0 | AK19: 70092.6 | AL19: =AK19/$F19 -> 0.011904885
D20: 46125 | E20: 一 | F20: =SUM(M20,S20,U20,W20,AC20,AE20,AG20,AI20,AK20) -> 5758150 | I20: 786274.22 | J20: =I20/$F20 -> 0.1365498 | K20: 1455401.4 | L20: =K20/$F20 -> 0.25275503 | M20: =I20+K20 -> 2241675.6 | N20: =M20/$F20 -> 0.38930483 | O20: 348349.76 | P20: =O20/$F20 -> 0.060496819 | Q20: 0 | R20: =Q20/$F20 -> 0 | S20: =O20+Q20 -> 348349.76 | T20: =S20/$F20 -> 0.060496819 | U20: 114683.79 | V20: =U20/$F20 -> 0.019916777 | W20: 175473.28 | X20: =W20/$F20 -> 0.030473899 | Y20: 253478.05 | Z20: =Y20/$F20 -> 0.044020744 | AA20: 728125.53 | AB20: =AA20/$F20 -> 0.1264513 | AC20: =Y20+AA20 -> 981603.58 | AD20: =AC20/$F20 -> 0.17047204 | AE20: 1823552.8 | AF20: =AE20/F20 -> 0.31669074 | AG20: 0 | AH20: =AG20/$F20 -> 0 | AI20: 0 | AJ20: =AI20/$F20 -> 0 | AK20: 72811.2 | AL20: =AK20/$F20 -> 0.012644895
B21: =D22+7 -> 46134 | D21: 46126 | E21: 二 | F21: =SUM(M21,S21,U21,W21,AC21,AE21,AG21,AI21,AK21) -> 6972503.3 | G21: =SUM(F21:F27) -> 42842571 | I21: 1258157.2 | J21: =I21/$F21 -> 0.18044554 | K21: 1524527.7 | L21: =K21/$F21 -> 0.21864855 | M21: =I21+K21 -> 2782684.9 | N21: =M21/$F21 -> 0.3990941 | O21: 393165.25 | P21: =O21/$F21 -> 0.056387962 | Q21: 0 | R21: =Q21/$F21 -> 0 | S21: =O21+Q21 -> 393165.25 | T21: =S21/$F21 -> 0.056387962 | U21: 116867.41 | V21: =U21/$F21 -> 0.016761184 | W21: 225134.61 | X21: =W21/$F21 -> 0.032288921 | Y21: 271871.53 | Z21: =Y21/$F21 -> 0.038991954 | AA21: 708520.84 | AB21: =AA21/$F21 -> 0.10161642 | AC21: =Y21+AA21 -> 980392.37 | AD21: =AC21/$F21 -> 0.14060838 | AE21: 1697613.4 | AF21: =AE21/F21 -> 0.24347258 | AG21: 0 | AH21: =AG21/$F21 -> 0 | AI21: 700169.98 | AJ21: =AI21/$F21 -> 0.10041874 | AK21: 76475.4 | AL21: =AK21/$F21 -> 0.010968141
D22: 46127 | E22: 三 | F22: =SUM(M22,S22,U22,W22,AC22,AE22,AG22,AI22,AK22) -> 6457162.2 | I22: 1139592.1 | J22: =I22/$F22 -> 0.17648497 | K22: 1416940.8 | L22: =K22/$F22 -> 0.21943708 | M22: =I22+K22 -> 2556532.9 | N22: =M22/F22 -> 0.39592205 | O22: 371236.07 | P22: =O22/$F22 -> 0.05749214 | Q22: 0 | R22: =Q22/$F22 -> 0 | S22: =O22+Q22 -> 371236.07 | T22: =S22/F22 -> 0.05749214 | U22: 106528.63 | V22: =U22/F22 -> 0.016497747 | W22: 220203.09 | X22: =W22/$F22 -> 0.034102146 | Y22: 225603.98 | Z22: =Y22/$F22 -> 0.034938565 | AA22: 629756.9 | AB22: =AA22/$F22 -> 0.097528432 | AC22: =Y22+AA22 -> 855360.88 | AD22: =AC22/$F22 -> 0.132467 | AE22: 1629884 | AF22: =AE22/F22 -> 0.25241491 | AG22: 0 | AH22: =AG22/$F22 -> 0 | AI22: 644487.2 | AJ22: =AI22/$F22 -> 0.099809666 | AK22: 72929.4 | AL22: =AK22/$F22 -> 0.011294342
D23: 46128 | E23: 四 | F23: =SUM(M23,S23,U23,W23,AC23,AE23,AG23,AI23,AK23) -> 5781414.6 | I23: 1038888.5 | J23: =I23/$F23 -> 0.17969452 | K23: 1249824.1 | L23: =K23/$F23 -> 0.21617963 | M23: =I23+K23 -> 2288712.6 | N23: =M23/$F23 -> 0.39587415 | O23: 372327.2 | P23: =O23/$F23 -> 0.064400709 | Q23: 0 | R23: =Q23/$F23 -> 0 | S23: =O23+Q23 -> 372327.2 | T23: =S23/$F23 -> 0.064400709 | U23: 104326.46 | V23: =U23/$F23 -> 0.018045144 | W23: 221197.83 | X23: =W23/$F23 -> 0.038260157 | Y23: 164178.84 | Z23: =Y23/$F23 -> 0.028397694 | AA23: 517650.11 | AB23: =AA23/$F23 -> 0.089536929 | AC23: =Y23+AA23 -> 681828.95 | AD23: =AC23/$F23 -> 0.11793462 | AE23: 1462842 | AF23: =AE23/F23 -> 0.25302492 | AG23: 0 | AH23: =AG23/$F23 -> 0 | AI23: 580323.4 | AJ23: =AI23/$F23 -> 0.10037741 | AK23: 69856.2 | AL23: =AK23/$F23 -> 0.012082891
D24: 46129 | E24: 五 | F24: =SUM(M24,S24,U24,W24,AC24,AE24,AG24,AI24,AK24) -> 5012455.3 | I24: 921116.98 | J24: =I24/$F24 -> 0.18376562 | K24: 1146056 | L24: =K24/$F24 -> 0.22864163 | M24: =I24+K24 -> 2067172.9 | N24: =M24/F24 -> 0.41240725 | O24: 271252.9 | P24: =O24/$F24 -> 0.054115774 | Q24: 0 | R24: =Q24/$F24 -> 0 | S24: =O24+Q24 -> 271252.9 | T24: =S24/F24 -> 0.054115774 | U24: 88997.86 | V24: =U24/F24 -> 0.017755342 | W24: 143139.74 | X24: =W24/$F24 -> 0.028556811 | Y24: 181266.61 | Z24: =Y24/$F24 -> 0.036163237 | AA24: 547464.2 | AB24: =AA24/$F24 -> 0.10922076 | AC24: =Y24+AA24 -> 728730.81 | AD24: =AC24/$F24 -> 0.145384 | AE24: 1185234.5 | AF24: =AE24/F24 -> 0.23645788 | AG24: 0 | AH24: =AG24/$F24 -> 0 | AI24: 463330.24 | AJ24: =AI24/$F24 -> 0.092435784 | AK24: 64596.3 | AL24: =AK24/$F24 -> 0.012887157
D25: 46130 | E25: 六 | F25: =SUM(M25,S25,U25,W25,AC25,AE25,AG25,AI25,AK25) -> 5245500.3 | I25: 888743.04 | J25: =I25/$F25 -> 0.1694296 | K25: 1270153.7 | L25: =K25/$F25 -> 0.24214157 | M25: =I25+K25 -> 2158896.8 | N25: =M25/$F25 -> 0.41157118 | O25: 260175.2 | P25: =O25/$F25 -> 0.049599692 | Q25: 0 | R25: =Q25/$F25 -> 0 | S25: =O25+Q25 -> 260175.2 | T25: =S25/$F25 -> 0.049599692 | U25: 94890.53 | V25: =U25/$F25 -> 0.018089891 | W25: 148344.82 | X25: =W25/$F25 -> 0.028280395 | Y25: 209424.53 | Z25: =Y25/$F25 -> 0.039924605 | AA25: 568078.98 | AB25: =AA25/$F25 -> 0.10829834 | AC25: =Y25+AA25 -> 777503.51 | AD25: =AC25/$F25 -> 0.14822295 | AE25: 1279111.7 | AF25: =AE25/F25 -> 0.24384932 | AG25: 0 | AH25: =AG25/$F25 -> 0 | AI25: 465527.54 | AJ25: =AI25/$F25 -> 0.088747976 | AK25: 61050.3 | AL25: =AK25/$F25 -> 0.011638604
D26: 46131 | E26: 日 | F26: =SUM(M26,S26,U26,W26,AC26,AE26,AG26,AI26,AK26) -> 6890291.9 | I26: 1212193.8 | J26: =I26/$F26 -> 0.17592778 | K26: 1407729 | L26: =K26/$F26 -> 0.20430615 | M26: =I26+K26 -> 2619922.8 | N26: =M26/F26 -> 0.38023394 | O26: 348770.65 | P26: =O26/$F26 -> 0.050617689 | Q26: 0 | R26: =Q26/$F26 -> 0 | S26: =O26+Q26 -> 348770.65 | T26: =S26/F26 -> 0.050617689 | U26: 114802.47 | V26: =U26/F26 -> 0.016661481 | W26: 178802.81 | X26: =W26/$F26 -> 0.025949962 | Y26: 241726.66 | Z26: =Y26/$F26 -> 0.035082209 | AA26: 669644.16 | AB26: =AA26/$F26 -> 0.097186618 | AC26: =Y26+AA26 -> 911370.82 | AD26: =AC26/$F26 -> 0.13226883 | AE26: 1978242.8 | AF26: =AE26/F26 -> 0.2871058 | AG26: 0 | AH26: =AG26/$F26 -> 0 | AI26: 669468.94 | AJ26: =AI26/$F26 -> 0.097161188 | AK26: 68910.6 | AL26: =AK26/$F26 -> 0.010001115
D27: 46132 | E27: 一 | F27: =SUM(M27,S27,U27,W27,AC27,AE27,AG27,AI27,AK27) -> 6483243.3 | I27: 1132051.6 | J27: =I27/$F27 -> 0.17461193 | K27: 1366929.5 | L27: =K27/$F27 -> 0.21084039 | M27: =I27+K27 -> 2498981.1 | N27: =M27/$F27 -> 0.38545232 | O27: 329958.05 | P27: =O27/$F27 -> 0.050893979 | Q27: 0 | R27: =Q27/$F27 -> 0 | S27: =O27+Q27 -> 329958.05 | T27: =S27/$F27 -> 0.050893979 | U27: 110429.19 | V27: =U27/$F27 -> 0.017033017 | W27: 134382.16 | X27: =W27/$F27 -> 0.020727613 | Y27: 242351.13 | Z27: =Y27/$F27 -> 0.037381156 | AA27: 842782.64 | AB27: =AA27/$F27 -> 0.12999399 | AC27: =Y27+AA27 -> 1085133.8 | AD27: =AC27/$F27 -> 0.16737514 | AE27: 1735202.8 | AF27: =AE27/F27 -> 0.26764426 | AG27: 0 | AH27: =AG27/$F27 -> 0 | AI27: 520895.62 | AJ27: =AI27/$F27 -> 0.080344914 | AK27: 68260.5 | AL27: =AK27/$F27 -> 0.010528758
B28: =D29+7 -> 46141 | D28: 46133 | E28: 二 | F28: =SUM(M28,S28,U28,W28,AC28,AE28,AG28,AI28,AK28) -> 0 | G28: =SUM(F28:F34) -> 0
D29: 46134 | E29: 三 | F29: =SUM(M29,S29,U29,W29,AC29,AE29,AG29,AI29,AK29) -> 0
D30: 46135 | E30: 四 | F30: =SUM(M30,S30,U30,W30,AC30,AE30,AG30,AI30,AK30) -> 0
D31: 46136 | E31: 五 | F31: =SUM(M31,S31,U31,W31,AC31,AE31,AG31,AI31,AK31) -> 0
D32: 46137 | E32: 六 | F32: =SUM(M32,S32,U32,W32,AC32,AE32,AG32,AI32,AK32) -> 0
D33: 46138 | E33: 日 | F33: =SUM(M33,S33,U33,W33,AC33,AE33,AG33,AI33,AK33) -> 0
D34: 46139 | E34: 一 | F34: =SUM(M34,S34,U34,W34,AC34,AE34,AG34,AI34,AK34) -> 0
B35: =D36+7 -> 46148 | D35: 46140 | E35: 二 | F35: =SUM(M35,S35,U35,W35,AC35,AE35,AG35,AI35,AK35) -> 0 | G35: =SUM(F35:F41) -> 0
D36: 46141 | E36: 三 | F36: =SUM(M36,S36,U36,W36,AC36,AE36,AG36,AI36,AK36) -> 0
D37: 46142 | E37: 四 | F37: =SUM(M37,S37,U37,W37,AC37,AE37,AG37,AI37,AK37) -> 0
D38: 46143 | E38: 五 | F38: =SUM(M38,S38,U38,W38,AC38,AE38,AG38,AI38,AK38) -> 0
D39: 46144 | E39: 六 | F39: =SUM(M39,S39,U39,W39,AC39,AE39,AG39,AI39,AK39) -> 0
D40: 46145 | E40: 日 | F40: =SUM(M40,S40,U40,W40,AC40,AE40,AG40,AI40,AK40) -> 0
D41: 46146 | E41: 一 | F41: =SUM(M41,S41,U41,W41,AC41,AE41,AG41,AI41,AK41) -> 0

Sheet （４）訂單數量構成比
B2: （4）訂單數量構成比
B3: 資料繳交日 | C3: 月份 | D3: 日期 | F3: 訂單量 | I3: 品類訂單量
I4: 18℃-飯糰 | O4: 18℃-壽司手卷 | U4: 4℃-飯糰 | W4: 4℃-壽司手卷 | Y4: 主食 | AE4: 便當 | AG4: 熱食義麵 | AI4: 季節調理麵 | AK4: 微波小吃
F5: 日 | G5: 週累積 | H5: 月累積 | I5: 一配 | K5: 二配 | M5: 合計 | O5: 一配 | Q5: 二配 | S5: 合計 | U5: 一配 | W5: 一配 | Y5: 一配 | AA5: 二配 | AC5: 合計 | AE5: 一配 | AG5: 一配 | AI5: 一配 | AK5: 一配
I6: 訂單數 | J6: 比例(%) | K6: 訂單數 | L6: 比例(%) | M6: 訂單數 | N6: 比例(%) | O6: 訂單數 | P6: 比例(%) | Q6: 訂單數 | R6: 比例(%) | S6: 訂單數 | T6: 比例(%) | U6: 訂單數 | V6: 比例(%) | W6: 訂單數 | X6: 比例(%) | Y6: 訂單數 | Z6: 比例(%) | AA6: 訂單數 | AB6: 比例(%) | AC6: 訂單數 | AD6: 比例(%) | AE6: 訂單數 | AF6: 比例(%) | AG6: 訂單數 | AH6: 比例(%) | AI6: 訂單數 | AJ6: 比例(%) | AK6: 訂單數 | AL6: 比例(%)
B7: 46120 | D7: 46112 | E7: 二 | F7: =SUM(M7,S7,U7,W7,AC7,AE7,AG7,AI7,AK7) -> 179182 | G7: =SUM(F7:F13) -> 995977 | I7: 39563 | J7: =I7/$F7 -> 0.22079785 | K7: 61872 | L7: =K7/$F7 -> 0.34530254 | M7: =I7+K7 -> 101435 | N7: =M7/$F7 -> 0.56610039 | O7: 11990 | P7: =O7/$F7 -> 0.066915204 | Q7: 5532 | R7: =Q7/$F7 -> 0.030873637 | S7: =O7+Q7 -> 17522 | T7: =S7/$F7 -> 0.09778884 | U7: 4406 | V7: =U7/$F7 -> 0.024589524 | W7: 2100 | X7: =W7/$F7 -> 0.011719927 | Y7: 3703 | Z7: =Y7/$F7 -> 0.020666138 | AA7: 13360 | AB7: =AA7/$F7 -> 0.074561061 | AC7: =Y7+AA7 -> 17063 | AD7: =AC7/$F7 -> 0.095227199 | AE7: 33080 | AF7: =AE7/$F7 -> 0.18461676 | AG7: 0 | AH7: =AG7/$F7 -> 0 | AI7: 0 | AJ7: =AI7/$F7 -> 0 | AK7: 3576 | AL7: =AK7/$F7 -> 0.019957362
C8: 四 | D8: 46113 | E8: 三 | F8: =SUM(M8,S8,U8,W8,AC8,AE8,AG8,AI8,AK8) -> 156110 | H8: =SUM(F8:F37) -> 3434128 | I8: 37671 | J8: =I8/$F8 -> 0.24131061 | K8: 53228 | L8: =K8/$F8 -> 0.3409647 | M8: =I8+K8 -> 90899 | N8: =M8/$F8 -> 0.58227532 | O8: 11422 | P8: =O8/$F8 -> 0.073166357 | Q8: 5248 | R8: =Q8/$F8 -> 0.033617321 | S8: =O8+Q8 -> 16670 | T8: =S8/$F8 -> 0.10678368 | U8: 3921 | V8: =U8/$F8 -> 0.025116905 | W8: 2035 | X8: =W8/$F8 -> 0.01303568 | Y8: 3191 | Z8: =Y8/$F8 -> 0.020440715 | AA8: 9792 | AB8: =AA8/$F8 -> 0.062725002 | AC8: =Y8+AA8 -> 12983 | AD8: =AC8/$F8 -> 0.083165716 | AE8: 25933 | AF8: =AE8/$F8 -> 0.16612004 | AG8: 0 | AH8: =AG8/$F8 -> 0 | AI8: 0 | AJ8: =AI8/$F8 -> 0 | AK8: 3669 | AL8: =AK8/$F8 -> 0.023502658
D9: 46114 | E9: 四 | F9: =SUM(M9,S9,U9,W9,AC9,AE9,AG9,AI9,AK9) -> 125387 | I9: 27133 | J9: =I9/$F9 -> 0.21639404 | K9: 46135 | L9: =K9/$F9 -> 0.36794086 | M9: =I9+K9 -> 73268 | N9: =M9/$F9 -> 0.5843349 | O9: 7731 | P9: =O9/$F9 -> 0.06165711 | Q9: 4501 | R9: =Q9/$F9 -> 0.035896863 | S9: =O9+Q9 -> 12232 | T9: =S9/$F9 -> 0.097553973 | U9: 3648 | V9: =U9/$F9 -> 0.029093925 | W9: 2130 | X9: =W9/$F9 -> 0.016987407 | Y9: 2859 | Z9: =Y9/$F9 -> 0.022801407 | AA9: 8660 | AB9: =AA9/$F9 -> 0.069066171 | AC9: =Y9+AA9 -> 11519 | AD9: =AC9/$F9 -> 0.091867578 | AE9: 19281 | AF9: =AE9/$F9 -> 0.15377192 | AG9: 0 | AH9: =AG9/$F9 -> 0 | AI9: 0 | AJ9: =AI9/$F9 -> 0 | AK9: 3309 | AL9: =AK9/$F9 -> 0.026390296
D10: 46115 | E10: 五 | F10: =SUM(M10,S10,U10,W10,AC10,AE10,AG10,AI10,AK10) -> 119195 | I10: 25747 | J10: =I10/$F10 -> 0.21600738 | K10: 43064 | L10: =K10/$F10 -> 0.36129032 | M10: =I10+K10 -> 68811 | N10: =M10/$F10 -> 0.57729771 | O10: 7237 | P10: =O10/$F10 -> 0.060715634 | Q10: 4414 | R10: =Q10/$F10 -> 0.037031755 | S10: =O10+Q10 -> 11651 | T10: =S10/$F10 -> 0.097747389 | U10: 3295 | V10: =U10/$F10 -> 0.027643777 | W10: 1950 | X10: =W10/$F10 -> 0.016359747 | Y10: 2911 | Z10: =Y10/$F10 -> 0.024422165 | AA10: 10214 | AB10: =AA10/$F10 -> 0.085691514 | AC10: =Y10+AA10 -> 13125 | AD10: =AC10/$F10 -> 0.11011368 | AE10: 16976 | AF10: =AE10/$F10 -> 0.14242208 | AG10: 0 | AH10: =AG10/$F10 -> 0 | AI10: 0 | AJ10: =AI10/$F10 -> 0 | AK10: 3387 | AL10: =AK10/$F10 -> 0.028415621
D11: 46116 | E11: 六 | F11: =SUM(M11,S11,U11,W11,AC11,AE11,AG11,AI11,AK11) -> 114970 | I11: 24260 | J11: =I11/$F11 -> 0.21101157 | K11: 41153 | L11: =K11/$F11 -> 0.35794555 | M11: =I11+K11 -> 65413 | N11: =M11/$F11 -> 0.56895712 | O11: 6856 | P11: =O11/$F11 -> 0.059632948 | Q11: 4201 | R11: =Q11/$F11 -> 0.036539967 | S11: =O11+Q11 -> 11057 | T11: =S11/$F11 -> 0.096172915 | U11: 3268 | V11: =U11/$F11 -> 0.028424806 | W11: 2046 | X11: =W11/$F11 -> 0.017795947 | Y11: 3158 | Z11: =Y11/$F11 -> 0.027468035 | AA11: 9944 | AB11: =AA11/$F11 -> 0.086492128 | AC11: =Y11+AA11 -> 13102 | AD11: =AC11/$F11 -> 0.11396016 | AE11: 17210 | AF11: =AE11/$F11 -> 0.14969122 | AG11: 0 | AH11: =AG11/$F11 -> 0 | AI11: 0 | AJ11: =AI11/$F11 -> 0 | AK11: 2874 | AL11: =AK11/$F11 -> 0.024997826
D12: 46117 | E12: 日 | F12: =SUM(M12,S12,U12,W12,AC12,AE12,AG12,AI12,AK12) -> 129122 | I12: 25018 | J12: =I12/$F12 -> 0.19375474 | K12: 50126 | L12: =K12/$F12 -> 0.3882065 | M12: =I12+K12 -> 75144 | N12: =M12/$F12 -> 0.58196125 | O12: 7276 | P12: =O12/$F12 -> 0.056349809 | Q12: 4599 | R12: =Q12/$F12 -> 0.035617478 | S12: =O12+Q12 -> 11875 | T12: =S12/$F12 -> 0.091967287 | U12: 3281 | V12: =U12/$F12 -> 0.025410077 | W12: 1678 | X12: =W12/$F12 -> 0.012995462 | Y12: 3244 | Z12: =Y12/$F12 -> 0.025123527 | AA12: 12878 | AB12: =AA12/$F12 -> 0.099735134 | AC12: =Y12+AA12 -> 16122 | AD12: =AC12/$F12 -> 0.12485866 | AE12: 18574 | AF12: =AE12/$F12 -> 0.14384845 | AG12: 0 | AH12: =AG12/$F12 -> 0 | AI12: 0 | AJ12: =AI12/$F12 -> 0 | AK12: 2448 | AL12: =AK12/$F12 -> 0.018958814
D13: 46118 | E13: 一 | F13: =SUM(M13,S13,U13,W13,AC13,AE13,AG13,AI13,AK13) -> 172011 | I13: 38598 | J13: =I13/$F13 -> 0.22439263 | K13: 63604 | L13: =K13/$F13 -> 0.36976705 | M13: =I13+K13 -> 102202 | N13: =M13/$F13 -> 0.59415968 | O13: 10406 | P13: =O13/$F13 -> 0.060496131 | Q13: 1439 | R13: =Q13/$F13 -> 0.0083657441 | S13: =O13+Q13 -> 11845 | T13: =S13/$F13 -> 0.068861875 | U13: 4158 | V13: =U13/$F13 -> 0.024172873 | W13: 2066 | X13: =W13/$F13 -> 0.01201086 | Y13: 4119 | Z13: =Y13/$F13 -> 0.023946143 | AA13: 14276 | AB13: =AA13/$F13 -> 0.082994692 | AC13: =Y13+AA13 -> 18395 | AD13: =AC13/$F13 -> 0.10694084 | AE13: 29946 | AF13: =AE13/$F13 -> 0.17409352 | AG13: 0 | AH13: =AG13/$F13 -> 0 | AI13: 0 | AJ13: =AI13/$F13 -> 0 | AK13: 3399 | AL13: =AK13/$F13 -> 0.019760364
B14: =B7+7 -> 46127 | D14: 46119 | E14: 二 | F14: =SUM(M14,S14,U14,W14,AC14,AE14,AG14,AI14,AK14) -> 179797 | G14: =SUM(F14:F20) -> 1171613 | I14: 38175 | J14: =I14/$F14 -> 0.21232279 | K14: 61850 | L14: =K14/$F14 -> 0.34399907 | M14: =I14+K14 -> 100025 | N14: =M14/$F14 -> 0.55632185 | O14: 15937 | P14: =O14/$F14 -> 0.088638854 | Q14: 1427 | R14: =Q14/$F14 -> 0.0079367286 | S14: =O14+Q14 -> 17364 | T14: =S14/$F14 -> 0.096575582 | U14: 3887 | V14: =U14/$F14 -> 0.021618826 | W14: 10076 | X14: =W14/$F14 -> 0.05604098 | Y14: 3893 | Z14: =Y14/$F14 -> 0.021652197 | AA14: 13527 | AB14: =AA14/$F14 -> 0.075234848 | AC14: =Y14+AA14 -> 17420 | AD14: =AC14/$F14 -> 0.096887045 | AE14: 27659 | AF14: =AE14/$F14 -> 0.1538346 | AG14: 0 | AH14: =AG14/$F14 -> 0 | AI14: 0 | AJ14: =AI14/$F14 -> 0 | AK14: 3366 | AL14: =AK14/$F14 -> 0.018721113
D15: 46120 | E15: 三 | F15: =SUM(M15,S15,U15,W15,AC15,AE15,AG15,AI15,AK15) -> 166150 | I15: 37405 | J15: =I15/$F15 -> 0.2251279 | K15: 59075 | L15: =K15/$F15 -> 0.35555221 | M15: =I15+K15 -> 96480 | N15: =M15/$F15 -> 0.58068011 | O15: 11557 | P15: =O15/$F15 -> 0.069557629 | Q15: 1499 | R15: =Q15/$F15 -> 0.0090219681 | S15: =O15+Q15 -> 13056 | T15: =S15/$F15 -> 0.078579597 | U15: 3727 | V15: =U15/$F15 -> 0.022431538 | W15: 6442 | X15: =W15/$F15 -> 0.038772194 | Y15: 4326 | Z15: =Y15/$F15 -> 0.026036714 | AA15: 12822 | AB15: =AA15/$F15 -> 0.077171231 | AC15: =Y15+AA15 -> 17148 | AD15: =AC15/$F15 -> 0.10320794 | AE15: 25679 | AF15: =AE15/$F15 -> 0.15455311 | AG15: 0 | AH15: =AG15/$F15 -> 0 | AI15: 0 | AJ15: =AI15/$F15 -> 0 | AK15: 3618 | AL15: =AK15/$F15 -> 0.021775504
D16: 46121 | E16: 四 | F16: =SUM(M16,S16,U16,W16,AC16,AE16,AG16,AI16,AK16) -> 155377 | I16: 37021 | J16: =I16/$F16 -> 0.23826564 | K16: 53369 | L16: =K16/$F16 -> 0.3434807 | M16: =I16+K16 -> 90390 | N16: =M16/$F16 -> 0.58174633 | O16: 11585 | P16: =O16/$F16 -> 0.074560585 | Q16: 1526 | R16: =Q16/$F16 -> 0.0098212734 | S16: =O16+Q16 -> 13111 | T16: =S16/$F16 -> 0.084381858 | U16: 3661 | V16: =U16/$F16 -> 0.023562046 | W16: 6152 | X16: =W16/$F16 -> 0.03959402 | Y16: 3675 | Z16: =Y16/$F16 -> 0.023652149 | AA16: 10970 | AB16: =AA16/$F16 -> 0.07060247 | AC16: =Y16+AA16 -> 14645 | AD16: =AC16/$F16 -> 0.094254619 | AE16: 23782 | AF16: =AE16/$F16 -> 0.15305998 | AG16: 0 | AH16: =AG16/$F16 -> 0 | AI16: 0 | AJ16: =AI16/$F16 -> 0 | AK16: 3636 | AL16: =AK16/$F16 -> 0.023401147
D17: 46122 | E17: 五 | F17: =SUM(M17,S17,U17,W17,AC17,AE17,AG17,AI17,AK17) -> 137940 | I17: 28594 | J17: =I17/$F17 -> 0.20729303 | K17: 50493 | L17: =K17/$F17 -> 0.36605046 | M17: =I17+K17 -> 79087 | N17: =M17/$F17 -> 0.57334348 | O17: 13148 | P17: =O17/$F17 -> 0.095316804 | Q17: 1207 | R17: =Q17/$F17 -> 0.0087501812 | S17: =O17+Q17 -> 14355 | T17: =S17/$F17 -> 0.10406699 | U17: 3144 | V17: =U17/$F17 -> 0.022792518 | W17: 3411 | X17: =W17/$F17 -> 0.024728143 | Y17: 3280 | Z17: =Y17/$F17 -> 0.023778454 | AA17: 11226 | AB17: =AA17/$F17 -> 0.08138321 | AC17: =Y17+AA17 -> 14506 | AD17: =AC17/$F17 -> 0.10516166 | AE17: 19918 | AF17: =AE17/$F17 -> 0.14439611 | AG17: 0 | AH17: =AG17/$F17 -> 0 | AI17: 0 | AJ17: =AI17/$F17 -> 0 | AK17: 3519 | AL17: =AK17/$F17 -> 0.025511092
D18: 46123 | E18: 六 | F18: =SUM(M18,S18,U18,W18,AC18,AE18,AG18,AI18,AK18) -> 148324 | I18: 27633 | J18: =I18/$F18 -> 0.18630161 | K18: 57067 | L18: =K18/$F18 -> 0.38474556 | M18: =I18+K18 -> 84700 | N18: =M18/$F18 -> 0.57104717 | O18: 12199 | P18: =O18/$F18 -> 0.082245624 | Q18: 1216 | R18: =Q18/$F18 -> 0.0081982687 | S18: =O18+Q18 -> 13415 | T18: =S18/$F18 -> 0.090443893 | U18: 3540 | V18: =U18/$F18 -> 0.02386667 | W18: 5532 | X18: =W18/$F18 -> 0.037296729 | Y18: 3555 | Z18: =Y18/$F18 -> 0.0239678 | AA18: 12588 | AB18: =AA18/$F18 -> 0.084868261 | AC18: =Y18+AA18 -> 16143 | AD18: =AC18/$F18 -> 0.10883606 | AE18: 21598 | AF18: =AE18/$F18 -> 0.14561366 | AG18: 0 | AH18: =AG18/$F18 -> 0 | AI18: 0 | AJ18: =AI18/$F18 -> 0 | AK18: 3396 | AL18: =AK18/$F18 -> 0.022895823
D19: 46124 | E19: 日 | F19: =SUM(M19,S19,U19,W19,AC19,AE19,AG19,AI19,AK19) -> 191499 | I19: 41219 | J19: =I19/$F19 -> 0.21524394 | K19: 64586 | L19: =K19/$F19 -> 0.33726547 | M19: =I19+K19 -> 105805 | N19: =M19/$F19 -> 0.55250941 | O19: 17972 | P19: =O19/$F19 -> 0.093849054 | Q19: 1534 | R19: =Q19/$F19 -> 0.0080104857 | S19: =O19+Q19 -> 19506 | T19: =S19/$F19 -> 0.10185954 | U19: 4388 | V19: =U19/$F19 -> 0.022913958 | W19: 6826 | X19: =W19/$F19 -> 0.035645095 | Y19: 4903 | Z19: =Y19/$F19 -> 0.025603267 | AA19: 14479 | AB19: =AA19/$F19 -> 0.07560875 | AC19: =Y19+AA19 -> 19382 | AD19: =AC19/$F19 -> 0.10121202 | AE19: 32034 | AF19: =AE19/$F19 -> 0.16728025 | AG19: 0 | AH19: =AG19/$F19 -> 0 | AI19: 0 | AJ19: =AI19/$F19 -> 0 | AK19: 3558 | AL19: =AK19/$F19 -> 0.018579731
