Workbook

Sheet 數值累積總表(月)
B1: 項目 | D1: 1月 | E1: 2月 | F1: 3月 | G1: 4月 | H1: 5月 | I1: 6月 | J1: 7月 | K1: 8月 | L1: 9月 | M1: 10月 | N1: 11月 | O1: 12月 | P1: 合計/平均
B2: （１）收支狀況 | C2: 業績金額(千元) | D2: 146299.94 | E2: 116569.43 | F2: 148838 | G2: 160648.31 | H2: 181836.63 | I2: 194099.29 | P2: =SUM(D2:O2) -> 948291.59
C3: 訂單數量 | D3: 4768701 | E3: 3787002 | F3: 5045753 | G3: 5396292 | H3: 6084520 | I3: 6275618 | P3: =SUM(D3:O3) -> 31357886
C4: 材料費(千元) | D4: 93253 | E4: 74777 | F4: 93614 | G4: 104435 | H4: 116562 | I4: 126964 | P4: =SUM(D4:O4) -> 609605
C5: 材料費率(%) | D5: 0.655 | E5: 0.653 | F5: 0.648 | G5: 0.663 | H5: 0.672 | I5: 0.675 | J5: =IFERROR(J4/J2, "") | K5: =IFERROR(K4/K2, "") | L5: =IFERROR(L4/L2, "") | M5: =IFERROR(M4/M2, "") | N5: =IFERROR(N4/N2, "") | O5: =IFERROR(O4/O2, "") | P5: =AVERAGEIF(D5:O5, ">0") -> 0.661
C6: 勞務成本(千元) | D6: 22378 | E6: 22860 | F6: 22710 | G6: 23226 | H6: 24474 | I6: 26795 | P6: =SUM(D6:O6) -> 142443
C7: 勞務費率(%) | D7: 0.157 | E7: 0.2 | F7: 0.157 | G7: 0.147 | H7: 0.141 | I7: 0.142 | J7: =IFERROR(J6/J2, "") | K7: =IFERROR(K6/K2, "") | L7: =IFERROR(L6/L2, "") | M7: =IFERROR(M6/M2, "") | N7: =IFERROR(N6/N2, "") | O7: =IFERROR(O6/O2, "") | P7: =AVERAGEIF(D7:O7, ">0") -> 0.15733333
B9: （２）ＫＰＩ達成進度 | C9: 人時性KPI | D9: 497.6 | E9: 497.6 | F9: 497.6 | G9: 497.6 | H9: 497.6 | I9: 497.6 | P9: =AVERAGEIF(D9:O9, ">0") -> 497.6
C10: 人時性(個/月均) | D10: 458.38414 | E10: 476.04172 | F10: 409.81563 | G10: 402.86432 | H10: 419.38046 | I10: 425.95259 | P10: =AVERAGEIF(D10:O10, ">0") -> 432.07314
C11: 人時達成率(%/月均) | D11: =IFERROR(D10/D9, "") -> 0.92118999 | E11: =IFERROR(E10/E9, "") -> 0.95667547 | F11: =IFERROR(F10/F9, "") -> 0.82358447 | G11: =IFERROR(G10/G9, "") -> 0.80961479 | H11: 0.94796667 | I11: 0.96282231 | J11: =IFERROR(J10/J9, "") | K11: =IFERROR(K10/K9, "") | L11: =IFERROR(L10/L9, "") | M11: =IFERROR(M10/M9, "") | N11: =IFERROR(N10/N9, "") | O11: =IFERROR(O10/O9, "") | P11: =AVERAGEIF(D11:O11, ">0") -> 0.90364229
C12: 半成品-報廢(%) | D12: 0.0024135432 | E12: 0.0023657636 | F12: 0.0020222248 | G12: 0.0020113648 | H12: 0.002008824 | I12: 0.0020072506 | P12: =AVERAGEIF(D12:O12, ">0") -> 0.0021381618
C13: 半成品-超用(%) | D13: 0.0055994433 | E13: 0.0052393001 | F13: 0.0048799138 | G13: 0.0043085188 | H13: 0.0061874817 | I13: 0.0060775211 | P13: =AVERAGEIF(D13:O13, ">0") -> 0.0053820298
C14: 固定產線-導入率(%) | D14: 0.9 | E14: 0.9 | F14: 0.9 | G14: 0.9 | H14: 0.9 | I14: 0.9 | P14: =AVERAGEIF(D14:O14, ">0") -> 0.9
C15: 教育訓練-實施率(%) | D15: 0.057692308 | E15: 0.13873626 | F15: 0.21960298 | G15: 0.30384615 | H15: 0.38709677 | I15: 0.47115385 | P15: =MAX(D15:O15) -> 0.47115385
B17: （３）業績構成比 | C17: 18℃-飯糰(061,063) | D17: 0.36139567 | E17: 0.34737657 | F17: 0.36414345 | G17: 0.38079956 | H17: 0.3631831 | I17: 0.29977347 | P17: =AVERAGEIF(D17:O17, ">0") -> 0.35277864
C18: 18℃-壽司手卷(071,072,075,076) | D18: 0.069633574 | E18: 0.077793665 | F18: 0.084480826 | G18: 0.060267904 | H18: 0.041707027 | I18: 0.035290065 | P18: =AVERAGEIF(D18:O18, ">0") -> 0.061528844
C19: 4℃-飯糰(065) | D19: 0.022453222 | E19: 0.02167645 | F19: 0.02436516 | G19: 0.018891118 | H19: 0.013969 | I19: 0.010903809 | P19: =AVERAGEIF(D19:O19, ">0") -> 0.018709793
C20: 4℃-壽司手卷(077) | D20: 0.008585039 | E20: 0.0099523222 | F20: 0.014684918 | G20: 0.028316296 | H20: 0.034128078 | I20: 0.049548361 | P20: =AVERAGEIF(D20:O20, ">0") -> 0.024202502
C21: 主食(091,092,093,094,095) | D21: 0.16215294 | E21: 0.18214708 | F21: 0.20289324 | G21: 0.15628268 | H21: 0.13415544 | I21: 0.1343246 | P21: =AVERAGEIF(D21:O21, ">0") -> 0.16199266
C22: 便當(083) | D22: 0.27057088 | E22: 0.27529226 | F22: 0.29293399 | G22: 0.27842234 | H22: 0.26474822 | I22: 0.22905816 | P22: =AVERAGEIF(D22:O22, ">0") -> 0.26850431
C23: 熱食義麵(122,123,124,126) | D23: 0.029234371 | E23: 0.0089796819 | F23: 0 | G23: 0 | H23: 0 | I23: 0 | P23: =AVERAGEIF(D23:O23, ">0") -> 0.019107026
C24: 季節調理麵(111,112) | D24: 0.040564166 | E24: 0.040109499 | F24: 0.0016541185 | G24: 0.064343547 | H24: 0.13502459 | I24: 0.17184921 | P24: =AVERAGEIF(D24:O24, ">0") -> 0.075590856
C25: 微波小吃(153,154,155) | D25: 0.035410133 | E25: 0.036672477 | F25: 0.01484429 | G25: 0.012676559 | H25: 0.013084541 | I25: 0.069252321 | P25: =AVERAGEIF(D25:O25, ">0") -> 0.030323387
B27: （４）訂單數量構成比 | C27: 18℃-飯糰(061,063) | D27: 0.58577126 | E27: 0.57025346 | F27: 0.57640852 | G27: 0.58366912 | H27: 0.56064801 | I27: 0.49244059 | P27: =AVERAGEIF(D27:O27, ">0") -> 0.56153182
C28: 18℃-壽司手卷(071,072,075,076) | D28: 0.081693946 | E28: 0.091615478 | F28: 0.10179987 | G28: 0.068907687 | H28: 0.044634581 | I28: 0.037850934 | P28: =AVERAGEIF(D28:O28, ">0") -> 0.071083749
C29: 4℃-飯糰(065) | D29: 0.024966128 | E29: 0.023825971 | F29: 0.026809081 | G29: 0.020313393 | H29: 0.014309264 | I29: 0.011252756 | P29: =AVERAGEIF(D29:O29, ">0") -> 0.020246099
C30: 4℃-壽司手卷(077) | D30: 0.0097963785 | E30: 0.011706622 | F30: 0.016401516 | G30: 0.031347822 | H30: 0.048132803 | I30: 0.062276894 | P30: =AVERAGEIF(D30:O30, ">0") -> 0.029943673
C31: 主食(091,092,093,094,095) | D31: 0.089953008 | E31: 0.10114835 | F31: 0.11343936 | G31: 0.089562981 | H31: 0.075610895 | I31: 0.076646794 | P31: =AVERAGEIF(D31:O31, ">0") -> 0.091060231
C32: 便當(083) | D32: 0.13708178 | E32: 0.14060779 | F32: 0.14223546 | G32: 0.13317793 | H32: 0.12743437 | I32: 0.11321897 | P32: =AVERAGEIF(D32:O32, ">0") -> 0.13229272
C33: 熱食義麵(122,123,124,126) | D33: 0.015652481 | E33: 0.0048238686 | F33: 0 | G33: 0 | H33: 0 | I33: 0 | P33: =AVERAGEIF(D33:O33, ">0") -> 0.010238175
C34: 季節調理麵(111,112) | D34: 0.022004735 | E34: 0.020902022 | F34: 0.00067918505 | G34: 0.05386458 | H34: 0.1102248 | I34: 0.14207987 | P34: =AVERAGEIF(D34:O34, ">0") -> 0.058292532
C35: 微波小吃(153,154,155) | D35: 0.033080287 | E35: 0.035116432 | F35: 0.02222701 | G35: 0.019156487 | H35: 0.019005279 | I35: 0.064233196 | P35: =AVERAGEIF(D35:O35, ">0") -> 0.032136449
B37: （５）品群別人時生產性 | C37: 18℃-飯糰(061,063) | D37: 768.96509 | E37: 774.12086 | F37: 757.59042 | G37: 740.76981 | H37: 765.35782 | I37: 783.42711 | P37: =AVERAGEIF(D37:O37, ">0") -> 765.03852
C38: 18℃-壽司手卷(071,072,075,076) | D38: 280.52358 | E38: 304.46478 | F38: 311.70582 | G38: 320.67204 | H38: 308.11597 | I38: 298.23677 | P38: =AVERAGEIF(D38:O38, ">0") -> 303.95316
C39: 4℃-飯糰(065) | D39: 258.56167 | E39: 203.24374 | F39: 331.13667 | G39: 331.07659 | H39: 209.58696 | I39: 118.56652 | P39: =AVERAGEIF(D39:O39, ">0") -> 242.02869
C40: 4℃-壽司手卷(077) | D40: 486.07171 | E40: 490.19814 | F40: 493.97618 | G40: 416.8019 | H40: 367.70757 | I40: 397.08854 | P40: =AVERAGEIF(D40:O40, ">0") -> 441.97401
C41: 主食(091,092,093,094,095) | D41: 82.669482 | E41: 81.452412 | F41: 79.949999 | G41: 82.282454 | H41: 81.903989 | I41: 84.22771 | P41: =AVERAGEIF(D41:O41, ">0") -> 82.081008
C42: 便當(083) | D42: 78.306367 | E42: 77.971323 | F42: 77.906797 | G42: 78.189351 | H42: 79.190462 | I42: 79.718377 | P42: =AVERAGEIF(D42:O42, ">0") -> 78.547113
C43: 熱食義麵(122,123,124,126) | D43: 76.250133 | E43: 72.949976 | F43: 0 | G43: 0 | H43: 0 | I43: 0 | P43: =AVERAGEIF(D43:O43, ">0") -> 74.600054
C44: 季節調理麵(111,112) | D44: 110.8083 | E44: 97.157501 | F44: 84.601424 | G44: 159.74229 | H44: 161.80618 | I44: 157.36335 | P44: =AVERAGEIF(D44:O44, ">0") -> 128.57984
...

Sheet 生產管理報表(月)
A1: 大溪廠生產管理報表
A3: 月別 | B3: 6 | C3: 工廠 | D3: 大溪廠
A4: （１）收支狀況 | E4: ※單位：千元 | G4: （２）ＫＰＩ達成進度
A5: 項目 | B5: 當月 | C5: 前月 | D5: 差異 | E5: 累計 | G5: 項目 | H5: KPI | I5: 當月 | J5: 前月 | K5: 累計 | L5: ※補充
A6: 業績金額 | B6: ='（１）收支狀況'!#REF!/1000 -> #REF! | C6: 181836.63 | D6: =B6-C6 -> #REF! | E6: ='數值累積總表(月)'!P2 -> 948291.59 | G6: 人時性(個/月均) | H6: 497.6 | I6: ='（２）ＫＰＩ達成進度'!#REF! -> #REF! | J6: 419.38046 | K6: ='數值累積總表(月)'!P10 -> 432.07314 | L6: 個／MH
A7: 訂單數量 | B7: ='（１）收支狀況'!#REF! -> #REF! | C7: 6084520 | D7: =B7-C7 -> #REF! | E7: ='數值累積總表(月)'!P3 -> 31357886 | G7: 人時達成率(%/月均) | H7: 0.8 | I7: ='（２）ＫＰＩ達成進度'!#REF! -> #REF! | J7: 0.94796667 | K7: ='數值累積總表(月)'!P11 -> 0.90364229 | L7: 達成率
A8: 材料費 | B8: ='（１）收支狀況'!#REF!/1000 -> #REF! | C8: 122511 | D8: =B8-C8 -> #REF! | E8: ='數值累積總表(月)'!P4 -> 609605 | G8: 半成品-報廢(%) | H8: 0.0025 | I8: ='（２）ＫＰＩ達成進度'!#REF! -> #REF! | J8: 0.002008824 | K8: ='數值累積總表(月)'!P12 -> 0.0021381618 | L8: 報廢率
A9: 材料費率 | B9: ='（１）收支狀況'!#REF! -> #REF! | C9: 0.67374214 | D9: =B9-C9 -> #REF! | E9: ='數值累積總表(月)'!P5 -> 0.661 | G9: 半成品-超用(%) | H9: 0.004 | I9: ='（２）ＫＰＩ達成進度'!#REF! -> #REF! | J9: 0.0061874817 | K9: ='數值累積總表(月)'!P13 -> 0.0053820298 | L9: 超用率
A10: 勞務成本 | B10: ='（１）收支狀況'!#REF!/1000 -> #REF! | C10: 25634.58 | D10: =B10-C10 -> #REF! | E10: ='數值累積總表(月)'!P6 -> 142443 | G10: 固定產線-導入率(%) | H10: 0.8 | I10: ='（２）ＫＰＩ達成進度'!#REF! -> #REF! | J10: 0.9 | K10: ='數值累積總表(月)'!P14 -> 0.9 | L10: 導入率
A11: 勞務費率 | B11: ='（１）收支狀況'!#REF! -> #REF! | C11: 0.14097589 | D11: =B11-C11 -> #REF! | E11: ='數值累積總表(月)'!P7 -> 0.15733333 | G11: 教育訓練-實施率(%) | H11: 1 | I11: ='（２）ＫＰＩ達成進度'!#REF! -> #REF! | J11: 0.38709677 | K11: ='數值累積總表(月)'!P15 -> 0.47115385 | L11: 實施率
A13: （３）業績構成比 | E13: ※單位：千元 | G13: （４）訂單數量構成比 | K13: ※單位：個
B14: 當月 | C14: 比例 | D14: 前月 | E14: 差異 | H14: 當月 | I14: 比例 | J14: 前月 | K14: 差異
A15: 18℃-飯糰(061,063) | B15: =SUM('（３）業績構成比'!M7:M7)/1000 -> 2166.4421 | C15: =IFERROR(B15/$B$6,"") | D15: 0.3631831 | E15: =IFERROR(C15-D15,"") | G15: 18℃-飯糰(061,063) | H15: =SUM('（４）訂單數量構成比'!M7:M7) -> 114912 | I15: =IFERROR(H15/$B$7,"") | J15: 0.56064801 | K15: =IFERROR(I15-J15,"")
A16: 18℃-壽司手卷(071,072,075,076) | B16: =SUM('（３）業績構成比'!S7:S7)/1000 -> 243.64036 | C16: =IFERROR(B16/$B$6,"") | D16: 0.041707027 | E16: =IFERROR(C16-D16,"") | G16: 18℃-壽司手卷(071,072,075,076) | H16: =SUM('（４）訂單數量構成比'!S7:S7) -> 8454 | I16: =IFERROR(H16/$B$7,"") | J16: 0.044634581 | K16: =IFERROR(I16-J16,"")
A17: 4℃-飯糰(065) | B17: =SUM('（３）業績構成比'!U7:U7)/1000 -> 76.93299 | C17: =IFERROR(B17/$B$6,"") | D17: 0.013969 | E17: =IFERROR(C17-D17,"") | G17: 4℃-飯糰(065) | H17: =SUM('（４）訂單數量構成比'!U7:U7) -> 2567 | I17: =IFERROR(H17/$B$7,"") | J17: 0.014309264 | K17: =IFERROR(I17-J17,"")
A18: 4℃-壽司手卷(077) | B18: =SUM('（３）業績構成比'!W7:W7)/1000 -> 269.17606 | C18: =IFERROR(B18/$B$6,"") | D18: 0.034128078 | E18: =IFERROR(C18-D18,"") | G18: 4℃-壽司手卷(077) | H18: =SUM('（４）訂單數量構成比'!W7:W7) -> 11068 | I18: =IFERROR(H18/$B$7,"") | J18: 0.048132803 | K18: =IFERROR(I18-J18,"")
A19: 主食(091,092,093,094,095) | B19: =SUM('（３）業績構成比'!AC7:AC7)/1000 -> 1058.9949 | C19: =IFERROR(B19/$B$6,"") | D19: 0.13415544 | E19: =IFERROR(C19-D19,"") | G19: 主食(091,092,093,094,095) | H19: =SUM('（４）訂單數量構成比'!AC7:AC7) -> 19314 | I19: =IFERROR(H19/$B$7,"") | J19: 0.075610895 | K19: =IFERROR(I19-J19,"")
A20: 便當(083) | B20: =SUM('（３）業績構成比'!AE7:AE7)/1000 -> 1964.1923 | C20: =IFERROR(B20/$B$6,"") | D20: 0.26474822 | E20: =IFERROR(C20-D20,"") | G20: 便當(083) | H20: =SUM('（４）訂單數量構成比'!AE7:AE7) -> 31363 | I20: =IFERROR(H20/$B$7,"") | J20: 0.12743437 | K20: =IFERROR(I20-J20,"")
A21: 熱食義麵(122,123,124,126) | B21: =SUM('（３）業績構成比'!AG7:AG7)/1000 -> 0 | C21: =IFERROR(B21/$B$6,"") | D21: 0 | E21: =IFERROR(C21-D21,"") | G21: 熱食義麵(122,123,124,126) | H21: =SUM('（４）訂單數量構成比'!AG7:AG7) -> 0 | I21: =IFERROR(H21/$B$7,"") | J21: 0 | K21: =IFERROR(I21-J21,"")
A22: 季節調理麵(111,112) | B22: =SUM('（３）業績構成比'!AI7:AI7)/1000 -> 1049.909 | C22: =IFERROR(B22/$B$6,"") | D22: 0.13502459 | E22: =IFERROR(C22-D22,"") | G22: 季節調理麵(111,112) | H22: =SUM('（４）訂單數量構成比'!AI7:AI7) -> 28378 | I22: =IFERROR(H22/$B$7,"") | J22: 0.1102248 | K22: =IFERROR(I22-J22,"")
A23: 微波小吃(153,154,155) | B23: =SUM('（３）業績構成比'!AK7:AK7)/1000 -> 463.46359 | C23: =IFERROR(B23/$B$6,"") | D23: 0.013084541 | E23: =IFERROR(C23-D23,"") | G23: 微波小吃(153,154,155) | H23: =SUM('（４）訂單數量構成比'!AK7:AK7) -> 13924 | I23: =IFERROR(H23/$B$7,"") | J23: 0.019005279 | K23: =IFERROR(I23-J23,"")
C24: =SUM(C15:C23) -> 0 | D24: =SUM(D15:D23) -> 1 | I24: =SUM(I15:I23) -> 0 | J24: =SUM(J15:J23) -> 1
A26: （５）品群別人時生產性
A27: 品群 | B27: 當月 | C27: 前月 | D27: 差異 | E27: 累計
A28: 18℃-飯A15:A23糰(061,063) | B28: ='（５-1）品群別人時生產性(18℃-飯糰)'!C1 -> 768.74032 | C28: 765.35782 | D28: =B28-C28 -> 3.3825014 | E28: ='數值累積總表(月)'!P37 -> 765.03852
A29: 18℃-壽司手卷(071,072,075,076) | B29: ='（５-2）品群別人時生產性(18℃-壽司手卷)'!C1 -> 298.86613 | C29: 308.11597 | D29: =B29-C29 -> -9.2498406 | E29: ='數值累積總表(月)'!P38 -> 303.95316
A30: 4℃-飯糰(065) | B30: ='（５-3）品群別人時生產性(4℃-飯糰)'!C1 -> 116.24957 | C30: 209.58696 | D30: =B30-C30 -> -93.337399 | E30: ='數值累積總表(月)'!P39 -> 242.02869
A31: 4℃-壽司手卷(077) | B31: ='（５-4）品群別人時生產性(4℃-壽司手卷)'!C1 -> 432.41163 | C31: 367.70757 | D31: =B31-C31 -> 64.70406 | E31: ='數值累積總表(月)'!P40 -> 441.97401
A32: 主食(091,092,093,094,095) | B32: ='（５-5）品群別人時生產性(微波主食) '!C1 -> 85.267291 | C32: 81.903989 | D32: =B32-C32 -> 3.3633018 | E32: ='數值累積總表(月)'!P41 -> 82.081008
A33: 便當(083) | B33: ='（５-6）品群別人時生產性(便當)'!C1 -> 79.34755 | C33: 79.190462 | D33: =B33-C33 -> 0.15708879 | E33: ='數值累積總表(月)'!P42 -> 78.547113
A34: 熱食義麵(122,123,124,126) | B34: ='（５-7）品群別人時生產性(熱食義麵) '!C1 -> 0 | C34: 0 | D34: =B34-C34 -> 0 | E34: ='數值累積總表(月)'!P43 -> 74.600054
A35: 季節調理麵(111,112) | B35: ='（５-8）品群別人時生產性(季節調理麵) '!C1 -> 156.88743 | C35: 161.80618 | D35: =B35-C35 -> -4.9187539 | E35: ='數值累積總表(月)'!P44 -> 128.57984
A36: 微波小吃(153,154,155) | B36: ='（５-9）品群別人時生產性(微波小吃)'!C1 -> 117.5096 | C36: 89.419713 | D36: =B36-C36 -> 28.089884 | E36: ='數值累積總表(月)'!P45 -> 87.921481

Sheet 生產管理報表(週) 
A1: 大溪廠生產管理報表
A3: 月別 | B3: 7 | C3: 週別 | D3: W3 | E3: 工廠 | F3: 大溪廠
A4: （１）收支狀況 | E4: ※單位：千元 | G4: （２）ＫＰＩ達成進度
A5: 項目 | B5: 當週 | C5: 前週 | D5: 差異 | E5: 累計 | G5: 項目 | H5: KPI | I5: 當週 | J5: 前週 | K5: 累計 | L5: ※補充
A6: 業績金額 | B6: ='（１）收支狀況'!G19/1000 -> 43787.409 | C6: 48409.402 | D6: =B6-C6 -> -4621.9934 | E6: ='（１）收支狀況'!H6:H6/1000 -> 131301.23 | G6: 人時性(個/月均) | H6: 442.4 | I6: ='（２）ＫＰＩ達成進度'!G19 -> 435.74576 | J6: 427.48888 | K6: ='（２）ＫＰＩ達成進度'!H6 -> 431.30084 | L6: 個／MH
A7: 訂單數量 | B7: ='（１）收支狀況'!J19 -> 1380106 | C7: 1514096 | D7: =B7-C7 -> -133990 | E7: ='（１）收支狀況'!K6:K6 -> 4151257 | G7: 人時達成率(%/月均) | H7: 0.8 | I7: ='（２）ＫＰＩ達成進度'!J19 -> 0.98495878 | J7: 0.96629495 | K7: ='（２）ＫＰＩ達成進度'!K6 -> 0.97491147 | L7: 達成率
A8: 材料費 | B8: ='（１）收支狀況'!M19/1000 -> 29380.856 | C8: 32519.175 | D8: =B8-C8 -> -3138.319 | E8: ='（１）收支狀況'!N6:N6/1000 -> 88351.545 | G8: 半成品-報廢(%) | H8: 0.0025 | I8: ='（２）ＫＰＩ達成進度'!M19 -> 0.0020036679 | J8: 0.002012889 | K8: ='（２）ＫＰＩ達成進度'!N6 -> 0.0020080487 | L8: 報廢率
A9: 材料費率 | B9: ='（１）收支狀況'!P19 -> 0.67098869 | C9: 0.67175329 | D9: =B9-C9 -> -0.00076459715 | E9: ='（１）收支狀況'!Q6 -> 0.67289201 | G9: 半成品-超用(%) | H9: 0.004 | I9: ='（２）ＫＰＩ達成進度'!P19 -> 0.0060137091 | J9: 0.0060293903 | K9: ='（２）ＫＰＩ達成進度'!Q6 -> 0.0060192687 | L9: 超用率
A10: 勞務成本 | B10: ='（１）收支狀況'!S19/1000 -> 6117.744 | C10: 6474.2051 | D10: =B10-C10 -> -356.46102 | E10: ='（１）收支狀況'!T6/1000 -> 17903.717 | G10: 固定產線-導入率(%) | H10: 0.8 | I10: ='（２）ＫＰＩ達成進度'!S19 -> 0.9 | J10: 0.9 | K10: ='（２）ＫＰＩ達成進度'!T6 -> 0.9 | L10: 導入率
A11: 勞務費率 | B11: ='（１）收支狀況'!V19 -> 0.13971469 | C11: 0.13373859 | D11: =B11-C11 -> 0.0059760983 | E11: ='（１）收支狀況'!W6 -> 0.13635605 | G11: 教育訓練-實施率(%) | H11: 1 | I11: =29/52*100% -> 0.55769231 | J11: 0.53846154 | K11: ='（２）ＫＰＩ達成進度'!W6 -> 0.53942308 | L11: 實施率
A13: （３）業績構成比 | E13: ※單位：千元 | G13: （４）訂單數量構成比 | K13: ※單位：個
B14: 當週 | C14: 比例 | D14: 前週 | E14: 差異 | H14: 當週 | I14: 比例 | J14: 前週 | K14: 差異
A15: 18℃-飯糰(061,063) | B15: =SUM('（３）業績構成比'!M21:M27)/1000 -> 12614.878 | C15: =IFERROR(B15/$B$6,"") -> 0.28809374 | D15: 0.26595563 | E15: =IFERROR(C15-D15,"") -> 0.02213811 | G15: 18℃-飯糰(061,063) | H15: =SUM('（４）訂單數量構成比'!M21:M27) -> 659652 | I15: =IFERROR(H15/$B$7,"") -> 0.47797198 | J15: 0.45248782 | K15: =IFERROR(I15-J15,"") -> 0.025484161
A16: 18℃-壽司手卷(071,072,075,076) | B16: =SUM('（３）業績構成比'!S21:S27)/1000 -> 1542.3037 | C16: =IFERROR(B16/$B$6,"") -> 0.035222539 | D16: 0.032307378 | E16: =IFERROR(C16-D16,"") -> 0.0029151606 | G16: 18℃-壽司手卷(071,072,075,076) | H16: =SUM('（４）訂單數量構成比'!S21:S27) -> 53620 | I16: =IFERROR(H16/$B$7,"") -> 0.038852088 | J16: 0.035898648 | K16: =IFERROR(I16-J16,"") -> 0.0029534397
A17: 4℃-飯糰(065) | B17: =SUM('（３）業績構成比'!U21:U27)/1000 -> 1287.4039 | C17: =IFERROR(B17/$B$6,"") -> 0.029401235 | D17: 0.034651895 | E17: =IFERROR(C17-D17,"") -> -0.0052506597 | G17: 4℃-飯糰(065) | H17: =SUM('（４）訂單數量構成比'!U21:U27) -> 43652 | I17: =IFERROR(H17/$B$7,"") -> 0.031629455 | J17: 0.037657454 | K17: =IFERROR(I17-J17,"") -> -0.0060279991
A18: 4℃-壽司手卷(077) | B18: =SUM('（３）業績構成比'!W21:W27)/1000 -> 1533.5521 | C18: =IFERROR(B18/$B$6,"") -> 0.035022673 | D18: 0.033949055 | E18: =IFERROR(C18-D18,"") -> 0.0010736173 | G18: 4℃-壽司手卷(077) | H18: =SUM('（４）訂單數量構成比'!W21:W27) -> 63826 | I18: =IFERROR(H18/$B$7,"") -> 0.046247172 | J18: 0.044975352 | K18: =IFERROR(I18-J18,"") -> 0.0012718207
A19: 主食(091,092,093,094,095) | B19: =SUM('（３）業績構成比'!AC21:AC27)/1000 -> 7180.1879 | C19: =IFERROR(B19/$B$6,"") -> 0.16397837 | D19: 0.17931256 | E19: =IFERROR(C19-D19,"") -> -0.015334189 | G19: 主食(091,092,093,094,095) | H19: =SUM('（４）訂單數量構成比'!AC21:AC27) -> 134272 | I19: =IFERROR(H19/$B$7,"") -> 0.097291078 | J19: 0.10840462 | K19: =IFERROR(I19-J19,"") -> -0.011113541
A20: 便當(083) | B20: =SUM('（３）業績構成比'!AE21:AE27)/1000 -> 10175.318 | C20: =IFERROR(B20/$B$6,"") -> 0.23238001 | D20: 0.2183814 | E20: =IFERROR(C20-D20,"") -> 0.013998603 | G20: 便當(083) | H20: =SUM('（４）訂單數量構成比'!AE21:AE27) -> 163257 | I20: =IFERROR(H20/$B$7,"") -> 0.11829309 | J20: 0.11181854 | K20: =IFERROR(I20-J20,"") -> 0.0064745504
A21: 熱食義麵(122,123,124,126) | B21: =SUM('（３）業績構成比'!AG21:AG27)/1000 -> 0 | C21: =IFERROR(B21/$B$6,"") -> 0 | D21: 0 | E21: =IFERROR(C21-D21,"") -> 0 | G21: 熱食義麵(122,123,124,126) | H21: =SUM('（４）訂單數量構成比'!AG21:AG27) -> 0 | I21: =IFERROR(H21/$B$7,"") -> 0 | J21: 0 | K21: =IFERROR(I21-J21,"") -> 0
A22: 季節調理麵(111,112) | B22: =SUM('（３）業績構成比'!AI21:AI27)/1000 -> 6739.2106 | C22: =IFERROR(B22/$B$6,"") -> 0.1539075 | D22: 0.17424934 | E22: =IFERROR(C22-D22,"") -> -0.020341837 | G22: 季節調理麵(111,112) | H22: =SUM('（４）訂單數量構成比'!AI21:AI27) -> 178703 | I22: =IFERROR(H22/$B$7,"") -> 0.12948498 | J22: 0.1491702 | K22: =IFERROR(I22-J22,"") -> -0.019685216
A23: 微波小吃(153,154,155) | B23: =SUM('（３）業績構成比'!AK21:AK27)/1000 -> 2714.5536 | C23: =IFERROR(B23/$B$6,"") -> 0.061993933 | D23: 0.061192737 | E23: =IFERROR(C23-D23,"") -> 0.00080119515 | G23: 微波小吃(153,154,155) | H23: =SUM('（４）訂單數量構成比'!AK21:AK27) -> 83124 | I23: =IFERROR(H23/$B$7,"") -> 0.060230156 | J23: 0.059587371 | K23: =IFERROR(I23-J23,"") -> 0.00064278529
C24: =SUM(C15:C23) -> 1 | D24: =SUM(D15:D23) -> 1 | I24: =SUM(I15:I23) -> 1 | J24: =SUM(J15:J23) -> 1
A26: （５）品群別人時生產性
A27: 品群 | B27: 當週 | C27: 前週 | D27: 差異 | E27: 累計
A28: 18℃-飯糰(061,063) | B28: ='（５-1）品群別人時生產性(18℃-飯糰)'!L91 -> 769.53148 | C28: 765.61007 | D28: =B28-C28 -> 3.9214086 | E28: ='（５-1）品群別人時生產性(18℃-飯糰)'!C1 -> 768.74032
A29: 18℃-壽司手卷(071,072,075,076) | B29: ='（５-2）品群別人時生產性(18℃-壽司手卷)'!L47 -> 298.89112 | C29: 298.97236 | D29: =B29-C29 -> -0.081239932 | E29: ='（５-2）品群別人時生產性(18℃-壽司手卷)'!C1 -> 298.86613
A30: 4℃-飯糰(065) | B30: ='（５-3）品群別人時生產性(4℃-飯糰)'!L47 -> 115.9678 | C30: 113.38841 | D30: =B30-C30 -> 2.5793906 | E30: ='（５-3）品群別人時生產性(4℃-飯糰)'!C1 -> 116.24957
A31: 4℃-壽司手卷(077) | B31: ='（５-4）品群別人時生產性(4℃-壽司手卷)'!L47 -> 452.87919 | C31: 451.13497 | D31: =B31-C31 -> 1.7442227 | E31: ='（５-4）品群別人時生產性(4℃-壽司手卷)'!C1 -> 432.41163
A32: 主食(091,092,093,094,095) | B32: ='（５-5）品群別人時生產性(微波主食) '!L47 -> 85.849102 | C32: 84.201375 | D32: =B32-C32 -> 1.6477269 | E32: ='（５-5）品群別人時生產性(微波主食) '!C1 -> 85.267291
A33: 便當(083) | B33: ='（５-6）品群別人時生產性(便當)'!L47 -> 79.518358 | C33: 79.487088 | D33: =B33-C33 -> 0.031270237 | E33: ='（５-6）品群別人時生產性(便當)'!C1 -> 79.34755
A34: 熱食義麵(122,123,124,126) | B34: ='（５-7）品群別人時生產性(熱食義麵) '!L47 -> 0 | C34: 0 | D34: =B34-C34 -> 0 | E34: ='（５-7）品群別人時生產性(熱食義麵) '!C1 -> 0
A35: 季節調理麵(111,112) | B35: ='（５-8）品群別人時生產性(季節調理麵) '!L47 -> 155.59253 | C35: 157.47086 | D35: =B35-C35 -> -1.8783338 | E35: ='（５-8）品群別人時生產性(季節調理麵) '!C1 -> 156.88743
A36: 微波小吃(153,154,155) | B36: ='（５-9）品群別人時生產性(微波小吃)'!L47 -> 117.51708 | C36: 117.52142 | D36: =B36-C36 -> -0.0043364273 | E36: ='（５-9）品群別人時生產性(微波小吃)'!C1 -> 117.5096

Sheet （１）收支狀況
B2: （１）收支狀況
B3: 資料繳交日 | C3: 月份 | D3: 日期 | F3: 營業額(元) | I3: 訂單數量(個) | L3: 材料費(元) | O3: 材料費率（材料費／營業額） | R3: 勞務成本（全廠人事成本） | U3: 勞務費率（勞務成本／營業額）
F4: 日 | G4: 週累積 | H4: 月累積 | I4: 日 | J4: 週累積 | K4: 月累積 | L4: 日 | M4: 週累積 | N4: 月累積 | O4: 日 | P4: 週累積 | Q4: 月累積 | R4: 日 | S4: 週累積 | T4: 月累積 | U4: 日 | V4: 週累積 | W4: 月累積
B5: 46211 | D5: 46203 | E5: 二 | F5: 7292751.3 | G5: =SUM(F5:F11) -> 46397167 | I5: 229980 | J5: =SUM(I5:I11) -> 1487035 | L5: 4832312.4 | M5: =SUM(L5:L11) -> 31283826 | O5: =L5/F5 -> 0.66261856 | P5: =M5/G5 -> 0.67426157 | R5: 983789.55 | S5: =SUM(R5:R11) -> 6295557.1 | U5: =R5/F5 -> 0.13489964 | V5: =S5/G5 -> 0.1356884
C6: 七 | D6: =D5+1 -> 46204 | E6: 三 | F6: 6821172.8 | H6: =SUM(F6:F36) -> 1.3130123e+08 | I6: 219467 | K6: =SUM(I6:I36) -> 4151257 | L6: 4619692 | N6: =SUM(L6:L36) -> 88351545 | O6: =L6/F6 -> 0.67725773 | Q6: =N6/H6 -> 0.67289201 | R6: 891137.81 | T6: =SUM(R6:R36) -> 17903717 | U6: =R6/F6 -> 0.1306429 | W6: =T6/H6 -> 0.13635605
D7: =D6+1 -> 46205 | E7: 四 | F7: 6343385.2 | I7: 206563 | L7: 4244444.1 | O7: =L7/F7 -> 0.6691134 | R7: 886674.37 | U7: =R7/F7 -> 0.13977937
D8: =D7+1 -> 46206 | E8: 五 | F8: 5464679.9 | I8: 176725 | L8: 3679588.7 | O8: =L8/F8 -> 0.67334021 | R8: 824958.19 | U8: =R8/F8 -> 0.15096185
D9: =D8+1 -> 46207 | E9: 六 | F9: 6007602.6 | I9: 192415 | L9: 4079843.5 | O9: =L9/F9 -> 0.6791134 | R9: 838341.33 | U9: =R9/F9 -> 0.13954673
D10: =D9+1 -> 46208 | E10: 日 | F10: 7429288.9 | I10: 234759 | L10: 5016225.2 | O10: =L10/F10 -> 0.67519588 | R10: 943212.37 | U10: =R10/F10 -> 0.12695863
D11: =D10+1 -> 46209 | E11: 一 | F11: 7038286 | I11: 227126 | L11: 4811720.6 | O11: =L11/F11 -> 0.68364948 | R11: 927443.5 | U11: =R11/F11 -> 0.13177121
B12: =B5+7 -> 46218 | D12: =D11+1 -> 46210 | E12: 二 | F12: 7860603.4 | G12: =SUM(F12:F18) -> 48409402 | I12: 249215 | J12: =SUM(I12:I18) -> 1514096 | L12: 5271790.6 | M12: =SUM(L12:L18) -> 32519175 | O12: =L12/F12 -> 0.67065979 | P12: =M12/G12 -> 0.67175329 | R12: 992155.3 | S12: =SUM(R12:R18) -> 6474205.1 | U12: =R12/F12 -> 0.12621872 | V12: =S12/G12 -> 0.13373859
D13: =D12+1 -> 46211 | E13: 三 | F13: 7229875 | I13: 230160 | L13: 4820463.2 | O13: =L13/F13 -> 0.66674227 | R13: 938245.1 | U13: =R13/F13 -> 0.12977335
D14: =D13+1 -> 46212 | E14: 四 | F14: 6763681.4 | I14: 211372 | L14: 4492897.4 | O14: =L14/F14 -> 0.66426804 | R14: 923989.09 | U14: =R14/F14 -> 0.13661038
D15: =D14+1 -> 46213 | E15: 五 | F15: 5383246.3 | I15: 168721 | L15: 3666934.2 | O15: =L15/F15 -> 0.68117526 | R15: 808018.27 | U15: =R15/F15 -> 0.1500987
D16: =D15+1 -> 46214 | E16: 六 | F16: 6085802.3 | I16: 191243 | L16: 4159928.2 | O16: =L16/F16 -> 0.68354639 | R16: 846564.04 | U16: =R16/F16 -> 0.13910475
D17: =D16+1 -> 46215 | E17: 日 | F17: 7790002.1 | I17: 237620 | L17: 5212394.8 | O17: =L17/F17 -> 0.6691134 | R17: 1014302.4 | U17: =R17/F17 -> 0.13020566
D18: =D17+1 -> 46216 | E18: 一 | F18: 7296191.5 | I18: 225765 | L18: 4894766.6 | O18: =L18/F18 -> 0.67086598 | R18: 950930.87 | U18: =R18/F18 -> 0.1303325
B19: =B12+7 -> 46225 | D19: =D18+1 -> 46217 | E19: 二 | F19: 6870172.4 | G19: =SUM(F19:F25) -> 43787409 | I19: 215096 | J19: =SUM(I19:I25) -> 1380106 | L19: 4655710.5 | M19: =SUM(L19:L25) -> 29380856 | O19: =L19/F19 -> 0.6776701 | P19: =M19/G19 -> 0.67098869 | R19: 917953.9 | S19: =SUM(R19:R25) -> 6117744 | U19: =R19/F19 -> 0.13361439 | V19: =S19/G19 -> 0.13971469
D20: =D19+1 -> 46218 | E20: 三 | F20: 6423738.6 | I20: 202647 | L20: 4261786.3 | O20: =L20/F20 -> 0.6634433 | R20: 880401.01 | U20: =R20/F20 -> 0.1370543
D21: =D20+1 -> 46219 | E21: 四 | F21: 5886839.1 | I21: 187259 | L21: 3929252.7 | O21: =L21/F21 -> 0.66746392 | R21: 849047.79 | U21: =R21/F21 -> 0.14422813
D22: =D21+1 -> 46220 | E22: 五 | F22: 5200104.5 | I22: 164894 | L22: 3489109.3 | O22: =L22/F22 -> 0.67096907 | R22: 799003.18 | U22: =R22/F22 -> 0.15365137
D23: =D22+1 -> 46221 | E23: 六 | F23: 5391308.3 | I23: 172065 | L23: 3661865.5 | O23: =L23/F23 -> 0.67921649 | R23: 802686.22 | U23: =R23/F23 -> 0.14888524
D24: =D23+1 -> 46222 | E24: 日 | F24: 7176291.2 | I24: 222011 | L24: 4825427 | O24: =L24/F24 -> 0.67241237 | R24: 944834.8 | U24: =R24/F24 -> 0.1316606
D25: =D24+1 -> 46223 | E25: 一 | F25: 6838954.4 | I25: 216134 | L25: 4557704.8 | O25: =L25/F25 -> 0.66643299 | R25: 923817.14 | U25: =R25/F25 -> 0.13508164
B26: =B19+7 -> 46232 | D26: =D25+1 -> 46224 | E26: 二 | G26: =SUM(F26:F32) -> 0 | J26: =SUM(I26:I32) -> 0 | M26: =SUM(L26:L32) -> 0 | O26: =L26/F26 -> #DIV/0! | P26: =M26/G26 -> #DIV/0! | S26: =SUM(R26:R32) -> 0 | U26: =R26/F26 -> #DIV/0! | V26: =S26/G26 -> #DIV/0!
D27: =D26+1 -> 46225 | E27: 三 | O27: =L27/F27 -> #DIV/0! | U27: =R27/F27 -> #DIV/0!
D28: =D27+1 -> 46226 | E28: 四 | O28: =L28/F28 -> #DIV/0! | U28: =R28/F28 -> #DIV/0!
D29: =D28+1 -> 46227 | E29: 五 | O29: =L29/F29 -> #DIV/0! | U29: =R29/F29 -> #DIV/0!
D30: =D29+1 -> 46228 | E30: 六 | O30: =L30/F30 -> #DIV/0! | U30: =R30/F30 -> #DIV/0!
D31: =D30+1 -> 46229 | E31: 日 | O31: =L31/F31 -> #DIV/0! | U31: =R31/F31 -> #DIV/0!
D32: =D31+1 -> 46230 | E32: 一 | O32: =L32/F32 -> #DIV/0! | U32: =R32/F32 -> #DIV/0!
B33: =B26+7 -> 46239 | D33: =D32+1 -> 46231 | E33: 二 | G33: =SUM(F33:F39) -> 0 | J33: =SUM(I33:I39) -> 0 | M33: =SUM(L33:L39) -> 0 | O33: =L33/F33 -> #DIV/0! | P33: =M33/G33 -> #DIV/0! | S33: =SUM(R33:R39) -> 0 | U33: =R33/F33 -> #DIV/0! | V33: =S33/G33 -> #DIV/0!
D34: =D33+1 -> 46232 | E34: 三 | O34: =L34/F34 -> #DIV/0! | U34: =R34/F34 -> #DIV/0!
D35: =D34+1 -> 46233 | E35: 四 | O35: =L35/F35 -> #DIV/0! | U35: =R35/F35 -> #DIV/0!
D36: =D35+1 -> 46234 | E36: 五 | O36: =L36/F36 -> #DIV/0! | U36: =R36/F36 -> #DIV/0!
D37: =D36+1 -> 46235 | E37: 六 | O37: =L37/F37 -> #DIV/0! | U37: =R37/F37 -> #DIV/0!
D38: =D37+1 -> 46236 | E38: 日 | O38: =L38/F38 -> #DIV/0! | U38: =R38/F38 -> #DIV/0!
D39: =D38+1 -> 46237 | E39: 一 | O39: =L39/F39 -> #DIV/0! | U39: =R39/F39 -> #DIV/0!

Sheet （２）ＫＰＩ達成進度
B1: 人時生產性基準值 | C1: 442.4
B2: （２）ＫＰＩ達成進度
B3: 資料繳交日 | C3: 月份 | D3: 日期 | F3: 人時生產性(個/人) | I3: 人時生產性達成率(%) | L3: 半成品報廢(%) | O3: 半成品超用(%) | R3: 固定產線-導入率(固定產線數/總產線數) | U3: 教育訓練-實施率(進度/計畫)
F4: 日 | G4: 週平均 | H4: 月平均 | I4: 日 | J4: 週平均 | K4: 月平均 | L4: 日 | M4: 週平均 | N4: 月平均 | O4: 日 | P4: 週平均 | Q4: 月平均 | R4: 日 | S4: 週平均 | T4: 月平均 | U4: 日 | V4: 週平均 | W4: 月平均
B5: 46211 | D5: 46203 | E5: 二 | F5: 414.46182 | G5: =AVERAGE(F5:F11) -> 428.26229 | I5: =F5/$C$1 -> 0.93684859 | J5: =AVERAGE(I5:I11) -> 0.96804314 | L5: 0.00201 | M5: =AVERAGE(L5:L11) -> 0.002007868 | O5: 0.006 | P5: =AVERAGE(O5:O11) -> 0.0060119541 | R5: 0.9 | S5: =AVERAGE(R5:R11) -> 0.9 | U5: =27/52*100% -> 0.51923077 | V5: =AVERAGE(U5:U11) -> 0.51923077
C6: 七 | D6: =D5+1 -> 46204 | E6: 三 | F6: 435.97969 | H6: =AVERAGEIF(F6:F36,"<>0") -> 431.30084 | I6: =F6/$C$1 -> 0.98548754 | K6: =AVERAGEIF(I6:I36,"<>0") -> 0.97491147 | L6: 0.002007906 | N6: =AVERAGEIF(L6:L36,"<>0") -> 0.0020080487 | O6: 0.0060181156 | Q6: =AVERAGEIF(O6:O36,"<>0") -> 0.0060192687 | R6: 0.9 | T6: =AVERAGEIF(R6:R36,"<>0") -> 0.9 | U6: =27/52*100% -> 0.51923077 | W6: =AVERAGEIF(U6:U36,"<>0") -> 0.53942308
D7: =D6+1 -> 46205 | E7: 四 | F7: 436.43137 | I7: =F7/$C$1 -> 0.98650852 | L7: 0.0020058935 | O7: 0.0060118098 | R7: 0.9 | U7: =27/52*100% -> 0.51923077
D8: =D7+1 -> 46206 | E8: 五 | F8: 437.68597 | I8: =F8/$C$1 -> 0.98934442 | L8: 0.0020024104 | O8: 0.0060083487 | R8: 0.9 | U8: =27/52*100% -> 0.51923077
D9: =D8+1 -> 46207 | E9: 六 | F9: 437.88829 | I9: =F9/$C$1 -> 0.98980174 | L9: 0.0020044785 | O9: 0.0060121684 | R9: 0.9 | U9: =27/52*100% -> 0.51923077
D10: =D9+1 -> 46208 | E10: 日 | F10: 417.6721 | I10: =F10/$C$1 -> 0.94410511 | L10: 0.0020142457 | O10: 0.0060237044 | R10: 0.9 | U10: =27/52*100% -> 0.51923077
D11: =D10+1 -> 46209 | E11: 一 | F11: 417.71676 | I11: =F11/$C$1 -> 0.94420606 | L11: 0.0020101416 | O11: 0.006009532 | R11: 0.9 | U11: =27/52*100% -> 0.51923077
B12: =B5+7 -> 46218 | D12: =D11+1 -> 46210 | E12: 二 | F12: 423.14213 | G12: =AVERAGE(F12:F18) -> 427.48888 | I12: =F12/$C$1 -> 0.95646954 | J12: =AVERAGE(I12:I18) -> 0.96629495 | L12: 0.002019974 | M12: =AVERAGE(L12:L18) -> 0.002012889 | O12: 0.0060496513 | P12: =AVERAGE(O12:O18) -> 0.0060293903 | R12: 0.9 | S12: =AVERAGE(R12:R18) -> 0.9 | U12: =28/52*100% -> 0.53846154 | V12: =AVERAGE(U12:U18) -> 0.53846154
D13: =D12+1 -> 46211 | E13: 三 | F13: 423.43805 | I13: =F13/$C$1 -> 0.95713846 | L13: 0.0020159882 | O13: 0.0060363254 | R13: 0.9 | U13: =28/52*100% -> 0.53846154
D14: =D13+1 -> 46212 | E14: 四 | F14: 422.02496 | I14: =F14/$C$1 -> 0.95394431 | L14: 0.0020104575 | O14: 0.0059852622 | R14: 0.9 | U14: =28/52*100% -> 0.53846154
D15: =D14+1 -> 46213 | E15: 五 | F15: 443.36312 | I15: =F15/$C$1 -> 1.002177 | L15: 0.0020041493 | O15: 0.0059880402 | R15: 0.9 | U15: =28/52*100% -> 0.53846154
D16: =D15+1 -> 46214 | E16: 六 | F16: 440.60112 | I16: =F16/$C$1 -> 0.99593382 | L16: 0.0020097747 | O16: 0.0060040977 | R16: 0.9 | U16: =28/52*100% -> 0.53846154
D17: =D16+1 -> 46215 | E17: 日 | F17: 420.01861 | I17: =F17/$C$1 -> 0.94940916 | L17: 0.0020195444 | O17: 0.0061082606 | R17: 0.9 | U17: =28/52*100% -> 0.53846154
D18: =D17+1 -> 46216 | E18: 一 | F18: 419.83419 | I18: =F18/$C$1 -> 0.94899229 | L18: 0.0020103349 | O18: 0.0060340948 | R18: 0.9 | U18: =28/52*100% -> 0.53846154
B19: =B12+7 -> 46225 | D19: =D18+1 -> 46217 | E19: 二 | F19: 418.55908 | G19: =AVERAGE(F19:F25) -> 435.74576 | I19: =F19/$C$1 -> 0.94611004 | J19: =AVERAGE(I19:I25) -> 0.98495878 | L19: 0.0020063636 | M19: =AVERAGE(L19:L25) -> 0.0020036679 | O19: 0.0060199613 | P19: =AVERAGE(O19:O25) -> 0.0060137091 | R19: 0.9 | S19: =AVERAGE(R19:R25) -> 0.9 | U19: =29/52*100% -> 0.55769231 | V19: =AVERAGE(U19:U25) -> 0.55769231
D20: =D19+1 -> 46218 | E20: 三 | F20: 437.52615 | I20: =F20/$C$1 -> 0.98898316 | L20: 0.0020015268 | O20: 0.0060137341 | R20: 0.9 | U20: =29/52*100% -> 0.55769231
D21: =D20+1 -> 46219 | E21: 四 | F21: 437.96388 | I21: =F21/$C$1 -> 0.9899726 | L21: 0.0020004877 | O21: 0.0060104612 | R21: 0.9 | U21: =29/52*100% -> 0.55769231
D22: =D21+1 -> 46220 | E22: 五 | F22: 440.66021 | I22: =F22/$C$1 -> 0.99606738 | L22: 0.0019975764 | O22: 0.0060076929 | R22: 0.9 | U22: =29/52*100% -> 0.55769231
D23: =D22+1 -> 46221 | E23: 六 | F23: 438.37297 | I23: =F23/$C$1 -> 0.99089732 | L23: 0.0019995971 | O23: 0.0060103892 | R23: 0.9 | U23: =29/52*100% -> 0.55769231
D24: =D23+1 -> 46222 | E24: 日 | F24: 438.70799 | I24: =F24/$C$1 -> 0.99165459 | L24: 0.0020142842 | O24: 0.0060178085 | R24: 0.9 | U24: =29/52*100% -> 0.55769231
D25: =D24+1 -> 46223 | E25: 一 | F25: 438.43007 | I25: =F25/$C$1 -> 0.99102637 | L25: 0.0020058393 | O25: 0.0060159161 | R25: 0.9 | U25: =29/52*100% -> 0.55769231
B26: =B19+7 -> 46232 | D26: =D25+1 -> 46224 | E26: 二 | G26: =AVERAGE(F26:F32) -> #DIV/0! | I26: =F26/$C$1 -> 0 | J26: =AVERAGE(I26:I32) -> 0 | M26: =AVERAGE(L26:L32) -> #DIV/0! | P26: =AVERAGE(O26:O32) -> #DIV/0! | S26: =AVERAGE(R26:R32) -> #DIV/0! | V26: =AVERAGE(U26:U32) -> #DIV/0!
D27: =D26+1 -> 46225 | E27: 三 | I27: =F27/$C$1 -> 0
D28: =D27+1 -> 46226 | E28: 四 | I28: =F28/$C$1 -> 0
D29: =D28+1 -> 46227 | E29: 五 | I29: =F29/$C$1 -> 0
D30: =D29+1 -> 46228 | E30: 六 | I30: =F30/$C$1 -> 0
D31: =D30+1 -> 46229 | E31: 日 | I31: =F31/$C$1 -> 0
D32: =D31+1 -> 46230 | E32: 一 | I32: =F32/$C$1 -> 0
B33: =B26+7 -> 46239 | D33: =D32+1 -> 46231 | E33: 二 | G33: =AVERAGE(F33:F39) -> #DIV/0! | I33: =F33/$C$1 -> 0 | J33: =AVERAGE(I33:I39) -> 0 | M33: =AVERAGE(L33:L39) -> #DIV/0! | P33: =AVERAGE(O33:O39) -> #DIV/0! | S33: =AVERAGE(R33:R39) -> #DIV/0! | V33: =AVERAGE(U33:U39) -> #DIV/0!
D34: =D33+1 -> 46232 | E34: 三 | I34: =F34/$C$1 -> 0
D35: =D34+1 -> 46233 | E35: 四 | I35: =F35/$C$1 -> 0
D36: =D35+1 -> 46234 | E36: 五 | I36: =F36/$C$1 -> 0
D37: =D36+1 -> 46235 | E37: 六 | I37: =F37/$C$1 -> 0
D38: =D37+1 -> 46236 | E38: 日 | I38: =F38/$C$1 -> 0
D39: =D38+1 -> 46237 | E39: 一 | I39: =F39/$C$1 -> 0

Sheet （３）業績構成比
B2: （3）業績構成比
B3: 資料繳交日 | C3: 月份 | D3: 日期 | F3: 營業額 | I3: 品類業績
I4: 18℃-飯糰 | O4: 18℃-壽司手卷 | U4: 4℃-飯糰 | W4: 4℃-壽司手卷 | Y4: 主食 | AE4: 便當 | AG4: 熱食義麵 | AI4: 季節調理麵 | AK4: 微波小吃
F5: 日 | G5: 週累積 | H5: 月累積 | I5: 一配 | K5: 二配 | M5: 合計 | O5: 一配 | Q5: 二配 | S5: 合計 | U5: 一配 | W5: 一配 | Y5: 一配 | AA5: 二配 | AC5: 合計 | AE5: 一配 | AG5: 一配 | AI5: 一配 | AK5: 一配
I6: 業績(元) | J6: 比例(%) | K6: 業績(元) | L6: 比例(%) | M6: 業績(元) | N6: 比例(%) | O6: 業績(元) | P6: 比例(%) | Q6: 業績(元) | R6: 比例(%) | S6: 業績(元) | T6: 比例(%) | U6: 業績(元) | V6: 比例(%) | W6: 業績(元) | X6: 比例(%) | Y6: 業績(元) | Z6: 比例(%) | AA6: 業績(元) | AB6: 比例(%) | AC6: 業績(元) | AD6: 比例(%) | AE6: 業績(元) | AF6: 比例(%) | AG6: 業績(元) | AH6: 比例(%) | AI6: 業績(元) | AJ6: 比例(%) | AK6: 業績(元) | AL6: 比例(%)
B7: =D8+7 -> 46211 | D7: 46203 | E7: 二 | F7: =SUM(M7,S7,U7,W7,AC7,AE7,AG7,AI7,AK7) -> 7292751.3 | G7: =SUM(F7:F13) -> 46397167 | I7: 870247.34 | J7: =I7/$F7 -> 0.11933046 | K7: 1296194.8 | L7: =K7/$F7 -> 0.17773742 | M7: =I7+K7 -> 2166442.1 | N7: =M7/$F7 -> 0.29706787 | O7: 243640.36 | P7: =O7/$F7 -> 0.033408565 | Q7: 0 | R7: =Q7/$F7 -> 0 | S7: =O7+Q7 -> 243640.36 | T7: =S7/$F7 -> 0.033408565 | U7: 76932.99 | V7: =U7/$F7 -> 0.010549241 | W7: 269176.06 | X7: =W7/$F7 -> 0.036910083 | Y7: 267703.92 | Z7: =Y7/$F7 -> 0.03670822 | AA7: 791291.01 | AB7: =AA7/$F7 -> 0.10850377 | AC7: =Y7+AA7 -> 1058994.9 | AD7: =AC7/$F7 -> 0.14521199 | AE7: 1964192.3 | AF7: =AE7/F7 -> 0.26933488 | AG7: 0 | AH7: =AG7/$F7 -> 0 | AI7: 1049909 | AJ7: =AI7/$F7 -> 0.1439661 | AK7: 463463.59 | AL7: =AK7/$F7 -> 0.063551268
C8: 七 | D8: 46204 | E8: 三 | F8: =SUM(M8,S8,U8,W8,AC8,AE8,AG8,AI8,AK8) -> 6821172.8 | H8: =SUM(F8:F38) -> 1.3130123e+08 | I8: 852518.15 | J8: =I8/$F8 -> 0.12498117 | K8: 1247636.7 | L8: =K8/$F8 -> 0.18290648 | M8: =I8+K8 -> 2100154.9 | N8: =M8/F8 -> 0.30788765 | O8: 241584.82 | P8: =O8/$F8 -> 0.035416904 | Q8: 0 | R8: =Q8/$F8 -> 0 | S8: =O8+Q8 -> 241584.82 | T8: =S8/F8 -> 0.035416904 | U8: 69560.37 | V8: =U8/F8 -> 0.010197714 | W8: 266298.69 | X8: =W8/$F8 -> 0.039040015 | Y8: 228710.79 | Z8: =Y8/$F8 -> 0.033529541 | AA8: 715486.28 | AB8: =AA8/$F8 -> 0.10489197 | AC8: =Y8+AA8 -> 944197.07 | AD8: =AC8/$F8 -> 0.13842151 | AE8: 1635986 | AF8: =AE8/F8 -> 0.2398394 | AG8: 0 | AH8: =AG8/$F8 -> 0 | AI8: 1137140.8 | AJ8: =AI8/$F8 -> 0.16670752 | AK8: 426250.15 | AL8: =AK8/$F8 -> 0.062489276
D9: 46205 | E9: 四 | F9: =SUM(M9,S9,U9,W9,AC9,AE9,AG9,AI9,AK9) -> 6343385.2 | I9: 841060.58 | J9: =I9/$F9 -> 0.1325886 | K9: 1132330.3 | L9: =K9/$F9 -> 0.17850568 | M9: =I9+K9 -> 1973390.9 | N9: =M9/$F9 -> 0.31109428 | O9: 241052.02 | P9: =O9/$F9 -> 0.038000533 | Q9: 0 | R9: =Q9/$F9 -> 0 | S9: =O9+Q9 -> 241052.02 | T9: =S9/$F9 -> 0.038000533 | U9: 68391.54 | V9: =U9/$F9 -> 0.010781552 | W9: 263487.44 | X9: =W9/$F9 -> 0.041537354 | Y9: 238868.19 | Z9: =Y9/$F9 -> 0.037656264 | AA9: 571313.38 | AB9: =AA9/$F9 -> 0.090064431 | AC9: =Y9+AA9 -> 810181.57 | AD9: =AC9/$F9 -> 0.1277207 | AE9: 1417335.5 | AF9: =AE9/F9 -> 0.22343519 | AG9: 0 | AH9: =AG9/$F9 -> 0 | AI9: 1172740.3 | AJ9: =AI9/$F9 -> 0.18487609 | AK9: 396806.03 | AL9: =AK9/$F9 -> 0.062554301
D10: 46206 | E10: 五 | F10: =SUM(M10,S10,U10,W10,AC10,AE10,AG10,AI10,AK10) -> 5464679.9 | I10: 647323.16 | J10: =I10/$F10 -> 0.11845582 | K10: 1011868.3 | L10: =K10/$F10 -> 0.18516515 | M10: =I10+K10 -> 1659191.4 | N10: =M10/F10 -> 0.30362097 | O10: 189998.62 | P10: =O10/$F10 -> 0.034768481 | Q10: 0 | R10: =Q10/$F10 -> 0 | S10: =O10+Q10 -> 189998.62 | T10: =S10/F10 -> 0.034768481 | U10: 52327.62 | V10: =U10/F10 -> 0.0095756056 | W10: 203624.02 | X10: =W10/$F10 -> 0.037261838 | Y10: 304834.86 | Z10: =Y10/$F10 -> 0.055782747 | AA10: 602529.19 | AB10: =AA10/$F10 -> 0.11025883 | AC10: =Y10+AA10 -> 907364.05 | AD10: =AC10/$F10 -> 0.16604157 | AE10: 1049930.6 | AF10: =AE10/F10 -> 0.1921303 | AG10: 0 | AH10: =AG10/$F10 -> 0 | AI10: 1060721.9 | AJ10: =AI10/$F10 -> 0.19410504 | AK10: 341521.67 | AL10: =AK10/$F10 -> 0.062496189
D11: 46207 | E11: 六 | F11: =SUM(M11,S11,U11,W11,AC11,AE11,AG11,AI11,AK11) -> 6007602.6 | I11: 628066.32 | J11: =I11/$F11 -> 0.10454525 | K11: 1138095.7 | L11: =K11/$F11 -> 0.18944257 | M11: =I11+K11 -> 1766162 | N11: =M11/$F11 -> 0.29398782 | O11: 182080.85 | P11: =O11/$F11 -> 0.030308404 | Q11: 0 | R11: =Q11/$F11 -> 0 | S11: =O11+Q11 -> 182080.85 | T11: =S11/$F11 -> 0.030308404 | U11: 58711.23 | V11: =U11/$F11 -> 0.0097728218 | W11: 240534.61 | X11: =W11/$F11 -> 0.040038369 | Y11: 256248.63 | Z11: =Y11/$F11 -> 0.042654058 | AA11: 720303.38 | AB11: =AA11/$F11 -> 0.11989864 | AC11: =Y11+AA11 -> 976552.01 | AD11: =AC11/$F11 -> 0.1625527 | AE11: 1274785.1 | AF11: =AE11/F11 -> 0.2121953 | AG11: 0 | AH11: =AG11/$F11 -> 0 | AI11: 1117715.3 | AJ11: =AI11/$F11 -> 0.18605015 | AK11: 391061.54 | AL11: =AK11/$F11 -> 0.065094442
D12: 46208 | E12: 日 | F12: =SUM(M12,S12,U12,W12,AC12,AE12,AG12,AI12,AK12) -> 7429288.9 | I12: 898860.55 | J12: =I12/$F12 -> 0.12098877 | K12: 1280412.9 | L12: =K12/$F12 -> 0.17234663 | M12: =I12+K12 -> 2179273.5 | N12: =M12/F12 -> 0.2933354 | O12: 252783.55 | P12: =O12/$F12 -> 0.034025268 | Q12: 0 | R12: =Q12/$F12 -> 0 | S12: =O12+Q12 -> 252783.55 | T12: =S12/F12 -> 0.034025268 | U12: 83136.78 | V12: =U12/F12 -> 0.011190409 | W12: 262650.2 | X12: =W12/$F12 -> 0.035353343 | Y12: 291573.81 | Z12: =Y12/$F12 -> 0.03924653 | AA12: 778259.38 | AB12: =AA12/$F12 -> 0.10475557 | AC12: =Y12+AA12 -> 1069833.2 | AD12: =AC12/$F12 -> 0.1440021 | AE12: 1901796.6 | AF12: =AE12/F12 -> 0.25598635 | AG12: 0 | AH12: =AG12/$F12 -> 0 | AI12: 1246032.1 | AJ12: =AI12/$F12 -> 0.16771889 | AK12: 433783.09 | AL12: =AK12/$F12 -> 0.058388238
D13: 46209 | E13: 一 | F13: =SUM(M13,S13,U13,W13,AC13,AE13,AG13,AI13,AK13) -> 7038286 | I13: 885803.68 | J13: =I13/$F13 -> 0.12585503 | K13: 1266607.5 | L13: =K13/$F13 -> 0.17995966 | M13: =I13+K13 -> 2152411.2 | N13: =M13/$F13 -> 0.30581468 | O13: 250345.35 | P13: =O13/$F13 -> 0.035569079 | Q13: 0 | R13: =Q13/$F13 -> 0 | S13: =O13+Q13 -> 250345.35 | T13: =S13/$F13 -> 0.035569079 | U13: 77682.24 | V13: =U13/$F13 -> 0.011037096 | W13: 286246.63 | X13: =W13/$F13 -> 0.040669934 | Y13: 242197.56 | Z13: =Y13/$F13 -> 0.03441144 | AA13: 759357.09 | AB13: =AA13/$F13 -> 0.10788949 | AC13: =Y13+AA13 -> 1001554.7 | AD13: =AC13/$F13 -> 0.14230093 | AE13: 1659551.5 | AF13: =AE13/F13 -> 0.23578915 | AG13: 0 | AH13: =AG13/$F13 -> 0 | AI13: 1152323.2 | AJ13: =AI13/$F13 -> 0.16372213 | AK13: 458171.27 | AL13: =AK13/$F13 -> 0.065096995
B14: =D15+7 -> 46218 | D14: 46210 | E14: 二 | F14: =SUM(M14,S14,U14,W14,AC14,AE14,AG14,AI14,AK14) -> 7860603.4 | G14: =SUM(F14:F20) -> 48409402 | I14: 880930.33 | J14: =I14/$F14 -> 0.11206905 | K14: 1233744.4 | L14: =K14/$F14 -> 0.15695289 | M14: =I14+K14 -> 2114674.8 | N14: =M14/$F14 -> 0.26902194 | O14: 249319.47 | P14: =O14/$F14 -> 0.0317176 | Q14: 0 | R14: =Q14/$F14 -> 0 | S14: =O14+Q14 -> 249319.47 | T14: =S14/$F14 -> 0.0317176 | U14: 346715.9 | V14: =U14/$F14 -> 0.044108052 | W14: 263397.85 | X14: =W14/$F14 -> 0.033508605 | Y14: 682575.13 | Z14: =Y14/$F14 -> 0.086834954 | AA14: 734119.83 | AB14: =AA14/$F14 -> 0.0933923 | AC14: =Y14+AA14 -> 1416695 | AD14: =AC14/$F14 -> 0.18022725 | AE14: 1550480.4 | AF14: =AE14/F14 -> 0.19724699 | AG14: 0 | AH14: =AG14/$F14 -> 0 | AI14: 1479142.7 | AJ14: =AI14/$F14 -> 0.18817165 | AK14: 440177.33 | AL14: =AK14/$F14 -> 0.055997906
D15: 46211 | E15: 三 | F15: =SUM(M15,S15,U15,W15,AC15,AE15,AG15,AI15,AK15) -> 7229875 | I15: 854165.39 | J15: =I15/$F15 -> 0.11814387 | K15: 1144812 | L15: =K15/$F15 -> 0.15834464 | M15: =I15+K15 -> 1998977.3 | N15: =M15/F15 -> 0.27648851 | O15: 246302.58 | P15: =O15/$F15 -> 0.034067336 | Q15: 0 | R15: =Q15/$F15 -> 0 | S15: =O15+Q15 -> 246302.58 | T15: =S15/F15 -> 0.034067336 | U15: 229547.26 | V15: =U15/F15 -> 0.031749824 | W15: 255314.84 | X15: =W15/$F15 -> 0.035313867 | Y15: 535980.38 | Z15: =Y15/$F15 -> 0.074134115 | AA15: 722118.41 | AB15: =AA15/$F15 -> 0.099879792 | AC15: =Y15+AA15 -> 1258098.8 | AD15: =AC15/$F15 -> 0.17401391 | AE15: 1457285.8 | AF15: =AE15/F15 -> 0.20156445 | AG15: 0 | AH15: =AG15/$F15 -> 0 | AI15: 1356785.8 | AJ15: =AI15/$F15 -> 0.18766381 | AK15: 427562.5 | AL15: =AK15/$F15 -> 0.059138298
D16: 46212 | E16: 四 | F16: =SUM(M16,S16,U16,W16,AC16,AE16,AG16,AI16,AK16) -> 6763681.4 | I16: 765228.93 | J16: =I16/$F16 -> 0.11313793 | K16: 992416.56 | L16: =K16/$F16 -> 0.14672728 | M16: =I16+K16 -> 1757645.5 | N16: =M16/$F16 -> 0.25986521 | O16: 228745.53 | P16: =O16/$F16 -> 0.033819678 | Q16: 0 | R16: =Q16/$F16 -> 0 | S16: =O16+Q16 -> 228745.53 | T16: =S16/$F16 -> 0.033819678 | U16: 212758.88 | V16: =U16/$F16 -> 0.031456076 | W16: 247015.87 | X16: =W16/$F16 -> 0.03652092 | Y16: 496231.16 | Z16: =Y16/$F16 -> 0.073367021 | AA16: 668808.42 | AB16: =AA16/$F16 -> 0.098882307 | AC16: =Y16+AA16 -> 1165039.6 | AD16: =AC16/$F16 -> 0.17224933 | AE16: 1456308.1 | AF16: =AE16/F16 -> 0.21531294 | AG16: 0 | AH16: =AG16/$F16 -> 0 | AI16: 1250972.6 | AJ16: =AI16/$F16 -> 0.18495439 | AK16: 445195.38 | AL16: =AK16/$F16 -> 0.065821459
D17: 46213 | E17: 五 | F17: =SUM(M17,S17,U17,W17,AC17,AE17,AG17,AI17,AK17) -> 5383246.3 | I17: 579909.59 | J17: =I17/$F17 -> 0.10772489 | K17: 866974.1 | L17: =K17/$F17 -> 0.16105043 | M17: =I17+K17 -> 1446883.7 | N17: =M17/F17 -> 0.26877531 | O17: 178415.97 | P17: =O17/$F17 -> 0.033142822 | Q17: 0 | R17: =Q17/$F17 -> 0 | S17: =O17+Q17 -> 178415.97 | T17: =S17/F17 -> 0.033142822 | U17: 182945.39 | V17: =U17/F17 -> 0.033984213 | W17: 183686.99 | X17: =W17/$F17 -> 0.034121974 | Y17: 384734.26 | Z17: =Y17/$F17 -> 0.07146882 | AA17: 584000.58 | AB17: =AA17/$F17 -> 0.10848483 | AC17: =Y17+AA17 -> 968734.84 | AD17: =AC17/$F17 -> 0.17995365 | AE17: 1171330.5 | AF17: =AE17/F17 -> 0.21758813 | AG17: 0 | AH17: =AG17/$F17 -> 0 | AI17: 917881.72 | AJ17: =AI17/$F17 -> 0.1705071 | AK17: 333367.17 | AL17: =AK17/$F17 -> 0.061926792
D18: 46214 | E18: 六 | F18: =SUM(M18,S18,U18,W18,AC18,AE18,AG18,AI18,AK18) -> 6085802.3 | I18: 575469.15 | J18: =I18/$F18 -> 0.09455929 | K18: 1056890.2 | L18: =K18/$F18 -> 0.17366488 | M18: =I18+K18 -> 1632359.3 | N18: =M18/$F18 -> 0.26822417 | O18: 180329.66 | P18: =O18/$F18 -> 0.029631205 | Q18: 0 | R18: =Q18/$F18 -> 0 | S18: =O18+Q18 -> 180329.66 | T18: =S18/$F18 -> 0.029631205 | U18: 224454.95 | V18: =U18/$F18 -> 0.036881735 | W18: 209800.09 | X18: =W18/$F18 -> 0.034473694 | Y18: 453560.67 | Z18: =Y18/$F18 -> 0.07452767 | AA18: 671874.37 | AB18: =AA18/$F18 -> 0.11040029 | AC18: =Y18+AA18 -> 1125435 | AD18: =AC18/$F18 -> 0.18492796 | AE18: 1269917.1 | AF18: =AE18/F18 -> 0.2086688 | AG18: 0 | AH18: =AG18/$F18 -> 0 | AI18: 1068018.8 | AJ18: =AI18/$F18 -> 0.17549351 | AK18: 375487.37 | AL18: =AK18/$F18 -> 0.06169891
D19: 46215 | E19: 日 | F19: =SUM(M19,S19,U19,W19,AC19,AE19,AG19,AI19,AK19) -> 7790002.1 | I19: 825821.42 | J19: =I19/$F19 -> 0.10601042 | K19: 1163118.6 | L19: =K19/$F19 -> 0.14930915 | M19: =I19+K19 -> 1988940.1 | N19: =M19/F19 -> 0.25531958 | O19: 241261.93 | P19: =O19/$F19 -> 0.030970714 | Q19: 0 | R19: =Q19/$F19 -> 0 | S19: =O19+Q19 -> 241261.93 | T19: =S19/F19 -> 0.030970714 | U19: 263001.55 | V19: =U19/F19 -> 0.033761422 | W19: 231269.79 | X19: =W19/$F19 -> 0.029688027 | Y19: 588890.14 | Z19: =Y19/$F19 -> 0.075595633 | AA19: 823525.13 | AB19: =AA19/$F19 -> 0.10571565 | AC19: =Y19+AA19 -> 1412415.3 | AD19: =AC19/$F19 -> 0.18131128 | AE19: 1954760.6 | AF19: =AE19/F19 -> 0.25093198 | AG19: 0 | AH19: =AG19/$F19 -> 0 | AI19: 1247470.8 | AJ19: =AI19/$F19 -> 0.16013742 | AK19: 450882.04 | AL19: =AK19/$F19 -> 0.057879579
D20: 46216 | E20: 一 | F20: =SUM(M20,S20,U20,W20,AC20,AE20,AG20,AI20,AK20) -> 7296191.5 | I20: 807393.35 | J20: =I20/$F20 -> 0.11065956 | K20: 1127879.2 | L20: =K20/$F20 -> 0.15458465 | M20: =I20+K20 -> 1935272.5 | N20: =M20/$F20 -> 0.26524421 | O20: 239605.71 | P20: =O20/$F20 -> 0.032839833 | Q20: 0 | R20: =Q20/$F20 -> 0 | S20: =O20+Q20 -> 239605.71 | T20: =S20/$F20 -> 0.032839833 | U20: 218053.58 | V20: =U20/$F20 -> 0.029885945 | W20: 252968.04 | X20: =W20/$F20 -> 0.034671245 | Y20: 496197.77 | Z20: =Y20/$F20 -> 0.068007778 | AA20: 837797.56 | AB20: =AA20/$F20 -> 0.1148267 | AC20: =Y20+AA20 -> 1333995.3 | AD20: =AC20/$F20 -> 0.18283447 | AE20: 1711630.6 | AF20: =AE20/F20 -> 0.23459234 | AG20: 0 | AH20: =AG20/$F20 -> 0 | AI20: 1115033.7 | AJ20: =AI20/$F20 -> 0.15282407 | AK20: 489632.03 | AL20: =AK20/$F20 -> 0.067107892
B21: =D22+7 -> 46225 | D21: 46217 | E21: 二 | F21: =SUM(M21,S21,U21,W21,AC21,AE21,AG21,AI21,AK21) -> 6870172.4 | G21: =SUM(F21:F27) -> 43787409 | I21: 933663.58 | J21: =I21/$F21 -> 0.13590104 | K21: 1079108.7 | L21: =K21/$F21 -> 0.15707156 | M21: =I21+K21 -> 2012772.3 | N21: =M21/$F21 -> 0.2929726 | O21: 235295.28 | P21: =O21/$F21 -> 0.034248817 | Q21: 0 | R21: =Q21/$F21 -> 0 | S21: =O21+Q21 -> 235295.28 | T21: =S21/$F21 -> 0.034248817 | U21: 181053.58 | V21: =U21/$F21 -> 0.026353571 | W21: 237786.15 | X21: =W21/$F21 -> 0.03461138 | Y21: 440755.01 | Z21: =Y21/$F21 -> 0.064154869 | AA21: 668894.01 | AB21: =AA21/$F21 -> 0.097362041 | AC21: =Y21+AA21 -> 1109649 | AD21: =AC21/$F21 -> 0.16151691 | AE21: 1680304.2 | AF21: =AE21/F21 -> 0.24457963 | AG21: 0 | AH21: =AG21/$F21 -> 0 | AI21: 987387.25 | AJ21: =AI21/$F21 -> 0.14372088 | AK21: 425924.66 | AL21: =AK21/$F21 -> 0.061996211
D22: 46218 | E22: 三 | F22: =SUM(M22,S22,U22,W22,AC22,AE22,AG22,AI22,AK22) -> 6423738.6 | I22: 837864.73 | J22: =I22/$F22 -> 0.13043257 | K22: 1031638.5 | L22: =K22/$F22 -> 0.16059783 | M22: =I22+K22 -> 1869503.2 | N22: =M22/F22 -> 0.2910304 | O22: 233445.58 | P22: =O22/$F22 -> 0.036341077 | Q22: 0 | R22: =Q22/$F22 -> 0 | S22: =O22+Q22 -> 233445.58 | T22: =S22/F22 -> 0.036341077 | U22: 191547.89 | V22: =U22/F22 -> 0.029818755 | W22: 224753.52 | X22: =W22/$F22 -> 0.034987962 | Y22: 441698.23 | Z22: =Y22/$F22 -> 0.068760306 | AA22: 594309.3 | AB22: =AA22/$F22 -> 0.092517665 | AC22: =Y22+AA22 -> 1036007.5 | AD22: =AC22/$F22 -> 0.16127797 | AE22: 1535257.7 | AF22: =AE22/F22 -> 0.23899754 | AG22: 0 | AH22: =AG22/$F22 -> 0 | AI22: 914812.07 | AJ22: =AI22/$F22 -> 0.14241116 | AK22: 418411.07 | AL22: =AK22/$F22 -> 0.065135133
D23: 46219 | E23: 四 | F23: =SUM(M23,S23,U23,W23,AC23,AE23,AG23,AI23,AK23) -> 5886839.1 | I23: 796140.71 | J23: =I23/$F23 -> 0.13524078 | K23: 914813.24 | L23: =K23/$F23 -> 0.15539974 | M23: =I23+K23 -> 1710954 | N23: =M23/$F23 -> 0.29064052 | O23: 230334.59 | P23: =O23/$F23 -> 0.03912704 | Q23: 0 | R23: =Q23/$F23 -> 0 | S23: =O23+Q23 -> 230334.59 | T23: =S23/$F23 -> 0.03912704 | U23: 179909.91 | V23: =U23/$F23 -> 0.030561377 | W23: 219929.86 | X23: =W23/$F23 -> 0.037359584 | Y23: 431493.03 | Z23: =Y23/$F23 -> 0.073297915 | AA23: 483611.21 | AB23: =AA23/$F23 -> 0.082151253 | AC23: =Y23+AA23 -> 915104.24 | AD23: =AC23/$F23 -> 0.15544917 | AE23: 1354591.6 | AF23: =AE23/F23 -> 0.23010507 | AG23: 0 | AH23: =AG23/$F23 -> 0 | AI23: 895147.95 | AJ23: =AI23/$F23 -> 0.15205918 | AK23: 380867.04 | AL23: =AK23/$F23 -> 0.064698055
D24: 46220 | E24: 五 | F24: =SUM(M24,S24,U24,W24,AC24,AE24,AG24,AI24,AK24) -> 5200104.5 | I24: 640903.02 | J24: =I24/$F24 -> 0.1232481 | K24: 838132.21 | L24: =K24/$F24 -> 0.16117603 | M24: =I24+K24 -> 1479035.2 | N24: =M24/F24 -> 0.28442414 | O24: 184063.19 | P24: =O24/$F24 -> 0.035396056 | Q24: 0 | R24: =Q24/$F24 -> 0 | S24: =O24+Q24 -> 184063.19 | T24: =S24/F24 -> 0.035396056 | U24: 161117.61 | V24: =U24/F24 -> 0.030983533 | W24: 175888.92 | X24: =W24/$F24 -> 0.033824113 | Y24: 442099.4 | Z24: =Y24/$F24 -> 0.085017407 | AA24: 477587.3 | AB24: =AA24/$F24 -> 0.091841866 | AC24: =Y24+AA24 -> 919686.7 | AD24: =AC24/$F24 -> 0.17685927 | AE24: 1020406.2 | AF24: =AE24/F24 -> 0.19622801 | AG24: 0 | AH24: =AG24/$F24 -> 0 | AI24: 946134.59 | AJ24: =AI24/$F24 -> 0.1819453 | AK24: 313772.08 | AL24: =AK24/$F24 -> 0.060339572
D25: 46221 | E25: 六 | F25: =SUM(M25,S25,U25,W25,AC25,AE25,AG25,AI25,AK25) -> 5391308.3 | I25: 615469.3 | J25: =I25/$F25 -> 0.11415954 | K25: 969000.51 | L25: =K25/$F25 -> 0.17973383 | M25: =I25+K25 -> 1584469.8 | N25: =M25/$F25 -> 0.29389338 | O25: 174193.89 | P25: =O25/$F25 -> 0.032310133 | Q25: 0 | R25: =Q25/$F25 -> 0 | S25: =O25+Q25 -> 174193.89 | T25: =S25/$F25 -> 0.032310133 | U25: 161820.98 | V25: =U25/$F25 -> 0.03001516 | W25: 183074.12 | X25: =W25/$F25 -> 0.033957271 | Y25: 413382.74 | Z25: =Y25/$F25 -> 0.076675774 | AA25: 556245.62 | AB25: =AA25/$F25 -> 0.10317451 | AC25: =Y25+AA25 -> 969628.36 | AD25: =AC25/$F25 -> 0.17985029 | AE25: 1087810 | AF25: =AE25/F25 -> 0.20177106 | AG25: 0 | AH25: =AG25/$F25 -> 0 | AI25: 903060.12 | AJ25: =AI25/$F25 -> 0.16750296 | AK25: 327251.05 | AL25: =AK25/$F25 -> 0.060699747
D26: 46222 | E26: 日 | F26: =SUM(M26,S26,U26,W26,AC26,AE26,AG26,AI26,AK26) -> 7176291.2 | I26: 881753.83 | J26: =I26/$F26 -> 0.12287041 | K26: 1111733.8 | L26: =K26/$F26 -> 0.15491759 | M26: =I26+K26 -> 1993487.6 | N26: =M26/F26 -> 0.277788 | O26: 243741.48 | P26: =O26/$F26 -> 0.033964825 | Q26: 0 | R26: =Q26/$F26 -> 0 | S26: =O26+Q26 -> 243741.48 | T26: =S26/F26 -> 0.033964825 | U26: 217036.82 | V26: =U26/F26 -> 0.030243591 | W26: 227469.35 | X26: =W26/$F26 -> 0.031697341 | Y26: 509935.66 | Z26: =Y26/$F26 -> 0.071058384 | AA26: 636335.04 | AB26: =AA26/$F26 -> 0.088671853 | AC26: =Y26+AA26 -> 1146270.7 | AD26: =AC26/$F26 -> 0.15973024 | AE26: 1873840.4 | AF26: =AE26/F26 -> 0.26111543 | AG26: 0 | AH26: =AG26/$F26 -> 0 | AI26: 1069355 | AJ26: =AI26/$F26 -> 0.14901221 | AK26: 405089.93 | AL26: =AK26/$F26 -> 0.056448368
D27: 46223 | E27: 一 | F27: =SUM(M27,S27,U27,W27,AC27,AE27,AG27,AI27,AK27) -> 6838954.4 | I27: 865702.96 | J27: =I27/$F27 -> 0.12658411 | K27: 1098953.4 | L27: =K27/$F27 -> 0.16069027 | M27: =I27+K27 -> 1964656.4 | N27: =M27/$F27 -> 0.28727438 | O27: 241229.68 | P27: =O27/$F27 -> 0.035272889 | Q27: 0 | R27: =Q27/$F27 -> 0 | S27: =O27+Q27 -> 241229.68 | T27: =S27/$F27 -> 0.035272889 | U27: 194917.11 | V27: =U27/$F27 -> 0.02850101 | W27: 264650.16 | X27: =W27/$F27 -> 0.03869746 | Y27: 484698.73 | Z27: =Y27/$F27 -> 0.070873222 | AA27: 599142.64 | AB27: =AA27/$F27 -> 0.087607346 | AC27: =Y27+AA27 -> 1083841.4 | AD27: =AC27/$F27 -> 0.15848057 | AE27: 1623108.3 | AF27: =AE27/F27 -> 0.23733281 | AG27: 0 | AH27: =AG27/$F27 -> 0 | AI27: 1023313.6 | AJ27: =AI27/$F27 -> 0.14963012 | AK27: 443237.82 | AL27: =AK27/$F27 -> 0.064810759
B28: =D29+7 -> 46232 | D28: 46224 | E28: 二 | F28: =SUM(M28,S28,U28,W28,AC28,AE28,AG28,AI28,AK28) -> 0 | G28: =SUM(F28:F34) -> 0
D29: 46225 | E29: 三 | F29: =SUM(M29,S29,U29,W29,AC29,AE29,AG29,AI29,AK29) -> 0
D30: 46226 | E30: 四 | F30: =SUM(M30,S30,U30,W30,AC30,AE30,AG30,AI30,AK30) -> 0
D31: 46227 | E31: 五 | F31: =SUM(M31,S31,U31,W31,AC31,AE31,AG31,AI31,AK31) -> 0
D32: 46228 | E32: 六 | F32: =SUM(M32,S32,U32,W32,AC32,AE32,AG32,AI32,AK32) -> 0
D33: 46229 | E33: 日 | F33: =SUM(M33,S33,U33,W33,AC33,AE33,AG33,AI33,AK33) -> 0
D34: 46230 | E34: 一 | F34: =SUM(M34,S34,U34,W34,AC34,AE34,AG34,AI34,AK34) -> 0
B35: =D36+7 -> 46239 | D35: 46231 | E35: 二 | F35: =SUM(M35,S35,U35,W35,AC35,AE35,AG35,AI35,AK35) -> 0 | G35: =SUM(F35:F41) -> 0
D36: 46232 | E36: 三 | F36: =SUM(M36,S36,U36,W36,AC36,AE36,AG36,AI36,AK36) -> 0
D37: 46233 | E37: 四 | F37: =SUM(M37,S37,U37,W37,AC37,AE37,AG37,AI37,AK37) -> 0
D38: 46234 | E38: 五 | F38: =SUM(M38,S38,U38,W38,AC38,AE38,AG38,AI38,AK38) -> 0
C39: 八 | D39: 46235 | E39: 六 | F39: =SUM(M39,S39,U39,W39,AC39,AE39,AG39,AI39,AK39) -> 0
D40: 46236 | E40: 日 | F40: =SUM(M40,S40,U40,W40,AC40,AE40,AG40,AI40,AK40) -> 0
D41: 46237 | E41: 一 | F41: =SUM(M41,S41,U41,W41,AC41,AE41,AG41,AI41,AK41) -> 0

Sheet （４）訂單數量構成比
B2: （4）訂單數量構成比
B3: 資料繳交日 | C3: 月份 | D3: 日期 | F3: 訂單量 | I3: 品類訂單量
I4: 18℃-飯糰 | O4: 18℃-壽司手卷 | U4: 4℃-飯糰 | W4: 4℃-壽司手卷 | Y4: 主食 | AE4: 便當 | AG4: 熱食義麵 | AI4: 季節調理麵 | AK4: 微波小吃
F5: 日 | G5: 週累積 | H5: 月累積 | I5: 一配 | K5: 二配 | M5: 合計 | O5: 一配 | Q5: 二配 | S5: 合計 | U5: 一配 | W5: 一配 | Y5: 一配 | AA5: 二配 | AC5: 合計 | AE5: 一配 | AG5: 一配 | AI5: 一配 | AK5: 一配
I6: 訂單數 | J6: 比例(%) | K6: 訂單數 | L6: 比例(%) | M6: 訂單數 | N6: 比例(%) | O6: 訂單數 | P6: 比例(%) | Q6: 訂單數 | R6: 比例(%) | S6: 訂單數 | T6: 比例(%) | U6: 訂單數 | V6: 比例(%) | W6: 訂單數 | X6: 比例(%) | Y6: 訂單數 | Z6: 比例(%) | AA6: 訂單數 | AB6: 比例(%) | AC6: 訂單數 | AD6: 比例(%) | AE6: 訂單數 | AF6: 比例(%) | AG6: 訂單數 | AH6: 比例(%) | AI6: 訂單數 | AJ6: 比例(%) | AK6: 訂單數 | AL6: 比例(%)
B7: 46211 | D7: 46203 | E7: 二 | F7: =SUM(M7,S7,U7,W7,AC7,AE7,AG7,AI7,AK7) -> 229980 | G7: =SUM(F7:F13) -> 1487035 | I7: 45550 | J7: =I7/$F7 -> 0.1980607 | K7: 69362 | L7: =K7/$F7 -> 0.30160014 | M7: =I7+K7 -> 114912 | N7: =M7/$F7 -> 0.49966084 | O7: 8454 | P7: =O7/$F7 -> 0.036759718 | Q7: 0 | R7: =Q7/$F7 -> 0 | S7: =O7+Q7 -> 8454 | T7: =S7/$F7 -> 0.036759718 | U7: 2567 | V7: =U7/$F7 -> 0.01116184 | W7: 11068 | X7: =W7/$F7 -> 0.048125924 | Y7: 4744 | Z7: =Y7/$F7 -> 0.020627881 | AA7: 14570 | AB7: =AA7/$F7 -> 0.063353335 | AC7: =Y7+AA7 -> 19314 | AD7: =AC7/$F7 -> 0.083981216 | AE7: 31363 | AF7: =AE7/$F7 -> 0.13637273 | AG7: 0 | AH7: =AG7/$F7 -> 0 | AI7: 28378 | AJ7: =AI7/$F7 -> 0.12339334 | AK7: 13924 | AL7: =AK7/$F7 -> 0.060544395
C8: 七 | D8: =D7+1 -> 46204 | E8: 三 | F8: =SUM(M8,S8,U8,W8,AC8,AE8,AG8,AI8,AK8) -> 219467 | H8: =SUM(F8:F38) -> 4151257 | I8: 44534 | J8: =I8/$F8 -> 0.20291889 | K8: 66568 | L8: =K8/$F8 -> 0.30331667 | M8: =I8+K8 -> 111102 | N8: =M8/$F8 -> 0.50623556 | O8: 8378 | P8: =O8/$F8 -> 0.038174304 | Q8: 0 | R8: =Q8/$F8 -> 0 | S8: =O8+Q8 -> 8378 | T8: =S8/$F8 -> 0.038174304 | U8: 2321 | V8: =U8/$F8 -> 0.010575622 | W8: 10915 | X8: =W8/$F8 -> 0.049734129 | Y8: 4053 | Z8: =Y8/$F8 -> 0.018467469 | AA8: 13127 | AB8: =AA8/$F8 -> 0.059813093 | AC8: =Y8+AA8 -> 17180 | AD8: =AC8/$F8 -> 0.078280562 | AE8: 26085 | AF8: =AE8/$F8 -> 0.11885614 | AG8: 0 | AH8: =AG8/$F8 -> 0 | AI8: 30626 | AJ8: =AI8/$F8 -> 0.13954718 | AK8: 12860 | AL8: =AK8/$F8 -> 0.058596509
D9: =D8+1 -> 46205 | E9: 四 | F9: =SUM(M9,S9,U9,W9,AC9,AE9,AG9,AI9,AK9) -> 206563 | I9: 43894 | J9: =I9/$F9 -> 0.21249691 | K9: 60386 | L9: =K9/$F9 -> 0.29233696 | M9: =I9+K9 -> 104280 | N9: =M9/$F9 -> 0.50483388 | O9: 8359 | P9: =O9/$F9 -> 0.040467073 | Q9: 0 | R9: =Q9/$F9 -> 0 | S9: =O9+Q9 -> 8359 | T9: =S9/$F9 -> 0.040467073 | U9: 2282 | V9: =U9/$F9 -> 0.011047477 | W9: 10882 | X9: =W9/$F9 -> 0.052681264 | Y9: 4233 | Z9: =Y9/$F9 -> 0.020492537 | AA9: 10501 | AB9: =AA9/$F9 -> 0.050836791 | AC9: =Y9+AA9 -> 14734 | AD9: =AC9/$F9 -> 0.071329328 | AE9: 22577 | AF9: =AE9/$F9 -> 0.10929837 | AG9: 0 | AH9: =AG9/$F9 -> 0 | AI9: 31626 | AJ9: =AI9/$F9 -> 0.15310583 | AK9: 11823 | AL9: =AK9/$F9 -> 0.057236775
D10: =D9+1 -> 46206 | E10: 五 | F10: =SUM(M10,S10,U10,W10,AC10,AE10,AG10,AI10,AK10) -> 176725 | I10: 33752 | J10: =I10/$F10 -> 0.190986 | K10: 54067 | L10: =K10/$F10 -> 0.30593861 | M10: =I10+K10 -> 87819 | N10: =M10/$F10 -> 0.4969246 | O10: 6604 | P10: =O10/$F10 -> 0.037368793 | Q10: 0 | R10: =Q10/$F10 -> 0 | S10: =O10+Q10 -> 6604 | T10: =S10/$F10 -> 0.037368793 | U10: 1746 | V10: =U10/$F10 -> 0.0098797567 | W10: 8346 | X10: =W10/$F10 -> 0.047225916 | Y10: 5402 | Z10: =Y10/$F10 -> 0.030567266 | AA10: 11076 | AB10: =AA10/$F10 -> 0.062673645 | AC10: =Y10+AA10 -> 16478 | AD10: =AC10/$F10 -> 0.093240911 | AE10: 16756 | AF10: =AE10/$F10 -> 0.094813977 | AG10: 0 | AH10: =AG10/$F10 -> 0 | AI10: 28501 | AJ10: =AI10/$F10 -> 0.16127316 | AK10: 10475 | AL10: =AK10/$F10 -> 0.059272882
D11: =D10+1 -> 46207 | E11: 六 | F11: =SUM(M11,S11,U11,W11,AC11,AE11,AG11,AI11,AK11) -> 192415 | I11: 32941 | J11: =I11/$F11 -> 0.17119767 | K11: 61237 | L11: =K11/$F11 -> 0.31825481 | M11: =I11+K11 -> 94178 | N11: =M11/$F11 -> 0.48945249 | O11: 6326 | P11: =O11/$F11 -> 0.032876855 | Q11: 0 | R11: =Q11/$F11 -> 0 | S11: =O11+Q11 -> 6326 | T11: =S11/$F11 -> 0.032876855 | U11: 1959 | V11: =U11/$F11 -> 0.010181119 | W11: 9903 | X11: =W11/$F11 -> 0.051466881 | Y11: 4541 | Z11: =Y11/$F11 -> 0.023600031 | AA11: 13213 | AB11: =AA11/$F11 -> 0.068669283 | AC11: =Y11+AA11 -> 17754 | AD11: =AC11/$F11 -> 0.092269314 | AE11: 20362 | AF11: =AE11/$F11 -> 0.10582335 | AG11: 0 | AH11: =AG11/$F11 -> 0 | AI11: 30085 | AJ11: =AI11/$F11 -> 0.15635475 | AK11: 11848 | AL11: =AK11/$F11 -> 0.061575241
D12: =D11+1 -> 46208 | E12: 日 | F12: =SUM(M12,S12,U12,W12,AC12,AE12,AG12,AI12,AK12) -> 234759 | I12: 47177 | J12: =I12/$F12 -> 0.20095928 | K12: 68899 | L12: =K12/$F12 -> 0.29348822 | M12: =I12+K12 -> 116076 | N12: =M12/$F12 -> 0.4944475 | O12: 8773 | P12: =O12/$F12 -> 0.037370239 | Q12: 0 | R12: =Q12/$F12 -> 0 | S12: =O12+Q12 -> 8773 | T12: =S12/$F12 -> 0.037370239 | U12: 2774 | V12: =U12/$F12 -> 0.011816373 | W12: 10858 | X12: =W12/$F12 -> 0.046251688 | Y12: 5167 | Z12: =Y12/$F12 -> 0.022009806 | AA12: 14280 | AB12: =AA12/$F12 -> 0.060828339 | AC12: =Y12+AA12 -> 19447 | AD12: =AC12/$F12 -> 0.082838145 | AE12: 30337 | AF12: =AE12/$F12 -> 0.12922614 | AG12: 0 | AH12: =AG12/$F12 -> 0 | AI12: 33607 | AJ12: =AI12/$F12 -> 0.14315532 | AK12: 12887 | AL12: =AK12/$F12 -> 0.054894594
D13: =D12+1 -> 46209 | E13: 一 | F13: =SUM(M13,S13,U13,W13,AC13,AE13,AG13,AI13,AK13) -> 227126 | I13: 46467 | J13: =I13/$F13 -> 0.20458688 | K13: 68106 | L13: =K13/$F13 -> 0.29985999 | M13: =I13+K13 -> 114573 | N13: =M13/$F13 -> 0.50444687 | O13: 8688 | P13: =O13/$F13 -> 0.038251895 | Q13: 0 | R13: =Q13/$F13 -> 0 | S13: =O13+Q13 -> 8688 | T13: =S13/$F13 -> 0.038251895 | U13: 2592 | V13: =U13/$F13 -> 0.011412168 | W13: 11801 | X13: =W13/$F13 -> 0.051957944 | Y13: 4292 | Z13: =Y13/$F13 -> 0.018897 | AA13: 13922 | AB13: =AA13/$F13 -> 0.061296373 | AC13: =Y13+AA13 -> 18214 | AD13: =AC13/$F13 -> 0.080193373 | AE13: 26496 | AF13: =AE13/$F13 -> 0.11665771 | AG13: 0 | AH13: =AG13/$F13 -> 0 | AI13: 31068 | AJ13: =AI13/$F13 -> 0.13678751 | AK13: 13694 | AL13: =AK13/$F13 -> 0.060292525
B14: =D15+7 -> 46218 | D14: =D13+1 -> 46210 | E14: 二 | F14: =SUM(M14,S14,U14,W14,AC14,AE14,AG14,AI14,AK14) -> 249215 | G14: =SUM(F14:F20) -> 1514096 | I14: 46233 | J14: =I14/$F14 -> 0.18551452 | K14: 66245 | L14: =K14/$F14 -> 0.26581466 | M14: =I14+K14 -> 112478 | N14: =M14/$F14 -> 0.45132917 | O14: 8659 | P14: =O14/$F14 -> 0.0347451 | Q14: 0 | R14: =Q14/$F14 -> 0 | S14: =O14+Q14 -> 8659 | T14: =S14/$F14 -> 0.0347451 | U14: 11796 | V14: =U14/$F14 -> 0.047332624 | W14: 10943 | X14: =W14/$F14 -> 0.043909877 | Y14: 13734 | Z14: =Y14/$F14 -> 0.055109042 | AA14: 13478 | AB14: =AA14/$F14 -> 0.054081817 | AC14: =Y14+AA14 -> 27212 | AD14: =AC14/$F14 -> 0.10919086 | AE14: 24810 | AF14: =AE14/$F14 -> 0.099552595 | AG14: 0 | AH14: =AG14/$F14 -> 0 | AI14: 40029 | AJ14: =AI14/$F14 -> 0.16062035 | AK14: 13288 | AL14: =AK14/$F14 -> 0.053319423
D15: =D14+1 -> 46211 | E15: 三 | F15: =SUM(M15,S15,U15,W15,AC15,AE15,AG15,AI15,AK15) -> 230160 | I15: 44805 | J15: =I15/$F15 -> 0.19466893 | K15: 61375 | L15: =K15/$F15 -> 0.26666232 | M15: =I15+K15 -> 106180 | N15: =M15/$F15 -> 0.46133125 | O15: 8552 | P15: =O15/$F15 -> 0.037156761 | Q15: 0 | R15: =Q15/$F15 -> 0 | S15: =O15+Q15 -> 8552 | T15: =S15/$F15 -> 0.037156761 | U15: 7808 | V15: =U15/$F15 -> 0.033924227 | W15: 10614 | X15: =W15/$F15 -> 0.046115746 | Y15: 10532 | Z15: =Y15/$F15 -> 0.045759472 | AA15: 13276 | AB15: =AA15/$F15 -> 0.057681613 | AC15: =Y15+AA15 -> 23808 | AD15: =AC15/$F15 -> 0.10344108 | AE15: 23380 | AF15: =AE15/$F15 -> 0.10158151 | AG15: 0 | AH15: =AG15/$F15 -> 0 | AI15: 36686 | AJ15: =AI15/$F15 -> 0.15939347 | AK15: 13132 | AL15: =AK15/$F15 -> 0.057055961
D16: =D15+1 -> 46212 | E16: 四 | F16: =SUM(M16,S16,U16,W16,AC16,AE16,AG16,AI16,AK16) -> 211372 | I16: 40163 | J16: =I16/$F16 -> 0.19001098 | K16: 53139 | L16: =K16/$F16 -> 0.25140037 | M16: =I16+K16 -> 93302 | N16: =M16/$F16 -> 0.44141135 | O16: 7949 | P16: =O16/$F16 -> 0.037606684 | Q16: 0 | R16: =Q16/$F16 -> 0 | S16: =O16+Q16 -> 7949 | T16: =S16/$F16 -> 0.037606684 | U16: 7232 | V16: =U16/$F16 -> 0.03421456 | W16: 10237 | X16: =W16/$F16 -> 0.048431202 | Y16: 9723 | Z16: =Y16/$F16 -> 0.04599947 | AA16: 12306 | AB16: =AA16/$F16 -> 0.058219632 | AC16: =Y16+AA16 -> 22029 | AD16: =AC16/$F16 -> 0.1042191 | AE16: 23273 | AF16: =AE16/$F16 -> 0.11010446 | AG16: 0 | AH16: =AG16/$F16 -> 0 | AI16: 33866 | AJ16: =AI16/$F16 -> 0.1602199 | AK16: 13484 | AL16: =AK16/$F16 -> 0.063792745
D17: =D16+1 -> 46213 | E17: 五 | F17: =SUM(M17,S17,U17,W17,AC17,AE17,AG17,AI17,AK17) -> 168721 | I17: 30451 | J17: =I17/$F17 -> 0.18048139 | K17: 46500 | L17: =K17/$F17 -> 0.27560292 | M17: =I17+K17 -> 76951 | N17: =M17/$F17 -> 0.4560843 | O17: 6208 | P17: =O17/$F17 -> 0.036794471 | Q17: 0 | R17: =Q17/$F17 -> 0 | S17: =O17+Q17 -> 6208 | T17: =S17/$F17 -> 0.036794471 | U17: 6217 | V17: =U17/$F17 -> 0.036847814 | W17: 7579 | X17: =W17/$F17 -> 0.044920312 | Y17: 7492 | Z17: =Y17/$F17 -> 0.044404668 | AA17: 10740 | AB17: =AA17/$F17 -> 0.063655384 | AC17: =Y17+AA17 -> 18232 | AD17: =AC17/$F17 -> 0.10806005 | AE17: 18753 | AF17: =AE17/$F17 -> 0.11114799 | AG17: 0 | AH17: =AG17/$F17 -> 0 | AI17: 24332 | AJ17: =AI17/$F17 -> 0.14421441 | AK17: 10449 | AL17: =AK17/$F17 -> 0.061930643
