Workbook

Sheet 生產管理報表(月)
A1: 大溪廠生產管理報表
A3: 月別 | B3: 2 | C3: 工廠 | D3: 大溪廠
A4: （１）收支狀況 | E4: ※單位：千元 | G4: （２）ＫＰＩ達成進度
A5: 項目 | B5: 當月 | C5: 前月 | D5: 差異 | E5: 累計 | G5: 項目 | H5: KPI | I5: 當月 | J5: 前月 | K5: 累計 | L5: ※補充
A6: 業績金額 | B6: ='（１）收支狀況'!H10/1000 -> 116569.43 | C6: 146299.94 | D6: =B6-C6 -> -29730.505 | E6: =B6+C6 -> 262869.37 | G6: 人時性(個/月均) | H6: 497.6 | I6: ='（２）ＫＰＩ達成進度'!H10 -> 476.04172 | J6: 458.38414 | K6: =(I6+J6)/2 -> 467.21293 | L6: 個／MH
A7: 訂單數量 | B7: ='（１）收支狀況'!K10 -> 3787002 | C7: 4768701 | D7: =B7-C7 -> -981699 | E7: =B7+C7 -> 8555703 | G7: 人時達成率(%/月均) | H7: 0.8 | I7: ='（２）ＫＰＩ達成進度'!K10 -> 0.95667547 | J7: 0.92118999 | K7: =(I7+J7)/2 -> 0.93893273 | L7: 達成率
A8: 材料費 | B8: 74777 | C8: 93253 | D8: =B8-C8 -> -18476 | E8: =B8+C8 -> 168030 | G8: 半成品-報廢(%) | H8: 0.0025 | I8: ='（２）ＫＰＩ達成進度'!N10 -> 0.0023657636 | J8: 0.0024135432 | K8: =(I8+J8)/2 -> 0.0023896534 | L8: 報廢率
A9: 材料費率 | B9: 0.653 | C9: 0.655 | D9: =B9-C9 -> -0.002 | E9: =E8/E6 -> 0.63921484 | G9: 半成品-超用(%) | H9: 0.004 | I9: ='（２）ＫＰＩ達成進度'!Q10 -> 0.0052393001 | J9: 0.0055994433 | K9: =(I9+J9)/2 -> 0.0054193717 | L9: 超用率
A10: 勞務成本 | B10: 22860 | C10: 22378 | D10: =B10-C10 -> 482 | E10: =B10+C10 -> 45238 | G10: 固定產線-導入率(%) | H10: 0.8 | I10: ='（２）ＫＰＩ達成進度'!T10 -> 0.9 | J10: 0.9 | K10: 0.9 | L10: 導入率
A11: 勞務費率 | B11: 0.2 | C11: 0.157 | D11: =B11-C11 -> 0.043 | E11: =E10/E6 -> 0.17209308 | G11: 教育訓練-實施率(%) | H11: 1 | I11: ='（２）ＫＰＩ達成進度'!W10 -> 0.13873626 | J11: 0.057692308 | K11: 0.13873626 | L11: 實施率
A13: （３）業績構成比 | E13: ※單位：千元 | G13: （４）訂單數量構成比 | K13: ※單位：個
B14: 當月 | C14: 比例 | D14: 前月 | E14: 差異 | H14: 當月 | I14: 比例 | J14: 前月 | K14: 差異
A15: 18℃-飯糰(061,063) | B15: =SUM('（３）業績構成比'!M12:M39)/1000 -> 40493.489 | C15: =IFERROR(B15/$B$6,"") -> 0.34737657 | D15: 0.36139567 | E15: =IFERROR(C15-D15,"") -> -0.014019107 | G15: 18℃-飯糰(061,063) | H15: =SUM('（４）訂單數量構成比'!M12:M39) -> 2159551 | I15: =IFERROR(H15/$B$7,"") -> 0.57025346 | J15: 0.58577126 | K15: =IFERROR(I15-J15,"") -> -0.0155178
A16: 18℃-壽司手卷(071,072,075,076) | B16: =SUM('（３）業績構成比'!S12:S39)/1000 -> 9068.3632 | C16: =IFERROR(B16/$B$6,"") -> 0.077793665 | D16: 0.069633574 | E16: =IFERROR(C16-D16,"") -> 0.0081600909 | G16: 18℃-壽司手卷(071,072,075,076) | H16: =SUM('（４）訂單數量構成比'!S12:S39) -> 346948 | I16: =IFERROR(H16/$B$7,"") -> 0.091615478 | J16: 0.081693946 | K16: =IFERROR(I16-J16,"") -> 0.0099215328
A17: 4℃-飯糰(065) | B17: =SUM('（３）業績構成比'!U12:U39)/1000 -> 2526.8114 | C17: =IFERROR(B17/$B$6,"") -> 0.02167645 | D17: 0.022453222 | E17: =IFERROR(C17-D17,"") -> -0.00077677219 | G17: 4℃-飯糰(065) | H17: =SUM('（４）訂單數量構成比'!U12:U39) -> 90229 | I17: =IFERROR(H17/$B$7,"") -> 0.023825971 | J17: 0.024966128 | K17: =IFERROR(I17-J17,"") -> -0.001140157
A18: 4℃-壽司手卷(077) | B18: =SUM('（３）業績構成比'!W12:W39)/1000 -> 1160.1365 | C18: =IFERROR(B18/$B$6,"") -> 0.0099523222 | D18: 0.008585039 | E18: =IFERROR(C18-D18,"") -> 0.0013672832 | G18: 4℃-壽司手卷(077) | H18: =SUM('（４）訂單數量構成比'!W12:W39) -> 44333 | I18: =IFERROR(H18/$B$7,"") -> 0.011706622 | J18: 0.0097963785 | K18: =IFERROR(I18-J18,"") -> 0.0019102432
A19: 主食(091,092,093,094,095) | B19: =SUM('（３）業績構成比'!AC12:AC39)/1000 -> 21232.781 | C19: =IFERROR(B19/$B$6,"") -> 0.18214708 | D19: 0.16215294 | E19: =IFERROR(C19-D19,"") -> 0.019994139 | G19: 主食(091,092,093,094,095) | H19: =SUM('（４）訂單數量構成比'!AC12:AC39) -> 383049 | I19: =IFERROR(H19/$B$7,"") -> 0.10114835 | J19: 0.089953008 | K19: =IFERROR(I19-J19,"") -> 0.011195341
A20: 便當(083) | B20: =SUM('（３）業績構成比'!AE12:AE39)/1000 -> 32090.662 | C20: =IFERROR(B20/$B$6,"") -> 0.27529226 | D20: 0.27057088 | E20: =IFERROR(C20-D20,"") -> 0.0047213779 | G20: 便當(083) | H20: =SUM('（４）訂單數量構成比'!AE12:AE39) -> 532482 | I20: =IFERROR(H20/$B$7,"") -> 0.14060779 | J20: 0.13708178 | K20: =IFERROR(I20-J20,"") -> 0.0035260192
A21: 熱食義麵(122,123,124,126) | B21: =SUM('（３）業績構成比'!AG12:AG39)/1000 -> 1046.7564 | C21: =IFERROR(B21/$B$6,"") -> 0.0089796819 | D21: 0.029234371 | E21: =IFERROR(C21-D21,"") -> -0.020254689 | G21: 熱食義麵(122,123,124,126) | H21: =SUM('（４）訂單數量構成比'!AG12:AG39) -> 18268 | I21: =IFERROR(H21/$B$7,"") -> 0.0048238686 | J21: 0.015652481 | K21: =IFERROR(I21-J21,"") -> -0.010828612
A22: 季節調理麵(111,112) | B22: =SUM('（３）業績構成比'!AI12:AI39)/1000 -> 4675.5414 | C22: =IFERROR(B22/$B$6,"") -> 0.040109499 | D22: 0.040564166 | E22: =IFERROR(C22-D22,"") -> -0.00045466718 | G22: 季節調理麵(111,112) | H22: =SUM('（４）訂單數量構成比'!AI12:AI39) -> 79156 | I22: =IFERROR(H22/$B$7,"") -> 0.020902022 | J22: 0.022004735 | K22: =IFERROR(I22-J22,"") -> -0.0011027124
A23: 微波小吃(153,154,155) | B23: =SUM('（３）業績構成比'!AK12:AK39)/1000 -> 4274.8898 | C23: =IFERROR(B23/$B$6,"") -> 0.036672477 | D23: 0.035410133 | E23: =IFERROR(C23-D23,"") -> 0.0012623446 | G23: 微波小吃(153,154,155) | H23: =SUM('（４）訂單數量構成比'!AK12:AK39) -> 132986 | I23: =IFERROR(H23/$B$7,"") -> 0.035116432 | J23: 0.033080287 | K23: =IFERROR(I23-J23,"") -> 0.002036145
C24: =SUM(C15:C23) -> 1 | D24: =SUM(D15:D23) -> 1 | I24: =SUM(I15:I23) -> 1 | J24: =SUM(J15:J23) -> 1
A26: （５）品群別人時生產性
A27: 品群 | B27: 當月 | C27: 前月 | D27: 差異 | E27: 累計
A28: 18℃-飯A15:A23糰(061,063) | B28: ='（５-1）品群別人時生產性(18℃-飯糰)'!C1 -> 774.12086 | C28: 768.96509 | D28: =B28-C28 -> 5.1557775 | E28: =(B28+C28)/2 -> 771.54298
A29: 18℃-壽司手卷(071,072,075,076) | B29: ='（５-2）品群別人時生產性(18℃-壽司手卷)'!C1 -> 304.46478 | C29: 280.52358 | D29: =B29-C29 -> 23.941208 | E29: =(B29+C29)/2 -> 292.49418
A30: 4℃-飯糰(065) | B30: ='（５-3）品群別人時生產性(4℃-飯糰)'!C1 -> 203.24374 | C30: 258.56167 | D30: =B30-C30 -> -55.317924 | E30: =(B30+C30)/2 -> 230.9027
A31: 4℃-壽司手卷(077) | B31: ='（５-4）品群別人時生產性(4℃-壽司手卷)'!C1 -> 490.19814 | C31: 486.07171 | D31: =B31-C31 -> 4.1264334 | E31: =(B31+C31)/2 -> 488.13493
A32: 主食(091,092,093,094,095) | B32: ='（５-5）品群別人時生產性(微波主食) '!C1 -> 81.452412 | C32: 82.669482 | D32: =B32-C32 -> -1.2170709 | E32: =(B32+C32)/2 -> 82.060947
A33: 便當(083) | B33: ='（５-6）品群別人時生產性(便當)'!C1 -> 77.971323 | C33: 78.306367 | D33: =B33-C33 -> -0.3350444 | E33: =(B33+C33)/2 -> 78.138845
A34: 熱食義麵(122,123,124,126) | B34: ='（５-7）品群別人時生產性(熱食義麵) '!C1 -> 72.949976 | C34: 76.250133 | D34: =B34-C34 -> -3.3001571 | E34: =(B34+C34)/2 -> 74.600054
A35: 季節調理麵(111,112) | B35: ='（５-8）品群別人時生產性(季節調理麵) '!C1 -> 97.157501 | C35: 110.8083 | D35: =B35-C35 -> -13.650803 | E35: =(B35+C35)/2 -> 103.9829
A36: 微波小吃(153,154,155) | B36: ='（５-9）品群別人時生產性(微波小吃)'!C1 -> 77.592138 | C36: 76.123665 | D36: =B36-C36 -> 1.468473 | E36: =(B36+C36)/2 -> 76.857902

Sheet 生產管理報表(週) 
A1: 大溪廠生產管理報表
A3: 月別 | B3: 2 | C3: 週別 | D3: W4 | E3: 工廠 | F3: 大溪廠
A4: （１）收支狀況 | E4: ※單位：千元 | G4: （２）ＫＰＩ達成進度
A5: 項目 | B5: 當週 | C5: 前週 | D5: 差異 | E5: 累計 | G5: 項目 | H5: KPI | I5: 當週 | J5: 前週 | K5: 累計 | L5: ※補充
A6: 業績金額 | B6: ='（１）收支狀況'!G33/1000 -> 32338.42 | C6: 27936.826 | D6: =B6-C6 -> 4401.5938 | E6: ='（１）收支狀況'!H10:H10/1000 -> 116569.43 | G6: 人時性(個/月均) | I6: ='（２）ＫＰＩ達成進度'!G33 -> 468.73197 | J6: 480.5262 | K6: ='（２）ＫＰＩ達成進度'!H10 -> 476.04172 | L6: 個／MH
A7: 訂單數量 | B7: ='（１）收支狀況'!J33 -> 1076054 | C7: 906470 | D7: =B7-C7 -> 169584 | E7: ='（１）收支狀況'!K10:K10 -> 3787002 | G7: 人時達成率(%/月均) | H7: 0.8 | I7: ='（２）ＫＰＩ達成進度'!J33 -> 0.94198547 | J7: 0.96568771 | K7: ='（２）ＫＰＩ達成進度'!K10 -> 0.95667547 | L7: 達成率
A8: 材料費 | B8: ='（１）收支狀況'!M33/1000 -> 21241.351 | C8: 18452.974 | D8: =B8-C8 -> 2788.3766 | E8: ='（１）收支狀況'!N10:N10/1000 -> 76972.896 | G8: 半成品-報廢(%) | H8: 0.0025 | I8: ='（２）ＫＰＩ達成進度'!M33 -> 0.0022409997 | J8: 0.0023384416 | K8: ='（２）ＫＰＩ達成進度'!N10 -> 0.0023657636 | L8: 報廢率
A9: 材料費率 | B9: ='（１）收支狀況'!P33 -> 0.65684565 | C9: 0.66052507 | D9: =B9-C9 -> -0.0036794153 | E9: ='（１）收支狀況'!Q10 -> 0.66031803 | G9: 半成品-超用(%) | H9: 0.004 | I9: ='（２）ＫＰＩ達成進度'!P33 -> 0.0050772955 | J9: 0.0051307507 | K9: ='（２）ＫＰＩ達成進度'!Q10 -> 0.0052393001 | L9: 超用率
A10: 勞務成本 | B10: ='（１）收支狀況'!S33/1000 -> 5488.2978 | C10: 5131.8224 | D10: =B10-C10 -> 356.47534 | E10: ='（１）收支狀況'!T10/1000 -> 23269.912 | G10: 固定產線-導入率(%) | H10: 0.8 | I10: ='（２）ＫＰＩ達成進度'!S33 -> 0.9 | J10: 0.9 | K10: ='（２）ＫＰＩ達成進度'!T10 -> 0.9 | L10: 導入率
A11: 勞務費率 | B11: ='（１）收支狀況'!V33 -> 0.16971447 | C11: 0.18369382 | D11: =B11-C11 -> -0.013979355 | E11: ='（１）收支狀況'!W10 -> 0.19962277 | G11: 教育訓練-實施率(%) | H11: 1 | I11: =9/52*100% -> 0.17307692 | J11: 0.15384615 | K11: ='（２）ＫＰＩ達成進度'!W10 -> 0.13873626 | L11: 實施率
A13: （３）業績構成比 | E13: ※單位：千元 | G13: （４）訂單數量構成比 | K13: ※單位：個
B14: 當週 | C14: 比例 | D14: 前週 | E14: 差異 | H14: 當週 | I14: 比例 | J14: 前週 | K14: 差異
A15: 18℃-飯糰(061,063) | B15: =SUM('（３）業績構成比'!M35:M41)/1000 -> 11271.407 | C15: =IFERROR(B15/$B$6,"") -> 0.34854538 | D15: 0.34613225 | E15: =IFERROR(C15-D15,"") -> 0.0024131363 | G15: 18℃-飯糰(061,063) | H15: =SUM('（４）訂單數量構成比'!M35:M41) -> 604491 | I15: =IFERROR(H15/$B$7,"") -> 0.56176642 | J15: 0.57188876 | K15: =IFERROR(I15-J15,"") -> -0.010122338
A16: 18℃-壽司手卷(071,072,075,076) | B16: =SUM('（３）業績構成比'!S35:S41)/1000 -> 2511.3867 | C16: =IFERROR(B16/$B$6,"") -> 0.077659535 | D16: 0.084176297 | E16: =IFERROR(C16-D16,"") -> -0.006516762 | G16: 18℃-壽司手卷(071,072,075,076) | H16: =SUM('（４）訂單數量構成比'!S35:S41) -> 95875 | I16: =IFERROR(H16/$B$7,"") -> 0.089098688 | J16: 0.098761128 | K16: =IFERROR(I16-J16,"") -> -0.00966244
A17: 4℃-飯糰(065) | B17: =SUM('（３）業績構成比'!U35:U41)/1000 -> 986.86665 | C17: =IFERROR(B17/$B$6,"") -> 0.030516848 | D17: 0.018452847 | E17: =IFERROR(C17-D17,"") -> 0.012064001 | G17: 4℃-飯糰(065) | H17: =SUM('（４）訂單數量構成比'!U35:U41) -> 39322 | I17: =IFERROR(H17/$B$7,"") -> 0.036542776 | J17: 0.018975807 | K17: =IFERROR(I17-J17,"") -> 0.017566968
A18: 4℃-壽司手卷(077) | B18: =SUM('（３）業績構成比'!W35:W41)/1000 -> 862.21558 | C18: =IFERROR(B18/$B$6,"") -> 0.026662267 | D18: 0.0052924874 | E18: =IFERROR(C18-D18,"") -> 0.021369779 | G18: 4℃-壽司手卷(077) | H18: =SUM('（４）訂單數量構成比'!W35:W41) -> 33582 | I18: =IFERROR(H18/$B$7,"") -> 0.031208471 | J18: 0.0060299844 | K18: =IFERROR(I18-J18,"") -> 0.025178487
A19: 主食(091,092,093,094,095) | B19: =SUM('（３）業績構成比'!AC35:AC41)/1000 -> 5937.0161 | C19: =IFERROR(B19/$B$6,"") -> 0.18359017 | D19: 0.20596075 | E19: =IFERROR(C19-D19,"") -> -0.022370577 | G19: 主食(091,092,093,094,095) | H19: =SUM('（４）訂單數量構成比'!AC35:AC41) -> 108871 | I19: =IFERROR(H19/$B$7,"") -> 0.10117615 | J19: 0.11447483 | K19: =IFERROR(I19-J19,"") -> -0.013298682
A20: 便當(083) | B20: =SUM('（３）業績構成比'!AE35:AE41)/1000 -> 9166.714 | C20: =IFERROR(B20/$B$6,"") -> 0.28346202 | D20: 0.26268194 | E20: =IFERROR(C20-D20,"") -> 0.020780087 | G20: 便當(083) | H20: =SUM('（４）訂單數量構成比'!AE35:AE41) -> 151572 | I20: =IFERROR(H20/$B$7,"") -> 0.1408591 | J20: 0.13510541 | K20: =IFERROR(I20-J20,"") -> 0.005753693
A21: 熱食義麵(122,123,124,126) | B21: =SUM('（３）業績構成比'!AG35:AG41)/1000 -> 0 | C21: =IFERROR(B21/$B$6,"") -> 0 | D21: 0 | E21: =IFERROR(C21-D21,"") -> 0 | G21: 熱食義麵(122,123,124,126) | H21: =SUM('（４）訂單數量構成比'!AG35:AG41) -> 0 | I21: =IFERROR(H21/$B$7,"") -> 0 | J21: 0 | K21: =IFERROR(I21-J21,"") -> 0
A22: 季節調理麵(111,112) | B22: =SUM('（３）業績構成比'!AI35:AI41)/1000 -> 770.52052 | C22: =IFERROR(B22/$B$6,"") -> 0.023826783 | D22: 0.041097888 | E22: =IFERROR(C22-D22,"") -> -0.017271105 | G22: 季節調理麵(111,112) | H22: =SUM('（４）訂單數量構成比'!AI35:AI41) -> 11768 | I22: =IFERROR(H22/$B$7,"") -> 0.010936254 | J22: 0.020215782 | K22: =IFERROR(I22-J22,"") -> -0.009279528
A23: 微波小吃(153,154,155) | B23: =SUM('（３）業績構成比'!AK35:AK41)/1000 -> 832.29354 | C23: =IFERROR(B23/$B$6,"") -> 0.025736988 | D23: 0.036205548 | E23: =IFERROR(C23-D23,"") -> -0.01046856 | G23: 微波小吃(153,154,155) | H23: =SUM('（４）訂單數量構成比'!AK35:AK41) -> 30573 | I23: =IFERROR(H23/$B$7,"") -> 0.028412143 | J23: 0.034548303 | K23: =IFERROR(I23-J23,"") -> -0.0061361599
C24: =SUM(C15:C23) -> 1 | D24: =SUM(D15:D23) -> 1 | I24: =SUM(I15:I23) -> 1 | J24: =SUM(J15:J23) -> 1
A26: （５）品群別人時生產性
A27: 品群 | B27: 當週 | C27: 前週 | D27: 差異 | E27: 累計
A28: 18℃-飯糰(061,063) | B28: ='（５-1）品群別人時生產性(18℃-飯糰)'!L159 -> 770.91906 | C28: 775.89436 | D28: =B28-C28 -> -4.9753035 | E28: ='（５-1）品群別人時生產性(18℃-飯糰)'!C1 -> 774.12086
A29: 18℃-壽司手卷(071,072,075,076) | B29: ='（５-2）品群別人時生產性(18℃-壽司手卷)'!L87 -> 300.55928 | C29: 300.48131 | D29: =B29-C29 -> 0.077973985 | E29: ='（５-2）品群別人時生產性(18℃-壽司手卷)'!C1 -> 304.46478
A30: 4℃-飯糰(065) | B30: ='（５-3）品群別人時生產性(4℃-飯糰)'!L87 -> 317.4626 | C30: 118.5383 | D30: =B30-C30 -> 198.9243 | E30: ='（５-3）品群別人時生產性(4℃-飯糰)'!C1 -> 203.24374
A31: 4℃-壽司手卷(077) | B31: ='（５-4）品群別人時生產性(4℃-壽司手卷)'!L87 -> 481.20057 | C31: 493.52911 | D31: =B31-C31 -> -12.328544 | E31: ='（５-4）品群別人時生產性(4℃-壽司手卷)'!C1 -> 490.19814
A32: 主食(091,092,093,094,095) | B32: ='（５-5）品群別人時生產性(微波主食) '!L87 -> 79.96347 | C32: 82.013443 | D32: =B32-C32 -> -2.0499727 | E32: ='（５-5）品群別人時生產性(微波主食) '!C1 -> 81.452412
A33: 便當(083) | B33: ='（５-6）品群別人時生產性(便當)'!L87 -> 78.283794 | C33: 77.927859 | D33: =B33-C33 -> 0.35593467 | E33: ='（５-6）品群別人時生產性(便當)'!C1 -> 77.971323
A34: 熱食義麵(122,123,124,126) | B34: 0 | C34: 0 | D34: =B34-C34 -> 0 | E34: ='（５-7）品群別人時生產性(熱食義麵) '!C1 -> 72.949976
A35: 季節調理麵(111,112) | B35: ='（５-8）品群別人時生產性(季節調理麵) '!L87 -> 84.576459 | C35: 84.549903 | D35: =B35-C35 -> 0.026555633 | E35: ='（５-8）品群別人時生產性(季節調理麵) '!C1 -> 97.157501
A36: 微波小吃(153,154,155) | B36: ='（５-9）品群別人時生產性(微波小吃)'!L87 -> 78.042646 | C36: 78.027614 | D36: =B36-C36 -> 0.01503221 | E36: ='（５-9）品群別人時生產性(微波小吃)'!C1 -> 77.592138

Sheet （１）收支狀況
B2: （１）收支狀況
B3: 資料繳交日 | C3: 月份 | D3: 日期 | F3: 營業額(元) | I3: 訂單數量(個) | L3: 材料費(元) | O3: 材料費率（材料費／營業額） | R3: 勞務成本（全廠人事成本） | U3: 勞務費率（勞務成本／營業額）
F4: 日 | G4: 週累積 | H4: 月累積 | I4: 日 | J4: 週累積 | K4: 月累積 | L4: 日 | M4: 週累積 | N4: 月累積 | O4: 日 | P4: 週累積 | Q4: 月累積 | R4: 日 | S4: 週累積 | T4: 月累積 | U4: 日 | V4: 週累積 | W4: 月累積
B5: 46057 | D5: 46049 | E5: 二 | F5: 4884312 | G5: =SUM(F5:F11) -> 31759620 | I5: 158031 | J5: =SUM(I5:I11) -> 1022206 | L5: 3270172.8 | M5: =SUM(L5:L11) -> 20915970 | O5: =L5/F5 -> 0.66952577 | P5: =M5/G5 -> 0.65857116 | R5: 768617.64 | S5: =SUM(R5:R11) -> 5357781.8 | U5: =R5/F5 -> 0.15736456 | V5: =S5/G5 -> 0.16869792
D6: =D5+1 -> 46050 | E6: 三 | F6: 4734075.2 | I6: 153374 | L6: 3056358 | O6: =L6/F6 -> 0.64560825 | R6: 765106.55 | U6: =R6/F6 -> 0.1616169
D7: =D6+1 -> 46051 | E7: 四 | F7: 4383675.5 | I7: 141591 | L7: 2886627.7 | O7: =L7/F7 -> 0.65849485 | R7: 749089.25 | U7: =R7/F7 -> 0.17088155
D8: =D7+1 -> 46052 | E8: 五 | F8: 3724978 | I8: 121636 | L8: 2422541.4 | O8: =L8/F8 -> 0.65035052 | R8: 710473.81 | U8: =R8/F8 -> 0.19073235
D9: =D8+1 -> 46053 | E9: 六 | F9: 4007768.4 | I9: 129053 | L9: 2649424.1 | O9: =L9/F9 -> 0.66107216 | R9: 749349.55 | U9: =R9/F9 -> 0.18697427
C10: 二 | D10: 46054 | E10: 日 | F10: 5128838 | H10: =SUM(F10:F37) -> 1.1656943e+08 | I10: 162127 | K10: =SUM(I10:I37) -> 3787002 | L10: 3450280.4 | N10: =SUM(L10:L37) -> 76972896 | O10: =L10/F10 -> 0.67272165 | Q10: =N10/H10 -> 0.66031803 | R10: 816738.48 | T10: =SUM(R7:R37) -> 23269912 | U10: =R10/F10 -> 0.15924435 | W10: =T10/H10 -> 0.19962277
D11: =D10+1 -> 46055 | E11: 一 | F11: 4895972.9 | I11: 156394 | L11: 3180565.3 | O11: =L11/F11 -> 0.64962887 | R11: 798406.55 | U11: =R11/F11 -> 0.16307414
B12: =B5+7 -> 46064 | D12: =D11+1 -> 46056 | E12: 二 | F12: 4840106 | G12: =SUM(F12:F18) -> 31225639 | I12: 156238 | J12: =SUM(I12:I18) -> 1008252 | L12: 3163732.8 | M12: =SUM(L12:L18) -> 20602212 | O12: =L12/F12 -> 0.65364948 | P12: =M12/G12 -> 0.65978512 | R12: 815557.2 | S12: =SUM(R12:R18) -> 5456624.7 | U12: =R12/F12 -> 0.16849986 | V12: =S12/G12 -> 0.17474821
D13: =D12+1 -> 46057 | E13: 三 | F13: 4730102.7 | I13: 152389 | L13: 3110359.5 | O13: =L13/F13 -> 0.65756701 | R13: 776077.2 | U13: =R13/F13 -> 0.16407196
D14: =D13+1 -> 46058 | E14: 四 | F14: 4380960.5 | I14: 141990 | L14: 3009494.1 | O14: =L14/F14 -> 0.68694845 | R14: 800406.53 | U14: =R14/F14 -> 0.18270115
D15: =D14+1 -> 46059 | E15: 五 | F15: 3638268.6 | I15: 119260 | L15: 2380778 | O15: =L15/F15 -> 0.65437113 | R15: 739184.12 | U15: =R15/F15 -> 0.2031692
D16: =D15+1 -> 46060 | E16: 六 | F16: 3904128.8 | I16: 126462 | L16: 2545089.5 | O16: =L16/F16 -> 0.65189691 | R16: 753512.37 | U16: =R16/F16 -> 0.19300397
D17: =D16+1 -> 46061 | E17: 日 | F17: 4998806.5 | I17: 158901 | L17: 3270559.3 | O17: =L17/F17 -> 0.65426804 | R17: 796234.77 | U17: =R17/F17 -> 0.15928497
D18: =D17+1 -> 46062 | E18: 一 | F18: 4733266.2 | I18: 153012 | L18: 3122199 | O18: =L18/F18 -> 0.65962887 | R18: 775652.56 | U18: =R18/F18 -> 0.16387258
B19: =B12+7 -> 46071 | D19: =D18+1 -> 46063 | E19: 二 | F19: 4628863.8 | G19: =SUM(F19:F25) -> 26015260 | I19: 149487 | J19: =SUM(I19:I25) -> 840384 | L19: 2986046.7 | M19: =SUM(L19:L25) -> 17203358 | O19: =L19/F19 -> 0.64509278 | P19: =M19/G19 -> 0.66127948 | R19: 772199.39 | S19: =SUM(R19:R25) -> 4977527.4 | U19: =R19/F19 -> 0.16682266 | V19: =S19/G19 -> 0.19133106
D20: =D19+1 -> 46064 | E20: 三 | F20: 4314019.5 | I20: 140252 | L20: 2826083 | O20: =L20/F20 -> 0.65509278 | R20: 743951.77 | U20: =R20/F20 -> 0.1724498
D21: =D20+1 -> 46065 | E21: 四 | F21: 3791314.2 | I21: 123421 | L21: 2588021.4 | O21: =L21/F21 -> 0.68261856 | R21: 718723.54 | U21: =R21/F21 -> 0.18957108
D22: =D21+1 -> 46066 | E22: 五 | F22: 3262863.4 | I22: 106028 | L22: 2161697.5 | O22: =L22/F22 -> 0.66251546 | R22: 692417.14 | U22: =R22/F22 -> 0.2122115
D23: =D22+1 -> 46067 | E23: 六 | F23: 3301360 | I23: 104504 | L23: 2194009 | O23: =L23/F23 -> 0.66457732 | R23: 693832.38 | U23: =R23/F23 -> 0.21016562
D24: =D23+1 -> 46068 | E24: 日 | F24: 3384701.6 | I24: 107334 | L24: 2257770.4 | O24: =L24/F24 -> 0.66705155 | R24: 684307.21 | U24: =R24/F24 -> 0.20217652
D25: =D24+1 -> 46069 | E25: 一 | F25: 3332137.9 | I25: 109358 | L25: 2189729.9 | O25: =L25/F25 -> 0.65715464 | R25: 672096 | U25: =R25/F25 -> 0.20170113
B26: =B19+7 -> 46078 | D26: =D25+1 -> 46070 | E26: 二 | F26: 3579308.7 | G26: =SUM(F26:F32) -> 27936826 | I26: 116010 | J26: =SUM(I26:I32) -> 906470 | L26: 2434815.5 | M26: =SUM(L26:L32) -> 18452974 | O26: =L26/F26 -> 0.68024742 | P26: =M26/G26 -> 0.66052507 | R26: 697761.82 | S26: =SUM(R26:R32) -> 5131822.4 | U26: =R26/F26 -> 0.19494318 | V26: =S26/G26 -> 0.18369382
D27: =D26+1 -> 46071 | E27: 三 | F27: 3442485.4 | I27: 113544 | L27: 2271117.6 | O27: =L27/F27 -> 0.65973196 | R27: 689405.34 | U27: =R27/F27 -> 0.20026384
D28: =D27+1 -> 46072 | E28: 四 | F28: 3403767.2 | I28: 111594 | L28: 2203114.6 | O28: =L28/F28 -> 0.64725773 | R28: 690936.85 | U28: =R28/F28 -> 0.2029918
D29: =D28+1 -> 46073 | E29: 五 | F29: 3391576.3 | I29: 108182 | L29: 2264803.7 | O29: =L29/F29 -> 0.6677732 | R29: 692880.99 | U29: =R29/F29 -> 0.20429468
D30: =D29+1 -> 46074 | E30: 六 | F30: 3950864.4 | I30: 126225 | L30: 2526679.6 | O30: =L30/F30 -> 0.63952577 | R30: 741738.53 | U30: =R30/F30 -> 0.18774082
D31: =D30+1 -> 46075 | E31: 日 | F31: 5157259.6 | I31: 167195 | L31: 3414637.5 | O31: =L31/F31 -> 0.66210309 | R31: 820162.48 | U31: =R31/F31 -> 0.15903068
D32: =D31+1 -> 46076 | E32: 一 | F32: 5011564.7 | I32: 163720 | L32: 3337805.4 | O32: =L32/F32 -> 0.66602062 | R32: 798936.41 | U32: =R32/F32 -> 0.15941856
B33: =B26+7 -> 46085 | D33: =D32+1 -> 46077 | E33: 二 | F33: 5238957.1 | G33: =SUM(F33:F39) -> 32338420 | I33: 175154 | J33: =SUM(I33:I39) -> 1076054 | L33: 3399597.1 | M33: =SUM(L33:L39) -> 21241351 | O33: =L33/F33 -> 0.64890722 | P33: =M33/G33 -> 0.65684565 | R33: 840082.55 | S33: =SUM(R33:R39) -> 5488297.8 | U33: =R33/F33 -> 0.16035301 | V33: =S33/G33 -> 0.16971447
D34: =D33+1 -> 46078 | E34: 三 | F34: 4692647.5 | I34: 156618 | L34: 3098792.2 | O34: =L34/F34 -> 0.66035052 | R34: 789675.12 | U34: =R34/F34 -> 0.16827923
D35: =D34+1 -> 46079 | E35: 四 | F35: 3909306.8 | I35: 129387 | L35: 2647205.3 | O35: =L35/F35 -> 0.67715464 | R35: 725122.7 | U35: =R35/F35 -> 0.18548626
D36: =D35+1 -> 46080 | E36: 五 | F36: 3610052.1 | I36: 120519 | L36: 2369385.1 | O36: =L36/F36 -> 0.6563299 | R36: 750061.99 | U36: =R36/F36 -> 0.20777041
D37: =D36+1 -> 46081 | E37: 六 | F37: 3915929.6 | H37: =SUM(F38:F67) -> 10971527 | I37: 131697 | K37: =SUM(I38:I67) -> 362679 | L37: 2568526.9 | O37: =L37/F37 -> 0.65591753 | R37: 774937.55 | U37: =R37/F37 -> 0.19789364
D38: =D37+1 -> 46082 | E38: 日 | F38: 5447490.3 | I38: 179915 | L38: 3643303.9 | N38: =SUM(L38:L65) -> 7157844.2 | O38: =L38/F38 -> 0.66880412 | Q38: =N38/H37 -> 0.65240182 | R38: 804587.51 | T38: =SUM(R38:R65) -> 1608417.9 | U38: =R38/F38 -> 0.14769875 | W38: =T38/H38 -> #DIV/0!
D39: =D38+1 -> 46083 | E39: 一 | F39: 5524036.8 | I39: 182764 | L39: 3514540.3 | O39: =L39/F39 -> 0.6362268 | R39: 803830.36 | U39: =R39/F39 -> 0.14551503
B40: =B33+7 -> 46092 | D40: =D39+1 -> 46084 | E40: 二 | G40: =SUM(F40:F46) -> 0 | J40: =SUM(I40:I46) -> 0 | M40: =SUM(L40:L46) -> 0 | O40: =L40/F40 -> #DIV/0! | P40: =M40/G40 -> #DIV/0! | S40: =SUM(R40:R46) -> 0 | U40: =R40/F40 -> #DIV/0! | V40: =S40/G40 -> #DIV/0!
D41: =D40+1 -> 46085 | E41: 三 | O41: =L41/F41 -> #DIV/0! | U41: =R41/F41 -> #DIV/0!
...

Sheet （２）ＫＰＩ達成進度
B1: 人時生產性基準值 | C1: 497.6
B2: （２）ＫＰＩ達成進度
B3: 資料繳交日 | C3: 月份 | D3: 日期 | F3: 人時生產性(個/人) | I3: 人時生產性達成率(%) | L3: 半成品報廢(%) | O3: 半成品超用(%) | R3: 固定產線-導入率(固定產線數/總產線數) | U3: 教育訓練-實施率(進度/計畫)
F4: 日 | G4: 週平均 | H4: 月平均 | I4: 日 | J4: 週平均 | K4: 月平均 | L4: 日 | M4: 週平均 | N4: 月平均 | O4: 日 | P4: 週平均 | Q4: 月平均 | R4: 日 | S4: 週平均 | T4: 月平均 | U4: 日 | V4: 週平均 | W4: 月平均
B5: 46057 | D5: 46049 | E5: 二 | F5: 464.44705 | G5: =AVERAGE(F5:F11) -> 471.15538 | I5: =F5/$C$1 -> 0.9333743 | J5: =AVERAGE(I5:I11) -> 0.94685567 | L5: 0.0024116968 | M5: =AVERAGE(L5:L11) -> 0.0024091778 | O5: 0.0054938914 | P5: =AVERAGE(O5:O11) -> 0.0054843793 | R5: 0.9 | S5: =AVERAGE(R5:R11) -> 0.9 | U5: =5/52*100% -> 0.096153846 | V5: =AVERAGE(U5:U11) -> 0.096153846
D6: =D5+1 -> 46050 | E6: 三 | F6: 464.47506 | I6: =F6/$C$1 -> 0.93343059 | L6: 0.00241014 | O6: 0.0054977047 | R6: 0.9 | U6: =5/52*100% -> 0.096153846
D7: =D6+1 -> 46051 | E7: 四 | F7: 463.28113 | I7: =F7/$C$1 -> 0.9310312 | L7: 0.0024038368 | O7: 0.0054877595 | R7: 0.9 | U7: =5/52*100% -> 0.096153846
D8: =D7+1 -> 46052 | E8: 五 | F8: 485.61792 | I8: =F8/$C$1 -> 0.97592025 | L8: 0.0024044941 | O8: 0.0054453132 | R8: 0.9 | U8: =5/52*100% -> 0.096153846
D9: =D8+1 -> 46053 | E9: 六 | F9: 485.65869 | I9: =F9/$C$1 -> 0.9760022 | L9: 0.0024081846 | O9: 0.0054880042 | R9: 0.9 | U9: =5/52*100% -> 0.096153846
C10: 二 | D10: =D9+1 -> 46054 | E10: 日 | F10: 467.59644 | H10: =AVERAGEIF(F10:F37,"<>0") -> 476.04172 | I10: =F10/$C$1 -> 0.93970345 | K10: =AVERAGEIF(I10:I37,"<>0") -> 0.95667547 | L10: 0.0024135408 | N10: =AVERAGEIF(L10:L37,"<>0") -> 0.0023657636 | O10: 0.0055021522 | Q10: =AVERAGEIF(O10:O37,"<>0") -> 0.0052393001 | R10: 0.9 | T10: =AVERAGEIF(R10:R37,"<>0") -> 0.9 | U10: =5/52*100% -> 0.096153846 | W10: =AVERAGEIF(U10:U37,"<>0") -> 0.13873626
D11: =D10+1 -> 46055 | E11: 一 | F11: 467.01138 | I11: =F11/$C$1 -> 0.9385277 | L11: 0.0024123511 | O11: 0.0054758296 | R11: 0.9 | U11: =5/52*100% -> 0.096153846
B12: =B5+7 -> 46064 | D12: =D11+1 -> 46056 | E12: 二 | F12: 467.06788 | G12: =AVERAGE(F12:F18) -> 471.89204 | I12: =F12/$C$1 -> 0.93864123 | J12: =AVERAGE(I12:I18) -> 0.94833609 | L12: 0.0024099596 | M12: =AVERAGE(L12:L18) -> 0.0024053838 | O12: 0.005456354 | P12: =AVERAGE(O12:O18) -> 0.0054866418 | R12: 0.9 | S12: =AVERAGE(R12:R18) -> 0.9 | U12: =6/52*100% -> 0.11538462 | V12: =AVERAGE(U12:U18) -> 0.11538462
D13: =D12+1 -> 46057 | E13: 三 | F13: 467.08348 | I13: =F13/$C$1 -> 0.93867259 | L13: 0.0024057726 | O13: 0.0054342785 | R13: 0.9 | U13: =6/52*100% -> 0.11538462
D14: =D13+1 -> 46058 | E14: 四 | F14: 464.03002 | I14: =F14/$C$1 -> 0.93253622 | L14: 0.0024042543 | O14: 0.0056361359 | R14: 0.9 | U14: =6/52*100% -> 0.11538462
D15: =D14+1 -> 46059 | E15: 五 | F15: 484.44025 | I15: =F15/$C$1 -> 0.97355356 | L15: 0.0024039703 | O15: 0.0056098775 | R15: 0.9 | U15: =6/52*100% -> 0.11538462
D16: =D15+1 -> 46060 | E16: 六 | F16: 488.96905 | I16: =F16/$C$1 -> 0.98265484 | L16: 0.0023935394 | O16: 0.0054016523 | R16: 0.9 | U16: =6/52*100% -> 0.11538462
D17: =D16+1 -> 46061 | E17: 日 | F17: 465.70359 | I17: =F17/$C$1 -> 0.9358995 | L17: 0.0024099821 | O17: 0.0054364217 | R17: 0.9 | U17: =6/52*100% -> 0.11538462
D18: =D17+1 -> 46062 | E18: 一 | F18: 465.95001 | I18: =F18/$C$1 -> 0.93639472 | L18: 0.0024102079 | O18: 0.005431773 | R18: 0.9 | U18: =6/52*100% -> 0.11538462
B19: =B12+7 -> 46071 | D19: =D18+1 -> 46063 | E19: 二 | F19: 465.9749 | G19: =AVERAGE(F19:F25) -> 479.8197 | I19: =F19/$C$1 -> 0.93644473 | J19: =AVERAGE(I19:I25) -> 0.96426789 | L19: 0.0024035921 | M19: =AVERAGE(L19:L25) -> 0.0023845912 | O19: 0.0052120318 | P19: =AVERAGE(O19:O25) -> 0.0051587843 | R19: 0.9 | S19: =AVERAGE(R19:R25) -> 0.9 | U19: =7/52*100% -> 0.13461538 | V19: =AVERAGE(U19:U25) -> 0.13461538
D20: =D19+1 -> 46064 | E20: 三 | F20: 464.40398 | I20: =F20/$C$1 -> 0.93328775 | L20: 0.0024001654 | O20: 0.0051896535 | R20: 0.9 | U20: =7/52*100% -> 0.13461538
D21: =D20+1 -> 46065 | E21: 四 | F21: 483.871 | I21: =F21/$C$1 -> 0.97240956 | L21: 0.0023864435 | O21: 0.0052018675 | R21: 0.9 | U21: =7/52*100% -> 0.13461538
D22: =D21+1 -> 46066 | E22: 五 | F22: 485.76981 | I22: =F22/$C$1 -> 0.97622549 | L22: 0.0023843744 | O22: 0.0051595122 | R22: 0.9 | U22: =7/52*100% -> 0.13461538
D23: =D22+1 -> 46067 | E23: 六 | F23: 486.12079 | I23: =F23/$C$1 -> 0.97693085 | L23: 0.002380026 | O23: 0.0051356531 | R23: 0.9 | U23: =7/52*100% -> 0.13461538
D24: =D23+1 -> 46068 | E24: 日 | F24: 486.27042 | I24: =F24/$C$1 -> 0.97723154 | L24: 0.0023759181 | O24: 0.0051124749 | R24: 0.9 | U24: =7/52*100% -> 0.13461538
D25: =D24+1 -> 46069 | E25: 一 | F25: 486.32701 | I25: =F25/$C$1 -> 0.97734527 | L25: 0.0023616188 | O25: 0.0051002968 | R25: 0.9 | U25: =7/52*100% -> 0.13461538
B26: =B19+7 -> 46078 | D26: =D25+1 -> 46070 | E26: 二 | F26: 486.38126 | G26: =AVERAGE(F26:F32) -> 480.5262 | I26: =F26/$C$1 -> 0.9774543 | J26: =AVERAGE(I26:I32) -> 0.96568771 | L26: 0.0023683165 | M26: =AVERAGE(L26:L32) -> 0.0023384416 | O26: 0.0051080287 | P26: =AVERAGE(O26:O32) -> 0.0051307507 | R26: 0.9 | S26: =AVERAGE(R26:R32) -> 0.9 | U26: =8/52*100% -> 0.15384615 | V26: =AVERAGE(U26:U32) -> 0.15384615
D27: =D26+1 -> 46071 | E27: 三 | F27: 486.45194 | I27: =F27/$C$1 -> 0.97759635 | L27: 0.0023663889 | O27: 0.005142342 | R27: 0.9 | U27: =8/52*100% -> 0.15384615
D28: =D27+1 -> 46072 | E28: 四 | F28: 486.50397 | I28: =F28/$C$1 -> 0.9777009 | L28: 0.0023484626 | O28: 0.0051317619 | R28: 0.9 | U28: =8/52*100% -> 0.15384615
D29: =D28+1 -> 46073 | E29: 五 | F29: 486.52779 | I29: =F29/$C$1 -> 0.97774877 | L29: 0.0023353383 | O29: 0.0051600067 | R29: 0.9 | U29: =8/52*100% -> 0.15384615
D30: =D29+1 -> 46074 | E30: 六 | F30: 486.58007 | I30: =F30/$C$1 -> 0.97785383 | L30: 0.002330231 | O30: 0.005136114 | R30: 0.9 | U30: =8/52*100% -> 0.15384615
D31: =D30+1 -> 46075 | E31: 日 | F31: 465.5986 | I31: =F31/$C$1 -> 0.93568851 | L31: 0.0023099847 | O31: 0.00511556 | R31: 0.9 | U31: =8/52*100% -> 0.15384615
D32: =D31+1 -> 46076 | E32: 一 | F32: 465.63979 | I32: =F32/$C$1 -> 0.93577128 | L32: 0.0023103693 | O32: 0.0051214414 | R32: 0.9 | U32: =8/52*100% -> 0.15384615
B33: =B26+7 -> 46085 | D33: =D32+1 -> 46077 | E33: 二 | F33: 464.32904 | G33: =AVERAGE(F33:F39) -> 468.73197 | I33: =F33/$C$1 -> 0.93313713 | J33: =AVERAGE(I33:I39) -> 0.94198547 | L33: 0.0023089761 | M33: =AVERAGE(L33:L39) -> 0.0022409997 | O33: 0.0050852114 | P33: =AVERAGE(O33:O39) -> 0.0050772955 | R33: 0.9 | S33: =AVERAGE(R33:R39) -> 0.9 | U33: =9/52*100% -> 0.17307692 | V33: =AVERAGE(U33:U39) -> 0.17307692
D34: =D33+1 -> 46078 | E34: 三 | F34: 465.03721 | I34: =F34/$C$1 -> 0.93456032 | L34: 0.0023055099 | O34: 0.0050598022 | R34: 0.9 | U34: =9/52*100% -> 0.17307692
D35: =D34+1 -> 46079 | E35: 四 | F35: 463.62331 | I35: =F35/$C$1 -> 0.93171887 | L35: 0.0022997824 | O35: 0.0050498788 | R35: 0.9 | U35: =9/52*100% -> 0.17307692
D36: =D35+1 -> 46080 | E36: 五 | F36: 486.84866 | I36: =F36/$C$1 -> 0.97839362 | L36: 0.002298035 | O36: 0.0050264345 | R36: 0.9 | U36: =9/52*100% -> 0.17307692
D37: =D36+1 -> 46081 | E37: 六 | F37: 489.05639 | I37: =F37/$C$1 -> 0.98283036 | L37: 0.0023042698 | O37: 0.0050678558 | R37: 0.9 | U37: =9/52*100% -> 0.17307692
D38: =D37+1 -> 46082 | E38: 日 | F38: 467.10925 | I38: =F38/$C$1 -> 0.93872437 | L38: 0.0020801358 | O38: 0.0051182745 | R38: 0.9 | U38: =9/52*100% -> 0.17307692
D39: =D38+1 -> 46083 | E39: 一 | F39: 445.11993 | I39: =F39/$C$1 -> 0.89453362 | L39: 0.002090289 | O39: 0.0051336112 | R39: 0.9 | U39: =9/52*100% -> 0.17307692
B40: =B33+7 -> 46092 | D40: =D39+1 -> 46084 | E40: 二 | G40: =AVERAGE(F40:F46) -> #DIV/0! | I40: =F40/$C$1 -> 0 | J40: =AVERAGE(I40:I46) -> 0 | M40: =AVERAGE(L40:L46) -> #DIV/0! | P40: =AVERAGE(O40:O46) -> #DIV/0! | S40: =AVERAGE(R40:R46) -> #DIV/0! | V40: =AVERAGE(U40:U46) -> #DIV/0!
...

Sheet （３）業績構成比
B2: （3）業績構成比
B3: 資料繳交日 | C3: 月份 | D3: 日期 | F3: 營業額 | I3: 品類業績
I4: 18℃-飯糰 | O4: 18℃-壽司手卷 | U4: 4℃-飯糰 | W4: 4℃-壽司手卷 | Y4: 主食 | AE4: 便當 | AG4: 熱食義麵 | AI4: 季節調理麵 | AK4: 微波小吃
F5: 日 | G5: 週累積 | H5: 月累積 | I5: 一配 | K5: 二配 | M5: 合計 | O5: 一配 | Q5: 二配 | S5: 合計 | U5: 一配 | W5: 一配 | Y5: 一配 | AA5: 二配 | AC5: 合計 | AE5: 一配 | AG5: 一配 | AI5: 一配 | AK5: 一配
I6: 業績(元) | J6: 比例(%) | K6: 業績(元) | L6: 比例(%) | M6: 業績(元) | N6: 比例(%) | O6: 業績(元) | P6: 比例(%) | Q6: 業績(元) | R6: 比例(%) | S6: 業績(元) | T6: 比例(%) | U6: 業績(元) | V6: 比例(%) | W6: 業績(元) | X6: 比例(%) | Y6: 業績(元) | Z6: 比例(%) | AA6: 業績(元) | AB6: 比例(%) | AC6: 業績(元) | AD6: 比例(%) | AE6: 業績(元) | AF6: 比例(%) | AG6: 業績(元) | AH6: 比例(%) | AI6: 業績(元) | AJ6: 比例(%) | AK6: 業績(元) | AL6: 比例(%)
B7: 46057 | D7: 46049 | E7: 二 | F7: =SUM(M7,S7,U7,W7,AC7,AE7,AG7,AI7,AK7) -> 4884312 | G7: =SUM(F7:F13) -> 31759620 | I7: 853494.19 | J7: =I7/$F7 -> 0.17474195 | K7: 910330.83 | L7: =K7/$F7 -> 0.18637852 | M7: =I7+K7 -> 1763825 | N7: =M7/$F7 -> 0.36112046 | O7: 181062.83 | P7: =O7/$F7 -> 0.037070283 | Q7: 139548.3 | R7: =Q7/$F7 -> 0.028570718 | S7: =O7+Q7 -> 320611.13 | T7: =S7/$F7 -> 0.065641001 | U7: 106504.18 | V7: =U7/$F7 -> 0.02180536 | W7: 32784.6 | X7: =W7/$F7 -> 0.0067122247 | Y7: 199716.86 | Z7: =Y7/$F7 -> 0.040889456 | AA7: 564421.27 | AB7: =AA7/$F7 -> 0.11555799 | AC7: =Y7+AA7 -> 764138.13 | AD7: =AC7/$F7 -> 0.15644744 | AE7: 1395175.2 | AF7: =AE7/F7 -> 0.28564415 | AG7: 88700.4 | AH7: =AG7/$F7 -> 0.018160265 | AI7: 245515.77 | AJ7: =AI7/$F7 -> 0.050266193 | AK7: 167057.65 | AL7: =AK7/$F7 -> 0.034202903
D8: 46050 | E8: 三 | F8: =SUM(M8,S8,U8,W8,AC8,AE8,AG8,AI8,AK8) -> 4734075.2 | I8: 831988.56 | J8: =I8/$F8 -> 0.17574469 | K8: 862624.73 | L8: =K8/$F8 -> 0.1822161 | M8: =I8+K8 -> 1694613.3 | N8: =M8/F8 -> 0.35796079 | O8: 194239.53 | P8: =O8/$F8 -> 0.04103009 | Q8: 145026.12 | R8: =Q8/$F8 -> 0.03063452 | S8: =O8+Q8 -> 339265.65 | T8: =S8/F8 -> 0.07166461 | U8: 100287.54 | V8: =U8/F8 -> 0.021184188 | W8: 34407.6 | X8: =W8/$F8 -> 0.0072680722 | Y8: 190576.89 | Z8: =Y8/$F8 -> 0.040256414 | AA8: 541555.91 | AB8: =AA8/$F8 -> 0.11439529 | AC8: =Y8+AA8 -> 732132.8 | AD8: =AC8/$F8 -> 0.15465171 | AE8: 1316021 | AF8: =AE8/F8 -> 0.27798905 | AG8: 90992.4 | AH8: =AG8/$F8 -> 0.019220734 | AI8: 252653.35 | AJ8: =AI8/$F8 -> 0.053369104 | AK8: 173701.51 | AL8: =AK8/$F8 -> 0.036691751
D9: 46051 | E9: 四 | F9: =SUM(M9,S9,U9,W9,AC9,AE9,AG9,AI9,AK9) -> 4383675.5 | I9: 781634.2 | J9: =I9/$F9 -> 0.17830567 | K9: 765589.38 | L9: =K9/$F9 -> 0.17464554 | M9: =I9+K9 -> 1547223.6 | N9: =M9/$F9 -> 0.35295122 | O9: 187197.27 | P9: =O9/$F9 -> 0.042703269 | Q9: 149643.08 | R9: =Q9/$F9 -> 0.034136441 | S9: =O9+Q9 -> 336840.35 | T9: =S9/$F9 -> 0.07683971 | U9: 99056.27 | V9: =U9/$F9 -> 0.022596625 | W9: 33190.35 | X9: =W9/$F9 -> 0.007571352 | Y9: 179620.28 | Z9: =Y9/$F9 -> 0.040974813 | AA9: 446540.55 | AB9: =AA9/$F9 -> 0.10186442 | AC9: =Y9+AA9 -> 626160.83 | AD9: =AC9/$F9 -> 0.14283923 | AE9: 1223384.5 | AF9: =AE9/F9 -> 0.27907735 | AG9: 93628.2 | AH9: =AG9/$F9 -> 0.021358379 | AI9: 254604.91 | AJ9: =AI9/$F9 -> 0.058080237 | AK9: 169586.43 | AL9: =AK9/$F9 -> 0.0386859
D10: 46052 | E10: 五 | F10: =SUM(M10,S10,U10,W10,AC10,AE10,AG10,AI10,AK10) -> 3724978 | I10: 613209.19 | J10: =I10/$F10 -> 0.16462089 | K10: 738110.29 | L10: =K10/$F10 -> 0.19815158 | M10: =I10+K10 -> 1351319.5 | N10: =M10/F10 -> 0.36277247 | O10: 132952.63 | P10: =O10/$F10 -> 0.035692192 | Q10: 118971.19 | R10: =Q10/$F10 -> 0.031938763 | S10: =O10+Q10 -> 251923.82 | T10: =S10/F10 -> 0.067630955 | U10: 79282.88 | V10: =U10/F10 -> 0.02128412 | W10: 25886.85 | X10: =W10/$F10 -> 0.0069495309 | Y10: 174056.82 | Z10: =Y10/$F10 -> 0.046726939 | AA10: 463375.93 | AB10: =AA10/$F10 -> 0.12439696 | AC10: =Y10+AA10 -> 637432.75 | AD10: =AC10/$F10 -> 0.1711239 | AE10: 961597.17 | AF10: =AE10/F10 -> 0.25814841 | AG10: 72541.8 | AH10: =AG10/$F10 -> 0.019474424 | AI10: 209875.57 | AJ10: =AI10/$F10 -> 0.056342767 | AK10: 135117.7 | AL10: =AK10/$F10 -> 0.036273422
D11: 46053 | E11: 六 | F11: =SUM(M11,S11,U11,W11,AC11,AE11,AG11,AI11,AK11) -> 4007768.4 | I11: 579928.73 | J11: =I11/$F11 -> 0.14470116 | K11: 832680.89 | L11: =K11/$F11 -> 0.20776672 | M11: =I11+K11 -> 1412609.6 | N11: =M11/$F11 -> 0.35246788 | O11: 125493.32 | P11: =O11/$F11 -> 0.031312518 | Q11: 113295.76 | R11: =Q11/$F11 -> 0.028269039 | S11: =O11+Q11 -> 238789.08 | T11: =S11/$F11 -> 0.059581557 | U11: 86337.3 | V11: =U11/$F11 -> 0.021542487 | W11: 26563.1 | X11: =W11/$F11 -> 0.0066279029 | Y11: 193756.01 | Z11: =Y11/$F11 -> 0.048345111 | AA11: 524242.37 | AB11: =AA11/$F11 -> 0.13080655 | AC11: =Y11+AA11 -> 717998.38 | AD11: =AC11/$F11 -> 0.17915166 | AE11: 1049859.4 | AF11: =AE11/F11 -> 0.2619561 | AG11: 87038.7 | AH11: =AG11/$F11 -> 0.021717497 | AI11: 224467.83 | AJ11: =AI11/$F11 -> 0.056008184 | AK11: 164105.01 | AL11: =AK11/$F11 -> 0.04094673
C12: 二 | D12: 46054 | E12: 日 | F12: =SUM(M12,S12,U12,W12,AC12,AE12,AG12,AI12,AK12) -> 5128838 | H12: =SUM(F12:F39) -> 1.1656943e+08 | I12: 822588.93 | J12: =I12/$F12 -> 0.16038505 | K12: 921629.34 | L12: =K12/$F12 -> 0.17969554 | M12: =I12+K12 -> 1744218.3 | N12: =M12/F12 -> 0.34008059 | O12: 196730.22 | P12: =O12/$F12 -> 0.038357659 | Q12: 140075.05 | R12: =Q12/$F12 -> 0.027311264 | S12: =O12+Q12 -> 336805.27 | T12: =S12/F12 -> 0.065668923 | U12: 111357.12 | V12: =U12/F12 -> 0.021711959 | W12: 34786.3 | X12: =W12/$F12 -> 0.0067824915 | Y12: 212944.27 | Z12: =Y12/$F12 -> 0.041519009 | AA12: 608050.05 | AB12: =AA12/$F12 -> 0.11855513 | AC12: =Y12+AA12 -> 820994.32 | AD12: =AC12/$F12 -> 0.16007414 | AE12: 1637542.5 | AF12: =AE12/F12 -> 0.31928139 | AG12: 85606.2 | AH12: =AG12/$F12 -> 0.016691149 | AI12: 207174.87 | AJ12: =AI12/$F12 -> 0.040394115 | AK12: 150353.13 | AL12: =AK12/$F12 -> 0.029315242
D13: 46055 | E13: 一 | F13: =SUM(M13,S13,U13,W13,AC13,AE13,AG13,AI13,AK13) -> 4895972.9 | I13: 795637.69 | J13: =I13/$F13 -> 0.1625086 | K13: 900596.82 | L13: =K13/$F13 -> 0.18394645 | M13: =I13+K13 -> 1696234.5 | N13: =M13/$F13 -> 0.34645504 | O13: 185830.13 | P13: =O13/$F13 -> 0.03795571 | Q13: 140641.23 | R13: =Q13/$F13 -> 0.0287259 | S13: =O13+Q13 -> 326471.36 | T13: =S13/$F13 -> 0.066681611 | U13: 98762.34 | V13: =U13/$F13 -> 0.020172158 | W13: 33460.85 | X13: =W13/$F13 -> 0.0068343618 | Y13: 212149.49 | Z13: =Y13/$F13 -> 0.043331426 | AA13: 571236.47 | AB13: =AA13/$F13 -> 0.11667476 | AC13: =Y13+AA13 -> 783385.96 | AD13: =AC13/$F13 -> 0.16000619 | AE13: 1441498.8 | AF13: =AE13/F13 -> 0.2944254 | AG13: 96206.7 | AH13: =AG13/$F13 -> 0.01965017 | AI13: 242716.64 | AJ13: =AI13/$F13 -> 0.049574751 | AK13: 177235.75 | AL13: =AK13/$F13 -> 0.036200313
B14: =B7+7 -> 46064 | D14: 46056 | E14: 二 | F14: =SUM(M14,S14,U14,W14,AC14,AE14,AG14,AI14,AK14) -> 4840106 | G14: =SUM(F14:F20) -> 31225639 | I14: 805654.11 | J14: =I14/$F14 -> 0.16645382 | K14: 903998.27 | L14: =K14/$F14 -> 0.18677241 | M14: =I14+K14 -> 1709652.4 | N14: =M14/$F14 -> 0.35322623 | O14: 189898.68 | P14: =O14/$F14 -> 0.039234405 | Q14: 148484.16 | R14: =Q14/$F14 -> 0.030677874 | S14: =O14+Q14 -> 338382.84 | T14: =S14/$F14 -> 0.069912279 | U14: 98046.38 | V14: =U14/$F14 -> 0.020257073 | W14: 34353.5 | X14: =W14/$F14 -> 0.0070976751 | Y14: 203577.22 | Z14: =Y14/$F14 -> 0.042060488 | AA14: 596197.07 | AB14: =AA14/$F14 -> 0.12317852 | AC14: =Y14+AA14 -> 799774.29 | AD14: =AC14/$F14 -> 0.165239 | AE14: 1378129.2 | AF14: =AE14/F14 -> 0.2847312 | AG14: 84975.9 | AH14: =AG14/$F14 -> 0.01755662 | AI14: 226898.62 | AJ14: =AI14/$F14 -> 0.046878853 | AK14: 169892.89 | AL14: =AK14/$F14 -> 0.035101068
D15: 46057 | E15: 三 | F15: =SUM(M15,S15,U15,W15,AC15,AE15,AG15,AI15,AK15) -> 4730102.7 | I15: 798741.87 | J15: =I15/$F15 -> 0.16886354 | K15: 860524.79 | L15: =K15/$F15 -> 0.18192518 | M15: =I15+K15 -> 1659266.7 | N15: =M15/F15 -> 0.35078872 | O15: 204275.72 | P15: =O15/$F15 -> 0.043186318 | Q15: 151374.66 | R15: =Q15/$F15 -> 0.032002404 | S15: =O15+Q15 -> 355650.38 | T15: =S15/F15 -> 0.075188722 | U15: 97169.36 | V15: =U15/F15 -> 0.020542759 | W15: 33379.7 | X15: =W15/$F15 -> 0.0070568658 | Y15: 197446.06 | Z15: =Y15/$F15 -> 0.041742447 | AA15: 555977.34 | AB15: =AA15/$F15 -> 0.11754023 | AC15: =Y15+AA15 -> 753423.4 | AD15: =AC15/$F15 -> 0.15928267 | AE15: 1302867.9 | AF15: =AE15/F15 -> 0.27544179 | AG15: 82683.9 | AH15: =AG15/$F15 -> 0.01748036 | AI15: 248743.8 | AJ15: =AI15/$F15 -> 0.052587399 | AK15: 196917.57 | AL15: =AK15/$F15 -> 0.041630717
D16: 46058 | E16: 四 | F16: =SUM(M16,S16,U16,W16,AC16,AE16,AG16,AI16,AK16) -> 4380960.5 | I16: 759713.44 | J16: =I16/$F16 -> 0.17341253 | K16: 781752.39 | L16: =K16/$F16 -> 0.17844315 | M16: =I16+K16 -> 1541465.8 | N16: =M16/$F16 -> 0.35185568 | O16: 200678.65 | P16: =O16/$F16 -> 0.045806998 | Q16: 150870.35 | R16: =Q16/$F16 -> 0.034437733 | S16: =O16+Q16 -> 351549 | T16: =S16/$F16 -> 0.080244731 | U16: 87760.73 | V16: =U16/$F16 -> 0.020032303 | W16: 32730.5 | X16: =W16/$F16 -> 0.0074710785 | Y16: 184672.81 | Z16: =Y16/$F16 -> 0.042153498 | AA16: 447847.86 | AB16: =AA16/$F16 -> 0.10222595 | AC16: =Y16+AA16 -> 632520.67 | AD16: =AC16/$F16 -> 0.14437945 | AE16: 1223663.9 | AF16: =AE16/F16 -> 0.27931407 | AG16: 85262.4 | AH16: =AG16/$F16 -> 0.019462033 | AI16: 229490.12 | AJ16: =AI16/$F16 -> 0.052383517 | AK16: 196517.38 | AL16: =AK16/$F16 -> 0.044857145
D17: 46059 | E17: 五 | F17: =SUM(M17,S17,U17,W17,AC17,AE17,AG17,AI17,AK17) -> 3638268.6 | I17: 589942.58 | J17: =I17/$F17 -> 0.16214926 | K17: 731719.39 | L17: =K17/$F17 -> 0.20111747 | M17: =I17+K17 -> 1321662 | N17: =M17/F17 -> 0.36326673 | O17: 135346.13 | P17: =O17/$F17 -> 0.037200697 | Q17: 121416.47 | R17: =Q17/$F17 -> 0.033372046 | S17: =O17+Q17 -> 256762.6 | T17: =S17/F17 -> 0.070572743 | U17: 69068.22 | V17: =U17/F17 -> 0.018983815 | W17: 21450.65 | X17: =W17/$F17 -> 0.00589584 | Y17: 169004.29 | Z17: =Y17/$F17 -> 0.046451845 | AA17: 468514.79 | AB17: =AA17/$F17 -> 0.12877411 | AC17: =Y17+AA17 -> 637519.08 | AD17: =AC17/$F17 -> 0.17522595 | AE17: 965034.65 | AF17: =AE17/F17 -> 0.26524557 | AG17: 62915.4 | AH17: =AG17/$F17 -> 0.017292676 | AI17: 150301.77 | AJ17: =AI17/$F17 -> 0.041311345 | AK17: 153554.31 | AL17: =AK17/$F17 -> 0.042205325
D18: 46060 | E18: 六 | F18: =SUM(M18,S18,U18,W18,AC18,AE18,AG18,AI18,AK18) -> 3904128.8 | I18: 550717.77 | J18: =I18/$F18 -> 0.14106035 | K18: 836143.76 | L18: =K18/$F18 -> 0.2141691 | M18: =I18+K18 -> 1386861.5 | N18: =M18/$F18 -> 0.35522945 | O18: 125007.97 | P18: =O18/$F18 -> 0.032019428 | Q18: 114762.48 | R18: =Q18/$F18 -> 0.029395157 | S18: =O18+Q18 -> 239770.45 | T18: =S18/$F18 -> 0.061414585 | U18: 73242.04 | V18: =U18/$F18 -> 0.01876015 | W18: 21071.95 | X18: =W18/$F18 -> 0.0053973501 | Y18: 192563.84 | Z18: =Y18/$F18 -> 0.049323127 | AA18: 512199.33 | AB18: =AA18/$F18 -> 0.13119427 | AC18: =Y18+AA18 -> 704763.17 | AD18: =AC18/$F18 -> 0.1805174 | AE18: 1046882.6 | AF18: =AE18/F18 -> 0.26814756 | AG18: 80391.9 | AH18: =AG18/$F18 -> 0.020591508 | AI18: 152212.68 | AJ18: =AI18/$F18 -> 0.038987617 | AK18: 198932.45 | AL18: =AK18/$F18 -> 0.050954377
D19: 46061 | E19: 日 | F19: =SUM(M19,S19,U19,W19,AC19,AE19,AG19,AI19,AK19) -> 4998806.5 | I19: 795904.07 | J19: =I19/$F19 -> 0.15921882 | K19: 919470.56 | L19: =K19/$F19 -> 0.18393802 | M19: =I19+K19 -> 1715374.6 | N19: =M19/F19 -> 0.34315684 | O19: 201984.05 | P19: =O19/$F19 -> 0.040406455 | Q19: 143487.92 | R19: =Q19/$F19 -> 0.028704436 | S19: =O19+Q19 -> 345471.97 | T19: =S19/F19 -> 0.069110891 | U19: 94255.65 | V19: =U19/F19 -> 0.018855631 | W19: 23722.85 | X19: =W19/$F19 -> 0.0047457028 | Y19: 216577.55 | Z19: =Y19/$F19 -> 0.043325852 | AA19: 605602.38 | AB19: =AA19/$F19 -> 0.12114939 | AC19: =Y19+AA19 -> 822179.93 | AD19: =AC19/$F19 -> 0.16447525 | AE19: 1586999.4 | AF19: =AE19/F19 -> 0.31747565 | AG19: 79990.8 | AH19: =AG19/$F19 -> 0.01600198 | AI19: 156005.14 | AJ19: =AI19/$F19 -> 0.031208477 | AK19: 174806.18 | AL19: =AK19/$F19 -> 0.034969583
D20: 46062 | E20: 一 | F20: =SUM(M20,S20,U20,W20,AC20,AE20,AG20,AI20,AK20) -> 4733266.2 | I20: 775970.3 | J20: =I20/$F20 -> 0.16393971 | K20: 901679.03 | L20: =K20/$F20 -> 0.19049827 | M20: =I20+K20 -> 1677649.3 | N20: =M20/$F20 -> 0.35443798 | O20: 191473.16 | P20: =O20/$F20 -> 0.04045265 | Q20: 143278.46 | R20: =Q20/$F20 -> 0.030270526 | S20: =O20+Q20 -> 334751.62 | T20: =S20/$F20 -> 0.070723176 | U20: 83646.27 | V20: =U20/$F20 -> 0.017671998 | W20: 26346.7 | X20: =W20/$F20 -> 0.0055662831 | Y20: 213852.59 | Z20: =Y20/$F20 -> 0.045180765 | AA20: 568050.39 | AB20: =AA20/$F20 -> 0.12001235 | AC20: =Y20+AA20 -> 781902.98 | AD20: =AC20/$F20 -> 0.16519311 | AE20: 1407917 | AF20: =AE20/F20 -> 0.29745148 | AG20: 91221.6 | AH20: =AG20/$F20 -> 0.019272442 | AI20: 182235.28 | AJ20: =AI20/$F20 -> 0.038500957 | AK20: 147595.41 | AL20: =AK20/$F20 -> 0.031182571
B21: =B14+7 -> 46071 | D21: 46063 | E21: 二 | F21: =SUM(M21,S21,U21,W21,AC21,AE21,AG21,AI21,AK21) -> 4628863.8 | G21: =SUM(F21:F27) -> 26015260 | I21: 762285.19 | J21: =I21/$F21 -> 0.16468084 | K21: 875943.54 | L21: =K21/$F21 -> 0.18923511 | M21: =I21+K21 -> 1638228.7 | N21: =M21/$F21 -> 0.35391595 | O21: 186104.06 | P21: =O21/$F21 -> 0.040205127 | Q21: 142648.13 | R21: =Q21/$F21 -> 0.030817094 | S21: =O21+Q21 -> 328752.19 | T21: =S21/$F21 -> 0.071022221 | U21: 86883.03 | V21: =U21/$F21 -> 0.018769839 | W21: 25995.05 | X21: =W21/$F21 -> 0.0056158597 | Y21: 205393.86 | Z21: =Y21/$F21 -> 0.044372413 | AA21: 563493.89 | AB21: =AA21/$F21 -> 0.12173482 | AC21: =Y21+AA21 -> 768887.75 | AD21: =AC21/$F21 -> 0.16610723 | AE21: 1388549.5 | AF21: =AE21/F21 -> 0.29997632 | AG21: 78386.4 | AH21: =AG21/$F21 -> 0.016934264 | AI21: 168096.91 | AJ21: =AI21/$F21 -> 0.036314939 | AK21: 145084.25 | AL21: =AK21/$F21 -> 0.031343383
D22: 46064 | E22: 三 | F22: =SUM(M22,S22,U22,W22,AC22,AE22,AG22,AI22,AK22) -> 4314019.5 | I22: 725375.63 | J22: =I22/$F22 -> 0.1681438 | K22: 797354.71 | L22: =K22/$F22 -> 0.18482872 | M22: =I22+K22 -> 1522730.3 | N22: =M22/F22 -> 0.35297253 | O22: 201662.7 | P22: =O22/$F22 -> 0.046745895 | Q22: 149798.7 | R22: =Q22/$F22 -> 0.034723696 | S22: =O22+Q22 -> 351461.4 | T22: =S22/F22 -> 0.081469591 | U22: 76962.96 | V22: =U22/F22 -> 0.017840198 | W22: 27050 | X22: =W22/$F22 -> 0.0062702545 | Y22: 199092.39 | Z22: =Y22/$F22 -> 0.046150091 | AA22: 538162.94 | AB22: =AA22/$F22 -> 0.12474745 | AC22: =Y22+AA22 -> 737255.33 | AD22: =AC22/$F22 -> 0.17089754 | AE22: 1207259.1 | AF22: =AE22/F22 -> 0.27984555 | AG22: 75578.7 | AH22: =AG22/$F22 -> 0.017519323 | AI22: 169493.87 | AJ22: =AI22/$F22 -> 0.039289083 | AK22: 146227.7 | AL22: =AK22/$F22 -> 0.03389593
D23: 46065 | E23: 四 | F23: =SUM(M23,S23,U23,W23,AC23,AE23,AG23,AI23,AK23) -> 3791314.2 | I23: 614610.84 | J23: =I23/$F23 -> 0.16211024 | K23: 702141.31 | L23: =K23/$F23 -> 0.18519734 | M23: =I23+K23 -> 1316752.1 | N23: =M23/$F23 -> 0.34730758 | O23: 195224.08 | P23: =O23/$F23 -> 0.051492456 | Q23: 144615.69 | R23: =Q23/$F23 -> 0.038143947 | S23: =O23+Q23 -> 339839.77 | T23: =S23/$F23 -> 0.089636403 | U23: 80859.06 | V23: =U23/$F23 -> 0.021327449 | W23: 23506.45 | X23: =W23/$F23 -> 0.0062000796 | Y23: 193188.31 | Z23: =Y23/$F23 -> 0.0509555 | AA23: 463633.83 | AB23: =AA23/$F23 -> 0.12228842 | AC23: =Y23+AA23 -> 656822.14 | AD23: =AC23/$F23 -> 0.17324392 | AE23: 995165.62 | AF23: =AE23/F23 -> 0.26248566 | AG23: 80391.9 | AH23: =AG23/$F23 -> 0.02120423 | AI23: 143492.67 | AJ23: =AI23/$F23 -> 0.037847739 | AK23: 154484.46 | AL23: =AK23/$F23 -> 0.040746942
D24: 46066 | E24: 五 | F24: =SUM(M24,S24,U24,W24,AC24,AE24,AG24,AI24,AK24) -> 3262863.4 | I24: 502290.15 | J24: =I24/$F24 -> 0.15394152 | K24: 618469.46 | L24: =K24/$F24 -> 0.18954807 | M24: =I24+K24 -> 1120759.6 | N24: =M24/F24 -> 0.34348959 | O24: 158341.76 | P24: =O24/$F24 -> 0.048528467 | Q24: 110620.01 | R24: =Q24/$F24 -> 0.03390274 | S24: =O24+Q24 -> 268961.77 | T24: =S24/F24 -> 0.082431208 | U24: 62667.27 | V24: =U24/F24 -> 0.019206219 | W24: 16473.45 | X24: =W24/$F24 -> 0.005048771 | Y24: 187908.7 | Z24: =Y24/$F24 -> 0.057590122 | AA24: 510253.4 | AB24: =AA24/$F24 -> 0.15638209 | AC24: =Y24+AA24 -> 698162.1 | AD24: =AC24/$F24 -> 0.21397221 | AE24: 738317.67 | AF24: =AE24/F24 -> 0.22627906 | AG24: 63144.6 | AH24: =AG24/$F24 -> 0.019352511 | AI24: 150259.21 | AJ24: =AI24/$F24 -> 0.046051333 | AK24: 144117.72 | AL24: =AK24/$F24 -> 0.044169094
D25: 46067 | E25: 六 | F25: =SUM(M25,S25,U25,W25,AC25,AE25,AG25,AI25,AK25) -> 3301360 | I25: 469659.5 | J25: =I25/$F25 -> 0.14226243 | K25: 598492.55 | L25: =K25/$F25 -> 0.18128667 | M25: =I25+K25 -> 1068152 | N25: =M25/$F25 -> 0.3235491 | O25: 149590.5 | P25: =O25/$F25 -> 0.04531178 | Q25: 108896.52 | R25: =Q25/$F25 -> 0.032985351 | S25: =O25+Q25 -> 258487.02 | T25: =S25/$F25 -> 0.078297132 | U25: 65634.3 | V25: =U25/$F25 -> 0.019880988 | W25: 21450.65 | X25: =W25/$F25 -> 0.0064975192 | Y25: 201930.89 | Z25: =Y25/$F25 -> 0.061165971 | AA25: 526054.58 | AB25: =AA25/$F25 -> 0.15934481 | AC25: =Y25+AA25 -> 727985.47 | AD25: =AC25/$F25 -> 0.22051078 | AE25: 822130.01 | AF25: =AE25/F25 -> 0.24902767 | AG25: 0 | AH25: =AG25/$F25 -> 0 | AI25: 186308.29 | AJ25: =AI25/$F25 -> 0.0564338 | AK25: 151212.23 | AL25: =AK25/$F25 -> 0.045803011
D26: 46068 | E26: 日 | F26: =SUM(M26,S26,U26,W26,AC26,AE26,AG26,AI26,AK26) -> 3384701.6 | I26: 475620.61 | J26: =I26/$F26 -> 0.14052069 | K26: 635950.71 | L26: =K26/$F26 -> 0.18788974 | M26: =I26+K26 -> 1111571.3 | N26: =M26/F26 -> 0.32841043 | O26: 149302.92 | P26: =O26/$F26 -> 0.044111103 | Q26: 114039.96 | R26: =Q26/$F26 -> 0.033692766 | S26: =O26+Q26 -> 263342.88 | T26: =S26/F26 -> 0.077803869 | U26: 73006.92 | V26: =U26/F26 -> 0.021569677 | W26: 18015.3 | X26: =W26/$F26 -> 0.0053225667 | Y26: 206586.03 | Z26: =Y26/$F26 -> 0.061035227 | AA26: 525059.12 | AB26: =AA26/$F26 -> 0.15512715 | AC26: =Y26+AA26 -> 731645.15 | AD26: =AC26/$F26 -> 0.21616238 | AE26: 897336.84 | AF26: =AE26/F26 -> 0.26511549 | AG26: 0 | AH26: =AG26/$F26 -> 0 | AI26: 157315.82 | AJ26: =AI26/$F26 -> 0.04647849 | AK26: 132467.37 | AL26: =AK26/$F26 -> 0.03913709
D27: 46069 | E27: 一 | F27: =SUM(M27,S27,U27,W27,AC27,AE27,AG27,AI27,AK27) -> 3332137.9 | I27: 503145.18 | J27: =I27/$F27 -> 0.1509977 | K27: 662393.48 | L27: =K27/$F27 -> 0.19878933 | M27: =I27+K27 -> 1165538.7 | N27: =M27/$F27 -> 0.34978704 | O27: 163169.48 | P27: =O27/$F27 -> 0.048968405 | Q27: 126313.78 | R27: =Q27/$F27 -> 0.037907728 | S27: =O27+Q27 -> 289483.26 | T27: =S27/$F27 -> 0.086876133 | U27: 69890.04 | V27: =U27/$F27 -> 0.020974534 | W27: 18421.05 | X27: =W27/$F27 -> 0.0055282975 | Y27: 203293.37 | Z27: =Y27/$F27 -> 0.06100989 | AA27: 522877.47 | AB27: =AA27/$F27 -> 0.15691952 | AC27: =Y27+AA27 -> 726170.84 | AD27: =AC27/$F27 -> 0.21792941 | AE27: 768646.73 | AF27: =AE27/F27 -> 0.23067674 | AG27: 0 | AH27: =AG27/$F27 -> 0 | AI27: 159767.92 | AJ27: =AI27/$F27 -> 0.047947571 | AK27: 134219.44 | AL27: =AK27/$F27 -> 0.040280277
B28: =B21+7 -> 46078 | D28: 46070 | E28: 二 | F28: =SUM(M28,S28,U28,W28,AC28,AE28,AG28,AI28,AK28) -> 3579308.7 | G28: =SUM(F28:F34) -> 27936826 | I28: 528533.6 | J28: =I28/$F28 -> 0.1476636 | K28: 690449.46 | L28: =K28/$F28 -> 0.19290023 | M28: =I28+K28 -> 1218983.1 | N28: =M28/$F28 -> 0.34056382 | O28: 180479.16 | P28: =O28/$F28 -> 0.05042291 | Q28: 141948.74 | R28: =Q28/$F28 -> 0.039658144 | S28: =O28+Q28 -> 322427.9 | T28: =S28/$F28 -> 0.090081054 | U28: 72527.4 | V28: =U28/$F28 -> 0.020262963 | W28: 19638.3 | X28: =W28/$F28 -> 0.0054866181 | Y28: 210673.47 | Z28: =Y28/$F28 -> 0.058858703 | AA28: 558185.8 | AB28: =AA28/$F28 -> 0.15594793 | AC28: =Y28+AA28 -> 768859.27 | AD28: =AC28/$F28 -> 0.21480664 | AE28: 880245.02 | AF28: =AE28/F28 -> 0.24592598 | AG28: 0 | AH28: =AG28/$F28 -> 0 | AI28: 162564.69 | AJ28: =AI28/$F28 -> 0.045417901 | AK28: 134063.07 | AL28: =AK28/$F28 -> 0.037455017
D29: 46071 | E29: 三 | F29: =SUM(M29,S29,U29,W29,AC29,AE29,AG29,AI29,AK29) -> 3442485.4 | I29: 535449.12 | J29: =I29/$F29 -> 0.15554143 | K29: 684510.44 | L29: =K29/$F29 -> 0.19884193 | M29: =I29+K29 -> 1219959.6 | N29: =M29/F29 -> 0.35438336 | O29: 179086.75 | P29: =O29/$F29 -> 0.052022515 | Q29: 140138.88 | R29: =Q29/$F29 -> 0.040708634 | S29: =O29+Q29 -> 319225.63 | T29: =S29/F29 -> 0.092731149 | U29: 70699.23 | V29: =U29/F29 -> 0.020537263 | W29: 18907.95 | X29: =W29/$F29 -> 0.0054925287 | Y29: 211184.4 | Z29: =Y29/$F29 -> 0.061346491 | AA29: 525276.96 | AB29: =AA29/$F29 -> 0.15258655 | AC29: =Y29+AA29 -> 736461.36 | AD29: =AC29/$F29 -> 0.21393304 | AE29: 786978.13 | AF29: =AE29/F29 -> 0.22860754 | AG29: 0 | AH29: =AG29/$F29 -> 0 | AI29: 156238.44 | AJ29: =AI29/$F29 -> 0.04538536 | AK29: 134015.12 | AL29: =AK29/$F29 -> 0.038929757
D30: 46072 | E30: 四 | F30: =SUM(M30,S30,U30,W30,AC30,AE30,AG30,AI30,AK30) -> 3403767.2 | I30: 524967.61 | J30: =I30/$F30 -> 0.15423135 | K30: 661410.1 | L30: =K30/$F30 -> 0.19431708 | M30: =I30+K30 -> 1186377.7 | N30: =M30/$F30 -> 0.34854843 | O30: 173010.19 | P30: =O30/$F30 -> 0.050829031 | Q30: 139321.23 | R30: =Q30/$F30 -> 0.04093148 | S30: =O30+Q30 -> 312331.42 | T30: =S30/$F30 -> 0.091760512 | U30: 73066.86 | V30: =U30/$F30 -> 0.021466468 | W30: 19205.5 | X30: =W30/$F30 -> 0.0056424247 | Y30: 213341.66 | Z30: =Y30/$F30 -> 0.0626781 | AA30: 476496.08 | AB30: =AA30/$F30 -> 0.1399908 | AC30: =Y30+AA30 -> 689837.74 | AD30: =AC30/$F30 -> 0.2026689 | AE30: 820711.3 | AF30: =AE30/F30 -> 0.24111852 | AG30: 0 | AH30: =AG30/$F30 -> 0 | AI30: 161512.92 | AJ30: =AI30/$F30 -> 0.047451224 | AK30: 140723.75 | AL30: =AK30/$F30 -> 0.04134353
D31: 46073 | E31: 五 | F31: =SUM(M31,S31,U31,W31,AC31,AE31,AG31,AI31,AK31) -> 3391576.3 | I31: 483803.12 | J31: =I31/$F31 -> 0.14264846 | K31: 636714.06 | L31: =K31/$F31 -> 0.18773397 | M31: =I31+K31 -> 1120517.2 | N31: =M31/F31 -> 0.33038242 | O31: 152352.69 | P31: =O31/$F31 -> 0.044920909 | Q31: 122824.25 | R31: =Q31/$F31 -> 0.036214503 | S31: =O31+Q31 -> 275176.94 | T31: =S31/F31 -> 0.081135413 | U31: 67552.38 | V31: =U31/F31 -> 0.019917695 | W31: 16906.25 | X31: =W31/$F31 -> 0.0049847766 | Y31: 214987.99 | Z31: =Y31/$F31 -> 0.063388812 | AA31: 545217.54 | AB31: =AA31/$F31 -> 0.16075639 | AC31: =Y31+AA31 -> 760205.53 | AD31: =AC31/$F31 -> 0.2241452 | AE31: 860814.57 | AF31: =AE31/F31 -> 0.25380959 | AG31: 0 | AH31: =AG31/$F31 -> 0 | AI31: 150174.38 | AJ31: =AI31/$F31 -> 0.044278639 | AK31: 140229.03 | AL31: =AK31/$F31 -> 0.041346271
D32: 46074 | E32: 六 | F32: =SUM(M32,S32,U32,W32,AC32,AE32,AG32,AI32,AK32) -> 3950864.4 | I32: 501496.6 | J32: =I32/$F32 -> 0.12693339 | K32: 824281.16 | L32: =K32/$F32 -> 0.20863312 | M32: =I32+K32 -> 1325777.8 | N32: =M32/$F32 -> 0.3355665 | O32: 157973.4 | P32: =O32/$F32 -> 0.039984515 | Q32: 135616.68 | R32: =Q32/$F32 -> 0.034325825 | S32: =O32+Q32 -> 293590.08 | T32: =S32/$F32 -> 0.07431034 | U32: 70609.32 | V32: =U32/$F32 -> 0.017871866 | W32: 23344.15 | X32: =W32/$F32 -> 0.0059086183 | Y32: 231905.45 | Z32: =Y32/$F32 -> 0.058697395 | AA32: 639615.1 | AB32: =AA32/$F32 -> 0.16189244 | AC32: =Y32+AA32 -> 871520.55 | AD32: =AC32/$F32 -> 0.22058984 | AE32: 1022516 | AF32: =AE32/F32 -> 0.25880817 | AG32: 0 | AH32: =AG32/$F32 -> 0 | AI32: 184582 | AJ32: =AI32/$F32 -> 0.046719396 | AK32: 158924.57 | AL32: =AK32/$F32 -> 0.040225265
D33: 46075 | E33: 日 | F33: =SUM(M33,S33,U33,W33,AC33,AE33,AG33,AI33,AK33) -> 5157259.6 | I33: 826577.67 | J33: =I33/$F33 -> 0.16027459 | K33: 984970.74 | L33: =K33/$F33 -> 0.19098723 | M33: =I33+K33 -> 1811548.4 | N33: =M33/F33 -> 0.35126182 | O33: 233227.33 | P33: =O33/$F33 -> 0.045223112 | Q33: 182014.1 | R33: =Q33/$F33 -> 0.035292794 | S33: =O33+Q33 -> 415241.43 | T33: =S33/F33 -> 0.080515906 | U33: 84245.67 | V33: =U33/F33 -> 0.016335356 | W33: 24074.5 | X33: =W33/$F33 -> 0.0046680799 | Y33: 247573.97 | Z33: =Y33/$F33 -> 0.048004946 | AA33: 712761.68 | AB33: =AA33/$F33 -> 0.13820551 | AC33: =Y33+AA33 -> 960335.65 | AD33: =AC33/$F33 -> 0.18621045 | AE33: 1550856.2 | AF33: =AE33/F33 -> 0.30071323 | AG33: 0 | AH33: =AG33/$F33 -> 0 | AI33: 163451.94 | AJ33: =AI33/$F33 -> 0.031693565 | AK33: 147505.79 | AL33: =AK33/$F33 -> 0.028601583
D34: 46076 | E34: 一 | F34: =SUM(M34,S34,U34,W34,AC34,AE34,AG34,AI34,AK34) -> 5011564.7 | I34: 811758.55 | J34: =I34/$F34 -> 0.16197707 | K34: 974914.22 | L34: =K34/$F34 -> 0.1945329 | M34: =I34+K34 -> 1786672.8 | N34: =M34/$F34 -> 0.35650997 | O34: 228662.22 | P34: =O34/$F34 -> 0.045626912 | Q34: 184962.98 | R34: =Q34/$F34 -> 0.036907232 | S34: =O34+Q34 -> 413625.2 | T34: =S34/$F34 -> 0.082534143 | U34: 76813.11 | V34: =U34/$F34 -> 0.015327171 | W34: 25778.65 | X34: =W34/$F34 -> 0.0051438326 | Y34: 282373.98 | Z34: =Y34/$F34 -> 0.056344474 | AA34: 684295.61 | AB34: =AA34/$F34 -> 0.13654331 | AC34: =Y34+AA34 -> 966669.59 | AD34: =AC34/$F34 -> 0.19288778 | AE34: 1416378.4 | AF34: =AE34/F34 -> 0.28262199 | AG34: 0 | AH34: =AG34/$F34 -> 0 | AI34: 169620.2 | AJ34: =AI34/$F34 -> 0.033845757 | AK34: 156006.79 | AL34: =AK34/$F34 -> 0.031129358
B35: =B28+7 -> 46085 | D35: 46077 | E35: 二 | F35: =SUM(M35,S35,U35,W35,AC35,AE35,AG35,AI35,AK35) -> 5238957.1 | G35: =SUM(F35:F41) -> 32338420 | I35: 815562.13 | J35: =I35/$F35 -> 0.15567261 | K35: 962970.78 | L35: =K35/$F35 -> 0.18380963 | M35: =I35+K35 -> 1778532.9 | N35: =M35/$F35 -> 0.33948224 | O35: 220466.87 | P35: =O35/$F35 -> 0.042082206 | Q35: 178349.54 | R35: =Q35/$F35 -> 0.034042947 | S35: =O35+Q35 -> 398816.41 | T35: =S35/$F35 -> 0.076125153 | U35: 185358.41 | V35: =U35/$F35 -> 0.035380784 | W35: 233726.34 | X35: =W35/$F35 -> 0.044613143 | Y35: 262050.32 | Z35: =Y35/$F35 -> 0.050019558 | AA35: 622985.41 | AB35: =AA35/$F35 -> 0.11891401 | AC35: =Y35+AA35 -> 885035.73 | AD35: =AC35/$F35 -> 0.16893357 | AE35: 1459250.8 | AF35: =AE35/F35 -> 0.27853842 | AG35: 0 | AH35: =AG35/$F35 -> 0 | AI35: 147496.78 | AJ35: =AI35/$F35 -> 0.028153844 | AK35: 150739.66 | AL35: =AK35/$F35 -> 0.028772837
D36: 46078 | E36: 三 | F36: =SUM(M36,S36,U36,W36,AC36,AE36,AG36,AI36,AK36) -> 4692647.5 | I36: 799279.1 | J36: =I36/$F36 -> 0.17032583 | K36: 843869.38 | L36: =K36/$F36 -> 0.17982799 | M36: =I36+K36 -> 1643148.5 | N36: =M36/F36 -> 0.35015383 | O36: 220683.48 | P36: =O36/$F36 -> 0.0470275 | Q36: 169504.31 | R36: =Q36/$F36 -> 0.036121254 | S36: =O36+Q36 -> 390187.79 | T36: =S36/F36 -> 0.083148753 | U36: 148052.14 | V36: =U36/F36 -> 0.031549811 | W36: 127954.87 | X36: =W36/$F36 -> 0.027267096 | Y36: 246268.26 | Z36: =Y36/$F36 -> 0.052479599 | AA36: 471199.58 | AB36: =AA36/$F36 -> 0.10041231 | AC36: =Y36+AA36 -> 717467.84 | AD36: =AC36/$F36 -> 0.15289191 | AE36: 1390723.7 | AF36: =AE36/F36 -> 0.29636227 | AG36: 0 | AH36: =AG36/$F36 -> 0 | AI36: 133540.96 | AJ36: =AI36/$F36 -> 0.028457488 | AK36: 141571.74 | AL36: =AK36/$F36 -> 0.030168842
D37: 46079 | E37: 四 | F37: =SUM(M37,S37,U37,W37,AC37,AE37,AG37,AI37,AK37) -> 3909306.8 | I37: 569381.54 | J37: =I37/$F37 -> 0.1456477 | K37: 745558.51 | L37: =K37/$F37 -> 0.19071374 | M37: =I37+K37 -> 1314940.1 | N37: =M37/$F37 -> 0.33636143 | O37: 181316.11 | P37: =O37/$F37 -> 0.046380629 | Q37: 144695.62 | R37: =Q37/$F37 -> 0.037013114 | S37: =O37+Q37 -> 326011.73 | T37: =S37/$F37 -> 0.083393743 | U37: 126261.09 | V37: =U37/$F37 -> 0.032297565 | W37: 117881.98 | X37: =W37/$F37 -> 0.03015419 | Y37: 228101.86 | Z37: =Y37/$F37 -> 0.058348416 | AA37: 422415.5 | AB37: =AA37/$F37 -> 0.10805381 | AC37: =Y37+AA37 -> 650517.36 | AD37: =AC37/$F37 -> 0.16640223 | AE37: 1113115.7 | AF37: =AE37/F37 -> 0.28473481 | AG37: 0 | AH37: =AG37/$F37 -> 0 | AI37: 126738.1 | AJ37: =AI37/$F37 -> 0.032419584 | AK37: 133840.79 | AL37: =AK37/$F37 -> 0.034236451
D38: 46080 | E38: 五 | F38: =SUM(M38,S38,U38,W38,AC38,AE38,AG38,AI38,AK38) -> 3610052.1 | I38: 545361.13 | J38: =I38/$F38 -> 0.15106739 | K38: 729491.75 | L38: =K38/$F38 -> 0.20207236 | M38: =I38+K38 -> 1274852.9 | N38: =M38/F38 -> 0.35313975 | O38: 174530.93 | P38: =O38/$F38 -> 0.048345821 | Q38: 138334.66 | R38: =Q38/$F38 -> 0.038319298 | S38: =O38+Q38 -> 312865.59 | T38: =S38/F38 -> 0.086665119 | U38: 105159.82 | V38: =U38/F38 -> 0.029129724 | W38: 54549.87 | X38: =W38/$F38 -> 0.015110549 | Y38: 204485.54 | Z38: =Y38/$F38 -> 0.056643377 | AA38: 465150.64 | AB38: =AA38/$F38 -> 0.12884873 | AC38: =Y38+AA38 -> 669636.18 | AD38: =AC38/$F38 -> 0.18549211 | AE38: 952067.01 | AF38: =AE38/F38 -> 0.26372667 | AG38: 0 | AH38: =AG38/$F38 -> 0 | AI38: 118704.2 | AJ38: =AI38/$F38 -> 0.032881576 | AK38: 122216.51 | AL38: =AK38/$F38 -> 0.033854501
D39: 46081 | E39: 六 | F39: =SUM(M39,S39,U39,W39,AC39,AE39,AG39,AI39,AK39) -> 3915929.6 | I39: 533505.22 | J39: =I39/$F39 -> 0.13623974 | K39: 882554.59 | L39: =K39/$F39 -> 0.2253755 | M39: =I39+K39 -> 1416059.8 | N39: =M39/$F39 -> 0.36161524 | O39: 166313.67 | P39: =O39/$F39 -> 0.042471057 | Q39: 136605.65 | R39: =Q39/$F39 -> 0.034884603 | S39: =O39+Q39 -> 302919.32 | T39: =S39/$F39 -> 0.07735566 | U39: 117254.27 | V39: =U39/$F39 -> 0.029942895 | W39: 65953.22 | X39: =W39/$F39 -> 0.016842289 | Y39: 222027.47 | Z39: =Y39/$F39 -> 0.056698534 | AA39: 550814.38 | AB39: =AA39/$F39 -> 0.14065993 | AC39: =Y39+AA39 -> 772841.85 | AD39: =AC39/$F39 -> 0.19735846 | AE39: 1029063.2 | AF39: =AE39/F39 -> 0.262789 | AG39: 0 | AH39: =AG39/$F39 -> 0 | AI39: 70403.2 | AJ39: =AI39/$F39 -> 0.017978668 | AK39: 141434.74 | AL39: =AK39/$F39 -> 0.036117794
C40: 三 | D40: 46082 | E40: 日 | F40: =SUM(M40,S40,U40,W40,AC40,AE40,AG40,AI40,AK40) -> 5447490.3 | H40: =SUM(F40:F69) -> 10971527 | I40: 880068.55 | J40: =I40/$F40 -> 0.16155486 | K40: 1018931.3 | L40: =K40/$F40 -> 0.18704601 | M40: =I40+K40 -> 1898999.9 | N40: =M40/F40 -> 0.34860087 | O40: 229722.55 | P40: =O40/$F40 -> 0.042170346 | Q40: 170790.6 | R40: =Q40/$F40 -> 0.031352163 | S40: =O40+Q40 -> 400513.15 | T40: =S40/F40 -> 0.073522509 | U40: 173999.36 | V40: =U40/F40 -> 0.031941197 | W40: 148402.32 | X40: =W40/$F40 -> 0.027242329 | Y40: 296339.4 | Z40: =Y40/$F40 -> 0.054399253 | AA40: 622748.12 | AB40: =AA40/$F40 -> 0.11431835 | AC40: =Y40+AA40 -> 919087.52 | AD40: =AC40/$F40 -> 0.16871761 | AE40: 1756824.7 | AF40: =AE40/F40 -> 0.32250167 | AG40: 0 | AH40: =AG40/$F40 -> 0 | AI40: 81107.36 | AJ40: =AI40/$F40 -> 0.014888941 | AK40: 68556 | AL40: =AK40/$F40 -> 0.012584878
D41: 46083 | E41: 一 | F41: =SUM(M41,S41,U41,W41,AC41,AE41,AG41,AI41,AK41) -> 5524036.8 | I41: 846957.8 | J41: =I41/$F41 -> 0.15332226 | K41: 1097915.2 | L41: =K41/$F41 -> 0.19875234 | M41: =I41+K41 -> 1944873 | N41: =M41/$F41 -> 0.3520746 | O41: 211406.03 | P41: =O41/$F41 -> 0.038270207 | Q41: 168666.66 | R41: =Q41/$F41 -> 0.030533225 | S41: =O41+Q41 -> 380072.69 | T41: =S41/$F41 -> 0.068803432 | U41: 130781.56 | V41: =U41/$F41 -> 0.023674998 | W41: 113746.98 | X41: =W41/$F41 -> 0.020591279 | Y41: 253080.66 | Z41: =Y41/$F41 -> 0.045814442 | AA41: 1069349 | AB41: =AA41/$F41 -> 0.19358108 | AC41: =Y41+AA41 -> 1322429.7 | AD41: =AC41/$F41 -> 0.23939552 | AE41: 1465668.8 | AF41: =AE41/F41 -> 0.26532568 | AG41: 0 | AH41: =AG41/$F41 -> 0 | AI41: 92529.92 | AJ41: =AI41/$F41 -> 0.016750417 | AK41: 73934.1 | AL41: =AK41/$F41 -> 0.013384071
...

Sheet （４）訂單數量構成比
B2: （4）訂單數量構成比
B3: 資料繳交日 | C3: 月份 | D3: 日期 | F3: 訂單量 | I3: 品類訂單量
I4: 18℃-飯糰 | O4: 18℃-壽司手卷 | U4: 4℃-飯糰 | W4: 4℃-壽司手卷 | Y4: 主食 | AE4: 便當 | AG4: 熱食義麵 | AI4: 季節調理麵 | AK4: 微波小吃
F5: 日 | G5: 週累積 | H5: 月累積 | I5: 一配 | K5: 二配 | M5: 合計 | O5: 一配 | Q5: 二配 | S5: 合計 | U5: 一配 | W5: 一配 | Y5: 一配 | AA5: 二配 | AC5: 合計 | AE5: 一配 | AG5: 一配 | AI5: 一配 | AK5: 一配
I6: 訂單數 | J6: 比例(%) | K6: 訂單數 | L6: 比例(%) | M6: 訂單數 | N6: 比例(%) | O6: 訂單數 | P6: 比例(%) | Q6: 訂單數 | R6: 比例(%) | S6: 訂單數 | T6: 比例(%) | U6: 訂單數 | V6: 比例(%) | W6: 訂單數 | X6: 比例(%) | Y6: 訂單數 | Z6: 比例(%) | AA6: 訂單數 | AB6: 比例(%) | AC6: 訂單數 | AD6: 比例(%) | AE6: 訂單數 | AF6: 比例(%) | AG6: 訂單數 | AH6: 比例(%) | AI6: 訂單數 | AJ6: 比例(%) | AK6: 訂單數 | AL6: 比例(%)
