Workbook

Sheet 生產管理報表(月)
A1: 大溪廠生產管理報表
A3: 月別 | B3: 2 | C3: 工廠 | D3: 大溪廠
A4: （１）收支狀況 | E4: ※單位：千元 | G4: （２）ＫＰＩ達成進度
A5: 項目 | B5: 當月 | C5: 前月 | D5: 差異 | E5: 累計 | G5: 項目 | H5: KPI | I5: 當月 | J5: 前月 | K5: 累計 | L5: ※補充
A6: 業績金額 | B6: ='（１）收支狀況'!H10/1000 -> 41250.45 | C6: 146299.94 | D6: =B6-C6 -> -105049.49 | G6: 人時性(個/月均) | I6: ='（２）ＫＰＩ達成進度'!H7 -> 0 | J6: 458.38414 | L6: 個／MH
A7: 訂單數量 | B7: ='（１）收支狀況'!K10 -> 1326773 | C7: 4768701 | D7: =B7-C7 -> -3441928 | G7: 人時達成率(%/月均) | H7: 0.8 | I7: ='（２）ＫＰＩ達成進度'!K5 -> 0 | J7: 0.92118999 | L7: 達成率
A8: 材料費 | B8: 93253 | C8: 93253 | D8: =B8-C8 -> 0 | G8: 半成品-報廢(%) | H8: 0.0025 | I8: ='（２）ＫＰＩ達成進度'!N5 -> 0 | J8: 0.0024135432 | L8: 報廢率
A9: 材料費率 | B9: 0.655 | C9: 0.655 | D9: =B9-C9 -> 0 | G9: 半成品-超用(%) | H9: 0.004 | I9: ='（２）ＫＰＩ達成進度'!Q10 -> 0.0054871638 | J9: 0.0055994433 | L9: 超用率
A10: 勞務成本 | B10: 22378 | C10: 22378 | D10: =B10-C10 -> 0 | G10: 固定產線-導入率(%) | H10: 0.8 | I10: ='（２）ＫＰＩ達成進度'!T5 -> 0 | J10: 0.9 | L10: 導入率
A11: 勞務費率 | B11: 0.157 | C11: 0.157 | D11: =B11-C11 -> 0 | G11: 教育訓練-實施率(%) | H11: 1 | I11: ='（２）ＫＰＩ達成進度'!W5 -> 0 | J11: 0.057692308 | L11: 實施率
A13: （３）業績構成比 | E13: ※單位：千元 | G13: （４）訂單數量構成比 | K13: ※單位：個
B14: 當月 | C14: 比例 | D14: 前月 | E14: 差異 | H14: 當月 | I14: 比例 | J14: 前月 | K14: 差異
A15: 18℃-飯糰(061,063) | B15: =SUM('（３）業績構成比'!M9:M39)/1000 -> 18763.538 | C15: =IFERROR(B15/$B$6,"") -> 0.45486868 | D15: 0.36139567 | E15: =IFERROR(C15-D15,"") -> 0.093473003 | G15: 18℃-飯糰(061,063) | H15: =SUM('（４）訂單數量構成比'!M9:M39) -> 992979 | I15: =IFERROR(H15/$B$7,"") -> 0.74841665 | J15: 0.58577126 | K15: =IFERROR(I15-J15,"") -> 0.16264539
A16: 18℃-壽司手卷(071,072,075,076) | B16: =SUM('（３）業績構成比'!S9:S39)/1000 -> 3713.1687 | C16: =IFERROR(B16/$B$6,"") -> 0.090015229 | D16: 0.069633574 | E16: =IFERROR(C16-D16,"") -> 0.020381655 | G16: 18℃-壽司手卷(071,072,075,076) | H16: =SUM('（４）訂單數量構成比'!S9:S39) -> 142661 | I16: =IFERROR(H16/$B$7,"") -> 0.1075248 | J16: 0.081693946 | K16: =IFERROR(I16-J16,"") -> 0.025830853
A17: 4℃-飯糰(065) | B17: =SUM('（３）業績構成比'!U9:U39)/1000 -> 1077.9846 | C17: =IFERROR(B17/$B$6,"") -> 0.026132674 | D17: 0.022453222 | E17: =IFERROR(C17-D17,"") -> 0.0036794518 | G17: 4℃-飯糰(065) | H17: =SUM('（４）訂單數量構成比'!U9:U39) -> 37692 | I17: =IFERROR(H17/$B$7,"") -> 0.028408778 | J17: 0.024966128 | K17: =IFERROR(I17-J17,"") -> 0.0034426502
A18: 4℃-壽司手卷(077) | B18: =SUM('（３）業績構成比'!W9:W39)/1000 -> 346.9433 | C18: =IFERROR(B18/$B$6,"") -> 0.0084106548 | D18: 0.008585039 | E18: =IFERROR(C18-D18,"") -> -0.00017438415 | G18: 4℃-壽司手卷(077) | H18: =SUM('（４）訂單數量構成比'!W9:W39) -> 12826 | I18: =IFERROR(H18/$B$7,"") -> 0.0096670644 | J18: 0.0097963785 | K18: =IFERROR(I18-J18,"") -> -0.00012931414
A19: 主食(091,092,093,094,095) | B19: =SUM('（３）業績構成比'!AC9:AC39)/1000 -> 8718.0558 | C19: =IFERROR(B19/$B$6,"") -> 0.2113445 | D19: 0.16215294 | E19: =IFERROR(C19-D19,"") -> 0.049191558 | G19: 主食(091,092,093,094,095) | H19: =SUM('（４）訂單數量構成比'!AC9:AC39) -> 157522 | I19: =IFERROR(H19/$B$7,"") -> 0.11872566 | J19: 0.089953008 | K19: =IFERROR(I19-J19,"") -> 0.028772652
A20: 便當(083) | B20: =SUM('（３）業績構成比'!AE9:AE39)/1000 -> 15225.377 | C20: =IFERROR(B20/$B$6,"") -> 0.36909602 | D20: 0.27057088 | E20: =IFERROR(C20-D20,"") -> 0.098525142 | G20: 便當(083) | H20: =SUM('（４）訂單數量構成比'!AE9:AE39) -> 252125 | I20: =IFERROR(H20/$B$7,"") -> 0.19002874 | J20: 0.13708178 | K20: =IFERROR(I20-J20,"") -> 0.052946963
A21: 熱食義麵(122,123,124,126) | B21: =SUM('（３）業績構成比'!AG9:AG39)/1000 -> 1002.4635 | C21: =IFERROR(B21/$B$6,"") -> 0.02430188 | D21: 0.029234371 | E21: =IFERROR(C21-D21,"") -> -0.0049324909 | G21: 熱食義麵(122,123,124,126) | H21: =SUM('（４）訂單數量構成比'!AG9:AG39) -> 17495 | I21: =IFERROR(H21/$B$7,"") -> 0.013186129 | J21: 0.015652481 | K21: =IFERROR(I21-J21,"") -> -0.0024663516
A22: 季節調理麵(111,112) | B22: =SUM('（３）業績構成比'!AI9:AI39)/1000 -> 2484.7272 | C22: =IFERROR(B22/$B$6,"") -> 0.060235154 | D22: 0.040564166 | E22: =IFERROR(C22-D22,"") -> 0.019670988 | G22: 季節調理麵(111,112) | H22: =SUM('（４）訂單數量構成比'!AI9:AI39) -> 44725 | I22: =IFERROR(H22/$B$7,"") -> 0.03370961 | J22: 0.022004735 | K22: =IFERROR(I22-J22,"") -> 0.011704875
A23: 微波小吃(153,154,155) | B23: =SUM('（３）業績構成比'!AK9:AK39)/1000 -> 2034.6142 | C23: =IFERROR(B23/$B$6,"") -> 0.049323442 | D23: 0.035410133 | E23: =IFERROR(C23-D23,"") -> 0.013913309 | G23: 微波小吃(153,154,155) | H23: =SUM('（４）訂單數量構成比'!AK9:AK39) -> 61028 | I23: =IFERROR(H23/$B$7,"") -> 0.045997318 | J23: 0.033080287 | K23: =IFERROR(I23-J23,"") -> 0.012917031
C24: =SUM(C15:C23) -> 1.2937282 | D24: =SUM(D15:D23) -> 1 | I24: =SUM(I15:I23) -> 1.2956647 | J24: =SUM(J15:J23) -> 1
A26: （５）品群別人時生產性
A27: 品群 | B27: 當月 | C27: 前月 | D27: 差異 | E27: 累計
A28: 18℃-飯A15:A23糰(061,063) | B28: ='（５-1）品群別人時生產性(18℃-飯糰)'!C1 -> 774.4368 | C28: 768.96509 | D28: =B28-C28 -> 5.4717158
A29: 18℃-壽司手卷(071,072,075,076) | B29: ='（５-2）品群別人時生產性(18℃-壽司手卷)'!C1 -> 308.28366 | C29: 280.52358 | D29: =B29-C29 -> 27.760082
A30: 4℃-飯糰(065) | B30: ='（５-3）品群別人時生產性(4℃-飯糰)'!C1 -> 258.45296 | C30: 258.56167 | D30: =B30-C30 -> -0.10871068
A31: 4℃-壽司手卷(077) | B31: ='（５-4）品群別人時生產性(4℃-壽司手卷)'!C1 -> 493.01674 | C31: 486.07171 | D31: =B31-C31 -> 6.9450363
A32: 主食(091,092,093,094,095) | B32: ='（５-5）品群別人時生產性(微波主食) '!C1 -> 81.884985 | C32: 68.891235 | D32: =B32-C32 -> 12.993749
A33: 便當(083) | B33: ='（５-6）品群別人時生產性(便當)'!C1 -> 77.80588 | C33: 78.306367 | D33: =B33-C33 -> -0.50048728
A34: 熱食義麵(122,123,124,126) | B34: ='（５-7）品群別人時生產性(熱食義麵) '!C1 -> 72.928814 | C34: 76.250133 | D34: =B34-C34 -> -3.3213185
A35: 季節調理麵(111,112) | B35: ='（５-8）品群別人時生產性(季節調理麵) '!C1 -> 106.79855 | C35: 110.8083 | D35: =B35-C35 -> -4.0097506
A36: 微波小吃(153,154,155) | B36: ='（５-9）品群別人時生產性(微波小吃)'!C1 -> 76.29523 | C36: 76.123665 | D36: =B36-C36 -> 0.17156459

Sheet 生產管理報表(週) 
A1: 大溪廠生產管理報表
A3: 月別 | B3: 2 | C3: 週別 | D3: W1 | E3: 工廠 | F3: 大溪廠
A4: （１）收支狀況 | E4: ※單位：千元 | G4: （２）ＫＰＩ達成進度
A5: 項目 | B5: 當週 | C5: 前週 | D5: 差異 | E5: 累計 | G5: 項目 | H5: KPI | I5: 當週 | J5: 前週 | K5: 累計 | L5: ※補充
A6: 業績金額 | B6: ='（１）收支狀況'!G12/1000 -> 31225.639 | C6: 31759.62 | D6: =B6-C6 -> -533.98057 | E6: ='（１）收支狀況'!H10:H10/1000 -> 41250.45 | G6: 人時性(個/月均) | I6: ='（２）ＫＰＩ達成進度'!G12 -> 471.89204 | J6: 471.15538 | K6: ='（２）ＫＰＩ達成進度'!H10 -> 470.87246 | L6: 個／MH
A7: 訂單數量 | B7: ='（１）收支狀況'!J12 -> 1008252 | C7: 1022206 | D7: =B7-C7 -> -13954 | E7: ='（１）收支狀況'!K10:K10 -> 1326773 | G7: 人時達成率(%/月均) | H7: 0.8 | I7: ='（２）ＫＰＩ達成進度'!J12 -> 0.94833609 | J7: 0.94685567 | K7: ='（２）ＫＰＩ達成進度'!K10 -> 0.94628709 | L7: 達成率
A8: 材料費 | B8: ='（１）收支狀況'!M12/1000 -> 20602.212 | C8: 20915.97 | D8: =B8-C8 -> -313.75746 | E8: ='（１）收支狀況'!N10:N10/1000 -> 27233.058 | G8: 半成品-報廢(%) | H8: 0.0025 | I8: ='（２）ＫＰＩ達成進度'!M12 -> 0.0024053838 | J8: 0.0024091778 | K8: ='（２）ＫＰＩ達成進度'!N10 -> 0.0024070642 | L8: 報廢率
A9: 材料費率 | B9: ='（１）收支狀況'!P12 -> 0.65978512 | C9: 0.65857116 | D9: =B9-C9 -> 0.0012139622 | E9: ='（１）收支狀況'!Q10 -> 0.66018814 | G9: 半成品-超用(%) | H9: 0.004 | I9: ='（２）ＫＰＩ達成進度'!P12 -> 0.0054866418 | J9: 0.0054843793 | K9: ='（２）ＫＰＩ達成進度'!Q10 -> 0.0054871638 | L9: 超用率
A10: 勞務成本 | B10: ='（１）收支狀況'!S12/1000 -> 5456.6247 | C10: 5357.7818 | D10: =B10-C10 -> 98.842906 | E10: ='（１）收支狀況'!T10/1000 -> 9280.6824 | G10: 固定產線-導入率(%) | H10: 0.8 | I10: ='（２）ＫＰＩ達成進度'!S12 -> 0.9 | J10: 0.9 | K10: ='（２）ＫＰＩ達成進度'!T10 -> 0.9 | L10: 導入率
A11: 勞務費率 | B11: ='（１）收支狀況'!V12 -> 0.17474821 | C11: 0.16869792 | D11: =B11-C11 -> 0.0060502946 | E11: ='（１）收支狀況'!W10 -> 0.22498378 | G11: 教育訓練-實施率(%) | H11: 1 | I11: =6/52*100% -> 0.11538462 | J11: 0.096153846 | K11: ='（２）ＫＰＩ達成進度'!W10 -> 0.11111111 | L11: 實施率
A13: （３）業績構成比 | E13: ※單位：千元 | G13: （４）訂單數量構成比 | K13: ※單位：個
B14: 當週 | C14: 比例 | D14: 前週 | E14: 差異 | H14: 當週 | I14: 比例 | J14: 前週 | K14: 差異
A15: 18℃-飯糰(061,063) | B15: =SUM('（３）業績構成比'!M14:M20)/1000 -> 11011.932 | C15: =IFERROR(B15/$B$6,"") -> 0.35265674 | D15: 0.3529653 | E15: =IFERROR(C15-D15,"") -> -0.00030855504 | G15: 18℃-飯糰(061,063) | H15: =SUM('（４）訂單數量構成比'!M14:M20) -> 583255 | I15: =IFERROR(H15/$B$7,"") -> 0.57848137 | J15: 0.57889897 | K15: =IFERROR(I15-J15,"") -> -0.00041759776
A16: 18℃-壽司手卷(071,072,075,076) | B16: =SUM('（３）業績構成比'!S14:S20)/1000 -> 2222.3389 | C16: =IFERROR(B16/$B$6,"") -> 0.071170324 | D16: 0.067718274 | E16: =IFERROR(C16-D16,"") -> 0.0034520492 | G16: 18℃-壽司手卷(071,072,075,076) | H16: =SUM('（４）訂單數量構成比'!S14:S20) -> 85625 | I16: =IFERROR(H16/$B$7,"") -> 0.084924205 | J16: 0.080616823 | K16: =IFERROR(I16-J16,"") -> 0.0043073826
A17: 4℃-飯糰(065) | B17: =SUM('（３）業績構成比'!U14:U20)/1000 -> 603.18865 | C17: =IFERROR(B17/$B$6,"") -> 0.019317095 | D17: 0.021460824 | E17: =IFERROR(C17-D17,"") -> -0.0021437293 | G17: 4℃-飯糰(065) | H17: =SUM('（４）訂單數量構成比'!U14:U20) -> 20782 | I17: =IFERROR(H17/$B$7,"") -> 0.020611911 | J17: 0.023775051 | K17: =IFERROR(I17-J17,"") -> -0.0031631407
A18: 4℃-壽司手卷(077) | B18: =SUM('（３）業績構成比'!W14:W20)/1000 -> 193.05585 | C18: =IFERROR(B18/$B$6,"") -> 0.0061826068 | D18: 0.0069610294 | E18: =IFERROR(C18-D18,"") -> -0.00077842267 | G18: 4℃-壽司手卷(077) | H18: =SUM('（４）訂單數量構成比'!W14:W20) -> 7137 | I18: =IFERROR(H18/$B$7,"") -> 0.0070785875 | J18: 0.007995453 | K18: =IFERROR(I18-J18,"") -> -0.00091686548
A19: 主食(091,092,093,094,095) | B19: =SUM('（３）業績構成比'!AC14:AC20)/1000 -> 5132.0835 | C19: =IFERROR(B19/$B$6,"") -> 0.16435479 | D19: 0.16002217 | E19: =IFERROR(C19-D19,"") -> 0.0043326279 | G19: 主食(091,092,093,094,095) | H19: =SUM('（４）訂單數量構成比'!AC14:AC20) -> 92767 | I19: =IFERROR(H19/$B$7,"") -> 0.092007752 | J19: 0.089784251 | K19: =IFERROR(I19-J19,"") -> 0.0022235011
A20: 便當(083) | B20: =SUM('（３）業績構成比'!AE14:AE20)/1000 -> 8911.4947 | C20: =IFERROR(B20/$B$6,"") -> 0.2853903 | D20: 0.28416834 | E20: =IFERROR(C20-D20,"") -> 0.0012219604 | G20: 便當(083) | H20: =SUM('（４）訂單數量構成比'!AE14:AE20) -> 147599 | I20: =IFERROR(H20/$B$7,"") -> 0.14639098 | J20: 0.14615645 | K20: =IFERROR(I20-J20,"") -> 0.00023453175
A21: 熱食義麵(122,123,124,126) | B21: =SUM('（３）業績構成比'!AG14:AG20)/1000 -> 567.4419 | C21: =IFERROR(B21/$B$6,"") -> 0.018172307 | D21: 0.019355219 | E21: =IFERROR(C21-D21,"") -> -0.0011829122 | G21: 熱食義麵(122,123,124,126) | H21: =SUM('（４）訂單數量構成比'!AG14:AG20) -> 9903 | I21: =IFERROR(H21/$B$7,"") -> 0.0098219493 | J21: 0.010494949 | K21: =IFERROR(I21-J21,"") -> -0.00067299988
A22: 季節調理麵(111,112) | B22: =SUM('（３）業績構成比'!AI14:AI20)/1000 -> 1345.8874 | C22: =IFERROR(B22/$B$6,"") -> 0.043101997 | D22: 0.051543719 | E22: =IFERROR(C22-D22,"") -> -0.0084417226 | G22: 季節調理麵(111,112) | H22: =SUM('（４）訂單數量構成比'!AI14:AI20) -> 24629 | I22: =IFERROR(H22/$B$7,"") -> 0.024427425 | J22: 0.028274144 | K22: =IFERROR(I22-J22,"") -> -0.0038467195
A23: 微波小吃(153,154,155) | B23: =SUM('（３）業績構成比'!AK14:AK20)/1000 -> 1238.2162 | C23: =IFERROR(B23/$B$6,"") -> 0.03965383 | D23: 0.035805126 | E23: =IFERROR(C23-D23,"") -> 0.0038487043 | G23: 微波小吃(153,154,155) | H23: =SUM('（４）訂單數量構成比'!AK14:AK20) -> 36555 | I23: =IFERROR(H23/$B$7,"") -> 0.036255817 | J23: 0.034003909 | K23: =IFERROR(I23-J23,"") -> 0.0022519078
C24: =SUM(C15:C23) -> 1 | D24: =SUM(D15:D23) -> 1 | I24: =SUM(I15:I23) -> 1 | J24: =SUM(J15:J23) -> 1
A26: （５）品群別人時生產性
A27: 品群 | B27: 當週 | C27: 前週 | D27: 差異 | E27: 累計
A28: 18℃-飯糰(061,063) | B28: ='（５-1）品群別人時生產性(18℃-飯糰)'!L45 -> 774.4368 | C28: 771.63649 | D28: =B28-C28 -> 2.800313 | E28: ='（５-1）品群別人時生產性(18℃-飯糰)'!C1 -> 774.4368
A29: 18℃-壽司手卷(071,072,075,076) | B29: ='（５-2）品群別人時生產性(18℃-壽司手卷)'!L27 -> 308.28366 | C29: 307.88508 | D29: =B29-C29 -> 0.39857775 | E29: ='（５-2）品群別人時生產性(18℃-壽司手卷)'!C1 -> 308.28366
A30: 4℃-飯糰(065) | B30: ='（５-3）品群別人時生產性(4℃-飯糰)'!L27 -> 258.45296 | C30: 261.26621 | D30: =B30-C30 -> -2.8132512 | E30: ='（５-3）品群別人時生產性(4℃-飯糰)'!C1 -> 258.45296
A31: 4℃-壽司手卷(077) | B31: ='（５-4）品群別人時生產性(4℃-壽司手卷)'!L27 -> 493.01674 | C31: 492.02069 | D31: =B31-C31 -> 0.99605598 | E31: ='（５-4）品群別人時生產性(4℃-壽司手卷)'!C1 -> 493.01674
A32: 主食(091,092,093,094,095) | B32: ='（５-5）品群別人時生產性(微波主食) '!L27 -> 81.884985 | C32: 81.823352 | D32: =B32-C32 -> 0.061632292 | E32: ='（５-5）品群別人時生產性(微波主食) '!C1 -> 81.884985
A33: 便當(083) | B33: ='（５-6）品群別人時生產性(便當)'!L27 -> 77.80588 | C33: 77.7413 | D33: =B33-C33 -> 0.064579886 | E33: ='（５-6）品群別人時生產性(便當)'!C1 -> 77.80588
A34: 熱食義麵(122,123,124,126) | B34: ='（５-7）品群別人時生產性(熱食義麵) '!L27 -> 72.928814 | C34: 72.911661 | D34: =B34-C34 -> 0.017153397 | E34: ='（５-7）品群別人時生產性(熱食義麵) '!C1 -> 72.928814
A35: 季節調理麵(111,112) | B35: ='（５-8）品群別人時生產性(季節調理麵) '!L27 -> 106.79855 | C35: 106.72237 | D35: =B35-C35 -> 0.076184915 | E35: ='（５-8）品群別人時生產性(季節調理麵) '!C1 -> 106.79855
A36: 微波小吃(153,154,155) | B36: ='（５-9）品群別人時生產性(微波小吃)'!L27 -> 76.29523 | C36: 76.251803 | D36: =B36-C36 -> 0.043426892 | E36: ='（５-9）品群別人時生產性(微波小吃)'!C1 -> 76.29523

Sheet （１）收支狀況
B2: （１）收支狀況
B3: 資料繳交日 | C3: 月份 | D3: 日期 | F3: 營業額(元) | I3: 訂單數量(個) | L3: 材料費(元) | O3: 材料費率（材料費／營業額） | R3: 勞務成本（全廠人事成本） | U3: 勞務費率（勞務成本／營業額）
F4: 日 | G4: 週累積 | H4: 月累積 | I4: 日 | J4: 週累積 | K4: 月累積 | L4: 日 | M4: 週累積 | N4: 月累積 | O4: 日 | P4: 週累積 | Q4: 月累積 | R4: 日 | S4: 週累積 | T4: 月累積 | U4: 日 | V4: 週累積 | W4: 月累積
B5: 46057 | D5: 46049 | E5: 二 | F5: 4884312 | G5: =SUM(F5:F11) -> 31759620 | I5: 158031 | J5: =SUM(I5:I11) -> 1022206 | L5: 3270172.8 | M5: =SUM(L5:L11) -> 20915970 | O5: =L5/F5 -> 0.66952577 | P5: =M5/G5 -> 0.65857116 | R5: 768617.64 | S5: =SUM(R5:R11) -> 5357781.8 | U5: =R5/F5 -> 0.15736456 | V5: =S5/G5 -> 0.16869792
D6: =D5+1 -> 46050 | E6: 三 | F6: 4734075.2 | I6: 153374 | L6: 3056358 | O6: =L6/F6 -> 0.64560825 | R6: 765106.55 | U6: =R6/F6 -> 0.1616169
D7: =D6+1 -> 46051 | E7: 四 | F7: 4383675.5 | I7: 141591 | L7: 2886627.7 | O7: =L7/F7 -> 0.65849485 | R7: 749089.25 | U7: =R7/F7 -> 0.17088155
D8: =D7+1 -> 46052 | E8: 五 | F8: 3724978 | I8: 121636 | L8: 2422541.4 | O8: =L8/F8 -> 0.65035052 | R8: 710473.81 | U8: =R8/F8 -> 0.19073235
D9: =D8+1 -> 46053 | E9: 六 | F9: 4007768.4 | I9: 129053 | L9: 2649424.1 | O9: =L9/F9 -> 0.66107216 | R9: 749349.55 | U9: =R9/F9 -> 0.18697427
C10: 二 | D10: 46054 | E10: 日 | F10: 5128838 | H10: =SUM(F10:F37) -> 41250450 | I10: 162127 | K10: =SUM(I10:I37) -> 1326773 | L10: 3450280.4 | N10: =SUM(L10:L37) -> 27233058 | O10: =L10/F10 -> 0.67272165 | Q10: =N10/H10 -> 0.66018814 | R10: 816738.48 | T10: =SUM(R7:R37) -> 9280682.4 | U10: =R10/F10 -> 0.15924435 | W10: =T10/H10 -> 0.22498378
D11: =D10+1 -> 46055 | E11: 一 | F11: 4895972.9 | I11: 156394 | L11: 3180565.3 | O11: =L11/F11 -> 0.64962887 | R11: 798406.55 | U11: =R11/F11 -> 0.16307414
B12: =B5+7 -> 46064 | D12: =D11+1 -> 46056 | E12: 二 | F12: 4840106 | G12: =SUM(F12:F18) -> 31225639 | I12: 156238 | J12: =SUM(I12:I18) -> 1008252 | L12: 3163732.8 | M12: =SUM(L12:L18) -> 20602212 | O12: =L12/F12 -> 0.65364948 | P12: =M12/G12 -> 0.65978512 | R12: 815557.2 | S12: =SUM(R12:R18) -> 5456624.7 | U12: =R12/F12 -> 0.16849986 | V12: =S12/G12 -> 0.17474821
D13: =D12+1 -> 46057 | E13: 三 | F13: 4730102.7 | I13: 152389 | L13: 3110359.5 | O13: =L13/F13 -> 0.65756701 | R13: 776077.2 | U13: =R13/F13 -> 0.16407196
D14: =D13+1 -> 46058 | E14: 四 | F14: 4380960.5 | I14: 141990 | L14: 3009494.1 | O14: =L14/F14 -> 0.68694845 | R14: 800406.53 | U14: =R14/F14 -> 0.18270115
D15: =D14+1 -> 46059 | E15: 五 | F15: 3638268.6 | I15: 119260 | L15: 2380778 | O15: =L15/F15 -> 0.65437113 | R15: 739184.12 | U15: =R15/F15 -> 0.2031692
D16: =D15+1 -> 46060 | E16: 六 | F16: 3904128.8 | I16: 126462 | L16: 2545089.5 | O16: =L16/F16 -> 0.65189691 | R16: 753512.37 | U16: =R16/F16 -> 0.19300397
D17: =D16+1 -> 46061 | E17: 日 | F17: 4998806.5 | I17: 158901 | L17: 3270559.3 | O17: =L17/F17 -> 0.65426804 | R17: 796234.77 | U17: =R17/F17 -> 0.15928497
D18: =D17+1 -> 46062 | E18: 一 | F18: 4733266.2 | I18: 153012 | L18: 3122199 | O18: =L18/F18 -> 0.65962887 | R18: 775652.56 | U18: =R18/F18 -> 0.16387258
B19: =B12+7 -> 46071 | D19: =D18+1 -> 46063 | E19: 二 | G19: =SUM(F19:F25) -> 0 | J19: =SUM(I19:I25) -> 0 | M19: =SUM(L19:L25) -> 0 | O19: =L19/F19 -> #DIV/0! | P19: =M19/G19 -> #DIV/0! | S19: =SUM(R19:R25) -> 0 | U19: =R19/F19 -> #DIV/0! | V19: =S19/G19 -> #DIV/0!
D20: =D19+1 -> 46064 | E20: 三 | O20: =L20/F20 -> #DIV/0! | U20: =R20/F20 -> #DIV/0!
D21: =D20+1 -> 46065 | E21: 四 | O21: =L21/F21 -> #DIV/0! | U21: =R21/F21 -> #DIV/0!
D22: =D21+1 -> 46066 | E22: 五 | O22: =L22/F22 -> #DIV/0! | U22: =R22/F22 -> #DIV/0!
D23: =D22+1 -> 46067 | E23: 六 | O23: =L23/F23 -> #DIV/0! | U23: =R23/F23 -> #DIV/0!
D24: =D23+1 -> 46068 | E24: 日 | O24: =L24/F24 -> #DIV/0! | U24: =R24/F24 -> #DIV/0!
D25: =D24+1 -> 46069 | E25: 一 | O25: =L25/F25 -> #DIV/0! | U25: =R25/F25 -> #DIV/0!
B26: =B19+7 -> 46078 | D26: =D25+1 -> 46070 | E26: 二 | G26: =SUM(F26:F32) -> 0 | J26: =SUM(I26:I32) -> 0 | M26: =SUM(L26:L32) -> 0 | O26: =L26/F26 -> #DIV/0! | P26: =M26/G26 -> #DIV/0! | S26: =SUM(R26:R32) -> 0 | U26: =R26/F26 -> #DIV/0! | V26: =S26/G26 -> #DIV/0!
D27: =D26+1 -> 46071 | E27: 三 | O27: =L27/F27 -> #DIV/0! | U27: =R27/F27 -> #DIV/0!
D28: =D27+1 -> 46072 | E28: 四 | O28: =L28/F28 -> #DIV/0! | U28: =R28/F28 -> #DIV/0!
D29: =D28+1 -> 46073 | E29: 五 | O29: =L29/F29 -> #DIV/0! | U29: =R29/F29 -> #DIV/0!
D30: =D29+1 -> 46074 | E30: 六 | O30: =L30/F30 -> #DIV/0! | U30: =R30/F30 -> #DIV/0!
D31: =D30+1 -> 46075 | E31: 日 | O31: =L31/F31 -> #DIV/0! | U31: =R31/F31 -> #DIV/0!
D32: =D31+1 -> 46076 | E32: 一 | O32: =L32/F32 -> #DIV/0! | U32: =R32/F32 -> #DIV/0!
B33: =B26+7 -> 46085 | D33: =D32+1 -> 46077 | E33: 二 | G33: =SUM(F33:F39) -> 0 | J33: =SUM(I33:I39) -> 0 | M33: =SUM(L33:L39) -> 0 | O33: =L33/F33 -> #DIV/0! | P33: =M33/G33 -> #DIV/0! | S33: =SUM(R33:R39) -> 0 | U33: =R33/F33 -> #DIV/0! | V33: =S33/G33 -> #DIV/0!
D34: =D33+1 -> 46078 | E34: 三 | O34: =L34/F34 -> #DIV/0! | U34: =R34/F34 -> #DIV/0!
D35: =D34+1 -> 46079 | E35: 四 | O35: =L35/F35 -> #DIV/0! | U35: =R35/F35 -> #DIV/0!
D36: =D35+1 -> 46080 | E36: 五 | O36: =L36/F36 -> #DIV/0! | U36: =R36/F36 -> #DIV/0!
D37: =D36+1 -> 46081 | E37: 六 | H37: =SUM(F38:F67) -> 0 | K37: =SUM(I38:I67) -> 0 | O37: =L37/F37 -> #DIV/0! | U37: =R37/F37 -> #DIV/0!
D38: =D37+1 -> 46082 | E38: 日 | N38: =SUM(L38:L65) -> 0 | O38: =L38/F38 -> #DIV/0! | Q38: =N38/H37 -> #DIV/0! | T38: =SUM(R38:R65) -> 0 | U38: =R38/F38 -> #DIV/0! | W38: =T38/H38 -> #DIV/0!
D39: =D38+1 -> 46083 | E39: 一 | O39: =L39/F39 -> #DIV/0! | U39: =R39/F39 -> #DIV/0!
B40: =B33+7 -> 46092 | D40: =D39+1 -> 46084 | E40: 二 | G40: =SUM(F40:F46) -> 0 | J40: =SUM(I40:I46) -> 0 | M40: =SUM(L40:L46) -> 0 | O40: =L40/F40 -> #DIV/0! | P40: =M40/G40 -> #DIV/0! | S40: =SUM(R40:R46) -> 0 | U40: =R40/F40 -> #DIV/0! | V40: =S40/G40 -> #DIV/0!
D41: =D40+1 -> 46085 | E41: 三 | O41: =L41/F41 -> #DIV/0! | U41: =R41/F41 -> #DIV/0!
...

Sheet （２）ＫＰＩ達成進度
B1: 人時生產性基準值 | C1: 497.6
B2: （２）ＫＰＩ達成進度
B3: 資料繳交日 | C3: 月份 | D3: 日期 | F3: 人時生產性(個/人) | I3: 人時生產性達成率(%) | L3: 半成品報廢(%) | O3: 半成品超用(%) | R3: 固定產線-導入率(固定產線數/總產線數) | U3: 教育訓練-實施率(進度/計畫)
F4: 日 | G4: 週平均 | H4: 月平均 | I4: 日 | J4: 週平均 | K4: 月平均 | L4: 日 | M4: 週平均 | N4: 月平均 | O4: 日 | P4: 週平均 | Q4: 月平均 | R4: 日 | S4: 週平均 | T4: 月平均 | U4: 日 | V4: 週平均 | W4: 月平均
B5: 46057 | D5: 46049 | E5: 二 | F5: 464.44705 | G5: =AVERAGE(F5:F11) -> 471.15538 | I5: =F5/$C$1 -> 0.9333743 | J5: =AVERAGE(I5:I11) -> 0.94685567 | L5: 0.0024116968 | M5: =AVERAGE(L5:L11) -> 0.0024091778 | O5: 0.0054938914 | P5: =AVERAGE(O5:O11) -> 0.0054843793 | R5: 0.9 | S5: =AVERAGE(R5:R11) -> 0.9 | U5: =5/52*100% -> 0.096153846 | V5: =AVERAGE(U5:U11) -> 0.096153846
D6: =D5+1 -> 46050 | E6: 三 | F6: 464.47506 | I6: =F6/$C$1 -> 0.93343059 | L6: 0.00241014 | O6: 0.0054977047 | R6: 0.9 | U6: =5/52*100% -> 0.096153846
D7: =D6+1 -> 46051 | E7: 四 | F7: 463.28113 | I7: =F7/$C$1 -> 0.9310312 | L7: 0.0024038368 | O7: 0.0054877595 | R7: 0.9 | U7: =5/52*100% -> 0.096153846
D8: =D7+1 -> 46052 | E8: 五 | F8: 485.61792 | I8: =F8/$C$1 -> 0.97592025 | L8: 0.0024044941 | O8: 0.0054453132 | R8: 0.9 | U8: =5/52*100% -> 0.096153846
D9: =D8+1 -> 46053 | E9: 六 | F9: 485.65869 | I9: =F9/$C$1 -> 0.9760022 | L9: 0.0024081846 | O9: 0.0054880042 | R9: 0.9 | U9: =5/52*100% -> 0.096153846
C10: 二 | D10: =D9+1 -> 46054 | E10: 日 | F10: 467.59644 | H10: =AVERAGEIF(F10:F37,"<>0") -> 470.87246 | I10: =F10/$C$1 -> 0.93970345 | K10: =AVERAGEIF(I10:I37,"<>0") -> 0.94628709 | L10: 0.0024135408 | N10: =AVERAGEIF(L10:L37,"<>0") -> 0.0024070642 | O10: 0.0055021522 | Q10: =AVERAGEIF(O10:O37,"<>0") -> 0.0054871638 | R10: 0.9 | T10: =AVERAGEIF(R10:R37,"<>0") -> 0.9 | U10: =5/52*100% -> 0.096153846 | W10: =AVERAGEIF(U10:U37,"<>0") -> 0.11111111
D11: =D10+1 -> 46055 | E11: 一 | F11: 467.01138 | I11: =F11/$C$1 -> 0.9385277 | L11: 0.0024123511 | O11: 0.0054758296 | R11: 0.9 | U11: =5/52*100% -> 0.096153846
B12: =B5+7 -> 46064 | D12: =D11+1 -> 46056 | E12: 二 | F12: 467.06788 | G12: =AVERAGE(F12:F18) -> 471.89204 | I12: =F12/$C$1 -> 0.93864123 | J12: =AVERAGE(I12:I18) -> 0.94833609 | L12: 0.0024099596 | M12: =AVERAGE(L12:L18) -> 0.0024053838 | O12: 0.005456354 | P12: =AVERAGE(O12:O18) -> 0.0054866418 | R12: 0.9 | S12: =AVERAGE(R12:R18) -> 0.9 | U12: =6/52*100% -> 0.11538462 | V12: =AVERAGE(U12:U18) -> 0.11538462
D13: =D12+1 -> 46057 | E13: 三 | F13: 467.08348 | I13: =F13/$C$1 -> 0.93867259 | L13: 0.0024057726 | O13: 0.0054342785 | R13: 0.9 | U13: =6/52*100% -> 0.11538462
D14: =D13+1 -> 46058 | E14: 四 | F14: 464.03002 | I14: =F14/$C$1 -> 0.93253622 | L14: 0.0024042543 | O14: 0.0056361359 | R14: 0.9 | U14: =6/52*100% -> 0.11538462
D15: =D14+1 -> 46059 | E15: 五 | F15: 484.44025 | I15: =F15/$C$1 -> 0.97355356 | L15: 0.0024039703 | O15: 0.0056098775 | R15: 0.9 | U15: =6/52*100% -> 0.11538462
D16: =D15+1 -> 46060 | E16: 六 | F16: 488.96905 | I16: =F16/$C$1 -> 0.98265484 | L16: 0.0023935394 | O16: 0.0054016523 | R16: 0.9 | U16: =6/52*100% -> 0.11538462
D17: =D16+1 -> 46061 | E17: 日 | F17: 465.70359 | I17: =F17/$C$1 -> 0.9358995 | L17: 0.0024099821 | O17: 0.0054364217 | R17: 0.9 | U17: =6/52*100% -> 0.11538462
D18: =D17+1 -> 46062 | E18: 一 | F18: 465.95001 | I18: =F18/$C$1 -> 0.93639472 | L18: 0.0024102079 | O18: 0.005431773 | R18: 0.9 | U18: =6/52*100% -> 0.11538462
B19: =B12+7 -> 46071 | D19: =D18+1 -> 46063 | E19: 二 | G19: =AVERAGE(F19:F25) -> #DIV/0! | I19: =F19/$C$1 -> 0 | J19: =AVERAGE(I19:I25) -> 0 | M19: =AVERAGE(L19:L25) -> #DIV/0! | P19: =AVERAGE(O19:O25) -> #DIV/0! | S19: =AVERAGE(R19:R25) -> #DIV/0! | V19: =AVERAGE(U19:U25) -> #DIV/0!
D20: =D19+1 -> 46064 | E20: 三 | I20: =F20/$C$1 -> 0
D21: =D20+1 -> 46065 | E21: 四 | I21: =F21/$C$1 -> 0
D22: =D21+1 -> 46066 | E22: 五 | I22: =F22/$C$1 -> 0
D23: =D22+1 -> 46067 | E23: 六 | I23: =F23/$C$1 -> 0
D24: =D23+1 -> 46068 | E24: 日 | I24: =F24/$C$1 -> 0
D25: =D24+1 -> 46069 | E25: 一 | I25: =F25/$C$1 -> 0
B26: =B19+7 -> 46078 | D26: =D25+1 -> 46070 | E26: 二 | G26: =AVERAGE(F26:F32) -> #DIV/0! | I26: =F26/$C$1 -> 0 | J26: =AVERAGE(I26:I32) -> 0 | M26: =AVERAGE(L26:L32) -> #DIV/0! | P26: =AVERAGE(O26:O32) -> #DIV/0! | S26: =AVERAGE(R26:R32) -> #DIV/0! | V26: =AVERAGE(U26:U32) -> #DIV/0!
D27: =D26+1 -> 46071 | E27: 三 | I27: =F27/$C$1 -> 0
D28: =D27+1 -> 46072 | E28: 四 | I28: =F28/$C$1 -> 0
D29: =D28+1 -> 46073 | E29: 五 | I29: =F29/$C$1 -> 0
D30: =D29+1 -> 46074 | E30: 六 | I30: =F30/$C$1 -> 0
D31: =D30+1 -> 46075 | E31: 日 | I31: =F31/$C$1 -> 0
D32: =D31+1 -> 46076 | E32: 一 | I32: =F32/$C$1 -> 0
B33: =B26+7 -> 46085 | D33: =D32+1 -> 46077 | E33: 二 | G33: =AVERAGE(F33:F39) -> #DIV/0! | I33: =F33/$C$1 -> 0 | J33: =AVERAGE(I33:I39) -> 0 | M33: =AVERAGE(L33:L39) -> #DIV/0! | P33: =AVERAGE(O33:O39) -> #DIV/0! | S33: =AVERAGE(R33:R39) -> #DIV/0! | V33: =AVERAGE(U33:U39) -> #DIV/0!
D34: =D33+1 -> 46078 | E34: 三 | I34: =F34/$C$1 -> 0
D35: =D34+1 -> 46079 | E35: 四 | I35: =F35/$C$1 -> 0
D36: =D35+1 -> 46080 | E36: 五 | I36: =F36/$C$1 -> 0
D37: =D36+1 -> 46081 | E37: 六 | I37: =F37/$C$1 -> 0
D38: =D37+1 -> 46082 | E38: 日 | I38: =F38/$C$1 -> 0
D39: =D38+1 -> 46083 | E39: 一 | I39: =F39/$C$1 -> 0
B40: =B33+7 -> 46092 | D40: =D39+1 -> 46084 | E40: 二 | G40: =AVERAGE(F40:F46) -> #DIV/0! | I40: =F40/$C$1 -> 0 | J40: =AVERAGE(I40:I46) -> 0 | M40: =AVERAGE(L40:L46) -> #DIV/0! | P40: =AVERAGE(O40:O46) -> #DIV/0! | S40: =AVERAGE(R40:R46) -> #DIV/0! | V40: =AVERAGE(U40:U46) -> #DIV/0!
...

Sheet （３）業績構成比
B2: （3）業績構成比
B3: 資料繳交日 | C3: 月份 | D3: 日期 | F3: 營業額 | I3: 品類業績
I4: 18℃-飯糰 | O4: 18℃-壽司手卷 | U4: 4℃-飯糰 | W4: 4℃-壽司手卷 | Y4: 主食 | AE4: 便當 | AG4: 熱食義麵 | AI4: 季節調理麵 | AK4: 微波小吃
F5: 日 | G5: 週累積 | H5: 月累積 | I5: 一配 | K5: 二配 | M5: 合計 | O5: 一配 | Q5: 二配 | S5: 合計 | U5: 一配 | W5: 一配 | Y5: 一配 | AA5: 二配 | AC5: 合計 | AE5: 一配 | AG5: 一配 | AI5: 一配 | AK5: 一配
I6: 業績(元) | J6: 比例(%) | K6: 業績(元) | L6: 比例(%) | M6: 業績(元) | N6: 比例(%) | O6: 業績(元) | P6: 比例(%) | Q6: 業績(元) | R6: 比例(%) | S6: 業績(元) | T6: 比例(%) | U6: 業績(元) | V6: 比例(%) | W6: 業績(元) | X6: 比例(%) | Y6: 業績(元) | Z6: 比例(%) | AA6: 業績(元) | AB6: 比例(%) | AC6: 業績(元) | AD6: 比例(%) | AE6: 業績(元) | AF6: 比例(%) | AG6: 業績(元) | AH6: 比例(%) | AI6: 業績(元) | AJ6: 比例(%) | AK6: 業績(元) | AL6: 比例(%)
B7: 46057 | D7: 46049 | E7: 二 | F7: =SUM(M7,S7,U7,W7,AC7,AE7,AG7,AI7,AK7) -> 4884312 | G7: =SUM(F7:F13) -> 31759620 | I7: 853494.19 | J7: =I7/$F7 -> 0.17474195 | K7: 910330.83 | L7: =K7/$F7 -> 0.18637852 | M7: =I7+K7 -> 1763825 | N7: =M7/$F7 -> 0.36112046 | O7: 181062.83 | P7: =O7/$F7 -> 0.037070283 | Q7: 139548.3 | R7: =Q7/$F7 -> 0.028570718 | S7: =O7+Q7 -> 320611.13 | T7: =S7/$F7 -> 0.065641001 | U7: 106504.18 | V7: =U7/$F7 -> 0.02180536 | W7: 32784.6 | X7: =W7/$F7 -> 0.0067122247 | Y7: 199716.86 | Z7: =Y7/$F7 -> 0.040889456 | AA7: 564421.27 | AB7: =AA7/$F7 -> 0.11555799 | AC7: =Y7+AA7 -> 764138.13 | AD7: =AC7/$F7 -> 0.15644744 | AE7: 1395175.2 | AF7: =AE7/F7 -> 0.28564415 | AG7: 88700.4 | AH7: =AG7/$F7 -> 0.018160265 | AI7: 245515.77 | AJ7: =AI7/$F7 -> 0.050266193 | AK7: 167057.65 | AL7: =AK7/$F7 -> 0.034202903
D8: 46050 | E8: 三 | F8: =SUM(M8,S8,U8,W8,AC8,AE8,AG8,AI8,AK8) -> 4734075.2 | I8: 831988.56 | J8: =I8/$F8 -> 0.17574469 | K8: 862624.73 | L8: =K8/$F8 -> 0.1822161 | M8: =I8+K8 -> 1694613.3 | N8: =M8/F8 -> 0.35796079 | O8: 194239.53 | P8: =O8/$F8 -> 0.04103009 | Q8: 145026.12 | R8: =Q8/$F8 -> 0.03063452 | S8: =O8+Q8 -> 339265.65 | T8: =S8/F8 -> 0.07166461 | U8: 100287.54 | V8: =U8/F8 -> 0.021184188 | W8: 34407.6 | X8: =W8/$F8 -> 0.0072680722 | Y8: 190576.89 | Z8: =Y8/$F8 -> 0.040256414 | AA8: 541555.91 | AB8: =AA8/$F8 -> 0.11439529 | AC8: =Y8+AA8 -> 732132.8 | AD8: =AC8/$F8 -> 0.15465171 | AE8: 1316021 | AF8: =AE8/F8 -> 0.27798905 | AG8: 90992.4 | AH8: =AG8/$F8 -> 0.019220734 | AI8: 252653.35 | AJ8: =AI8/$F8 -> 0.053369104 | AK8: 173701.51 | AL8: =AK8/$F8 -> 0.036691751
D9: 46051 | E9: 四 | F9: =SUM(M9,S9,U9,W9,AC9,AE9,AG9,AI9,AK9) -> 4383675.5 | I9: 781634.2 | J9: =I9/$F9 -> 0.17830567 | K9: 765589.38 | L9: =K9/$F9 -> 0.17464554 | M9: =I9+K9 -> 1547223.6 | N9: =M9/$F9 -> 0.35295122 | O9: 187197.27 | P9: =O9/$F9 -> 0.042703269 | Q9: 149643.08 | R9: =Q9/$F9 -> 0.034136441 | S9: =O9+Q9 -> 336840.35 | T9: =S9/$F9 -> 0.07683971 | U9: 99056.27 | V9: =U9/$F9 -> 0.022596625 | W9: 33190.35 | X9: =W9/$F9 -> 0.007571352 | Y9: 179620.28 | Z9: =Y9/$F9 -> 0.040974813 | AA9: 446540.55 | AB9: =AA9/$F9 -> 0.10186442 | AC9: =Y9+AA9 -> 626160.83 | AD9: =AC9/$F9 -> 0.14283923 | AE9: 1223384.5 | AF9: =AE9/F9 -> 0.27907735 | AG9: 93628.2 | AH9: =AG9/$F9 -> 0.021358379 | AI9: 254604.91 | AJ9: =AI9/$F9 -> 0.058080237 | AK9: 169586.43 | AL9: =AK9/$F9 -> 0.0386859
D10: 46052 | E10: 五 | F10: =SUM(M10,S10,U10,W10,AC10,AE10,AG10,AI10,AK10) -> 3724978 | I10: 613209.19 | J10: =I10/$F10 -> 0.16462089 | K10: 738110.29 | L10: =K10/$F10 -> 0.19815158 | M10: =I10+K10 -> 1351319.5 | N10: =M10/F10 -> 0.36277247 | O10: 132952.63 | P10: =O10/$F10 -> 0.035692192 | Q10: 118971.19 | R10: =Q10/$F10 -> 0.031938763 | S10: =O10+Q10 -> 251923.82 | T10: =S10/F10 -> 0.067630955 | U10: 79282.88 | V10: =U10/F10 -> 0.02128412 | W10: 25886.85 | X10: =W10/$F10 -> 0.0069495309 | Y10: 174056.82 | Z10: =Y10/$F10 -> 0.046726939 | AA10: 463375.93 | AB10: =AA10/$F10 -> 0.12439696 | AC10: =Y10+AA10 -> 637432.75 | AD10: =AC10/$F10 -> 0.1711239 | AE10: 961597.17 | AF10: =AE10/F10 -> 0.25814841 | AG10: 72541.8 | AH10: =AG10/$F10 -> 0.019474424 | AI10: 209875.57 | AJ10: =AI10/$F10 -> 0.056342767 | AK10: 135117.7 | AL10: =AK10/$F10 -> 0.036273422
D11: 46053 | E11: 六 | F11: =SUM(M11,S11,U11,W11,AC11,AE11,AG11,AI11,AK11) -> 4007768.4 | I11: 579928.73 | J11: =I11/$F11 -> 0.14470116 | K11: 832680.89 | L11: =K11/$F11 -> 0.20776672 | M11: =I11+K11 -> 1412609.6 | N11: =M11/$F11 -> 0.35246788 | O11: 125493.32 | P11: =O11/$F11 -> 0.031312518 | Q11: 113295.76 | R11: =Q11/$F11 -> 0.028269039 | S11: =O11+Q11 -> 238789.08 | T11: =S11/$F11 -> 0.059581557 | U11: 86337.3 | V11: =U11/$F11 -> 0.021542487 | W11: 26563.1 | X11: =W11/$F11 -> 0.0066279029 | Y11: 193756.01 | Z11: =Y11/$F11 -> 0.048345111 | AA11: 524242.37 | AB11: =AA11/$F11 -> 0.13080655 | AC11: =Y11+AA11 -> 717998.38 | AD11: =AC11/$F11 -> 0.17915166 | AE11: 1049859.4 | AF11: =AE11/F11 -> 0.2619561 | AG11: 87038.7 | AH11: =AG11/$F11 -> 0.021717497 | AI11: 224467.83 | AJ11: =AI11/$F11 -> 0.056008184 | AK11: 164105.01 | AL11: =AK11/$F11 -> 0.04094673
C12: 二 | D12: 46054 | E12: 日 | F12: =SUM(M12,S12,U12,W12,AC12,AE12,AG12,AI12,AK12) -> 5128838 | H12: =SUM(F12:F39) -> 41250450 | I12: 822588.93 | J12: =I12/$F12 -> 0.16038505 | K12: 921629.34 | L12: =K12/$F12 -> 0.17969554 | M12: =I12+K12 -> 1744218.3 | N12: =M12/F12 -> 0.34008059 | O12: 196730.22 | P12: =O12/$F12 -> 0.038357659 | Q12: 140075.05 | R12: =Q12/$F12 -> 0.027311264 | S12: =O12+Q12 -> 336805.27 | T12: =S12/F12 -> 0.065668923 | U12: 111357.12 | V12: =U12/F12 -> 0.021711959 | W12: 34786.3 | X12: =W12/$F12 -> 0.0067824915 | Y12: 212944.27 | Z12: =Y12/$F12 -> 0.041519009 | AA12: 608050.05 | AB12: =AA12/$F12 -> 0.11855513 | AC12: =Y12+AA12 -> 820994.32 | AD12: =AC12/$F12 -> 0.16007414 | AE12: 1637542.5 | AF12: =AE12/F12 -> 0.31928139 | AG12: 85606.2 | AH12: =AG12/$F12 -> 0.016691149 | AI12: 207174.87 | AJ12: =AI12/$F12 -> 0.040394115 | AK12: 150353.13 | AL12: =AK12/$F12 -> 0.029315242
D13: 46055 | E13: 一 | F13: =SUM(M13,S13,U13,W13,AC13,AE13,AG13,AI13,AK13) -> 4895972.9 | I13: 795637.69 | J13: =I13/$F13 -> 0.1625086 | K13: 900596.82 | L13: =K13/$F13 -> 0.18394645 | M13: =I13+K13 -> 1696234.5 | N13: =M13/$F13 -> 0.34645504 | O13: 185830.13 | P13: =O13/$F13 -> 0.03795571 | Q13: 140641.23 | R13: =Q13/$F13 -> 0.0287259 | S13: =O13+Q13 -> 326471.36 | T13: =S13/$F13 -> 0.066681611 | U13: 98762.34 | V13: =U13/$F13 -> 0.020172158 | W13: 33460.85 | X13: =W13/$F13 -> 0.0068343618 | Y13: 212149.49 | Z13: =Y13/$F13 -> 0.043331426 | AA13: 571236.47 | AB13: =AA13/$F13 -> 0.11667476 | AC13: =Y13+AA13 -> 783385.96 | AD13: =AC13/$F13 -> 0.16000619 | AE13: 1441498.8 | AF13: =AE13/F13 -> 0.2944254 | AG13: 96206.7 | AH13: =AG13/$F13 -> 0.01965017 | AI13: 242716.64 | AJ13: =AI13/$F13 -> 0.049574751 | AK13: 177235.75 | AL13: =AK13/$F13 -> 0.036200313
B14: 46058 | D14: 46056 | E14: 二 | F14: =SUM(M14,S14,U14,W14,AC14,AE14,AG14,AI14,AK14) -> 4840106 | G14: =SUM(F14:F20) -> 31225639 | I14: 805654.11 | J14: =I14/$F14 -> 0.16645382 | K14: 903998.27 | L14: =K14/$F14 -> 0.18677241 | M14: =I14+K14 -> 1709652.4 | N14: =M14/$F14 -> 0.35322623 | O14: 189898.68 | P14: =O14/$F14 -> 0.039234405 | Q14: 148484.16 | R14: =Q14/$F14 -> 0.030677874 | S14: =O14+Q14 -> 338382.84 | T14: =S14/$F14 -> 0.069912279 | U14: 98046.38 | V14: =U14/$F14 -> 0.020257073 | W14: 34353.5 | X14: =W14/$F14 -> 0.0070976751 | Y14: 203577.22 | Z14: =Y14/$F14 -> 0.042060488 | AA14: 596197.07 | AB14: =AA14/$F14 -> 0.12317852 | AC14: =Y14+AA14 -> 799774.29 | AD14: =AC14/$F14 -> 0.165239 | AE14: 1378129.2 | AF14: =AE14/F14 -> 0.2847312 | AG14: 84975.9 | AH14: =AG14/$F14 -> 0.01755662 | AI14: 226898.62 | AJ14: =AI14/$F14 -> 0.046878853 | AK14: 169892.89 | AL14: =AK14/$F14 -> 0.035101068
D15: 46057 | E15: 三 | F15: =SUM(M15,S15,U15,W15,AC15,AE15,AG15,AI15,AK15) -> 4730102.7 | I15: 798741.87 | J15: =I15/$F15 -> 0.16886354 | K15: 860524.79 | L15: =K15/$F15 -> 0.18192518 | M15: =I15+K15 -> 1659266.7 | N15: =M15/F15 -> 0.35078872 | O15: 204275.72 | P15: =O15/$F15 -> 0.043186318 | Q15: 151374.66 | R15: =Q15/$F15 -> 0.032002404 | S15: =O15+Q15 -> 355650.38 | T15: =S15/F15 -> 0.075188722 | U15: 97169.36 | V15: =U15/F15 -> 0.020542759 | W15: 33379.7 | X15: =W15/$F15 -> 0.0070568658 | Y15: 197446.06 | Z15: =Y15/$F15 -> 0.041742447 | AA15: 555977.34 | AB15: =AA15/$F15 -> 0.11754023 | AC15: =Y15+AA15 -> 753423.4 | AD15: =AC15/$F15 -> 0.15928267 | AE15: 1302867.9 | AF15: =AE15/F15 -> 0.27544179 | AG15: 82683.9 | AH15: =AG15/$F15 -> 0.01748036 | AI15: 248743.8 | AJ15: =AI15/$F15 -> 0.052587399 | AK15: 196917.57 | AL15: =AK15/$F15 -> 0.041630717
D16: 46058 | E16: 四 | F16: =SUM(M16,S16,U16,W16,AC16,AE16,AG16,AI16,AK16) -> 4380960.5 | I16: 759713.44 | J16: =I16/$F16 -> 0.17341253 | K16: 781752.39 | L16: =K16/$F16 -> 0.17844315 | M16: =I16+K16 -> 1541465.8 | N16: =M16/$F16 -> 0.35185568 | O16: 200678.65 | P16: =O16/$F16 -> 0.045806998 | Q16: 150870.35 | R16: =Q16/$F16 -> 0.034437733 | S16: =O16+Q16 -> 351549 | T16: =S16/$F16 -> 0.080244731 | U16: 87760.73 | V16: =U16/$F16 -> 0.020032303 | W16: 32730.5 | X16: =W16/$F16 -> 0.0074710785 | Y16: 184672.81 | Z16: =Y16/$F16 -> 0.042153498 | AA16: 447847.86 | AB16: =AA16/$F16 -> 0.10222595 | AC16: =Y16+AA16 -> 632520.67 | AD16: =AC16/$F16 -> 0.14437945 | AE16: 1223663.9 | AF16: =AE16/F16 -> 0.27931407 | AG16: 85262.4 | AH16: =AG16/$F16 -> 0.019462033 | AI16: 229490.12 | AJ16: =AI16/$F16 -> 0.052383517 | AK16: 196517.38 | AL16: =AK16/$F16 -> 0.044857145
D17: 46059 | E17: 五 | F17: =SUM(M17,S17,U17,W17,AC17,AE17,AG17,AI17,AK17) -> 3638268.6 | I17: 589942.58 | J17: =I17/$F17 -> 0.16214926 | K17: 731719.39 | L17: =K17/$F17 -> 0.20111747 | M17: =I17+K17 -> 1321662 | N17: =M17/F17 -> 0.36326673 | O17: 135346.13 | P17: =O17/$F17 -> 0.037200697 | Q17: 121416.47 | R17: =Q17/$F17 -> 0.033372046 | S17: =O17+Q17 -> 256762.6 | T17: =S17/F17 -> 0.070572743 | U17: 69068.22 | V17: =U17/F17 -> 0.018983815 | W17: 21450.65 | X17: =W17/$F17 -> 0.00589584 | Y17: 169004.29 | Z17: =Y17/$F17 -> 0.046451845 | AA17: 468514.79 | AB17: =AA17/$F17 -> 0.12877411 | AC17: =Y17+AA17 -> 637519.08 | AD17: =AC17/$F17 -> 0.17522595 | AE17: 965034.65 | AF17: =AE17/F17 -> 0.26524557 | AG17: 62915.4 | AH17: =AG17/$F17 -> 0.017292676 | AI17: 150301.77 | AJ17: =AI17/$F17 -> 0.041311345 | AK17: 153554.31 | AL17: =AK17/$F17 -> 0.042205325
D18: 46060 | E18: 六 | F18: =SUM(M18,S18,U18,W18,AC18,AE18,AG18,AI18,AK18) -> 3904128.8 | I18: 550717.77 | J18: =I18/$F18 -> 0.14106035 | K18: 836143.76 | L18: =K18/$F18 -> 0.2141691 | M18: =I18+K18 -> 1386861.5 | N18: =M18/$F18 -> 0.35522945 | O18: 125007.97 | P18: =O18/$F18 -> 0.032019428 | Q18: 114762.48 | R18: =Q18/$F18 -> 0.029395157 | S18: =O18+Q18 -> 239770.45 | T18: =S18/$F18 -> 0.061414585 | U18: 73242.04 | V18: =U18/$F18 -> 0.01876015 | W18: 21071.95 | X18: =W18/$F18 -> 0.0053973501 | Y18: 192563.84 | Z18: =Y18/$F18 -> 0.049323127 | AA18: 512199.33 | AB18: =AA18/$F18 -> 0.13119427 | AC18: =Y18+AA18 -> 704763.17 | AD18: =AC18/$F18 -> 0.1805174 | AE18: 1046882.6 | AF18: =AE18/F18 -> 0.26814756 | AG18: 80391.9 | AH18: =AG18/$F18 -> 0.020591508 | AI18: 152212.68 | AJ18: =AI18/$F18 -> 0.038987617 | AK18: 198932.45 | AL18: =AK18/$F18 -> 0.050954377
D19: 46061 | E19: 日 | F19: =SUM(M19,S19,U19,W19,AC19,AE19,AG19,AI19,AK19) -> 4998806.5 | I19: 795904.07 | J19: =I19/$F19 -> 0.15921882 | K19: 919470.56 | L19: =K19/$F19 -> 0.18393802 | M19: =I19+K19 -> 1715374.6 | N19: =M19/F19 -> 0.34315684 | O19: 201984.05 | P19: =O19/$F19 -> 0.040406455 | Q19: 143487.92 | R19: =Q19/$F19 -> 0.028704436 | S19: =O19+Q19 -> 345471.97 | T19: =S19/F19 -> 0.069110891 | U19: 94255.65 | V19: =U19/F19 -> 0.018855631 | W19: 23722.85 | X19: =W19/$F19 -> 0.0047457028 | Y19: 216577.55 | Z19: =Y19/$F19 -> 0.043325852 | AA19: 605602.38 | AB19: =AA19/$F19 -> 0.12114939 | AC19: =Y19+AA19 -> 822179.93 | AD19: =AC19/$F19 -> 0.16447525 | AE19: 1586999.4 | AF19: =AE19/F19 -> 0.31747565 | AG19: 79990.8 | AH19: =AG19/$F19 -> 0.01600198 | AI19: 156005.14 | AJ19: =AI19/$F19 -> 0.031208477 | AK19: 174806.18 | AL19: =AK19/$F19 -> 0.034969583
D20: 46062 | E20: 一 | F20: =SUM(M20,S20,U20,W20,AC20,AE20,AG20,AI20,AK20) -> 4733266.2 | I20: 775970.3 | J20: =I20/$F20 -> 0.16393971 | K20: 901679.03 | L20: =K20/$F20 -> 0.19049827 | M20: =I20+K20 -> 1677649.3 | N20: =M20/$F20 -> 0.35443798 | O20: 191473.16 | P20: =O20/$F20 -> 0.04045265 | Q20: 143278.46 | R20: =Q20/$F20 -> 0.030270526 | S20: =O20+Q20 -> 334751.62 | T20: =S20/$F20 -> 0.070723176 | U20: 83646.27 | V20: =U20/$F20 -> 0.017671998 | W20: 26346.7 | X20: =W20/$F20 -> 0.0055662831 | Y20: 213852.59 | Z20: =Y20/$F20 -> 0.045180765 | AA20: 568050.39 | AB20: =AA20/$F20 -> 0.12001235 | AC20: =Y20+AA20 -> 781902.98 | AD20: =AC20/$F20 -> 0.16519311 | AE20: 1407917 | AF20: =AE20/F20 -> 0.29745148 | AG20: 91221.6 | AH20: =AG20/$F20 -> 0.019272442 | AI20: 182235.28 | AJ20: =AI20/$F20 -> 0.038500957 | AK20: 147595.41 | AL20: =AK20/$F20 -> 0.031182571
B21: =B14+7 -> 46065 | D21: 46063 | E21: 二 | G21: =SUM(F21:F27) -> 0 | J21: =I21/$F21 -> #DIV/0! | L21: =K21/$F21 -> #DIV/0! | M21: =I21+K21 -> 0 | N21: =M21/$F21 -> #DIV/0! | P21: =O21/$F21 -> #DIV/0! | R21: =Q21/$F21 -> #DIV/0! | S21: =O21+Q21 -> 0 | T21: =S21/$F21 -> #DIV/0! | V21: =U21/$F21 -> #DIV/0! | X21: =W21/$F21 -> #DIV/0! | Z21: =Y21/$F21 -> #DIV/0! | AB21: =AA21/$F21 -> #DIV/0! | AC21: =Y21+AA21 -> 0 | AD21: =AC21/$F21 -> #DIV/0! | AF21: =AE21/F21 -> #DIV/0! | AH21: =AG21/$F21 -> #DIV/0! | AJ21: =AI21/$F21 -> #DIV/0! | AL21: =AK21/$F21 -> #DIV/0!
D22: 46064 | E22: 三 | J22: =I22/$F22 -> #DIV/0! | L22: =K22/$F22 -> #DIV/0! | M22: =I22+K22 -> 0 | N22: =M22/F22 -> #DIV/0! | P22: =O22/$F22 -> #DIV/0! | R22: =Q22/$F22 -> #DIV/0! | S22: =O22+Q22 -> 0 | T22: =S22/F22 -> #DIV/0! | V22: =U22/F22 -> #DIV/0! | X22: =W22/$F22 -> #DIV/0! | Z22: =Y22/$F22 -> #DIV/0! | AB22: =AA22/$F22 -> #DIV/0! | AC22: =Y22+AA22 -> 0 | AD22: =AC22/$F22 -> #DIV/0! | AF22: =AE22/F22 -> #DIV/0! | AH22: =AG22/$F22 -> #DIV/0! | AJ22: =AI22/$F22 -> #DIV/0! | AL22: =AK22/$F22 -> #DIV/0!
D23: 46065 | E23: 四 | J23: =I23/$F23 -> #DIV/0! | L23: =K23/$F23 -> #DIV/0! | M23: =I23+K23 -> 0 | N23: =M23/$F23 -> #DIV/0! | P23: =O23/$F23 -> #DIV/0! | R23: =Q23/$F23 -> #DIV/0! | S23: =O23+Q23 -> 0 | T23: =S23/$F23 -> #DIV/0! | V23: =U23/$F23 -> #DIV/0! | X23: =W23/$F23 -> #DIV/0! | Z23: =Y23/$F23 -> #DIV/0! | AB23: =AA23/$F23 -> #DIV/0! | AC23: =Y23+AA23 -> 0 | AD23: =AC23/$F23 -> #DIV/0! | AF23: =AE23/F23 -> #DIV/0! | AH23: =AG23/$F23 -> #DIV/0! | AJ23: =AI23/$F23 -> #DIV/0! | AL23: =AK23/$F23 -> #DIV/0!
D24: 46066 | E24: 五 | J24: =I24/$F24 -> #DIV/0! | L24: =K24/$F24 -> #DIV/0! | M24: =I24+K24 -> 0 | N24: =M24/F24 -> #DIV/0! | P24: =O24/$F24 -> #DIV/0! | R24: =Q24/$F24 -> #DIV/0! | S24: =O24+Q24 -> 0 | T24: =S24/F24 -> #DIV/0! | V24: =U24/F24 -> #DIV/0! | X24: =W24/$F24 -> #DIV/0! | Z24: =Y24/$F24 -> #DIV/0! | AB24: =AA24/$F24 -> #DIV/0! | AC24: =Y24+AA24 -> 0 | AD24: =AC24/$F24 -> #DIV/0! | AF24: =AE24/F24 -> #DIV/0! | AH24: =AG24/$F24 -> #DIV/0! | AJ24: =AI24/$F24 -> #DIV/0! | AL24: =AK24/$F24 -> #DIV/0!
D25: 46067 | E25: 六 | J25: =I25/$F25 -> #DIV/0! | L25: =K25/$F25 -> #DIV/0! | M25: =I25+K25 -> 0 | N25: =M25/$F25 -> #DIV/0! | P25: =O25/$F25 -> #DIV/0! | R25: =Q25/$F25 -> #DIV/0! | S25: =O25+Q25 -> 0 | T25: =S25/$F25 -> #DIV/0! | V25: =U25/$F25 -> #DIV/0! | X25: =W25/$F25 -> #DIV/0! | Z25: =Y25/$F25 -> #DIV/0! | AB25: =AA25/$F25 -> #DIV/0! | AC25: =Y25+AA25 -> 0 | AD25: =AC25/$F25 -> #DIV/0! | AF25: =AE25/F25 -> #DIV/0! | AH25: =AG25/$F25 -> #DIV/0! | AJ25: =AI25/$F25 -> #DIV/0! | AL25: =AK25/$F25 -> #DIV/0!
D26: 46068 | E26: 日 | J26: =I26/$F26 -> #DIV/0! | L26: =K26/$F26 -> #DIV/0! | M26: =I26+K26 -> 0 | N26: =M26/F26 -> #DIV/0! | P26: =O26/$F26 -> #DIV/0! | R26: =Q26/$F26 -> #DIV/0! | S26: =O26+Q26 -> 0 | T26: =S26/F26 -> #DIV/0! | V26: =U26/F26 -> #DIV/0! | X26: =W26/$F26 -> #DIV/0! | Z26: =Y26/$F26 -> #DIV/0! | AB26: =AA26/$F26 -> #DIV/0! | AC26: =Y26+AA26 -> 0 | AD26: =AC26/$F26 -> #DIV/0! | AF26: =AE26/F26 -> #DIV/0! | AH26: =AG26/$F26 -> #DIV/0! | AJ26: =AI26/$F26 -> #DIV/0! | AL26: =AK26/$F26 -> #DIV/0!
D27: 46069 | E27: 一 | J27: =I27/$F27 -> #DIV/0! | L27: =K27/$F27 -> #DIV/0! | M27: =I27+K27 -> 0 | N27: =M27/$F27 -> #DIV/0! | P27: =O27/$F27 -> #DIV/0! | R27: =Q27/$F27 -> #DIV/0! | S27: =O27+Q27 -> 0 | T27: =S27/$F27 -> #DIV/0! | V27: =U27/$F27 -> #DIV/0! | X27: =W27/$F27 -> #DIV/0! | Z27: =Y27/$F27 -> #DIV/0! | AB27: =AA27/$F27 -> #DIV/0! | AC27: =Y27+AA27 -> 0 | AD27: =AC27/$F27 -> #DIV/0! | AF27: =AE27/F27 -> #DIV/0! | AH27: =AG27/$F27 -> #DIV/0! | AJ27: =AI27/$F27 -> #DIV/0! | AL27: =AK27/$F27 -> #DIV/0!
B28: =B21+7 -> 46072 | D28: 46070 | E28: 二 | G28: =SUM(F28:F34) -> 0 | J28: =I28/$F28 -> #DIV/0! | L28: =K28/$F28 -> #DIV/0! | M28: =I28+K28 -> 0 | N28: =M28/$F28 -> #DIV/0! | P28: =O28/$F28 -> #DIV/0! | R28: =Q28/$F28 -> #DIV/0! | S28: =O28+Q28 -> 0 | T28: =S28/$F28 -> #DIV/0! | V28: =U28/$F28 -> #DIV/0! | X28: =W28/$F28 -> #DIV/0! | Z28: =Y28/$F28 -> #DIV/0! | AB28: =AA28/$F28 -> #DIV/0! | AC28: =Y28+AA28 -> 0 | AD28: =AC28/$F28 -> #DIV/0! | AF28: =AE28/F28 -> #DIV/0! | AH28: =AG28/$F28 -> #DIV/0! | AJ28: =AI28/$F28 -> #DIV/0! | AL28: =AK28/$F28 -> #DIV/0!
D29: 46071 | E29: 三 | J29: =I29/$F29 -> #DIV/0! | L29: =K29/$F29 -> #DIV/0! | M29: =I29+K29 -> 0 | N29: =M29/F29 -> #DIV/0! | P29: =O29/$F29 -> #DIV/0! | R29: =Q29/$F29 -> #DIV/0! | S29: =O29+Q29 -> 0 | T29: =S29/F29 -> #DIV/0! | V29: =U29/F29 -> #DIV/0! | X29: =W29/$F29 -> #DIV/0! | Z29: =Y29/$F29 -> #DIV/0! | AB29: =AA29/$F29 -> #DIV/0! | AC29: =Y29+AA29 -> 0 | AD29: =AC29/$F29 -> #DIV/0! | AF29: =AE29/F29 -> #DIV/0! | AH29: =AG29/$F29 -> #DIV/0! | AJ29: =AI29/$F29 -> #DIV/0! | AL29: =AK29/$F29 -> #DIV/0!
D30: 46072 | E30: 四 | J30: =I30/$F30 -> #DIV/0! | L30: =K30/$F30 -> #DIV/0! | M30: =I30+K30 -> 0 | N30: =M30/$F30 -> #DIV/0! | P30: =O30/$F30 -> #DIV/0! | R30: =Q30/$F30 -> #DIV/0! | S30: =O30+Q30 -> 0 | T30: =S30/$F30 -> #DIV/0! | V30: =U30/$F30 -> #DIV/0! | X30: =W30/$F30 -> #DIV/0! | Z30: =Y30/$F30 -> #DIV/0! | AB30: =AA30/$F30 -> #DIV/0! | AC30: =Y30+AA30 -> 0 | AD30: =AC30/$F30 -> #DIV/0! | AF30: =AE30/F30 -> #DIV/0! | AH30: =AG30/$F30 -> #DIV/0! | AJ30: =AI30/$F30 -> #DIV/0! | AL30: =AK30/$F30 -> #DIV/0!
D31: 46073 | E31: 五 | J31: =I31/$F31 -> #DIV/0! | L31: =K31/$F31 -> #DIV/0! | M31: =I31+K31 -> 0 | N31: =M31/F31 -> #DIV/0! | P31: =O31/$F31 -> #DIV/0! | R31: =Q31/$F31 -> #DIV/0! | S31: =O31+Q31 -> 0 | T31: =S31/F31 -> #DIV/0! | V31: =U31/F31 -> #DIV/0! | X31: =W31/$F31 -> #DIV/0! | Z31: =Y31/$F31 -> #DIV/0! | AB31: =AA31/$F31 -> #DIV/0! | AC31: =Y31+AA31 -> 0 | AD31: =AC31/$F31 -> #DIV/0! | AF31: =AE31/F31 -> #DIV/0! | AH31: =AG31/$F31 -> #DIV/0! | AJ31: =AI31/$F31 -> #DIV/0! | AL31: =AK31/$F31 -> #DIV/0!
D32: 46074 | E32: 六 | J32: =I32/$F32 -> #DIV/0! | L32: =K32/$F32 -> #DIV/0! | M32: =I32+K32 -> 0 | N32: =M32/$F32 -> #DIV/0! | P32: =O32/$F32 -> #DIV/0! | R32: =Q32/$F32 -> #DIV/0! | S32: =O32+Q32 -> 0 | T32: =S32/$F32 -> #DIV/0! | V32: =U32/$F32 -> #DIV/0! | X32: =W32/$F32 -> #DIV/0! | Z32: =Y32/$F32 -> #DIV/0! | AB32: =AA32/$F32 -> #DIV/0! | AC32: =Y32+AA32 -> 0 | AD32: =AC32/$F32 -> #DIV/0! | AF32: =AE32/F32 -> #DIV/0! | AH32: =AG32/$F32 -> #DIV/0! | AJ32: =AI32/$F32 -> #DIV/0! | AL32: =AK32/$F32 -> #DIV/0!
D33: 46075 | E33: 日 | J33: =I33/$F33 -> #DIV/0! | L33: =K33/$F33 -> #DIV/0! | M33: =I33+K33 -> 0 | N33: =M33/F33 -> #DIV/0! | P33: =O33/$F33 -> #DIV/0! | R33: =Q33/$F33 -> #DIV/0! | S33: =O33+Q33 -> 0 | T33: =S33/F33 -> #DIV/0! | V33: =U33/F33 -> #DIV/0! | X33: =W33/$F33 -> #DIV/0! | Z33: =Y33/$F33 -> #DIV/0! | AB33: =AA33/$F33 -> #DIV/0! | AC33: =Y33+AA33 -> 0 | AD33: =AC33/$F33 -> #DIV/0! | AF33: =AE33/F33 -> #DIV/0! | AH33: =AG33/$F33 -> #DIV/0! | AJ33: =AI33/$F33 -> #DIV/0! | AL33: =AK33/$F33 -> #DIV/0!
D34: 46076 | E34: 一 | J34: =I34/$F34 -> #DIV/0! | L34: =K34/$F34 -> #DIV/0! | M34: =I34+K34 -> 0 | N34: =M34/$F34 -> #DIV/0! | P34: =O34/$F34 -> #DIV/0! | R34: =Q34/$F34 -> #DIV/0! | S34: =O34+Q34 -> 0 | T34: =S34/$F34 -> #DIV/0! | V34: =U34/$F34 -> #DIV/0! | X34: =W34/$F34 -> #DIV/0! | Z34: =Y34/$F34 -> #DIV/0! | AB34: =AA34/$F34 -> #DIV/0! | AC34: =Y34+AA34 -> 0 | AD34: =AC34/$F34 -> #DIV/0! | AF34: =AE34/F34 -> #DIV/0! | AH34: =AG34/$F34 -> #DIV/0! | AJ34: =AI34/$F34 -> #DIV/0! | AL34: =AK34/$F34 -> #DIV/0!
B35: =B28+7 -> 46079 | D35: 46077 | E35: 二 | G35: =SUM(F35:F41) -> 0 | J35: =I35/$F35 -> #DIV/0! | L35: =K35/$F35 -> #DIV/0! | M35: =I35+K35 -> 0 | N35: =M35/$F35 -> #DIV/0! | P35: =O35/$F35 -> #DIV/0! | R35: =Q35/$F35 -> #DIV/0! | S35: =O35+Q35 -> 0 | T35: =S35/$F35 -> #DIV/0! | V35: =U35/$F35 -> #DIV/0! | X35: =W35/$F35 -> #DIV/0! | Z35: =Y35/$F35 -> #DIV/0! | AB35: =AA35/$F35 -> #DIV/0! | AC35: =Y35+AA35 -> 0 | AD35: =AC35/$F35 -> #DIV/0! | AF35: =AE35/F35 -> #DIV/0! | AH35: =AG35/$F35 -> #DIV/0! | AJ35: =AI35/$F35 -> #DIV/0! | AL35: =AK35/$F35 -> #DIV/0!
D36: 46078 | E36: 三 | J36: =I36/$F36 -> #DIV/0! | L36: =K36/$F36 -> #DIV/0! | M36: =I36+K36 -> 0 | N36: =M36/F36 -> #DIV/0! | P36: =O36/$F36 -> #DIV/0! | R36: =Q36/$F36 -> #DIV/0! | S36: =O36+Q36 -> 0 | T36: =S36/F36 -> #DIV/0! | V36: =U36/F36 -> #DIV/0! | X36: =W36/$F36 -> #DIV/0! | Z36: =Y36/$F36 -> #DIV/0! | AB36: =AA36/$F36 -> #DIV/0! | AC36: =Y36+AA36 -> 0 | AD36: =AC36/$F36 -> #DIV/0! | AF36: =AE36/F36 -> #DIV/0! | AH36: =AG36/$F36 -> #DIV/0! | AJ36: =AI36/$F36 -> #DIV/0! | AL36: =AK36/$F36 -> #DIV/0!
D37: 46079 | E37: 四 | J37: =I37/$F37 -> #DIV/0! | L37: =K37/$F37 -> #DIV/0! | M37: =I37+K37 -> 0 | N37: =M37/$F37 -> #DIV/0! | P37: =O37/$F37 -> #DIV/0! | R37: =Q37/$F37 -> #DIV/0! | S37: =O37+Q37 -> 0 | T37: =S37/$F37 -> #DIV/0! | V37: =U37/$F37 -> #DIV/0! | X37: =W37/$F37 -> #DIV/0! | Z37: =Y37/$F37 -> #DIV/0! | AB37: =AA37/$F37 -> #DIV/0! | AC37: =Y37+AA37 -> 0 | AD37: =AC37/$F37 -> #DIV/0! | AF37: =AE37/F37 -> #DIV/0! | AH37: =AG37/$F37 -> #DIV/0! | AJ37: =AI37/$F37 -> #DIV/0! | AL37: =AK37/$F37 -> #DIV/0!
D38: 46080 | E38: 五 | J38: =I38/$F38 -> #DIV/0! | L38: =K38/$F38 -> #DIV/0! | M38: =I38+K38 -> 0 | N38: =M38/F38 -> #DIV/0! | P38: =O38/$F38 -> #DIV/0! | R38: =Q38/$F38 -> #DIV/0! | S38: =O38+Q38 -> 0 | T38: =S38/F38 -> #DIV/0! | V38: =U38/F38 -> #DIV/0! | X38: =W38/$F38 -> #DIV/0! | Z38: =Y38/$F38 -> #DIV/0! | AB38: =AA38/$F38 -> #DIV/0! | AC38: =Y38+AA38 -> 0 | AD38: =AC38/$F38 -> #DIV/0! | AF38: =AE38/F38 -> #DIV/0! | AH38: =AG38/$F38 -> #DIV/0! | AJ38: =AI38/$F38 -> #DIV/0! | AL38: =AK38/$F38 -> #DIV/0!
D39: 46081 | E39: 六 | J39: =I39/$F39 -> #DIV/0! | L39: =K39/$F39 -> #DIV/0! | M39: =I39+K39 -> 0 | N39: =M39/$F39 -> #DIV/0! | P39: =O39/$F39 -> #DIV/0! | R39: =Q39/$F39 -> #DIV/0! | S39: =O39+Q39 -> 0 | T39: =S39/$F39 -> #DIV/0! | V39: =U39/$F39 -> #DIV/0! | X39: =W39/$F39 -> #DIV/0! | Z39: =Y39/$F39 -> #DIV/0! | AB39: =AA39/$F39 -> #DIV/0! | AC39: =Y39+AA39 -> 0 | AD39: =AC39/$F39 -> #DIV/0! | AF39: =AE39/F39 -> #DIV/0! | AH39: =AG39/$F39 -> #DIV/0! | AJ39: =AI39/$F39 -> #DIV/0! | AL39: =AK39/$F39 -> #DIV/0!
C40: 三 | D40: 46082 | E40: 日 | H40: =SUM(F40:F69) -> 0 | J40: =I40/$F40 -> #DIV/0! | L40: =K40/$F40 -> #DIV/0! | M40: =I40+K40 -> 0 | N40: =M40/F40 -> #DIV/0! | P40: =O40/$F40 -> #DIV/0! | R40: =Q40/$F40 -> #DIV/0! | S40: =O40+Q40 -> 0 | T40: =S40/F40 -> #DIV/0! | V40: =U40/F40 -> #DIV/0! | X40: =W40/$F40 -> #DIV/0! | Z40: =Y40/$F40 -> #DIV/0! | AB40: =AA40/$F40 -> #DIV/0! | AC40: =Y40+AA40 -> 0 | AD40: =AC40/$F40 -> #DIV/0! | AF40: =AE40/F40 -> #DIV/0! | AH40: =AG40/$F40 -> #DIV/0! | AJ40: =AI40/$F40 -> #DIV/0! | AL40: =AK40/$F40 -> #DIV/0!
D41: 46083 | E41: 一 | J41: =I41/$F41 -> #DIV/0! | L41: =K41/$F41 -> #DIV/0! | M41: =I41+K41 -> 0 | N41: =M41/$F41 -> #DIV/0! | P41: =O41/$F41 -> #DIV/0! | R41: =Q41/$F41 -> #DIV/0! | S41: =O41+Q41 -> 0 | T41: =S41/$F41 -> #DIV/0! | V41: =U41/$F41 -> #DIV/0! | X41: =W41/$F41 -> #DIV/0! | Z41: =Y41/$F41 -> #DIV/0! | AB41: =AA41/$F41 -> #DIV/0! | AC41: =Y41+AA41 -> 0 | AD41: =AC41/$F41 -> #DIV/0! | AF41: =AE41/F41 -> #DIV/0! | AH41: =AG41/$F41 -> #DIV/0! | AJ41: =AI41/$F41 -> #DIV/0! | AL41: =AK41/$F41 -> #DIV/0!
...

Sheet （４）訂單數量構成比
B2: （4）訂單數量構成比
B3: 資料繳交日 | C3: 月份 | D3: 日期 | F3: 訂單量 | I3: 品類訂單量
I4: 18℃-飯糰 | O4: 18℃-壽司手卷 | U4: 4℃-飯糰 | W4: 4℃-壽司手卷 | Y4: 主食 | AE4: 便當 | AG4: 熱食義麵 | AI4: 季節調理麵 | AK4: 微波小吃
F5: 日 | G5: 週累積 | H5: 月累積 | I5: 一配 | K5: 二配 | M5: 合計 | O5: 一配 | Q5: 二配 | S5: 合計 | U5: 一配 | W5: 一配 | Y5: 一配 | AA5: 二配 | AC5: 合計 | AE5: 一配 | AG5: 一配 | AI5: 一配 | AK5: 一配
I6: 訂單數 | J6: 比例(%) | K6: 訂單數 | L6: 比例(%) | M6: 訂單數 | N6: 比例(%) | O6: 訂單數 | P6: 比例(%) | Q6: 訂單數 | R6: 比例(%) | S6: 訂單數 | T6: 比例(%) | U6: 訂單數 | V6: 比例(%) | W6: 訂單數 | X6: 比例(%) | Y6: 訂單數 | Z6: 比例(%) | AA6: 訂單數 | AB6: 比例(%) | AC6: 訂單數 | AD6: 比例(%) | AE6: 訂單數 | AF6: 比例(%) | AG6: 訂單數 | AH6: 比例(%) | AI6: 訂單數 | AJ6: 比例(%) | AK6: 訂單數 | AL6: 比例(%)
B7: =D15 -> 46057 | D7: 46049 | E7: 二 | F7: =SUM(M7,S7,U7,W7,AC7,AE7,AG7,AI7,AK7) -> 158031 | G7: =SUM(F7:F13) -> 1022206 | I7: 42547 | J7: =I7/$F7 -> 0.26923199 | K7: 50369 | L7: =K7/$F7 -> 0.3187286 | M7: =I7+K7 -> 92916 | N7: =M7/$F7 -> 0.58796059 | O7: 7410 | P7: =O7/$F7 -> 0.046889534 | Q7: 4888 | R7: =Q7/$F7 -> 0.03093064 | S7: =O7+Q7 -> 12298 | T7: =S7/$F7 -> 0.077820175 | U7: 3795 | V7: =U7/$F7 -> 0.024014276 | W7: 1212 | X7: =W7/$F7 -> 0.0076693813 | Y7: 3518 | Z7: =Y7/$F7 -> 0.022261455 | AA7: 10270 | AB7: =AA7/$F7 -> 0.064987249 | AC7: =Y7+AA7 -> 13788 | AD7: =AC7/$F7 -> 0.087248704 | AE7: 23127 | AF7: =AE7/$F7 -> 0.1463447 | AG7: 1548 | AH7: =AG7/$F7 -> 0.0097955464 | AI7: 4390 | AJ7: =AI7/$F7 -> 0.02777936 | AK7: 4957 | AL7: =AK7/$F7 -> 0.031367263
D8: 46050 | E8: 三 | F8: =SUM(M8,S8,U8,W8,AC8,AE8,AG8,AI8,AK8) -> 153374 | I8: 41368 | J8: =I8/$F8 -> 0.26971977 | K8: 47746 | L8: =K8/$F8 -> 0.31130439 | M8: =I8+K8 -> 89114 | N8: =M8/$F8 -> 0.58102416 | O8: 7989 | P8: =O8/$F8 -> 0.052088359 | Q8: 5084 | R8: =Q8/$F8 -> 0.03314773 | S8: =O8+Q8 -> 13073 | T8: =S8/$F8 -> 0.08523609 | U8: 3598 | V8: =U8/$F8 -> 0.023458996 | W8: 1272 | X8: =W8/$F8 -> 0.0082934526 | Y8: 3357 | Z8: =Y8/$F8 -> 0.021887673 | AA8: 9878 | AB8: =AA8/$F8 -> 0.064404658 | AC8: =Y8+AA8 -> 13235 | AD8: =AC8/$F8 -> 0.086292331 | AE8: 21749 | AF8: =AE8/$F8 -> 0.1418037 | AG8: 1588 | AH8: =AG8/$F8 -> 0.010353776 | AI8: 4416 | AJ8: =AI8/$F8 -> 0.028792364 | AK8: 5329 | AL8: =AK8/$F8 -> 0.034745133
D9: 46051 | E9: 四 | F9: =SUM(M9,S9,U9,W9,AC9,AE9,AG9,AI9,AK9) -> 141591 | I9: 38709 | J9: =I9/$F9 -> 0.27338602 | K9: 42389 | L9: =K9/$F9 -> 0.29937637 | M9: =I9+K9 -> 81098 | N9: =M9/$F9 -> 0.57276239 | O9: 7671 | P9: =O9/$F9 -> 0.054177172 | Q9: 5232 | R9: =Q9/$F9 -> 0.036951501 | S9: =O9+Q9 -> 12903 | T9: =S9/$F9 -> 0.091128673 | U9: 3548 | V9: =U9/$F9 -> 0.02505809 | W9: 1227 | X9: =W9/$F9 -> 0.008665805 | Y9: 3164 | Z9: =Y9/$F9 -> 0.022346053 | AA9: 8144 | AB9: =AA9/$F9 -> 0.05751778 | AC9: =Y9+AA9 -> 11308 | AD9: =AC9/$F9 -> 0.079863833 | AE9: 20259 | AF9: =AE9/$F9 -> 0.14308113 | AG9: 1634 | AH9: =AG9/$F9 -> 0.011540282 | AI9: 4463 | AJ9: =AI9/$F9 -> 0.031520365 | AK9: 5151 | AL9: =AK9/$F9 -> 0.036379431
D10: 46052 | E10: 五 | F10: =SUM(M10,S10,U10,W10,AC10,AE10,AG10,AI10,AK10) -> 121636 | I10: 30481 | J10: =I10/$F10 -> 0.25059193 | K10: 40864 | L10: =K10/$F10 -> 0.33595317 | M10: =I10+K10 -> 71345 | N10: =M10/$F10 -> 0.5865451 | O10: 5445 | P10: =O10/$F10 -> 0.044764708 | Q10: 4164 | R10: =Q10/$F10 -> 0.034233286 | S10: =O10+Q10 -> 9609 | T10: =S10/$F10 -> 0.078997994 | U10: 2795 | V10: =U10/$F10 -> 0.022978395 | W10: 957 | X10: =W10/$F10 -> 0.0078677365 | Y10: 3066 | Z10: =Y10/$F10 -> 0.025206353 | AA10: 8457 | AB10: =AA10/$F10 -> 0.069527114 | AC10: =Y10+AA10 -> 11523 | AD10: =AC10/$F10 -> 0.094733467 | AE10: 15962 | AF10: =AE10/$F10 -> 0.1312276 | AG10: 1266 | AH10: =AG10/$F10 -> 0.010408103 | AI10: 3714 | AJ10: =AI10/$F10 -> 0.030533724 | AK10: 4465 | AL10: =AK10/$F10 -> 0.036707883
D11: 46053 | E11: 六 | F11: =SUM(M11,S11,U11,W11,AC11,AE11,AG11,AI11,AK11) -> 129053 | I11: 28921 | J11: =I11/$F11 -> 0.22410173 | K11: 46125 | L11: =K11/$F11 -> 0.3574113 | M11: =I11+K11 -> 75046 | N11: =M11/$F11 -> 0.58151302 | O11: 5099 | P11: =O11/$F11 -> 0.039510899 | Q11: 3970 | R11: =Q11/$F11 -> 0.030762555 | S11: =O11+Q11 -> 9069 | T11: =S11/$F11 -> 0.070273454 | U11: 3096 | V11: =U11/$F11 -> 0.023990144 | W11: 982 | X11: =W11/$F11 -> 0.0076092768 | Y11: 3413 | Z11: =Y11/$F11 -> 0.026446499 | AA11: 9550 | AB11: =AA11/$F11 -> 0.074000604 | AC11: =Y11+AA11 -> 12963 | AD11: =AC11/$F11 -> 0.1004471 | AE11: 17425 | AF11: =AE11/$F11 -> 0.13502205 | AG11: 1519 | AH11: =AG11/$F11 -> 0.011770358 | AI11: 3976 | AJ11: =AI11/$F11 -> 0.030809047 | AK11: 4977 | AL11: =AK11/$F11 -> 0.038565551
C12: 二 | D12: 46054 | E12: 日 | F12: =SUM(M12,S12,U12,W12,AC12,AE12,AG12,AI12,AK12) -> 162127 | H12: =SUM(F12:F39) -> 1326773 | I12: 41113 | J12: =I12/$F12 -> 0.25358515 | K12: 51186 | L12: =K12/$F12 -> 0.31571546 | M12: =I12+K12 -> 92299 | N12: =M12/$F12 -> 0.56930061 | O12: 8035 | P12: =O12/$F12 -> 0.049559913 | Q12: 4908 | R12: =Q12/$F12 -> 0.030272564 | S12: =O12+Q12 -> 12943 | T12: =S12/$F12 -> 0.079832477 | U12: 3922 | V12: =U12/$F12 -> 0.024190912 | W12: 1286 | X12: =W12/$F12 -> 0.0079320533 | Y12: 3751 | Z12: =Y12/$F12 -> 0.023136183 | AA12: 11082 | AB12: =AA12/$F12 -> 0.068353821 | AC12: =Y12+AA12 -> 14833 | AD12: =AC12/$F12 -> 0.091490005 | AE12: 27031 | AF12: =AE12/$F12 -> 0.16672732 | AG12: 1494 | AH12: =AG12/$F12 -> 0.0092149981 | AI12: 3681 | AJ12: =AI12/$F12 -> 0.022704423 | AK12: 4638 | AL12: =AK12/$F12 -> 0.028607203
D13: 46055 | E13: 一 | F13: =SUM(M13,S13,U13,W13,AC13,AE13,AG13,AI13,AK13) -> 156394 | I13: 39864 | J13: =I13/$F13 -> 0.25489469 | K13: 50072 | L13: =K13/$F13 -> 0.32016574 | M13: =I13+K13 -> 89936 | N13: =M13/$F13 -> 0.57506042 | O13: 7588 | P13: =O13/$F13 -> 0.048518485 | Q13: 4924 | R13: =Q13/$F13 -> 0.031484584 | S13: =O13+Q13 -> 12512 | T13: =S13/$F13 -> 0.080003069 | U13: 3549 | V13: =U13/$F13 -> 0.022692686 | W13: 1237 | X13: =W13/$F13 -> 0.0079095106 | Y13: 3737 | Z13: =Y13/$F13 -> 0.023894779 | AA13: 10391 | AB13: =AA13/$F13 -> 0.066441168 | AC13: =Y13+AA13 -> 14128 | AD13: =AC13/$F13 -> 0.090335946 | AE13: 23849 | AF13: =AE13/$F13 -> 0.15249306 | AG13: 1679 | AH13: =AG13/$F13 -> 0.010735706 | AI13: 4262 | AJ13: =AI13/$F13 -> 0.027251685 | AK13: 5242 | AL13: =AK13/$F13 -> 0.03351791
B14: =D22 -> 46064 | D14: 46056 | E14: 二 | F14: =SUM(M14,S14,U14,W14,AC14,AE14,AG14,AI14,AK14) -> 156238 | G14: =SUM(F14:F20) -> 1008252 | I14: 40290 | J14: =I14/$F14 -> 0.2578758 | K14: 50139 | L14: =K14/$F14 -> 0.32091425 | M14: =I14+K14 -> 90429 | N14: =M14/$F14 -> 0.57879005 | O14: 7848 | P14: =O14/$F14 -> 0.050231058 | Q14: 5201 | R14: =Q14/$F14 -> 0.033288957 | S14: =O14+Q14 -> 13049 | T14: =S14/$F14 -> 0.083520014 | U14: 3482 | V14: =U14/$F14 -> 0.022286512 | W14: 1270 | X14: =W14/$F14 -> 0.0081286243 | Y14: 3586 | Z14: =Y14/$F14 -> 0.022952163 | AA14: 10856 | AB14: =AA14/$F14 -> 0.069483736 | AC14: =Y14+AA14 -> 14442 | AD14: =AC14/$F14 -> 0.092435899 | AE14: 22871 | AF14: =AE14/$F14 -> 0.14638564 | AG14: 1483 | AH14: =AG14/$F14 -> 0.009491929 | AI14: 4030 | AJ14: =AI14/$F14 -> 0.025793981 | AK14: 5182 | AL14: =AK14/$F14 -> 0.033167347
D15: 46057 | E15: 三 | F15: =SUM(M15,S15,U15,W15,AC15,AE15,AG15,AI15,AK15) -> 152389 | I15: 39672 | J15: =I15/$F15 -> 0.26033375 | K15: 47565 | L15: =K15/$F15 -> 0.31212883 | M15: =I15+K15 -> 87237 | N15: =M15/$F15 -> 0.57246258 | O15: 8493 | P15: =O15/$F15 -> 0.055732369 | Q15: 5308 | R15: =Q15/$F15 -> 0.03483191 | S15: =O15+Q15 -> 13801 | T15: =S15/$F15 -> 0.09056428 | U15: 3467 | V15: =U15/$F15 -> 0.022750986 | W15: 1234 | X15: =W15/$F15 -> 0.0080976973 | Y15: 3478 | Z15: =Y15/$F15 -> 0.02282317 | AA15: 10158 | AB15: =AA15/$F15 -> 0.066658355 | AC15: =Y15+AA15 -> 13636 | AD15: =AC15/$F15 -> 0.089481524 | AE15: 21537 | AF15: =AE15/$F15 -> 0.1413291 | AG15: 1443 | AH15: =AG15/$F15 -> 0.0094691874 | AI15: 4457 | AJ15: =AI15/$F15 -> 0.029247518 | AK15: 5577 | AL15: =AK15/$F15 -> 0.03659713
D16: 46058 | E16: 四 | F16: =SUM(M16,S16,U16,W16,AC16,AE16,AG16,AI16,AK16) -> 141990 | I16: 37921 | J16: =I16/$F16 -> 0.2670681 | K16: 43213 | L16: =K16/$F16 -> 0.30433833 | M16: =I16+K16 -> 81134 | N16: =M16/$F16 -> 0.57140644 | O16: 8339 | P16: =O16/$F16 -> 0.058729488 | Q16: 5281 | R16: =Q16/$F16 -> 0.03719276 | S16: =O16+Q16 -> 13620 | T16: =S16/$F16 -> 0.095922248 | U16: 3009 | V16: =U16/$F16 -> 0.021191633 | W16: 1210 | X16: =W16/$F16 -> 0.0085217269 | Y16: 3253 | Z16: =Y16/$F16 -> 0.022910064 | AA16: 8183 | AB16: =AA16/$F16 -> 0.057630819 | AC16: =Y16+AA16 -> 11436 | AD16: =AC16/$F16 -> 0.080540883 | AE16: 20274 | AF16: =AE16/$F16 -> 0.1427847 | AG16: 1488 | AH16: =AG16/$F16 -> 0.010479611 | AI16: 4160 | AJ16: =AI16/$F16 -> 0.029297838 | AK16: 5659 | AL16: =AK16/$F16 -> 0.039854919
D17: 46059 | E17: 五 | F17: =SUM(M17,S17,U17,W17,AC17,AE17,AG17,AI17,AK17) -> 119260 | I17: 29522 | J17: =I17/$F17 -> 0.24754318 | K17: 40622 | L17: =K17/$F17 -> 0.34061714 | M17: =I17+K17 -> 70144 | N17: =M17/$F17 -> 0.58816032 | O17: 5561 | P17: =O17/$F17 -> 0.046629213 | Q17: 4252 | R17: =Q17/$F17 -> 0.035653195 | S17: =O17+Q17 -> 9813 | T17: =S17/$F17 -> 0.082282408 | U17: 2366 | V17: =U17/$F17 -> 0.019839007 | W17: 793 | X17: =W17/$F17 -> 0.0066493376 | Y17: 2977 | Z17: =Y17/$F17 -> 0.024962267 | AA17: 8561 | AB17: =AA17/$F17 -> 0.071784337 | AC17: =Y17+AA17 -> 11538 | AD17: =AC17/$F17 -> 0.096746604 | AE17: 16022 | AF17: =AE17/$F17 -> 0.13434513 | AG17: 1098 | AH17: =AG17/$F17 -> 0.0092067751 | AI17: 2755 | AJ17: =AI17/$F17 -> 0.023100788 | AK17: 4731 | AL17: =AK17/$F17 -> 0.039669629
D18: 46060 | E18: 六 | F18: =SUM(M18,S18,U18,W18,AC18,AE18,AG18,AI18,AK18) -> 126462 | I18: 27664 | J18: =I18/$F18 -> 0.21875346 | K18: 46342 | L18: =K18/$F18 -> 0.36645 | M18: =I18+K18 -> 74006 | N18: =M18/$F18 -> 0.58520346 | O18: 5103 | P18: =O18/$F18 -> 0.040352043 | Q18: 4016 | R18: =Q18/$F18 -> 0.031756575 | S18: =O18+Q18 -> 9119 | T18: =S18/$F18 -> 0.072108618 | U18: 2522 | V18: =U18/$F18 -> 0.01994275 | W18: 779 | X18: =W18/$F18 -> 0.0061599532 | Y18: 3392 | Z18: =Y18/$F18 -> 0.026822287 | AA18: 9340 | AB18: =AA18/$F18 -> 0.073856178 | AC18: =Y18+AA18 -> 12732 | AD18: =AC18/$F18 -> 0.10067846 | AE18: 17369 | AF18: =AE18/$F18 -> 0.13734561 | AG18: 1403 | AH18: =AG18/$F18 -> 0.011094242 | AI18: 2845 | AJ18: =AI18/$F18 -> 0.022496877 | AK18: 5687 | AL18: =AK18/$F18 -> 0.044970031
D19: 46061 | E19: 日 | F19: =SUM(M19,S19,U19,W19,AC19,AE19,AG19,AI19,AK19) -> 158901 | I19: 40022 | J19: =I19/$F19 -> 0.25186751 | K19: 51103 | L19: =K19/$F19 -> 0.32160276 | M19: =I19+K19 -> 91125 | N19: =M19/$F19 -> 0.57347027 | O19: 8326 | P19: =O19/$F19 -> 0.052397405 | Q19: 5023 | R19: =Q19/$F19 -> 0.031610877 | S19: =O19+Q19 -> 13349 | T19: =S19/$F19 -> 0.084008282 | U19: 3145 | V19: =U19/$F19 -> 0.019792198 | W19: 877 | X19: =W19/$F19 -> 0.0055191597 | Y19: 3815 | Z19: =Y19/$F19 -> 0.024008659 | AA19: 11052 | AB19: =AA19/$F19 -> 0.06955274 | AC19: =Y19+AA19 -> 14867 | AD19: =AC19/$F19 -> 0.0935614 | AE19: 26223 | AF19: =AE19/$F19 -> 0.16502728 | AG19: 1396 | AH19: =AG19/$F19 -> 0.0087853443 | AI19: 2976 | AJ19: =AI19/$F19 -> 0.018728642 | AK19: 4943 | AL19: =AK19/$F19 -> 0.031107419
D20: 46062 | E20: 一 | F20: =SUM(M20,S20,U20,W20,AC20,AE20,AG20,AI20,AK20) -> 153012 | I20: 39063 | J20: =I20/$F20 -> 0.2552937 | K20: 50117 | L20: =K20/$F20 -> 0.3275364 | M20: =I20+K20 -> 89180 | N20: =M20/$F20 -> 0.5828301 | O20: 7865 | P20: =O20/$F20 -> 0.051401197 | Q20: 5009 | R20: =Q20/$F20 -> 0.032735995 | S20: =O20+Q20 -> 12874 | T20: =S20/$F20 -> 0.084137192 | U20: 2791 | V20: =U20/$F20 -> 0.018240399 | W20: 974 | X20: =W20/$F20 -> 0.0063655138 | Y20: 3767 | Z20: =Y20/$F20 -> 0.024618984 | AA20: 10349 | AB20: =AA20/$F20 -> 0.067635218 | AC20: =Y20+AA20 -> 14116 | AD20: =AC20/$F20 -> 0.092254202 | AE20: 23303 | AF20: =AE20/$F20 -> 0.15229524 | AG20: 1592 | AH20: =AG20/$F20 -> 0.010404413 | AI20: 3406 | AJ20: =AI20/$F20 -> 0.022259692 | AK20: 4776 | AL20: =AK20/$F20 -> 0.031213238
B21: =D29 -> 46071 | D21: 46063 | E21: 二 | G21: =SUM(F21:F27) -> 0 | J21: =I21/$F21 -> #DIV/0! | L21: =K21/$F21 -> #DIV/0! | M21: =I21+K21 -> 0 | N21: =M21/$F21 -> #DIV/0! | P21: =O21/$F21 -> #DIV/0! | R21: =Q21/$F21 -> #DIV/0! | S21: =O21+Q21 -> 0 | T21: =S21/$F21 -> #DIV/0! | V21: =U21/$F21 -> #DIV/0! | X21: =W21/$F21 -> #DIV/0! | Z21: =Y21/$F21 -> #DIV/0! | AB21: =AA21/$F21 -> #DIV/0! | AC21: =Y21+AA21 -> 0 | AD21: =AC21/$F21 -> #DIV/0! | AF21: =AE21/$F21 -> #DIV/0! | AH21: =AG21/$F21 -> #DIV/0! | AJ21: =AI21/$F21 -> #DIV/0! | AL21: =AK21/$F21 -> #DIV/0!
