Workbook

Sheet 生產管理報表(月)
A1: 大溪廠生產管理報表
A3: 月別 | B3: 1 | C3: 工廠 | D3: 大溪廠
A4: （１）收支狀況 | E4: ※單位：千元 | G4: （２）ＫＰＩ達成進度
A5: 項目 | B5: 當月 | C5: 前月 | D5: 差異 | E5: 累計 | G5: 項目 | H5: KPI | I5: 當月 | J5: 前月 | K5: 累計 | L5: ※補充
A6: 業績金額 | B6: ='（１）收支狀況'!H7/1000 -> 124565.13 | C6: 176732.06 | D6: =B6-C6 -> -52166.934 | G6: 人時性(個/月均) | I6: ='（２）ＫＰＩ達成進度'!H7 -> 455.63186 | J6: 414.41163 | L6: 個／MH
A7: 訂單數量 | B7: ='（１）收支狀況'!K7 -> 4065016 | C7: 5518274 | D7: =B7-C7 -> -1453258 | G7: 人時達成率(%/月均) | H7: 0.8 | I7: ='（２）ＫＰＩ達成進度'!K7 -> 0.91565889 | J7: 0.8328208 | L7: 達成率
A8: 材料費 | B8: ='（１）收支狀況'!N7/1000 -> 82084.889 | C8: 115112 | D8: =B8-C8 -> -33027.111 | G8: 半成品-報廢(%) | H8: 0.0025 | I8: ='（２）ＫＰＩ達成進度'!N7 -> 0.0024146726 | J8: 0.0024165598 | L8: 報廢率
A9: 材料費率 | B9: ='（１）收支狀況'!Q7 -> 0.65897167 | C9: 0.655 | D9: =B9-C9 -> 0.0039716697 | G9: 半成品-超用(%) | H9: 0.004 | I9: ='（２）ＫＰＩ達成進度'!Q7 -> 0.0056219258 | J9: 0.0061020274 | L9: 超用率
A10: 勞務成本 | B10: ='（１）收支狀況'!T7/1000 -> 20360.682 | C10: 25545 | D10: =B10-C10 -> -5184.3184 | G10: 固定產線-導入率(%) | H10: 0.8 | I10: ='（２）ＫＰＩ達成進度'!T7 -> 0.9 | J10: 0.9 | L10: 導入率
A11: 勞務費率 | B11: ='（１）收支狀況'!W7 -> 0.16345411 | C11: 0.145 | D11: =B11-C11 -> 0.018454108 | G11: 教育訓練-實施率(%) | H11: 1 | I11: ='（２）ＫＰＩ達成進度'!W7 -> 0.050295858 | J11: 0.97084367 | L11: 實施率
A13: （３）業績構成比 | E13: ※單位：千元 | G13: （４）訂單數量構成比 | K13: ※單位：個
B14: 當月 | C14: 比例 | D14: 前月 | E14: 差異 | H14: 當月 | I14: 比例 | J14: 前月 | K14: 差異
A15: 18℃-飯糰(061,063) | B15: =SUM('（３）業績構成比'!M9:M39)/1000 -> 45102.573 | C15: =IFERROR(B15/$B$6,"") -> 0.36208026 | D15: 0.30192713 | E15: =IFERROR(C15-D15,"") -> 0.060153126 | G15: 18℃-飯糰(061,063) | H15: =SUM('（４）訂單數量構成比'!M9:M39) -> 2383849 | I15: =IFERROR(H15/$B$7,"") -> 0.58643041 | J15: 0.51227449 | K15: =IFERROR(I15-J15,"") -> 0.07415592
A16: 18℃-壽司手卷(071,072,075,076) | B16: =SUM('（３）業績構成比'!S9:S39)/1000 -> 8699.9574 | C16: =IFERROR(B16/$B$6,"") -> 0.069842641 | D16: 0.069383438 | E16: =IFERROR(C16-D16,"") -> 0.0004592031 | G16: 18℃-壽司手卷(071,072,075,076) | H16: =SUM('（４）訂單數量構成比'!S9:S39) -> 332622 | I16: =IFERROR(H16/$B$7,"") -> 0.081825508 | J16: 0.086791268 | K16: =IFERROR(I16-J16,"") -> -0.0049657602
A17: 4℃-飯糰(065) | B17: =SUM('（３）業績構成比'!U9:U39)/1000 -> 2813.4367 | C17: =IFERROR(B17/$B$6,"") -> 0.022586071 | D17: 0.071182856 | E17: =IFERROR(C17-D17,"") -> -0.048596785 | G17: 4℃-飯糰(065) | H17: =SUM('（４）訂單數量構成比'!U9:U39) -> 102224 | I17: =IFERROR(H17/$B$7,"") -> 0.025147256 | J17: 0.076188859 | K17: =IFERROR(I17-J17,"") -> -0.051041603
A18: 4℃-壽司手卷(077) | B18: =SUM('（３）業績構成比'!W9:W39)/1000 -> 1103.1581 | C18: =IFERROR(B18/$B$6,"") -> 0.0088560754 | D18: 0.0038510891 | E18: =IFERROR(C18-D18,"") -> 0.0050049863 | G18: 4℃-壽司手卷(077) | H18: =SUM('（４）訂單數量構成比'!W9:W39) -> 41066 | I18: =IFERROR(H18/$B$7,"") -> 0.010102297 | J18: 0.0043462865 | K18: =IFERROR(I18-J18,"") -> 0.0057560107
A19: 主食(091,092,093,094,095) | B19: =SUM('（３）業績構成比'!AC9:AC39)/1000 -> 20245.102 | C19: =IFERROR(B19/$B$6,"") -> 0.16252624 | D19: 0.16662246 | E19: =IFERROR(C19-D19,"") -> -0.0040962155 | G19: 主食(091,092,093,094,095) | H19: =SUM('（４）訂單數量構成比'!AC9:AC39) -> 366142 | I19: =IFERROR(H19/$B$7,"") -> 0.090071478 | J19: 0.098131046 | K19: =IFERROR(I19-J19,"") -> -0.0080595679
A20: 便當(083) | B20: =SUM('（３）業績構成比'!AE9:AE39)/1000 -> 33638.465 | C20: =IFERROR(B20/$B$6,"") -> 0.27004721 | D20: 0.25124875 | E20: =IFERROR(C20-D20,"") -> 0.018798459 | G20: 便當(083) | H20: =SUM('（４）訂單數量構成比'!AE9:AE39) -> 555180 | I20: =IFERROR(H20/$B$7,"") -> 0.13657511 | J20: 0.13239085 | K20: =IFERROR(I20-J20,"") -> 0.0041842555
A21: 熱食義麵(122,123,124,126) | B21: =SUM('（３）業績構成比'!AG9:AG39)/1000 -> 3844.0851 | C21: =IFERROR(B21/$B$6,"") -> 0.030860043 | D21: 0.041820764 | E21: =IFERROR(C21-D21,"") -> -0.010960721 | G21: 熱食義麵(122,123,124,126) | H21: =SUM('（４）訂單數量構成比'!AG9:AG39) -> 67087 | I21: =IFERROR(H21/$B$7,"") -> 0.016503502 | J21: 0.023374881 | K21: =IFERROR(I21-J21,"") -> -0.0068713793
A22: 季節調理麵(111,112) | B22: =SUM('（３）業績構成比'!AI9:AI39)/1000 -> 4747.4174 | C22: =IFERROR(B22/$B$6,"") -> 0.03811193 | D22: 0.059874119 | E22: =IFERROR(C22-D22,"") -> -0.021762189 | G22: 季節調理麵(111,112) | H22: =SUM('（４）訂單數量構成比'!AI9:AI39) -> 83975 | I22: =IFERROR(H22/$B$7,"") -> 0.020657975 | J22: 0.035279872 | K22: =IFERROR(I22-J22,"") -> -0.014621897
A23: 微波小吃(153,154,155) | B23: =SUM('（３）業績構成比'!AK9:AK39)/1000 -> 4370.9319 | C23: =IFERROR(B23/$B$6,"") -> 0.035089531 | D23: 0.034089394 | E23: =IFERROR(C23-D23,"") -> 0.0010001367 | G23: 微波小吃(153,154,155) | H23: =SUM('（４）訂單數量構成比'!AK9:AK39) -> 132871 | I23: =IFERROR(H23/$B$7,"") -> 0.032686464 | J23: 0.031222444 | K23: =IFERROR(I23-J23,"") -> 0.0014640204
C24: =SUM(C15:C23) -> 1 | D24: =SUM(D15:D23) -> 1 | I24: =SUM(I15:I23) -> 1 | J24: =SUM(J15:J23) -> 1
A26: （５）品群別人時生產性
A27: 品群 | B27: 當月 | C27: 前月 | D27: 差異 | E27: 累計
A28: 18℃-飯A15:A23糰(061,063) | B28: ='（５-1）品群別人時生產性(18℃-飯糰)'!C1 -> 768.29724 | C28: 766.81397 | D28: =B28-C28 -> 1.4832628
A29: 18℃-壽司手卷(071,072,075,076) | B29: ='（５-2）品群別人時生產性(18℃-壽司手卷)'!C1 -> 273.6832 | C29: 270.9953 | D29: =B29-C29 -> 2.6878999
A30: 4℃-飯糰(065) | B30: ='（５-3）品群別人時生產性(4℃-飯糰)'!C1 -> 257.88553 | C30: 280.90267 | D30: =B30-C30 -> -23.017141
A31: 4℃-壽司手卷(077) | B31: ='（５-4）品群別人時生產性(4℃-壽司手卷)'!C1 -> 484.08871 | C31: 328.95494 | D31: =B31-C31 -> 155.13378
A32: 主食(091,092,093,094,095) | B32: ='（５-5）品群別人時生產性(微波主食) '!C1 -> 66.304812 | C32: 82.868901 | D32: =B32-C32 -> -16.564089
A33: 便當(083) | B33: ='（５-6）品群別人時生產性(便當)'!C1 -> 78.447634 | C33: 79.179969 | D33: =B33-C33 -> -0.73233515
A34: 熱食義麵(122,123,124,126) | B34: ='（５-7）品群別人時生產性(熱食義麵) '!C1 -> 77.084751 | C34: 78.41919 | D34: =B34-C34 -> -1.3344389
A35: 季節調理麵(111,112) | B35: ='（５-8）品群別人時生產性(季節調理麵) '!C1 -> 111.82979 | C35: 120.50217 | D35: =B35-C35 -> -8.6723765
A36: 微波小吃(153,154,155) | B36: ='（５-9）品群別人時生產性(微波小吃)'!C1 -> 76.091631 | C36: 75.986634 | D36: =B36-C36 -> 0.10499678

Sheet 生產管理報表(週) 
A1: 大溪廠生產管理報表
A3: 月別 | B3: 1 | C3: 週別 | D3: W4 | E3: 工廠 | F3: 大溪廠
A4: （１）收支狀況 | E4: ※單位：千元 | G4: （２）ＫＰＩ達成進度
A5: 項目 | B5: 當週 | C5: 前週 | D5: 差異 | E5: 累計 | G5: 項目 | H5: KPI | I5: 當週 | J5: 前週 | K5: 累計 | L5: ※補充
A6: 業績金額 | B6: ='（１）收支狀況'!G26/1000 -> 33925.348 | C6: 33161.159 | D6: =B6-C6 -> 764.18901 | E6: ='（１）收支狀況'!H7:H7/1000 -> 124565.13 | G6: 人時性(個/月均) | I6: ='（２）ＫＰＩ達成進度'!G26 -> 466.53938 | J6: 463.69602 | K6: ='（２）ＫＰＩ達成進度'!H7 -> 455.63186 | L6: 個／MH
A7: 訂單數量 | B7: ='（１）收支狀況'!J26 -> 1096366 | C7: 1095713 | D7: =B7-C7 -> 653 | E7: ='（１）收支狀況'!K7:K7 -> 4065016 | G7: 人時達成率(%/月均) | H7: 0.8 | I7: ='（２）ＫＰＩ達成進度'!J26 -> 0.93757914 | J7: 0.931865 | K7: ='（２）ＫＰＩ達成進度'!K7 -> 0.91565889 | L7: 達成率
A8: 材料費 | B8: ='（１）收支狀況'!M26/1000 -> 22388.797 | C8: 21779.479 | D8: =B8-C8 -> 609.31779 | E8: ='（１）收支狀況'!N7:N7/1000 -> 82084.889 | G8: 半成品-報廢(%) | H8: 0.0025 | I8: ='（２）ＫＰＩ達成進度'!M26 -> 0.0024189722 | J8: 0.0024117997 | K8: ='（２）ＫＰＩ達成進度'!N7 -> 0.0024146726 | L8: 報廢率
A9: 材料費率 | B9: ='（１）收支狀況'!P26 -> 0.65994302 | C9: 0.65677677 | D9: =B9-C9 -> 0.0031662521 | E9: ='（１）收支狀況'!Q7 -> 0.65897167 | G9: 半成品-超用(%) | H9: 0.004 | I9: ='（２）ＫＰＩ達成進度'!P26 -> 0.005650009 | J9: 0.0055709665 | K9: ='（２）ＫＰＩ達成進度'!Q7 -> 0.0056219258 | L9: 超用率
A10: 勞務成本 | B10: ='（１）收支狀況'!S26/1000 -> 5364.2808 | C10: 5508.0302 | D10: =B10-C10 -> -143.7494 | E10: ='（１）收支狀況'!T7/1000 -> 20360.682 | G10: 固定產線-導入率(%) | H10: 0.8 | I10: ='（２）ＫＰＩ達成進度'!S26 -> 0.9 | J10: 0.9 | K10: ='（２）ＫＰＩ達成進度'!T7 -> 0.9 | L10: 導入率
A11: 勞務費率 | B11: ='（１）收支狀況'!V26 -> 0.15812014 | C11: 0.16609885 | D11: =B11-C11 -> -0.007978704 | E11: ='（１）收支狀況'!W7 -> 0.16345411 | G11: 教育訓練-實施率(%) | H11: 1 | I11: =4/52*100% -> 0.076923077 | J11: 0.057692308 | K11: ='（２）ＫＰＩ達成進度'!W7 -> 0.050295858 | L11: 實施率
A13: （３）業績構成比 | E13: ※單位：千元 | G13: （４）訂單數量構成比 | K13: ※單位：個
B14: 當週 | C14: 比例 | D14: 前週 | E14: 差異 | H14: 當週 | I14: 比例 | J14: 前週 | K14: 差異
A15: 18℃-飯糰(061,063) | B15: =SUM('（３）業績構成比'!M28:M34)/1000 -> 12392.824 | C15: =IFERROR(B15/$B$6,"") -> 0.3652969 | D15: 0.37091571 | E15: =IFERROR(C15-D15,"") -> -0.0056188161 | G15: 18℃-飯糰(061,063) | H15: =SUM('（４）訂單數量構成比'!M28:M34) -> 646222 | I15: =IFERROR(H15/$B$7,"") -> 0.58942178 | J15: 0.59401869 | K15: =IFERROR(I15-J15,"") -> -0.0045969085
A16: 18℃-壽司手卷(071,072,075,076) | B16: =SUM('（３）業績構成比'!S28:S34)/1000 -> 2205.21 | C16: =IFERROR(B16/$B$6,"") -> 0.06500184 | D16: 0.068935667 | E16: =IFERROR(C16-D16,"") -> -0.003933827 | G16: 18℃-壽司手卷(071,072,075,076) | H16: =SUM('（４）訂單數量構成比'!S28:S34) -> 84818 | I16: =IFERROR(H16/$B$7,"") -> 0.077362851 | J16: 0.079900485 | K16: =IFERROR(I16-J16,"") -> -0.0025376334
A17: 4℃-飯糰(065) | B17: =SUM('（３）業績構成比'!U28:U34)/1000 -> 700.7761 | C17: =IFERROR(B17/$B$6,"") -> 0.020656416 | D17: 0.022900897 | E17: =IFERROR(C17-D17,"") -> -0.0022444814 | G17: 4℃-飯糰(065) | H17: =SUM('（４）訂單數量構成比'!U28:U34) -> 25204 | I17: =IFERROR(H17/$B$7,"") -> 0.022988673 | J17: 0.025072259 | K17: =IFERROR(I17-J17,"") -> -0.0020835854
A18: 4℃-壽司手卷(077) | B18: =SUM('（３）業績構成比'!W28:W34)/1000 -> 313.21195 | C18: =IFERROR(B18/$B$6,"") -> 0.0092323872 | D18: 0.011511347 | E18: =IFERROR(C18-D18,"") -> -0.0022789595 | G18: 4℃-壽司手卷(077) | H18: =SUM('（４）訂單數量構成比'!W28:W34) -> 11579 | I18: =IFERROR(H18/$B$7,"") -> 0.010561254 | J18: 0.012879285 | K18: =IFERROR(I18-J18,"") -> -0.0023180308
A19: 主食(091,092,093,094,095) | B19: =SUM('（３）業績構成比'!AC28:AC34)/1000 -> 4980.529 | C19: =IFERROR(B19/$B$6,"") -> 0.14680849 | D19: 0.1610725 | E19: =IFERROR(C19-D19,"") -> -0.014264017 | G19: 主食(091,092,093,094,095) | H19: =SUM('（４）訂單數量構成比'!AC28:AC34) -> 89863 | I19: =IFERROR(H19/$B$7,"") -> 0.081964417 | J19: 0.087874288 | K19: =IFERROR(I19-J19,"") -> -0.0059098713
A20: 便當(083) | B20: =SUM('（３）業績構成比'!AE28:AE34)/1000 -> 9446.4542 | C20: =IFERROR(B20/$B$6,"") -> 0.27844826 | D20: 0.26471905 | E20: =IFERROR(C20-D20,"") -> 0.013729215 | G20: 便當(083) | H20: =SUM('（４）訂單數量構成比'!AE28:AE34) -> 155708 | I20: =IFERROR(H20/$B$7,"") -> 0.14202192 | J20: 0.13280941 | K20: =IFERROR(I20-J20,"") -> 0.0092125034
A21: 熱食義麵(122,123,124,126) | B21: =SUM('（３）業績構成比'!AG28:AG34)/1000 -> 614.4279 | C21: =IFERROR(B21/$B$6,"") -> 0.018111175 | D21: 0.032623226 | E21: =IFERROR(C21-D21,"") -> -0.014512052 | G21: 熱食義麵(122,123,124,126) | H21: =SUM('（４）訂單數量構成比'!AG28:AG34) -> 10723 | I21: =IFERROR(H21/$B$7,"") -> 0.009780493 | J21: 0.017230789 | K21: =IFERROR(I21-J21,"") -> -0.0074502964
A22: 季節調理麵(111,112) | B22: =SUM('（３）業績構成比'!AI28:AI34)/1000 -> 2092.1062 | C22: =IFERROR(B22/$B$6,"") -> 0.061667936 | D22: 0.03365954 | E22: =IFERROR(C22-D22,"") -> 0.028008396 | G22: 季節調理麵(111,112) | H22: =SUM('（４）訂單數量構成比'!AI28:AI34) -> 37184 | I22: =IFERROR(H22/$B$7,"") -> 0.033915681 | J22: 0.01834787 | K22: =IFERROR(I22-J22,"") -> 0.015567811
A23: 微波小吃(153,154,155) | B23: =SUM('（３）業績構成比'!AK28:AK34)/1000 -> 1179.8083 | C23: =IFERROR(B23/$B$6,"") -> 0.0347766 | D23: 0.033662058 | E23: =IFERROR(C23-D23,"") -> 0.0011145426 | G23: 微波小吃(153,154,155) | H23: =SUM('（４）訂單數量構成比'!AK28:AK34) -> 35065 | I23: =IFERROR(H23/$B$7,"") -> 0.031982933 | J23: 0.031866921 | K23: =IFERROR(I23-J23,"") -> 0.00011601135
C24: =SUM(C15:C23) -> 1 | D24: =SUM(D15:D23) -> 1 | I24: =SUM(I15:I23) -> 1 | J24: =SUM(J15:J23) -> 1
A26: （５）品群別人時生產性
A27: 品群 | B27: 當週 | C27: 前週 | D27: 差異 | E27: 累計
A28: 18℃-飯糰(061,063) | B28: ='（５-1）品群別人時生產性(18℃-飯糰)'!L121 -> 761.81358 | C28: 766.73953 | D28: =B28-C28 -> -4.9259596 | E28: ='（５-1）品群別人時生產性(18℃-飯糰)'!C1 -> 768.29724
A29: 18℃-壽司手卷(071,072,075,076) | B29: ='（５-2）品群別人時生產性(18℃-壽司手卷)'!L67 -> 289.20848 | C29: 288.95733 | D29: =B29-C29 -> 0.25115204 | E29: ='（５-2）品群別人時生產性(18℃-壽司手卷)'!C1 -> 273.6832
A30: 4℃-飯糰(065) | B30: ='（５-3）品群別人時生產性(4℃-飯糰)'!L67 -> 257.79938 | C30: 257.84825 | D30: =B30-C30 -> -0.048871037 | E30: ='（５-3）品群別人時生產性(4℃-飯糰)'!C1 -> 257.88553
A31: 4℃-壽司手卷(077) | B31: ='（５-4）品群別人時生產性(4℃-壽司手卷)'!L67 -> 491.07965 | C31: 491.07408 | D31: =B31-C31 -> 0.0055669247 | E31: ='（５-4）品群別人時生產性(4℃-壽司手卷)'!C1 -> 484.08871
A32: 主食(091,092,093,094,095) | B32: ='（５-5）品群別人時生產性(微波主食) '!L67 -> 81.692631 | C32: 81.63893 | D32: =B32-C32 -> 0.053701137 | E32: ='（５-5）品群別人時生產性(微波主食) '!C1 -> 66.304812
A33: 便當(083) | B33: ='（５-6）品群別人時生產性(便當)'!L67 -> 77.332946 | C33: 78.073513 | D33: =B33-C33 -> -0.74056654 | E33: ='（５-6）品群別人時生產性(便當)'!C1 -> 78.447634
A34: 熱食義麵(122,123,124,126) | B34: ='（５-7）品群別人時生產性(熱食義麵) '!L67 -> 72.724655 | C34: 78.618786 | D34: =B34-C34 -> -5.8941308 | E34: ='（５-7）品群別人時生產性(熱食義麵) '!C1 -> 77.084751
A35: 季節調理麵(111,112) | B35: ='（５-8）品群別人時生產性(季節調理麵) '!L67 -> 105.82456 | C35: 114.01378 | D35: =B35-C35 -> -8.1892201 | E35: ='（５-8）品群別人時生產性(季節調理麵) '!C1 -> 111.82979
A36: 微波小吃(153,154,155) | B36: ='（５-9）品群別人時生產性(微波小吃)'!L67 -> 76.183774 | C36: 76.118817 | D36: =B36-C36 -> 0.064957497 | E36: ='（５-9）品群別人時生產性(微波小吃)'!C1 -> 76.091631

Sheet （１）收支狀況
B2: （１）收支狀況
B3: 資料繳交日 | C3: 月份 | D3: 日期 | F3: 營業額(元) | I3: 訂單數量(個) | L3: 材料費(元) | O3: 材料費率（材料費／營業額） | R3: 勞務成本（全廠人事成本） | U3: 勞務費率（勞務成本／營業額）
F4: 日 | G4: 週累積 | H4: 月累積 | I4: 日 | J4: 週累積 | K4: 月累積 | L4: 日 | M4: 週累積 | N4: 月累積 | O4: 日 | P4: 週累積 | Q4: 月累積 | R4: 日 | S4: 週累積 | T4: 月累積 | U4: 日 | V4: 週累積 | W4: 月累積
B5: 46029 | D5: 46021 | E5: 二 | F5: 4991542.2 | G5: =SUM(F5:F11) -> 32267367 | I5: 160010 | J5: =SUM(I5:I11) -> 1040875 | L5: 3281758.9 | M5: =SUM(L5:L11) -> 21329815 | O5: =L5/F5 -> 0.65746392 | P5: =M5/G5 -> 0.66103366 | R5: 770189.23 | S5: =SUM(R5:R11) -> 5432548.6 | U5: =R5/F5 -> 0.15429885 | V5: =S5/G5 -> 0.16836046
D6: =D5+1 -> 46022 | E6: 三 | F6: 3992684.9 | I6: 129015 | L6: 2620930.1 | O6: =L6/F6 -> 0.65643299 | R6: 763301.32 | U6: =R6/F6 -> 0.19117495
C7: 一 | D7: =D6+1 -> 46023 | E7: 四 | F7: 4613445.5 | H7: =SUM(F7:F37) -> 1.2456513e+08 | I7: 149358 | K7: =SUM(I7:I37) -> 4065016 | L7: 3122113.5 | N7: =SUM(L7:L37) -> 82084889 | O7: =L7/F7 -> 0.67674227 | Q7: =N7/H7 -> 0.65897167 | R7: 779524.36 | T7: =SUM(R7:R37) -> 20360682 | U7: =R7/F7 -> 0.16896794 | W7: =T7/H7 -> 0.16345411
D8: =D7+1 -> 46024 | E8: 五 | F8: 3838107.8 | I8: 127084 | L8: 2500863.6 | O8: =L8/F8 -> 0.65158763 | R8: 719210.93 | U8: =R8/F8 -> 0.18738685
D9: =D8+1 -> 46025 | E9: 六 | F9: 4182799.2 | I9: 134835 | L9: 2821621.5 | O9: =L9/F9 -> 0.67457732 | R9: 749294.21 | U9: =R9/F9 -> 0.17913703
D10: =D9+1 -> 46026 | E10: 日 | F10: 5433229 | I10: 171722 | L10: 3522300.7 | O10: =L10/F10 -> 0.64828866 | R10: 834523.13 | U10: =R10/F10 -> 0.15359616
D11: =D10+1 -> 46027 | E11: 一 | F11: 5215558.1 | I11: 168851 | L11: 3460227 | O11: =L11/F11 -> 0.6634433 | R11: 816505.38 | U11: =R11/F11 -> 0.15655187
B12: =B5+7 -> 46036 | D12: =D11+1 -> 46028 | E12: 二 | F12: 5249227.5 | G12: =SUM(F12:F18) -> 34195480 | I12: 174288 | J12: =SUM(I12:I18) -> 1121087 | L12: 3378121.4 | M12: =SUM(L12:L18) -> 22489488 | O12: =L12/F12 -> 0.64354639 | P12: =M12/G12 -> 0.65767428 | R12: 823625.84 | S12: =SUM(R12:R18) -> 5589312.6 | U12: =R12/F12 -> 0.1569042 | V12: =S12/G12 -> 0.16345179
D13: =D12+1 -> 46029 | E13: 三 | F13: 5156925.3 | I13: 171001 | L13: 3445251.4 | O13: =L13/F13 -> 0.66808247 | R13: 816957.91 | U13: =R13/F13 -> 0.15841957
D14: =D13+1 -> 46030 | E14: 四 | F14: 4787771.4 | I14: 156400 | L14: 3160620.1 | O14: =L14/F14 -> 0.66014433 | R14: 806511.29 | U14: =R14/F14 -> 0.16845234
D15: =D14+1 -> 46031 | E15: 五 | F15: 3992298.3 | I15: 132095 | L15: 2592277.5 | O15: =L15/F15 -> 0.64931959 | R15: 748811.7 | U15: =R15/F15 -> 0.18756407
D16: =D15+1 -> 46032 | E16: 六 | F16: 4224538.2 | I16: 138394 | L16: 2721735 | O16: =L16/F16 -> 0.64426804 | R16: 759551.91 | U16: =R16/F16 -> 0.17979525
D17: =D16+1 -> 46033 | E17: 日 | F17: 5539416.9 | I17: 178077 | L17: 3719632.8 | O17: =L17/F17 -> 0.67148454 | R17: 833013.1 | U17: =R17/F17 -> 0.1503792
D18: =D17+1 -> 46034 | E18: 一 | F18: 5245302.3 | I18: 170832 | L18: 3471849.4 | O18: =L18/F18 -> 0.66189691 | R18: 800840.82 | U18: =R18/F18 -> 0.15267772
B19: =B12+7 -> 46043 | D19: =D18+1 -> 46035 | E19: 二 | F19: 5099657 | G19: =SUM(F19:F25) -> 33161159 | I19: 169120 | J19: =SUM(I19:I25) -> 1095713 | L19: 3379653.1 | M19: =SUM(L19:L25) -> 21779479 | O19: =L19/F19 -> 0.66272165 | P19: =M19/G19 -> 0.65677677 | R19: 815995.46 | S19: =SUM(R19:R25) -> 5508030.2 | U19: =R19/F19 -> 0.16000987 | V19: =S19/G19 -> 0.16609885
D20: =D19+1 -> 46036 | E20: 三 | F20: 4896820.7 | I20: 162179 | L20: 3228569.8 | O20: =L20/F20 -> 0.65931959 | R20: 800688.75 | U20: =R20/F20 -> 0.16351196
D21: =D20+1 -> 46037 | E21: 四 | F21: 4477044.2 | I21: 149377 | L21: 2975803.6 | O21: =L21/F21 -> 0.66468041 | R21: 770496.8 | U21: =R21/F21 -> 0.17209944
D22: =D21+1 -> 46038 | E22: 五 | F22: 3898014.1 | I22: 131262 | L22: 2466357.9 | O22: =L22/F22 -> 0.63272165 | R22: 752479.98 | U22: =R22/F22 -> 0.19304188
D23: =D22+1 -> 46039 | E23: 六 | F23: 4192072.2 | I23: 138888 | L23: 2862018.5 | O23: =L23/F23 -> 0.68272165 | R23: 746099.49 | U23: =R23/F23 -> 0.17797868
D24: =D23+1 -> 46040 | E24: 日 | F24: 5422198.4 | I24: 175701 | L24: 3585582.4 | O24: =L24/F24 -> 0.66127835 | R24: 820754.13 | U24: =R24/F24 -> 0.15136925
D25: =D24+1 -> 46041 | E25: 一 | F25: 5175352.3 | I25: 169186 | L25: 3281493.5 | O25: =L25/F25 -> 0.63406186 | R25: 801515.61 | U25: =R25/F25 -> 0.1548717
B26: =B19+7 -> 46050 | D26: =D25+1 -> 46042 | E26: 二 | F26: 5709399.8 | G26: =SUM(F26:F32) -> 33925348 | I26: 181180 | J26: =SUM(I26:I32) -> 1096366 | L26: 3774913.9 | M26: =SUM(L26:L32) -> 22388797 | O26: =L26/F26 -> 0.66117526 | P26: =M26/G26 -> 0.65994302 | R26: 835978.46 | S26: =SUM(R26:R32) -> 5364280.8 | U26: =R26/F26 -> 0.14642142 | V26: =S26/G26 -> 0.15812014
D27: =D26+1 -> 46043 | E27: 三 | F27: 5079869.2 | I27: 167291 | L27: 3360778.6 | O27: =L27/F27 -> 0.66158763 | R27: 789425.39 | U27: =R27/F27 -> 0.1554027
D28: =D27+1 -> 46044 | E28: 四 | F28: 4686919.8 | I28: 153715 | L28: 3092110.8 | O28: =L28/F28 -> 0.65973196 | R28: 748901.32 | U28: =R28/F28 -> 0.15978539
D29: =D28+1 -> 46045 | E29: 五 | F29: 3890561.4 | I29: 127797 | L29: 2523811.2 | O29: =L29/F29 -> 0.64870103 | R29: 703121.61 | U29: =R29/F29 -> 0.18072497
D30: =D29+1 -> 46046 | E30: 六 | F30: 4094540 | I30: 133316 | L30: 2783189.7 | O30: =L30/F30 -> 0.67973196 | R30: 717320.73 | U30: =R30/F30 -> 0.17518958
D31: =D30+1 -> 46047 | E31: 日 | F31: 5451395.5 | I31: 171924 | L31: 3585219.8 | O31: =L31/F31 -> 0.6576701 | R31: 809541.44 | U31: =R31/F31 -> 0.14850169
D32: =D31+1 -> 46048 | E32: 一 | F32: 5012662.3 | I32: 161143 | L32: 3268772.6 | O32: =L32/F32 -> 0.65210309 | R32: 759991.89 | U32: =R32/F32 -> 0.15161442
B33: =B26+7 -> 46057 | D33: =D32+1 -> 46049 | E33: 二 | G33: =SUM(F33:F39) -> 0 | J33: =SUM(I33:I39) -> 0 | M33: =SUM(L33:L39) -> 0 | O33: =L33/F33 -> #DIV/0! | P33: =M33/G33 -> #DIV/0! | S33: =SUM(R33:R39) -> 0 | U33: =R33/F33 -> #DIV/0! | V33: =S33/G33 -> #DIV/0!
D34: =D33+1 -> 46050 | E34: 三 | O34: =L34/F34 -> #DIV/0! | U34: =R34/F34 -> #DIV/0!
D35: =D34+1 -> 46051 | E35: 四 | O35: =L35/F35 -> #DIV/0! | U35: =R35/F35 -> #DIV/0!
D36: =D35+1 -> 46052 | E36: 五 | O36: =L36/F36 -> #DIV/0! | U36: =R36/F36 -> #DIV/0!
D37: =D36+1 -> 46053 | E37: 六 | O37: =L37/F37 -> #DIV/0! | U37: =R37/F37 -> #DIV/0!
D38: =D37+1 -> 46054 | E38: 日 | O38: =L38/F38 -> #DIV/0! | U38: =R38/F38 -> #DIV/0!
D39: =D38+1 -> 46055 | E39: 一 | O39: =L39/F39 -> #DIV/0! | U39: =R39/F39 -> #DIV/0!
B40: =B33+7 -> 46064 | D40: =D39+1 -> 46056 | E40: 二 | G40: =SUM(F40:F46) -> 0 | J40: =SUM(I40:I46) -> 0 | M40: =SUM(L40:L46) -> 0 | O40: =L40/F40 -> #DIV/0! | P40: =M40/G40 -> #DIV/0! | S40: =SUM(R40:R46) -> 0 | U40: =R40/F40 -> #DIV/0! | V40: =S40/G40 -> #DIV/0!
D41: =D40+1 -> 46057 | E41: 三 | O41: =L41/F41 -> #DIV/0! | U41: =R41/F41 -> #DIV/0!
...

Sheet （２）ＫＰＩ達成進度
B1: 人時生產性基準值 | C1: 497.6
B2: （２）ＫＰＩ達成進度
B3: 資料繳交日 | C3: 月份 | D3: 日期 | F3: 人時生產性(個/人) | I3: 人時生產性達成率(%) | L3: 半成品報廢(%) | O3: 半成品超用(%) | R3: 固定產線-導入率(固定產線數/總產線數) | U3: 教育訓練-實施率(進度/計畫)
F4: 日 | G4: 週平均 | H4: 月平均 | I4: 日 | J4: 週平均 | K4: 月平均 | L4: 日 | M4: 週平均 | N4: 月平均 | O4: 日 | P4: 週平均 | Q4: 月平均 | R4: 日 | S4: 週平均 | T4: 月平均 | U4: 日 | V4: 週平均 | W4: 月平均
B5: 46029 | D5: 46021 | E5: 二 | F5: 440.60228 | G5: =AVERAGE(F5:F11) -> 447.97015 | I5: =F5/$C$1 -> 0.88545475 | J5: =AVERAGE(I5:I11) -> 0.90026155 | L5: 0.0024159468 | M5: =AVERAGE(L5:L11) -> 0.0024173357 | O5: 0.0058219496 | P5: =AVERAGE(O5:O11) -> 0.0057340977 | R5: 0.9 | S5: =AVERAGE(R5:R11) -> 0.9 | U5: =52/52*100% -> 1 | V5: =AVERAGE(U5:U11) -> 0.29945055
D6: 46022 | E6: 三 | F6: 440.80433 | I6: =F6/$C$1 -> 0.88586079 | L6: 0.0024122386 | O6: 0.0058017357 | R6: 0.9 | U6: =52/52*100% -> 1
C7: 一 | D7: =D6+1 -> 46023 | E7: 四 | F7: 440.8693 | H7: =AVERAGEIF(F7:F37,"<>0") -> 455.63186 | I7: =F7/$C$1 -> 0.88599135 | K7: =AVERAGEIF(I7:I37,"<>0") -> 0.91565889 | L7: 0.0024220732 | N7: =AVERAGEIF(L7:L37,"<>0") -> 0.0024146726 | O7: 0.005872848 | Q7: =AVERAGEIF(O7:O37,"<>0") -> 0.0056219258 | R7: 0.9 | T7: =AVERAGEIF(R7:R37,"<>0") -> 0.9 | U7: =1/52*100% -> 0.019230769 | W7: =AVERAGEIF(U7:U37,"<>0") -> 0.050295858
D8: =D7+1 -> 46024 | E8: 五 | F8: 463.40281 | I8: =F8/$C$1 -> 0.93127575 | L8: 0.0024156114 | O8: 0.0056425943 | R8: 0.9 | U8: =1/52*100% -> 0.019230769
D9: =D8+1 -> 46025 | E9: 六 | F9: 463.53185 | I9: =F9/$C$1 -> 0.93153507 | L9: 0.0024240751 | O9: 0.0058074651 | R9: 0.9 | U9: =1/52*100% -> 0.019230769
D10: =D9+1 -> 46026 | E10: 日 | F10: 442.23485 | I10: =F10/$C$1 -> 0.88873563 | L10: 0.0024174926 | O10: 0.0055999118 | R10: 0.9 | U10: =1/52*100% -> 0.019230769
D11: =D10+1 -> 46027 | E11: 一 | F11: 444.3456 | I11: =F11/$C$1 -> 0.89297749 | L11: 0.0024139122 | O11: 0.0055921795 | R11: 0.9 | U11: =1/52*100% -> 0.019230769
B12: =B5+7 -> 46036 | D12: =D11+1 -> 46028 | E12: 二 | F12: 440.89877 | G12: =AVERAGE(F12:F18) -> 440.0566 | I12: =F12/$C$1 -> 0.88605058 | J12: =AVERAGE(I12:I18) -> 0.88435812 | L12: 0.0024139636 | M12: =AVERAGE(L12:L18) -> 0.0024104171 | O12: 0.0055846081 | P12: =AVERAGE(O12:O18) -> 0.0055868919 | R12: 0.9 | S12: =AVERAGE(R12:R18) -> 0.9 | U12: =2/52*100% -> 0.038461538 | V12: =AVERAGE(U12:U18) -> 0.038461538
D13: =D12+1 -> 46029 | E13: 三 | F13: 441.45466 | I13: =F13/$C$1 -> 0.88716772 | L13: 0.0024075363 | O13: 0.0056016447 | R13: 0.9 | U13: =2/52*100% -> 0.038461538
D14: =D13+1 -> 46030 | E14: 四 | F14: 438.9474 | I14: =F14/$C$1 -> 0.88212902 | L14: 0.0024079022 | O14: 0.0055576109 | R14: 0.9 | U14: =2/52*100% -> 0.038461538
D15: =D14+1 -> 46031 | E15: 五 | F15: 437.5021 | I15: =F15/$C$1 -> 0.87922448 | L15: 0.0024035889 | O15: 0.0055400322 | R15: 0.9 | U15: =2/52*100% -> 0.038461538
D16: =D15+1 -> 46032 | E16: 六 | F16: 439.86336 | I16: =F16/$C$1 -> 0.88396977 | L16: 0.0024198592 | O16: 0.0056553493 | R16: 0.9 | U16: =2/52*100% -> 0.038461538
D17: =D16+1 -> 46033 | E17: 日 | F17: 440.72648 | I17: =F17/$C$1 -> 0.88570435 | L17: 0.0024119192 | O17: 0.005625184 | R17: 0.9 | U17: =2/52*100% -> 0.038461538
D18: =D17+1 -> 46034 | E18: 一 | F18: 441.00343 | I18: =F18/$C$1 -> 0.88626091 | L18: 0.0024081507 | O18: 0.005543814 | R18: 0.9 | U18: =2/52*100% -> 0.038461538
B19: =B12+7 -> 46043 | D19: =D18+1 -> 46035 | E19: 二 | F19: 456.62187 | G19: =AVERAGE(F19:F25) -> 463.69602 | I19: =F19/$C$1 -> 0.91764845 | J19: =AVERAGE(I19:I25) -> 0.931865 | L19: 0.0024037991 | M19: =AVERAGE(L19:L25) -> 0.0024117997 | O19: 0.0055260677 | P19: =AVERAGE(O19:O25) -> 0.0055709665 | R19: 0.9 | S19: =AVERAGE(R19:R25) -> 0.9 | U19: =3/52*100% -> 0.057692308 | V19: =AVERAGE(U19:U25) -> 0.057692308
D20: =D19+1 -> 46036 | E20: 三 | F20: 456.81046 | I20: =F20/$C$1 -> 0.91802745 | L20: 0.0024043348 | O20: 0.0055230113 | R20: 0.9 | U20: =3/52*100% -> 0.057692308
D21: =D20+1 -> 46037 | E21: 四 | F21: 456.86978 | I21: =F21/$C$1 -> 0.91814666 | L21: 0.0024040082 | O21: 0.0054763851 | R21: 0.9 | U21: =3/52*100% -> 0.057692308
D22: =D21+1 -> 46038 | E22: 五 | F22: 482.14238 | I22: =F22/$C$1 -> 0.96893566 | L22: 0.0024202418 | O22: 0.0055601032 | R22: 0.9 | U22: =3/52*100% -> 0.057692308
D23: =D22+1 -> 46039 | E23: 六 | F23: 479.63067 | I23: =F23/$C$1 -> 0.963888 | L23: 0.0024142007 | O23: 0.0056116122 | R23: 0.9 | U23: =3/52*100% -> 0.057692308
D24: =D23+1 -> 46040 | E24: 日 | F24: 457.39343 | I24: =F24/$C$1 -> 0.91919901 | L24: 0.0024159528 | O24: 0.0056241436 | R24: 0.9 | U24: =3/52*100% -> 0.057692308
D25: =D24+1 -> 46041 | E25: 一 | F25: 456.40359 | I25: =F25/$C$1 -> 0.91720979 | L25: 0.0024200607 | O25: 0.0056754426 | R25: 0.9 | U25: =3/52*100% -> 0.057692308
B26: =B19+7 -> 46050 | D26: =D25+1 -> 46042 | E26: 二 | F26: 455.46638 | G26: =AVERAGE(F26:F32) -> 466.53938 | I26: =F26/$C$1 -> 0.91532632 | J26: =AVERAGE(I26:I32) -> 0.93757914 | L26: 0.0024279547 | M26: =AVERAGE(L26:L32) -> 0.0024189722 | O26: 0.0057649191 | P26: =AVERAGE(O26:O32) -> 0.005650009 | R26: 0.9 | S26: =AVERAGE(R26:R32) -> 0.9 | U26: =4/52*100% -> 0.076923077 | V26: =AVERAGE(U26:U32) -> 0.076923077
D27: =D26+1 -> 46043 | E27: 三 | F27: 457.17927 | I27: =F27/$C$1 -> 0.91876864 | L27: 0.0024238598 | O27: 0.005635773 | R27: 0.9 | U27: =4/52*100% -> 0.076923077
D28: =D27+1 -> 46044 | E28: 四 | F28: 457.38336 | I28: =F28/$C$1 -> 0.91917878 | L28: 0.0024181957 | O28: 0.0055916716 | R28: 0.9 | U28: =4/52*100% -> 0.076923077
D29: =D28+1 -> 46045 | E29: 五 | F29: 481.48416 | I29: =F29/$C$1 -> 0.96761286 | L29: 0.0024142471 | O29: 0.0058235341 | R29: 0.9 | U29: =4/52*100% -> 0.076923077
D30: =D29+1 -> 46046 | E30: 六 | F30: 486.54463 | I30: =F30/$C$1 -> 0.97778262 | L30: 0.0024123421 | O30: 0.0056244632 | R30: 0.9 | U30: =4/52*100% -> 0.076923077
D31: =D30+1 -> 46047 | E31: 日 | F31: 463.63629 | I31: =F31/$C$1 -> 0.93174495 | L31: 0.0024223209 | O31: 0.0055695871 | R31: 0.9 | U31: =4/52*100% -> 0.076923077
D32: =D31+1 -> 46048 | E32: 一 | F32: 464.08157 | I32: =F32/$C$1 -> 0.93263982 | L32: 0.0024138854 | O32: 0.0055401145 | R32: 0.9 | U32: =4/52*100% -> 0.076923077
B33: =B26+7 -> 46057 | D33: =D32+1 -> 46049 | E33: 二 | G33: =AVERAGE(F33:F39) -> #DIV/0! | I33: =F33/$C$1 -> 0 | J33: =AVERAGE(I33:I39) -> 0 | M33: =AVERAGE(L33:L39) -> #DIV/0! | P33: =AVERAGE(O33:O39) -> #DIV/0! | S33: =AVERAGE(R33:R39) -> #DIV/0! | V33: =AVERAGE(U33:U39) -> #DIV/0!
D34: =D33+1 -> 46050 | E34: 三 | I34: =F34/$C$1 -> 0
D35: =D34+1 -> 46051 | E35: 四 | I35: =F35/$C$1 -> 0
D36: =D35+1 -> 46052 | E36: 五 | I36: =F36/$C$1 -> 0
D37: =D36+1 -> 46053 | E37: 六 | I37: =F37/$C$1 -> 0
D38: =D37+1 -> 46054 | E38: 日 | I38: =F38/$C$1 -> 0
D39: =D38+1 -> 46055 | E39: 一 | I39: =F39/$C$1 -> 0
B40: =B33+7 -> 46064 | D40: =D39+1 -> 46056 | E40: 二 | G40: =AVERAGE(F40:F46) -> #DIV/0! | I40: =F40/$C$1 -> 0 | J40: =AVERAGE(I40:I46) -> 0 | M40: =AVERAGE(L40:L46) -> #DIV/0! | P40: =AVERAGE(O40:O46) -> #DIV/0! | S40: =AVERAGE(R40:R46) -> #DIV/0! | V40: =AVERAGE(U40:U46) -> #DIV/0!
...

Sheet （３）業績構成比
B2: （3）業績構成比
B3: 資料繳交日 | C3: 月份 | D3: 日期 | F3: 營業額 | I3: 品類業績
I4: 18℃-飯糰 | O4: 18℃-壽司手卷 | U4: 4℃-飯糰 | W4: 4℃-壽司手卷 | Y4: 主食 | AE4: 便當 | AG4: 熱食義麵 | AI4: 季節調理麵 | AK4: 微波小吃
F5: 日 | G5: 週累積 | H5: 月累積 | I5: 一配 | K5: 二配 | M5: 合計 | O5: 一配 | Q5: 二配 | S5: 合計 | U5: 一配 | W5: 一配 | Y5: 一配 | AA5: 二配 | AC5: 合計 | AE5: 一配 | AG5: 一配 | AI5: 一配 | AK5: 一配
I6: 業績(元) | J6: 比例(%) | K6: 業績(元) | L6: 比例(%) | M6: 業績(元) | N6: 比例(%) | O6: 業績(元) | P6: 比例(%) | Q6: 業績(元) | R6: 比例(%) | S6: 業績(元) | T6: 比例(%) | U6: 業績(元) | V6: 比例(%) | W6: 業績(元) | X6: 比例(%) | Y6: 業績(元) | Z6: 比例(%) | AA6: 業績(元) | AB6: 比例(%) | AC6: 業績(元) | AD6: 比例(%) | AE6: 業績(元) | AF6: 比例(%) | AG6: 業績(元) | AH6: 比例(%) | AI6: 業績(元) | AJ6: 比例(%) | AK6: 業績(元) | AL6: 比例(%)
B7: =D15 -> 46029 | D7: 46021 | E7: 二 | F7: =SUM(M7,S7,U7,W7,AC7,AE7,AG7,AI7,AK7) -> 4991542.2 | G7: =SUM(F7:F13) -> 32267367 | I7: 802705.93 | J7: =I7/$F7 -> 0.16081321 | K7: 896992.84 | L7: =K7/$F7 -> 0.17970255 | M7: =I7+K7 -> 1699698.8 | N7: =M7/$F7 -> 0.34051576 | O7: 261073.92 | P7: =O7/$F7 -> 0.052303259 | Q7: 154968.15 | R7: =Q7/$F7 -> 0.031046147 | S7: =O7+Q7 -> 416042.07 | T7: =S7/$F7 -> 0.083349405 | U7: 126348.91 | V7: =U7/$F7 -> 0.0253126 | W7: 0 | X7: =W7/$F7 -> 0 | Y7: 216293.7 | Z7: =Y7/$F7 -> 0.043332039 | AA7: 702239.58 | AB7: =AA7/$F7 -> 0.1406859 | AC7: =Y7+AA7 -> 918533.28 | AD7: =AC7/$F7 -> 0.18401793 | AE7: 1335435.9 | AF7: =AE7/F7 -> 0.26753974 | AG7: 197570.4 | AH7: =AG7/$F7 -> 0.039581034 | AI7: 122009.18 | AJ7: =AI7/$F7 -> 0.024443183 | AK7: 175903.66 | AL7: =AK7/$F7 -> 0.035240343
D8: 46022 | E8: 三 | F8: =SUM(M8,S8,U8,W8,AC8,AE8,AG8,AI8,AK8) -> 3992684.9 | I8: 538705.53 | J8: =I8/$F8 -> 0.13492313 | K8: 837711.87 | L8: =K8/$F8 -> 0.20981167 | M8: =I8+K8 -> 1376417.4 | N8: =M8/F8 -> 0.34473479 | O8: 201360.75 | P8: =O8/$F8 -> 0.050432417 | Q8: 127362.57 | R8: =Q8/$F8 -> 0.031898979 | S8: =O8+Q8 -> 328723.32 | T8: =S8/F8 -> 0.082331396 | U8: 99108.65 | V8: =U8/F8 -> 0.024822558 | W8: 0 | X8: =W8/$F8 -> 0 | Y8: 185183.74 | Z8: =Y8/$F8 -> 0.046380755 | AA8: 635625.71 | AB8: =AA8/$F8 -> 0.15919757 | AC8: =Y8+AA8 -> 820809.45 | AD8: =AC8/$F8 -> 0.20557832 | AE8: 936523.95 | AF8: =AE8/F8 -> 0.23455995 | AG8: 165654.3 | AH8: =AG8/$F8 -> 0.04148945 | AI8: 105301.12 | AJ8: =AI8/$F8 -> 0.026373511 | AK8: 160146.68 | AL8: =AK8/$F8 -> 0.040110023
C9: 一 | D9: 46023 | E9: 四 | F9: =SUM(M9,S9,U9,W9,AC9,AE9,AG9,AI9,AK9) -> 4613445.5 | H9: =SUM(F9:F39) -> 1.2456513e+08 | I9: 733836.13 | J9: =I9/$F9 -> 0.15906466 | K9: 867971.3 | L9: =K9/$F9 -> 0.1881395 | M9: =I9+K9 -> 1601807.4 | N9: =M9/$F9 -> 0.34720416 | O9: 258662.63 | P9: =O9/$F9 -> 0.056067127 | Q9: 152453 | R9: =Q9/$F9 -> 0.033045367 | S9: =O9+Q9 -> 411115.63 | T9: =S9/$F9 -> 0.089112494 | U9: 120898.22 | V9: =U9/$F9 -> 0.026205625 | W9: 0 | X9: =W9/$F9 -> 0 | Y9: 198751.77 | Z9: =Y9/$F9 -> 0.043080984 | AA9: 588606.35 | AB9: =AA9/$F9 -> 0.12758498 | AC9: =Y9+AA9 -> 787358.12 | AD9: =AC9/$F9 -> 0.17066597 | AE9: 1173809.6 | AF9: =AE9/F9 -> 0.25443232 | AG9: 198258 | AH9: =AG9/$F9 -> 0.042973956 | AI9: 137100.22 | AJ9: =AI9/$F9 -> 0.029717534 | AK9: 183098.18 | AL9: =AK9/$F9 -> 0.039687947
D10: 46024 | E10: 五 | F10: =SUM(M10,S10,U10,W10,AC10,AE10,AG10,AI10,AK10) -> 3838107.8 | I10: 616848.89 | J10: =I10/$F10 -> 0.16071693 | K10: 804129.28 | L10: =K10/$F10 -> 0.20951191 | M10: =I10+K10 -> 1420978.2 | N10: =M10/F10 -> 0.37022883 | O10: 181633.29 | P10: =O10/$F10 -> 0.047323655 | Q10: 126817.27 | R10: =Q10/$F10 -> 0.033041612 | S10: =O10+Q10 -> 308450.56 | T10: =S10/F10 -> 0.080365267 | U10: 89125.1 | V10: =U10/F10 -> 0.023221104 | W10: 0 | X10: =W10/$F10 -> 0 | Y10: 182856.17 | Z10: =Y10/$F10 -> 0.04764227 | AA10: 614873.41 | AB10: =AA10/$F10 -> 0.16020223 | AC10: =Y10+AA10 -> 797729.58 | AD10: =AC10/$F10 -> 0.2078445 | AE10: 841389.09 | AF10: =AE10/F10 -> 0.21921977 | AG10: 155283 | AH10: =AG10/$F10 -> 0.040458217 | AI10: 78120.3 | AJ10: =AI10/$F10 -> 0.020353858 | AK10: 147032 | AL10: =AK10/$F10 -> 0.03830846
D11: 46025 | E11: 六 | F11: =SUM(M11,S11,U11,W11,AC11,AE11,AG11,AI11,AK11) -> 4182799.2 | I11: 568561.79 | J11: =I11/$F11 -> 0.13592854 | K11: 909430.02 | L11: =K11/$F11 -> 0.21742139 | M11: =I11+K11 -> 1477991.8 | N11: =M11/$F11 -> 0.35334993 | O11: 158873.68 | P11: =O11/$F11 -> 0.037982622 | Q11: 117746.54 | R11: =Q11/$F11 -> 0.028150178 | S11: =O11+Q11 -> 276620.22 | T11: =S11/$F11 -> 0.0661328 | U11: 101228.33 | V11: =U11/$F11 -> 0.024201097 | W11: 0 | X11: =W11/$F11 -> 0 | Y11: 203463.68 | Z11: =Y11/$F11 -> 0.048642947 | AA11: 669974.6 | AB11: =AA11/$F11 -> 0.16017374 | AC11: =Y11+AA11 -> 873438.28 | AD11: =AC11/$F11 -> 0.20881669 | AE11: 1010860.2 | AF11: =AE11/F11 -> 0.24167074 | AG11: 172759.5 | AH11: =AG11/$F11 -> 0.041302365 | AI11: 110152.8 | AJ11: =AI11/$F11 -> 0.026334709 | AK11: 159748.05 | AL11: =AK11/$F11 -> 0.038191661
D12: 46026 | E12: 日 | F12: =SUM(M12,S12,U12,W12,AC12,AE12,AG12,AI12,AK12) -> 5433229 | I12: 821434.85 | J12: =I12/$F12 -> 0.15118723 | K12: 995961.99 | L12: =K12/$F12 -> 0.18330941 | M12: =I12+K12 -> 1817396.8 | N12: =M12/F12 -> 0.33449664 | O12: 267837.94 | P12: =O12/$F12 -> 0.049296273 | Q12: 143688.31 | R12: =Q12/$F12 -> 0.026446209 | S12: =O12+Q12 -> 411526.25 | T12: =S12/F12 -> 0.075742482 | U12: 133118.12 | V12: =U12/F12 -> 0.024500738 | W12: 0 | X12: =W12/$F12 -> 0 | Y12: 239455.86 | Z12: =Y12/$F12 -> 0.044072477 | AA12: 741705.58 | AB12: =AA12/$F12 -> 0.13651285 | AC12: =Y12+AA12 -> 981161.44 | AD12: =AC12/$F12 -> 0.18058533 | AE12: 1613752.9 | AF12: =AE12/F12 -> 0.29701543 | AG12: 202612.8 | AH12: =AG12/$F12 -> 0.037291415 | AI12: 103840.4 | AJ12: =AI12/$F12 -> 0.019112097 | AK12: 169820.28 | AL12: =AK12/$F12 -> 0.031255866
D13: 46027 | E13: 一 | F13: =SUM(M13,S13,U13,W13,AC13,AE13,AG13,AI13,AK13) -> 5215558.1 | I13: 791674.72 | J13: =I13/$F13 -> 0.15179099 | K13: 1050196.6 | L13: =K13/$F13 -> 0.20135844 | M13: =I13+K13 -> 1841871.3 | N13: =M13/$F13 -> 0.35314943 | O13: 237986.69 | P13: =O13/$F13 -> 0.045630149 | Q13: 143481.64 | R13: =Q13/$F13 -> 0.027510314 | S13: =O13+Q13 -> 381468.33 | T13: =S13/$F13 -> 0.073140463 | U13: 125146.84 | V13: =U13/$F13 -> 0.023994909 | W13: 0 | X13: =W13/$F13 -> 0 | Y13: 228272.17 | Z13: =Y13/$F13 -> 0.043767545 | AA13: 691812.51 | AB13: =AA13/$F13 -> 0.13264401 | AC13: =Y13+AA13 -> 920084.68 | AD13: =AC13/$F13 -> 0.17641155 | AE13: 1422290.7 | AF13: =AE13/F13 -> 0.27270154 | AG13: 203357.7 | AH13: =AG13/$F13 -> 0.038990593 | AI13: 128528.52 | AJ13: =AI13/$F13 -> 0.024643292 | AK13: 192809.95 | AL13: =AK13/$F13 -> 0.03696823
B14: =B7+7 -> 46036 | D14: 46028 | E14: 二 | F14: =SUM(M14,S14,U14,W14,AC14,AE14,AG14,AI14,AK14) -> 5249227.5 | G14: =SUM(F14:F20) -> 34195480 | I14: 884847.67 | J14: =I14/$F14 -> 0.16856722 | K14: 1045584.6 | L14: =K14/$F14 -> 0.19918828 | M14: =I14+K14 -> 1930432.3 | N14: =M14/$F14 -> 0.3677555 | O14: 239355.84 | P14: =O14/$F14 -> 0.045598298 | Q14: 154596.19 | R14: =Q14/$F14 -> 0.029451227 | S14: =O14+Q14 -> 393952.03 | T14: =S14/$F14 -> 0.075049526 | U14: 122235.25 | V14: =U14/$F14 -> 0.023286331 | W14: 74762 | X14: =W14/$F14 -> 0.014242477 | Y14: 225320.13 | Z14: =Y14/$F14 -> 0.042924436 | AA14: 647628.2 | AB14: =AA14/$F14 -> 0.12337591 | AC14: =Y14+AA14 -> 872948.33 | AD14: =AC14/$F14 -> 0.16630034 | AE14: 1364310.1 | AF14: =AE14/F14 -> 0.25990683 | AG14: 196710.9 | AH14: =AG14/$F14 -> 0.037474257 | AI14: 118337.16 | AJ14: =AI14/$F14 -> 0.022543729 | AK14: 175539.47 | AL14: =AK14/$F14 -> 0.03344101
D15: 46029 | E15: 三 | F15: =SUM(M15,S15,U15,W15,AC15,AE15,AG15,AI15,AK15) -> 5156925.3 | I15: 847957.46 | J15: =I15/$F15 -> 0.16443082 | K15: 1006063.3 | L15: =K15/$F15 -> 0.19508976 | M15: =I15+K15 -> 1854020.8 | N15: =M15/F15 -> 0.35952058 | O15: 239419.33 | P15: =O15/$F15 -> 0.046426759 | Q15: 159169.43 | R15: =Q15/$F15 -> 0.03086518 | S15: =O15+Q15 -> 398588.76 | T15: =S15/F15 -> 0.07729194 | U15: 115364.1 | V15: =U15/F15 -> 0.022370714 | W15: 70637.2 | X15: =W15/$F15 -> 0.013697542 | Y15: 47459.72 | Z15: =Y15/$F15 -> 0.009203104 | AA15: 641235.73 | AB15: =AA15/$F15 -> 0.12434458 | AC15: =Y15+AA15 -> 688695.45 | AD15: =AC15/$F15 -> 0.13354769 | AE15: 1409530.1 | AF15: =AE15/F15 -> 0.27332762 | AG15: 190694.4 | AH15: =AG15/$F15 -> 0.036978313 | AI15: 233237.76 | AJ15: =AI15/$F15 -> 0.045228066 | AK15: 196156.73 | AL15: =AK15/$F15 -> 0.038037536
D16: 46030 | E16: 四 | F16: =SUM(M16,S16,U16,W16,AC16,AE16,AG16,AI16,AK16) -> 4787771.4 | I16: 812165.65 | J16: =I16/$F16 -> 0.16963334 | K16: 895250.53 | L16: =K16/$F16 -> 0.1869869 | M16: =I16+K16 -> 1707416.2 | N16: =M16/$F16 -> 0.35662024 | O16: 234745.32 | P16: =O16/$F16 -> 0.049030186 | Q16: 148770.77 | R16: =Q16/$F16 -> 0.031073073 | S16: =O16+Q16 -> 383516.09 | T16: =S16/$F16 -> 0.080103259 | U16: 115227.25 | V16: =U16/$F16 -> 0.024066991 | W16: 10440.9 | X16: =W16/$F16 -> 0.0021807432 | Y16: 215101.53 | Z16: =Y16/$F16 -> 0.044927277 | AA16: 539460.28 | AB16: =AA16/$F16 -> 0.11267461 | AC16: =Y16+AA16 -> 754561.81 | AD16: =AC16/$F16 -> 0.15760189 | AE16: 1302891.7 | AF16: =AE16/F16 -> 0.27212905 | AG16: 173332.5 | AH16: =AG16/$F16 -> 0.03620317 | AI16: 137563.46 | AJ16: =AI16/$F16 -> 0.028732253 | AK16: 202821.52 | AL16: =AK16/$F16 -> 0.042362407
D17: 46031 | E17: 五 | F17: =SUM(M17,S17,U17,W17,AC17,AE17,AG17,AI17,AK17) -> 3992298.3 | I17: 660555.63 | J17: =I17/$F17 -> 0.16545748 | K17: 819793.64 | L17: =K17/$F17 -> 0.20534378 | M17: =I17+K17 -> 1480349.3 | N17: =M17/F17 -> 0.37080126 | O17: 154117.79 | P17: =O17/$F17 -> 0.038603776 | Q17: 118237.22 | R17: =Q17/$F17 -> 0.029616329 | S17: =O17+Q17 -> 272355.01 | T17: =S17/F17 -> 0.068220105 | U17: 89839.62 | V17: =U17/F17 -> 0.022503233 | W17: 37653.6 | X17: =W17/$F17 -> 0.0094315597 | Y17: 178144.26 | Z17: =Y17/$F17 -> 0.044621981 | AA17: 529134.13 | AB17: =AA17/$F17 -> 0.13253872 | AC17: =Y17+AA17 -> 707278.39 | AD17: =AC17/$F17 -> 0.17716071 | AE17: 1037369.5 | AF17: =AE17/F17 -> 0.25984267 | AG17: 137978.4 | AH17: =AG17/$F17 -> 0.034561145 | AI17: 86506.78 | AJ17: =AI17/$F17 -> 0.021668416 | AK17: 142967.8 | AL17: =AK17/$F17 -> 0.035810901
D18: 46032 | E18: 六 | F18: =SUM(M18,S18,U18,W18,AC18,AE18,AG18,AI18,AK18) -> 4224538.2 | I18: 618842.31 | J18: =I18/$F18 -> 0.14648756 | K18: 910163.82 | L18: =K18/$F18 -> 0.21544694 | M18: =I18+K18 -> 1529006.1 | N18: =M18/$F18 -> 0.3619345 | O18: 134935.16 | P18: =O18/$F18 -> 0.031940807 | Q18: 109950.09 | R18: =Q18/$F18 -> 0.026026535 | S18: =O18+Q18 -> 244885.25 | T18: =S18/$F18 -> 0.057967342 | U18: 97884.63 | V18: =U18/$F18 -> 0.023170492 | W18: 52504.05 | X18: =W18/$F18 -> 0.012428352 | Y18: 211014.09 | Z18: =Y18/$F18 -> 0.049949623 | AA18: 574904.44 | AB18: =AA18/$F18 -> 0.13608693 | AC18: =Y18+AA18 -> 785918.53 | AD18: =AC18/$F18 -> 0.18603655 | AE18: 1081209.9 | AF18: =AE18/F18 -> 0.25593564 | AG18: 152131.5 | AH18: =AG18/$F18 -> 0.036011392 | AI18: 119357.8 | AJ18: =AI18/$F18 -> 0.028253455 | AK18: 161640.43 | AL18: =AK18/$F18 -> 0.038262272
D19: 46033 | E19: 日 | F19: =SUM(M19,S19,U19,W19,AC19,AE19,AG19,AI19,AK19) -> 5539416.9 | I19: 880077.95 | J19: =I19/$F19 -> 0.15887556 | K19: 1015987.1 | L19: =K19/$F19 -> 0.18341048 | M19: =I19+K19 -> 1896065.1 | N19: =M19/F19 -> 0.34228604 | O19: 229298.65 | P19: =O19/$F19 -> 0.041394005 | Q19: 141500.74 | R19: =Q19/$F19 -> 0.025544338 | S19: =O19+Q19 -> 370799.39 | T19: =S19/F19 -> 0.066938343 | U19: 125385.72 | V19: =U19/F19 -> 0.022635184 | W19: 97677.55 | X19: =W19/$F19 -> 0.017633183 | Y19: 236901.21 | Z19: =Y19/$F19 -> 0.042766452 | AA19: 676723.34 | AB19: =AA19/$F19 -> 0.12216508 | AC19: =Y19+AA19 -> 913624.55 | AD19: =AC19/$F19 -> 0.16493154 | AE19: 1673735 | AF19: =AE19/F19 -> 0.30215003 | AG19: 177171.6 | AH19: =AG19/$F19 -> 0.031983799 | AI19: 123572 | AJ19: =AI19/$F19 -> 0.022307763 | AK19: 161386.03 | AL19: =AK19/$F19 -> 0.029134119
D20: 46034 | E20: 一 | F20: =SUM(M20,S20,U20,W20,AC20,AE20,AG20,AI20,AK20) -> 5245302.3 | I20: 862582.66 | J20: =I20/$F20 -> 0.16444861 | K20: 989835.57 | L20: =K20/$F20 -> 0.18870897 | M20: =I20+K20 -> 1852418.2 | N20: =M20/$F20 -> 0.35315757 | O20: 213786.17 | P20: =O20/$F20 -> 0.040757645 | Q20: 141697.06 | R20: =Q20/$F20 -> 0.027014088 | S20: =O20+Q20 -> 355483.23 | T20: =S20/$F20 -> 0.067771734 | U20: 117787.16 | V20: =U20/$F20 -> 0.022455743 | W20: 64541.3 | X20: =W20/$F20 -> 0.012304591 | Y20: 211979.18 | Z20: =Y20/$F20 -> 0.040413148 | AA20: 628443.53 | AB20: =AA20/$F20 -> 0.11981074 | AC20: =Y20+AA20 -> 840422.71 | AD20: =AC20/$F20 -> 0.16022388 | AE20: 1482471.8 | AF20: =AE20/F20 -> 0.28262848 | AG20: 187542.9 | AH20: =AG20/$F20 -> 0.03575445 | AI20: 162804.68 | AJ20: =AI20/$F20 -> 0.031038188 | AK20: 181830.29 | AL20: =AK20/$F20 -> 0.03466536
B21: =B14+7 -> 46043 | D21: 46035 | E21: 二 | F21: =SUM(M21,S21,U21,W21,AC21,AE21,AG21,AI21,AK21) -> 5099657 | G21: =SUM(F21:F27) -> 33161159 | I21: 942550.84 | J21: =I21/$F21 -> 0.18482632 | K21: 970515.5 | L21: =K21/$F21 -> 0.19030996 | M21: =I21+K21 -> 1913066.3 | N21: =M21/$F21 -> 0.37513628 | O21: 203416.82 | P21: =O21/$F21 -> 0.039888334 | Q21: 142952 | R21: =Q21/$F21 -> 0.028031689 | S21: =O21+Q21 -> 346368.82 | T21: =S21/$F21 -> 0.067920023 | U21: 121455.03 | V21: =U21/$F21 -> 0.023816314 | W21: 50583.5 | X21: =W21/$F21 -> 0.0099190005 | Y21: 198978.85 | Z21: =Y21/$F21 -> 0.039018085 | AA21: 623949.2 | AB21: =AA21/$F21 -> 0.12235121 | AC21: =Y21+AA21 -> 822928.05 | AD21: =AC21/$F21 -> 0.16136929 | AE21: 1360429.2 | AF21: =AE21/F21 -> 0.26676878 | AG21: 169035 | AH21: =AG21/$F21 -> 0.033146347 | AI21: 136492.8 | AJ21: =AI21/$F21 -> 0.026765094 | AK21: 179298.2 | AL21: =AK21/$F21 -> 0.035158874
D22: 46036 | E22: 三 | F22: =SUM(M22,S22,U22,W22,AC22,AE22,AG22,AI22,AK22) -> 4896820.7 | I22: 878533.38 | J22: =I22/$F22 -> 0.17940893 | K22: 924108.3 | L22: =K22/$F22 -> 0.18871598 | M22: =I22+K22 -> 1802641.7 | N22: =M22/F22 -> 0.36812491 | O22: 213825.17 | P22: =O22/$F22 -> 0.043666122 | Q22: 146439.05 | R22: =Q22/$F22 -> 0.029904924 | S22: =O22+Q22 -> 360264.22 | T22: =S22/F22 -> 0.073571045 | U22: 110481.03 | V22: =U22/F22 -> 0.022561788 | W22: 69653.75 | X22: =W22/$F22 -> 0.01422428 | Y22: 188306.09 | Z22: =Y22/$F22 -> 0.038454765 | AA22: 567026.74 | AB22: =AA22/$F22 -> 0.11579487 | AC22: =Y22+AA22 -> 755332.83 | AD22: =AC22/$F22 -> 0.15424964 | AE22: 1331077.4 | AF22: =AE22/F22 -> 0.27182481 | AG22: 160210.8 | AH22: =AG22/$F22 -> 0.03271731 | AI22: 136147.58 | AJ22: =AI22/$F22 -> 0.02780326 | AK22: 171011.49 | AL22: =AK22/$F22 -> 0.034922963
D23: 46037 | E23: 四 | F23: =SUM(M23,S23,U23,W23,AC23,AE23,AG23,AI23,AK23) -> 4477044.2 | I23: 834491.21 | J23: =I23/$F23 -> 0.18639334 | K23: 833194.26 | L23: =K23/$F23 -> 0.18610365 | M23: =I23+K23 -> 1667685.5 | N23: =M23/$F23 -> 0.37249698 | O23: 218131.67 | P23: =O23/$F23 -> 0.04872225 | Q23: 143287.52 | R23: =Q23/$F23 -> 0.032004937 | S23: =O23+Q23 -> 361419.19 | T23: =S23/$F23 -> 0.080727188 | U23: 108850.53 | V23: =U23/$F23 -> 0.024313034 | W23: 47770.3 | X23: =W23/$F23 -> 0.010670053 | Y23: 185354.05 | Z23: =Y23/$F23 -> 0.041400987 | AA23: 470354.39 | AB23: =AA23/$F23 -> 0.10505913 | AC23: =Y23+AA23 -> 655708.44 | AD23: =AC23/$F23 -> 0.14646012 | AE23: 1122061.9 | AF23: =AE23/F23 -> 0.2506256 | AG23: 158892.9 | AH23: =AG23/$F23 -> 0.035490581 | AI23: 189929.56 | AJ23: =AI23/$F23 -> 0.04242298 | AK23: 164725.96 | AL23: =AK23/$F23 -> 0.036793463
D24: 46038 | E24: 五 | F24: =SUM(M24,S24,U24,W24,AC24,AE24,AG24,AI24,AK24) -> 3898014.1 | I24: 716969.34 | J24: =I24/$F24 -> 0.18393195 | K24: 797548.95 | L24: =K24/$F24 -> 0.20460392 | M24: =I24+K24 -> 1514518.3 | N24: =M24/F24 -> 0.38853587 | O24: 143324.36 | P24: =O24/$F24 -> 0.036768559 | Q24: 119907.69 | R24: =Q24/$F24 -> 0.030761225 | S24: =O24+Q24 -> 263232.05 | T24: =S24/F24 -> 0.067529784 | U24: 86872.4 | V24: =U24/F24 -> 0.022286323 | W24: 50015.45 | X24: =W24/$F24 -> 0.012831008 | Y24: 185240.51 | Z24: =Y24/$F24 -> 0.047521765 | AA24: 490854.95 | AB24: =AA24/$F24 -> 0.12592437 | AC24: =Y24+AA24 -> 676095.46 | AD24: =AC24/$F24 -> 0.17344613 | AE24: 913609.28 | AF24: =AE24/F24 -> 0.23437814 | AG24: 120100.8 | AH24: =AG24/$F24 -> 0.030810766 | AI24: 139486.12 | AJ24: =AI24/$F24 -> 0.035783893 | AK24: 134084.23 | AL24: =AK24/$F24 -> 0.034398088
D25: 46039 | E25: 六 | F25: =SUM(M25,S25,U25,W25,AC25,AE25,AG25,AI25,AK25) -> 4192072.2 | I25: 676753.55 | J25: =I25/$F25 -> 0.16143652 | K25: 905744.45 | L25: =K25/$F25 -> 0.21606127 | M25: =I25+K25 -> 1582498 | N25: =M25/$F25 -> 0.37749779 | O25: 132818.53 | P25: =O25/$F25 -> 0.031683264 | Q25: 114455.77 | R25: =Q25/$F25 -> 0.02730291 | S25: =O25+Q25 -> 247274.3 | T25: =S25/$F25 -> 0.058986174 | U25: 95610.59 | V25: =U25/$F25 -> 0.022807477 | W25: 40953.7 | X25: =W25/$F25 -> 0.0097693212 | Y25: 199773.63 | Z25: =Y25/$F25 -> 0.047655102 | AA25: 532967.31 | AB25: =AA25/$F25 -> 0.12713696 | AC25: =Y25+AA25 -> 732740.94 | AD25: =AC25/$F25 -> 0.17479206 | AE25: 1025917.5 | AF25: =AE25/F25 -> 0.24472802 | AG25: 142619.7 | AH25: =AG25/$F25 -> 0.034021289 | AI25: 172861.88 | AJ25: =AI25/$F25 -> 0.041235425 | AK25: 151595.6 | AL25: =AK25/$F25 -> 0.036162449
D26: 46040 | E26: 日 | F26: =SUM(M26,S26,U26,W26,AC26,AE26,AG26,AI26,AK26) -> 5422198.4 | I26: 943211.11 | J26: =I26/$F26 -> 0.17395363 | K26: 999031.08 | L26: =K26/$F26 -> 0.18424834 | M26: =I26+K26 -> 1942242.2 | N26: =M26/F26 -> 0.35820198 | O26: 219539.53 | P26: =O26/$F26 -> 0.040489026 | Q26: 140913.34 | R26: =Q26/$F26 -> 0.02598823 | S26: =O26+Q26 -> 360452.87 | T26: =S26/F26 -> 0.066477256 | U26: 120740.76 | V26: =U26/F26 -> 0.022267861 | W26: 61755.15 | X26: =W26/$F26 -> 0.01138932 | Y26: 226398.76 | Z26: =Y26/$F26 -> 0.041754053 | AA26: 643776.31 | AB26: =AA26/$F26 -> 0.11872976 | AC26: =Y26+AA26 -> 870175.07 | AD26: =AC26/$F26 -> 0.16048381 | AE26: 1613452.1 | AF26: =AE26/F26 -> 0.2975642 | AG26: 159294 | AH26: =AG26/$F26 -> 0.029378121 | AI26: 146285.76 | AJ26: =AI26/$F26 -> 0.02697905 | AK26: 147800.49 | AL26: =AK26/$F26 -> 0.027258407
D27: 46041 | E27: 一 | F27: =SUM(M27,S27,U27,W27,AC27,AE27,AG27,AI27,AK27) -> 5175352.3 | I27: 901600.28 | J27: =I27/$F27 -> 0.17421042 | K27: 975742.68 | L27: =K27/$F27 -> 0.18853647 | M27: =I27+K27 -> 1877343 | N27: =M27/$F27 -> 0.36274689 | O27: 203740.16 | P27: =O27/$F27 -> 0.039367399 | Q27: 143234.99 | R27: =Q27/$F27 -> 0.027676375 | S27: =O27+Q27 -> 346975.15 | T27: =S27/$F27 -> 0.067043774 | U27: 115409.96 | V27: =U27/$F27 -> 0.022299923 | W27: 60997.75 | X27: =W27/$F27 -> 0.011786202 | Y27: 227647.7 | Z27: =Y27/$F27 -> 0.043986899 | AA27: 600722.44 | AB27: =AA27/$F27 -> 0.11607373 | AC27: =Y27+AA27 -> 828370.14 | AD27: =AC27/$F27 -> 0.16006063 | AE27: 1411843 | AF27: =AE27/F27 -> 0.27280133 | AG27: 171670.8 | AH27: =AG27/$F27 -> 0.033170843 | AI27: 194985.66 | AJ27: =AI27/$F27 -> 0.037675823 | AK27: 167756.88 | AL27: =AK27/$F27 -> 0.032414582
B28: =B21+7 -> 46050 | D28: 46042 | E28: 二 | F28: =SUM(M28,S28,U28,W28,AC28,AE28,AG28,AI28,AK28) -> 5709399.8 | G28: =SUM(F28:F34) -> 33925348 | I28: 1038749.5 | J28: =I28/$F28 -> 0.18193672 | K28: 975807.19 | L28: =K28/$F28 -> 0.17091239 | M28: =I28+K28 -> 2014556.7 | N28: =M28/$F28 -> 0.35284911 | O28: 203469.87 | P28: =O28/$F28 -> 0.035637698 | Q28: 150065.56 | R28: =Q28/$F28 -> 0.026283947 | S28: =O28+Q28 -> 353535.43 | T28: =S28/$F28 -> 0.061921645 | U28: 113219.87 | V28: =U28/$F28 -> 0.019830433 | W28: 64649.5 | X28: =W28/$F28 -> 0.011323344 | Y28: 205223.55 | Z28: =Y28/$F28 -> 0.035944855 | AA28: 595732.83 | AB28: =AA28/$F28 -> 0.10434246 | AC28: =Y28+AA28 -> 800956.38 | AD28: =AC28/$F28 -> 0.14028732 | AE28: 1638650.4 | AF28: =AE28/F28 -> 0.28700922 | AG28: 94086.6 | AH28: =AG28/$F28 -> 0.016479245 | AI28: 448435.25 | AJ28: =AI28/$F28 -> 0.078543325 | AK28: 181309.73 | AL28: =AK28/$F28 -> 0.031756355
D29: 46043 | E29: 三 | F29: =SUM(M29,S29,U29,W29,AC29,AE29,AG29,AI29,AK29) -> 5079869.2 | I29: 982959.08 | J29: =I29/$F29 -> 0.19350086 | K29: 930445.68 | L29: =K29/$F29 -> 0.18316331 | M29: =I29+K29 -> 1913404.8 | N29: =M29/F29 -> 0.37666418 | O29: 207673.72 | P29: =O29/$F29 -> 0.040881706 | Q29: 154562.65 | R29: =Q29/$F29 -> 0.030426502 | S29: =O29+Q29 -> 362236.37 | T29: =S29/F29 -> 0.071308208 | U29: 96854.28 | V29: =U29/F29 -> 0.019066294 | W29: 62106.8 | X29: =W29/$F29 -> 0.012226063 | Y29: 166449.64 | Z29: =Y29/$F29 -> 0.032766521 | AA29: 537579.29 | AB29: =AA29/$F29 -> 0.10582542 | AC29: =Y29+AA29 -> 704028.93 | AD29: =AC29/$F29 -> 0.13859194 | AE29: 1336469.4 | AF29: =AE29/F29 -> 0.2630913 | AG29: 80506.5 | AH29: =AG29/$F29 -> 0.015848144 | AI29: 332833.63 | AJ29: =AI29/$F29 -> 0.065520118 | AK29: 191428.54 | AL29: =AK29/$F29 -> 0.037683754
D30: 46044 | E30: 四 | F30: =SUM(M30,S30,U30,W30,AC30,AE30,AG30,AI30,AK30) -> 4686919.8 | I30: 924847.69 | J30: =I30/$F30 -> 0.19732527 | K30: 829233.72 | L30: =K30/$F30 -> 0.17692509 | M30: =I30+K30 -> 1754081.4 | N30: =M30/$F30 -> 0.37425036 | O30: 198440.28 | P30: =O30/$F30 -> 0.042339167 | Q30: 145046.96 | R30: =Q30/$F30 -> 0.030947182 | S30: =O30+Q30 -> 343487.24 | T30: =S30/$F30 -> 0.073286349 | U30: 97046.76 | V30: =U30/$F30 -> 0.020705872 | W30: 43198.85 | X30: =W30/$F30 -> 0.0092168955 | Y30: 162646.05 | Z30: =Y30/$F30 -> 0.034702119 | AA30: 431131.16 | AB30: =AA30/$F30 -> 0.091986033 | AC30: =Y30+AA30 -> 593777.21 | AD30: =AC30/$F30 -> 0.12668815 | AE30: 1262459.2 | AF30: =AE30/F30 -> 0.26935798 | AG30: 87783.6 | AH30: =AG30/$F30 -> 0.018729486 | AI30: 321725.06 | AJ30: =AI30/$F30 -> 0.068643176 | AK30: 183360.42 | AL30: =AK30/$F30 -> 0.039121732
D31: 46045 | E31: 五 | F31: =SUM(M31,S31,U31,W31,AC31,AE31,AG31,AI31,AK31) -> 3890561.4 | I31: 739838.29 | J31: =I31/$F31 -> 0.19016235 | K31: 752653.62 | L31: =K31/$F31 -> 0.1934563 | M31: =I31+K31 -> 1492491.9 | N31: =M31/F31 -> 0.38361865 | O31: 131927.15 | P31: =O31/$F31 -> 0.033909541 | Q31: 116592.25 | R31: =Q31/$F31 -> 0.029967976 | S31: =O31+Q31 -> 248519.4 | T31: =S31/F31 -> 0.063877517 | U31: 80161.37 | V31: =U31/F31 -> 0.020604063 | W31: 27455.75 | X31: =W31/$F31 -> 0.007057015 | Y31: 172353.72 | Z31: =Y31/$F31 -> 0.044300476 | AA31: 456103.97 | AB31: =AA31/$F31 -> 0.11723346 | AC31: =Y31+AA31 -> 628457.69 | AD31: =AC31/$F31 -> 0.16153394 | AE31: 1001123.6 | AF31: =AE31/F31 -> 0.25732113 | AG31: 76610.1 | AH31: =AG31/$F31 -> 0.019691271 | AI31: 194943.97 | AJ31: =AI31/$F31 -> 0.0501069 | AK31: 140797.54 | AL31: =AK31/$F31 -> 0.036189518
D32: 46046 | E32: 六 | F32: =SUM(M32,S32,U32,W32,AC32,AE32,AG32,AI32,AK32) -> 4094540 | I32: 683851.14 | J32: =I32/$F32 -> 0.16701538 | K32: 847104.44 | L32: =K32/$F32 -> 0.20688635 | M32: =I32+K32 -> 1530955.6 | N32: =M32/$F32 -> 0.37390173 | O32: 124372.89 | P32: =O32/$F32 -> 0.030375302 | Q32: 109659.84 | R32: =Q32/$F32 -> 0.026781968 | S32: =O32+Q32 -> 234032.73 | T32: =S32/$F32 -> 0.057157271 | U32: 88719.57 | V32: =U32/$F32 -> 0.021667775 | W32: 27401.65 | X32: =W32/$F32 -> 0.0066922414 | Y32: 181607.23 | Z32: =Y32/$F32 -> 0.044353513 | AA32: 496190.43 | AB32: =AA32/$F32 -> 0.12118344 | AC32: =Y32+AA32 -> 677797.66 | AD32: =AC32/$F32 -> 0.16553695 | AE32: 1067042.9 | AF32: =AE32/F32 -> 0.26060142 | AG32: 84746.7 | AH32: =AG32/$F32 -> 0.02069749 | AI32: 217721.31 | AJ32: =AI32/$F32 -> 0.053173571 | AK32: 166121.83 | AL32: =AK32/$F32 -> 0.040571549
D33: 46047 | E33: 日 | F33: =SUM(M33,S33,U33,W33,AC33,AE33,AG33,AI33,AK33) -> 5451395.5 | I33: 958250.01 | J33: =I33/$F33 -> 0.17578068 | K33: 945432.14 | L33: =K33/$F33 -> 0.17342938 | M33: =I33+K33 -> 1903682.1 | N33: =M33/F33 -> 0.34921006 | O33: 198616.65 | P33: =O33/$F33 -> 0.036434093 | Q33: 137036.52 | R33: =Q33/$F33 -> 0.025137879 | S33: =O33+Q33 -> 335653.17 | T33: =S33/F33 -> 0.061571972 | U33: 114144.05 | V33: =U33/F33 -> 0.020938501 | W33: 45308.75 | X33: =W33/$F33 -> 0.0083114039 | Y33: 212660.42 | Z33: =Y33/$F33 -> 0.039010272 | AA33: 597087.32 | AB33: =AA33/$F33 -> 0.10952926 | AC33: =Y33+AA33 -> 809747.74 | AD33: =AC33/$F33 -> 0.14853953 | AE33: 1713098.1 | AF33: =AE33/F33 -> 0.31424946 | AG33: 90018.3 | AH33: =AG33/$F33 -> 0.016512891 | AI33: 293792.29 | AJ33: =AI33/$F33 -> 0.053893043 | AK33: 145950.96 | AL33: =AK33/$F33 -> 0.026773137
D34: 46048 | E34: 一 | F34: =SUM(M34,S34,U34,W34,AC34,AE34,AG34,AI34,AK34) -> 5012662.3 | I34: 860128.21 | J34: =I34/$F34 -> 0.17159109 | K34: 923523.65 | L34: =K34/$F34 -> 0.18423815 | M34: =I34+K34 -> 1783651.9 | N34: =M34/$F34 -> 0.35582925 | O34: 188670.85 | P34: =O34/$F34 -> 0.037638851 | Q34: 139074.84 | R34: =Q34/$F34 -> 0.027744706 | S34: =O34+Q34 -> 327745.69 | T34: =S34/$F34 -> 0.065383556 | U34: 110630.2 | V34: =U34/$F34 -> 0.022070148 | W34: 43090.65 | X34: =W34/$F34 -> 0.00859636 | Y34: 209140.68 | Z34: =Y34/$F34 -> 0.041722475 | AA34: 556622.73 | AB34: =AA34/$F34 -> 0.11104333 | AC34: =Y34+AA34 -> 765763.41 | AD34: =AC34/$F34 -> 0.15276581 | AE34: 1427610.5 | AF34: =AE34/F34 -> 0.28480085 | AG34: 100676.1 | AH34: =AG34/$F34 -> 0.020084357 | AI34: 282654.68 | AJ34: =AI34/$F34 -> 0.056388135 | AK34: 170839.25 | AL34: =AK34/$F34 -> 0.03408154
B35: =B28+7 -> 46057 | D35: 46049 | E35: 二 | G35: =SUM(F35:F41) -> 0 | J35: =I35/$F35 -> #DIV/0! | L35: =K35/$F35 -> #DIV/0! | M35: =I35+K35 -> 0 | N35: =M35/$F35 -> #DIV/0! | P35: =O35/$F35 -> #DIV/0! | R35: =Q35/$F35 -> #DIV/0! | S35: =O35+Q35 -> 0 | T35: =S35/$F35 -> #DIV/0! | V35: =U35/$F35 -> #DIV/0! | X35: =W35/$F35 -> #DIV/0! | Z35: =Y35/$F35 -> #DIV/0! | AB35: =AA35/$F35 -> #DIV/0! | AC35: =Y35+AA35 -> 0 | AD35: =AC35/$F35 -> #DIV/0! | AF35: =AE35/F35 -> #DIV/0! | AH35: =AG35/$F35 -> #DIV/0! | AJ35: =AI35/$F35 -> #DIV/0! | AL35: =AK35/$F35 -> #DIV/0!
D36: 46050 | E36: 三 | J36: =I36/$F36 -> #DIV/0! | L36: =K36/$F36 -> #DIV/0! | M36: =I36+K36 -> 0 | N36: =M36/F36 -> #DIV/0! | P36: =O36/$F36 -> #DIV/0! | R36: =Q36/$F36 -> #DIV/0! | S36: =O36+Q36 -> 0 | T36: =S36/F36 -> #DIV/0! | V36: =U36/F36 -> #DIV/0! | X36: =W36/$F36 -> #DIV/0! | Z36: =Y36/$F36 -> #DIV/0! | AB36: =AA36/$F36 -> #DIV/0! | AC36: =Y36+AA36 -> 0 | AD36: =AC36/$F36 -> #DIV/0! | AF36: =AE36/F36 -> #DIV/0! | AH36: =AG36/$F36 -> #DIV/0! | AJ36: =AI36/$F36 -> #DIV/0! | AL36: =AK36/$F36 -> #DIV/0!
D37: 46051 | E37: 四 | J37: =I37/$F37 -> #DIV/0! | L37: =K37/$F37 -> #DIV/0! | M37: =I37+K37 -> 0 | N37: =M37/$F37 -> #DIV/0! | P37: =O37/$F37 -> #DIV/0! | R37: =Q37/$F37 -> #DIV/0! | S37: =O37+Q37 -> 0 | T37: =S37/$F37 -> #DIV/0! | V37: =U37/$F37 -> #DIV/0! | X37: =W37/$F37 -> #DIV/0! | Z37: =Y37/$F37 -> #DIV/0! | AB37: =AA37/$F37 -> #DIV/0! | AC37: =Y37+AA37 -> 0 | AD37: =AC37/$F37 -> #DIV/0! | AF37: =AE37/F37 -> #DIV/0! | AH37: =AG37/$F37 -> #DIV/0! | AJ37: =AI37/$F37 -> #DIV/0! | AL37: =AK37/$F37 -> #DIV/0!
D38: 46052 | E38: 五 | H38: =SUM(F40:F67) -> 0 | J38: =I38/$F38 -> #DIV/0! | L38: =K38/$F38 -> #DIV/0! | M38: =I38+K38 -> 0 | N38: =M38/F38 -> #DIV/0! | P38: =O38/$F38 -> #DIV/0! | R38: =Q38/$F38 -> #DIV/0! | S38: =O38+Q38 -> 0 | T38: =S38/F38 -> #DIV/0! | V38: =U38/F38 -> #DIV/0! | X38: =W38/$F38 -> #DIV/0! | Z38: =Y38/$F38 -> #DIV/0! | AB38: =AA38/$F38 -> #DIV/0! | AC38: =Y38+AA38 -> 0 | AD38: =AC38/$F38 -> #DIV/0! | AF38: =AE38/F38 -> #DIV/0! | AH38: =AG38/$F38 -> #DIV/0! | AJ38: =AI38/$F38 -> #DIV/0! | AL38: =AK38/$F38 -> #DIV/0!
D39: 46053 | E39: 六 | J39: =I39/$F39 -> #DIV/0! | L39: =K39/$F39 -> #DIV/0! | M39: =I39+K39 -> 0 | N39: =M39/$F39 -> #DIV/0! | P39: =O39/$F39 -> #DIV/0! | R39: =Q39/$F39 -> #DIV/0! | S39: =O39+Q39 -> 0 | T39: =S39/$F39 -> #DIV/0! | V39: =U39/$F39 -> #DIV/0! | X39: =W39/$F39 -> #DIV/0! | Z39: =Y39/$F39 -> #DIV/0! | AB39: =AA39/$F39 -> #DIV/0! | AC39: =Y39+AA39 -> 0 | AD39: =AC39/$F39 -> #DIV/0! | AF39: =AE39/F39 -> #DIV/0! | AH39: =AG39/$F39 -> #DIV/0! | AJ39: =AI39/$F39 -> #DIV/0! | AL39: =AK39/$F39 -> #DIV/0!
C40: 二 | D40: 46054 | E40: 日 | J40: =I40/$F40 -> #DIV/0! | L40: =K40/$F40 -> #DIV/0! | M40: =I40+K40 -> 0 | N40: =M40/F40 -> #DIV/0! | P40: =O40/$F40 -> #DIV/0! | R40: =Q40/$F40 -> #DIV/0! | S40: =O40+Q40 -> 0 | T40: =S40/F40 -> #DIV/0! | V40: =U40/F40 -> #DIV/0! | X40: =W40/$F40 -> #DIV/0! | Z40: =Y40/$F40 -> #DIV/0! | AB40: =AA40/$F40 -> #DIV/0! | AC40: =Y40+AA40 -> 0 | AD40: =AC40/$F40 -> #DIV/0! | AF40: =AE40/F40 -> #DIV/0! | AH40: =AG40/$F40 -> #DIV/0! | AJ40: =AI40/$F40 -> #DIV/0! | AL40: =AK40/$F40 -> #DIV/0!
D41: 46055 | E41: 一 | J41: =I41/$F41 -> #DIV/0! | L41: =K41/$F41 -> #DIV/0! | M41: =I41+K41 -> 0 | N41: =M41/$F41 -> #DIV/0! | P41: =O41/$F41 -> #DIV/0! | R41: =Q41/$F41 -> #DIV/0! | S41: =O41+Q41 -> 0 | T41: =S41/$F41 -> #DIV/0! | V41: =U41/$F41 -> #DIV/0! | X41: =W41/$F41 -> #DIV/0! | Z41: =Y41/$F41 -> #DIV/0! | AB41: =AA41/$F41 -> #DIV/0! | AC41: =Y41+AA41 -> 0 | AD41: =AC41/$F41 -> #DIV/0! | AF41: =AE41/F41 -> #DIV/0! | AH41: =AG41/$F41 -> #DIV/0! | AJ41: =AI41/$F41 -> #DIV/0! | AL41: =AK41/$F41 -> #DIV/0!
...

Sheet （４）訂單數量構成比
B2: （4）訂單數量構成比
B3: 資料繳交日 | C3: 月份 | D3: 日期 | F3: 訂單量 | I3: 品類訂單量
I4: 18℃-飯糰 | O4: 18℃-壽司手卷 | U4: 4℃-飯糰 | W4: 4℃-壽司手卷 | Y4: 主食 | AE4: 便當 | AG4: 熱食義麵 | AI4: 季節調理麵 | AK4: 微波小吃
F5: 日 | G5: 週累積 | H5: 月累積 | I5: 一配 | K5: 二配 | M5: 合計 | O5: 一配 | Q5: 二配 | S5: 合計 | U5: 一配 | W5: 一配 | Y5: 一配 | AA5: 二配 | AC5: 合計 | AE5: 一配 | AG5: 一配 | AI5: 一配 | AK5: 一配
I6: 訂單數 | J6: 比例(%) | K6: 訂單數 | L6: 比例(%) | M6: 訂單數 | N6: 比例(%) | O6: 訂單數 | P6: 比例(%) | Q6: 訂單數 | R6: 比例(%) | S6: 訂單數 | T6: 比例(%) | U6: 訂單數 | V6: 比例(%) | W6: 訂單數 | X6: 比例(%) | Y6: 訂單數 | Z6: 比例(%) | AA6: 訂單數 | AB6: 比例(%) | AC6: 訂單數 | AD6: 比例(%) | AE6: 訂單數 | AF6: 比例(%) | AG6: 訂單數 | AH6: 比例(%) | AI6: 訂單數 | AJ6: 比例(%) | AK6: 訂單數 | AL6: 比例(%)
B7: =D15 -> 46029 | D7: 46021 | E7: 二 | F7: =SUM(M7,S7,U7,W7,AC7,AE7,AG7,AI7,AK7) -> 160010 | G7: =SUM(F7:F13) -> 1040875 | I7: 41135 | J7: =I7/$F7 -> 0.25707768 | K7: 49025 | L7: =K7/$F7 -> 0.3063871 | M7: =I7+K7 -> 90160 | N7: =M7/$F7 -> 0.56346478 | O7: 10414 | P7: =O7/$F7 -> 0.065083432 | Q7: 5418 | R7: =Q7/$F7 -> 0.033860384 | S7: =O7+Q7 -> 15832 | T7: =S7/$F7 -> 0.098943816 | U7: 4682 | V7: =U7/$F7 -> 0.029260671 | W7: 0 | X7: =W7/$F7 -> 0 | Y7: 3810 | Z7: =Y7/$F7 -> 0.023811012 | AA7: 12841 | AB7: =AA7/$F7 -> 0.080251234 | AC7: =Y7+AA7 -> 16651 | AD7: =AC7/$F7 -> 0.10406225 | AE7: 22032 | AF7: =AE7/$F7 -> 0.13769139 | AG7: 3448 | AH7: =AG7/$F7 -> 0.021548653 | AI7: 1909 | AJ7: =AI7/$F7 -> 0.011930504 | AK7: 5296 | AL7: =AK7/$F7 -> 0.033097931
D8: 46022 | E8: 三 | F8: =SUM(M8,S8,U8,W8,AC8,AE8,AG8,AI8,AK8) -> 129015 | I8: 27508 | J8: =I8/$F8 -> 0.21321552 | K8: 45667 | L8: =K8/$F8 -> 0.35396659 | M8: =I8+K8 -> 73175 | N8: =M8/$F8 -> 0.56718211 | O8: 7977 | P8: =O8/$F8 -> 0.06183002 | Q8: 4464 | R8: =Q8/$F8 -> 0.034600628 | S8: =O8+Q8 -> 12441 | T8: =S8/$F8 -> 0.096430648 | U8: 3651 | V8: =U8/$F8 -> 0.028299035 | W8: 0 | X8: =W8/$F8 -> 0 | Y8: 3262 | Z8: =Y8/$F8 -> 0.025283882 | AA8: 11681 | AB8: =AA8/$F8 -> 0.09053986 | AC8: =Y8+AA8 -> 14943 | AD8: =AC8/$F8 -> 0.11582374 | AE8: 15484 | AF8: =AE8/$F8 -> 0.12001705 | AG8: 2891 | AH8: =AG8/$F8 -> 0.022408247 | AI8: 1652 | AJ8: =AI8/$F8 -> 0.012804713 | AK8: 4778 | AL8: =AK8/$F8 -> 0.037034453
C9: 一 | D9: 46023 | E9: 四 | F9: =SUM(M9,S9,U9,W9,AC9,AE9,AG9,AI9,AK9) -> 149358 | H9: =SUM(F9:F39) -> 4065016 | I9: 37452 | J9: =I9/$F9 -> 0.25075322 | K9: 47285 | L9: =K9/$F9 -> 0.31658833 | M9: =I9+K9 -> 84737 | N9: =M9/$F9 -> 0.56734156 | O9: 10291 | P9: =O9/$F9 -> 0.068901565 | Q9: 5336 | R9: =Q9/$F9 -> 0.035726242 | S9: =O9+Q9 -> 15627 | T9: =S9/$F9 -> 0.10462781 | U9: 4491 | V9: =U9/$F9 -> 0.030068694 | W9: 0 | X9: =W9/$F9 -> 0 | Y9: 3501 | Z9: =Y9/$F9 -> 0.023440325 | AA9: 10812 | AB9: =AA9/$F9 -> 0.072389828 | AC9: =Y9+AA9 -> 14313 | AD9: =AC9/$F9 -> 0.095830153 | AE9: 19326 | AF9: =AE9/$F9 -> 0.12939381 | AG9: 3460 | AH9: =AG9/$F9 -> 0.023165816 | AI9: 2098 | AJ9: =AI9/$F9 -> 0.014046787 | AK9: 5306 | AL9: =AK9/$F9 -> 0.035525382
D10: 46024 | E10: 五 | F10: =SUM(M10,S10,U10,W10,AC10,AE10,AG10,AI10,AK10) -> 127084 | I10: 31423 | J10: =I10/$F10 -> 0.24726165 | K10: 43837 | L10: =K10/$F10 -> 0.34494508 | M10: =I10+K10 -> 75260 | N10: =M10/$F10 -> 0.59220673 | O10: 7172 | P10: =O10/$F10 -> 0.056435114 | Q10: 4438 | R10: =Q10/$F10 -> 0.034921784 | S10: =O10+Q10 -> 11610 | T10: =S10/$F10 -> 0.091356898 | U10: 3270 | V10: =U10/$F10 -> 0.025731013 | W10: 0 | X10: =W10/$F10 -> 0 | Y10: 3221 | Z10: =Y10/$F10 -> 0.025345441 | AA10: 11287 | AB10: =AA10/$F10 -> 0.088815272 | AC10: =Y10+AA10 -> 14508 | AD10: =AC10/$F10 -> 0.11416071 | AE10: 13863 | AF10: =AE10/$F10 -> 0.10908533 | AG10: 2710 | AH10: =AG10/$F10 -> 0.021324478 | AI10: 1160 | AJ10: =AI10/$F10 -> 0.009127821 | AK10: 4703 | AL10: =AK10/$F10 -> 0.037007019
D11: 46025 | E11: 六 | F11: =SUM(M11,S11,U11,W11,AC11,AE11,AG11,AI11,AK11) -> 134835 | I11: 29003 | J11: =I11/$F11 -> 0.21509994 | K11: 49620 | L11: =K11/$F11 -> 0.36800534 | M11: =I11+K11 -> 78623 | N11: =M11/$F11 -> 0.58310528 | O11: 6256 | P11: =O11/$F11 -> 0.046397449 | Q11: 4122 | R11: =Q11/$F11 -> 0.030570698 | S11: =O11+Q11 -> 10378 | T11: =S11/$F11 -> 0.076968146 | U11: 3736 | V11: =U11/$F11 -> 0.027707939 | W11: 0 | X11: =W11/$F11 -> 0 | Y11: 3584 | Z11: =Y11/$F11 -> 0.026580636 | AA11: 12289 | AB11: =AA11/$F11 -> 0.091141024 | AC11: =Y11+AA11 -> 15873 | AD11: =AC11/$F11 -> 0.11772166 | AE11: 16705 | AF11: =AE11/$F11 -> 0.12389216 | AG11: 3015 | AH11: =AG11/$F11 -> 0.022360663 | AI11: 1726 | AJ11: =AI11/$F11 -> 0.012800831 | AK11: 4779 | AL11: =AK11/$F11 -> 0.03544332
D12: 46026 | E12: 日 | F12: =SUM(M12,S12,U12,W12,AC12,AE12,AG12,AI12,AK12) -> 171722 | I12: 41974 | J12: =I12/$F12 -> 0.24442995 | K12: 54588 | L12: =K12/$F12 -> 0.31788589 | M12: =I12+K12 -> 96562 | N12: =M12/$F12 -> 0.56231584 | O12: 10766 | P12: =O12/$F12 -> 0.062694355 | Q12: 5034 | R12: =Q12/$F12 -> 0.029314823 | S12: =O12+Q12 -> 15800 | T12: =S12/$F12 -> 0.092009178 | U12: 4855 | V12: =U12/$F12 -> 0.02827244 | W12: 0 | X12: =W12/$F12 -> 0 | Y12: 4218 | Z12: =Y12/$F12 -> 0.024562956 | AA12: 13631 | AB12: =AA12/$F12 -> 0.079378297 | AC12: =Y12+AA12 -> 17849 | AD12: =AC12/$F12 -> 0.10394125 | AE12: 26492 | AF12: =AE12/$F12 -> 0.1542726 | AG12: 3536 | AH12: =AG12/$F12 -> 0.020591421 | AI12: 1552 | AJ12: =AI12/$F12 -> 0.0090378635 | AK12: 5076 | AL12: =AK12/$F12 -> 0.029559404
