Workbook

Sheet 日別報廢率總表 
A1: 大溪廠半成品管理日別總表 | V1: 半成品品項數
A2: 日期 | B2: 營業額 | C2: 報廢額 | D2: 報廢率 KPI 0.25% | E2: 超用額 | F2: 超用率 | G2: 廢棄前10名 | I2: 超用前10名 | K2: 共用類廢棄
G3: 金額總計 | H3: 構成比 | I3: 金額總計 | J3: 構成比 | K3: 金額總計 | L3: 構成比 KPI 15%
A4: 45870 | B4: ='0801分析標準表'!$C$3 -> 5795364.7 | C4: ='0801分析標準表'!$D$5 -> 14010.514 | D4: =C4/B4 -> 0.002417538 | E4: ='0801分析標準表'!$F$5 -> 49520.757 | F4: =E4/B4 -> 0.0085448906 | G4: ='0801分析標準表'!$H$5 -> 5524.3521 | H4: =G4/C4 -> 0.39430045 | I4: ='0801分析標準表'!$J$5 -> 15556.247 | J4: =I4/E4 -> 0.3141359 | K4: ='0801分析標準表'!$L$5 -> 2512.3204 | L4: =K4/C4 -> 0.17931679 | M4: 1.5i為調理多產 抓樣不穩2.4i製程耗損 3.1i炊飯單鍋基礎量 下飯機差異 | V4: 195
A5: =A4+1 -> 45871 | B5: ='0802分析標準表'!$C$3 -> 6281761 | C5: ='0802分析標準表'!$D$5 -> 15177.069 | D5: =C5/B5 -> 0.0024160533 | E5: ='0802分析標準表'!$F$5 -> 54183.439 | F5: =E5/B5 -> 0.0086255174 | G5: ='0802分析標準表'!$H$5 -> 5919.614 | H5: =G5/C5 -> 0.3900367 | I5: ='0802分析標準表'!$J$5 -> 15905.347 | J5: =I5/E5 -> 0.29354628 | K5: ='0802分析標準表'!$L$5 -> 2131.872 | L5: =K5/C5 -> 0.14046664 | M5: 1.5i為調理多產 抓樣不穩2.4i製程耗損 3.1i炊飯單鍋基礎量 下飯機差異 | V5: 195
A6: =A5+1 -> 45872 | B6: ='0803分析標準表'!$C$3 -> 8003391.1 | C6: ='0803分析標準表'!$D$5 -> 19418.772 | D6: =C6/B6 -> 0.0024263181 | E6: ='0803分析標準表'!$F$5 -> 69171 | F6: =E6/B6 -> 0.0086427114 | G6: ='0803分析標準表'!$H$5 -> 6610.6163 | H6: =G6/C6 -> 0.340424 | I6: ='0803分析標準表'!$J$5 -> 16236.487 | J6: =I6/E6 -> 0.23472968 | K6: ='0803分析標準表'!$L$5 -> 2218 | L6: =K6/C6 -> 0.11421937 | M6: 1.6i為調理多產 抓樣不穩2.3i製程耗損 3.1i炊飯單鍋基礎量 下飯機差異 | V6: 190
A7: =A6+1 -> 45873 | B7: ='0804分析標準表'!$C$3 -> 7902480.4 | C7: ='0804分析標準表'!$D$5 -> 19143 | D7: =C7/B7 -> 0.002422404 | E7: ='0804分析標準表'!$F$5 -> 67519 | F7: =E7/B7 -> 0.0085440262 | G7: ='0804分析標準表'!$H$5 -> 4995.8102 | H7: =G7/C7 -> 0.26097321 | I7: ='0804分析標準表'!$J$5 -> 19331.03 | J7: =I7/E7 -> 0.28630503 | K7: ='0804分析標準表'!$L$5 -> 2641 | L7: =K7/C7 -> 0.13796166 | M7: 1.4i為調理多產 抓樣不穩2.4i製程耗損 3.1i炊飯單鍋基礎量 下飯機差異 4.1i原物料規格差異 | V7: 190
A8: =A7+1 -> 45874 | B8: ='0805分析標準表'!$C$3 -> 9130487.1 | C8: ='0805分析標準表'!$D$5 -> 22183.573 | D8: =C8/B8 -> 0.0024296155 | E8: ='0805分析標準表'!$F$5 -> 79296.298 | F8: =E8/B8 -> 0.0086847829 | G8: ='0805分析標準表'!$H$5 -> 6103.0743 | H8: =G8/C8 -> 0.27511683 | I8: ='0805分析標準表'!$J$5 -> 33550.617 | J8: =I8/E8 -> 0.42310445 | K8: ='0805分析標準表'!$L$5 -> 2729.3154 | L8: =K8/C8 -> 0.12303318 | M8: 1.4i為展開量105%(2i為新品) 2i抓樣不穩 3.2i製程耗損 4.1i炊飯機固定批量 5.1i研發設定，小片的規格不符合指示書設定重量 | V8: 198
A9: =A8+1 -> 45875 | B9: ='0806分析標準表'!$C$3 -> 8314895.1 | C9: ='0806分析標準表'!$D$5 -> 20159.281 | D9: =C9/B9 -> 0.0024244781 | E9: ='0806分析標準表'!$F$5 -> 70683.501 | F9: =E9/B9 -> 0.008500829 | G9: ='0806分析標準表'!$H$5 -> 4480.2092 | H9: =G9/C9 -> 0.22224053 | I9: ='0806分析標準表'!$J$5 -> 20441.846 | J9: =I9/E9 -> 0.28920251 | K9: ='0806分析標準表'!$L$5 -> 2591.0327 | L9: =K9/C9 -> 0.12852803 | M9: 1.5i為展開量105%(1i為新品) 2.2i製程耗損(1i為新品) 3.1i抓樣不穩 4.1i炊飯機固定批量 5.1i研發設定，小片的規格不符合指示書設定 | V9: 198
A10: =A9+1 -> 45876 | B10: ='0807分析標準表'!$C$3 -> 7555343.1 | C10: ='0807分析標準表'!$D$5 -> 18266.416 | D10: =C10/B10 -> 0.0024176818 | E10: ='0807分析標準表'!$F$5 -> 64099.004 | F10: =E10/B10 -> 0.0084839303 | G10: ='0807分析標準表'!$H$5 -> 7049.461 | H10: =G10/C10 -> 0.3859247 | I10: ='0807分析標準表'!$J$5 -> 19618.586 | J10: =I10/E10 -> 0.30606694 | K10: ='0807分析標準表'!$L$5 -> 3279.034 | L10: =K10/C10 -> 0.17951163 | M10: 1.4i為展開量105%(2i為新品) 2.1i製程耗損 3.2i抓樣不穩 4.1i原物料規格，大顆比例高 5.1i研發設定，小片的規格不符合指示書設定 5.1i煮麵機固定批量 | V10: 198
A11: =A10+1 -> 45877 | B11: ='0808分析標準表'!$C$3 -> 6209389.7 | C11: ='0808分析標準表'!$D$5 -> 15004.129 | D11: =C11/B11 -> 0.0024163613 | E11: ='0808分析標準表'!$F$5 -> 53146.336 | F11: =E11/B11 -> 0.0085590273 | G11: ='0808分析標準表'!$H$5 -> 5839.2655 | H11: =G11/C11 -> 0.38917723 | I11: ='0808分析標準表'!$J$5 -> 13239.133 | J11: =I11/E11 -> 0.24910716 | K11: ='0808分析標準表'!$L$5 -> 2524.6271 | L11: =K11/C11 -> 0.16826215 | M11: 1.7i為抓樣不穩 2.1i製程耗損 3.1i煮麵機固定批量 4.1i研發設定，小片的規格不符合指示書設定重量 | V11: 196
A12: =A11+1 -> 45878 | B12: ='0809分析標準表'!$C$3 -> 6591313.1 | C12: ='0809分析標準表'!$D$5 -> 15935.423 | D12: =C12/B12 -> 0.0024176401 | E12: ='0809分析標準表'!$F$5 -> 55317.723 | F12: =E12/B12 -> 0.0083925193 | G12: ='0809分析標準表'!$H$5 -> 5590.956 | H12: =G12/C12 -> 0.3508508 | I12: ='0809分析標準表'!$J$5 -> 13860.97 | J12: =I12/E12 -> 0.25057015 | K12: ='0809分析標準表'!$L$5 -> 3905.1883 | L12: =K12/C12 -> 0.24506336 | M12: 1.3i為抓樣不穩 2.4i展開量105% 3.1i原物料規格，大顆比例高 4.1i研發設定，小片的規格不符合指示書設定重量 5.1i炊飯機固定批量 | V12: 196
A13: =A12+1 -> 45879 | B13: ='0810分析標準表'!$C$3 -> 8170415.2 | C13: ='0810分析標準表'!$D$5 -> 19791.18 | D13: =C13/B13 -> 0.0024222979 | E13: ='0810分析標準表'!$F$5 -> 69175.717 | F13: =E13/B13 -> 0.0084666097 | G13: ='0810分析標準表'!$H$5 -> 4749.146 | H13: =G13/C13 -> 0.23996275 | I13: ='0810分析標準表'!$J$5 -> 22018.89 | J13: =I13/E13 -> 0.31830375 | K13: ='0810分析標準表'!$L$5 -> 2177.9221 | L13: =K13/C13 -> 0.11004509 | M13: 1.4i為抓樣不穩 2.3i展開量105% 3.1i製程耗損 4.1i研發設定，小片的規格不符合指示書設定重量 5.1i炊飯機固定批量 | V13: 190
A14: =A13+1 -> 45880 | B14: ='0811分析標準表'!$C$3 -> 7815178.3 | C14: ='0811分析標準表'!$D$5 -> 18915.579 | D14: =C14/B14 -> 0.0024203644 | E14: ='0811分析標準表'!$F$5 -> 65473.776 | F14: =E14/B14 -> 0.0083777712 | G14: ='0811分析標準表'!$H$5 -> 5024.6253 | H14: =G14/C14 -> 0.26563423 | I14: ='0811分析標準表'!$J$5 -> 21910.52 | J14: =I14/E14 -> 0.33464574 | K14: ='0811分析標準表'!$L$5 -> 2437.3231 | L14: =K14/C14 -> 0.12885268 | M14: 1.4i為抓樣不穩 2.3i展開量105% 3.2i製程耗損 4.1i研發設定，小片的規格不符合指示書設定重量 | V14: 189
A15: =A14+1 -> 45881 | B15: ='0812分析標準表'!$C$3 -> 7841558.5 | C15: ='0812分析標準表'!$D$5 -> 18989.923 | D15: =C15/B15 -> 0.0024217026 | E15: ='0812分析標準表'!$F$5 -> 66433.737 | F15: =E15/B15 -> 0.0084720068 | G15: ='0812分析標準表'!$H$5 -> 6434.6202 | H15: =G15/C15 -> 0.33884394 | I15: ='0812分析標準表'!$J$5 -> 17858.852 | J15: =I15/E15 -> 0.26882203 | K15: ='0812分析標準表'!$L$5 -> 3211.2649 | L15: =K15/C15 -> 0.16910363 | M15: 1.2i為抓樣不穩 2.5i展開量105% 3.2i製程耗損 4.1i研發設定，小片的規格不符合指示書設定重量 | V15: 193
A16: =A15+1 -> 45882 | B16: ='0813分析標準表'!$C$3 -> 7976719.9 | C16: ='0813分析標準表'!$D$5 -> 19336.486 | D16: =C16/B16 -> 0.0024241149 | E16: ='0813分析標準表'!$F$5 -> 64898.551 | F16: =E16/B16 -> 0.0081359947 | G16: ='0813分析標準表'!$H$5 -> 6901.5355 | H16: =G16/C16 -> 0.35691778 | I16: ='0813分析標準表'!$J$5 -> 20197.4 | J16: =I16/E16 -> 0.31121496 | K16: ='0813分析標準表'!$L$5 -> 2721.0186 | L16: =K16/C16 -> 0.1407194 | M16: 1.3i為抓樣不穩 2.4i展開量105% 3.1i研發設定，小片的規格不符合指示書設定重量 4.2i原物料規格差異 | V16: 193
A17: =A16+1 -> 45883 | B17: ='0814分析標準表'!$C$3 -> 7479649 | C17: ='0814分析標準表'!$D$5 -> 18102.073 | D17: =C17/B17 -> 0.0024201768 | E17: ='0814分析標準表'!$F$5 -> 61257.188 | F17: =E17/B17 -> 0.0081898479 | G17: ='0814分析標準表'!$H$5 -> 7271.5655 | H17: =G17/C17 -> 0.40169794 | I17: ='0814分析標準表'!$J$5 -> 23636.318 | J17: =I17/E17 -> 0.38585379 | K17: ='0814分析標準表'!$L$5 -> 4829.1512 | L17: =K17/C17 -> 0.26677338 | M17: 1.4i為抓樣不穩 2.2i展開量105% 3.1i研發設定，小片的規格不符合指示書設定重量 4.1i原物料規格差異5.1i炊飯機固定批量 6.1i製程耗損 | V17: 193
A18: =A17+1 -> 45884 | B18: ='0815分析標準表'!$C$3 -> 6364780.2 | C18: ='0815分析標準表'!$D$5 -> 15365.392 | D18: =C18/B18 -> 0.0024141277 | E18: ='0815分析標準表'!$F$5 -> 52005.885 | F18: =E18/B18 -> 0.0081708847 | G18: ='0815分析標準表'!$H$5 -> 4258.2772 | H18: =G18/C18 -> 0.2771343 | I18: ='0815分析標準表'!$J$5 -> 14153.418 | J18: =I18/E18 -> 0.27215031 | K18: ='0815分析標準表'!$L$5 -> 3010.4887 | L18: =K18/C18 -> 0.19592658 | M18: 1.3i為抓樣不穩 2.1i展開量105% 3.1i研發設定，小片的規格不符合指示書設定重量 4.1i原物料規格差異 5.1i炊飯機固定批量 6.3i製程耗損 | V18: 193
A19: =A18+1 -> 45885 | B19: ='0816分析標準表'!$C$3 -> 6421067.8 | C19: ='0816分析標準表'!$D$5 -> 15499.561 | D19: =C19/B19 -> 0.0024138604 | E19: ='0816分析標準表'!$F$5 -> 51768.063 | F19: =E19/B19 -> 0.0080622203 | G19: ='0816分析標準表'!$H$5 -> 6561.8213 | H19: =G19/C19 -> 0.42335529 | I19: ='0816分析標準表'!$J$5 -> 11886.044 | J19: =I19/E19 -> 0.22960187 | K19: ='0816分析標準表'!$L$5 -> 2280.5809 | L19: =K19/C19 -> 0.14713842 | M19: 1.4i為抓樣不穩 2.1i展開量105% 3.1i研發設定，小片的規格不符合指示書設定重量 4.1i原物料規格差異 5.1i炊飯機固定批量 6.2i煮麵機固定批量 | V19: 190
A20: =A19+1 -> 45886 | B20: ='0817分析標準表'!$C$3 -> 8145084.9 | C20: ='0817分析標準表'!$D$5 -> 19707.465 | D20: =C20/B20 -> 0.0024195531 | E20: ='0817分析標準表'!$F$5 -> 65748.467 | F20: =E20/B20 -> 0.0080721648 | G20: ='0817分析標準表'!$H$5 -> 5342.519 | H20: =G20/C20 -> 0.27109113 | I20: ='0817分析標準表'!$J$5 -> 14761.841 | J20: =I20/E20 -> 0.22451993 | K20: ='0817分析標準表'!$L$5 -> 2941.4027 | L20: =K20/C20 -> 0.14925322 | M20: 1.1i為抓樣不穩 2.3i展開量105% 3.2i製程耗損 4.1i研發設定，小片的規格不符合指示書設定重量 5.3i原物料規格差異 | V20: 186
A21: =A20+1 -> 45887 | B21: ='0818分析標準表'!$C$3 -> 7989071.5 | C21: ='0818分析標準表'!$D$5 -> 19315.408 | D21: =C21/B21 -> 0.0024177288 | E21: ='0818分析標準表'!$F$5 -> 63949.724 | F21: =E21/B21 -> 0.0080046503 | G21: ='0818分析標準表'!$H$5 -> 4834.7357 | H21: =G21/C21 -> 0.25030461 | I21: ='0818分析標準表'!$J$5 -> 16251.213 | J21: =I21/E21 -> 0.25412483 | K21: ='0818分析標準表'!$L$5 -> 2780.3091 | L21: =K21/C21 -> 0.14394255 | M21: 1.3i為抓樣不穩 2.3i展開量105% 3.2i製程耗損 4.1i研發設定，小片的規格不符合指示書設定重量 5.1i原物料規格差異 6.1i炊飯機固定批量 | V21: 185
A22: =A21+1 -> 45888 | B22: ='0819分析標準表'!$C$3 -> 7909637 | C22: ='0819分析標準表'!$D$5 -> 19096.599 | D22: =C22/B22 -> 0.0024143458 | E22: ='0819分析標準表'!$F$5 -> 63190.177 | F22: =E22/B22 -> 0.007989011 | G22: ='0819分析標準表'!$H$5 -> 4584.4793 | H22: =G22/C22 -> 0.24006784 | I22: ='0819分析標準表'!$J$5 -> 19388.742 | J22: =I22/E22 -> 0.30683159 | K22: ='0819分析標準表'!$L$5 -> 2920.665 | L22: =K22/C22 -> 0.15294163 | M22: 1.1i為抓樣不穩 2.4i展開量105% 3.1i研發設定，小片的規格不符合指示書設定重量 4.1i原物料規格差異 5.1i其他原因 6.2i製程不穩 | V22: 185
A23: =A22+1 -> 45889 | B23: ='0820分析標準表'!$C$3 -> 7775987.8 | C23: ='0820分析標準表'!$D$5 -> 18753.286 | D23: =C23/B23 -> 0.0024116918 | E23: ='0820分析標準表'!$F$5 -> 61899.049 | F23: =E23/B23 -> 0.0079602811 | G23: ='0820分析標準表'!$H$5 -> 4932.1411 | H23: =G23/C23 -> 0.26300144 | I23: ='0820分析標準表'!$J$5 -> 15165.343 | J23: =I23/E23 -> 0.24500122 | K23: ='0820分析標準表'!$L$5 -> 3175.0388 | L23: =K23/C23 -> 0.16930573 | M23: 1.3i為抓樣不穩 2.3i展開量105% 3.1i研發設定，小片的規格不符合指示書設定重量 4.1i原物料規格差異 5.2i製程不穩 | V23: 185
A24: =A23+1 -> 45890 | B24: ='0821分析標準表'!$C$3 -> 7246465.3 | C24: ='0821分析標準表'!$D$5 -> 17467.345 | D24: =C24/B24 -> 0.0024104642 | E24: ='0821分析標準表'!$F$5 -> 57573.538 | F24: =E24/B24 -> 0.0079450513 | G24: ='0821分析標準表'!$H$5 -> 3942.5741 | H24: =G24/C24 -> 0.22571112 | I24: ='0821分析標準表'!$J$5 -> 17476.456 | J24: =I24/E24 -> 0.30355015 | K24: ='0821分析標準表'!$L$5 -> 3001.2627 | L24: =K24/C24 -> 0.17182134 | M24: 1.3i為抓樣不穩 2.2i展開量105% 3.1i研發設定，小片的規格不符合指示書設定重量 4.1i原物料規格差異 5.3i製程不穩 | V24: 185
A25: =A24+1 -> 45891 | B25: ='0822分析標準表'!$C$3 -> 5933586.3 | C25: ='0822分析標準表'!$D$5 -> 14356.761 | D25: =C25/B25 -> 0.0024195756 | E25: ='0822分析標準表'!$F$5 -> 47139.286 | F25: =E25/B25 -> 0.0079444846 | G25: ='0822分析標準表'!$H$5 -> 6190.3314 | H25: =G25/C25 -> 0.43117884 | I25: ='0822分析標準表'!$J$5 -> 10886.71 | J25: =I25/E25 -> 0.2309477 | K25: ='0822分析標準表'!$L$5 -> 2994.4934 | L25: =K25/C25 -> 0.20857723 | M25: 1.2i為抓樣不穩 2.4i展開量105% 3.1i研發設定，小片的規格不符合指示書設定重量 4.1i原物料規格差異 5.2i製程不穩 | V25: 185
A26: =A25+1 -> 45892 | B26: ='0823分析標準表'!$C$3 -> 6081229.5 | C26: ='0823分析標準表'!$D$5 -> 14691.886 | D26: =C26/B26 -> 0.0024159401 | E26: ='0823分析標準表'!$F$5 -> 48212.656 | F26: =E26/B26 -> 0.0079281099 | G26: ='0823分析標準表'!$H$5 -> 5687.0399 | H26: =G26/C26 -> 0.38708712 | I26: ='0823分析標準表'!$J$5 -> 13306.951 | J26: =I26/E26 -> 0.27600535 | K26: ='0823分析標準表'!$L$5 -> 1926.7929 | L26: =K26/C26 -> 0.13114673 | M26: 1.2i為抓樣不穩 2.4i展開量105% 3.1i研發設定，小片的規格不符合指示書設定重量 4.1i原物料規格差異 5.2i其他原因 | V26: 178
A27: =A26+1 -> 45893 | B27: ='0824分析標準表'!$C$3 -> 7894027 | C27: ='0824分析標準表'!$D$5 -> 19089.354 | D27: =C27/B27 -> 0.0024182023 | E27: ='0824分析標準表'!$F$5 -> 61921.235 | F27: =E27/B27 -> 0.0078440617 | G27: ='0824分析標準表'!$H$5 -> 4499.02 | H27: =G27/C27 -> 0.23568215 | I27: ='0824分析標準表'!$J$5 -> 16773.528 | J27: =I27/E27 -> 0.27088491 | K27: ='0824分析標準表'!$L$5 -> 2496.1021 | L27: =K27/C27 -> 0.13075886 | M27: 1.1i為抓樣不穩 2.2i展開量105% 3.1i研發設定，小片的規格不符合指示書設定重量 4.2i原物料規格差異 5.1i其他原因 6.3i製程不穩 | V27: 178
A28: =A27+1 -> 45894 | B28: ='0825分析標準表'!$C$3 -> 7726391.3 | C28: ='0825分析標準表'!$D$5 -> 18655.308 | D28: =C28/B28 -> 0.0024144917 | E28: ='0825分析標準表'!$F$5 -> 60538.646 | F28: =E28/B28 -> 0.0078353068 | G28: ='0825分析標準表'!$H$5 -> 4083.4716 | H28: =G28/C28 -> 0.2188906 | I28: ='0825分析標準表'!$J$5 -> 18900.472 | J28: =I28/E28 -> 0.31220506 | K28: ='0825分析標準表'!$L$5 -> 2441.0153 | L28: =K28/C28 -> 0.1308483 | M28: 1.1i為抓樣不穩 2.4i展開量105% 3.1i研發設定，小片的規格不符合指示書設定重量 4.1i其他原因 5.3i製程不穩 | V28: 178
A29: =A28+1 -> 45895 | B29: ='0826分析標準表'!$C$3 -> 7423824.2 | C29: ='0826分析標準表'!$D$5 -> 17888.274 | D29: =C29/B29 -> 0.0024095768 | E29: ='0826分析標準表'!$F$5 -> 58011.729 | F29: =E29/B29 -> 0.0078142649 | G29: ='0826分析標準表'!$H$5 -> 2865.4103 | H29: =G29/C29 -> 0.16018372 | I29: ='0826分析標準表'!$J$5 -> 20404.953 | J29: =I29/E29 -> 0.35173841 | K29: ='0826分析標準表'!$L$5 -> 2550.2186 | L29: =K29/C29 -> 0.1425637 | M29: 1.3i為抓樣不穩 2.2i展開量105% 3.1i研發設定，小片的規格不符合指示書設定重量 4.1i其他原因 5.3i製程不穩 | V29: 176
A30: =A29+1 -> 45896 | B30: ='0827分析標準表'!$C$3 -> 7268105.9 | C30: ='0827分析標準表'!$D$5 -> 17530.725 | D30: =C30/B30 -> 0.0024120074 | E30: ='0827分析標準表'!$F$5 -> 56275.879 | F30: =E30/B30 -> 0.0077428535 | G30: ='0827分析標準表'!$H$5 -> 4957.1863 | H30: =G30/C30 -> 0.28277132 | I30: ='0827分析標準表'!$J$5 -> 16268.267 | J30: =I30/E30 -> 0.28908064 | K30: ='0827分析標準表'!$L$5 -> 2589.0621 | L30: =K30/C30 -> 0.14768711 | M30: 1.2i為抓樣不穩 2.4i展開量105% 3.1i研發設定，小片的規格不符合指示書設定重量 4.3i製程不穩 | V30: 171
A31: =A30+1 -> 45897 | B31: ='0828分析標準表'!$C$3 -> 6765305.7 | C31: ='0828分析標準表'!$D$5 -> 16316.671 | D31: =C31/B31 -> 0.0024118158 | E31: ='0828分析標準表'!$F$5 -> 52026.534 | F31: =E31/B31 -> 0.0076901971 | G31: ='0828分析標準表'!$H$5 -> 4258.0322 | H31: =G31/C31 -> 0.26096207 | I31: ='0828分析標準表'!$J$5 -> 15396.414 | J31: =I31/E31 -> 0.29593387 | K31: ='0828分析標準表'!$L$5 -> 2340.916 | L31: =K31/C31 -> 0.14346775 | M31: 1.1i為抓樣不穩 2.3i展開量105% 3.1i研發設定，小片的規格不符合指示書設定重量 4.5i製程不穩 | V31: 171
A32: =A31+1 -> 45898 | B32: ='0829分析標準表'!$C$3 -> 5760799.9 | C32: ='0829分析標準表'!$D$5 -> 13931.159 | D32: =C32/B32 -> 0.0024182681 | E32: ='0829分析標準表'!$F$5 -> 44372.037 | F32: =E32/B32 -> 0.007702409 | G32: ='0829分析標準表'!$H$5 -> 4345.5272 | H32: =G32/C32 -> 0.31192863 | I32: ='0829分析標準表'!$J$5 -> 13543.466 | J32: =I32/E32 -> 0.30522526 | K32: ='0829分析標準表'!$L$5 -> 1847.3764 | L32: =K32/C32 -> 0.13260752 | M32: 1.2i為抓樣不穩 2.4i展開量105% 3.1i研發設定，小片的規格不符合指示書設定重量 4.3i製程不穩 | V32: 171
A33: =A32+1 -> 45899 | B33: ='0830分析標準表'!$C$3 -> 6161593.8 | C33: ='0830分析標準表'!$D$5 -> 14887.156 | D33: =C33/B33 -> 0.002416121 | E33: ='0830分析標準表'!$F$5 -> 46839.279 | F33: =E33/B33 -> 0.0076018123 | G33: ='0830分析標準表'!$H$5 -> 3050.8294 | H33: =G33/C33 -> 0.2049303 | I33: ='0830分析標準表'!$J$5 -> 15095.027 | J33: =I33/E33 -> 0.32227284 | K33: ='0830分析標準表'!$L$5 -> 2593.1287 | L33: =K33/C33 -> 0.17418563 | M33: 1.2i為抓樣不穩 2.4i展開量105% 3.1i研發設定，小片的規格不符合指示書設定重量 4.1i製程不穩 5.2i原物料規格差異 | V33: 171
A34: =A33+1 -> 45900 | B34: ='0831分析標準表'!$C$3 -> 7725142.4 | C34: ='0831分析標準表'!$D$5 -> 18650.44 | D34: =C34/B34 -> 0.002414252 | E34: ='0831分析標準表'!$F$5 -> 57442.342 | F34: =E34/B34 -> 0.0074357648 | G34: ='0831分析標準表'!$H$5 -> 3612.8209 | H34: =G34/C34 -> 0.19371237 | I34: ='0831分析標準表'!$J$5 -> 13612.391 | J34: =I34/E34 -> 0.23697486 | K34: ='0831分析標準表'!$L$5 -> 2446.0283 | L34: =K34/C34 -> 0.13115124 | M34: 1.3i為抓樣不穩 2.3i展開量105% 3.1i研發設定，小片的規格不符合指示書設定重量 4.1i製程不穩 5.2i原物料規格差異 | V34: 161
A35: ※淺黃色為工廠自填項目
A36: ※日期紅色為新品日
M46: 原物料規格，大顆比例高
M47: 原物料規格

Sheet 0831分析標準表
A1: 大溪廠半成品管理分析
A2: 日期 | C2: 營業額 | D2: 報廢展開 | F2: 超用展開 | H2: 報廢展開 | J2: 超用展開 | L2: 報廢展開
A3: 45900 | C3: 7725142.4 | D3: 總報廢 | F3: 總超用 | H3: 報廢-前10名 | J3: 超用-前10名 | L3: 共用類-總報廢
D4: 金額 | E4: 占比(營業額) | F4: 金額 | G4: 占比(營業額) | H4: 金額 | I4: 占比(總報廢) | J4: 金額 | K4: 占比(總超用) | L4: 金額 | M4: 占比(總報廢)
A5: 年度KPI目標0.25% | D5: 18650.44 | E5: =D5/C3 -> 0.002414252 | F5: 57442.342 | G5: =F5/C3 -> 0.0074357648 | H5: =SUM(C12:C21) -> 3612.8209 | I5: =H5/D5 -> 0.19371237 | J5: =SUM(C28:C37) -> 13612.391 | K5: =J5/F5 -> 0.23697486 | L5: 2446.0283 | M5: =L5/D5 -> 0.13115124
A7: 報廢金額前十名半成品
A8: 明細展開 | D8: 生產資訊 | O8: 類別 | P8: 分析原因 (請填寫8大原因) | Q8: 其他原因說明 | R8: 備註-商品名稱
A9: 排序 | B9: 半成品 | D9: 生產端 | J9: 組合端
B10: 名稱 | C10: 報廢金額 排序 | D10: 產出量 | J10: 報廢 | L10: 超用
D11: 訂單需求 (kg) | E11: 實際產出 (kg) | F11: 補單 (kg) | G11: 單價 (元) | H11: 實際生產 (對比訂單需求) | I11: 差異 (元) | J11: kg | K11: 占比 | L11: kg | M11: 占比 | N11: 金額 (元)
A12: 1 | B12: 炒培根片(114年) | C12: 520.2498 | D12: 24.09 | E12: 25.06 | F12: 0 | G12: 536.34 | H12: =(E12+F12)/D12 -> 1.0402657 | I12: 520.2498 | J12: 0.97 | K12: =J12/D12 -> 0.04026567 | L12: =((E12+F12)-D12)-J12 -> -1.110223e-15 | M12: =L12/D12 -> -4.6086468e-17 | N12: =L12*G12 -> -5.9545702e-13 | O12: 調理端 | P12: 抓樣不穩 | R12: 二配哞哞培根奶香海陸焗飯
A13: 2 | B13: 烤銀鮭魚肚 | C13: 463.5 | D13: 4283 | E13: 4313 | F13: 0 | G13: 15.45 | H13: =(E13+F13)/D13 -> 1.0070044 | I13: 463.5 | J13: 30 | K13: =J13/D13 -> 0.0070044361 | L13: =((E13+F13)-D13)-J13 -> 0 | M13: =L13/D13 -> 0 | N13: =L13*G13 -> 0 | O13: 調理端 | P13: 研發設定 | Q13: 研發設定，小片的規格不符合指示書設定重量 | R13: 一配贅沢鮭魚肚飯糰
A14: 3 | B14: 炒油蔥醬 | C14: 456.7225 | D14: 204.2 | E14: 215.68 | F14: 0 | G14: 152.75 | H14: =(E14+F14)/D14 -> 1.0562194 | I14: 1753.57 | J14: 2.99 | K14: =J14/D14 -> 0.014642507 | L14: =((E14+F14)-D14)-J14 -> 8.49 | M14: =L14/D14 -> 0.041576885 | N14: =L14*G14 -> 1296.8475 | O14: 調理端 | P14: 展開量105% | R14: 雞肉飯飯糰
A15: 4 | B15: 蒸鰻魚片(主食用) | C15: 437.22 | D15: 4890 | E15: 4932 | F15: 0 | G15: 10.41 | H15: =(E15+F15)/D15 -> 1.008589 | I15: 437.22 | J15: 42 | K15: =J15/D15 -> 0.0085889571 | L15: =((E15+F15)-D15)-J15 -> 0 | M15: =L15/D15 -> 0 | N15: =L15*G15 -> 0 | O15: 調理端 | P15: 製程不穩 | R15: 鰻牛雙饗匠食盒
A16: 5 | B16: (V)川燙小青花菜 | C16: 427.547 | D16: 807.18 | E16: 810.36 | F16: 14.2 | G16: 147.43 | H16: =(E16+F16)/D16 -> 1.0215318 | I16: 2562.3334 | J16: 2.9 | K16: =J16/D16 -> 0.003592755 | L16: =((E16+F16)-D16)-J16 -> 14.48 | M16: =L16/D16 -> 0.017938997 | N16: =L16*G16 -> 2134.7864 | O16: 調理端 | P16: 原物料規格 | Q16: 大顆比例高 | R16: 共用類
A17: 6 | B17: 洋蔥壹號醬 | C17: 281.8696 | D17: 52.26 | E17: 54.81 | F17: 0 | G17: 153.19 | H17: =(E17+F17)/D17 -> 1.0487945 | I17: 390.6345 | J17: 1.84 | K17: =J17/D17 -> 0.035208573 | L17: =((E17+F17)-D17)-J17 -> 0.71 | M17: =L17/D17 -> 0.013585917 | N17: =L17*G17 -> 108.7649 | O17: 調理端 | P17: 抓樣不穩 | R17: 壹號醬炙烤牛飯糰
A18: 7 | B18: 消毒青蔥絲 | C18: 278.2752 | D18: 36.63 | E18: 38.34 | F18: 0 | G18: 248.46 | H18: =(E18+F18)/D18 -> 1.046683 | I18: 424.8666 | J18: 1.12 | K18: =J18/D18 -> 0.030576031 | L18: =((E18+F18)-D18)-J18 -> 0.59 | M18: =L18/D18 -> 0.016107016 | N18: =L18*G18 -> 146.5914 | O18: 調理端 | P18: 抓樣不穩 | R18: 共用類
A19: 8 | B19: 炒辣醬蔬菜 | C19: 256.1286 | D19: 18.61 | E19: 20.71 | F19: 0 | G19: 140.73 | H19: =(E19+F19)/D19 -> 1.1128426 | I19: 295.533 | J19: 1.82 | K19: =J19/D19 -> 0.097796883 | L19: =((E19+F19)-D19)-J19 -> 0.28 | M19: =L19/D19 -> 0.015045674 | N19: =L19*G19 -> 39.4044 | O19: 調理端 | P19: 展開量105% | R19: 二配大飯糰春川風味辣炒雞
A20: 9 | B20: 韓式辣炒豆芽 | C20: 251.3082 | D20: 27.64 | E20: 29.6 | F20: 0 | G20: 144.43 | H20: =(E20+F20)/D20 -> 1.0709117 | I20: 283.0828 | J20: 1.74 | K20: =J20/D20 -> 0.062952243 | L20: =((E20+F20)-D20)-J20 -> 0.22 | M20: =L20/D20 -> 0.007959479 | N20: =L20*G20 -> 31.7746 | O20: 調理端 | P20: 展開量105% | R20: 蒜蒜燒豚飯
A21: 10 | B21: 熟化去皮馬鈴薯滾刀17-23g | C21: 240 | D21: 145.16 | E21: 147.66 | F21: 0 | G21: 96 | H21: =(E21+F21)/D21 -> 1.0172224 | I21: 240 | J21: 2.5 | K21: =J21/D21 -> 0.017222375 | L21: =((E21+F21)-D21)-J21 -> 0 | M21: =L21/D21 -> 0 | N21: =L21*G21 -> 0 | O21: 調理端 | P21: 原物料規格 | R21: 嫩烤香料雞胸排蔬滿盒
A23: 超用金額前十名半成品
A24: 明細展開 | D24: 生產資訊 | O24: 類別 | P24: 分析原因 (請填寫8大原因) | Q24: 其他原因說明 | R24: 備註-商品名稱
A25: 排序 | B25: 半成品 | D25: 生產端 | J25: 組合端
B26: 名稱 | C26: 超用金額 排序 | D26: 產出量 | J26: 報廢 | M26: 超用
D27: 訂單需求 (kg) | E27: 實際產出 (kg) | F27: 補單 (kg) | G27: 單價 (元) | H27: 實際生產 (對比訂單需求) | I27: 差異 (元) | J27: kg | K27: 占比 | L27: 金額 (元) | M27: kg | N27: 占比
A28: 1 | B28: (V)川燙小青花菜 | C28: 2134.7864 | D28: 807.18 | E28: 810.36 | F28: 14.2 | G28: 147.43 | H28: =(E28+F28)/D28 -> 1.0215318 | I28: 2562.3334 | J28: 2.9 | K28: =J28/D28 -> 0.003592755 | L28: =J28*G28 -> 427.547 | M28: =((E28+F28)-D28)-J28 -> 14.48 | N28: =M28/D28 -> 0.017938997 | O28: 組合室 | P28: 原物料規格 | Q28: 大顆比例高 | R28: 共用類
A29: 2 | B29: 蒸-全熟雞肉絲CL(113年) | C29: 1873.1691 | D29: 125.67 | E29: 130.06 | F29: 0 | G29: 426.69 | H29: =(E29+F29)/D29 -> 1.0349328 | I29: 1873.1691 | J29: 0 | K29: =J29/D29 -> 0 | L29: =J29*G29 -> 0 | M29: =((E29+F29)-D29)-J29 -> 4.39 | N29: =M29/D29 -> 0.03493276 | O29: 組合室 | P29: 抓樣不穩 | R29: 雞肉飯飯糰
A30: 3 | B30: 越式湯凍(114年) | C30: 1375.3692 | D30: 633.16 | E30: 613.6 | F30: 61.2 | G30: 33.03 | H30: =(E30+F30)/D30 -> 1.0657654 | I30: 1375.3692 | J30: 0 | K30: =J30/D30 -> 0 | L30: =J30*G30 -> 0 | M30: =((E30+F30)-D30)-J30 -> 41.64 | N30: =M30/D30 -> 0.065765367 | O30: 組合室 | P30: 其他原因 | Q30: 注餡機差異 | R30: 越式牛肉寬粉
A31: 4 | B31: 切-究極燒肉片 | C31: 1329.7728 | D31: 52.81 | E31: 52.93 | F31: 1.8 | G31: 692.59 | H31: =(E31+F31)/D31 -> 1.0363568 | I31: 1329.7728 | J31: 0 | K31: =J31/D31 -> 0 | L31: =J31*G31 -> 0 | M31: =((E31+F31)-D31)-J31 -> 1.92 | N31: =M31/D31 -> 0.036356751 | O31: 組合室 | P31: 抓樣不穩 | R31: 壹號醬雞豚雙拼
A32: 5 | B32: 炒油蔥醬 | C32: 1296.8475 | D32: 204.2 | E32: 215.68 | F32: 0 | G32: 152.75 | H32: =(E32+F32)/D32 -> 1.0562194 | I32: 1753.57 | J32: 2.99 | K32: =J32/D32 -> 0.014642507 | L32: =J32*G32 -> 456.7225 | M32: =((E32+F32)-D32)-J32 -> 8.49 | N32: =M32/D32 -> 0.041576885 | O32: 組合室 | P32: 抓樣不穩 | R32: 雞肉飯飯糰
A33: 6 | B33: 日式牛培根 | C33: 1277.9004 | D33: 36.1 | E33: 35.96 | F33: 2.2 | G33: 620.34 | H33: =(E33+F33)/D33 -> 1.0570637 | I33: 1277.9004 | J33: 0 | K33: =J33/D33 -> 0 | L33: =J33*G33 -> 0 | M33: =((E33+F33)-D33)-J33 -> 2.06 | N33: =M33/D33 -> 0.057063712 | O33: 組合室 | P33: 抓樣不穩 | R33: 柚見極炙烤牛
A34: 7 | B34: 蘑菇湯凍 | C34: 1231.9988 | D34: 323.52 | E34: 324.18 | F34: 10.72 | G34: 108.26 | H34: =(E34+F34)/D34 -> 1.0351756 | I34: 1231.9988 | J34: 0 | K34: =J34/D34 -> 0 | L34: =J34*G34 -> 0 | M34: =((E34+F34)-D34)-J34 -> 11.38 | N34: =M34/D34 -> 0.035175569 | O34: 組合室 | P34: 其他原因 | Q34: 注餡機差異 | R34: 二配鐵板蘑菇肉醬起司焗飯
A35: 8 | B35: 煮中華冷麵(110年) | C35: 1109.2224 | D35: 4946.34 | E35: 4925 | F35: 49.5 | G35: 39.39 | H35: =(E35+F35)/D35 -> 1.0056931 | I35: 1109.2224 | J35: 0 | K35: =J35/D35 -> 0 | L35: =J35*G35 -> 0 | M35: =((E35+F35)-D35)-J35 -> 28.16 | N35: =M35/D35 -> 0.0056930983 | O35: 組合室 | P35: 抓樣不穩 | R35: 共用類
A36: 9 | B36: 切-烤牛五花(112年) | C36: 993.4792 | D36: 202.53 | E36: 201.16 | F36: 3.01 | G36: 605.78 | H36: =(E36+F36)/D36 -> 1.0080976 | I36: 993.4792 | J36: 0 | K36: =J36/D36 -> 0 | L36: =J36*G36 -> 0 | M36: =((E36+F36)-D36)-J36 -> 1.64 | N36: =M36/D36 -> 0.0080975658 | O36: 組合室 | P36: 其他原因 | Q36: 雙圈秤重範圍 | R36: 糖燻野郎三十天熟成牛飯
A37: 10 | B37: 川燙毛豆玉米 | C37: 989.8449 | D37: 392.03 | E37: 393.1 | F37: 5.2 | G37: 157.87 | H37: =(E37+F37)/D37 -> 1.0159937 | I37: 989.8449 | J37: 0 | K37: =J37/D37 -> 0 | L37: =J37*G37 -> 0 | M37: =((E37+F37)-D37)-J37 -> 6.27 | N37: =M37/D37 -> 0.015993674 | O37: 組合室 | P37: 抓樣不穩 | R37: 共用類
A39: 共用類報廢金額前十名半成品
A40: 明細展開
A41: 排序 | B41: 半成品
B42: 名稱 | C42: 報廢金額 排序 | D42: 共用類總金額 占比
A44: 1 | B44: (V)川燙小青花菜 | C44: 427.547 | D44: =C44/$L$5 -> 0.17479234
...

Sheet 0830分析標準表
A1: 大溪廠半成品管理分析
A2: 日期 | C2: 營業額 | D2: 報廢展開 | F2: 超用展開 | H2: 報廢展開 | J2: 超用展開 | L2: 報廢展開
A3: 45899 | C3: 6161593.8 | D3: 總報廢 | F3: 總超用 | H3: 報廢-前10名 | J3: 超用-前10名 | L3: 共用類-總報廢
D4: 金額 | E4: 占比(營業額) | F4: 金額 | G4: 占比(營業額) | H4: 金額 | I4: 占比(總報廢) | J4: 金額 | K4: 占比(總超用) | L4: 金額 | M4: 占比(總報廢)
A5: 年度KPI目標0.25% | D5: 14887.156 | E5: =D5/C3 -> 0.002416121 | F5: 46839.279 | G5: =F5/C3 -> 0.0076018123 | H5: =SUM(C12:C21) -> 3050.8294 | I5: =H5/D5 -> 0.2049303 | J5: =SUM(C28:C37) -> 15095.027 | K5: =J5/F5 -> 0.32227284 | L5: 2593.1287 | M5: =L5/D5 -> 0.17418563
A7: 報廢金額前十名半成品
A8: 明細展開 | D8: 生產資訊 | O8: 類別 | P8: 分析原因 (請填寫8大原因) | Q8: 其他原因說明 | R8: 備註-商品名稱
A9: 排序 | B9: 半成品 | D9: 生產端 | J9: 組合端
B10: 名稱 | C10: 報廢金額 排序 | D10: 產出量 | J10: 報廢 | L10: 超用
D11: 訂單需求 (kg) | E11: 實際產出 (kg) | F11: 補單 (kg) | G11: 單價 (元) | H11: 實際生產 (對比訂單需求) | I11: 差異 (元) | J11: kg | K11: 占比 | L11: kg | M11: 占比 | N11: 金額 (元)
A12: 1 | B12: 烤銀鮭魚肚 | C12: 540.75 | D12: 2889 | E12: 2924 | F12: 0 | G12: 15.45 | H12: =(E12+F12)/D12 -> 1.0121149 | I12: 540.75 | J12: 35 | K12: =J12/D12 -> 0.012114919 | L12: =((E12+F12)-D12)-J12 -> 0 | M12: =L12/D12 -> 0 | N12: =L12*G12 -> 0 | O12: 調理端 | P12: 研發設定 | Q12: 研發設定，小片的規格不符合指示書設定重量 | R12: 一配贅沢鮭魚肚飯糰
A13: 2 | B13: (V)川燙小青花菜 | C13: 343.5119 | D13: 505.54 | E13: 506.46 | F13: 12.8 | G13: 147.43 | H13: =(E13+F13)/D13 -> 1.0271393 | I13: 2022.7396 | J13: 2.33 | K13: =J13/D13 -> 0.004608933 | L13: =((E13+F13)-D13)-J13 -> 11.39 | M13: =L13/D13 -> 0.022530364 | N13: =L13*G13 -> 1679.2277 | O13: 調理端 | P13: 原物料規格 | Q13: 大顆比例高 | R13: 共用類
A14: 3 | B14: 滷嚕米-沙茶滷汁 | C14: 332.7075 | D14: 57.96 | E14: 64.71 | F14: 0 | G14: 49.29 | H14: =(E14+F14)/D14 -> 1.1164596 | I14: 332.7075 | J14: 6.75 | K14: =J14/D14 -> 0.11645963 | L14: =((E14+F14)-D14)-J14 -> 7.1054274e-15 | M14: =L14/D14 -> 1.2259191e-16 | N14: =L14*G14 -> 3.5022651e-13 | O14: 調理端 | P14: 展開量105% | R14: 一口滷魂便當
A15: 4 | B15: 熟化去皮馬鈴薯滾刀17-23g | C15: 288 | D15: 87.64 | E15: 90.64 | F15: 0 | G15: 96 | H15: =(E15+F15)/D15 -> 1.0342309 | I15: 288 | J15: 3 | K15: =J15/D15 -> 0.034230945 | L15: =((E15+F15)-D15)-J15 -> 0 | M15: =L15/D15 -> 0 | N15: =L15*G15 -> 0 | O15: 調理端 | P15: 原物料規格 | R15: 嫩烤香料雞胸排蔬滿盒
A16: 5 | B16: 洋蔥壹號醬 | C16: 271.1463 | D16: 42.03 | E16: 45.09 | F16: 0 | G16: 153.19 | H16: =(E16+F16)/D16 -> 1.0728051 | I16: 468.7614 | J16: 1.77 | K16: =J16/D16 -> 0.042112777 | L16: =((E16+F16)-D16)-J16 -> 1.29 | M16: =L16/D16 -> 0.030692363 | N16: =L16*G16 -> 197.6151 | O16: 調理端 | P16: 展開量105% | R16: 壹號醬炙烤牛飯糰
A17: 6 | B17: 蒸鰻魚片(主食用) | C17: 270.66 | D17: 4218 | E17: 4244 | F17: 0 | G17: 10.41 | H17: =(E17+F17)/D17 -> 1.0061641 | I17: 270.66 | J17: 26 | K17: =J17/D17 -> 0.0061640588 | L17: =((E17+F17)-D17)-J17 -> 0 | M17: =L17/D17 -> 0 | N17: =L17*G17 -> 0 | O17: 調理端 | P17: 製程不穩 | R17: 鰻牛雙饗匠食盒
A18: 7 | B18: 消毒青蔥絲 | C18: 253.4292 | D18: 29.45 | E18: 30.96 | F18: 0 | G18: 248.46 | H18: =(E18+F18)/D18 -> 1.0512733 | I18: 375.1746 | J18: 1.02 | K18: =J18/D18 -> 0.034634975 | L18: =((E18+F18)-D18)-J18 -> 0.49 | M18: =L18/D18 -> 0.01663837 | N18: =L18*G18 -> 121.7454 | O18: 調理端 | P18: 展開量105% | R18: 共用類
A19: 8 | B19: 川燙毛豆玉米 | C19: 251.0133 | D19: 233.45 | E19: 234.35 | F19: 2.96 | G19: 157.87 | H19: =(E19+F19)/D19 -> 1.0165346 | I19: 609.3782 | J19: 1.59 | K19: =J19/D19 -> 0.0068108803 | L19: =((E19+F19)-D19)-J19 -> 2.27 | M19: =L19/D19 -> 0.0097237096 | N19: =L19*G19 -> 358.3649 | O19: 調理端 | P19: 抓樣不穩 | R19: 共用類
A20: 9 | B20: 烤帶皮南瓜丁(114.6) | C20: 250.272 | D20: 29.41 | E20: 31.75 | F20: 0 | G20: 208.56 | H20: =(E20+F20)/D20 -> 1.0795648 | I20: 488.0304 | J20: 1.2 | K20: =J20/D20 -> 0.040802448 | L20: =((E20+F20)-D20)-J20 -> 1.14 | M20: =L20/D20 -> 0.038762326 | N20: =L20*G20 -> 237.7584 | O20: 調理端 | P20: 展開量105% | R20: 金沙豆腐細扁麵
A21: 10 | B21: 烤黑胡椒洋蔥絲 | C21: 249.3392 | D21: 87.77 | E21: 90.55 | F21: 0 | G21: 141.67 | H21: =(E21+F21)/D21 -> 1.0316737 | I21: 393.8426 | J21: 1.76 | K21: =J21/D21 -> 0.02005241 | L21: =((E21+F21)-D21)-J21 -> 1.02 | M21: =L21/D21 -> 0.011621283 | N21: =L21*G21 -> 144.5034 | O21: 調理端 | P21: 抓樣不穩 | R21: 糖燻野郎三十天熟成牛飯
A23: 超用金額前十名半成品
A24: 明細展開 | D24: 生產資訊 | O24: 類別 | P24: 分析原因 (請填寫8大原因) | Q24: 其他原因說明 | R24: 備註-商品名稱
A25: 排序 | B25: 半成品 | D25: 生產端 | J25: 組合端
B26: 名稱 | C26: 超用金額 排序 | D26: 產出量 | J26: 報廢 | M26: 超用
D27: 訂單需求 (kg) | E27: 實際產出 (kg) | F27: 補單 (kg) | G27: 單價 (元) | H27: 實際生產 (對比訂單需求) | I27: 差異 (元) | J27: kg | K27: 占比 | L27: 金額 (元) | M27: kg | N27: 占比
A28: 1 | B28: 切-鹽烤牛肉 | C28: 2245.6716 | D28: 68.75 | E28: 68.69 | F28: 3.45 | G28: 662.44 | H28: =(E28+F28)/D28 -> 1.0493091 | I28: 2245.6716 | J28: 0 | K28: =J28/D28 -> 0 | L28: =J28*G28 -> 0 | M28: =((E28+F28)-D28)-J28 -> 3.39 | N28: =M28/D28 -> 0.049309091 | O28: 組合室 | P28: 抓樣不穩 | R28: 共用類
A29: 2 | B29: 切-鹽烤熟成牛肉 | C29: 2172.1472 | D29: 28.12 | E29: 28.4 | F29: 3 | G29: 662.24 | H29: =(E29+F29)/D29 -> 1.116643 | I29: 2172.1472 | J29: 0 | K29: =J29/D29 -> 0 | L29: =J29*G29 -> 0 | M29: =((E29+F29)-D29)-J29 -> 3.28 | N29: =M29/D29 -> 0.11664296 | O29: 組合室 | P29: 抓樣不穩 | R29: 鰻牛雙饗匠食盒
A30: 3 | B30: 炙燒韓式牛五花 | C30: 1899.58 | D30: 24.01 | E30: 27.03 | F30: 0 | G30: 629 | H30: =(E30+F30)/D30 -> 1.1257809 | I30: 1899.58 | J30: 0 | K30: =J30/D30 -> 0 | L30: =J30*G30 -> 0 | M30: =((E30+F30)-D30)-J30 -> 3.02 | N30: =M30/D30 -> 0.12578092 | O30: 組合室 | P30: 抓樣不穩 | R30: 壹號醬炙烤牛飯糰
A31: 4 | B31: (V)川燙小青花菜 | C31: 1679.2277 | D31: 505.54 | E31: 506.46 | F31: 12.8 | G31: 147.43 | H31: =(E31+F31)/D31 -> 1.0271393 | I31: 2022.7396 | J31: 2.33 | K31: =J31/D31 -> 0.004608933 | L31: =J31*G31 -> 343.5119 | M31: =((E31+F31)-D31)-J31 -> 11.39 | N31: =M31/D31 -> 0.022530364 | O31: 組合室 | P31: 原物料規格 | Q31: 大顆比例高 | R31: 共用類
A32: 5 | B32: 蒸-全熟雞肉絲CL(113年) | C32: 1647.0234 | D32: 98.32 | E32: 102.18 | F32: 0 | G32: 426.69 | H32: =(E32+F32)/D32 -> 1.0392596 | I32: 1647.0234 | J32: 0 | K32: =J32/D32 -> 0 | L32: =J32*G32 -> 0 | M32: =((E32+F32)-D32)-J32 -> 3.86 | N32: =M32/D32 -> 0.039259561 | O32: 組合室 | P32: 抓樣不穩 | R32: 雞肉飯飯糰
A33: 6 | B33: 切-烤台式肉片 | C33: 1373.4366 | D33: 40.85 | E33: 41.55 | F33: 1.49 | G33: 627.14 | H33: =(E33+F33)/D33 -> 1.0536108 | I33: 1373.4366 | J33: 0 | K33: =J33/D33 -> 0 | L33: =J33*G33 -> 0 | M33: =((E33+F33)-D33)-J33 -> 2.19 | N33: =M33/D33 -> 0.053610771 | O33: 組合室 | P33: 抓樣不穩 | R33: 姨次滿足熟成牛豚雙拼
A34: 7 | B34: 炒油蔥醬 | C34: 1209.78 | D34: 159.78 | E34: 167.7 | F34: 0 | G34: 152.75 | H34: =(E34+F34)/D34 -> 1.0495682 | I34: 1209.78 | J34: 0 | K34: =J34/D34 -> 0 | L34: =J34*G34 -> 0 | M34: =((E34+F34)-D34)-J34 -> 7.92 | N34: =M34/D34 -> 0.049568156 | O34: 組合室 | P34: 抓樣不穩 | R34: 雞肉飯飯糰
A35: 8 | B35: 煮牛肉片(A7) | C35: 996.1624 | D35: 48.55 | E35: 46.83 | F35: 3.24 | G35: 655.37 | H35: =(E35+F35)/D35 -> 1.0313079 | I35: 996.1624 | J35: 0 | K35: =J35/D35 -> 0 | L35: =J35*G35 -> 0 | M35: =((E35+F35)-D35)-J35 -> 1.52 | N35: =M35/D35 -> 0.03130793 | O35: 組合室 | P35: 抓樣不穩 | R35: 越式牛肉寬粉
A36: 9 | B36: 煮中華冷麵(110年) | C36: 955.9953 | D36: 4155.93 | E36: 4142.1 | F36: 38.1 | G36: 39.39 | H36: =(E36+F36)/D36 -> 1.0058398 | I36: 955.9953 | J36: 0 | K36: =J36/D36 -> 0 | L36: =J36*G36 -> 0 | M36: =((E36+F36)-D36)-J36 -> 24.27 | N36: =M36/D36 -> 0.0058398481 | O36: 組合室 | P36: 其他原因 | Q36: 雙圈秤重範圍 | R36: 共用類
A37: 10 | B37: 拌鹽烤豬肉片(114年) | C37: 916.0032 | D37: 152.78 | E37: 156.22 | F37: 0 | G37: 266.28 | H37: =(E37+F37)/D37 -> 1.022516 | I37: 916.0032 | J37: 0 | K37: =J37/D37 -> 0 | L37: =J37*G37 -> 0 | M37: =((E37+F37)-D37)-J37 -> 3.44 | N37: =M37/D37 -> 0.022516036 | O37: 組合室 | P37: 抓樣不穩 | R37: 鹽蔥燒肉飯糰
A39: 共用類報廢金額前十名半成品
A40: 明細展開
A41: 排序 | B41: 半成品
B42: 名稱 | C42: 報廢金額 排序 | D42: 共用類總金額 占比
A44: 1 | B44: (V)川燙小青花菜 | C44: 343.5119 | D44: =C44/$L$5 -> 0.13247005
...

Sheet 0829分析標準表
A1: 大溪廠半成品管理分析
A2: 日期 | C2: 營業額 | D2: 報廢展開 | F2: 超用展開 | H2: 報廢展開 | J2: 超用展開 | L2: 報廢展開
A3: 45898 | C3: 5760799.9 | D3: 總報廢 | F3: 總超用 | H3: 報廢-前10名 | J3: 超用-前10名 | L3: 共用類-總報廢
D4: 金額 | E4: 占比(營業額) | F4: 金額 | G4: 占比(營業額) | H4: 金額 | I4: 占比(總報廢) | J4: 金額 | K4: 占比(總超用) | L4: 金額 | M4: 占比(總報廢)
A5: 年度KPI目標0.25% | D5: 13931.159 | E5: =D5/C3 -> 0.0024182681 | F5: 44372.037 | G5: =F5/C3 -> 0.007702409 | H5: =SUM(C12:C21) -> 4345.5272 | I5: =H5/D5 -> 0.31192863 | J5: =SUM(C28:C37) -> 13543.466 | K5: =J5/F5 -> 0.30522526 | L5: 1847.3764 | M5: =L5/D5 -> 0.13260752
A7: 報廢金額前十名半成品
A8: 明細展開 | D8: 生產資訊 | O8: 類別 | P8: 分析原因 (請填寫8大原因) | Q8: 其他原因說明 | R8: 備註-商品名稱
A9: 排序 | B9: 半成品 | D9: 生產端 | J9: 組合端
B10: 名稱 | C10: 報廢金額 排序 | D10: 產出量 | J10: 報廢 | L10: 超用
D11: 訂單需求 (kg) | E11: 實際產出 (kg) | F11: 補單 (kg) | G11: 單價 (元) | H11: 實際生產 (對比訂單需求) | I11: 差異 (元) | J11: kg | K11: 占比 | L11: kg | M11: 占比 | N11: 金額 (元)
A12: 1 | B12: 烤銀鮭魚肚 | C12: 1081.5 | D12: 3008 | E12: 3078 | F12: 0 | G12: 15.45 | H12: =(E12+F12)/D12 -> 1.0232713 | I12: 1081.5 | J12: 70 | K12: =J12/D12 -> 0.023271277 | L12: =((E12+F12)-D12)-J12 -> 0 | M12: =L12/D12 -> 0 | N12: =L12*G12 -> 0 | O12: 調理端 | P12: 研發設定 | Q12: 研發設定，小片的規格不符合指示書設定重量 | R12: 一配贅沢鮭魚肚飯糰
A13: 2 | B13: 薑炒筍尾 | C13: 734.6 | D13: 39 | E13: 43 | F13: 0 | G13: 183.65 | H13: =(E13+F13)/D13 -> 1.1025641 | I13: 734.6 | J13: 4 | K13: =J13/D13 -> 0.1025641 | L13: =((E13+F13)-D13)-J13 -> 0 | M13: =L13/D13 -> 0 | N13: =L13*G13 -> 0 | O13: 調理端 | P13: 展開量105% | R13: 經典滷肉飯
A14: 3 | B14: 川味秋木耳 | C14: 507.84 | D14: 31.5 | E14: 33.5 | F14: 0 | G14: 253.92 | H14: =(E14+F14)/D14 -> 1.0634921 | I14: 507.84 | J14: 2 | K14: =J14/D14 -> 0.063492063 | L14: =((E14+F14)-D14)-J14 -> 0 | M14: =L14/D14 -> 0 | N14: =L14*G14 -> 0 | O14: 調理端 | P14: 展開量105% | R14: 經典滷肉飯
A15: 4 | B15: 蒸鰻魚片(主食用) | C15: 312.3 | D15: 4035 | E15: 3975 | F15: 90 | G15: 10.41 | H15: =(E15+F15)/D15 -> 1.0074349 | I15: 312.3 | J15: 30 | K15: =J15/D15 -> 0.0074349442 | L15: =((E15+F15)-D15)-J15 -> 0 | M15: =L15/D15 -> 0 | N15: =L15*G15 -> 0 | O15: 調理端 | P15: 製程不穩 | R15: 鰻牛雙饗匠食盒
A16: 5 | B16: 自製鹽蔥(114年) | C16: 307.099 | D16: 16.95 | E16: 18.3 | F16: 0 | G16: 236.23 | H16: =(E16+F16)/D16 -> 1.079646 | I16: 318.9105 | J16: 1.3 | K16: =J16/D16 -> 0.076696165 | L16: =((E16+F16)-D16)-J16 -> 0.05 | M16: =L16/D16 -> 0.0029498525 | N16: =L16*G16 -> 11.8115 | O16: 調理端 | P16: 展開量105% | R16: 壹號醬雞豚雙拼
A17: 6 | B17: 炒紅K高麗菜(飯糰) | C17: 306.81 | D17: 28.82 | E17: 31.82 | F17: 0 | G17: 102.27 | H17: =(E17+F17)/D17 -> 1.1040944 | I17: 306.81 | J17: 3 | K17: =J17/D17 -> 0.10409438 | L17: =((E17+F17)-D17)-J17 -> 0 | M17: =L17/D17 -> 0 | N17: =L17*G17 -> 0 | O17: 調理端 | P17: 展開量105% | R17: 大口蒜味香腸燒肉雙拼飯糰
A18: 7 | B18: 烤黑胡椒洋蔥絲 | C18: 289.0068 | D18: 86.26 | E18: 88.86 | F18: 0 | G18: 141.67 | H18: =(E18+F18)/D18 -> 1.0301414 | I18: 368.342 | J18: 2.04 | K18: =J18/D18 -> 0.023649432 | L18: =((E18+F18)-D18)-J18 -> 0.56 | M18: =L18/D18 -> 0.0064920009 | N18: =L18*G18 -> 79.3352 | O18: 調理端 | P18: 抓樣不穩 | R18: 糖燻野郎三十天熟成牛飯
A19: 8 | B19: 切-蒸滷牛腱 | C19: 278.523 | D19: 11.78 | E19: 11.4 | F19: 0.95 | G19: 795.78 | H19: =(E19+F19)/D19 -> 1.0483871 | I19: 453.5946 | J19: 0.35 | K19: =J19/D19 -> 0.029711375 | L19: =((E19+F19)-D19)-J19 -> 0.22 | M19: =L19/D19 -> 0.018675722 | N19: =L19*G19 -> 175.0716 | O19: 調理端 | P19: 製程不穩 | R19: 一口滷魂便當
A20: 9 | B20: 切義美滷豆乾 | C20: 269.45 | D20: 10263 | E20: 10580 | F20: 0 | G20: 0.85 | H20: =(E20+F20)/D20 -> 1.0308877 | I20: 269.45 | J20: 317 | K20: =J20/D20 -> 0.030887655 | L20: =((E20+F20)-D20)-J20 -> 0 | M20: =L20/D20 -> 0 | N20: =L20*G20 -> 0 | O20: 調理端 | P20: 製程不穩 | R20: 共用類
A21: 10 | B21: 消毒青蔥絲 | C21: 258.3984 | D21: 29.46 | E21: 30.6 | F21: 0 | G21: 248.46 | H21: =(E21+F21)/D21 -> 1.0386965 | I21: 283.2444 | J21: 1.04 | K21: =J21/D21 -> 0.035302105 | L21: =((E21+F21)-D21)-J21 -> 0.1 | M21: =L21/D21 -> 0.0033944331 | N21: =L21*G21 -> 24.846 | O21: 調理端 | P21: 抓樣不穩 | R21: 共用類
A23: 超用金額前十名半成品
A24: 明細展開 | D24: 生產資訊 | O24: 類別 | P24: 分析原因 (請填寫8大原因) | Q24: 其他原因說明 | R24: 備註-商品名稱
A25: 排序 | B25: 半成品 | D25: 生產端 | J25: 組合端
B26: 名稱 | C26: 超用金額 排序 | D26: 產出量 | J26: 報廢 | M26: 超用
D27: 訂單需求 (kg) | E27: 實際產出 (kg) | F27: 補單 (kg) | G27: 單價 (元) | H27: 實際生產 (對比訂單需求) | I27: 差異 (元) | J27: kg | K27: 占比 | L27: 金額 (元) | M27: kg | N27: 占比
A28: 1 | B28: (V)川燙小青花菜 | C28: 4133.9372 | D28: 458.95 | E28: 452.91 | F28: 34.08 | G28: 147.43 | H28: =(E28+F28)/D28 -> 1.061096 | I28: 4133.9372 | J28: 0 | K28: =J28/D28 -> 0 | L28: =J28*G28 -> 0 | M28: =((E28+F28)-D28)-J28 -> 28.04 | N28: =M28/D28 -> 0.06109598 | O28: 組合室 | P28: 原物料規格 | Q28: 大顆比例高 | R28: 共用類
A29: 2 | B29: 焗飯-奶香白醬(114年) | C29: 1417.0396 | D29: 291.62 | E29: 292.62 | F29: 19.18 | G29: 70.22 | H29: =(E29+F29)/D29 -> 1.0691996 | I29: 1417.0396 | J29: 0 | K29: =J29/D29 -> 0 | L29: =J29*G29 -> 0 | M29: =((E29+F29)-D29)-J29 -> 20.18 | N29: =M29/D29 -> 0.069199643 | O29: 組合室 | P29: 其他原因 | Q29: 注餡機差異 | R29: 二配哞哞培根奶香海陸焗飯
A30: 3 | B30: 蒸-全熟雞肉絲CL(113年) | C30: 1237.401 | D30: 91.38 | E30: 94.28 | F30: 0 | G30: 426.69 | H30: =(E30+F30)/D30 -> 1.0317356 | I30: 1237.401 | J30: 0 | K30: =J30/D30 -> 0 | L30: =J30*G30 -> 0 | M30: =((E30+F30)-D30)-J30 -> 2.9 | N30: =M30/D30 -> 0.03173561 | O30: 組合室 | P30: 抓樣不穩 | R30: 雞肉飯飯糰
A31: 4 | B31: 蒸-醬香雞肉絲CL | C31: 1098.5744 | D31: 88.37 | E31: 88.29 | F31: 3.04 | G31: 371.14 | H31: =(E31+F31)/D31 -> 1.0334955 | I31: 1098.5744 | J31: 0 | K31: =J31/D31 -> 0 | L31: =J31*G31 -> 0 | M31: =((E31+F31)-D31)-J31 -> 2.96 | N31: =M31/D31 -> 0.03349553 | O31: 組合室 | P31: 抓樣不穩 | R31: 共用類
A32: 5 | B32: 切-鹽烤牛肉 | C32: 1059.904 | D32: 64.61 | E32: 64.92 | F32: 1.29 | G32: 662.44 | H32: =(E32+F32)/D32 -> 1.024764 | I32: 1059.904 | J32: 0 | K32: =J32/D32 -> 0 | L32: =J32*G32 -> 0 | M32: =((E32+F32)-D32)-J32 -> 1.6 | N32: =M32/D32 -> 0.024763968 | O32: 組合室 | P32: 抓樣不穩 | R32: 共用類
A33: 6 | B33: 炙燒韓式牛五花 | C33: 1000.11 | D33: 22.87 | E33: 24.46 | F33: 0 | G33: 629 | H33: =(E33+F33)/D33 -> 1.0695234 | I33: 1000.11 | J33: 0 | K33: =J33/D33 -> 0 | L33: =J33*G33 -> 0 | M33: =((E33+F33)-D33)-J33 -> 1.59 | N33: =M33/D33 -> 0.069523393 | O33: 組合室 | P33: 抓樣不穩 | R33: 壹號醬炙烤牛飯糰
A34: 7 | B34: 消毒細切紅蘿蔔絲 | C34: 983.032 | D34: 259.22 | E34: 258.32 | F34: 11.2 | G34: 95.44 | H34: =(E34+F34)/D34 -> 1.0397346 | I34: 983.032 | J34: 0 | K34: =J34/D34 -> 0 | L34: =J34*G34 -> 0 | M34: =((E34+F34)-D34)-J34 -> 10.3 | N34: =M34/D34 -> 0.039734588 | O34: 組合室 | P34: 抓樣不穩 | R34: 共用類
A35: 8 | B35: 切-鹽烤熟成牛肉 | C35: 880.7792 | D35: 26.9 | E35: 26.83 | F35: 1.4 | G35: 662.24 | H35: =(E35+F35)/D35 -> 1.0494424 | I35: 880.7792 | J35: 0 | K35: =J35/D35 -> 0 | L35: =J35*G35 -> 0 | M35: =((E35+F35)-D35)-J35 -> 1.33 | N35: =M35/D35 -> 0.049442379 | O35: 組合室 | P35: 抓樣不穩 | R35: 鰻牛雙饗匠食盒
A36: 9 | B36: 越式湯凍(114年) | C36: 868.689 | D36: 477.11 | E36: 467.71 | F36: 35.7 | G36: 33.03 | H36: =(E36+F36)/D36 -> 1.0551236 | I36: 868.689 | J36: 0 | K36: =J36/D36 -> 0 | L36: =J36*G36 -> 0 | M36: =((E36+F36)-D36)-J36 -> 26.3 | N36: =M36/D36 -> 0.055123556 | O36: 組合室 | P36: 其他原因 | Q36: 注餡機差異 | R36: 越式牛肉寬粉
A37: 10 | B37: 鮮食雙色起司絲 | C37: 864 | D37: 91.64 | E37: 97 | F37: 0 | G37: 200 | H37: =(E37+F37)/D37 -> 1.0584897 | I37: 1072 | J37: 1.04 | K37: =J37/D37 -> 0.011348756 | L37: =J37*G37 -> 208 | M37: =((E37+F37)-D37)-J37 -> 4.32 | N37: =M37/D37 -> 0.047140986 | O37: 組合室 | P37: 抓樣不穩 | R37: 共用類
A39: 共用類報廢金額前十名半成品
A40: 明細展開
A41: 排序 | B41: 半成品
B42: 名稱 | C42: 報廢金額 排序 | D42: 共用類總金額 占比
A44: 1 | B44: 切義美滷豆乾 | C44: 269.45 | D44: =C44/$L$5 -> 0.1458555
...

Sheet 0828分析標準表
A1: 大溪廠半成品管理分析
A2: 日期 | C2: 營業額 | D2: 報廢展開 | F2: 超用展開 | H2: 報廢展開 | J2: 超用展開 | L2: 報廢展開
A3: 45897 | C3: 6765305.7 | D3: 總報廢 | F3: 總超用 | H3: 報廢-前10名 | J3: 超用-前10名 | L3: 共用類-總報廢
D4: 金額 | E4: 占比(營業額) | F4: 金額 | G4: 占比(營業額) | H4: 金額 | I4: 占比(總報廢) | J4: 金額 | K4: 占比(總超用) | L4: 金額 | M4: 占比(總報廢)
A5: 年度KPI目標0.25% | D5: 16316.671 | E5: =D5/C3 -> 0.0024118158 | F5: 52026.534 | G5: =F5/C3 -> 0.0076901971 | H5: =SUM(C12:C21) -> 4258.0322 | I5: =H5/D5 -> 0.26096207 | J5: =SUM(C28:C37) -> 15396.414 | K5: =J5/F5 -> 0.29593387 | L5: 2340.916 | M5: =L5/D5 -> 0.14346775
A7: 報廢金額前十名半成品
A8: 明細展開 | D8: 生產資訊 | O8: 類別 | P8: 分析原因 (請填寫8大原因) | Q8: 其他原因說明 | R8: 備註-商品名稱
A9: 排序 | B9: 半成品 | D9: 生產端 | J9: 組合端
B10: 名稱 | C10: 報廢金額 排序 | D10: 產出量 | J10: 報廢 | L10: 超用
D11: 訂單需求 (kg) | E11: 實際產出 (kg) | F11: 補單 (kg) | G11: 單價 (元) | H11: 實際生產 (對比訂單需求) | I11: 差異 (元) | J11: kg | K11: 占比 | L11: kg | M11: 占比 | N11: 金額 (元)
A12: 1 | B12: 奶油蕈菇起司醬(113年) | C12: 689.164 | D12: 125.85 | E12: 131.89 | F12: 0 | G12: 114.1 | H12: =(E12+F12)/D12 -> 1.0479936 | I12: 689.164 | J12: 6.04 | K12: =J12/D12 -> 0.047993643 | L12: =((E12+F12)-D12)-J12 -> -7.9936058e-15 | M12: =L12/D12 -> -6.3516931e-17 | N12: =L12*G12 -> -9.1207042e-13 | O12: 調理端 | P12: 抓樣不穩 | R12: 大口法式蕈菇起司雞排飯糰(113年)
A13: 2 | B13: 烤銀鮭魚肚 | C13: 494.4 | D13: 3978 | E13: 4010 | F13: 0 | G13: 15.45 | H13: =(E13+F13)/D13 -> 1.0080442 | I13: 494.4 | J13: 32 | K13: =J13/D13 -> 0.0080442433 | L13: =((E13+F13)-D13)-J13 -> 0 | M13: =L13/D13 -> 0 | N13: =L13*G13 -> 0 | O13: 調理端 | P13: 研發設定 | Q13: 研發設定，小片的規格不符合指示書設定重量 | R13: 一配贅沢鮭魚肚飯糰
A14: 3 | B14: 烤黑胡椒洋蔥絲 | C14: 449.0939 | D14: 105.38 | E14: 119.78 | F14: 0 | G14: 141.67 | H14: =(E14+F14)/D14 -> 1.1366483 | I14: 2040.048 | J14: 3.17 | K14: =J14/D14 -> 0.030081609 | L14: =((E14+F14)-D14)-J14 -> 11.23 | M14: =L14/D14 -> 0.10656671 | N14: =L14*G14 -> 1590.9541 | O14: 調理端 | P14: 展開量105% | R14: 糖燻野郎三十天熟成牛飯
A15: 4 | B15: 蒸鰻魚片(主食用) | C15: 447.63 | D15: 4383 | E15: 4426 | F15: 0 | G15: 10.41 | H15: =(E15+F15)/D15 -> 1.0098106 | I15: 447.63 | J15: 43 | K15: =J15/D15 -> 0.009810632 | L15: =((E15+F15)-D15)-J15 -> 0 | M15: =L15/D15 -> 0 | N15: =L15*G15 -> 0 | O15: 調理端 | P15: 製程不穩 | R15: 鰻牛雙饗匠食盒
A16: 5 | B16: 炸蝦仁 | C16: 420.75 | D16: 2280 | E16: 2355 | F16: 0 | G16: 5.61 | H16: =(E16+F16)/D16 -> 1.0328947 | I16: 420.75 | J16: 75 | K16: =J16/D16 -> 0.032894737 | L16: =((E16+F16)-D16)-J16 -> 0 | M16: =L16/D16 -> 0 | N16: =L16*G16 -> 0 | O16: 調理端 | P16: 製程不穩 | R16: 一配海老天婦羅飯糰
A17: 6 | B17: 切義美滷豆乾 | C17: 417.35 | D17: 10779 | E17: 11270 | F17: 0 | G17: 0.85 | H17: =(E17+F17)/D17 -> 1.0455515 | I17: 417.35 | J17: 491 | K17: =J17/D17 -> 0.045551535 | L17: =((E17+F17)-D17)-J17 -> 0 | M17: =L17/D17 -> 0 | N17: =L17*G17 -> 0 | O17: 調理端 | P17: 製程不穩 | R17: 共用類
A18: 7 | B18: 炒辣醬蔬菜 | C18: 381.3783 | D18: 14.57 | E18: 17.61 | F18: 0 | G18: 140.73 | H18: =(E18+F18)/D18 -> 1.2086479 | I18: 427.8192 | J18: 2.71 | K18: =J18/D18 -> 0.18599863 | L18: =((E18+F18)-D18)-J18 -> 0.33 | M18: =L18/D18 -> 0.022649279 | N18: =L18*G18 -> 46.4409 | O18: 調理端 | P18: 展開量105% | R18: 二配大飯糰春川風味辣炒雞
A19: 8 | B19: 滷甜不辣條 | C19: 357.4518 | D19: 1736 | E19: 1899.22 | F19: 0 | G19: 2.19 | H19: =(E19+F19)/D19 -> 1.0940207 | I19: 357.4518 | J19: 163.22 | K19: =J19/D19 -> 0.094020737 | L19: =((E19+F19)-D19)-J19 -> 0 | M19: =L19/D19 -> 0 | N19: =L19*G19 -> 0 | O19: 調理端 | P19: 製程不穩 | R19: 一口滷魂便當
A20: 9 | B20: 滷米血糕麻丁 | C20: 304.779 | D20: 1736 | E20: 1908.45 | F20: 0 | G20: 1.9 | H20: =(E20+F20)/D20 -> 1.0993376 | I20: 327.655 | J20: 160.41 | K20: =J20/D20 -> 0.092402074 | L20: =((E20+F20)-D20)-J20 -> 12.04 | M20: =L20/D20 -> 0.0069354839 | N20: =L20*G20 -> 22.876 | O20: 調理端 | P20: 製程不穩 | R20: 一口滷魂便當
A21: 10 | B21: 消毒洋蔥絲 | C21: 296.0352 | D21: 25.45 | E21: 29.47 | F21: 0 | G21: 97.38 | H21: =(E21+F21)/D21 -> 1.1579568 | I21: 391.4676 | J21: 3.04 | K21: =J21/D21 -> 0.1194499 | L21: =((E21+F21)-D21)-J21 -> 0.98 | M21: =L21/D21 -> 0.038506876 | N21: =L21*G21 -> 95.4324 | O21: 調理端 | P21: 展開量105% | R21: 越式牛肉寬粉
A23: 超用金額前十名半成品
A24: 明細展開 | D24: 生產資訊 | O24: 類別 | P24: 分析原因 (請填寫8大原因) | Q24: 其他原因說明 | R24: 備註-商品名稱
A25: 排序 | B25: 半成品 | D25: 生產端 | J25: 組合端
B26: 名稱 | C26: 超用金額 排序 | D26: 產出量 | J26: 報廢 | M26: 超用
D27: 訂單需求 (kg) | E27: 實際產出 (kg) | F27: 補單 (kg) | G27: 單價 (元) | H27: 實際生產 (對比訂單需求) | I27: 差異 (元) | J27: kg | K27: 占比 | L27: 金額 (元) | M27: kg | N27: 占比
A28: 1 | B28: (V)川燙小青花菜 | C28: 2836.5532 | D28: 628.19 | E28: 621.27 | F28: 26.16 | G28: 147.43 | H28: =(E28+F28)/D28 -> 1.0306277 | I28: 2836.5532 | J28: 0 | K28: =J28/D28 -> 0 | L28: =J28*G28 -> 0 | M28: =((E28+F28)-D28)-J28 -> 19.24 | N28: =M28/D28 -> 0.030627676 | O28: 組合室 | P28: 原物料規格 | Q28: 大顆比例高 | R28: 共用類
A29: 2 | B29: 切烤雞胸肉(111年) | C29: 1802.2108 | D29: 192.4 | E29: 189.82 | F29: 7 | G29: 407.74 | H29: =(E29+F29)/D29 -> 1.022973 | I29: 1802.2108 | J29: 0 | K29: =J29/D29 -> 0 | L29: =J29*G29 -> 0 | M29: =((E29+F29)-D29)-J29 -> 4.42 | N29: =M29/D29 -> 0.022972973 | O29: 組合室 | P29: 其他原因 | Q29: 雙圈秤重範圍 | R29: 健身G肉餐盒(113年)
A30: 3 | B30: 煮中華冷麵(110年) | C30: 1676.0445 | D30: 4649.25 | E30: 4634.8 | F30: 57 | G30: 39.39 | H30: =(E30+F30)/D30 -> 1.009152 | I30: 1676.0445 | J30: 0 | K30: =J30/D30 -> 0 | L30: =J30*G30 -> 0 | M30: =((E30+F30)-D30)-J30 -> 42.55 | N30: =M30/D30 -> 0.0091520138 | O30: 組合室 | P30: 其他原因 | Q30: 雙圈秤重範圍 | R30: 共用類
A31: 4 | B31: 炙燒韓式牛五花 | C31: 1641.69 | D31: 25.97 | E31: 28.58 | F31: 0 | G31: 629 | H31: =(E31+F31)/D31 -> 1.1005006 | I31: 1641.69 | J31: 0 | K31: =J31/D31 -> 0 | L31: =J31*G31 -> 0 | M31: =((E31+F31)-D31)-J31 -> 2.61 | N31: =M31/D31 -> 0.10050058 | O31: 組合室 | P31: 抓樣不穩 | R31: 壹號醬炙烤牛飯糰
A32: 5 | B32: 烤黑胡椒洋蔥絲 | C32: 1590.9541 | D32: 105.38 | E32: 119.78 | F32: 0 | G32: 141.67 | H32: =(E32+F32)/D32 -> 1.1366483 | I32: 2040.048 | J32: 3.17 | K32: =J32/D32 -> 0.030081609 | L32: =J32*G32 -> 449.0939 | M32: =((E32+F32)-D32)-J32 -> 11.23 | N32: =M32/D32 -> 0.10656671 | O32: 組合室 | P32: 抓樣不穩 | R32: 糖燻野郎三十天熟成牛飯
A33: 6 | B33: 切-鹽烤熟成牛肉 | C33: 1390.704 | D33: 29.22 | E33: 29.32 | F33: 2 | G33: 662.24 | H33: =(E33+F33)/D33 -> 1.0718686 | I33: 1390.704 | J33: 0 | K33: =J33/D33 -> 0 | L33: =J33*G33 -> 0 | M33: =((E33+F33)-D33)-J33 -> 2.1 | N33: =M33/D33 -> 0.071868583 | O33: 組合室 | P33: 抓樣不穩 | R33: 鰻牛雙饗匠食盒
A34: 7 | B34: 烤BBQ雞丁(112年) | C34: 1273.4364 | D34: 90.28 | E34: 91.71 | F34: 2.05 | G34: 365.93 | H34: =(E34+F34)/D34 -> 1.0385467 | I34: 1273.4364 | J34: 0 | K34: =J34/D34 -> 0 | L34: =J34*G34 -> 0 | M34: =((E34+F34)-D34)-J34 -> 3.48 | N34: =M34/D34 -> 0.038546743 | O34: 組合室 | P34: 抓樣不穩 | R34: 美式雞丁餐盒(113年)
A35: 8 | B35: 炒油蔥醬 | C35: 1214.3625 | D35: 177.45 | E35: 185.4 | F35: 0 | G35: 152.75 | H35: =(E35+F35)/D35 -> 1.0448014 | I35: 1214.3625 | J35: 0 | K35: =J35/D35 -> 0 | L35: =J35*G35 -> 0 | M35: =((E35+F35)-D35)-J35 -> 7.95 | N35: =M35/D35 -> 0.044801352 | O35: 組合室 | P35: 抓樣不穩 | R35: 雞肉飯飯糰
A36: 9 | B36: 蒸-全熟雞肉絲CL(113年) | C36: 1015.5222 | D36: 109.2 | E36: 111.58 | F36: 0 | G36: 426.69 | H36: =(E36+F36)/D36 -> 1.0217949 | I36: 1015.5222 | J36: 0 | K36: =J36/D36 -> 0 | L36: =J36*G36 -> 0 | M36: =((E36+F36)-D36)-J36 -> 2.38 | N36: =M36/D36 -> 0.021794872 | O36: 組合室 | P36: 抓樣不穩 | R36: 雞肉飯飯糰
A37: 10 | B37: 切-蒸滷牛腱 | C37: 954.936 | D37: 13.02 | E37: 13.32 | F37: 0.9 | G37: 795.78 | H37: =(E37+F37)/D37 -> 1.0921659 | I37: 954.936 | J37: 0 | K37: =J37/D37 -> 0 | L37: =J37*G37 -> 0 | M37: =((E37+F37)-D37)-J37 -> 1.2 | N37: =M37/D37 -> 0.092165899 | O37: 組合室 | P37: 抓樣不穩 | R37: 一口滷魂便當
A39: 共用類報廢金額前十名半成品
A40: 明細展開
A41: 排序 | B41: 半成品
B42: 名稱 | C42: 報廢金額 排序 | D42: 共用類總金額 占比
A44: 1 | B44: 切義美滷豆乾 | C44: 417.35 | D44: =C44/$L$5 -> 0.17828491
...

Sheet 0827分析標準表
A1: 大溪廠半成品管理分析
A2: 日期 | C2: 營業額 | D2: 報廢展開 | F2: 超用展開 | H2: 報廢展開 | J2: 超用展開 | L2: 報廢展開
A3: 45896 | C3: 7268105.9 | D3: 總報廢 | F3: 總超用 | H3: 報廢-前10名 | J3: 超用-前10名 | L3: 共用類-總報廢
D4: 金額 | E4: 占比(營業額) | F4: 金額 | G4: 占比(營業額) | H4: 金額 | I4: 占比(總報廢) | J4: 金額 | K4: 占比(總超用) | L4: 金額 | M4: 占比(總報廢)
A5: 年度KPI目標0.25% | D5: 17530.725 | E5: =D5/C3 -> 0.0024120074 | F5: 56275.879 | G5: =F5/C3 -> 0.0077428535 | H5: =SUM(C12:C21) -> 4957.1863 | I5: =H5/D5 -> 0.28277132 | J5: =SUM(C28:C37) -> 16268.267 | K5: =J5/F5 -> 0.28908064 | L5: 2589.0621 | M5: =L5/D5 -> 0.14768711
A7: 報廢金額前十名半成品
A8: 明細展開 | D8: 生產資訊 | O8: 類別 | P8: 分析原因 (請填寫8大原因) | Q8: 其他原因說明 | R8: 備註-商品名稱
A9: 排序 | B9: 半成品 | D9: 生產端 | J9: 組合端
B10: 名稱 | C10: 報廢金額 排序 | D10: 產出量 | J10: 報廢 | L10: 超用
D11: 訂單需求 (kg) | E11: 實際產出 (kg) | F11: 補單 (kg) | G11: 單價 (元) | H11: 實際生產 (對比訂單需求) | I11: 差異 (元) | J11: kg | K11: 占比 | L11: kg | M11: 占比 | N11: 金額 (元)
A12: 1 | B12: 烤銀鮭魚肚 | C12: 1761.3 | D12: 4043 | E12: 4157 | F12: 0 | G12: 15.45 | H12: =(E12+F12)/D12 -> 1.0281969 | I12: 1761.3 | J12: 114 | K12: =J12/D12 -> 0.028196884 | L12: =((E12+F12)-D12)-J12 -> 0 | M12: =L12/D12 -> 0 | N12: =L12*G12 -> 0 | O12: 調理端 | P12: 研發設定 | Q12: 研發設定，小片的規格不符合指示書設定重量 | R12: 一配贅沢鮭魚肚飯糰
A13: 2 | B13: 滷米血糕麻丁 | C13: 566.2 | D13: 2034 | E13: 2332 | F13: 0 | G13: 1.9 | H13: =(E13+F13)/D13 -> 1.1465093 | I13: 566.2 | J13: 298 | K13: =J13/D13 -> 0.14650934 | L13: =((E13+F13)-D13)-J13 -> 0 | M13: =L13/D13 -> 0 | N13: =L13*G13 -> 0 | O13: 調理端 | P13: 製程不穩 | R13: 一口滷魂便當
A14: 3 | B14: 炒油蔥醬 | C14: 447.5575 | D14: 187.81 | E14: 199.27 | F14: 0 | G14: 152.75 | H14: =(E14+F14)/D14 -> 1.0610191 | I14: 1750.515 | J14: 2.93 | K14: =J14/D14 -> 0.015600873 | L14: =((E14+F14)-D14)-J14 -> 8.53 | M14: =L14/D14 -> 0.045418242 | N14: =L14*G14 -> 1302.9575 | O14: 調理端 | P14: 展開量105% | R14: 雞肉飯飯糰
A15: 4 | B15: 烤黑胡椒洋蔥絲 | C15: 351.3416 | D15: 115.94 | E15: 119.77 | F15: 0 | G15: 141.67 | H15: =(E15+F15)/D15 -> 1.0330343 | I15: 542.5961 | J15: 2.48 | K15: =J15/D15 -> 0.021390374 | L15: =((E15+F15)-D15)-J15 -> 1.35 | M15: =L15/D15 -> 0.011643954 | N15: =L15*G15 -> 191.2545 | O15: 調理端 | P15: 抓樣不穩 | R15: 糖燻野郎三十天熟成牛飯
A16: 5 | B16: 蒸鰻魚片(主食用) | C16: 322.71 | D16: 4221 | E16: 4252 | F16: 0 | G16: 10.41 | H16: =(E16+F16)/D16 -> 1.0073442 | I16: 322.71 | J16: 31 | K16: =J16/D16 -> 0.0073442312 | L16: =((E16+F16)-D16)-J16 -> 0 | M16: =L16/D16 -> 0 | N16: =L16*G16 -> 0 | O16: 調理端 | P16: 製程不穩 | R16: 鰻牛雙饗匠食盒
A17: 6 | B17: 消毒青蔥絲 | C17: 318.0288 | D17: 35.64 | E17: 37.5 | F17: 0 | G17: 248.46 | H17: =(E17+F17)/D17 -> 1.0521886 | I17: 462.1356 | J17: 1.28 | K17: =J17/D17 -> 0.035914703 | L17: =((E17+F17)-D17)-J17 -> 0.58 | M17: =L17/D17 -> 0.01627385 | N17: =L17*G17 -> 144.1068 | O17: 調理端 | P17: 展開量105% | R17: 共用類
A18: 7 | B18: 熟化去皮馬鈴薯滾刀17-23g | C18: 298.56 | D18: 128.2 | E18: 126.21 | F18: 5.1 | G18: 96 | H18: =(E18+F18)/D18 -> 1.024259 | I18: 298.56 | J18: 3.11 | K18: =J18/D18 -> 0.02425897 | L18: =((E18+F18)-D18)-J18 -> 1.3766766e-14 | M18: =L18/D18 -> 1.0738507e-16 | N18: =L18*G18 -> 1.3216095e-12 | O18: 調理端 | P18: 抓樣不穩 | R18: 嫩烤香料雞胸排蔬滿盒
A19: 8 | B19: 自製鹽蔥(114年) | C19: 297.6498 | D19: 21.36 | E19: 22.62 | F19: 0 | G19: 236.23 | H19: =(E19+F19)/D19 -> 1.0589888 | I19: 297.6498 | J19: 1.26 | K19: =J19/D19 -> 0.058988764 | L19: =((E19+F19)-D19)-J19 -> 0 | M19: =L19/D19 -> 0 | N19: =L19*G19 -> 0 | O19: 調理端 | P19: 展開量105% | R19: 壹號醬雞豚雙拼
A20: 9 | B20: 洋蔥壹號醬 | C20: 297.1886 | D20: 47.77 | E20: 51.1 | F20: 0 | G20: 153.19 | H20: =(E20+F20)/D20 -> 1.069709 | I20: 510.1227 | J20: 1.94 | K20: =J20/D20 -> 0.040611262 | L20: =((E20+F20)-D20)-J20 -> 1.39 | M20: =L20/D20 -> 0.02909776 | N20: =L20*G20 -> 212.9341 | O20: 調理端 | P20: 展開量105% | R20: 壹號醬炙烤牛飯糰
A21: 10 | B21: 切義美滷豆乾 | C21: 296.65 | D21: 11496 | E21: 11845 | F21: 0 | G21: 0.85 | H21: =(E21+F21)/D21 -> 1.0303584 | I21: 296.65 | J21: 349 | K21: =J21/D21 -> 0.030358386 | L21: =((E21+F21)-D21)-J21 -> 0 | M21: =L21/D21 -> 0 | N21: =L21*G21 -> 0 | O21: 調理端 | P21: 製程不穩 | R21: 共用類
A23: 超用金額前十名半成品
A24: 明細展開 | D24: 生產資訊 | O24: 類別 | P24: 分析原因 (請填寫8大原因) | Q24: 其他原因說明 | R24: 備註-商品名稱
A25: 排序 | B25: 半成品 | D25: 生產端 | J25: 組合端
B26: 名稱 | C26: 超用金額 排序 | D26: 產出量 | J26: 報廢 | M26: 超用
D27: 訂單需求 (kg) | E27: 實際產出 (kg) | F27: 補單 (kg) | G27: 單價 (元) | H27: 實際生產 (對比訂單需求) | I27: 差異 (元) | J27: kg | K27: 占比 | L27: 金額 (元) | M27: kg | N27: 占比
A28: 1 | B28: (V)川燙小青花菜 | C28: 2339.7141 | D28: 707.73 | E28: 707.4 | F28: 16.2 | G28: 147.43 | H28: =(E28+F28)/D28 -> 1.0224238 | I28: 2339.7141 | J28: 0 | K28: =J28/D28 -> 0 | L28: =J28*G28 -> 0 | M28: =((E28+F28)-D28)-J28 -> 15.87 | N28: =M28/D28 -> 0.022423806 | O28: 組合室 | P28: 原物料規格 | Q28: 大顆比例高 | R28: 共用類
A29: 2 | B29: 烤BBQ雞丁(112年) | C29: 2063.8452 | D29: 101.97 | E29: 102.28 | F29: 5.33 | G29: 365.93 | H29: =(E29+F29)/D29 -> 1.0553104 | I29: 2063.8452 | J29: 0 | K29: =J29/D29 -> 0 | L29: =J29*G29 -> 0 | M29: =((E29+F29)-D29)-J29 -> 5.64 | N29: =M29/D29 -> 0.055310385 | O29: 組合室 | P29: 抓樣不穩 | R29: 美式雞丁餐盒(113年)
A30: 3 | B30: 蒸-醬香雞肉絲CL | C30: 1926.2166 | D30: 106.93 | E30: 100.99 | F30: 11.13 | G30: 371.14 | H30: =(E30+F30)/D30 -> 1.0485364 | I30: 1926.2166 | J30: 0 | K30: =J30/D30 -> 0 | L30: =J30*G30 -> 0 | M30: =((E30+F30)-D30)-J30 -> 5.19 | N30: =M30/D30 -> 0.048536426 | O30: 組合室 | P30: 抓樣不穩 | R30: 共用類
A31: 4 | B31: 日式牛培根 | C31: 1600.4772 | D31: 29.9 | E31: 28.52 | F31: 3.96 | G31: 620.34 | H31: =(E31+F31)/D31 -> 1.0862876 | I31: 1600.4772 | J31: 0 | K31: =J31/D31 -> 0 | L31: =J31*G31 -> 0 | M31: =((E31+F31)-D31)-J31 -> 2.58 | N31: =M31/D31 -> 0.086287625 | O31: 組合室 | P31: 抓樣不穩 | R31: 柚見極炙烤牛
A32: 5 | B32: 切-烤牛五花(112年) | C32: 1496.2766 | D32: 207.73 | E32: 207.19 | F32: 3.01 | G32: 605.78 | H32: =(E32+F32)/D32 -> 1.0118904 | I32: 1496.2766 | J32: 0 | K32: =J32/D32 -> 0 | L32: =J32*G32 -> 0 | M32: =((E32+F32)-D32)-J32 -> 2.47 | N32: =M32/D32 -> 0.011890435 | O32: 組合室 | P32: 其他原因 | Q32: 雙圈秤重範圍 | R32: 糖燻野郎三十天熟成牛飯
A33: 6 | B33: 煮中華冷麵(110年) | C33: 1468.8531 | D33: 5009.31 | E33: 4981.8 | F33: 64.8 | G33: 39.39 | H33: =(E33+F33)/D33 -> 1.0074441 | I33: 1468.8531 | J33: 0 | K33: =J33/D33 -> 0 | L33: =J33*G33 -> 0 | M33: =((E33+F33)-D33)-J33 -> 37.29 | N33: =M33/D33 -> 0.007444139 | O33: 組合室 | P33: 其他原因 | Q33: 雙圈秤重範圍 | R33: 共用類
A34: 7 | B34: 蒸-全熟雞肉絲CL(113年) | C34: 1442.2122 | D34: 115.57 | E34: 118.95 | F34: 0 | G34: 426.69 | H34: =(E34+F34)/D34 -> 1.0292463 | I34: 1442.2122 | J34: 0 | K34: =J34/D34 -> 0 | L34: =J34*G34 -> 0 | M34: =((E34+F34)-D34)-J34 -> 3.38 | N34: =M34/D34 -> 0.029246344 | O34: 組合室 | P34: 抓樣不穩 | R34: 雞肉飯飯糰
A35: 8 | B35: 切-鹽烤熟成牛肉 | C35: 1337.7248 | D35: 28.14 | E35: 28.16 | F35: 2 | G35: 662.24 | H35: =(E35+F35)/D35 -> 1.0717839 | I35: 1337.7248 | J35: 0 | K35: =J35/D35 -> 0 | L35: =J35*G35 -> 0 | M35: =((E35+F35)-D35)-J35 -> 2.02 | N35: =M35/D35 -> 0.071783937 | O35: 組合室 | P35: 抓樣不穩 | R35: 鰻牛雙饗匠食盒
A36: 9 | B36: 炒油蔥醬 | C36: 1302.9575 | D36: 187.81 | E36: 199.27 | F36: 0 | G36: 152.75 | H36: =(E36+F36)/D36 -> 1.0610191 | I36: 1750.515 | J36: 2.93 | K36: =J36/D36 -> 0.015600873 | L36: =J36*G36 -> 447.5575 | M36: =((E36+F36)-D36)-J36 -> 8.53 | N36: =M36/D36 -> 0.045418242 | O36: 組合室 | P36: 抓樣不穩 | R36: 雞肉飯飯糰
A37: 10 | B37: 三杯海瓜子 | C37: 1289.9898 | D37: 34.93 | E37: 35.31 | F37: 2.05 | G37: 530.86 | H37: =(E37+F37)/D37 -> 1.0695677 | I37: 1289.9898 | J37: 0 | K37: =J37/D37 -> 0 | L37: =J37*G37 -> 0 | M37: =((E37+F37)-D37)-J37 -> 2.43 | N37: =M37/D37 -> 0.069567707 | O37: 組合室 | P37: 抓樣不穩 | R37: 二配三杯海瓜子好下飯
A39: 共用類報廢金額前十名半成品
A40: 明細展開
A41: 排序 | B41: 半成品
B42: 名稱 | C42: 報廢金額 排序 | D42: 共用類總金額 占比
A44: 1 | B44: 消毒青蔥絲 | C44: 318.0288 | D44: =C44/$L$5 -> 0.12283552
...

Sheet 0826分析標準表
A1: 大溪廠半成品管理分析
A2: 日期 | C2: 營業額 | D2: 報廢展開 | F2: 超用展開 | H2: 報廢展開 | J2: 超用展開 | L2: 報廢展開
A3: 45895 | C3: 7423824.2 | D3: 總報廢 | F3: 總超用 | H3: 報廢-前10名 | J3: 超用-前10名 | L3: 共用類-總報廢
D4: 金額 | E4: 占比(營業額) | F4: 金額 | G4: 占比(營業額) | H4: 金額 | I4: 占比(總報廢) | J4: 金額 | K4: 占比(總超用) | L4: 金額 | M4: 占比(總報廢)
A5: 年度KPI目標0.25% | D5: 17888.274 | E5: =D5/C3 -> 0.0024095768 | F5: 58011.729 | G5: =F5/C3 -> 0.0078142649 | H5: =SUM(C12:C21) -> 2865.4103 | I5: =H5/D5 -> 0.16018372 | J5: =SUM(C28:C37) -> 20404.953 | K5: =J5/F5 -> 0.35173841 | L5: 2550.2186 | M5: =L5/D5 -> 0.1425637
A7: 報廢金額前十名半成品
A8: 明細展開 | D8: 生產資訊 | O8: 類別 | P8: 分析原因 (請填寫8大原因) | Q8: 其他原因說明 | R8: 備註-商品名稱
A9: 排序 | B9: 半成品 | D9: 生產端 | J9: 組合端
B10: 名稱 | C10: 報廢金額 排序 | D10: 產出量 | J10: 報廢 | L10: 超用
D11: 訂單需求 (kg) | E11: 實際產出 (kg) | F11: 補單 (kg) | G11: 單價 (元) | H11: 實際生產 (對比訂單需求) | I11: 差異 (元) | J11: kg | K11: 占比 | L11: kg | M11: 占比 | N11: 金額 (元)
A12: 1 | B12: 烤銀鮭魚肚 | C12: 556.2 | D12: 4021 | E12: 4057 | F12: 0 | G12: 15.45 | H12: =(E12+F12)/D12 -> 1.008953 | I12: 556.2 | J12: 36 | K12: =J12/D12 -> 0.0089529968 | L12: =((E12+F12)-D12)-J12 -> 0 | M12: =L12/D12 -> 0 | N12: =L12*G12 -> 0 | O12: 調理端 | P12: 研發設定 | Q12: 研發設定，小片的規格不符合指示書設定重量 | R12: 一配贅沢鮭魚肚飯糰
A13: 2 | B13: 焗飯-蕃茄拌飯 | C13: 282.6054 | D13: 84.28 | E13: 89.22 | F13: 0 | G13: 61.17 | H13: =(E13+F13)/D13 -> 1.0586141 | I13: 302.1798 | J13: 4.62 | K13: =J13/D13 -> 0.054817276 | L13: =((E13+F13)-D13)-J13 -> 0.32 | M13: =L13/D13 -> 0.0037968676 | N13: =L13*G13 -> 19.5744 | O13: 調理端 | P13: 其他原因 | Q13: 炊飯機固定批量 | R13: 二配薯勾以蛋包飯
A14: 3 | B14: 烤黑胡椒洋蔥絲 | C14: 270.5897 | D14: 119.45 | E14: 122.74 | F14: 0 | G14: 141.67 | H14: =(E14+F14)/D14 -> 1.0275429 | I14: 466.0943 | J14: 1.91 | K14: =J14/D14 -> 0.015989954 | L14: =((E14+F14)-D14)-J14 -> 1.38 | M14: =L14/D14 -> 0.011552951 | N14: =L14*G14 -> 195.5046 | O14: 調理端 | P14: 抓樣不穩 | R14: 糖燻野郎三十天熟成牛飯
A15: 4 | B15: 洋蔥壹號醬 | C15: 269.6144 | D15: 48.8 | E15: 52.07 | F15: 0 | G15: 153.19 | H15: =(E15+F15)/D15 -> 1.0670082 | I15: 500.9313 | J15: 1.76 | K15: =J15/D15 -> 0.036065574 | L15: =((E15+F15)-D15)-J15 -> 1.51 | M15: =L15/D15 -> 0.030942623 | N15: =L15*G15 -> 231.3169 | O15: 調理端 | P15: 展開量105% | R15: 壹號醬炙烤牛飯糰
A16: 5 | B16: 切義美滷豆乾 | C16: 260.95 | D16: 11163 | E16: 11470 | F16: 0 | G16: 0.85 | H16: =(E16+F16)/D16 -> 1.0275016 | I16: 260.95 | J16: 307 | K16: =J16/D16 -> 0.027501568 | L16: =((E16+F16)-D16)-J16 -> 0 | M16: =L16/D16 -> 0 | N16: =L16*G16 -> 0 | O16: 調理端 | P16: 製程不穩 | R16: 共用類
A17: 6 | B17: 自製鹽蔥(114年) | C17: 259.853 | D17: 21.58 | E17: 22.68 | F17: 0 | G17: 236.23 | H17: =(E17+F17)/D17 -> 1.0509731 | I17: 259.853 | J17: 1.1 | K17: =J17/D17 -> 0.050973123 | L17: =((E17+F17)-D17)-J17 -> 0 | M17: =L17/D17 -> 0 | N17: =L17*G17 -> 0 | O17: 調理端 | P17: 展開量105% | R17: 壹號醬雞豚雙拼
A18: 7 | B18: 烤帶皮南瓜丁(114.6) | C18: 246.1008 | D18: 34.64 | E18: 36.06 | F18: 0 | G18: 208.56 | H18: =(E18+F18)/D18 -> 1.0409931 | I18: 296.1552 | J18: 1.18 | K18: =J18/D18 -> 0.034064665 | L18: =((E18+F18)-D18)-J18 -> 0.24 | M18: =L18/D18 -> 0.0069284065 | N18: =L18*G18 -> 50.0544 | O18: 調理端 | P18: 抓樣不穩 | R18: 金沙豆腐細扁麵
A19: 8 | B19: 烤四角薯餅 | C19: 244.03 | D19: 602 | E19: 625 | F19: 0 | G19: 10.61 | H19: =(E19+F19)/D19 -> 1.038206 | I19: 244.03 | J19: 23 | K19: =J19/D19 -> 0.03820598 | L19: =((E19+F19)-D19)-J19 -> 0 | M19: =L19/D19 -> 0 | N19: =L19*G19 -> 0 | O19: 調理端 | P19: 製程不穩 | R19: 二配薯勾以蛋包飯
A20: 9 | B20: 蒸鰻魚片(主食用) | C20: 239.43 | D20: 4809 | E20: 4700 | F20: 132 | G20: 10.41 | H20: =(E20+F20)/D20 -> 1.0047827 | I20: 239.43 | J20: 23 | K20: =J20/D20 -> 0.0047826991 | L20: =((E20+F20)-D20)-J20 -> 0 | M20: =L20/D20 -> 0 | N20: =L20*G20 -> 0 | O20: 調理端 | P20: 製程不穩 | R20: 鰻牛雙饗匠食盒
A21: 10 | B21: 消毒青蔥絲 | C21: 236.037 | D21: 36.07 | E21: 37.72 | F21: 0 | G21: 248.46 | H21: =(E21+F21)/D21 -> 1.0457444 | I21: 409.959 | J21: 0.95 | K21: =J21/D21 -> 0.026337677 | L21: =((E21+F21)-D21)-J21 -> 0.7 | M21: =L21/D21 -> 0.019406709 | N21: =L21*G21 -> 173.922 | O21: 調理端 | P21: 抓樣不穩 | R21: 共用類
A23: 超用金額前十名半成品
A24: 明細展開 | D24: 生產資訊 | O24: 類別 | P24: 分析原因 (請填寫8大原因) | Q24: 其他原因說明 | R24: 備註-商品名稱
A25: 排序 | B25: 半成品 | D25: 生產端 | J25: 組合端
B26: 名稱 | C26: 超用金額 排序 | D26: 產出量 | J26: 報廢 | M26: 超用
D27: 訂單需求 (kg) | E27: 實際產出 (kg) | F27: 補單 (kg) | G27: 單價 (元) | H27: 實際生產 (對比訂單需求) | I27: 差異 (元) | J27: kg | K27: 占比 | L27: 金額 (元) | M27: kg | N27: 占比
A28: 1 | B28: 切烤雞胸肉(111年) | C28: 3624.8086 | D28: 204.02 | E28: 202.41 | F28: 10.5 | G28: 407.74 | H28: =(E28+F28)/D28 -> 1.0435742 | I28: 3624.8086 | J28: 0 | K28: =J28/D28 -> 0 | L28: =J28*G28 -> 0 | M28: =((E28+F28)-D28)-J28 -> 8.89 | N28: =M28/D28 -> 0.043574159 | O28: 組合室 | P28: 其他原因 | Q28: 雙圈秤重範圍 | R28: 健身G肉餐盒(113年)
A29: 2 | B29: 切-鹽烤牛肉 | C29: 2563.6428 | D29: 83.51 | E29: 82.6 | F29: 4.78 | G29: 662.44 | H29: =(E29+F29)/D29 -> 1.0463418 | I29: 2563.6428 | J29: 0 | K29: =J29/D29 -> 0 | L29: =J29*G29 -> 0 | M29: =((E29+F29)-D29)-J29 -> 3.87 | N29: =M29/D29 -> 0.046341755 | O29: 組合室 | P29: 抓樣不穩 | R29: 共用類
A30: 3 | B30: 蒸-全熟雞肉絲CL(113年) | C30: 2487.6027 | D30: 117.69 | E30: 123.52 | F30: 0 | G30: 426.69 | H30: =(E30+F30)/D30 -> 1.0495369 | I30: 2487.6027 | J30: 0 | K30: =J30/D30 -> 0 | L30: =J30*G30 -> 0 | M30: =((E30+F30)-D30)-J30 -> 5.83 | N30: =M30/D30 -> 0.049536919 | O30: 組合室 | P30: 抓樣不穩 | R30: 雞肉飯飯糰
A31: 4 | B31: 切-究極燒肉片 | C31: 2126.2513 | D31: 48.56 | E31: 48.93 | F31: 2.7 | G31: 692.59 | H31: =(E31+F31)/D31 -> 1.0632208 | I31: 2126.2513 | J31: 0 | K31: =J31/D31 -> 0 | L31: =J31*G31 -> 0 | M31: =((E31+F31)-D31)-J31 -> 3.07 | N31: =M31/D31 -> 0.063220758 | O31: 組合室 | P31: 抓樣不穩 | R31: 壹號醬雞豚雙拼
A32: 5 | B32: 煮牛肉片(A7) | C32: 1959.5563 | D32: 55.66 | E32: 56.01 | F32: 2.64 | G32: 655.37 | H32: =(E32+F32)/D32 -> 1.053719 | I32: 1959.5563 | J32: 0 | K32: =J32/D32 -> 0 | L32: =J32*G32 -> 0 | M32: =((E32+F32)-D32)-J32 -> 2.99 | N32: =M32/D32 -> 0.053719008 | O32: 組合室 | P32: 抓樣不穩 | R32: 越式牛肉寬粉
A33: 6 | B33: (V)川燙小青花菜 | C33: 1885.6297 | D33: 704.17 | E33: 701.68 | F33: 15.28 | G33: 147.43 | H33: =(E33+F33)/D33 -> 1.0181632 | I33: 1885.6297 | J33: 0 | K33: =J33/D33 -> 0 | L33: =J33*G33 -> 0 | M33: =((E33+F33)-D33)-J33 -> 12.79 | N33: =M33/D33 -> 0.018163228 | O33: 組合室 | P33: 原物料規格 | Q33: 大顆比例高 | R33: 共用類
A34: 7 | B34: 切-烤台式肉片 | C34: 1561.5786 | D34: 50.78 | E34: 51.35 | F34: 1.92 | G34: 627.14 | H34: =(E34+F34)/D34 -> 1.0490351 | I34: 1561.5786 | J34: 0 | K34: =J34/D34 -> 0 | L34: =J34*G34 -> 0 | M34: =((E34+F34)-D34)-J34 -> 2.49 | N34: =M34/D34 -> 0.049035053 | O34: 組合室 | P34: 抓樣不穩 | R34: 姨次滿足熟成牛豚雙拼
A35: 8 | B35: 蘑菇湯凍 | C35: 1500.4836 | D35: 315.68 | E35: 316.74 | F35: 12.8 | G35: 108.26 | H35: =(E35+F35)/D35 -> 1.0439052 | I35: 1500.4836 | J35: 0 | K35: =J35/D35 -> 0 | L35: =J35*G35 -> 0 | M35: =((E35+F35)-D35)-J35 -> 13.86 | N35: =M35/D35 -> 0.04390522 | O35: 組合室 | P35: 其他原因 | Q35: 注餡機差異 | R35: 二配鐵板蘑菇肉醬起司焗飯
A36: 9 | B36: 切-烤牛五花(112年) | C36: 1405.4096 | D36: 214.01 | E36: 214.18 | F36: 2.15 | G36: 605.78 | H36: =(E36+F36)/D36 -> 1.0108406 | I36: 1405.4096 | J36: 0 | K36: =J36/D36 -> 0 | L36: =J36*G36 -> 0 | M36: =((E36+F36)-D36)-J36 -> 2.32 | N36: =M36/D36 -> 0.010840615 | O36: 組合室 | P36: 其他原因 | Q36: 雙圈秤重範圍 | R36: 糖燻野郎三十天熟成牛飯
