Workbook

Sheet 數值累積總表(月)
B1: 項目 | D1: 1月 | E1: 2月 | F1: 3月 | G1: 4月 | H1: 5月 | I1: 6月 | J1: 7月 | K1: 8月 | L1: 9月 | M1: 10月 | N1: 11月 | O1: 12月 | P1: 合計/平均
B2: （１）收支狀況 | C2: 業績金額(千元) | D2: 146299.94 | E2: 116569.43 | F2: 148838 | G2: 160648.31 | H2: 181836.63 | I2: 194099.29 | J2: 199388.62 | K2: 175321.62 | P2: =SUM(D2:O2) -> 1323001.8
C3: 訂單數量 | D3: 4768701 | E3: 3787002 | F3: 5045753 | G3: 5396292 | H3: 6084520 | I3: 6275618 | J3: 6323244 | K3: 5581950 | P3: =SUM(D3:O3) -> 43263080
C4: 材料費(千元) | D4: 93253 | E4: 74777 | F4: 93614 | G4: 104435 | H4: 116562 | I4: 126964 | J4: 134056.59 | K4: 119419.26 | P4: =SUM(D4:O4) -> 863080.86
C5: 材料費率(%) | D5: 0.655 | E5: 0.653 | F5: 0.648 | G5: 0.663 | H5: 0.672 | I5: 0.675 | J5: 0.67233825 | K5: 0.68114396 | L5: =IFERROR(L4/L2, "") | M5: =IFERROR(M4/M2, "") | N5: =IFERROR(N4/N2, "") | O5: =IFERROR(O4/O2, "") | P5: =AVERAGEIF(D5:O5, ">0") -> 0.66493528
C6: 勞務成本(千元) | D6: 22378 | E6: 22860 | F6: 22710 | G6: 23226 | H6: 24474 | I6: 26795 | J6: 27431.997 | K6: 25354.55 | P6: =SUM(D6:O6) -> 195229.55
C7: 勞務費率(%) | D7: 0.157 | E7: 0.2 | F7: 0.157 | G7: 0.147 | H7: 0.141 | I7: 0.142 | J7: 0.13758056 | K7: 0.14461736 | L7: =IFERROR(L6/L2, "") | M7: =IFERROR(M6/M2, "") | N7: =IFERROR(N6/N2, "") | O7: =IFERROR(O6/O2, "") | P7: =AVERAGEIF(D7:O7, ">0") -> 0.15327474
B9: （２）ＫＰＩ達成進度 | C9: 人時性KPI | D9: 497.6 | E9: 497.6 | F9: 497.6 | G9: 497.6 | H9: 497.6 | I9: 497.6 | J9: 497.6 | K9: 500.4 | P9: =AVERAGEIF(D9:O9, ">0") -> 497.95
C10: 人時性(個/月均) | D10: 458.38414 | E10: 476.04172 | F10: 409.81563 | G10: 402.86432 | H10: 419.38046 | I10: 425.95259 | J10: 434.66889 | K10: 448.73866 | P10: =AVERAGEIF(D10:O10, ">0") -> 434.4808
C11: 人時達成率(%/月均) | D11: =IFERROR(D10/D9, "") -> 0.92118999 | E11: =IFERROR(E10/E9, "") -> 0.95667547 | F11: =IFERROR(F10/F9, "") -> 0.82358447 | G11: =IFERROR(G10/G9, "") -> 0.80961479 | H11: 0.94796667 | I11: 0.96282231 | J11: 0.98252463 | K11: 0.8967599 | L11: =IFERROR(L10/L9, "") | M11: =IFERROR(M10/M9, "") | N11: =IFERROR(N10/N9, "") | O11: =IFERROR(O10/O9, "") | P11: =AVERAGEIF(D11:O11, ">0") -> 0.91264228
C12: 半成品-報廢(%) | D12: 0.0024135432 | E12: 0.0023657636 | F12: 0.0020222248 | G12: 0.0020113648 | H12: 0.002008824 | I12: 0.0020072506 | J12: 0.0020067058 | K12: 0.002006695 | P12: =AVERAGEIF(D12:O12, ">0") -> 0.0021052965
C13: 半成品-超用(%) | D13: 0.0055994433 | E13: 0.0052393001 | F13: 0.0048799138 | G13: 0.0043085188 | H13: 0.0061874817 | I13: 0.0060775211 | J13: 0.0060144112 | K13: 0.006013111 | P13: =AVERAGEIF(D13:O13, ">0") -> 0.0055399626
C14: 固定產線-導入率(%) | D14: 0.9 | E14: 0.9 | F14: 0.9 | G14: 0.9 | H14: 0.9 | I14: 0.9 | J14: 0.9 | K14: 0.9 | P14: =AVERAGEIF(D14:O14, ">0") -> 0.9
C15: 教育訓練-實施率(%) | D15: 0.057692308 | E15: 0.13873626 | F15: 0.21960298 | G15: 0.30384615 | H15: 0.38709677 | I15: 0.47115385 | J15: 0.55521092 | K15: 0.63957816 | P15: =MAX(D15:O15) -> 0.63957816
B17: （３）業績構成比 | C17: 18℃-飯糰(061,063) | D17: 0.36139567 | E17: 0.34737657 | F17: 0.36414345 | G17: 0.38079956 | H17: 0.3631831 | I17: 0.29977347 | J17: 0.28835229 | K17: 0.29075759 | P17: =AVERAGEIF(D17:O17, ">0") -> 0.33697271
C18: 18℃-壽司手卷(071,072,075,076) | D18: 0.069633574 | E18: 0.077793665 | F18: 0.084480826 | G18: 0.060267904 | H18: 0.041707027 | I18: 0.035290065 | J18: 0.040105547 | K18: 0.044488661 | P18: =AVERAGEIF(D18:O18, ">0") -> 0.056720909
C19: 4℃-飯糰(065) | D19: 0.022453222 | E19: 0.02167645 | F19: 0.02436516 | G19: 0.018891118 | H19: 0.013969 | I19: 0.010903809 | J19: 0.023749546 | K19: 0.01140788 | P19: =AVERAGEIF(D19:O19, ">0") -> 0.018427023
C20: 4℃-壽司手卷(077) | D20: 0.008585039 | E20: 0.0099523222 | F20: 0.014684918 | G20: 0.028316296 | H20: 0.034128078 | I20: 0.049548361 | J20: 0.037024874 | K20: 0.0484494 | P20: =AVERAGEIF(D20:O20, ">0") -> 0.028836161
C21: 主食(091,092,093,094,095) | D21: 0.16215294 | E21: 0.18214708 | F21: 0.20289324 | G21: 0.15628268 | H21: 0.13415544 | I21: 0.1343246 | J21: 0.15806065 | K21: 0.14990661 | P21: =AVERAGEIF(D21:O21, ">0") -> 0.1599904
C22: 便當(083) | D22: 0.27057088 | E22: 0.27529226 | F22: 0.29293399 | G22: 0.27842234 | H22: 0.26474822 | I22: 0.22905816 | J22: 0.22396346 | K22: 0.25307983 | P22: =AVERAGEIF(D22:O22, ">0") -> 0.26100864
C23: 熱食義麵(122,123,124,126) | D23: 0.029234371 | E23: 0.0089796819 | F23: 0 | G23: 0 | H23: 0 | I23: 0 | J23: 0 | K23: 0 | P23: =AVERAGEIF(D23:O23, ">0") -> 0.019107026
C24: 季節調理麵(111,112) | D24: 0.040564166 | E24: 0.040109499 | F24: 0.0016541185 | G24: 0.064343547 | H24: 0.13502459 | I24: 0.17184921 | J24: 0.16810092 | K24: 0.16627334 | P24: =AVERAGEIF(D24:O24, ">0") -> 0.098489924
C25: 微波小吃(153,154,155) | D25: 0.035410133 | E25: 0.036672477 | F25: 0.01484429 | G25: 0.012676559 | H25: 0.013084541 | I25: 0.069252321 | J25: 0.060642722 | K25: 0.035636696 | P25: =AVERAGEIF(D25:O25, ">0") -> 0.034777467
B27: （４）訂單數量構成比 | C27: 18℃-飯糰(061,063) | D27: 0.58577126 | E27: 0.57025346 | F27: 0.57640852 | G27: 0.58366912 | H27: 0.56064801 | I27: 0.49244059 | J27: 0.47778245 | K27: 0.48579009 | P27: =AVERAGEIF(D27:O27, ">0") -> 0.54159544
C28: 18℃-壽司手卷(071,072,075,076) | D28: 0.081693946 | E28: 0.091615478 | F28: 0.10179987 | G28: 0.068907687 | H28: 0.044634581 | I28: 0.037850934 | J28: 0.043692921 | K28: 0.048227053 | P28: =AVERAGEIF(D28:O28, ">0") -> 0.064802809
C29: 4℃-飯糰(065) | D29: 0.024966128 | E29: 0.023825971 | F29: 0.026809081 | G29: 0.020313393 | H29: 0.014309264 | I29: 0.011252756 | J29: 0.025356763 | K29: 0.011955499 | P29: =AVERAGEIF(D29:O29, ">0") -> 0.019848607
C30: 4℃-壽司手卷(077) | D30: 0.0097963785 | E30: 0.011706622 | F30: 0.016401516 | G30: 0.031347822 | H30: 0.048132803 | I30: 0.062276894 | J30: 0.048683239 | K30: 0.062519191 | P30: =AVERAGEIF(D30:O30, ">0") -> 0.036358058
C31: 主食(091,092,093,094,095) | D31: 0.089953008 | E31: 0.10114835 | F31: 0.11343936 | G31: 0.089562981 | H31: 0.075610895 | I31: 0.076646794 | J31: 0.092940902 | K31: 0.087620993 | P31: =AVERAGEIF(D31:O31, ">0") -> 0.09086541
C32: 便當(083) | D32: 0.13708178 | E32: 0.14060779 | F32: 0.14223546 | G32: 0.13317793 | H32: 0.12743437 | I32: 0.11321897 | J32: 0.1131492 | K32: 0.1282962 | P32: =AVERAGEIF(D32:O32, ">0") -> 0.12940021
C33: 熱食義麵(122,123,124,126) | D33: 0.015652481 | E33: 0.0048238686 | F33: 0 | G33: 0 | H33: 0 | I33: 0 | J33: 0 | K33: 0 | P33: =AVERAGEIF(D33:O33, ">0") -> 0.010238175
C34: 季節調理麵(111,112) | D34: 0.022004735 | E34: 0.020902022 | F34: 0.00067918505 | G34: 0.05386458 | H34: 0.1102248 | I34: 0.14207987 | J34: 0.13977857 | K34: 0.13758704 | P34: =AVERAGEIF(D34:O34, ">0") -> 0.078390101
C35: 微波小吃(153,154,155) | D35: 0.033080287 | E35: 0.035116432 | F35: 0.02222701 | G35: 0.019156487 | H35: 0.019005279 | I35: 0.064233196 | J35: 0.058615957 | K35: 0.038003923 | P35: =AVERAGEIF(D35:O35, ">0") -> 0.036179822
B37: （５）品群別人時生產性 | C37: 18℃-飯糰(061,063) | D37: 768.96509 | E37: 774.12086 | F37: 757.59042 | G37: 740.76981 | H37: 765.35782 | I37: 783.42711 | J37: 771.87393 | K37: 782.52868 | P37: =AVERAGEIF(D37:O37, ">0") -> 768.07922
C38: 18℃-壽司手卷(071,072,075,076) | D38: 280.52358 | E38: 304.46478 | F38: 311.70582 | G38: 320.67204 | H38: 308.11597 | I38: 298.23677 | J38: 296.14736 | K38: 295.72183 | P38: =AVERAGEIF(D38:O38, ">0") -> 301.94852
C39: 4℃-飯糰(065) | D39: 258.56167 | E39: 203.24374 | F39: 331.13667 | G39: 331.07659 | H39: 209.58696 | I39: 118.56652 | J39: 117.05023 | K39: 119.39248 | P39: =AVERAGEIF(D39:O39, ">0") -> 211.07686
C40: 4℃-壽司手卷(077) | D40: 486.07171 | E40: 490.19814 | F40: 493.97618 | G40: 416.8019 | H40: 367.70757 | I40: 397.08854 | J40: 437.64998 | K40: 448.42077 | P40: =AVERAGEIF(D40:O40, ">0") -> 442.23935
C41: 主食(091,092,093,094,095) | D41: 82.669482 | E41: 81.452412 | F41: 79.949999 | G41: 82.282454 | H41: 81.903989 | I41: 84.22771 | J41: 84.954232 | K41: 84.887088 | P41: =AVERAGEIF(D41:O41, ">0") -> 82.790921
C42: 便當(083) | D42: 78.306367 | E42: 77.971323 | F42: 77.906797 | G42: 78.189351 | H42: 79.190462 | I42: 79.718377 | J42: 79.472251 | K42: 79.704121 | P42: =AVERAGEIF(D42:O42, ">0") -> 78.807381
C43: 熱食義麵(122,123,124,126) | D43: 76.250133 | E43: 72.949976 | F43: 0 | G43: 0 | H43: 0 | I43: 0 | J43: 0 | K43: 0 | P43: =AVERAGEIF(D43:O43, ">0") -> 74.600054
C44: 季節調理麵(111,112) | D44: 110.8083 | E44: 97.157501 | F44: 84.601424 | G44: 159.74229 | H44: 161.80618 | I44: 157.36335 | J44: 155.73663 | K44: 158.12481 | P44: =AVERAGEIF(D44:O44, ">0") -> 135.66756
...

Sheet 生產管理報表(月)
A1: 大溪廠生產管理報表
A3: 月別 | B3: 8 | C3: 工廠 | D3: 大溪廠
A4: （１）收支狀況 | E4: ※單位：千元 | G4: （２）ＫＰＩ達成進度
A5: 項目 | B5: 當月 | C5: 前月 | D5: 差異 | E5: 累計 | G5: 項目 | H5: KPI | I5: 當月 | J5: 前月 | K5: 累計 | L5: ※補充
A6: 業績金額 | B6: ='（１）收支狀況'!H9/1000 -> 175321.62 | C6: 199388.62 | D6: =B6-C6 -> -24066.996 | E6: ='數值累積總表(月)'!P2 -> 1323001.8 | G6: 人時性(個/月均) | H6: 497.6 | I6: ='（２）ＫＰＩ達成進度'!H9 -> 448.73866 | J6: 434.66889 | K6: ='數值累積總表(月)'!P10 -> 434.4808 | L6: 個／MH
A7: 訂單數量 | B7: ='（１）收支狀況'!K9 -> 5581950 | C7: 6323244 | D7: =B7-C7 -> -741294 | E7: ='數值累積總表(月)'!P3 -> 43263080 | G7: 人時達成率(%/月均) | H7: 0.8 | I7: ='（２）ＫＰＩ達成進度'!K9 -> 0.8967599 | J7: 0.98252463 | K7: ='數值累積總表(月)'!P11 -> 0.91264228 | L7: 達成率
A8: 材料費 | B8: ='（１）收支狀況'!N9/1000 -> 119419.26 | C8: 131878 | D8: =B8-C8 -> -12458.736 | E8: ='數值累積總表(月)'!P4 -> 863080.86 | G8: 半成品-報廢(%) | H8: 0.0025 | I8: ='（２）ＫＰＩ達成進度'!N9 -> 0.002006695 | J8: 0.0020067058 | K8: ='數值累積總表(月)'!P12 -> 0.0021052965 | L8: 報廢率
A9: 材料費率 | B9: ='（１）收支狀況'!Q9 -> 0.68114396 | C9: 0.675 | D9: =B9-C9 -> 0.0061439612 | E9: ='數值累積總表(月)'!P5 -> 0.66493528 | G9: 半成品-超用(%) | H9: 0.004 | I9: ='（２）ＫＰＩ達成進度'!Q9 -> 0.006013111 | J9: 0.0060144112 | K9: ='數值累積總表(月)'!P13 -> 0.0055399626 | L9: 超用率
A10: 勞務成本 | B10: ='（１）收支狀況'!T9/1000 -> 25354.55 | C10: 26966 | D10: =B10-C10 -> -1611.4502 | E10: ='數值累積總表(月)'!P6 -> 195229.55 | G10: 固定產線-導入率(%) | H10: 0.8 | I10: ='（２）ＫＰＩ達成進度'!T9 -> 0.9 | J10: 0.9 | K10: ='數值累積總表(月)'!P14 -> 0.9 | L10: 導入率
A11: 勞務費率 | B11: ='（１）收支狀況'!W9 -> 0.14461736 | C11: 0.138 | D11: =B11-C11 -> 0.0066173585 | E11: ='數值累積總表(月)'!P7 -> 0.15327474 | G11: 教育訓練-實施率(%) | H11: 1 | I11: ='（２）ＫＰＩ達成進度'!W9 -> 0.63957816 | J11: 0.55521092 | K11: ='數值累積總表(月)'!P15 -> 0.63957816 | L11: 實施率
A13: （３）業績構成比 | E13: ※單位：千元 | G13: （４）訂單數量構成比 | K13: ※單位：個
B14: 當月 | C14: 比例 | D14: 前月 | E14: 差異 | H14: 當月 | I14: 比例 | J14: 前月 | K14: 差異
A15: 18℃-飯糰(061,063) | B15: =SUM('（３）業績構成比'!M11:M41)/1000 -> 50976.092 | C15: =IFERROR(B15/$B$6,"") -> 0.29075759 | D15: 0.29977347 | E15: =IFERROR(C15-D15,"") -> -0.0090158771 | G15: 18℃-飯糰(061,063) | H15: =SUM('（４）訂單數量構成比'!M11:M41) -> 2711656 | I15: =IFERROR(H15/$B$7,"") -> 0.48579009 | J15: 0.47778245 | K15: =IFERROR(I15-J15,"") -> 0.0080076429
A16: 18℃-壽司手卷(071,072,075,076) | B16: =SUM('（３）業績構成比'!S11:S41)/1000 -> 7799.8241 | C16: =IFERROR(B16/$B$6,"") -> 0.044488661 | D16: 0.035290065 | E16: =IFERROR(C16-D16,"") -> 0.0091985952 | G16: 18℃-壽司手卷(071,072,075,076) | H16: =SUM('（４）訂單數量構成比'!S11:S41) -> 269201 | I16: =IFERROR(H16/$B$7,"") -> 0.048227053 | J16: 0.043692921 | K16: =IFERROR(I16-J16,"") -> 0.0045341324
A17: 4℃-飯糰(065) | B17: =SUM('（３）業績構成比'!U11:U41)/1000 -> 2000.0479 | C17: =IFERROR(B17/$B$6,"") -> 0.01140788 | D17: 0.010903809 | E17: =IFERROR(C17-D17,"") -> 0.0005040711 | G17: 4℃-飯糰(065) | H17: =SUM('（４）訂單數量構成比'!U11:U41) -> 66735 | I17: =IFERROR(H17/$B$7,"") -> 0.011955499 | J17: 0.025356763 | K17: =IFERROR(I17-J17,"") -> -0.013401264
A18: 4℃-壽司手卷(077) | B18: =SUM('（３）業績構成比'!W11:W41)/1000 -> 8494.2273 | C18: =IFERROR(B18/$B$6,"") -> 0.0484494 | D18: 0.049548361 | E18: =IFERROR(C18-D18,"") -> -0.0010989614 | G18: 4℃-壽司手卷(077) | H18: =SUM('（４）訂單數量構成比'!W11:W41) -> 348979 | I18: =IFERROR(H18/$B$7,"") -> 0.062519191 | J18: 0.048683239 | K18: =IFERROR(I18-J18,"") -> 0.013835952
A19: 主食(091,092,093,094,095) | B19: =SUM('（３）業績構成比'!AC11:AC41)/1000 -> 26281.869 | C19: =IFERROR(B19/$B$6,"") -> 0.14990661 | D19: 0.1343246 | E19: =IFERROR(C19-D19,"") -> 0.015582006 | G19: 主食(091,092,093,094,095) | H19: =SUM('（４）訂單數量構成比'!AC11:AC41) -> 489096 | I19: =IFERROR(H19/$B$7,"") -> 0.087620993 | J19: 0.092940902 | K19: =IFERROR(I19-J19,"") -> -0.0053199092
A20: 便當(083) | B20: =SUM('（３）業績構成比'!AE11:AE41)/1000 -> 44370.365 | C20: =IFERROR(B20/$B$6,"") -> 0.25307983 | D20: 0.22905816 | E20: =IFERROR(C20-D20,"") -> 0.024021661 | G20: 便當(083) | H20: =SUM('（４）訂單數量構成比'!AE11:AE41) -> 716143 | I20: =IFERROR(H20/$B$7,"") -> 0.1282962 | J20: 0.1131492 | K20: =IFERROR(I20-J20,"") -> 0.015147005
A21: 熱食義麵(122,123,124,126) | B21: =SUM('（３）業績構成比'!AG11:AG41)/1000 -> 0 | C21: =IFERROR(B21/$B$6,"") -> 0 | D21: 0 | E21: =IFERROR(C21-D21,"") -> 0 | G21: 熱食義麵(122,123,124,126) | H21: =SUM('（４）訂單數量構成比'!AG11:AG41) -> 0 | I21: =IFERROR(H21/$B$7,"") -> 0 | J21: 0 | K21: =IFERROR(I21-J21,"") -> 0
A22: 季節調理麵(111,112) | B22: =SUM('（３）業績構成比'!AI11:AI41)/1000 -> 29151.312 | C22: =IFERROR(B22/$B$6,"") -> 0.16627334 | D22: 0.17184921 | E22: =IFERROR(C22-D22,"") -> -0.0055758706 | G22: 季節調理麵(111,112) | H22: =SUM('（４）訂單數量構成比'!AI11:AI41) -> 768004 | I22: =IFERROR(H22/$B$7,"") -> 0.13758704 | J22: 0.13977857 | K22: =IFERROR(I22-J22,"") -> -0.0021915254
A23: 微波小吃(153,154,155) | B23: =SUM('（３）業績構成比'!AK11:AK41)/1000 -> 6247.8834 | C23: =IFERROR(B23/$B$6,"") -> 0.035636696 | D23: 0.069252321 | E23: =IFERROR(C23-D23,"") -> -0.033615625 | G23: 微波小吃(153,154,155) | H23: =SUM('（４）訂單數量構成比'!AK11:AK41) -> 212136 | I23: =IFERROR(H23/$B$7,"") -> 0.038003923 | J23: 0.058615957 | K23: =IFERROR(I23-J23,"") -> -0.020612034
C24: =SUM(C15:C23) -> 1 | D24: =SUM(D15:D23) -> 1 | I24: =SUM(I15:I23) -> 1 | J24: =SUM(J15:J23) -> 1
A26: （５）品群別人時生產性
A27: 品群 | B27: 當月 | C27: 前月 | D27: 差異 | E27: 累計
A28: 18℃-飯A15:A23糰(061,063) | B28: ='（５-1）品群別人時生產性(18℃-飯糰)'!C1 -> 800.69876 | C28: 771.87393 | D28: =B28-C28 -> 28.824825 | E28: ='數值累積總表(月)'!P37 -> 768.07922
A29: 18℃-壽司手卷(071,072,075,076) | B29: ='（５-2）品群別人時生產性(18℃-壽司手卷)'!C1 -> 295.69211 | C29: 296.14736 | D29: =B29-C29 -> -0.45524585 | E29: ='數值累積總表(月)'!P38 -> 301.94852
A30: 4℃-飯糰(065) | B30: ='（５-3）品群別人時生產性(4℃-飯糰)'!C1 -> 119.39248 | C30: 117.05023 | D30: =B30-C30 -> 2.3422534 | E30: ='數值累積總表(月)'!P39 -> 211.07686
A31: 4℃-壽司手卷(077) | B31: ='（５-4）品群別人時生產性(4℃-壽司手卷)'!C1 -> 471.17142 | C31: 437.64998 | D31: =B31-C31 -> 33.52144 | E31: ='數值累積總表(月)'!P40 -> 442.23935
A32: 主食(091,092,093,094,095) | B32: ='（５-5）品群別人時生產性(微波主食) '!C1 -> 84.966442 | C32: 84.954232 | D32: =B32-C32 -> 0.012209616 | E32: ='數值累積總表(月)'!P41 -> 82.790921
A33: 便當(083) | B33: ='（５-6）品群別人時生產性(便當)'!C1 -> 80.052277 | C33: 79.472251 | D33: =B33-C33 -> 0.58002637 | E33: ='數值累積總表(月)'!P42 -> 78.807381
A34: 熱食義麵(122,123,124,126) | B34: ='（５-7）品群別人時生產性(熱食義麵) '!C1 -> 0 | C34: 0 | D34: =B34-C34 -> 0 | E34: ='數值累積總表(月)'!P43 -> 74.600054
A35: 季節調理麵(111,112) | B35: ='（５-8）品群別人時生產性(季節調理麵) '!C1 -> 160.09016 | C35: 155.73663 | D35: =B35-C35 -> 4.3535316 | E35: ='數值累積總表(月)'!P44 -> 135.66756
A36: 微波小吃(153,154,155) | B36: ='（５-9）品群別人時生產性(微波小吃)'!C1 -> 89.112332 | C36: 117.58781 | D36: =B36-C36 -> -28.475475 | E36: ='數值累積總表(月)'!P45 -> 93.463819

Sheet 生產管理報表(週) 
A1: 大溪廠生產管理報表
A3: 月別 | B3: 9 | C3: 週別 | D3: W1 | E3: 工廠 | F3: 大溪廠
A4: （１）收支狀況 | E4: ※單位：千元 | G4: （２）ＫＰＩ達成進度
A5: 項目 | B5: 當週 | C5: 前週 | D5: 差異 | E5: 累計 | G5: 項目 | H5: KPI | I5: 當週 | J5: 前週 | K5: 累計 | L5: ※補充
A6: 業績金額 | B6: ='（１）收支狀況'!G40/1000 -> 36405.587 | C6: 36749.312 | D6: =B6-C6 -> -343.72513 | E6: ='（１）收支狀況'!H40:H40/1000 -> 36405.587 | G6: 人時性(個/月均) | H6: 500.4 | I6: ='（２）ＫＰＩ達成進度'!G40 -> 440.66773 | J6: 451.70211 | K6: ='（２）ＫＰＩ達成進度'!H40 -> 440.66773 | L6: 個／MH
A7: 訂單數量 | B7: ='（１）收支狀況'!J40 -> 1128982 | C7: 1138303 | D7: =B7-C7 -> -9321 | E7: ='（１）收支狀況'!K40:K40 -> 1128982 | G7: 人時達成率(%/月均) | H7: 0.8 | I7: ='（２）ＫＰＩ達成進度'!J40 -> 0.88063096 | J7: 0.90268208 | K7: ='（２）ＫＰＩ達成進度'!K40 -> 0.88063096 | L7: 達成率
A8: 材料費 | B8: ='（１）收支狀況'!M40/1000 -> 24718.254 | C8: 24963.664 | D8: =B8-C8 -> -245.40926 | E8: ='（１）收支狀況'!N40:N40/1000 -> 24718.254 | G8: 半成品-報廢(%) | H8: 0.0025 | I8: ='（２）ＫＰＩ達成進度'!M40 -> 0.0020065696 | J8: 0.0020090438 | K8: ='（２）ＫＰＩ達成進度'!N40 -> 0.0020065696 | L8: 報廢率
A9: 材料費率 | B9: ='（１）收支狀況'!P40 -> 0.67896871 | C9: 0.67929608 | D9: =B9-C9 -> -0.00032737069 | E9: ='（１）收支狀況'!Q40 -> 0.67896871 | G9: 半成品-超用(%) | H9: 0.0025 | I9: ='（２）ＫＰＩ達成進度'!P40 -> 0.0060128427 | J9: 0.0060132433 | K9: ='（２）ＫＰＩ達成進度'!Q40 -> 0.0060128427 | L9: 超用率
A10: 勞務成本 | B10: ='（１）收支狀況'!S40/1000 -> 5251.2684 | C10: 5571.3564 | D10: =B10-C10 -> -320.08807 | E10: ='（１）收支狀況'!T40/1000 -> 5251.2684 | G10: 固定產線-導入率(%) | H10: 0.8 | I10: ='（２）ＫＰＩ達成進度'!S40 -> 0.9 | J10: 0.9 | K10: ='（２）ＫＰＩ達成進度'!T40 -> 0.9 | L10: 導入率
A11: 勞務費率 | B11: ='（１）收支狀況'!V40 -> 0.14424348 | C11: 0.15160437 | D11: =B11-C11 -> -0.0073608988 | E11: ='（１）收支狀況'!W40 -> 0.14424348 | G11: 教育訓練-實施率(%) | H11: 1 | I11: =36/52*100% -> 0.69230769 | J11: 0.67307692 | K11: ='（２）ＫＰＩ達成進度'!W40 -> 0.69230769 | L11: 實施率
A13: （３）業績構成比 | E13: ※單位：千元 | G13: （４）訂單數量構成比 | K13: ※單位：個
B14: 當週 | C14: 比例 | D14: 前週 | E14: 差異 | H14: 當週 | I14: 比例 | J14: 前週 | K14: 差異
A15: 18℃-飯糰(061,063) | B15: =SUM('（３）業績構成比'!M42:M48)/1000 -> 11298.812 | C15: =IFERROR(B15/$B$6,"") -> 0.3103593 | D15: 0.26335696 | E15: =IFERROR(C15-D15,"") -> 0.047002335 | G15: 18℃-飯糰(061,063) | H15: =SUM('（４）訂單數量構成比'!M42:M48) -> 564774 | I15: =IFERROR(H15/$B$7,"") -> 0.50025067 | J15: 0.45047496 | K15: =IFERROR(I15-J15,"") -> 0.049775707
A16: 18℃-壽司手卷(071,072,075,076) | B16: =SUM('（３）業績構成比'!S42:S48)/1000 -> 1188.3288 | C16: =IFERROR(B16/$B$6,"") -> 0.032641385 | D16: 0.036756348 | E16: =IFERROR(C16-D16,"") -> -0.0041149629 | G16: 18℃-壽司手卷(071,072,075,076) | H16: =SUM('（４）訂單數量構成比'!S42:S48) -> 41126 | I16: =IFERROR(H16/$B$7,"") -> 0.036427507 | J16: 0.041041796 | K16: =IFERROR(I16-J16,"") -> -0.0046142892
A17: 4℃-飯糰(065) | B17: =SUM('（３）業績構成比'!U42:U48)/1000 -> 407.95164 | C17: =IFERROR(B17/$B$6,"") -> 0.011205743 | D17: 0.012022477 | E17: =IFERROR(C17-D17,"") -> -0.00081673378 | G17: 4℃-飯糰(065) | H17: =SUM('（４）訂單數量構成比'!U42:U48) -> 13612 | I17: =IFERROR(H17/$B$7,"") -> 0.01205688 | J17: 0.012950858 | K17: =IFERROR(I17-J17,"") -> -0.00089397799
A18: 4℃-壽司手卷(077) | B18: =SUM('（３）業績構成比'!W42:W48)/1000 -> 2174.5728 | C18: =IFERROR(B18/$B$6,"") -> 0.059731843 | D18: 0.083245969 | E18: =IFERROR(C18-D18,"") -> -0.023514127 | G18: 4℃-壽司手卷(077) | H18: =SUM('（４）訂單數量構成比'!W42:W48) -> 83280 | I18: =IFERROR(H18/$B$7,"") -> 0.073765569 | J18: 0.10169788 | K18: =IFERROR(I18-J18,"") -> -0.027932309
A19: 主食(091,092,093,094,095) | B19: =SUM('（３）業績構成比'!AC42:AC48)/1000 -> 5841.8992 | C19: =IFERROR(B19/$B$6,"") -> 0.16046711 | D19: 0.16015975 | E19: =IFERROR(C19-D19,"") -> 0.00030735125 | G19: 主食(091,092,093,094,095) | H19: =SUM('（４）訂單數量構成比'!AC42:AC48) -> 108360 | I19: =IFERROR(H19/$B$7,"") -> 0.095980272 | J19: 0.095904166 | K19: =IFERROR(I19-J19,"") -> 7.6106379e-05
A20: 便當(083) | B20: =SUM('（３）業績構成比'!AE42:AE48)/1000 -> 9837.4476 | C20: =IFERROR(B20/$B$6,"") -> 0.27021808 | D20: 0.26933716 | E20: =IFERROR(C20-D20,"") -> 0.00088091427 | G20: 便當(083) | H20: =SUM('（４）訂單數量構成比'!AE42:AE48) -> 159850 | I20: =IFERROR(H20/$B$7,"") -> 0.14158773 | J20: 0.14062073 | K20: =IFERROR(I20-J20,"") -> 0.00096700021
A21: 熱食義麵(122,123,124,126) | B21: =SUM('（３）業績構成比'!AG42:AG48)/1000 -> 0 | C21: =IFERROR(B21/$B$6,"") -> 0 | D21: 0 | E21: =IFERROR(C21-D21,"") -> 0 | G21: 熱食義麵(122,123,124,126) | H21: =SUM('（４）訂單數量構成比'!AG42:AG48) -> 0 | I21: =IFERROR(H21/$B$7,"") -> 0 | J21: 0 | K21: =IFERROR(I21-J21,"") -> 0
A22: 季節調理麵(111,112) | B22: =SUM('（３）業績構成比'!AI42:AI48)/1000 -> 4788.3251 | C22: =IFERROR(B22/$B$6,"") -> 0.1315272 | D22: 0.15020728 | E22: =IFERROR(C22-D22,"") -> -0.018680079 | G22: 季節調理麵(111,112) | H22: =SUM('（４）訂單數量構成比'!AI42:AI48) -> 125415 | I22: =IFERROR(H22/$B$7,"") -> 0.1110868 | J22: 0.12758729 | K22: =IFERROR(I22-J22,"") -> -0.016500492
A23: 微波小吃(153,154,155) | B23: =SUM('（３）業績構成比'!AK42:AK48)/1000 -> 868.24932 | C23: =IFERROR(B23/$B$6,"") -> 0.023849343 | D23: 0.024914041 | E23: =IFERROR(C23-D23,"") -> -0.0010646986 | G23: 微波小吃(153,154,155) | H23: =SUM('（４）訂單數量構成比'!AK42:AK48) -> 32565 | I23: =IFERROR(H23/$B$7,"") -> 0.02884457 | J23: 0.029722315 | K23: =IFERROR(I23-J23,"") -> -0.000877745
C24: =SUM(C15:C23) -> 1 | D24: =SUM(D15:D23) -> 1 | I24: =SUM(I15:I23) -> 1 | J24: =SUM(J15:J23) -> 1
A26: （５）品群別人時生產性
A27: 品群 | B27: 當週 | C27: 前週 | D27: 差異 | E27: 累計
A28: 18℃-飯糰(061,063) | B28: ='（５-1）品群別人時生產性(18℃-飯糰)'!L7 -> 800.69876 | C28: 784.91185 | D28: =B28-C28 -> 15.786902 | E28: ='（５-1）品群別人時生產性(18℃-飯糰)'!C1 -> 800.69876
A29: 18℃-壽司手卷(071,072,075,076) | B29: ='（５-2）品群別人時生產性(18℃-壽司手卷)'!L7 -> 295.69211 | C29: 295.74145 | D29: =B29-C29 -> -0.049338123 | E29: ='（５-2）品群別人時生產性(18℃-壽司手卷)'!C1 -> 295.69211
A30: 4℃-飯糰(065) | B30: ='（５-3）品群別人時生產性(4℃-飯糰)'!L7 -> 119.39248 | C30: 119.39248 | D30: =B30-C30 -> 0 | E30: ='（５-3）品群別人時生產性(4℃-飯糰)'!C1 -> 119.39248
A31: 4℃-壽司手卷(077) | B31: ='（５-4）品群別人時生產性(4℃-壽司手卷)'!L7 -> 471.17142 | C31: 452.58861 | D31: =B31-C31 -> 18.582808 | E31: ='（５-4）品群別人時生產性(4℃-壽司手卷)'!C1 -> 471.17142
A32: 主食(091,092,093,094,095) | B32: ='（５-5）品群別人時生產性(微波主食) '!L7 -> 84.966442 | C32: 84.953503 | D32: =B32-C32 -> 0.012939351 | E32: ='（５-5）品群別人時生產性(微波主食) '!C1 -> 84.966442
A33: 便當(083) | B33: ='（５-6）品群別人時生產性(便當)'!L7 -> 80.052277 | C33: 80.058152 | D33: =B33-C33 -> -0.0058750525 | E33: ='（５-6）品群別人時生產性(便當)'!C1 -> 80.052277
A34: 熱食義麵(122,123,124,126) | B34: ='（５-7）品群別人時生產性(熱食義麵) '!L7 -> 0 | C34: 0 | D34: =B34-C34 -> 0 | E34: ='（５-7）品群別人時生產性(熱食義麵) '!C1 -> 0
A35: 季節調理麵(111,112) | B35: ='（５-8）品群別人時生產性(季節調理麵) '!L7 -> 160.09016 | C35: 162.29408 | D35: =B35-C35 -> -2.203919 | E35: ='（５-8）品群別人時生產性(季節調理麵) '!C1 -> 160.09016
A36: 微波小吃(153,154,155) | B36: ='（５-9）品群別人時生產性(微波小吃)'!L7 -> 89.112332 | C36: 89.167635 | D36: =B36-C36 -> -0.055303644 | E36: ='（５-9）品群別人時生產性(微波小吃)'!C1 -> 89.112332

Sheet （１）收支狀況
B2: （１）收支狀況
B3: 資料繳交日 | C3: 月份 | D3: 日期 | F3: 營業額(元) | I3: 訂單數量(個) | L3: 材料費(元) | O3: 材料費率（材料費／營業額） | R3: 勞務成本（全廠人事成本） | U3: 勞務費率（勞務成本／營業額）
F4: 日 | G4: 週累積 | H4: 月累積 | I4: 日 | J4: 週累積 | K4: 月累積 | L4: 日 | M4: 週累積 | N4: 月累積 | O4: 日 | P4: 週累積 | Q4: 月累積 | R4: 日 | S4: 週累積 | T4: 月累積 | U4: 日 | V4: 週累積 | W4: 月累積
B5: =D6+7 -> 46239 | D5: 46231 | E5: 二 | F5: 6626056.9 | G5: =SUM(F5:F11) -> 42486866 | I5: 213264 | J5: =SUM(I5:I11) -> 1361947 | L5: 4366639.8 | M5: =SUM(L5:L11) -> 28602574 | O5: =L5/F5 -> 0.65901031 | P5: =M5/G5 -> 0.67320978 | R5: 925337.43 | S5: =SUM(R5:R11) -> 6007602.4 | U5: =R5/F5 -> 0.1396513 | V5: =S5/G5 -> 0.14139905
D6: =D5+1 -> 46232 | E6: 三 | F6: 6255627.2 | I6: 201459 | L6: 4227643.2 | O6: =L6/F6 -> 0.67581443 | R6: 889269.56 | U6: =R6/F6 -> 0.14215514
D7: =D6+1 -> 46233 | E7: 四 | F7: 5785963.2 | I7: 187092 | L7: 3888763.8 | O7: =L7/F7 -> 0.67210309 | R7: 833792.64 | U7: =R7/F7 -> 0.14410611
D8: =D7+1 -> 46234 | E8: 五 | F8: 4936115 | I8: 159659 | L8: 3353708.5 | O8: =L8/F8 -> 0.67942268 | R8: 775080.81 | U8: =R8/F8 -> 0.15702244
C9: 八 | D9: =D8+1 -> 46235 | E9: 六 | F9: 5278918.6 | H9: =SUM(F9:F39) -> 1.7532162e+08 | I9: 170810 | K9: =SUM(I9:I39) -> 5581950 | L9: 3538725.8 | N9: =SUM(L9:L39) -> 1.1941926e+08 | O9: =L9/F9 -> 0.67035052 | Q9: =N9/H9 -> 0.68114396 | R9: 791868.99 | T9: =SUM(R9:R39) -> 25354550 | U9: =R9/F9 -> 0.15000591 | W9: =T9/H9 -> 0.14461736
D10: =D9+1 -> 46236 | E10: 日 | F10: 6878371.5 | I10: 216220 | L10: 4644248 | O10: =L10/F10 -> 0.67519588 | R10: 910527.83 | U10: =R10/F10 -> 0.13237549
D11: =D10+1 -> 46237 | E11: 一 | F11: 6725813.8 | I11: 213443 | L11: 4582844.7 | O11: =L11/F11 -> 0.68138144 | R11: 881725.11 | U11: =R11/F11 -> 0.13109568
B12: =B5+7 -> 46246 | D12: =D11+1 -> 46238 | E12: 二 | F12: 6631265.1 | G12: =SUM(F12:F18) -> 41863931 | I12: 211425 | J12: =SUM(I12:I18) -> 1345846 | L12: 4510217.4 | M12: =SUM(L12:L18) -> 28482743 | O12: =L12/F12 -> 0.68014433 | P12: =M12/G12 -> 0.68036475 | R12: 904901.96 | S12: =SUM(R12:R18) -> 5978077.1 | U12: =R12/F12 -> 0.13645993 | V12: =S12/G12 -> 0.1427978
D13: =D12+1 -> 46239 | E13: 三 | F13: 6359056 | I13: 203649 | L13: 4293608.4 | O13: =L13/F13 -> 0.67519588 | R13: 873214.77 | U13: =R13/F13 -> 0.1373183
D14: =D13+1 -> 46240 | E14: 四 | F14: 5817645.9 | I14: 188918 | L14: 3989225.8 | O14: =L14/F14 -> 0.68571134 | R14: 838149.94 | U14: =R14/F14 -> 0.14407029
D15: =D14+1 -> 46241 | E15: 五 | F15: 4858510.1 | I15: 157640 | L15: 3320015.3 | O15: =L15/F15 -> 0.68334021 | R15: 766305.87 | U15: =R15/F15 -> 0.15772446
D16: =D15+1 -> 46242 | E16: 六 | F16: 5207710 | I16: 168530 | L16: 3540920.6 | O16: =L16/F16 -> 0.67993814 | R16: 804139.22 | U16: =R16/F16 -> 0.15441321
D17: =D16+1 -> 46243 | E17: 日 | F17: 6655646.1 | I17: 211756 | L17: 4561793.5 | O17: =L17/F17 -> 0.68540206 | R17: 912097.3 | U17: =R17/F17 -> 0.13704114
D18: =D17+1 -> 46244 | E18: 一 | F18: 6334097.6 | I18: 203928 | L18: 4266961.6 | O18: =L18/F18 -> 0.67364948 | R18: 879268.07 | U18: =R18/F18 -> 0.13881505
B19: =B12+7 -> 46253 | D19: =D18+1 -> 46245 | E19: 二 | F19: 5779689.7 | G19: =SUM(F19:F25) -> 38288005 | I19: 187621 | J19: =SUM(I19:I25) -> 1244793 | L19: 3925660.6 | M19: =SUM(L19:L25) -> 26120854 | O19: =L19/F19 -> 0.67921649 | P19: =M19/G19 -> 0.68222029 | R19: 808693.21 | S19: =SUM(R19:R25) -> 5469240.5 | U19: =R19/F19 -> 0.13991983 | V19: =S19/G19 -> 0.14284475
D20: =D19+1 -> 46246 | E20: 三 | F20: 5663016 | I20: 184147 | L20: 3904795.5 | O20: =L20/F20 -> 0.68952577 | R20: 808683.84 | U20: =R20/F20 -> 0.14280091
D21: =D20+1 -> 46247 | E21: 四 | F21: 5284211.3 | I21: 172846 | L21: 3602197.8 | O21: =L21/F21 -> 0.68169072 | R21: 759116.8 | U21: =R21/F21 -> 0.14365754
D22: =D21+1 -> 46248 | E22: 五 | F22: 4470999 | I22: 146977 | L22: 3078259.8 | O22: =L22/F22 -> 0.68849485 | R22: 708139.37 | U22: =R22/F22 -> 0.15838504
D23: =D22+1 -> 46249 | E23: 六 | F23: 4735598.2 | I23: 155408 | L23: 3231630.8 | O23: =L23/F23 -> 0.68241237 | R23: 734523.98 | U23: =R23/F23 -> 0.1551069
D24: =D23+1 -> 46250 | E24: 日 | F24: 6269913.1 | I24: 200927 | L24: 4219845.4 | O24: =L24/F24 -> 0.67303093 | R24: 884957.24 | U24: =R24/F24 -> 0.14114346
D25: =D24+1 -> 46251 | E25: 一 | F25: 6084577.5 | I25: 196867 | L25: 4158463.7 | O25: =L25/F25 -> 0.6834433 | R25: 765126.02 | U25: =R25/F25 -> 0.12574842
B26: =B19+7 -> 46260 | D26: =D25+1 -> 46252 | E26: 二 | F26: 6583839.5 | G26: =SUM(F26:F32) -> 39537270 | I26: 201857 | J26: =SUM(I26:I32) -> 1252535 | L26: 4492214.8 | M26: =SUM(L26:L32) -> 27086185 | O26: =L26/F26 -> 0.68230928 | P26: =M26/G26 -> 0.68507981 | R26: 901149.49 | S26: =SUM(R26:R32) -> 5751753.8 | U26: =R26/F26 -> 0.13687294 | V26: =S26/G26 -> 0.14547676
D27: =D26+1 -> 46253 | E27: 三 | F27: 5965361.7 | I27: 188974 | L27: 4067146.7 | O27: =L27/F27 -> 0.68179381 | R27: 844162.56 | U27: =R27/F27 -> 0.14151071
D28: =D27+1 -> 46254 | E28: 四 | F28: 5515098.4 | I28: 175085 | L28: 3809056.8 | O28: =L28/F28 -> 0.69065979 | R28: 808002.69 | U28: =R28/F28 -> 0.14650739
D29: =D28+1 -> 46255 | E29: 五 | F29: 4265125.8 | I29: 140181 | L29: 2935637.7 | O29: =L29/F29 -> 0.68828866 | R29: 727337.02 | U29: =R29/F29 -> 0.1705312
D30: =D29+1 -> 46256 | E30: 六 | F30: 4672768.8 | I30: 150801 | L30: 3213805.1 | O30: =L30/F30 -> 0.6877732 | R30: 740066.26 | U30: =R30/F30 -> 0.15837853
D31: =D30+1 -> 46257 | E31: 日 | F31: 6356809.7 | I31: 197801 | L31: 4345829.7 | O31: =L31/F31 -> 0.68364948 | R31: 886504.03 | U31: =R31/F31 -> 0.13945738
D32: =D31+1 -> 46258 | E32: 一 | F32: 6178265.8 | I32: 197836 | L32: 4222494.4 | O32: =L32/F32 -> 0.6834433 | R32: 844531.76 | U32: =R32/F32 -> 0.13669398
B33: =B26+7 -> 46267 | D33: =D32+1 -> 46259 | E33: 二 | F33: 6384123.5 | G33: =SUM(F33:F39) -> 36749312 | I33: 208377 | J33: =SUM(I33:I39) -> 1138303 | L33: 4287498.4 | M33: =SUM(L33:L39) -> 24963664 | O33: =L33/F33 -> 0.67158763 | P33: =M33/G33 -> 0.67929608 | R33: 934133.47 | S33: =SUM(R33:R39) -> 5571356.4 | U33: =R33/F33 -> 0.14632133 | V33: =S33/G33 -> 0.15160437
D34: =D33+1 -> 46260 | E34: 三 | F34: 5681937.1 | I34: 184347 | L34: 3807132.1 | O34: =L34/F34 -> 0.67004124 | R34: 841535.97 | U34: =R34/F34 -> 0.14810723
D35: =D34+1 -> 46261 | E35: 四 | F35: 4735272.9 | I35: 144091 | L35: 3255817.4 | O35: =L35/F35 -> 0.68756701 | R35: 752033.99 | U35: =R35/F35 -> 0.15881534
D36: =D35+1 -> 46262 | E36: 五 | F36: 3911723.8 | I36: 119527 | L36: 2700460.5 | O36: =L36/F36 -> 0.69035052 | R36: 681681.27 | U36: =R36/F36 -> 0.17426621
D37: =D36+1 -> 46263 | E37: 六 | F37: 4263630.5 | I37: 130180 | L37: 2908675.1 | O37: =L37/F37 -> 0.68220619 | R37: 698343.09 | U37: =R37/F37 -> 0.16379071
D38: =D37+1 -> 46264 | E38: 日 | F38: 5874431.7 | I38: 174500 | L38: 3986377.2 | O38: =L38/F38 -> 0.67859794 | R38: 821515.78 | U38: =R38/F38 -> 0.139846
D39: =D38+1 -> 46265 | E39: 一 | F39: 5898192.5 | I39: 177281 | L39: 4017702.8 | O39: =L39/F39 -> 0.68117526 | R39: 842112.86 | U39: =R39/F39 -> 0.14277473
B40: =B33+7 -> 46274 | C40: 九 | D40: =D39+1 -> 46266 | E40: 二 | F40: 5905912.7 | G40: =SUM(F40:F46) -> 36405587 | H40: =SUM(F40:F69) -> 36405587 | I40: 184538 | J40: =SUM(I40:I46) -> 1128982 | K40: =SUM(I40:I69) -> 1128982 | L40: 3997389.6 | M40: =SUM(L40:L46) -> 24718254 | N40: =SUM(L40:L69) -> 24718254 | O40: =L40/F40 -> 0.67684536 | P40: =M40/G40 -> 0.67896871 | Q40: =N40/H40 -> 0.67896871 | R40: 806832 | S40: =SUM(R40:R46) -> 5251268.4 | T40: =SUM(R40:R69) -> 5251268.4 | U40: =R40/F40 -> 0.13661428 | V40: =S40/G40 -> 0.14424348 | W40: =T40/H40 -> 0.14424348
D41: =D40+1 -> 46267 | E41: 三 | F41: 5349912.9 | I41: 166898 | L41: 3724201.2 | O41: =L41/F41 -> 0.69612371 | R41: 764317.86 | U41: =R41/F41 -> 0.14286548
...

Sheet （２）ＫＰＩ達成進度
B1: 人時生產性基準值 | C1: 500.4
B2: （２）ＫＰＩ達成進度
B3: 資料繳交日 | C3: 月份 | D3: 日期 | F3: 人時生產性(個/人) | I3: 人時生產性達成率(%) | L3: 半成品報廢(%) | O3: 半成品超用(%) | R3: 固定產線-導入率(固定產線數/總產線數) | U3: 教育訓練-實施率(進度/計畫)
F4: 日 | G4: 週平均 | H4: 月平均 | I4: 日 | J4: 週平均 | K4: 月平均 | L4: 日 | M4: 週平均 | N4: 月平均 | O4: 日 | P4: 週平均 | Q4: 月平均 | R4: 日 | S4: 週平均 | T4: 月平均 | U4: 日 | V4: 週平均 | W4: 月平均
B5: 46239 | D5: 46231 | E5: 二 | F5: 435.56218 | G5: =AVERAGE(F5:F11) -> 441.50045 | I5: =F5/$C$1 -> 0.87042801 | J5: =AVERAGE(I5:I11) -> 0.88229506 | L5: 0.0020037797 | M5: =AVERAGE(L5:L11) -> 0.002002191 | O5: 0.0060038061 | P5: =AVERAGE(O5:O11) -> 0.0060080319 | R5: 0.9 | S5: =AVERAGE(R5:R11) -> 0.9 | U5: =31/52*100% -> 0.59615385 | V5: =AVERAGE(U5:U11) -> 0.59615385
D6: =D5+1 -> 46232 | E6: 三 | F6: 438.34046 | I6: =F6/$C$1 -> 0.87598014 | L6: 0.0020019479 | O6: 0.0060017525 | R6: 0.9 | U6: =31/52*100% -> 0.59615385
D7: =D6+1 -> 46233 | E7: 四 | F7: 441.47627 | I7: =F7/$C$1 -> 0.88224675 | L7: 0.001998529 | O7: 0.0059985558 | R7: 0.9 | U7: =31/52*100% -> 0.59615385
D8: =D7+1 -> 46234 | E8: 五 | F8: 442.85545 | I8: =F8/$C$1 -> 0.88500291 | L8: 0.0019964656 | O8: 0.0059963011 | R8: 0.9 | U8: =31/52*100% -> 0.59615385
C9: 八 | D9: =D8+1 -> 46235 | E9: 六 | F9: 443.79998 | H9: =AVERAGEIF(F9:F39,"<>0") -> 448.73866 | I9: =F9/$C$1 -> 0.88689045 | K9: =AVERAGEIF(I9:I39,"<>0") -> 0.8967599 | L9: 0.0020022607 | N9: =AVERAGEIF(L9:L39,"<>0") -> 0.002006695 | O9: 0.0060024305 | Q9: =AVERAGEIF(O9:O39,"<>0") -> 0.006013111 | R9: 0.9 | T9: =AVERAGEIF(R9:R39,"<>0") -> 0.9 | U9: =31/52*100% -> 0.59615385 | W9: =AVERAGEIF(U9:U39,"<>0") -> 0.63957816
D10: =D9+1 -> 46236 | E10: 日 | F10: 443.89283 | I10: =F10/$C$1 -> 0.88707601 | L10: 0.0020060667 | O10: 0.0060398551 | R10: 0.9 | U10: =31/52*100% -> 0.59615385
D11: =D10+1 -> 46237 | E11: 一 | F11: 444.57594 | I11: =F11/$C$1 -> 0.88844113 | L11: 0.0020062877 | O11: 0.0060135224 | R11: 0.9 | U11: =31/52*100% -> 0.59615385
B12: =B5+7 -> 46246 | D12: =D11+1 -> 46238 | E12: 二 | F12: 444.87453 | G12: =AVERAGE(F12:F18) -> 444.98753 | I12: =F12/$C$1 -> 0.88903784 | J12: =AVERAGE(I12:I18) -> 0.88926364 | L12: 0.002003565 | M12: =AVERAGE(L12:L18) -> 0.0020032276 | O12: 0.0060082803 | P12: =AVERAGE(O12:O18) -> 0.0060088059 | R12: 0.9 | S12: =AVERAGE(R12:R18) -> 0.9 | U12: =32/52*100% -> 0.61538462 | V12: =AVERAGE(U12:U18) -> 0.61538462
D13: =D12+1 -> 46239 | E13: 三 | F13: 444.99873 | I13: =F13/$C$1 -> 0.88928604 | L13: 0.0020020242 | O13: 0.0060023977 | R13: 0.9 | U13: =32/52*100% -> 0.61538462
D14: =D13+1 -> 46240 | E14: 四 | F14: 444.39754 | I14: =F14/$C$1 -> 0.88808462 | L14: 0.0019980107 | O14: 0.0060038798 | R14: 0.9 | U14: =32/52*100% -> 0.61538462
D15: =D14+1 -> 46241 | E15: 五 | F15: 444.01185 | I15: =F15/$C$1 -> 0.88731386 | L15: 0.0019963329 | O15: 0.0059962864 | R15: 0.9 | U15: =32/52*100% -> 0.61538462
D16: =D15+1 -> 46242 | E16: 六 | F16: 444.63999 | I16: =F16/$C$1 -> 0.88856913 | L16: 0.0020022747 | O16: 0.0060082594 | R16: 0.9 | U16: =32/52*100% -> 0.61538462
D17: =D16+1 -> 46243 | E17: 日 | F17: 445.08293 | I17: =F17/$C$1 -> 0.88945429 | L17: 0.0020120046 | O17: 0.0060243767 | R17: 0.9 | U17: =32/52*100% -> 0.61538462
D18: =D17+1 -> 46244 | E18: 一 | F18: 446.9071 | I18: =F18/$C$1 -> 0.89309972 | L18: 0.0020083813 | O18: 0.006018161 | R18: 0.9 | U18: =32/52*100% -> 0.61538462
B19: =B12+7 -> 46253 | D19: =D18+1 -> 46245 | E19: 二 | F19: 447.04912 | G19: =AVERAGE(F19:F25) -> 447.03098 | I19: =F19/$C$1 -> 0.89338352 | J19: =AVERAGE(I19:I25) -> 0.89334728 | L19: 0.0020055281 | M19: =AVERAGE(L19:L25) -> 0.0020059773 | O19: 0.0060164485 | P19: =AVERAGE(O19:O25) -> 0.0060108531 | R19: 0.9 | S19: =AVERAGE(R19:R25) -> 0.9 | U19: =33/52*100% -> 0.63461538 | V19: =AVERAGE(U19:U25) -> 0.63461538
D20: =D19+1 -> 46246 | E20: 三 | F20: 447.17079 | I20: =F20/$C$1 -> 0.89362668 | L20: 0.0020042621 | O20: 0.0060102545 | R20: 0.9 | U20: =33/52*100% -> 0.63461538
D21: =D20+1 -> 46247 | E21: 四 | F21: 446.55731 | I21: =F21/$C$1 -> 0.89240071 | L21: 0.002003608 | O21: 0.0060057968 | R21: 0.9 | U21: =33/52*100% -> 0.63461538
D22: =D21+1 -> 46248 | E22: 五 | F22: 448.30135 | I22: =F22/$C$1 -> 0.89588599 | L22: 0.0020019534 | O22: 0.0060037292 | R22: 0.9 | U22: =33/52*100% -> 0.63461538
D23: =D22+1 -> 46249 | E23: 六 | F23: 446.41709 | I23: =F23/$C$1 -> 0.89212048 | L23: 0.0020038676 | O23: 0.0060078388 | R23: 0.9 | U23: =33/52*100% -> 0.63461538
D24: =D23+1 -> 46250 | E24: 日 | F24: 446.80395 | I24: =F24/$C$1 -> 0.89289358 | L24: 0.0020144079 | O24: 0.0060199032 | R24: 0.9 | U24: =33/52*100% -> 0.63461538
D25: =D24+1 -> 46251 | E25: 一 | F25: 446.91724 | I25: =F25/$C$1 -> 0.89311999 | L25: 0.0020082142 | O25: 0.0060120004 | R25: 0.9 | U25: =33/52*100% -> 0.63461538
B26: =B19+7 -> 46260 | D26: =D25+1 -> 46252 | E26: 二 | F26: 449.78267 | G26: =AVERAGE(F26:F32) -> 453.22646 | I26: =F26/$C$1 -> 0.89884627 | J26: =AVERAGE(I26:I32) -> 0.90572834 | L26: 0.0020120115 | M26: =AVERAGE(L26:L32) -> 0.0020093127 | O26: 0.0060242774 | P26: =AVERAGE(O26:O32) -> 0.0060171883 | R26: 0.9 | S26: =AVERAGE(R26:R32) -> 0.9 | U26: =34/52*100% -> 0.65384615 | V26: =AVERAGE(U26:U32) -> 0.65384615
D27: =D26+1 -> 46253 | E27: 三 | F27: 450.85113 | I27: =F27/$C$1 -> 0.90098148 | L27: 0.0020060207 | O27: 0.0060115049 | R27: 0.9 | U27: =34/52*100% -> 0.65384615
D28: =D27+1 -> 46254 | E28: 四 | F28: 451.28891 | I28: =F28/$C$1 -> 0.90185633 | L28: 0.0020078396 | O28: 0.0060216163 | R28: 0.9 | U28: =34/52*100% -> 0.65384615
D29: =D28+1 -> 46255 | E29: 五 | F29: 453.28715 | I29: =F29/$C$1 -> 0.90584962 | L29: 0.0020053933 | O29: 0.0060117639 | R29: 0.9 | U29: =34/52*100% -> 0.65384615
D30: =D29+1 -> 46256 | E30: 六 | F30: 452.55058 | I30: =F30/$C$1 -> 0.90437766 | L30: 0.0020098782 | O30: 0.0060097968 | R30: 0.9 | U30: =34/52*100% -> 0.65384615
D31: =D30+1 -> 46257 | E31: 日 | F31: 454.36933 | I31: =F31/$C$1 -> 0.90801224 | L31: 0.0020143219 | O31: 0.0060237164 | R31: 0.9 | U31: =34/52*100% -> 0.65384615
D32: =D31+1 -> 46258 | E32: 一 | F32: 460.45547 | I32: =F32/$C$1 -> 0.92017481 | L32: 0.0020097236 | O32: 0.0060176424 | R32: 0.9 | U32: =34/52*100% -> 0.65384615
B33: =B26+7 -> 46267 | D33: =D32+1 -> 46259 | E33: 二 | F33: 450.42791 | G33: =AVERAGE(F33:F39) -> 451.70211 | I33: =F33/$C$1 -> 0.90013572 | J33: =AVERAGE(I33:I39) -> 0.90268208 | L33: 0.0020037385 | M33: =AVERAGE(L33:L39) -> 0.0020090438 | O33: 0.0060135774 | P33: =AVERAGE(O33:O39) -> 0.0060132433 | R33: 0.9 | S33: =AVERAGE(R33:R39) -> 0.9 | U33: =35/52*100% -> 0.67307692 | V33: =AVERAGE(U33:U39) -> 0.67307692
D34: =D33+1 -> 46260 | E34: 三 | F34: 450.16072 | I34: =F34/$C$1 -> 0.89960175 | L34: 0.0020181625 | O34: 0.0060178749 | R34: 0.9 | U34: =35/52*100% -> 0.67307692
D35: =D34+1 -> 46261 | E35: 四 | F35: 449.82108 | I35: =F35/$C$1 -> 0.89892301 | L35: 0.0020116665 | O35: 0.0060119582 | R35: 0.9 | U35: =35/52*100% -> 0.67307692
D36: =D35+1 -> 46262 | E36: 五 | F36: 453.0865 | I36: =F36/$C$1 -> 0.90544865 | L36: 0.0020003443 | O36: 0.0060095149 | R36: 0.9 | U36: =35/52*100% -> 0.67307692
D37: =D36+1 -> 46263 | E37: 六 | F37: 455.90036 | I37: =F37/$C$1 -> 0.91107186 | L37: 0.0020036692 | O37: 0.0060054864 | R37: 0.9 | U37: =35/52*100% -> 0.67307692
D38: =D37+1 -> 46264 | E38: 日 | F38: 454.23385 | I38: =F38/$C$1 -> 0.9077415 | L38: 0.0020137153 | O38: 0.0060144913 | R38: 0.9 | U38: =35/52*100% -> 0.67307692
D39: =D38+1 -> 46265 | E39: 一 | F39: 448.28439 | I39: =F39/$C$1 -> 0.89585209 | L39: 0.00201201 | O39: 0.0060197998 | R39: 0.9 | U39: =35/52*100% -> 0.67307692
B40: =B33+7 -> 46274 | D40: =D39+1 -> 46266 | E40: 二 | F40: 447.38329 | G40: =AVERAGE(F40:F46) -> 440.66773 | H40: =AVERAGEIF(F40:F69,"<>0") -> 440.66773 | I40: =F40/$C$1 -> 0.89405134 | J40: =AVERAGE(I40:I46) -> 0.88063096 | K40: =AVERAGEIF(I40:I69,"<>0") -> 0.88063096 | L40: 0.0020178576 | M40: =AVERAGE(L40:L46) -> 0.0020065696 | N40: =AVERAGEIF(L40:L69,"<>0") -> 0.0020065696 | O40: 0.0060304168 | P40: =AVERAGE(O40:O46) -> 0.0060128427 | Q40: =AVERAGEIF(O40:O69,"<>0") -> 0.0060128427 | R40: 0.9 | S40: =AVERAGE(R40:R46) -> 0.9 | T40: =AVERAGEIF(R40:R69,"<>0") -> 0.9 | U40: =36/52*100% -> 0.69230769 | V40: =AVERAGE(U40:U46) -> 0.69230769 | W40: =AVERAGEIF(U40:U69,"<>0") -> 0.69230769
...

Sheet （３）業績構成比
B2: （3）業績構成比
B3: 資料繳交日 | C3: 月份 | D3: 日期 | F3: 營業額 | I3: 品類業績
I4: 18℃-飯糰 | O4: 18℃-壽司手卷 | U4: 4℃-飯糰 | W4: 4℃-壽司手卷 | Y4: 主食 | AE4: 便當 | AG4: 熱食義麵 | AI4: 季節調理麵 | AK4: 微波小吃
F5: 日 | G5: 週累積 | H5: 月累積 | I5: 一配 | K5: 二配 | M5: 合計 | O5: 一配 | Q5: 二配 | S5: 合計 | U5: 一配 | W5: 一配 | Y5: 一配 | AA5: 二配 | AC5: 合計 | AE5: 一配 | AG5: 一配 | AI5: 一配 | AK5: 一配
I6: 業績(元) | J6: 比例(%) | K6: 業績(元) | L6: 比例(%) | M6: 業績(元) | N6: 比例(%) | O6: 業績(元) | P6: 比例(%) | Q6: 業績(元) | R6: 比例(%) | S6: 業績(元) | T6: 比例(%) | U6: 業績(元) | V6: 比例(%) | W6: 業績(元) | X6: 比例(%) | Y6: 業績(元) | Z6: 比例(%) | AA6: 業績(元) | AB6: 比例(%) | AC6: 業績(元) | AD6: 比例(%) | AE6: 業績(元) | AF6: 比例(%) | AG6: 業績(元) | AH6: 比例(%) | AI6: 業績(元) | AJ6: 比例(%) | AK6: 業績(元) | AL6: 比例(%)
B7: 46239 | D7: 46231 | E7: 二 | F7: =SUM(M7,S7,U7,W7,AC7,AE7,AG7,AI7,AK7) -> 6626056.9 | G7: =SUM(F7:F13) -> 42486866 | I7: 916210.92 | J7: =I7/$F7 -> 0.13827393 | K7: 1056654.7 | L7: =K7/$F7 -> 0.15946962 | M7: =I7+K7 -> 1972865.7 | N7: =M7/$F7 -> 0.29774354 | O7: 332859.43 | P7: =O7/$F7 -> 0.050234919 | Q7: 0 | R7: =Q7/$F7 -> 0 | S7: =O7+Q7 -> 332859.43 | T7: =S7/$F7 -> 0.050234919 | U7: 72647.28 | V7: =U7/$F7 -> 0.010963878 | W7: 405052.75 | X7: =W7/$F7 -> 0.061130286 | Y7: 391742.31 | Z7: =Y7/$F7 -> 0.059121483 | AA7: 564780.37 | AB7: =AA7/$F7 -> 0.08523627 | AC7: =Y7+AA7 -> 956522.68 | AD7: =AC7/$F7 -> 0.14435775 | AE7: 1542665.4 | AF7: =AE7/F7 -> 0.23281801 | AG7: 0 | AH7: =AG7/$F7 -> 0 | AI7: 974769.31 | AJ7: =AI7/$F7 -> 0.14711152 | AK7: 368674.37 | AL7: =AK7/$F7 -> 0.055640085
D8: 46232 | E8: 三 | F8: =SUM(M8,S8,U8,W8,AC8,AE8,AG8,AI8,AK8) -> 6255627.2 | I8: 892990.06 | J8: =I8/$F8 -> 0.14274988 | K8: 1002618.1 | L8: =K8/$F8 -> 0.16027459 | M8: =I8+K8 -> 1895608.1 | N8: =M8/F8 -> 0.30302447 | O8: 335009.01 | P8: =O8/$F8 -> 0.053553225 | Q8: 0 | R8: =Q8/$F8 -> 0 | S8: =O8+Q8 -> 335009.01 | T8: =S8/F8 -> 0.053553225 | U8: 65034.9 | V8: =U8/F8 -> 0.010396224 | W8: 310798.37 | X8: =W8/$F8 -> 0.049683007 | Y8: 360085.06 | Z8: =Y8/$F8 -> 0.057561784 | AA8: 557071.84 | AB8: =AA8/$F8 -> 0.089051317 | AC8: =Y8+AA8 -> 917156.9 | AD8: =AC8/$F8 -> 0.1466131 | AE8: 1411466.7 | AF8: =AE8/F8 -> 0.22563152 | AG8: 0 | AH8: =AG8/$F8 -> 0 | AI8: 957447.55 | AJ8: =AI8/$F8 -> 0.15305381 | AK8: 363105.69 | AL8: =AK8/$F8 -> 0.05804465
D9: 46233 | E9: 四 | F9: =SUM(M9,S9,U9,W9,AC9,AE9,AG9,AI9,AK9) -> 5785963.2 | I9: 838667.45 | J9: =I9/$F9 -> 0.14494863 | K9: 888976 | L9: =K9/$F9 -> 0.15364356 | M9: =I9+K9 -> 1727643.4 | N9: =M9/$F9 -> 0.29859219 | O9: 317196.07 | P9: =O9/$F9 -> 0.054821653 | Q9: 0 | R9: =Q9/$F9 -> 0 | S9: =O9+Q9 -> 317196.07 | T9: =S9/$F9 -> 0.054821653 | U9: 65454.48 | V9: =U9/$F9 -> 0.011312633 | W9: 297300.07 | X9: =W9/$F9 -> 0.051382987 | Y9: 336180.01 | Z9: =Y9/$F9 -> 0.058102687 | AA9: 426289.7 | AB9: =AA9/$F9 -> 0.073676531 | AC9: =Y9+AA9 -> 762469.71 | AD9: =AC9/$F9 -> 0.13177922 | AE9: 1297948 | AF9: =AE9/F9 -> 0.22432704 | AG9: 0 | AH9: =AG9/$F9 -> 0 | AI9: 974797.79 | AJ9: =AI9/$F9 -> 0.16847632 | AK9: 343153.66 | AL9: =AK9/$F9 -> 0.059307957
D10: 46234 | E10: 五 | F10: =SUM(M10,S10,U10,W10,AC10,AE10,AG10,AI10,AK10) -> 4936115 | I10: 642135.93 | J10: =I10/$F10 -> 0.13008934 | K10: 816869.93 | L10: =K10/$F10 -> 0.16548843 | M10: =I10+K10 -> 1459005.9 | N10: =M10/F10 -> 0.29557777 | O10: 253053.06 | P10: =O10/$F10 -> 0.051265633 | Q10: 0 | R10: =Q10/$F10 -> 0 | S10: =O10+Q10 -> 253053.06 | T10: =S10/F10 -> 0.051265633 | U10: 48281.67 | V10: =U10/F10 -> 0.0097813098 | W10: 216372.37 | X10: =W10/$F10 -> 0.043834548 | Y10: 296368.4 | Z10: =Y10/$F10 -> 0.060040821 | AA10: 405960.26 | AB10: =AA10/$F10 -> 0.082242869 | AC10: =Y10+AA10 -> 702328.66 | AD10: =AC10/$F10 -> 0.14228369 | AE10: 966163.92 | AF10: =AE10/F10 -> 0.19573367 | AG10: 0 | AH10: =AG10/$F10 -> 0 | AI10: 1001971.8 | AJ10: =AI10/$F10 -> 0.20298795 | AK10: 288937.63 | AL10: =AK10/$F10 -> 0.058535433
C11: 八 | D11: 46235 | E11: 六 | F11: =SUM(M11,S11,U11,W11,AC11,AE11,AG11,AI11,AK11) -> 5278918.6 | H11: =SUM(F11:F41) -> 1.7532162e+08 | I11: 603913.17 | J11: =I11/$F11 -> 0.11440093 | K11: 950774.94 | L11: =K11/$F11 -> 0.1801079 | M11: =I11+K11 -> 1554688.1 | N11: =M11/$F11 -> 0.29450883 | O11: 244351.8 | P11: =O11/$F11 -> 0.046288231 | Q11: 0 | R11: =Q11/$F11 -> 0 | S11: =O11+Q11 -> 244351.8 | T11: =S11/$F11 -> 0.046288231 | U11: 49630.32 | V11: =U11/$F11 -> 0.0094016074 | W11: 239798.25 | X11: =W11/$F11 -> 0.045425639 | Y11: 320707.3 | Z11: =Y11/$F11 -> 0.060752462 | AA11: 528342.76 | AB11: =AA11/$F11 -> 0.10008542 | AC11: =Y11+AA11 -> 849050.06 | AD11: =AC11/$F11 -> 0.16083788 | AE11: 1036536.9 | AF11: =AE11/F11 -> 0.19635402 | AG11: 0 | AH11: =AG11/$F11 -> 0 | AI11: 1014723.2 | AJ11: =AI11/$F11 -> 0.19222179 | AK11: 290139.98 | AL11: =AK11/$F11 -> 0.054962011
D12: 46236 | E12: 日 | F12: =SUM(M12,S12,U12,W12,AC12,AE12,AG12,AI12,AK12) -> 6878371.5 | I12: 877498.45 | J12: =I12/$F12 -> 0.12757358 | K12: 1090163.9 | L12: =K12/$F12 -> 0.15849157 | M12: =I12+K12 -> 1967662.3 | N12: =M12/F12 -> 0.28606515 | O12: 327772.14 | P12: =O12/$F12 -> 0.047652579 | Q12: 0 | R12: =Q12/$F12 -> 0 | S12: =O12+Q12 -> 327772.14 | T12: =S12/F12 -> 0.047652579 | U12: 81368.55 | V12: =U12/F12 -> 0.011829624 | W12: 267861.06 | X12: =W12/$F12 -> 0.038942512 | Y12: 391389.14 | Z12: =Y12/$F12 -> 0.056901425 | AA12: 621079.83 | AB12: =AA12/$F12 -> 0.090294604 | AC12: =Y12+AA12 -> 1012469 | AD12: =AC12/$F12 -> 0.14719603 | AE12: 1726381.6 | AF12: =AE12/F12 -> 0.25098696 | AG12: 0 | AH12: =AG12/$F12 -> 0 | AI12: 1134622.1 | AJ12: =AI12/$F12 -> 0.16495505 | AK12: 360234.73 | AL12: =AK12/$F12 -> 0.052372096
D13: 46237 | E13: 一 | F13: =SUM(M13,S13,U13,W13,AC13,AE13,AG13,AI13,AK13) -> 6725813.8 | I13: 864009.96 | J13: =I13/$F13 -> 0.12846177 | K13: 1075351.2 | L13: =K13/$F13 -> 0.15988418 | M13: =I13+K13 -> 1939361.2 | N13: =M13/$F13 -> 0.28834595 | O13: 315262.73 | P13: =O13/$F13 -> 0.046873544 | Q13: 0 | R13: =Q13/$F13 -> 0 | S13: =O13+Q13 -> 315262.73 | T13: =S13/$F13 -> 0.046873544 | U13: 70998.93 | V13: =U13/$F13 -> 0.010556184 | W13: 303013.85 | X13: =W13/$F13 -> 0.04505237 | Y13: 401346.24 | Z13: =Y13/$F13 -> 0.059672517 | AA13: 561753.03 | AB13: =AA13/$F13 -> 0.083521942 | AC13: =Y13+AA13 -> 963099.27 | AD13: =AC13/$F13 -> 0.14319446 | AE13: 1604276.8 | AF13: =AE13/F13 -> 0.2385253 | AG13: 0 | AH13: =AG13/$F13 -> 0 | AI13: 1129650.8 | AJ13: =AI13/$F13 -> 0.16795749 | AK13: 400150.24 | AL13: =AK13/$F13 -> 0.059494695
B14: =B7+7 -> 46246 | D14: 46238 | E14: 二 | F14: =SUM(M14,S14,U14,W14,AC14,AE14,AG14,AI14,AK14) -> 6631265.1 | G14: =SUM(F14:F20) -> 41863931 | I14: 857079.17 | J14: =I14/$F14 -> 0.12924821 | K14: 1068334.8 | L14: =K14/$F14 -> 0.16110573 | M14: =I14+K14 -> 1925414 | N14: =M14/$F14 -> 0.29035394 | O14: 313871.57 | P14: =O14/$F14 -> 0.04733208 | Q14: 0 | R14: =Q14/$F14 -> 0 | S14: =O14+Q14 -> 313871.57 | T14: =S14/$F14 -> 0.04733208 | U14: 74355.57 | V14: =U14/$F14 -> 0.011212879 | W14: 257387.76 | X14: =W14/$F14 -> 0.038814277 | Y14: 362160.97 | Z14: =Y14/$F14 -> 0.054614159 | AA14: 560720.56 | AB14: =AA14/$F14 -> 0.084557102 | AC14: =Y14+AA14 -> 922881.53 | AD14: =AC14/$F14 -> 0.13917126 | AE14: 1541947.7 | AF14: =AE14/F14 -> 0.23252693 | AG14: 0 | AH14: =AG14/$F14 -> 0 | AI14: 1242921.7 | AJ14: =AI14/$F14 -> 0.18743357 | AK14: 352485.25 | AL14: =AK14/$F14 -> 0.053155053
D15: 46239 | E15: 三 | F15: =SUM(M15,S15,U15,W15,AC15,AE15,AG15,AI15,AK15) -> 6359056 | I15: 842955.62 | J15: =I15/$F15 -> 0.13255987 | K15: 1022362.3 | L15: =K15/$F15 -> 0.16077266 | M15: =I15+K15 -> 1865317.9 | N15: =M15/F15 -> 0.29333252 | O15: 312054.82 | P15: =O15/$F15 -> 0.049072507 | Q15: 0 | R15: =Q15/$F15 -> 0 | S15: =O15+Q15 -> 312054.82 | T15: =S15/F15 -> 0.049072507 | U15: 63146.79 | V15: =U15/F15 -> 0.0099302145 | W15: 255786.58 | X15: =W15/$F15 -> 0.040223986 | Y15: 329826.56 | Z15: =Y15/$F15 -> 0.051867221 | AA15: 546079.94 | AB15: =AA15/$F15 -> 0.085874372 | AC15: =Y15+AA15 -> 875906.5 | AD15: =AC15/$F15 -> 0.13774159 | AE15: 1436100.7 | AF15: =AE15/F15 -> 0.22583551 | AG15: 0 | AH15: =AG15/$F15 -> 0 | AI15: 1204932.3 | AJ15: =AI15/$F15 -> 0.18948289 | AK15: 345810.39 | AL15: =AK15/$F15 -> 0.054380775
D16: 46240 | E16: 四 | F16: =SUM(M16,S16,U16,W16,AC16,AE16,AG16,AI16,AK16) -> 5817645.9 | I16: 805504.79 | J16: =I16/$F16 -> 0.13845889 | K16: 921519.6 | L16: =K16/$F16 -> 0.15840077 | M16: =I16+K16 -> 1727024.4 | N16: =M16/$F16 -> 0.29685966 | O16: 294598.61 | P16: =O16/$F16 -> 0.0506388 | Q16: 0 | R16: =Q16/$F16 -> 0 | S16: =O16+Q16 -> 294598.61 | T16: =S16/$F16 -> 0.0506388 | U16: 64974.96 | V16: =U16/$F16 -> 0.0111686 | W16: 249989.26 | X16: =W16/$F16 -> 0.042970862 | Y16: 309485.95 | Z16: =Y16/$F16 -> 0.053197798 | AA16: 415950.19 | AB16: =AA16/$F16 -> 0.071498025 | AC16: =Y16+AA16 -> 725436.14 | AD16: =AC16/$F16 -> 0.12469582 | AE16: 1249878.7 | AF16: =AE16/F16 -> 0.21484269 | AG16: 0 | AH16: =AG16/$F16 -> 0 | AI16: 1166851 | AJ16: =AI16/$F16 -> 0.20057098 | AK16: 338892.9 | AL16: =AK16/$F16 -> 0.058252583
D17: 46241 | E17: 五 | F17: =SUM(M17,S17,U17,W17,AC17,AE17,AG17,AI17,AK17) -> 4858510.1 | I17: 608534.95 | J17: =I17/$F17 -> 0.12525135 | K17: 819416.28 | L17: =K17/$F17 -> 0.16865588 | M17: =I17+K17 -> 1427951.2 | N17: =M17/F17 -> 0.29390723 | O17: 225136.19 | P17: =O17/$F17 -> 0.046338525 | Q17: 0 | R17: =Q17/$F17 -> 0 | S17: =O17+Q17 -> 225136.19 | T17: =S17/F17 -> 0.046338525 | U17: 44205.75 | V17: =U17/F17 -> 0.0090986227 | W17: 183306.33 | X17: =W17/$F17 -> 0.037728918 | Y17: 272663.26 | Z17: =Y17/$F17 -> 0.056120756 | AA17: 413793.2 | AB17: =AA17/$F17 -> 0.085168744 | AC17: =Y17+AA17 -> 686456.46 | AD17: =AC17/$F17 -> 0.1412895 | AE17: 937494.25 | AF17: =AE17/F17 -> 0.19295921 | AG17: 0 | AH17: =AG17/$F17 -> 0 | AI17: 1071266.3 | AJ17: =AI17/$F17 -> 0.22049275 | AK17: 282693.61 | AL17: =AK17/$F17 -> 0.058185247
D18: 46242 | E18: 六 | F18: =SUM(M18,S18,U18,W18,AC18,AE18,AG18,AI18,AK18) -> 5207710 | I18: 574346.99 | J18: =I18/$F18 -> 0.11028782 | K18: 958866.58 | L18: =K18/$F18 -> 0.18412442 | M18: =I18+K18 -> 1533213.6 | N18: =M18/$F18 -> 0.29441224 | O18: 213936.77 | P18: =O18/$F18 -> 0.041080777 | Q18: 0 | R18: =Q18/$F18 -> 0 | S18: =O18+Q18 -> 213936.77 | T18: =S18/$F18 -> 0.041080777 | U18: 47652.3 | V18: =U18/$F18 -> 0.0091503368 | W18: 193061.76 | X18: =W18/$F18 -> 0.037072295 | Y18: 290648.93 | Z18: =Y18/$F18 -> 0.055811275 | AA18: 526138.22 | AB18: =AA18/$F18 -> 0.10103063 | AC18: =Y18+AA18 -> 816787.15 | AD18: =AC18/$F18 -> 0.15684191 | AE18: 1057265.1 | AF18: =AE18/F18 -> 0.20301919 | AG18: 0 | AH18: =AG18/$F18 -> 0 | AI18: 1064846.3 | AJ18: =AI18/$F18 -> 0.20447496 | AK18: 280947.03 | AL18: =AK18/$F18 -> 0.053948287
D19: 46243 | E19: 日 | F19: =SUM(M19,S19,U19,W19,AC19,AE19,AG19,AI19,AK19) -> 6655646.1 | I19: 834309.99 | J19: =I19/$F19 -> 0.12535372 | K19: 1100928.4 | L19: =K19/$F19 -> 0.16541271 | M19: =I19+K19 -> 1935238.4 | N19: =M19/F19 -> 0.29076643 | O19: 299433.43 | P19: =O19/$F19 -> 0.044989386 | Q19: 0 | R19: =Q19/$F19 -> 0 | S19: =O19+Q19 -> 299433.43 | T19: =S19/F19 -> 0.044989386 | U19: 81218.7 | V19: =U19/F19 -> 0.012202978 | W19: 253716.25 | X19: =W19/$F19 -> 0.038120454 | Y19: 364346.75 | Z19: =Y19/$F19 -> 0.054742507 | AA19: 614255.54 | AB19: =AA19/$F19 -> 0.092290896 | AC19: =Y19+AA19 -> 978602.29 | AD19: =AC19/$F19 -> 0.1470334 | AE19: 1623092.2 | AF19: =AE19/F19 -> 0.24386697 | AG19: 0 | AH19: =AG19/$F19 -> 0 | AI19: 1235753.1 | AJ19: =AI19/$F19 -> 0.1856699 | AK19: 248591.62 | AL19: =AK19/$F19 -> 0.037350487
D20: 46244 | E20: 一 | F20: =SUM(M20,S20,U20,W20,AC20,AE20,AG20,AI20,AK20) -> 6334097.6 | I20: 801920.09 | J20: =I20/$F20 -> 0.12660368 | K20: 1078602.7 | L20: =K20/$F20 -> 0.17028514 | M20: =I20+K20 -> 1880522.8 | N20: =M20/$F20 -> 0.29688882 | O20: 312805.92 | P20: =O20/$F20 -> 0.049384449 | Q20: 0 | R20: =Q20/$F20 -> 0 | S20: =O20+Q20 -> 312805.92 | T20: =S20/$F20 -> 0.049384449 | U20: 71418.51 | V20: =U20/$F20 -> 0.011275246 | W20: 281829.55 | X20: =W20/$F20 -> 0.044494033 | Y20: 375996.35 | Z20: =Y20/$F20 -> 0.059360682 | AA20: 573928.04 | AB20: =AA20/$F20 -> 0.090609283 | AC20: =Y20+AA20 -> 949924.39 | AD20: =AC20/$F20 -> 0.14996996 | AE20: 1559266.4 | AF20: =AE20/F20 -> 0.24617025 | AG20: 0 | AH20: =AG20/$F20 -> 0 | AI20: 989183.96 | AJ20: =AI20/$F20 -> 0.1561681 | AK20: 289146.08 | AL20: =AK20/$F20 -> 0.045649136
B21: =B14+7 -> 46253 | D21: 46245 | E21: 二 | F21: =SUM(M21,S21,U21,W21,AC21,AE21,AG21,AI21,AK21) -> 5779689.7 | G21: =SUM(F21:F27) -> 38288005 | I21: 769716.01 | J21: =I21/$F21 -> 0.13317601 | K21: 1030354.5 | L21: =K21/$F21 -> 0.17827159 | M21: =I21+K21 -> 1800070.5 | N21: =M21/$F21 -> 0.3114476 | O21: 278005.31 | P21: =O21/$F21 -> 0.048100386 | Q21: 0 | R21: =Q21/$F21 -> 0 | S21: =O21+Q21 -> 278005.31 | T21: =S21/$F21 -> 0.048100386 | U21: 76273.65 | V21: =U21/$F21 -> 0.013196842 | W21: 238085.11 | X21: =W21/$F21 -> 0.041193407 | Y21: 343228.02 | Z21: =Y21/$F21 -> 0.059385198 | AA21: 564492.78 | AB21: =AA21/$F21 -> 0.097668353 | AC21: =Y21+AA21 -> 907720.8 | AD21: =AC21/$F21 -> 0.15705355 | AE21: 1468121.9 | AF21: =AE21/F21 -> 0.25401396 | AG21: 0 | AH21: =AG21/$F21 -> 0 | AI21: 804901.52 | AJ21: =AI21/$F21 -> 0.13926379 | AK21: 206511.02 | AL21: =AK21/$F21 -> 0.035730468
D22: 46246 | E22: 三 | F22: =SUM(M22,S22,U22,W22,AC22,AE22,AG22,AI22,AK22) -> 5663016 | I22: 758266.73 | J22: =I22/$F22 -> 0.13389804 | K22: 987157.76 | L22: =K22/$F22 -> 0.17431661 | M22: =I22+K22 -> 1745424.5 | N22: =M22/F22 -> 0.30821465 | O22: 281150.71 | P22: =O22/$F22 -> 0.049646815 | Q22: 0 | R22: =Q22/$F22 -> 0 | S22: =O22+Q22 -> 281150.71 | T22: =S22/F22 -> 0.049646815 | U22: 65694.24 | V22: =U22/F22 -> 0.011600575 | W22: 243905.42 | X22: =W22/$F22 -> 0.04306988 | Y22: 314787.56 | Z22: =Y22/$F22 -> 0.055586557 | AA22: 555141.96 | AB22: =AA22/$F22 -> 0.098029382 | AC22: =Y22+AA22 -> 869929.52 | AD22: =AC22/$F22 -> 0.15361594 | AE22: 1371919.9 | AF22: =AE22/F22 -> 0.24225958 | AG22: 0 | AH22: =AG22/$F22 -> 0 | AI22: 888246.86 | AJ22: =AI22/$F22 -> 0.15685049 | AK22: 196744.89 | AL22: =AK22/$F22 -> 0.034742068
D23: 46247 | E23: 四 | F23: =SUM(M23,S23,U23,W23,AC23,AE23,AG23,AI23,AK23) -> 5284211.3 | I23: 730872.77 | J23: =I23/$F23 -> 0.13831256 | K23: 888383.44 | L23: =K23/$F23 -> 0.16812035 | M23: =I23+K23 -> 1619256.2 | N23: =M23/$F23 -> 0.30643291 | O23: 271371.64 | P23: =O23/$F23 -> 0.051355184 | Q23: 0 | R23: =Q23/$F23 -> 0 | S23: =O23+Q23 -> 271371.64 | T23: =S23/$F23 -> 0.051355184 | U23: 67102.83 | V23: =U23/$F23 -> 0.012698741 | W23: 234136.44 | X23: =W23/$F23 -> 0.044308683 | Y23: 298896.26 | Z23: =Y23/$F23 -> 0.056564025 | AA23: 411941.73 | AB23: =AA23/$F23 -> 0.077957089 | AC23: =Y23+AA23 -> 710837.99 | AD23: =AC23/$F23 -> 0.13452111 | AE23: 1285534.4 | AF23: =AE23/F23 -> 0.24327839 | AG23: 0 | AH23: =AG23/$F23 -> 0 | AI23: 897256.88 | AJ23: =AI23/$F23 -> 0.16979959 | AK23: 198714.84 | AL23: =AK23/$F23 -> 0.037605393
D24: 46248 | E24: 五 | F24: =SUM(M24,S24,U24,W24,AC24,AE24,AG24,AI24,AK24) -> 4470999 | I24: 552586.48 | J24: =I24/$F24 -> 0.12359351 | K24: 812891.68 | L24: =K24/$F24 -> 0.18181433 | M24: =I24+K24 -> 1365478.2 | N24: =M24/F24 -> 0.30540784 | O24: 214671.62 | P24: =O24/$F24 -> 0.04801424 | Q24: 0 | R24: =Q24/$F24 -> 0 | S24: =O24+Q24 -> 214671.62 | T24: =S24/F24 -> 0.04801424 | U24: 49300.65 | V24: =U24/F24 -> 0.011026764 | W24: 183154.84 | X24: =W24/$F24 -> 0.040965082 | Y24: 255370.1 | Z24: =Y24/$F24 -> 0.057117011 | AA24: 401533.3 | AB24: =AA24/$F24 -> 0.089808407 | AC24: =Y24+AA24 -> 656903.4 | AD24: =AC24/$F24 -> 0.14692542 | AE24: 972783.65 | AF24: =AE24/F24 -> 0.21757635 | AG24: 0 | AH24: =AG24/$F24 -> 0 | AI24: 866402.56 | AJ24: =AI24/$F24 -> 0.19378277 | AK24: 162304.13 | AL24: =AK24/$F24 -> 0.036301536
D25: 46249 | E25: 六 | F25: =SUM(M25,S25,U25,W25,AC25,AE25,AG25,AI25,AK25) -> 4735598.2 | I25: 523224.64 | J25: =I25/$F25 -> 0.11048755 | K25: 952595.77 | L25: =K25/$F25 -> 0.20115637 | M25: =I25+K25 -> 1475820.4 | N25: =M25/$F25 -> 0.31164392 | O25: 203943.4 | P25: =O25/$F25 -> 0.043066027 | Q25: 0 | R25: =Q25/$F25 -> 0 | S25: =O25+Q25 -> 203943.4 | T25: =S25/$F25 -> 0.043066027 | U25: 52087.86 | V25: =U25/$F25 -> 0.010999214 | W25: 161920.18 | X25: =W25/$F25 -> 0.034192128 | Y25: 275461.35 | Z25: =Y25/$F25 -> 0.058168226 | AA25: 537538.14 | AB25: =AA25/$F25 -> 0.11351008 | AC25: =Y25+AA25 -> 812999.49 | AD25: =AC25/$F25 -> 0.17167831 | AE25: 1025283.1 | AF25: =AE25/F25 -> 0.2165055 | AG25: 0 | AH25: =AG25/$F25 -> 0 | AI25: 846485.74 | AJ25: =AI25/$F25 -> 0.17874948 | AK25: 157058.1 | AL25: =AK25/$F25 -> 0.033165419
D26: 46250 | E26: 日 | F26: =SUM(M26,S26,U26,W26,AC26,AE26,AG26,AI26,AK26) -> 6269913.1 | I26: 793652.13 | J26: =I26/$F26 -> 0.12658104 | K26: 1093741.4 | L26: =K26/$F26 -> 0.17444284 | M26: =I26+K26 -> 1887393.6 | N26: =M26/F26 -> 0.30102388 | O26: 288498.48 | P26: =O26/$F26 -> 0.046013155 | Q26: 0 | R26: =Q26/$F26 -> 0 | S26: =O26+Q26 -> 288498.48 | T26: =S26/F26 -> 0.046013155 | U26: 84335.58 | V26: =U26/F26 -> 0.013450837 | W26: 220963.28 | X26: =W26/$F26 -> 0.035241841 | Y26: 350031.54 | Z26: =Y26/$F26 -> 0.055827176 | AA26: 627063.07 | AB26: =AA26/$F26 -> 0.10001145 | AC26: =Y26+AA26 -> 977094.61 | AD26: =AC26/$F26 -> 0.15583862 | AE26: 1640135.9 | AF26: =AE26/F26 -> 0.2615883 | AG26: 0 | AH26: =AG26/$F26 -> 0 | AI26: 1026305.5 | AJ26: =AI26/$F26 -> 0.16368736 | AK26: 145186.16 | AL26: =AK26/$F26 -> 0.023156008
D27: 46251 | E27: 一 | F27: =SUM(M27,S27,U27,W27,AC27,AE27,AG27,AI27,AK27) -> 6084577.5 | I27: 784514.72 | J27: =I27/$F27 -> 0.12893495 | K27: 1082041 | L27: =K27/$F27 -> 0.17783338 | M27: =I27+K27 -> 1866555.7 | N27: =M27/$F27 -> 0.30676833 | O27: 281762.01 | P27: =O27/$F27 -> 0.046307572 | Q27: 0 | R27: =Q27/$F27 -> 0 | S27: =O27+Q27 -> 281762.01 | T27: =S27/$F27 -> 0.046307572 | U27: 73456.47 | V27: =U27/$F27 -> 0.012072567 | W27: 250384.3 | X27: =W27/$F27 -> 0.041150647 | Y27: 371928.8 | Z27: =Y27/$F27 -> 0.061126479 | AA27: 576313.35 | AB27: =AA27/$F27 -> 0.094717069 | AC27: =Y27+AA27 -> 948242.15 | AD27: =AC27/$F27 -> 0.15584355 | AE27: 1551809.5 | AF27: =AE27/F27 -> 0.2550398 | AG27: 0 | AH27: =AG27/$F27 -> 0 | AI27: 951265.58 | AJ27: =AI27/$F27 -> 0.15634045 | AK27: 161101.86 | AL27: =AK27/$F27 -> 0.026477082
B28: =B21+7 -> 46260 | D28: 46252 | E28: 二 | F28: =SUM(M28,S28,U28,W28,AC28,AE28,AG28,AI28,AK28) -> 6583839.5 | G28: =SUM(F28:F34) -> 39537270 | I28: 782871.45 | J28: =I28/$F28 -> 0.11890804 | K28: 1078113.7 | L28: =K28/$F28 -> 0.16375152 | M28: =I28+K28 -> 1860985.2 | N28: =M28/$F28 -> 0.28265956 | O28: 280506.93 | P28: =O28/$F28 -> 0.042605372 | Q28: 0 | R28: =Q28/$F28 -> 0 | S28: =O28+Q28 -> 280506.93 | T28: =S28/$F28 -> 0.042605372 | U28: 77112.81 | V28: =U28/$F28 -> 0.011712438 | W28: 213416.36 | X28: =W28/$F28 -> 0.032415183 | Y28: 316364.54 | Z28: =Y28/$F28 -> 0.048051679 | AA28: 560524.93 | AB28: =AA28/$F28 -> 0.085136481 | AC28: =Y28+AA28 -> 876889.47 | AD28: =AC28/$F28 -> 0.13318816 | AE28: 2195493.5 | AF28: =AE28/F28 -> 0.33346705 | AG28: 0 | AH28: =AG28/$F28 -> 0 | AI28: 944361.97 | AJ28: =AI28/$F28 -> 0.14343636 | AK28: 135073.28 | AL28: =AK28/$F28 -> 0.020515883
D29: 46253 | E29: 三 | F29: =SUM(M29,S29,U29,W29,AC29,AE29,AG29,AI29,AK29) -> 5965361.7 | I29: 765410.53 | J29: =I29/$F29 -> 0.12830916 | K29: 1019616.9 | L29: =K29/$F29 -> 0.1709229 | M29: =I29+K29 -> 1785027.4 | N29: =M29/F29 -> 0.29923205 | O29: 279389.89 | P29: =O29/$F29 -> 0.046835365 | Q29: 0 | R29: =Q29/$F29 -> 0 | S29: =O29+Q29 -> 279389.89 | T29: =S29/F29 -> 0.046835365 | U29: 65604.33 | V29: =U29/F29 -> 0.010997544 | W29: 218864.16 | X29: =W29/$F29 -> 0.036689168 | Y29: 288132.69 | Z29: =Y29/$F29 -> 0.048300959 | AA29: 538565.61 | AB29: =AA29/$F29 -> 0.090282138 | AC29: =Y29+AA29 -> 826698.3 | AD29: =AC29/$F29 -> 0.1385831 | AE29: 1741295.8 | AF29: =AE29/F29 -> 0.29190112 | AG29: 0 | AH29: =AG29/$F29 -> 0 | AI29: 913466.66 | AJ29: =AI29/$F29 -> 0.15312846 | AK29: 135015.18 | AL29: =AK29/$F29 -> 0.022633193
D30: 46254 | E30: 四 | F30: =SUM(M30,S30,U30,W30,AC30,AE30,AG30,AI30,AK30) -> 5515098.4 | I30: 735594.52 | J30: =I30/$F30 -> 0.13337831 | K30: 902228.4 | L30: =K30/$F30 -> 0.16359244 | M30: =I30+K30 -> 1637822.9 | N30: =M30/$F30 -> 0.29697075 | O30: 267973.56 | P30: =O30/$F30 -> 0.04858908 | Q30: 0 | R30: =Q30/$F30 -> 0 | S30: =O30+Q30 -> 267973.56 | T30: =S30/$F30 -> 0.04858908 | U30: 67912.02 | V30: =U30/$F30 -> 0.012313836 | W30: 215496.56 | X30: =W30/$F30 -> 0.039073928 | Y30: 280436.89 | Z30: =Y30/$F30 -> 0.050848936 | AA30: 418454.3 | AB30: =AA30/$F30 -> 0.075874312 | AC30: =Y30+AA30 -> 698891.19 | AD30: =AC30/$F30 -> 0.12672325 | AE30: 1631479.8 | AF30: =AE30/F30 -> 0.2958206 | AG30: 0 | AH30: =AG30/$F30 -> 0 | AI30: 861399.18 | AJ30: =AI30/$F30 -> 0.15618927 | AK30: 134123.26 | AL30: =AK30/$F30 -> 0.024319287
D31: 46255 | E31: 五 | F31: =SUM(M31,S31,U31,W31,AC31,AE31,AG31,AI31,AK31) -> 4265125.8 | I31: 549940.7 | J31: =I31/$F31 -> 0.12893892 | K31: 808605.97 | L31: =K31/$F31 -> 0.18958549 | M31: =I31+K31 -> 1358546.7 | N31: =M31/F31 -> 0.31852441 | O31: 207281.09 | P31: =O31/$F31 -> 0.048599057 | Q31: 0 | R31: =Q31/$F31 -> 0 | S31: =O31+Q31 -> 207281.09 | T31: =S31/F31 -> 0.048599057 | U31: 41388.57 | V31: =U31/F31 -> 0.0097039506 | W31: 161157 | X31: =W31/$F31 -> 0.037784818 | Y31: 223588.4 | Z31: =Y31/$F31 -> 0.052422463 | AA31: 409792.47 | AB31: =AA31/$F31 -> 0.096079808 | AC31: =Y31+AA31 -> 633380.87 | AD31: =AC31/$F31 -> 0.14850227 | AE31: 1016350.8 | AF31: =AE31/F31 -> 0.23829328 | AG31: 0 | AH31: =AG31/$F31 -> 0 | AI31: 735764.16 | AJ31: =AI31/$F31 -> 0.17250702 | AK31: 111256.62 | AL31: =AK31/$F31 -> 0.026085191
D32: 46256 | E32: 六 | F32: =SUM(M32,S32,U32,W32,AC32,AE32,AG32,AI32,AK32) -> 4672768.8 | I32: 519200.72 | J32: =I32/$F32 -> 0.11111201 | K32: 922716.42 | L32: =K32/$F32 -> 0.19746674 | M32: =I32+K32 -> 1441917.1 | N32: =M32/$F32 -> 0.30857875 | O32: 192243.65 | P32: =O32/$F32 -> 0.041141272 | Q32: 0 | R32: =Q32/$F32 -> 0 | S32: =O32+Q32 -> 192243.65 | T32: =S32/$F32 -> 0.041141272 | U32: 49450.5 | V32: =U32/$F32 -> 0.010582698 | W32: 159615.64 | X32: =W32/$F32 -> 0.034158686 | Y32: 252289.82 | Z32: =Y32/$F32 -> 0.053991505 | AA32: 539320.58 | AB32: =AA32/$F32 -> 0.11541778 | AC32: =Y32+AA32 -> 791610.4 | AD32: =AC32/$F32 -> 0.16940928 | AE32: 1199863.2 | AF32: =AE32/F32 -> 0.25677777 | AG32: 0 | AH32: =AG32/$F32 -> 0 | AI32: 726920.03 | AJ32: =AI32/$F32 -> 0.15556516 | AK32: 111148.26 | AL32: =AK32/$F32 -> 0.023786381
